Workbook

Sheet Linkสูตรออร์เดอร์  (2)
B2: เรียงกำหนดส่ง | D2: ลบ 0 | T2: เรียง 1
B3: ข้อมูลUpdate ณ. วันที่ | D3: 45905 | E3: เวลา | G3: 10.33
A4: วันรับออร์เดอร์/แบบ | B4: เลขที่ SO | C4: ชื่อลูกค้า | E4: 10.3 | I4: น้ำหนัก | L4: บิด/จับจีบ | M4: ถุงใน | Q4: =[1]หน้าผ้า!$AC$13 -> 44873 | S4: วิธีบรรจุ | T4: วันส่ง | U4: จำนวนส่ง | V4: ตัดเย็บ (ใบ) | W4: =[1]หน้าผ้า!$AJ$13 -> 44873 | X4: พิมพ์ (ใบ) | Y4: =[1]หน้าผ้า!$AM$13 -> 44876 | Z4: ผ้าทอ (เมตร) Updateณ | AB4: =[1]หน้าผ้า!$AR$12 -> 44876 | AD4: ผ้าเคลือบ(เมตร) | AF4: หมายเหตุ | AG4: เครื่อง
B5: เลขที่ SO | C5: ชื่อลูกค้า | D5: ตรา | E5: กว้าง | F5: ยาว | G5: สี | H5: เคลือบ | I5: กรัม/ใบ | J5: * | K5: aw | L5: บิด/จับจีบ | M5: กว้าง | N5: ยาว | O5: หนา | P5: ใช้(กก.) | Q5: Stock(กก.) | R5: ผลิต(กก.) | S5: วิธีบรรจุ | T5: วันส่ง | U5: จำนวนส่ง | V5: StockFG | W5: ค้างตัด | X5: พิมพ์แล้ว | Y5: ค้างพิมพ์ | Z5: ประเภท | AA5: ใช้ | AB5: Stock | AC5: ค้างทอ | AD5: Stock | AE5: ค้างเคลือบ | AF5: หมายเหตุ | AG5: ที่พิมพ์ได้ | AH5: process | AI5: Lead time | AJ5: วันที่ส่งPL | AK5: เคลือบ | AL5: ได้ ART | AM5: พิมพ์ | AN5: จีบ-บิด | AO5: ตัด-เย็บ | AP5: ทอ | AQ5: สวมถุง | AR5: เย็บปาก | AS5: PT | AT5: ม้วน | AU5: ตัด | AV5: ตอกตาไก่ | AW5: GROUP | AX5: ART | AY5: หมายเหตุปัญหา | AZ5: ราคา/ใบ | BA5: ราคารวม | BB5: workweek | BC5: เส้นเทป | BD5: จำนวน
A6: =[2]หน้าผ้า!C15 -> 0 | B6: =[2]หน้าผ้า!B15 -> 0 | C6: =[2]หน้าผ้า!E15 -> 0 | D6: =[2]หน้าผ้า!F15 -> 0 | E6: =[2]หน้าผ้า!G15 -> 12 | F6: =[2]หน้าผ้า!H15 -> 16 | G6: =[2]หน้าผ้า!I15 -> ขาว | H6: =[2]หน้าผ้า!J15 -> 0 | I6: =[2]หน้าผ้า!L15 -> 25 | J6: =[2]หน้าผ้า!M15 -> ± | K6: =[2]หน้าผ้า!N15 -> 5 | L6: =[2]หน้าผ้า!R15 -> 0 | M6: =[2]หน้าผ้า!T15 -> 0 | N6: =[2]หน้าผ้า!U15 -> 0 | O6: =[2]หน้าผ้า!V15 -> 0 | P6: =[2]หน้าผ้า!AB15 -> 0 | Q6: =[2]หน้าผ้า!AC15 -> 0 | R6: =[2]หน้าผ้า!AD15 -> 0 | S6: =[2]หน้าผ้า!Z15 -> 0 | T6: =[2]หน้าผ้า!X15 -> 0 | U6: =[2]หน้าผ้า!AA15 -> 0 | V6: =[2]หน้าผ้า!AJ15 -> 0 | W6: =[2]หน้าผ้า!AL15 -> 0 | X6: =[2]หน้าผ้า!AM15 -> 0 | Y6: =[2]หน้าผ้า!AN15 -> 0 | Z6: =[2]หน้าผ้า!AO15 -> WSWT1221750 | AA6: =[2]หน้าผ้า!AQ15 -> #REF! | AB6: =[2]หน้าผ้า!AR15 -> #REF! | AC6: =[2]หน้าผ้า!AS15 -> #REF! | AD6: =[2]หน้าผ้า!AT15 -> #REF! | AE6: =[2]หน้าผ้า!AU15 -> #REF! | AF6: =[2]หน้าผ้า!AI15 -> ระบุในSD | AG6: =[3]หน้าผ้า!DC18 -> < Ord 20,000 | AH6: =[2]หน้าผ้า!DL15 -> 0 | AI6: =[2]หน้าผ้า!DM15 -> 0 | AJ6: =[2]หน้าผ้า!DN15 -> 0 | AK6: =[2]หน้าผ้า!DQ15 -> 0 | AL6: =[2]หน้าผ้า!DR15 -> 0 | AM6: =[2]หน้าผ้า!DS15 -> 0 | AN6: =[2]หน้าผ้า!DT15 -> 0 | AO6: =[2]หน้าผ้า!DU15 -> 0 | AP6: =[2]หน้าผ้า!DP15 -> 0 | AQ6: =[2]หน้าผ้า!DW15 -> 0 | AR6: =[2]หน้าผ้า!DX15 -> 0 | AS6: =[2]หน้าผ้า!DY15 -> 0 | AT6: =[2]หน้าผ้า!DZ15 -> 0 | AU6: =[2]หน้าผ้า!EA15 -> 0 | AV6: =[2]หน้าผ้า!EB15 -> 0 | AW6: =[2]หน้าผ้า!EC15 -> 0 | AX6: =[2]หน้าผ้า!ED15 -> 0 | AY6: =[2]หน้าผ้า!AG15 -> 0 | AZ6: =[2]หน้าผ้า!EG15 -> 0 | BA6: =[2]หน้าผ้า!EH15 -> 0 | BB6: =[2]หน้าผ้า!EI15 -> 0 | BC6: =[2]หน้าผ้า!BZ15 -> WRWT120750/WRWT21750 | BD6: =[2]หน้าผ้า!CA15 -> 0
A7: =[2]หน้าผ้า!C16 -> 0 | B7: =[2]หน้าผ้า!B16 -> 0 | C7: =[2]หน้าผ้า!E16 -> 0 | D7: =[2]หน้าผ้า!F16 -> 0 | E7: =[2]หน้าผ้า!G16 -> 14 | F7: =[2]หน้าผ้า!H16 -> 22 | G7: =[2]หน้าผ้า!I16 -> ขาว | H7: =[2]หน้าผ้า!J16 -> 0 | I7: =[2]หน้าผ้า!L16 -> 36 | J7: =[2]หน้าผ้า!M16 -> ± | K7: =[2]หน้าผ้า!N16 -> 5 | L7: =[2]หน้าผ้า!R16 -> 0 | M7: =[2]หน้าผ้า!T16 -> 0 | N7: =[2]หน้าผ้า!U16 -> 0 | O7: =[2]หน้าผ้า!V16 -> 0 | P7: =[2]หน้าผ้า!AB16 -> 0 | Q7: =[2]หน้าผ้า!AC16 -> 0 | R7: =[2]หน้าผ้า!AD16 -> 0 | S7: =[2]หน้าผ้า!Z16 -> 0 | T7: =[2]หน้าผ้า!X16 -> 0 | U7: =[2]หน้าผ้า!AA16 -> 0 | V7: =[2]หน้าผ้า!AJ16 -> 0 | W7: =[2]หน้าผ้า!AL16 -> 0 | X7: =[2]หน้าผ้า!AM16 -> 0 | Y7: =[2]หน้าผ้า!AN16 -> 0 | Z7: =[2]หน้าผ้า!AO16 -> WSWT1425800 | AA7: =[2]หน้าผ้า!AQ16 -> #REF! | AB7: =[2]หน้าผ้า!AR16 -> #REF! | AC7: =[2]หน้าผ้า!AS16 -> #REF! | AD7: =[2]หน้าผ้า!AT16 -> #REF! | AE7: =[2]หน้าผ้า!AU16 -> #REF! | AF7: =[2]หน้าผ้า!AI16 -> ระบุในSD | AG7: =[3]หน้าผ้า!DC19 -> รอตัด | AH7: =[2]หน้าผ้า!DL16 -> 0 | AI7: =[2]หน้าผ้า!DM16 -> Lead time | AJ7: =[2]หน้าผ้า!DN16 -> 0 | AK7: =[2]หน้าผ้า!DQ16 -> 0 | AL7: =[2]หน้าผ้า!DR16 -> 0 | AM7: =[2]หน้าผ้า!DS16 -> 0 | AN7: =[2]หน้าผ้า!DT16 -> 0 | AO7: =[2]หน้าผ้า!DU16 -> 0 | AP7: =[2]หน้าผ้า!DP16 -> 0 | AQ7: =[2]หน้าผ้า!DW16 -> 0 | AR7: =[2]หน้าผ้า!DX16 -> 0 | AS7: =[2]หน้าผ้า!DY16 -> 0 | AT7: =[2]หน้าผ้า!DZ16 -> 0 | AU7: =[2]หน้าผ้า!EA16 -> 0 | AV7: =[2]หน้าผ้า!EB16 -> 0 | AW7: =[2]หน้าผ้า!EC16 -> 0 | AX7: =[2]หน้าผ้า!ED16 -> 0 | AY7: =[2]หน้าผ้า!AG16 -> 0 | AZ7: =[2]หน้าผ้า!EG16 -> 0 | BA7: =[2]หน้าผ้า!EH16 -> 0 | BB7: =[2]หน้าผ้า!EI16 -> 0 | BC7: =[2]หน้าผ้า!BZ16 -> WRWT140800/WRWT25800 | BD7: =[2]หน้าผ้า!CA16 -> 0
A8: =[2]หน้าผ้า!C17 -> 45896 | B8: =[2]หน้าผ้า!B17 -> MK68-001041 | C8: =[2]หน้าผ้า!E17 -> บจก.ซัน ซีเมนต์ โพรเซส | D8: =[2]หน้าผ้า!F17 -> พระอาทิตย์ | E8: =[2]หน้าผ้า!G17 -> 16 | F8: =[2]หน้าผ้า!H17 -> 25 | G8: =[2]หน้าผ้า!I17 -> ขาว | H8: =[2]หน้าผ้า!J17 -> ใส | I8: =[2]หน้าผ้า!L17 -> 50 | J8: =[2]หน้าผ้า!M17 -> ± | K8: =[2]หน้าผ้า!N17 -> 5 | L8: =[2]หน้าผ้า!R17 -> บิด | M8: =[2]หน้าผ้า!T17 -> 19 | N8: =[2]หน้าผ้า!U17 -> 28 | O8: =[2]หน้าผ้า!V17 -> 40 | P8: =[2]หน้าผ้า!AB17 -> 65.624643 | Q8: =[2]หน้าผ้า!AC17 -> 0 | R8: =[2]หน้าผ้า!AD17 -> 65.624643 | S8: =[2]หน้าผ้า!Z17 -> 500กระสอบ | T8: =[2]หน้าผ้า!X17 -> 45908 | U8: =[2]หน้าผ้า!AA17 -> 5000 | V8: =[2]หน้าผ้า!AJ17 -> 0 | W8: =[2]หน้าผ้า!AL17 -> 5000 | X8: =[2]หน้าผ้า!AM17 -> 0 | Y8: =[2]หน้าผ้า!AN17 -> 5250 | Z8: =[2]หน้าผ้า!AO17 -> WSWT1625800SM | AA8: =[2]หน้าผ้า!AQ17 -> 3702.05 | AB8: =[2]หน้าผ้า!AR17 -> 3702.05 | AC8: =[2]หน้าผ้า!AS17 -> 0 | AD8: =[2]หน้าผ้า!AT17 -> 0 | AE8: =[2]หน้าผ้า!AU17 -> 3702.05 | AF8: =[2]หน้าผ้า!AI17 -> 0 | AG8: =[3]หน้าผ้า!DC20 -> รอตัด | AH8: =[2]หน้าผ้า!DL17 -> P8 | AI8: =[2]หน้าผ้า!DM17 -> 4 | AJ8: =[2]หน้าผ้า!DN17 -> 45908 | AK8: =[2]หน้าผ้า!DQ17 -> 45904 | AL8: =[2]หน้าผ้า!DR17 -> 45898 | AM8: =[2]หน้าผ้า!DS17 -> 45905 | AN8: =[2]หน้าผ้า!DT17 -> 45906 | AO8: =[2]หน้าผ้า!DU17 -> 45906 | AP8: =[2]หน้าผ้า!DP17 -> 45903 | AQ8: =[2]หน้าผ้า!DW17 -> 45907 | AR8: =[2]หน้าผ้า!DX17 -> 0 | AS8: =[2]หน้าผ้า!DY17 -> 0 | AT8: =[2]หน้าผ้า!DZ17 -> 0 | AU8: =[2]หน้าผ้า!EA17 -> 0 | AV8: =[2]หน้าผ้า!EB17 -> 0 | AW8: =[2]หน้าผ้า!EC17 -> งานเคลือบ+พิมพ์ | AX8: =[2]หน้าผ้า!ED17 -> / | AY8: =[2]หน้าผ้า!AG17 -> รอลูกค้า | AZ8: =[2]หน้าผ้า!EG17 -> 0 | BA8: =[2]หน้าผ้า!EH17 -> 0 | BB8: =[2]หน้าผ้า!EI17 -> 0 | BC8: =[2]หน้าผ้า!BZ17 -> WRWT25800/WRWT25800 | BD8: =[2]หน้าผ้า!CA17 -> 0
A9: =[2]หน้าผ้า!C18 -> 0 | B9: =[2]หน้าผ้า!B18 -> 0 | C9: =[2]หน้าผ้า!E18 -> 0 | D9: =[2]หน้าผ้า!F18 | E9: =[2]หน้าผ้า!G18 -> 16 | F9: =[2]หน้าผ้า!H18 -> 25 | G9: =[2]หน้าผ้า!I18 -> ขาว | H9: =[2]หน้าผ้า!J18 -> 0 | I9: =[2]หน้าผ้า!L18 -> 45 | J9: =[2]หน้าผ้า!M18 -> ± | K9: =[2]หน้าผ้า!N18 -> 5 | L9: =[2]หน้าผ้า!R18 -> 0 | M9: =[2]หน้าผ้า!T18 -> 0 | N9: =[2]หน้าผ้า!U18 -> 0 | O9: =[2]หน้าผ้า!V18 -> 0 | P9: =[2]หน้าผ้า!AB18 -> 0 | Q9: =[2]หน้าผ้า!AC18 -> 0 | R9: =[2]หน้าผ้า!AD18 -> 0 | S9: =[2]หน้าผ้า!Z18 -> 0 | T9: =[2]หน้าผ้า!X18 -> 0 | U9: =[2]หน้าผ้า!AA18 -> 0 | V9: =[2]หน้าผ้า!AJ18 -> 0 | W9: =[2]หน้าผ้า!AL18 -> 0 | X9: =[2]หน้าผ้า!AM18 -> 0 | Y9: =[2]หน้าผ้า!AN18 -> 0 | Z9: =[2]หน้าผ้า!AO18 -> WSWT1625800SM | AA9: =[2]หน้าผ้า!AQ18 -> 3702.05 | AB9: =[2]หน้าผ้า!AR18 -> 3702.05 | AC9: =[2]หน้าผ้า!AS18 -> 0 | AD9: =[2]หน้าผ้า!AT18 -> 0 | AE9: =[2]หน้าผ้า!AU18 -> 3702.05 | AF9: =[2]หน้าผ้า!AI18 -> ระบุในSD | AG9: =[3]หน้าผ้า!DC21 -> ยังไม่ได้พิมพ์ | AH9: =[2]หน้าผ้า!DL18 -> 0 | AI9: =[2]หน้าผ้า!DM18 -> Lead time | AJ9: =[2]หน้าผ้า!DN18 -> 0 | AK9: =[2]หน้าผ้า!DQ18 -> 0 | AL9: =[2]หน้าผ้า!DR18 -> 0 | AM9: =[2]หน้าผ้า!DS18 -> 0 | AN9: =[2]หน้าผ้า!DT18 -> 0 | AO9: =[2]หน้าผ้า!DU18 -> 0 | AP9: =[2]หน้าผ้า!DP18 -> 0 | AQ9: =[2]หน้าผ้า!DW18 -> 0 | AR9: =[2]หน้าผ้า!DX18 -> 0 | AS9: =[2]หน้าผ้า!DY18 -> 0 | AT9: =[2]หน้าผ้า!DZ18 -> 0 | AU9: =[2]หน้าผ้า!EA18 -> 0 | AV9: =[2]หน้าผ้า!EB18 -> 0 | AW9: =[2]หน้าผ้า!EC18 -> 0 | AX9: =[2]หน้าผ้า!ED18 -> 0 | AY9: =[2]หน้าผ้า!AG18 -> 0 | AZ9: =[2]หน้าผ้า!EG18 -> 0 | BA9: =[2]หน้าผ้า!EH18 -> 0 | BB9: =[2]หน้าผ้า!EI18 -> 0 | BC9: =[2]หน้าผ้า!BZ18 -> WRWT160800/WRWT25800 | BD9: =[2]หน้าผ้า!CA18 -> 0
A10: =[2]หน้าผ้า!C19 -> 45897 | B10: =[2]หน้าผ้า!B19 -> MK68-001045 | C10: =[2]หน้าผ้า!E19 -> บจก.เคอรี่ฟลาวมิลล์ | D10: =[2]หน้าผ้า!F19 -> โบว์น้ำเงิน 10กก | E10: =[2]หน้าผ้า!G19 -> 16 | F10: =[2]หน้าผ้า!H19 -> 25 | G10: =[2]หน้าผ้า!I19 -> ขาว | H10: =[2]หน้าผ้า!J19 -> 0 | I10: =[2]หน้าผ้า!L19 -> 45 | J10: =[2]หน้าผ้า!M19 -> ± | K10: =[2]หน้าผ้า!N19 -> 5 | L10: =[2]หน้าผ้า!R19 -> ไม่ | M10: =[2]หน้าผ้า!T19 -> ไม่สวมถุงใน | N10: =[2]หน้าผ้า!U19 -> 0 | O10: =[2]หน้าผ้า!V19 -> 0 | P10: =[2]หน้าผ้า!AB19 -> 0 | Q10: =[2]หน้าผ้า!AC19 -> 0 | R10: =[2]หน้าผ้า!AD19 -> 0 | S10: =[2]หน้าผ้า!Z19 -> ห่ออัดเบลแบน500 | T10: =[2]หน้าผ้า!X19 -> 45909 | U10: =[2]หน้าผ้า!AA19 -> 5000 | V10: =[2]หน้าผ้า!AJ19 -> 0 | W10: =[2]หน้าผ้า!AL19 -> 5000 | X10: =[2]หน้าผ้า!AM19 -> 5400 | Y10: =[2]หน้าผ้า!AN19 -> 0 | Z10: =[2]หน้าผ้า!AO19 -> WSWT1625800 | AA10: =[2]หน้าผ้า!AQ19 -> 0 | AB10: =[2]หน้าผ้า!AR19 -> 0 | AC10: =[2]หน้าผ้า!AS19 -> 0 | AD10: =[2]หน้าผ้า!AT19 -> 0 | AE10: =[2]หน้าผ้า!AU19 -> 0 | AF10: =[2]หน้าผ้า!AI19 -> 0 | AG10: =[3]หน้าผ้า!DC22 -> พร้อมส่ง | AH10: =[2]หน้าผ้า!DL19 -> P7 | AI10: =[2]หน้าผ้า!DM19 -> 2 | AJ10: =[2]หน้าผ้า!DN19 -> 45909 | AK10: =[2]หน้าผ้า!DQ19 -> 0 | AL10: =[2]หน้าผ้า!DR19 -> 45900 | AM10: =[2]หน้าผ้า!DS19 -> 45907 | AN10: =[2]หน้าผ้า!DT19 -> 45908 | AO10: =[2]หน้าผ้า!DU19 -> 45908 | AP10: =[2]หน้าผ้า!DP19 -> 45904 | AQ10: =[2]หน้าผ้า!DW19 -> 0 | AR10: =[2]หน้าผ้า!DX19 -> 0 | AS10: =[2]หน้าผ้า!DY19 -> 0 | AT10: =[2]หน้าผ้า!DZ19 -> 0 | AU10: =[2]หน้าผ้า!EA19 -> 0 | AV10: =[2]หน้าผ้า!EB19 -> 0 | AW10: =[2]หน้าผ้า!EC19 -> งานพิมพ์ | AX10: =[2]หน้าผ้า!ED19 -> / | AY10: =[2]หน้าผ้า!AG19 -> 0 | AZ10: =[2]หน้าผ้า!EG19 -> 0 | BA10: =[2]หน้าผ้า!EH19 -> 0 | BB10: =[2]หน้าผ้า!EI19 -> 0 | BC10: =[2]หน้าผ้า!BZ19 -> WRWT25800/WRWT25800 | BD10: =[2]หน้าผ้า!CA19 -> 0
A11: =[2]หน้าผ้า!C20 -> 45897 | B11: =[2]หน้าผ้า!B20 -> MK68-001045 | C11: =[2]หน้าผ้า!E20 -> บจก.เคอรี่ฟลาวมิลล์ | D11: =[2]หน้าผ้า!F20 -> โดนัทแฟนฉัน 10กก | E11: =[2]หน้าผ้า!G20 -> 16 | F11: =[2]หน้าผ้า!H20 -> 25 | G11: =[2]หน้าผ้า!I20 -> ขาว | H11: =[2]หน้าผ้า!J20 -> 0 | I11: =[2]หน้าผ้า!L20 -> 45 | J11: =[2]หน้าผ้า!M20 -> ± | K11: =[2]หน้าผ้า!N20 -> 5 | L11: =[2]หน้าผ้า!R20 -> ไม่ | M11: =[2]หน้าผ้า!T20 -> ไม่สวมถุงใน | N11: =[2]หน้าผ้า!U20 -> 0 | O11: =[2]หน้าผ้า!V20 -> 0 | P11: =[2]หน้าผ้า!AB20 -> 0 | Q11: =[2]หน้าผ้า!AC20 -> 0 | R11: =[2]หน้าผ้า!AD20 -> 0 | S11: =[2]หน้าผ้า!Z20 -> ห่ออัดเบลแบน500 | T11: =[2]หน้าผ้า!X20 -> 45909 | U11: =[2]หน้าผ้า!AA20 -> 5000 | V11: =[2]หน้าผ้า!AJ20 -> 0 | W11: =[2]หน้าผ้า!AL20 -> 5000 | X11: =[2]หน้าผ้า!AM20 -> 5400 | Y11: =[2]หน้าผ้า!AN20 -> 0 | Z11: =[2]หน้าผ้า!AO20 -> WSWT1625800 | AA11: =[2]หน้าผ้า!AQ20 -> 0 | AB11: =[2]หน้าผ้า!AR20 -> 0 | AC11: =[2]หน้าผ้า!AS20 -> 0 | AD11: =[2]หน้าผ้า!AT20 -> 0 | AE11: =[2]หน้าผ้า!AU20 -> 0 | AF11: =[2]หน้าผ้า!AI20 -> 0 | AG11: =[3]หน้าผ้า!DC23 -> พร้อมส่ง | AH11: =[2]หน้าผ้า!DL20 -> P7 | AI11: =[2]หน้าผ้า!DM20 -> 2 | AJ11: =[2]หน้าผ้า!DN20 -> 45909 | AK11: =[2]หน้าผ้า!DQ20 -> 0 | AL11: =[2]หน้าผ้า!DR20 -> 45900 | AM11: =[2]หน้าผ้า!DS20 -> 45907 | AN11: =[2]หน้าผ้า!DT20 -> 45908 | AO11: =[2]หน้าผ้า!DU20 -> 45908 | AP11: =[2]หน้าผ้า!DP20 -> 45904 | AQ11: =[2]หน้าผ้า!DW20 -> 0 | AR11: =[2]หน้าผ้า!DX20 -> 0 | AS11: =[2]หน้าผ้า!DY20 -> 0 | AT11: =[2]หน้าผ้า!DZ20 -> 0 | AU11: =[2]หน้าผ้า!EA20 -> 0 | AV11: =[2]หน้าผ้า!EB20 -> 0 | AW11: =[2]หน้าผ้า!EC20 -> งานพิมพ์ | AX11: =[2]หน้าผ้า!ED20 -> / | AY11: =[2]หน้าผ้า!AG20 -> 0 | AZ11: =[2]หน้าผ้า!EG20 -> 0 | BA11: =[2]หน้าผ้า!EH20 -> 0 | BB11: =[2]หน้าผ้า!EI20 -> 0 | BC11: =[2]หน้าผ้า!BZ20 -> WRWT25800/WRWT25800 | BD11: =[2]หน้าผ้า!CA20 -> 0
A12: =[2]หน้าผ้า!C21 -> 45897 | B12: =[2]หน้าผ้า!B21 -> MK68-001045 | C12: =[2]หน้าผ้า!E21 -> บจก.เคอรี่ฟลาวมิลล์ | D12: =[2]หน้าผ้า!F21 -> น้องเอินโดนัท 10กก | E12: =[2]หน้าผ้า!G21 -> 16 | F12: =[2]หน้าผ้า!H21 -> 25 | G12: =[2]หน้าผ้า!I21 -> ขาว | H12: =[2]หน้าผ้า!J21 -> 0 | I12: =[2]หน้าผ้า!L21 -> 45 | J12: =[2]หน้าผ้า!M21 -> ± | K12: =[2]หน้าผ้า!N21 -> 5 | L12: =[2]หน้าผ้า!R21 -> ไม่ | M12: =[2]หน้าผ้า!T21 -> ไม่สวมถุงใน | N12: =[2]หน้าผ้า!U21 -> 0 | O12: =[2]หน้าผ้า!V21 -> 0 | P12: =[2]หน้าผ้า!AB21 -> 0 | Q12: =[2]หน้าผ้า!AC21 -> 0 | R12: =[2]หน้าผ้า!AD21 -> 0 | S12: =[2]หน้าผ้า!Z21 -> ห่ออัดเบลแบน500 | T12: =[2]หน้าผ้า!X21 -> 45925 | U12: =[2]หน้าผ้า!AA21 -> 5000 | V12: =[2]หน้าผ้า!AJ21 -> 0 | W12: =[2]หน้าผ้า!AL21 -> 5000 | X12: =[2]หน้าผ้า!AM21 -> 0 | Y12: =[2]หน้าผ้า!AN21 -> 5250 | Z12: =[2]หน้าผ้า!AO21 -> WSWT1625800 | AA12: =[2]หน้าผ้า!AQ21 -> 3702.05 | AB12: =[2]หน้าผ้า!AR21 -> 682 | AC12: =[2]หน้าผ้า!AS21 -> 3020.05 | AD12: =[2]หน้าผ้า!AT21 -> 0 | AE12: =[2]หน้าผ้า!AU21 -> 0 | AF12: =[2]หน้าผ้า!AI21 -> 0 | AG12: =[3]หน้าผ้า!DC24 -> พร้อมส่ง | AH12: =[2]หน้าผ้า!DL21 -> P7 | AI12: =[2]หน้าผ้า!DM21 -> 2 | AJ12: =[2]หน้าผ้า!DN21 -> 45925 | AK12: =[2]หน้าผ้า!DQ21 -> 0 | AL12: =[2]หน้าผ้า!DR21 -> 45916 | AM12: =[2]หน้าผ้า!DS21 -> 45923 | AN12: =[2]หน้าผ้า!DT21 -> 45924 | AO12: =[2]หน้าผ้า!DU21 -> 45924 | AP12: =[2]หน้าผ้า!DP21 -> 45920 | AQ12: =[2]หน้าผ้า!DW21 -> 0 | AR12: =[2]หน้าผ้า!DX21 -> 0 | AS12: =[2]หน้าผ้า!DY21 -> 0 | AT12: =[2]หน้าผ้า!DZ21 -> 0 | AU12: =[2]หน้าผ้า!EA21 -> 0 | AV12: =[2]หน้าผ้า!EB21 -> 0 | AW12: =[2]หน้าผ้า!EC21 -> งานพิมพ์ | AX12: =[2]หน้าผ้า!ED21 -> รอART | AY12: =[2]หน้าผ้า!AG21 -> 0 | AZ12: =[2]หน้าผ้า!EG21 -> 0 | BA12: =[2]หน้าผ้า!EH21 -> 0 | BB12: =[2]หน้าผ้า!EI21 -> 0 | BC12: =[2]หน้าผ้า!BZ21 -> WRWT25800/WRWT25800 | BD12: =[2]หน้าผ้า!CA21 -> 184.69284
A13: =[2]หน้าผ้า!C22 -> 0 | B13: =[2]หน้าผ้า!B22 -> 0 | C13: =[2]หน้าผ้า!E22 -> 0 | D13: =[2]หน้าผ้า!F22 -> 0 | E13: =[2]หน้าผ้า!G22 -> 16 | F13: =[2]หน้าผ้า!H22 -> 25 | G13: =[2]หน้าผ้า!I22 -> ขาว | H13: =[2]หน้าผ้า!J22 -> 0 | I13: =[2]หน้าผ้า!L22 -> 45 | J13: =[2]หน้าผ้า!M22 -> ± | K13: =[2]หน้าผ้า!N22 -> 5 | L13: =[2]หน้าผ้า!R22 -> 0 | M13: =[2]หน้าผ้า!T22 -> 0 | N13: =[2]หน้าผ้า!U22 -> 0 | O13: =[2]หน้าผ้า!V22 -> 0 | P13: =[2]หน้าผ้า!AB22 -> 0 | Q13: =[2]หน้าผ้า!AC22 -> 0 | R13: =[2]หน้าผ้า!AD22 -> 0 | S13: =[2]หน้าผ้า!Z22 -> 0 | T13: =[2]หน้าผ้า!X22 -> 0 | U13: =[2]หน้าผ้า!AA22 -> 0 | V13: =[2]หน้าผ้า!AJ22 -> 0 | W13: =[2]หน้าผ้า!AL22 -> 0 | X13: =[2]หน้าผ้า!AM22 -> 0 | Y13: =[2]หน้าผ้า!AN22 -> 0 | Z13: =[2]หน้าผ้า!AO22 -> WSWT1625800 | AA13: =[2]หน้าผ้า!AQ22 -> 3702.05 | AB13: =[2]หน้าผ้า!AR22 -> 682 | AC13: =[2]หน้าผ้า!AS22 -> 3020.05 | AD13: =[2]หน้าผ้า!AT22 -> 0 | AE13: =[2]หน้าผ้า!AU22 -> 0 | AF13: =[2]หน้าผ้า!AI22 -> ระบุในSD | AG13: =[3]หน้าผ้า!DC25 -> ยังไม่ได้พิมพ์ | AH13: =[2]หน้าผ้า!DL22 -> 0 | AI13: =[2]หน้าผ้า!DM22 -> Lead time | AJ13: =[2]หน้าผ้า!DN22 -> 0 | AK13: =[2]หน้าผ้า!DQ22 -> 0 | AL13: =[2]หน้าผ้า!DR22 -> 0 | AM13: =[2]หน้าผ้า!DS22 -> 0 | AN13: =[2]หน้าผ้า!DT22 -> 0 | AO13: =[2]หน้าผ้า!DU22 -> 0 | AP13: =[2]หน้าผ้า!DP22 -> 0 | AQ13: =[2]หน้าผ้า!DW22 -> 0 | AR13: =[2]หน้าผ้า!DX22 -> 0 | AS13: =[2]หน้าผ้า!DY22 -> 0 | AT13: =[2]หน้าผ้า!DZ22 -> 0 | AU13: =[2]หน้าผ้า!EA22 -> 0 | AV13: =[2]หน้าผ้า!EB22 -> 0 | AW13: =[2]หน้าผ้า!EC22 -> 0 | AX13: =[2]หน้าผ้า!ED22 -> 0 | AY13: =[2]หน้าผ้า!AG22 -> 0 | AZ13: =[2]หน้าผ้า!EG22 -> 0 | BA13: =[2]หน้าผ้า!EH22 -> 0 | BB13: =[2]หน้าผ้า!EI22 -> 0 | BC13: =[2]หน้าผ้า!BZ22 -> WRWT160800/WRWT25800 | BD13: =[2]หน้าผ้า!CA22 -> 0
A14: =[2]หน้าผ้า!C23 -> 0 | B14: =[2]หน้าผ้า!B23 -> 0 | C14: =[2]หน้าผ้า!E23 -> 0 | D14: =[2]หน้าผ้า!F23 -> 0 | E14: =[2]หน้าผ้า!G23 -> 16 | F14: =[2]หน้าผ้า!H23 -> 25 | G14: =[2]หน้าผ้า!I23 -> 0 | H14: =[2]หน้าผ้า!J23 -> 0 | I14: =[2]หน้าผ้า!L23 -> 47 | J14: =[2]หน้าผ้า!M23 -> ± | K14: =[2]หน้าผ้า!N23 -> 5 | L14: =[2]หน้าผ้า!R23 -> 0 | M14: =[2]หน้าผ้า!T23 -> 0 | N14: =[2]หน้าผ้า!U23 -> 0 | O14: =[2]หน้าผ้า!V23 -> 0 | P14: =[2]หน้าผ้า!AB23 -> 0 | Q14: =[2]หน้าผ้า!AC23 -> 0 | R14: =[2]หน้าผ้า!AD23 -> 0 | S14: =[2]หน้าผ้า!Z23 -> 0 | T14: =[2]หน้าผ้า!X23 -> 0 | U14: =[2]หน้าผ้า!AA23 -> 0 | V14: =[2]หน้าผ้า!AJ23 -> 0 | W14: =[2]หน้าผ้า!AL23 -> 0 | X14: =[2]หน้าผ้า!AM23 -> 0 | Y14: =[2]หน้าผ้า!AN23 -> 0 | Z14: =[2]หน้าผ้า!AO23 -> WSWT1621720SMFX | AA14: =[2]หน้าผ้า!AQ23 -> #REF! | AB14: =[2]หน้าผ้า!AR23 -> #REF! | AC14: =[2]หน้าผ้า!AS23 -> #REF! | AD14: =[2]หน้าผ้า!AT23 -> #REF! | AE14: =[2]หน้าผ้า!AU23 -> #REF! | AF14: =[2]หน้าผ้า!AI23 -> ระบุในSD | AG14: =[3]หน้าผ้า!DC26 -> พร้อมส่ง | AH14: =[2]หน้าผ้า!DL23 -> 0 | AI14: =[2]หน้าผ้า!DM23 -> 0 | AJ14: =[2]หน้าผ้า!DN23 -> 0 | AK14: =[2]หน้าผ้า!DQ23 -> 0 | AL14: =[2]หน้าผ้า!DR23 -> 0 | AM14: =[2]หน้าผ้า!DS23 -> 0 | AN14: =[2]หน้าผ้า!DT23 -> 0 | AO14: =[2]หน้าผ้า!DU23 -> 0 | AP14: =[2]หน้าผ้า!DP23 -> 0 | AQ14: =[2]หน้าผ้า!DW23 -> 0 | AR14: =[2]หน้าผ้า!DX23 -> 0 | AS14: =[2]หน้าผ้า!DY23 -> 0 | AT14: =[2]หน้าผ้า!DZ23 -> 0 | AU14: =[2]หน้าผ้า!EA23 -> 0 | AV14: =[2]หน้าผ้า!EB23 -> 0 | AW14: =[2]หน้าผ้า!EC23 -> 0 | AX14: =[2]หน้าผ้า!ED23 -> 0 | AY14: =[2]หน้าผ้า!AG23 -> 0 | AZ14: =[2]หน้าผ้า!EG23 -> 0 | BA14: =[2]หน้าผ้า!EH23 -> 0 | BB14: =[2]หน้าผ้า!EI23 -> 0 | BC14: =[2]หน้าผ้า!BZ23 -> WRWT160720/WRWT21720 | BD14: =[2]หน้าผ้า!CA23 -> 0
A15: =[2]หน้าผ้า!C24 -> 0 | B15: =[2]หน้าผ้า!B24 -> 0 | C15: =[2]หน้าผ้า!E24 -> 0 | D15: =[2]หน้าผ้า!F24 -> 0 | E15: =[2]หน้าผ้า!G24 -> 17 | F15: =[2]หน้าผ้า!H24 -> 26 | G15: =[2]หน้าผ้า!I24 -> 0 | H15: =[2]หน้าผ้า!J24 -> 0 | I15: =[2]หน้าผ้า!L24 -> 48 | J15: =[2]หน้าผ้า!M24 -> ± | K15: =[2]หน้าผ้า!N24 -> 5 | L15: =[2]หน้าผ้า!R24 -> 0 | M15: =[2]หน้าผ้า!T24 -> 0 | N15: =[2]หน้าผ้า!U24 -> 0 | O15: =[2]หน้าผ้า!V24 -> 0 | P15: =[2]หน้าผ้า!AB24 -> 0 | Q15: =[2]หน้าผ้า!AC24 -> 0 | R15: =[2]หน้าผ้า!AD24 -> 0 | S15: =[2]หน้าผ้า!Z24 -> 0 | T15: =[2]หน้าผ้า!X24 -> 0 | U15: =[2]หน้าผ้า!AA24 -> 0 | V15: =[2]หน้าผ้า!AJ24 -> 0 | W15: =[2]หน้าผ้า!AL24 -> 0 | X15: =[2]หน้าผ้า!AM24 -> 0 | Y15: =[2]หน้าผ้า!AN24 -> 0 | Z15: =[2]หน้าผ้า!AO24 -> WSWT1725800 | AA15: =[2]หน้าผ้า!AQ24 -> #REF! | AB15: =[2]หน้าผ้า!AR24 -> #REF! | AC15: =[2]หน้าผ้า!AS24 -> #REF! | AD15: =[2]หน้าผ้า!AT24 -> #REF! | AE15: =[2]หน้าผ้า!AU24 -> #REF! | AF15: =[2]หน้าผ้า!AI24 -> ระบุในSD | AG15: =[3]หน้าผ้า!DC27 -> ยังไม่ได้พิมพ์ | AH15: =[2]หน้าผ้า!DL24 -> 0 | AI15: =[2]หน้าผ้า!DM24 -> 0 | AJ15: =[2]หน้าผ้า!DN24 -> 0 | AK15: =[2]หน้าผ้า!DQ24 -> 0 | AL15: =[2]หน้าผ้า!DR24 -> 0 | AM15: =[2]หน้าผ้า!DS24 -> 0 | AN15: =[2]หน้าผ้า!DT24 -> 0 | AO15: =[2]หน้าผ้า!DU24 -> 0 | AP15: =[2]หน้าผ้า!DP24 -> 0 | AQ15: =[2]หน้าผ้า!DW24 -> 0 | AR15: =[2]หน้าผ้า!DX24 -> 0 | AS15: =[2]หน้าผ้า!DY24 -> 0 | AT15: =[2]หน้าผ้า!DZ24 -> 0 | AU15: =[2]หน้าผ้า!EA24 -> 0 | AV15: =[2]หน้าผ้า!EB24 -> 0 | AW15: =[2]หน้าผ้า!EC24 -> 0 | AX15: =[2]หน้าผ้า!ED24 -> 0 | AY15: =[2]หน้าผ้า!AG24 -> 0 | AZ15: =[2]หน้าผ้า!EG24 -> 0 | BA15: =[2]หน้าผ้า!EH24 -> 0 | BB15: =[2]หน้าผ้า!EI24 -> 0 | BC15: =[2]หน้าผ้า!BZ24 -> WRWT170800/WRWT25800 | BD15: =[2]หน้าผ้า!CA24 -> 0
A16: =[2]หน้าผ้า!C25 -> ประมาณการ | B16: =[2]หน้าผ้า!B25 -> ประมาณการ | C16: =[2]หน้าผ้า!E25 -> บจก.ฟาร์เธอร์ส วิง ซัพพลาย | D16: =[2]หน้าผ้า!F25 -> รถไฟ | E16: =[2]หน้าผ้า!G25 -> 18 | F16: =[2]หน้าผ้า!H25 -> 30 | G16: =[2]หน้าผ้า!I25 -> ขาว | H16: =[2]หน้าผ้า!J25 -> 0 | I16: =[2]หน้าผ้า!L25 -> 54 | J16: =[2]หน้าผ้า!M25 -> ± | K16: =[2]หน้าผ้า!N25 -> 5 | L16: =[2]หน้าผ้า!R25 -> บิด | M16: =[2]หน้าผ้า!T25 -> 19 | N16: =[2]หน้าผ้า!U25 -> 33 | O16: =[2]หน้าผ้า!V25 -> 40 | P16: =[2]หน้าผ้า!AB25 -> 232.02999 | Q16: =[2]หน้าผ้า!AC25 -> 0 | R16: =[2]หน้าผ้า!AD25 -> 232.02999 | S16: =[2]หน้าผ้า!Z25 -> 500กระสอบ | T16: =[2]หน้าผ้า!X25 -> รอแจ้ง | U16: =[2]หน้าผ้า!AA25 -> 15000 | V16: =[2]หน้าผ้า!AJ25 -> 0 | W16: =[2]หน้าผ้า!AL25 -> 15000 | X16: =[2]หน้าผ้า!AM25 -> 0 | Y16: =[2]หน้าผ้า!AN25 -> 15750 | Z16: =[2]หน้าผ้า!AO25 -> WSWT1825800 | AA16: =[2]หน้าผ้า!AQ25 -> 13201.65 | AB16: =[2]หน้าผ้า!AR25 -> 2599 | AC16: =[2]หน้าผ้า!AS25 -> 10602.65 | AD16: =[2]หน้าผ้า!AT25 -> 0 | AE16: =[2]หน้าผ้า!AU25 -> 0 | AF16: =[2]หน้าผ้า!AI25 -> 0 | AG16: =[3]หน้าผ้า!DC28 -> พร้อมส่ง | AH16: =[2]หน้าผ้า!DL25 -> P9 | AI16: =[2]หน้าผ้า!DM25 -> 3 | AJ16: =[2]หน้าผ้า!DN25 -> รอแจ้ง | AK16: =[2]หน้าผ้า!DQ25 -> 0 | AL16: =[2]หน้าผ้า!DR25 -> #VALUE! | AM16: =[2]หน้าผ้า!DS25 -> #VALUE! | AN16: =[2]หน้าผ้า!DT25 -> #VALUE! | AO16: =[2]หน้าผ้า!DU25 -> #VALUE! | AP16: =[2]หน้าผ้า!DP25 -> #VALUE! | AQ16: =[2]หน้าผ้า!DW25 -> #VALUE! | AR16: =[2]หน้าผ้า!DX25 -> 0 | AS16: =[2]หน้าผ้า!DY25 -> 0 | AT16: =[2]หน้าผ้า!DZ25 -> 0 | AU16: =[2]หน้าผ้า!EA25 -> 0 | AV16: =[2]หน้าผ้า!EB25 -> 0 | AW16: =[2]หน้าผ้า!EC25 -> งานพิมพ์ | AX16: =[2]หน้าผ้า!ED25 -> รอART | AY16: =[2]หน้าผ้า!AG25 -> 0 | AZ16: =[2]หน้าผ้า!EG25 -> 0 | BA16: =[2]หน้าผ้า!EH25 -> 0 | BB16: =[2]หน้าผ้า!EI25 -> 0 | BC16: =[2]หน้าผ้า!BZ25 -> WRWT25800/WRWT25800 | BD16: =[2]หน้าผ้า!CA25 -> 729.46232
A17: =[2]หน้าผ้า!C26 -> 0 | B17: =[2]หน้าผ้า!B26 -> 0 | C17: =[2]หน้าผ้า!E26 | D17: =[2]หน้าผ้า!F26 | E17: =[2]หน้าผ้า!G26 -> 18 | F17: =[2]หน้าผ้า!H26 -> 30 | G17: =[2]หน้าผ้า!I26 -> ขาว | H17: =[2]หน้าผ้า!J26 -> 0 | I17: =[2]หน้าผ้า!L26 -> 54 | J17: =[2]หน้าผ้า!M26 -> ± | K17: =[2]หน้าผ้า!N26 -> 5 | L17: =[2]หน้าผ้า!R26 -> 0 | M17: =[2]หน้าผ้า!T26 -> 0 | N17: =[2]หน้าผ้า!U26 -> 0 | O17: =[2]หน้าผ้า!V26 -> 0 | P17: =[2]หน้าผ้า!AB26 -> 0 | Q17: =[2]หน้าผ้า!AC26 -> 0 | R17: =[2]หน้าผ้า!AD26 -> 0 | S17: =[2]หน้าผ้า!Z26 -> 0 | T17: =[2]หน้าผ้า!X26 -> 0 | U17: =[2]หน้าผ้า!AA26 -> 0 | V17: =[2]หน้าผ้า!AJ26 -> 0 | W17: =[2]หน้าผ้า!AL26 -> 0 | X17: =[2]หน้าผ้า!AM26 -> 0 | Y17: =[2]หน้าผ้า!AN26 -> 0 | Z17: =[2]หน้าผ้า!AO26 -> WSWT1825800 | AA17: =[2]หน้าผ้า!AQ26 -> 13201.65 | AB17: =[2]หน้าผ้า!AR26 -> 2599 | AC17: =[2]หน้าผ้า!AS26 -> 10602.65 | AD17: =[2]หน้าผ้า!AT26 -> 0 | AE17: =[2]หน้าผ้า!AU26 -> 0 | AF17: =[2]หน้าผ้า!AI26 -> ระบุในSD | AG17: =[3]หน้าผ้า!DC29 -> ยังไม่ได้พิมพ์ | AH17: =[2]หน้าผ้า!DL26 -> 0 | AI17: =[2]หน้าผ้า!DM26 -> Lead time | AJ17: =[2]หน้าผ้า!DN26 -> 0 | AK17: =[2]หน้าผ้า!DQ26 -> 0 | AL17: =[2]หน้าผ้า!DR26 -> 0 | AM17: =[2]หน้าผ้า!DS26 -> 0 | AN17: =[2]หน้าผ้า!DT26 -> 0 | AO17: =[2]หน้าผ้า!DU26 -> 0 | AP17: =[2]หน้าผ้า!DP26 -> 0 | AQ17: =[2]หน้าผ้า!DW26 -> 0 | AR17: =[2]หน้าผ้า!DX26 -> 0 | AS17: =[2]หน้าผ้า!DY26 -> 0 | AT17: =[2]หน้าผ้า!DZ26 -> 0 | AU17: =[2]หน้าผ้า!EA26 -> 0 | AV17: =[2]หน้าผ้า!EB26 -> 0 | AW17: =[2]หน้าผ้า!EC26 -> 0 | AX17: =[2]หน้าผ้า!ED26 -> 0 | AY17: =[2]หน้าผ้า!AG26 -> 0 | AZ17: =[2]หน้าผ้า!EG26 -> 0 | BA17: =[2]หน้าผ้า!EH26 -> 0 | BB17: =[2]หน้าผ้า!EI26 -> 0 | BC17: =[2]หน้าผ้า!BZ26 -> WRWT25800/WRWT25800 | BD17: =[2]หน้าผ้า!CA26 -> 0
... A575: =[2]หน้าผ้า!C584 -> 0 | B575: =[2]หน้าผ้า!B584 -> 0 | C575: =[2]หน้าผ้า!E584 -> 0 | D575: =[2]หน้าผ้า!F584 -> 0 | E575: =[2]หน้าผ้า!G584 -> 0 | F575: =[2]หน้าผ้า!H584 -> 0 | G575: =[2]หน้าผ้า!I584 -> 0 | H575: =[2]หน้าผ้า!J584 -> 0 | I575: =[2]หน้าผ้า!L584 -> 0 | J575: =[2]หน้าผ้า!M584 -> 0 | K575: =[2]หน้าผ้า!N584 -> 0 | L575: =[2]หน้าผ้า!R584 -> 0 | M575: =[2]หน้าผ้า!T584 -> 0 | N575: =[2]หน้าผ้า!U584 -> 0 | O575: =[2]หน้าผ้า!V584 -> 0 | P575: =[2]หน้าผ้า!AB584 -> 0 | Q575: =[2]หน้าผ้า!AC584 -> 0 | R575: =[2]หน้าผ้า!AD584 -> 0 | S575: =[2]หน้าผ้า!Z584 -> 0 | T575: =[2]หน้าผ้า!X584 -> 0 | U575: =[2]หน้าผ้า!AA584 -> 0 | V575: =[2]หน้าผ้า!AJ584 -> 0 | W575: =[2]หน้าผ้า!AL584 -> 0 | X575: =[2]หน้าผ้า!AM584 -> 0 | Y575: =[2]หน้าผ้า!AN584 -> 0 | Z575: =[2]หน้าผ้า!AO584 -> 0 | AA575: =[2]หน้าผ้า!AQ584 -> 0 | AB575: =[2]หน้าผ้า!AR584 -> 0 | AC575: =[2]หน้าผ้า!AS584 -> 0 | AD575: =[2]หน้าผ้า!AT584 -> 0 | AE575: =[2]หน้าผ้า!AU584 -> 0 | AF575: =[2]หน้าผ้า!AI584 -> 0 | AG575: =[3]หน้าผ้า!DC587 -> 0 | AH575: =[2]หน้าผ้า!DL584 -> 0 | AI575: =[2]หน้าผ้า!DM584 -> 0 | AJ575: =[2]หน้าผ้า!DN584 -> 0 | AK575: =[2]หน้าผ้า!DQ584 -> 0 | AL575: =[2]หน้าผ้า!DR584 -> 0 | AM575: =[2]หน้าผ้า!DS584 -> 0 | AN575: =[2]หน้าผ้า!DT584 -> 0 | AO575: =[2]หน้าผ้า!DU584 -> 0 | AP575: =[2]หน้าผ้า!DP584 -> 0 | AQ575: =[2]หน้าผ้า!DW584 -> 0 | AR575: =[2]หน้าผ้า!DX584 -> 0 | AS575: =[2]หน้าผ้า!DY584 -> 0 | AT575: =[2]หน้าผ้า!DZ584 -> 0 | AU575: =[2]หน้าผ้า!EA584 -> 0 | AV575: =[2]หน้าผ้า!EB584 -> 0 | AW575: =[2]หน้าผ้า!EC584 -> 0 | AX575: =[2]หน้าผ้า!ED584 -> 0 | AY575: =[2]หน้าผ้า!AG584 -> 0 | AZ575: =[2]หน้าผ้า!EG584 -> 0 | BA575: =[2]หน้าผ้า!EH584 -> 0 | BB575: =[2]หน้าผ้า!EI584 -> 0 | BC575: =[2]หน้าผ้า!BZ584 -> 0 | BD575: =[2]หน้าผ้า!CA584 -> 0

Sheet 9(Order+FC)
A2: เลขที่ SO | B2: (หลายรายการ)
A3: วันส่ง | B3: (หลายรายการ)
A4: ชื่อลูกค้า | B4: (ทั้งหมด)
K5: 9
A6: ประเภท | B6: ผลรวม ของ จำนวนส่ง | C6: ผลรวม ของ ค้างพิมพ์ | D6: ผลรวม ของ ค้างตัด | E6: ผลรวม ของ ใช้ | F6: ผลรวม ของ Stock | G6: ผลรวม ของ ค้างทอ
A7: WSWT1625800SM | B7: 5000 | C7: 5250 | D7: 5000 | E7: 3702.05 | F7: 3702.05 | G7: 0 | H7: =+J7-I7 -> 0 | J7: =G7 -> 0
A8: WSWT1921720 | B8: 400000 | C8: 325500 | D8: 340500 | E8: 290156.9 | F8: 49840.6 | G8: 240316.3 | H8: =+J8-I8 -> 240316.3 | J8: =G8 -> 240316.3
A9: WSWT1925800 | B9: 150000 | C9: 157255.35 | D9: 149767 | E9: 132916.01 | F9: 24047 | G9: 108869.01 | H9: =+J9-I9 -> 108869.01 | J9: =G9 -> 108869.01
A10: WSWT2025800 | B10: 132454 | C10: 61161.45 | D10: 100138 | E10: 60641.797 | F10: 60641.797 | G10: 0 | H10: =+J10-I10 -> 0 | J10: =G10 -> 0
A11: WSWT2025800SM | B11: 316880 | C11: 303450 | D11: 291287 | E11: 309365.65 | F11: 57096.58 | G11: 252269.07 | H11: =+J11-I11 -> 252269.07 | J11: =G11 -> 252269.07
A12: WSWT2121670SM | B12: 152000 | C12: 124950 | D12: 119074 | E12: 128090.93 | F12: 128090.93 | G12: 0 | H12: =+J12-I12 -> 0 | J12: =G12 -> 0 | K12: 40000 | L12: =+K5*K12 -> 360000 | M12: =+L12-J12 -> 360000
A13: WSWT2325650 | B13: 60000 | C13: 63000 | D13: 60000 | E13: 59512.2 | F13: 27294 | G13: 32218.2 | H13: =+J13-I13 -> 32218.2 | J13: =G13 -> 32218.2 | K13: 14000 | L13: =+K13*K5 -> 126000 | M13: =+L13-J13 -> 93781.8
A14: WSWT2625650 | B14: 13000 | C14: 8400 | D14: 11200 | E14: 13120.624 | F14: 3621.024 | G14: 9499.6 | H14: =+J14-I14 -> 9499.6 | J14: =G14 -> 9499.6
A15: WSWT2625800 | B15: 10000 | C15: 0 | D15: 10000 | E15: 12433.3 | F15: 12433.3 | G15: 0 | H15: =+J15-I15 -> 0 | J15: =G15 -> 0 | K15: 20000 | L15: =+K15*K5 -> 180000 | M15: =+L15-J15 -> 180000
A16: WSWT2625850SM | B16: 90000 | C16: 59587.5 | D16: 90000 | E16: 109521.83 | F16: 72221.931 | G16: 37299.9 | H16: =+J16-I16 -> 37299.9 | J16: =G16 -> 37299.9
A17: WSWT2825850 | B17: 108000 | C17: 52500 | D17: 75159 | E17: 66147.95 | F17: 8265.45 | G17: 57882.5 | H17: =+J17-I17 -> 57882.5 | J17: =G17 -> 57882.5
A18: ผลรวมทั้งหมด | B18: 1437334 | C18: 1161054.3 | D18: 1252125 | E18: 1185609.2 | F18: 447254.66 | G18: 738354.58 | H18: =+J18-I18 -> 738354.58 | J18: =G18 -> 738354.58
H19: 0 | I19: 54000 | J19: =G19 -> 0
H20: =+J20-I20 -> 0 | J20: =G20 -> 0
H21: =+J21-I21 -> 0 | J21: =G21 -> 0
H22: =+J22-I22 -> 0 | J22: =G22 -> 0
H23: =+J23-I23 -> 0 | J23: =G23 -> 0
H24: =+J24-I24 -> 0 | J24: =G24 -> 0
H25: =+J25-I25 -> 0 | J25: =G25 -> 0
H26: =+J26-I26 -> 0 | J26: =G26 -> 0
H27: =+J27-I27 -> 0 | J27: =G27 -> 0
H28: =+J28-I28 -> 0 | J28: =G28 -> 0 | M28: =+GETPIVOTDATA("ผลรวม ของ ใช้",$A$6)+H29+H33 -> 2752318.4
H29: =SUM(H7:H28) -> 1476709.2 | I29: =SUM(I7:I28) -> 54000 | J29: =SUM(J7:J28) -> 1476709.2
H32: =+H26 -> 0 | I32: 85 | J32: =+(H32+H29)*I32 -> 1.2552028e+08 | K32: =+J32/1000 -> 125520.28
H33: 90000 | I33: 95 | J33: =+H33*I33 -> 8550000 | K33: =+J33/1000 -> 8550
H35: =+H32+H33+H29 -> 1566709.2 | K35: =+K32+K33 -> 134070.28
N36: 705222
A37: ยอดส่ง 1/2/68 - 17/2/68 | B37: 1565717 | H37: 15 | I37: =+H35/H37 -> 104447.28
N38: =+H35+N36 -> 2271931.2
I39: =+H37*110000 -> 1650000
B41: =+B29+B37+B31-110000 -> 1455717 | C41: =+C29+C37+C31 -> 0 | D41: =+D29+D37+D31-110000 -> -110000 | E41: =+E29+E37+E31 -> 0 | F41: =+F29+F37+F31 -> 0 | G41: =+G29+G37+G31 -> 0
B43: 3218150
B45: =+B43-B41 -> 1762433
C47: =+C41/9 -> 0 | D47: =+D41/9 -> -12222.222

Sheet 9(Order)
A2: เลขที่ SO | B2: (หลายรายการ)
A3: วันส่ง | B3: (หลายรายการ)
A4: ชื่อลูกค้า | B4: (ทั้งหมด)
A6: ประเภท | B6: ผลรวม ของ จำนวนส่ง | C6: ผลรวม ของ ค้างพิมพ์ | D6: ผลรวม ของ ค้างตัด | E6: ผลรวม ของ ใช้ | F6: ผลรวม ของ Stock | G6: ผลรวม ของ ค้างทอ
A7: WSWT1625800 | B7: 20000 | C7: 14978.25 | D7: 15000 | E7: 10719.841 | F7: 0 | G7: 10719.841 | I7: =+K7-J7 -> 10719.841 | K7: =G7 -> 10719.841
A8: WSWT1625800SM | B8: 5000 | C8: 5250 | D8: 5000 | E8: 3702.05 | F8: 3702.05 | G8: 0 | I8: =+K8-J8 -> 0 | K8: =G8 -> 0
A9: WSWT1825800SM | B9: 5000 | C9: 5250 | D9: 5000 | E9: 3841.75 | F9: 2000 | G9: 1841.75 | I9: =+K9-J9 -> 1841.75 | K9: =G9 -> 1841.75
A10: WSWT1921720 | B10: 130000 | C10: 42000 | D10: 70500 | E10: 37439.6 | F10: 37439.6 | G10: 0 | I10: =+K10-J10 -> 0 | K10: =G10 -> 0
A11: WSWT1925800 | B11: 90000 | C11: 94500 | D11: 90000 | E11: 79209.9 | F11: 24047 | G11: 55162.9 | I11: =+K11-J11 -> 55162.9 | K11: =G11 -> 55162.9
A12: WSWT2025800 | B12: 132454 | C12: 61161.45 | D12: 100138 | E12: 60641.797 | F12: 60641.797 | G12: 0 | I12: =+K12-J12 -> 0 | K12: =G12 -> 0
A13: WSWT2025800SM | B13: 176880 | C13: 156450 | D13: 151287 | E13: 161004.25 | F13: 57096.58 | G13: 103907.67 | I13: =+K13-J13 -> 103907.67 | K13: =G13 -> 103907.67
A14: WSWT2121670SM | B14: 52000 | C14: 19950 | D14: 19074 | E14: 20521.93 | F14: 20521.93 | G14: 0 | I14: =+K14-J14 -> 0 | K14: =G14 -> 0
A15: WSWT2325800 | B15: 5000 | C15: 0 | D15: 0 | E15: 0 | F15: 0 | G15: 0 | I15: =+K15-J15 -> 0 | K15: =G15 -> 0
A16: WSWT2625650 | B16: 5000 | C16: 0 | D16: 3200 | E16: 3621.024 | F16: 3621.024 | G16: 0 | I16: =+K16-J16 -> 0 | K16: =G16 -> 0
A17: WSWT2625850SM | B17: 90000 | C17: 59587.5 | D17: 90000 | E17: 109521.83 | F17: 72221.931 | G17: 37299.9 | I17: 0 | J17: 54000 | K17: =G17 -> 37299.9
A18: WSWT2825850 | B18: 53000 | C18: 0 | D18: 20159 | E18: 0 | F18: 0 | G18: 0 | I18: =+K18-J18 -> 0 | K18: =G18 -> 0
A19: ผลรวมทั้งหมด | B19: 764334 | C19: 459127.2 | D19: 569358 | E19: 490223.97 | F19: 281291.91 | G19: 208932.06 | I19: =+K19-J19 -> 208932.06 | K19: =G19 -> 208932.06
I20: =+K20-J20 -> 0 | K20: =G20 -> 0
I21: =+K21-J21 -> 0 | K21: =G21 -> 0
I22: =+K22-J22 -> 0 | K22: =G22 -> 0
I23: =+K23-J23 -> 0 | K23: =G23 -> 0
I24: =+K24-J24 -> 0 | K24: =G24 -> 0
I25: =+K25-J25 -> 0 | K25: =G25 -> 0
I26: =SUM(I7:I25) -> 380564.22 | J26: =SUM(J7:J25) -> 54000 | K26: =SUM(K7:K25) -> 417864.12
D34: =D18 -> 20159
D36: =D20 -> 0
A37: ยอดส่ง 1/4/68 - 12/4/68 | B37: 887615
A38: Order+ส่ง | B38: =++B25+B37 -> 887615
A39: ประมาณการ | B39: 262000 | C39: 238350 | D39: 262000 | E39: 279847.04 | F39: 60825.09 | G39: 219021.95
A41: Order+ส่ง+ประมาณการ | B41: =+B25+B37+B39+B33 -> 1149615 | C41: =+C25+C37+C39+C33 -> 238350 | D41: =+D25+D37+D39+D33 -> 262000 | E41: =+E25+E37+E39+E33 -> 279847.04 | F41: =+F25+F37+F39+F33 -> 60825.09 | G41: =+G25+G37+G39+G33 -> 219021.95
B43: 3171376
B45: =+B41-B43 -> -2021761 | C45: =+$B$45 -> -2021761 | D45: =+$B$45 -> -2021761 | F45: =+$B$45 -> -2021761
D47: =+D41/6 -> 43666.667

Sheet 9(Order) แยกลูกค้า
A1: เลขที่ SO | B1: (หลายรายการ)
A2: วันส่ง | B2: (หลายรายการ)
A4: ประเภท | B4: ชื่อลูกค้า | C4: ผลรวม ของ จำนวนส่ง | D4: ผลรวม ของ ค้างพิมพ์ | E4: ผลรวม ของ ค้างตัด | F4: ผลรวม ของ Stock | G4: ผลรวม ของ ค้างทอ | I4: vn
A5: WSWT2025800SM | B5: บจก.เอพีเอ็ม อะโกร | C5: 4000 | D5: 4200 | E5: 4000 | F5: 4414.52 | G5: 0 | H5: =G5 -> 0
B6: บจก.เอสพีเอ็ม อาหารสัตว์ | C6: 5000 | D6: 0 | E6: 527 | F6: 0 | G6: 0 | H6: =G6 -> 0
A7: WSWT2025800SM ผลรวม | C7: 9000 | D7: 4200 | E7: 4527 | F7: 4414.52 | G7: 0 | H7: =G7 -> 0
A8: WSWT2121670SM | B8: บจก.ที.ซี.ยูเนี่ยน อโกรเทค | C8: 16000 | D8: 16800 | E8: 16000 | F8: 17211.04 | G8: 0 | H8: =G8 -> 0
B9: บจก.เอพีเอ็ม อะโกร | C9: 3000 | D9: 3150 | E9: 3000 | F9: 3310.89 | G9: 0 | H9: =G9 -> 0
A10: WSWT2121670SM ผลรวม | C10: 19000 | D10: 19950 | E10: 19000 | F10: 20521.93 | G10: 0 | H10: =G10 -> 0
A11: WSWT2825850 | B11: บจก.ไทยร่วมใจน้ำมันพืช | C11: 3000 | D11: 0 | E11: 159 | F11: 0 | G11: 0 | H11: =G11 -> 0
A12: WSWT2825850 ผลรวม | C12: 3000 | D12: 0 | E12: 159 | F12: 0 | G12: 0 | H12: =G12 -> 0
A13: ผลรวมทั้งหมด | C13: 31000 | D13: 24150 | E13: 23686 | F13: 24936.45 | G13: 0 | H13: =G13 -> 0
H14: =G14 -> 0
H15: =G15 -> 0
H16: =G16 -> 0
H17: =G17 -> 0
H18: =G18 -> 0
H19: =G19 -> 0
H20: =G20 -> 0
H21: =G21 -> 0
H22: =G22 -> 0
H23: =G23 -> 0
H24: =G24 -> 0
H25: =G25 -> 0
... H65: =G65 -> 0
H70: =SUM(H5:H69) -> 0
D119: Cap พิมพ์ | E119: Cap ตัด | F119: Stock 16/7 บ่าย | G119: Cap ทอ | I119: วันทงาน
B120: lส่ง | C120: 1-16/7 | D120: 160000 | E120: 160000 | G120: 120000 | I120: 12
C121: 1975256 | D121: =+D120*I120 -> 1920000 | E121: =+E120*I120 -> 1920000 | F121: 825147 | G121: =+G120*I120 -> 1440000
A122: เบทาโกรส่งแล้ว | B122: 20700 | C122: 424374
A123: เบทาโกรส่งแล้ว | B123: 20800 | C123: 155973
C126: รวมส่ง+ค้างส่ง | D126: ส่วนต่างCapคงเหลือ | E126: ส่วนต่างCapคงเหลือ | F126: คงเหลือ
C127: =+C50+C121 -> 1975256 | D127: =+D121-D50 -> 1920000 | E127: =+E121-E50 -> 1920000 | F127: =+F121-F50 -> 825147 | G127: =+G121-G50 -> 1440000
B129: 20700VN 20/7 | G129: 350000

Sheet 9(Fc) แยกลูกค้า
A1: เลขที่ SO | B1: ประมาณการ
A2: วันส่ง | B2: (หลายรายการ) | D2: 12
A4: ประเภท | B4: ชื่อลูกค้า | C4: ผลรวม ของ จำนวนส่ง | D4: ผลรวม ของ ค้างพิมพ์ | E4: ผลรวม ของ ค้างตัด | F4: ผลรวม ของ ใช้ | G4: ผลรวม ของ Stock | H4: ผลรวม ของ ค้างทอ
A5: WSWT1921720 | B5: บจก.เคอรี่ฟลาวมิลล์ | C5: 270000 | D5: 283500 | E5: 270000 | F5: 252717.3 | G5: 12401 | H5: 240316.3
A6: WSWT1921720 ผลรวม | C6: 270000 | D6: 283500 | E6: 270000 | F6: 252717.3 | G6: 12401 | H6: 240316.3
A7: WSWT1925800 | B7: บจก.ไลม์มาสเตอร์ | C7: 20000 | D7: 20755.35 | E7: 19767 | F7: 18501.714 | G7: 0 | H7: 18501.714
B8: บจก.เอ็กเซลเล้นท์ | C8: 40000 | D8: 42000 | E8: 40000 | F8: 35204.4 | G8: 0 | H8: 35204.4
A9: WSWT1925800 ผลรวม | C9: 60000 | D9: 62755.35 | E9: 59767 | F9: 53706.114 | G9: 0 | H9: 53706.114
A10: WSWT2025800SM | B10: บจก.ไทยธรรมดี | C10: 20000 | D10: 21000 | E10: 20000 | F10: 21513.8 | G10: 0 | H10: 21513.8
B11: บจก.อินเทคค์ โกลบอล | C11: 100000 | D11: 105000 | E11: 100000 | F11: 104775 | G11: 0 | H11: 104775
B12: บจก.เอสพีเอ็ม อาหารสัตว์ | C12: 20000 | D12: 21000 | E12: 20000 | F12: 22072.6 | G12: 0 | H12: 22072.6
A13: WSWT2025800SM ผลรวม | C13: 140000 | D13: 147000 | E13: 140000 | F13: 148361.4 | G13: 0 | H13: 148361.4
A14: WSWT2121670SM | B14: บจก.แอมโก้เวท | C14: 100000 | D14: 105000 | E14: 100000 | F14: 107569 | G14: 107569 | H14: 0
A15: WSWT2121670SM ผลรวม | C15: 100000 | D15: 105000 | E15: 100000 | F15: 107569 | G15: 107569 | H15: 0
A16: WSWT2325650 | B16: พันธุ์ข้าว | C16: 30000 | D16: 31500 | E16: 30000 | F16: 29756.1 | G16: 27294 | H16: 2462.1
B17: บจก.ซิเบลโก้(สบปราบ) | C17: 30000 | D17: 31500 | E17: 30000 | F17: 29756.1 | G17: 0 | H17: 29756.1
A18: WSWT2325650 ผลรวม | C18: 60000 | D18: 63000 | E18: 60000 | F18: 59512.2 | G18: 27294 | H18: 32218.2
A19: WSWT2625650 | B19: บจก.กบินทร์อินทรีย์ | C19: 8000 | D19: 8400 | E19: 8000 | F19: 9499.6 | G19: 0 | H19: 9499.6
A20: WSWT2625650 ผลรวม | C20: 8000 | D20: 8400 | E20: 8000 | F20: 9499.6 | G20: 0 | H20: 9499.6
A21: WSWT2625800 | B21: บจก.ที.ซี.ยูเนี่ยน อโกรเทค | C21: 10000 | D21: 0 | E21: 10000 | F21: 12433.3 | G21: 12433.3 | H21: 0
A22: WSWT2625800 ผลรวม | C22: 10000 | D22: 0 | E22: 10000 | F22: 12433.3 | G22: 12433.3 | H22: 0
A23: WSWT2825850 | B23: บจก.ที.ซี.ยูเนี่ยน อโกรเทค | C23: 5000 | D23: 0 | E23: 5000 | F23: 6775.45 | G23: 6775.45 | H23: 0
A24: WSWT2825850 ผลรวม | C24: 5000 | D24: 0 | E24: 5000 | F24: 6775.45 | G24: 6775.45 | H24: 0
A25: ผลรวมทั้งหมด | C25: 653000 | D25: 669655.35 | E25: 652767 | F25: 650574.36 | G25: 166472.75 | H25: 484101.61
D119: Cap พิมพ์ | E119: Cap ตัด | F119: Stock 16/7 บ่าย | G119: Cap ทอ | I119: วันทงาน
B120: lส่ง | C120: 1-16/7 | D120: 160000 | E120: 160000 | G120: 120000 | I120: 12
C121: 1975256 | D121: =+D120*I120 -> 1920000 | E121: =+E120*I120 -> 1920000 | F121: 825147 | G121: =+G120*I120 -> 1440000
A122: เบทาโกรส่งแล้ว | B122: 20700 | C122: 424374
A123: เบทาโกรส่งแล้ว | B123: 20800 | C123: 155973
C126: รวมส่ง+ค้างส่ง | D126: ส่วนต่างCapคงเหลือ | E126: ส่วนต่างCapคงเหลือ | F126: คงเหลือ
C127: =+C50+C121 -> 1975256 | D127: =+D121-D50 -> 1920000 | E127: =+E121-E50 -> 1920000 | F127: =+F121-F50 -> 825147 | G127: =+G121-G50 -> 1440000
B129: 20700VN 20/7 | G129: 350000

Sheet 8(Order+Fc) แยกลูกค้า
A1: เลขที่ SO | B1: (หลายรายการ)
A2: วันส่ง | B2: (หลายรายการ) | D2: 12 | I2: เมตร | J2: vn | K2: ใบ | P2: วัน
A4: ประเภท | B4: ชื่อลูกค้า | C4: ผลรวม ของ จำนวนส่ง | D4: ผลรวม ของ ค้างพิมพ์ | E4: ผลรวม ของ ค้างตัด | F4: ผลรวม ของ ใช้ | G4: ผลรวม ของ Stock | H4: ผลรวม ของ ค้างทอ
A5: WSWT1921720 | B5: บจก.เคอรี่ฟลาวมิลล์ | C5: 215000 | D5: 57750 | E5: 155000 | F5: 99396.55 | G5: 99396.55 | H5: 0 | I5: =H5 -> 0
A6: WSWT1921720 ผลรวม | C6: 215000 | D6: 57750 | E6: 155000 | F6: 99396.55 | G6: 99396.55 | H6: 0
A7: WSWT19251000SM | B7: บจก.อินเทคค์ โกลบอล | C7: 10080 | D7: 10584 | E7: 10080 | F7: 10138.867 | G7: 5139.8424 | H7: 4999.0248 | I7: =H7 -> 4999.0248
A8: WSWT19251000SM ผลรวม | C8: 10080 | D8: 10584 | E8: 10080 | F8: 10138.867 | G8: 5139.8424 | H8: 4999.0248 | I8: =H8 -> 4999.0248
A9: WSWT1925800 | B9: บจก.ซีแมน | C9: 5800 | D9: 0 | E9: 0 | F9: 0 | G9: 0 | H9: 0 | I9: =H9 -> 0
A10: WSWT1925800 ผลรวม | C10: 5800 | D10: 0 | E10: 0 | F10: 0 | G10: 0 | H10: 0 | I10: =H10 -> 0
A11: WSWT2025650 | B11: บจก.หนกองบัวฟีด | C11: 5000 | D11: 0 | E11: 0 | F11: 0 | G11: 0 | H11: 0
A12: WSWT2025650 ผลรวม | C12: 5000 | D12: 0 | E12: 0 | F12: 0 | G12: 0 | H12: 0 | I12: =H12 -> 0
A13: WSWT2025800 | B13: บจก.เบทาโกร | C13: 103000 | D13: 0 | E13: 2000 | F13: 0 | G13: 0 | H13: 0
B14: บจก.อินเทคค์ โกลบอล | C14: 80393 | D14: 21155.4 | E14: 50393 | F14: 22144.982 | G14: 22144.982 | H14: 0 | I14: =H14 -> 0 | P14: 15000 | Q14: =+K14/P14 -> 0
A15: WSWT2025800 ผลรวม | C15: 183393 | D15: 21155.4 | E15: 52393 | F15: 22144.982 | G15: 22144.982 | H15: 0
A16: WSWT2025800SM | B16: บจก.อินเทคค์ โกลบอล | C16: 91933 | D16: 86964.15 | E16: 91933 | F16: 87478.167 | G16: 42098.068 | H16: 45380.099 | I16: =H16 -> 45380.099
B17: บจก.เอพีเอ็ม อะโกร | C17: 14000 | D17: 0 | E17: 10000 | F17: 0 | G17: 0 | H17: 0 | I17: =H17 -> 0
B18: บจก.วีซีเอฟ | C18: 20000 | D18: 0 | E18: 0 | F18: 0 | G18: 0 | H18: 0 | I18: =H18 -> 0
B19: บจก.กันยาวิ | C19: 8000 | D19: 8400 | E19: 8000 | F19: 8605.52 | G19: 8605.52 | H19: 0 | I19: =H19 -> 0
A20: WSWT2025800SM ผลรวม | C20: 133933 | D20: 95364.15 | E20: 109933 | F20: 96083.687 | G20: 50703.588 | H20: 45380.099 | I20: =H20 -> 45380.099 | P20: 16000 | Q20: =+K20/P20 -> 0
A21: WSWT2121670SM | B21: บจก.บลูฟาโล่ | C21: 5000 | D21: 0 | E21: 0 | F21: 0 | G21: 0 | H21: 0
B22: บจก.เอ็นบี ดิสทริบิวชั่น | C22: 30000 | D22: 0 | E22: 0 | F22: 0 | G22: 0 | H22: 0 | I22: =H22 -> 0
B23: บจก.หนองบัวฟีดมิลล์ | C23: 5000 | D23: 5250 | E23: 5000 | F23: 5378.45 | G23: 5378.45 | H23: 0
A24: WSWT2121670SM ผลรวม | C24: 40000 | D24: 5250 | E24: 5000 | F24: 5378.45 | G24: 5378.45 | H24: 0 | I24: =H24 -> 0
A25: WSWT2125650 | B25: บจก.หนองบัวฟีดมิลล์ | C25: 15000 | D25: 0 | E25: 15000 | F25: 16554.45 | G25: 16554.45 | H25: 0
A26: WSWT2125650 ผลรวม | C26: 15000 | D26: 0 | E26: 15000 | F26: 16554.45 | G26: 16554.45 | H26: 0 | I26: =H26 -> 0
A27: WSWT23211125120SMFX | B27: โรงสีธัญญกิจ(ราชบุรี) | C27: 10000 | D27: 0 | E27: 0 | F27: 0 | G27: 0 | H27: 0
A28: WSWT23211125120SMFX ผลรวม | C28: 10000 | D28: 0 | E28: 0 | F28: 0 | G28: 0 | H28: 0 | I28: =H28 -> 0
A29: WSWT2321750 | B29: คุณวัลภา เผ่าเต็ม | C29: 10000 | D29: 1560.3 | E29: 1500 | F29: 1678.3991 | G29: 0 | H29: 1678.3991 | I29: =H29 -> 1678.3991
A30: WSWT2321750 ผลรวม | C30: 10000 | D30: 1560.3 | E30: 1500 | F30: 1678.3991 | G30: 0 | H30: 1678.3991 | I30: =H30 -> 1678.3991
A31: WSWT2325650 | B31: พันธุ์ข้าว | C31: 30000 | D31: 31500 | E31: 30000 | F31: 29756.1 | G31: 29756.1 | H31: 0 | P31: 15000 | Q31: =+K31/P31 -> 0
B32: บจก.ซิเบลโก้(บางเลน) | C32: 10000 | D32: 0 | E32: 5000 | F32: 0 | G32: 0 | H32: 0 | I32: =H32 -> 0
B33: คุณปราสาท เจริญธรรมรักษา | C33: 5000 | D33: 5250 | E33: 5000 | F33: 4959.35 | G33: 4959.35 | H33: 0 | I33: =H33 -> 0
A34: WSWT2325650 ผลรวม | C34: 45000 | D34: 36750 | E34: 40000 | F34: 34715.45 | G34: 34715.45 | H34: 0 | I34: =H34 -> 0
A35: WSWT2625650 | B35: บจก.กบินทร์อินทรีย์ | C35: 8000 | D35: 8400 | E35: 8000 | F35: 9499.6 | G35: 1765 | H35: 7734.6 | I35: =H35 -> 7734.6
A36: WSWT2625650 ผลรวม | C36: 8000 | D36: 8400 | E36: 8000 | F36: 9499.6 | G36: 1765 | H36: 7734.6 | I36: =H36 -> 7734.6
A37: WSWT2625800 | B37: บจก.แลบอินเตอร์ | C37: 10000 | D37: 0 | E37: 0 | F37: 0 | G37: 0 | H37: 0 | I37: =H37 -> 0
A38: WSWT2625800 ผลรวม | C38: 10000 | D38: 0 | E38: 0 | F38: 0 | G38: 0 | H38: 0 | I38: =H38 -> 0
A39: WSWT2825850 | B39: บจก.ไทยร่วมใจน้ำมันพืช | C39: 53000 | D39: 52500 | E39: 50000 | F39: 59372.5 | G39: 59372.5 | H39: 0 | I39: =H39 -> 0
A40: WSWT2825850 ผลรวม | C40: 53000 | D40: 52500 | E40: 50000 | F40: 59372.5 | G40: 59372.5 | H40: 0 | I40: =H40 -> 0
A41: WSWTFCL022325650 | B41: คุณปราสาท เจริญธรรมรักษา | C41: 15000 | D41: 15750 | E41: 15000 | F41: 14878.05 | G41: 0 | H41: 14878.05
...

Sheet รายละเอียด1
A1: รายละเอียดสำหรับ ผลรวม ของ จำนวนส่ง - ประเภท: WSWT1925800, เลขที่ SO: MK66-000701, วันส่ง: 8/25/2025, ชื่อลูกค้า: 0 (+)
A3: วันรับออร์เดอร์/แบบ | B3: เลขที่ SO | C3: ชื่อลูกค้า | D3: ตรา | E3: กว้าง | F3: ยาว | G3: สี | H3: เคลือบ | I3: กรัม/ใบ | J3: * | K3: aw | L3: บิด/จับจีบ | M3: กว้าง2 | N3: ยาว2 | O3: หนา | P3: ใช้(กก.) | Q3: Stock(กก.) | R3: ผลิต(กก.) | S3: วิธีบรรจุ | T3: วันส่ง | U3: จำนวนส่ง | V3: StockFG | W3: ค้างตัด | X3: พิมพ์แล้ว | Y3: ค้างพิมพ์ | Z3: ประเภท | AA3: ใช้ | AB3: Stock | AC3: ค้างทอ | AD3: Stock2 | AE3: ค้างเคลือบ | AF3: หมายเหตุ
B4: MK68-001031 | C4: บจก.เอ็กเซลเล้นท์ | D4: รวงข้าวส้ม | E4: 19 | F4: 30 | G4: ขาว | H4: 0 | I4: 60 | J4: ± | K4: 5 | L4: บิด | M4: ไม่สวมถุงใน | N4: 0 | O4: 0 | P4: 0 | Q4: 0 | R4: 0 | S4: 500กระสอบ | T4: 45899 | U4: 5000 | V4: 0 | W4: 5000 | X4: 0 | Y4: 5150 | Z4: WSWT1925800 | AA4: 4401 | AB4: 0 | AC4: 4401 | AD4: 0 | AE4: 0 | AF4: 0

Sheet 8(Order)
A2: เลขที่ SO | B2: (หลายรายการ)
A3: วันส่ง | B3: (หลายรายการ)
A4: ชื่อลูกค้า | B4: (ทั้งหมด)
A6: ประเภท | B6: ผลรวม ของ จำนวนส่ง | C6: ผลรวม ของ ค้างพิมพ์ | D6: ผลรวม ของ ค้างตัด | E6: ผลรวม ของ ใช้ | F6: ผลรวม ของ Stock | G6: ผลรวม ของ ค้างทอ
A7: WSWT1921720 | B7: 90000 | C7: 0 | D7: 10250 | E7: 0 | F7: 0 | G7: 0
A8: WSWT19251000SM | B8: 10080 | C8: 5292 | D8: 10080 | E8: 5139.8424 | F8: 9833.8424 | G8: 0
A9: WSWT1925800 | B9: 5000 | C9: 5150 | D9: 5000 | E9: 4401 | F9: 0 | G9: 4401
A10: WSWT2025700 | B10: 10000 | C10: 10500 | D10: 10000 | E10: 10756.9 | F10: 5378 | G10: 5378.45
A11: WSWT2025800 | B11: 155513 | C11: 1598.1 | D11: 40153 | E11: 1674.4093 | F11: 1674.4093 | G11: 0 | L11: =76*2500 -> 190000
A12: WSWT2025800SM | B12: 112380 | C12: 53172 | D12: 66612 | E12: 53492.876 | F12: 41256.398 | G12: 12236.479
A13: WSWT2121670SM | B13: 42391 | C13: 0 | D13: 12465 | E13: 0 | F13: 0 | G13: 0
A14: WSWT2321750 | B14: 10000 | C14: 0 | D14: 242 | E14: 0 | F14: 0 | G14: 0
A15: WSWT2325650 | B15: 15000 | C15: 0 | D15: 5392 | E15: 0 | F15: 0 | G15: 0
A16: WSWT2825850 | B16: 3000 | C16: 0 | D16: 159 | E16: 0 | F16: 0 | G16: 0
A17: WSWTFCL022325650 | B17: 15000 | C17: 12951.75 | D17: 15000 | E17: 12350.517 | F17: 5012.8173 | G17: 7337.7
A18: ผลรวมทั้งหมด | B18: 468364 | C18: 88663.85 | D18: 175353 | E18: 87815.545 | F18: 63155.467 | G18: 29353.629
A37: ยอดส่ง 1/1/68 - 17/1/68 | B37: 1287052
A38: Order+ส่ง | B38: =++B22+B37 -> 1287052
A39: ประมาณการ | I39: 0
A41: Order+ส่ง+ประมาณการ | B41: =+B22+B37+B39+B29 -> 1287052 | C41: =+C22+C37+C39+C29 -> 0 | D41: =+D22+D37+D39+D29 -> 0 | E41: =+E22+E37+E39+E29 -> 0 | F41: =+F22+F37+F39+F29 -> 0 | G41: =+G22+G37+G39+G29 -> 0
B43: 3000000 | I43: 9
B45: =+B41-B43 -> -1712948
D46: =+D22/I43 -> 0
C47: =+C41/I43 -> 0 | D47: =+D41/I43 -> 0 | G47: =+G41/I43 -> 0

Sheet 8(Order) แยกลูกค้า
A1: เลขที่ SO | B1: (หลายรายการ)
A2: วันส่ง | B2: (หลายรายการ)
A4: ประเภท | B4: ชื่อลูกค้า | C4: ผลรวม ของ จำนวนส่ง | D4: ผลรวม ของ ค้างพิมพ์ | E4: ผลรวม ของ ค้างตัด | F4: ผลรวม ของ Stock | G4: ผลรวม ของ ค้างทอ | I4: vn
A5: WSWT1921720 | B5: บจก.เคอรี่ฟลาวมิลล์ | C5: 215000 | D5: 57750 | E5: 155000 | F5: 99396.55 | G5: 0 | H5: =G5 -> 0
A6: WSWT1921720 ผลรวม | C6: 215000 | D6: 57750 | E6: 155000 | F6: 99396.55 | G6: 0 | H6: =G6 -> 0
A7: WSWT1925800 | B7: บจก.ซีแมน | C7: 5800 | D7: 0 | E7: 0 | F7: 0 | G7: 0 | H7: =G7 -> 0
A8: WSWT1925800 ผลรวม | C8: 5800 | D8: 0 | E8: 0 | F8: 0 | G8: 0
A9: WSWT2025800 | B9: บจก.เบทาโกร | C9: 103000 | D9: 0 | E9: 2000 | F9: 0 | G9: 0 | H9: =G9 -> 0
B10: บจก.อินเทคค์ โกลบอล | C10: 393 | D10: 412.65 | E10: 393 | F10: 411.76575 | G10: 0 | H10: =G10 -> 0
A11: WSWT2025800 ผลรวม | C11: 103393 | D11: 412.65 | E11: 2393 | F11: 411.76575 | G11: 0
A12: WSWT2025800SM | B12: บจก.อินเทคค์ โกลบอล | C12: 1693 | D12: 1644.3 | E12: 1693 | F12: 0 | G12: 1640.7765 | H12: =G12 -> 1640.7765
B13: บจก.เอพีเอ็ม อะโกร | C13: 14000 | D13: 0 | E13: 10000 | F13: 0 | G13: 0 | H13: =G13 -> 0
B14: บจก.วีซีเอฟ | C14: 20000 | D14: 0 | E14: 0 | F14: 0 | G14: 0 | H14: =G14 -> 0
A15: WSWT2025800SM ผลรวม | C15: 35693 | D15: 1644.3 | E15: 11693 | F15: 0 | G15: 1640.7765
A16: WSWT2121670SM | B16: บจก.บลูฟาโล่ | C16: 5000 | D16: 0 | E16: 0 | F16: 0 | G16: 0 | H16: =G16 -> 0
B17: บจก.เอ็นบี ดิสทริบิวชั่น | C17: 30000 | D17: 0 | E17: 0 | F17: 0 | G17: 0
A18: WSWT2121670SM ผลรวม | C18: 35000 | D18: 0 | E18: 0 | F18: 0 | G18: 0 | H18: =G18 -> 0
A19: WSWT23211125120SMFX | B19: โรงสีธัญญกิจ(ราชบุรี) | C19: 10000 | D19: 0 | E19: 0 | F19: 0 | G19: 0 | H19: =G19 -> 0
A20: WSWT23211125120SMFX ผลรวม | C20: 10000 | D20: 0 | E20: 0 | F20: 0 | G20: 0 | H20: =G20 -> 0
A21: WSWT2325650 | B21: บจก.ซิเบลโก้(บางเลน) | C21: 10000 | D21: 0 | E21: 5000 | F21: 0 | G21: 0 | H21: =G21 -> 0
A22: WSWT2325650 ผลรวม | C22: 10000 | D22: 0 | E22: 5000 | F22: 0 | G22: 0
A23: WSWT2625800 | B23: บจก.แลบอินเตอร์ | C23: 10000 | D23: 0 | E23: 0 | F23: 0 | G23: 0 | H23: =G23 -> 0
A24: WSWT2625800 ผลรวม | C24: 10000 | D24: 0 | E24: 0 | F24: 0 | G24: 0
A25: WSWT2825850 | B25: บจก.ไทยร่วมใจน้ำมันพืช | C25: 53000 | D25: 52500 | E25: 50000 | F25: 59372.5 | G25: 0 | H25: =G25 -> 0
A26: WSWT2825850 ผลรวม | C26: 53000 | D26: 52500 | E26: 50000 | F26: 59372.5 | G26: 0
A27: ผลรวมทั้งหมด | C27: 477886 | D27: 112306.95 | E27: 224086 | F27: 159180.82 | G27: 1640.7765 | H27: =G27 -> 1640.7765
H28: =G28 -> 0
H29: =G29 -> 0
H31: =G31 -> 0
H32: =G32 -> 0
H33: =G33 -> 0
H34: =G34 -> 0
H35: =G35 -> 0
H36: =G36 -> 0
H37: =G37 -> 0
H38: =G38 -> 0
H39: =G39 -> 0
H41: =G41 -> 0
... H68: =G68 -> 0
H70: =SUM(H5:H69) -> 3281.553
...

Sheet 8(Fc) แยกลูกค้
A1: เลขที่ SO | B1: ประมาณการ
A2: วันส่ง | B2: (หลายรายการ) | D2: 12
A4: ประเภท | B4: ชื่อลูกค้า | C4: ผลรวม ของ จำนวนส่ง | D4: ผลรวม ของ ค้างพิมพ์ | E4: ผลรวม ของ ค้างตัด | F4: ผลรวม ของ ใช้ | G4: ผลรวม ของ Stock | H4: ผลรวม ของ ค้างทอ
A5: WSWT2325650 | B5: พันธุ์ข้าว | C5: 30000 | D5: 31500 | E5: 30000 | F5: 29756.1 | G5: 29756.1 | H5: 0
A6: WSWT2325650 ผลรวม | C6: 30000 | D6: 31500 | E6: 30000 | F6: 29756.1 | G6: 29756.1 | H6: 0
A7: WSWT2625650 | B7: บจก.กบินทร์อินทรีย์ | C7: 8000 | D7: 8400 | E7: 8000 | F7: 9499.6 | G7: 1765 | H7: 7734.6
A8: WSWT2625650 ผลรวม | C8: 8000 | D8: 8400 | E8: 8000 | F8: 9499.6 | G8: 1765 | H8: 7734.6
A9: ผลรวมทั้งหมด | C9: 38000 | D9: 39900 | E9: 38000 | F9: 39255.7 | G9: 31521.1 | H9: 7734.6
H43: =+GETPIVOTDATA("ผลรวม ของ ค้างทอ",$A$4)+H41 -> 7734.6
I119: วันทงาน
I120: 12
C121: 1975256 | D121: =+D120*I120 -> 0 | E121: =+E120*I120 -> 0 | F121: 825147 | G121: =+G120*I120 -> 0
A122: เบทาโกรส่งแล้ว | B122: 20700 | C122: 424374
A123: เบทาโกรส่งแล้ว | B123: 20800 | C123: 155973
C126: รวมส่ง+ค้างส่ง | D126: ส่วนต่างCapคงเหลือ | E126: ส่วนต่างCapคงเหลือ | F126: คงเหลือ
C127: =+C50+C121 -> 1975256 | D127: =+D121-D50 -> 0 | E127: =+E121-E50 -> 0 | F127: =+F121-F50 -> 825147 | G127: =+G121-G50 -> 0
B129: 20700VN 20/7 | G129: 350000

Sheet ค้างทอ2-9-68
A3: ผลรวม ของ ค้างทอ
A4: ป้ายชื่อแถว | B4: 45901 | C4: 45903 | D4: 45904 | E4: 45905 | F4: 45907 | G4: 45910 | H4: 45912 | I4: 45914 | J4: 45917 | K4: 45921 | L4: 45925 | M4: 45940 | N4: ผลรวมทั้งหมด
A5: WSWT1625800 | B5: 3702 | D5: 7404.1 | N5: =SUM(B5:M5) -> 11106.1
A6: WSWT1625800SM | C6: 0 | N6: =SUM(B6:M6) -> 0
A7: WSWT1825800SM | F7: 3841.75 | N7: =SUM(B7:M7) -> 3841.75
A8: WSWT1921720 | B8: 0 | D8: 4679.95 | N8: =SUM(B8:M8) -> 4679.95
A9: WSWT19251000SM | N9: =SUM(B9:M9) -> 0
A10: WSWT1925800 | E10: 55162.9 | N10: =SUM(B10:M10) -> 55162.9
A11: WSWT2025800 | B11: 0 | C11: 0 | G11: 0 | I11: 0 | J11: 0 | K11: 0 | N11: =SUM(B11:M11) -> 0
A12: WSWT2025800SM | C12: 0 | D12: 0 | E12: 0 | J12: 0 | L12: 4599.67 | N12: =SUM(B12:M12) -> 4599.67
A13: WSWT2121670SM | C13: 0 | K13: 0 | N13: =SUM(B13:M13) -> 0
A14: WSWT2325800 | D14: 0 | N14: =SUM(B14:M14) -> 0
A15: WSWT2625650 | B15: 1621 | N15: =SUM(B15:M15) -> 1621
A16: WSWT2625850SM | C16: 0 | D16: 0 | H16: 0 | L16: 37299.9 | M16: 12433.3 | N16: =SUM(B16:M16) -> 49733.2
A17: WSWT2825850 | D17: 0 | N17: =SUM(B17:M17) -> 0
A18: ผลรวมทั้งหมด | B18: =SUM(B5:B17) -> 5323 | C18: =SUM(C5:C17) -> 0 | D18: =SUM(D5:D17) -> 12084.05 | E18: =SUM(E5:E17) -> 55162.9 | F18: =SUM(F5:F17) -> 3841.75 | G18: =SUM(G5:G17) -> 0 | H18: =SUM(H5:H17) -> 0 | I18: =SUM(I5:I17) -> 0 | ... N18: =SUM(N5:N17) -> 130744.57

Sheet 5-9-68
B2: เรียงกำหนดส่ง | D2: ลบ 0 | T2: เรียง 1
B3: ข้อมูลUpdate ณ. วันที่ | D3: 45905 | E3: เวลา | G3: 10.33
A4: วันรับออร์เดอร์/แบบ | B4: เลขที่ SO | C4: ชื่อลูกค้า | E4: 10.3 | I4: น้ำหนัก | L4: บิด/จับจีบ | M4: ถุงใน | Q4: 44873 | S4: วิธีบรรจุ | T4: วันส่ง | U4: จำนวนส่ง | V4: ตัดเย็บ (ใบ) | W4: 44873 | X4: พิมพ์ (ใบ) | Y4: 44876 | Z4: ผ้าทอ (เมตร) Updateณ | AB4: 44876 | AD4: ผ้าเคลือบ(เมตร) | AF4: หมายเหตุ | AG4: เครื่อง
B5: เลขที่ SO | C5: ชื่อลูกค้า | D5: ตรา | E5: กว้าง | F5: ยาว | G5: สี | H5: เคลือบ | I5: กรัม/ใบ | J5: * | K5: aw | L5: บิด/จับจีบ | M5: กว้าง | N5: ยาว | O5: หนา | P5: ใช้(กก.) | Q5: Stock(กก.) | R5: ผลิต(กก.) | S5: วิธีบรรจุ | T5: วันส่ง | U5: จำนวนส่ง | V5: StockFG | W5: ค้างตัด | X5: พิมพ์แล้ว | Y5: ค้างพิมพ์ | Z5: ประเภท | AA5: ใช้ | AB5: Stock | AC5: ค้างทอ | AD5: Stock | AE5: ค้างเคลือบ | AF5: หมายเหตุ | AG5: ที่พิมพ์ได้ | AH5: process | AI5: Lead time | AJ5: วันที่ส่งPL | AK5: เคลือบ | AL5: ได้ ART | AM5: พิมพ์ | AN5: จีบ-บิด | AO5: ตัด-เย็บ | AP5: ทอ | AQ5: สวมถุง | AR5: เย็บปาก | AS5: PT | AT5: ม้วน | AU5: ตัด | AV5: ตอกตาไก่ | AW5: GROUP | AX5: ART | AY5: หมายเหตุปัญหา | AZ5: ราคา/ใบ | BA5: ราคารวม | BB5: workweek | BC5: เส้นเทป | BD5: จำนวน
A6: 45896 | B6: MK68-001041 | C6: บจก.ซัน ซีเมนต์ โพรเซส | D6: พระอาทิตย์ | E6: 16 | F6: 25 | G6: ขาว | H6: ใส | I6: 50 | J6: ± | K6: 5 | L6: บิด | M6: 19 | N6: 28 | O6: 40 | P6: 65.624643 | Q6: 0 | R6: 65.624643 | S6: 500กระสอบ | T6: 45908 | U6: 5000 | V6: 0 | W6: 5000 | X6: 0 | Y6: 5250 | Z6: WSWT1625800SM | AA6: 3702.05 | AB6: 3702.05 | AC6: 0 | AD6: 0 | AE6: 3702.05 | AF6: 0 | AG6: รอตัด | AH6: P8 | AI6: 4 | AJ6: 45908 | AK6: 45904 | AL6: 45898 | AM6: 45905 | AN6: 45906 | AO6: 45906 | AP6: 45903 | AQ6: 45907 | AR6: 0 | AS6: 0 | AT6: 0 | AU6: 0 | AV6: 0 | AW6: งานเคลือบ+พิมพ์ | AX6: / | AY6: รอลูกค้า | AZ6: 0 | BA6: 0 | BB6: 0 | BC6: WRWT25800/WRWT25800 | BD6: 0
A7: 0 | B7: 0 | C7: 0 | E7: 16 | F7: 25 | G7: ขาว | H7: 0 | I7: 45 | J7: ± | K7: 5 | L7: 0 | M7: 0 | N7: 0 | O7: 0 | P7: 0 | Q7: 0 | R7: 0 | S7: 0 | U7: 0 | V7: 0 | W7: 0 | X7: 0 | Y7: 0 | Z7: WSWT1625800SM | AA7: 3702.05 | AB7: 3702.05 | AC7: 0 | AD7: 0 | AE7: 3702.05 | AF7: ระบุในSD | AG7: ยังไม่ได้พิมพ์ | AH7: 0 | AI7: Lead time | AJ7: 0 | AK7: 0 | AL7: 0 | AM7: 0 | AN7: 0 | AO7: 0 | AP7: 0 | AQ7: 0 | AR7: 0 | AS7: 0 | AT7: 0 | AU7: 0 | AV7: 0 | AW7: 0 | AX7: 0 | AY7: 0 | AZ7: 0 | BA7: 0 | BB7: 0 | BC7: WRWT160800/WRWT25800 | BD7: 0
A8: 45897 | B8: MK68-001045 | C8: บจก.เคอรี่ฟลาวมิลล์ | D8: โบว์น้ำเงิน 10กก | E8: 16 | F8: 25 | G8: ขาว | H8: 0 | I8: 45 | J8: ± | K8: 5 | L8: ไม่ | M8: ไม่สวมถุงใน | N8: 0 | O8: 0 | P8: 0 | Q8: 0 | R8: 0 | S8: ห่ออัดเบลแบน500 | T8: 45909 | U8: 5000 | V8: 0 | W8: 5000 | X8: 5400 | Y8: 0 | Z8: WSWT1625800 | AA8: 0 | AB8: 0 | AC8: 0 | AD8: 0 | AE8: 0 | AF8: 0 | AG8: พร้อมส่ง | AH8: P7 | AI8: 2 | AJ8: 45909 | AK8: 0 | AL8: 45900 | AM8: 45907 | AN8: 45908 | AO8: 45908 | AP8: 45904 | AQ8: 0 | AR8: 0 | AS8: 0 | AT8: 0 | AU8: 0 | AV8: 0 | AW8: งานพิมพ์ | AX8: / | AY8: 0 | AZ8: 0 | BA8: 0 | BB8: 0 | BC8: WRWT25800/WRWT25800 | BD8: 0
A9: 45897 | B9: MK68-001045 | C9: บจก.เคอรี่ฟลาวมิลล์ | D9: โดนัทแฟนฉัน 10กก | E9: 16 | F9: 25 | G9: ขาว | H9: 0 | I9: 45 | J9: ± | K9: 5 | L9: ไม่ | M9: ไม่สวมถุงใน | N9: 0 | O9: 0 | P9: 0 | Q9: 0 | R9: 0 | S9: ห่ออัดเบลแบน500 | T9: 45909 | U9: 5000 | V9: 0 | W9: 5000 | X9: 5400 | Y9: 0 | Z9: WSWT1625800 | AA9: 0 | AB9: 0 | AC9: 0 | AD9: 0 | AE9: 0 | AF9: 0 | AG9: พร้อมส่ง | AH9: P7 | AI9: 2 | AJ9: 45909 | AK9: 0 | AL9: 45900 | AM9: 45907 | AN9: 45908 | AO9: 45908 | AP9: 45904 | AQ9: 0 | AR9: 0 | AS9: 0 | AT9: 0 | AU9: 0 | AV9: 0 | AW9: งานพิมพ์ | AX9: / | AY9: 0 | AZ9: 0 | BA9: 0 | BB9: 0 | BC9: WRWT25800/WRWT25800 | BD9: 0
A10: 45897 | B10: MK68-001045 | C10: บจก.เคอรี่ฟลาวมิลล์ | D10: น้องเอินโดนัท 10กก | E10: 16 | F10: 25 | G10: ขาว | H10: 0 | I10: 45 | J10: ± | K10: 5 | L10: ไม่ | M10: ไม่สวมถุงใน | N10: 0 | O10: 0 | P10: 0 | Q10: 0 | R10: 0 | S10: ห่ออัดเบลแบน500 | T10: 45925 | U10: 5000 | V10: 0 | W10: 5000 | X10: 0 | Y10: 5250 | Z10: WSWT1625800 | AA10: 3702.05 | AB10: 682 | AC10: 3020.05 | AD10: 0 | AE10: 0 | AF10: 0 | AG10: พร้อมส่ง | AH10: P7 | AI10: 2 | AJ10: 45925 | AK10: 0 | AL10: 45916 | AM10: 45923 | AN10: 45924 | AO10: 45924 | AP10: 45920 | AQ10: 0 | AR10: 0 | AS10: 0 | AT10: 0 | AU10: 0 | AV10: 0 | AW10: งานพิมพ์ | AX10: รอART | AY10: 0 | AZ10: 0 | BA10: 0 | BB10: 0 | BC10: WRWT25800/WRWT25800 | BD10: 184.69284
A11: 0 | B11: 0 | C11: 0 | D11: 0 | E11: 16 | F11: 25 | G11: ขาว | H11: 0 | I11: 45 | J11: ± | K11: 5 | L11: 0 | M11: 0 | N11: 0 | O11: 0 | P11: 0 | Q11: 0 | R11: 0 | S11: 0 | U11: 0 | V11: 0 | W11: 0 | X11: 0 | Y11: 0 | Z11: WSWT1625800 | AA11: 3702.05 | AB11: 682 | AC11: 3020.05 | AD11: 0 | AE11: 0 | AF11: ระบุในSD | AG11: ยังไม่ได้พิมพ์ | AH11: 0 | AI11: Lead time | AJ11: 0 | AK11: 0 | AL11: 0 | AM11: 0 | AN11: 0 | AO11: 0 | AP11: 0 | AQ11: 0 | AR11: 0 | AS11: 0 | AT11: 0 | AU11: 0 | AV11: 0 | AW11: 0 | AX11: 0 | AY11: 0 | AZ11: 0 | BA11: 0 | BB11: 0 | BC11: WRWT160800/WRWT25800 | BD11: 0
A12: ประมาณการ | B12: ประมาณการ | C12: บจก.ฟาร์เธอร์ส วิง ซัพพลาย | D12: รถไฟ | E12: 18 | F12: 30 | G12: ขาว | H12: 0 | I12: 54 | J12: ± | K12: 5 | L12: บิด | M12: 19 | N12: 33 | O12: 40 | P12: 232.02999 | Q12: 0 | R12: 232.02999 | S12: 500กระสอบ | T12: รอแจ้ง | U12: 15000 | V12: 0 | W12: 15000 | X12: 0 | Y12: 15750 | Z12: WSWT1825800 | AA12: 13201.65 | AB12: 2599 | AC12: 10602.65 | AD12: 0 | AE12: 0 | AF12: 0 | AG12: พร้อมส่ง | AH12: P9 | AI12: 3 | AJ12: รอแจ้ง | AK12: 0 | AL12: #VALUE! | AM12: #VALUE! | AN12: #VALUE! | AO12: #VALUE! | AP12: #VALUE! | AQ12: #VALUE! | AR12: 0 | AS12: 0 | AT12: 0 | AU12: 0 | AV12: 0 | AW12: งานพิมพ์ | AX12: รอART | AY12: 0 | AZ12: 0 | BA12: 0 | BB12: 0 | BC12: WRWT25800/WRWT25800 | BD12: 729.46232
A13: 0 | B13: 0 | E13: 18 | F13: 30 | G13: ขาว | H13: 0 | I13: 54 | J13: ± | K13: 5 | L13: 0 | M13: 0 | N13: 0 | O13: 0 | P13: 0 | Q13: 0 | R13: 0 | S13: 0 | U13: 0 | V13: 0 | W13: 0 | X13: 0 | Y13: 0 | Z13: WSWT1825800 | AA13: 13201.65 | AB13: 2599 | AC13: 10602.65 | AD13: 0 | AE13: 0 | AF13: ระบุในSD | AG13: ยังไม่ได้พิมพ์ | AH13: 0 | AI13: Lead time | AJ13: 0 | AK13: 0 | AL13: 0 | AM13: 0 | AN13: 0 | AO13: 0 | AP13: 0 | AQ13: 0 | AR13: 0 | AS13: 0 | AT13: 0 | AU13: 0 | AV13: 0 | AW13: 0 | AX13: 0 | AY13: 0 | AZ13: 0 | BA13: 0 | BB13: 0 | BC13: WRWT25800/WRWT25800 | BD13: 0
A14: 45901 | B14: MK68-001068 | C14: บจก.ยืนยงยิปซั่มปลาสเตอร์ | D14: YUENYONG | E14: 18 | F14: 26 | G14: ขาว | H14: ใส | I14: 65 | J14: ± | K14: 5 | L14: บิด | M14: 19 | N14: 29 | O14: 40 | P14: 67.96838 | Q14: 0 | R14: 67.96838 | S14: 500กระสอบแบน | T14: 45912 | U14: 5000 | V14: 0 | W14: 5000 | X14: 0 | Y14: 5250 | Z14: WSWT1825800SM | AA14: 3841.75 | AB14: 3841.75 | AC14: 0 | AD14: 0 | AE14: 3841.75 | AF14: 0 | AG14: พิมพ์ไม่ครบ | AH14: P8 | AI14: 4 | AJ14: 45912 | AK14: 45908 | AL14: 45902 | AM14: 45909 | AN14: 45910 | AO14: 45910 | AP14: 45907 | AQ14: 45911 | AR14: 0 | AS14: 0 | AT14: 0 | AU14: 0 | AV14: 0 | AW14: งานเคลือบ+พิมพ์ | AX14: / | AY14: 0 | AZ14: 0 | BA14: 0 | BB14: 0 | BC14: WRWT25800/WRWT25800 | BD14: 0
A15: 0 | B15: 0 | C15: 0 | E15: 18 | F15: 25 | G15: ขาว | H15: 0 | I15: 50 | J15: ± | K15: 5 | L15: 0 | M15: 0 | N15: 0 | O15: 0 | P15: 0 | Q15: 0 | R15: 0 | S15: 0 | U15: 0 | V15: 0 | W15: 0 | X15: 0 | Y15: 0 | Z15: WSWT1825800SM | AA15: 3841.75 | AB15: 3841.75 | AC15: 0 | AD15: 0 | AE15: 3841.75 | AF15: ระบุในSD | AG15: รอแบบ | AH15: 0 | AI15: Lead time | AJ15: 0 | AK15: 0 | AL15: 0 | AM15: 0 | AN15: 0 | AO15: 0 | AP15: 0 | AQ15: 0 | AR15: 0 | AS15: 0 | AT15: 0 | AU15: 0 | AV15: 0 | AW15: 0 | AX15: 0 | AY15: 0 | AZ15: 0 | BA15: 0 | BB15: 0 | BC15: WRWT180800/WRWT25800 | BD15: 0
A16: 45898 | B16: MK68-001049 | C16: บจก.เพรซิเดนท์ฟลาวมิลล์ | D16: ผึ้งเหลือง | E16: 19 | F16: 30 | G16: ขาว | H16: 0 | I16: 60 | J16: ± | K16: 5 | L16: บิด | M16: ไม่สวมถุงใน | N16: 0 | O16: 0 | P16: 0 | Q16: 0 | R16: 0 | S16: 500กระสอบ | T16: 45910 | U16: 50000 | V16: 0 | W16: 50000 | X16: 0 | Y16: 52500 | Z16: WSWT1925800 | AA16: 44005.5 | AB16: 0 | AC16: 44005.5 | AD16: 0 | AE16: 0 | AF16: 0 | AG16: ยังไม่ได้พิมพ์ | AH16: P7 | AI16: 2 | AJ16: 45910 | AK16: 0 | AL16: 45901 | AM16: 45908 | AN16: 45909 | AO16: 45909 | AP16: 45905 | AQ16: 0 | AR16: 0 | AS16: 0 | AT16: 0 | AU16: 0 | AV16: 0 | AW16: งานพิมพ์ | AX16: / | AY16: 0 | AZ16: 0 | BA16: 0 | BB16: 0 | BC16: WRWT25800/WRWT25800 | BD16: 3195.7772
A17: 45898 | B17: MK68-001048 | C17: บจก.เพรซิเดนท์ฟลาวมิลล์ | D17: ผึ้งชมพู | E17: 19 | F17: 30 | G17: ขาว | H17: 0 | I17: 60 | J17: ± | K17: 5 | L17: บิด | M17: ไม่สวมถุงใน | N17: 0 | O17: 0 | P17: 0 | Q17: 0 | R17: 0 | S17: 500กระสอบ | T17: 45910 | U17: 40000 | V17: 0 | W17: 40000 | X17: 9335 | Y17: 32198.25 | Z17: WSWT1925800 | AA17: 28338.002 | AB17: 24908 | AC17: 3430.0018 | AD17: 0 | AE17: 0 | AF17: 0 | AG17: พร้อมส่ง | AH17: P7 | AI17: 2 | AJ17: 45910 | AK17: 0 | AL17: 45901 | AM17: 45908 | AN17: 45909 | AO17: 45909 | AP17: 45905 | AQ17: 0 | AR17: 0 | AS17: 0 | AT17: 0 | AU17: 0 | AV17: 0 | AW17: งานพิมพ์ | AX17: / | AY17: 0 | AZ17: 0 | BA17: 0 | BB17: 0 | BC17: WRWT25800/WRWT25800 | BD17: 249.09435
A18: ประมาณการ | B18: ประมาณการ | C18: บจก.เอ็กเซลเล้นท์ | D18: รอแบบ | E18: 19 | F18: 30 | G18: ขาว | H18: 0 | I18: 60 | J18: ± | K18: 5 | L18: บิด | M18: ไม่สวมถุงใน | N18: 0 | O18: 0 | P18: 0 | Q18: 0 | R18: 0 | S18: 500กระสอบ | T18: 45925 | U18: 40000 | V18: 0 | W18: 40000 | X18: 0 | Y18: 42000 | Z18: WSWT1925800 | AA18: 35204.4 | AB18: 0 | AC18: 35204.4 | AD18: 0 | AE18: 0 | AF18: 0 | AG18: พร้อมส่ง | AH18: P7 | AI18: 2 | AJ18: 45925 | AK18: 0 | AL18: 45916 | AM18: 45923 | AN18: 45924 | AO18: 45924 | AP18: 45920 | AQ18: 0 | AR18: 0 | AS18: 0 | AT18: 0 | AU18: 0 | AV18: 0 | AW18: งานพิมพ์ | AX18: รอART | AY18: 0 | AZ18: 0 | BA18: 0 | BB18: 0 | BC18: WRWT25800/WRWT25800 | BD18: 2556.6218
A19: ประมาณการ | B19: ประมาณการ | C19: บจก.ไลม์มาสเตอร์ | D19: LMC 25 kg | E19: 19 | F19: 32 | G19: ขาว | H19: 0 | I19: 64 | J19: ± | K19: 5 | L19: ไม่ | M19: 20 | N19: 35 | O19: 40 | P19: 341.36903 | Q19: 0 | R19: 341.36903 | S19: 500กระสอบแบน | T19: 45925 | U19: 20000 | V19: 233 | W19: 19767 | X19: 0 | Y19: 20755.35 | Z19: WSWT1925800 | AA19: 18501.714 | AB19: 0 | AC19: 18501.714 | AD19: 0 | AE19: 0 | AF19: 0 | AG19: พร้อมส่ง | AH19: P9 | AI19: 3 | AJ19: 45925 | AK19: 0 | AL19: 45915 | AM19: 45922 | AN19: 45923 | AO19: 45923 | AP19: 45920 | AQ19: 45924 | AR19: 0 | AS19: 0 | AT19: 0 | AU19: 0 | AV19: 0 | AW19: งานพิมพ์ | AX19: รอART | AY19: 0 | AZ19: 0 | BA19: 0 | BB19: 0 | BC19: WRWT25800/WRWT25800 | BD19: 1343.6356
A20: 0 | B20: 0 | C20: 0 | D20: 0 | E20: 19 | F20: 30 | G20: ขาว | H20: 0 | I20: 60 | J20: ± | K20: 5 | L20: 0 | M20: 0 | N20: 0 | O20: 0 | P20: 0 | Q20: 0 | R20: 0 | S20: 0 | U20: 0 | V20: 0 | W20: 0 | X20: 0 | Y20: 0 | Z20: WSWT1925800 | AA20: 126049.62 | AB20: 24908 | AC20: 101141.62 | AD20: 0 | AE20: 0 | AF20: ระบุในSD | AG20: พร้อมส่ง | AH20: 0 | AI20: Lead time | AJ20: 0 | AK20: 0 | AL20: 0 | AM20: 0 | AN20: 0 | AO20: 0 | AP20: 0 | AQ20: 0 | AR20: 0 | AS20: 0 | AT20: 0 | AU20: 0 | AV20: 0 | AW20: 0 | AX20: 0 | AY20: 0 | AZ20: 0 | BA20: 0 | BB20: 0 | BC20: WRWT25800/WRWT25800 | BD20: 0
