Workbook

Sheet Linkสูตรออร์เดอร์  (2)
B2: เรียงกำหนดส่ง | D2: ลบ 0 | T2: เรียง 1
B3: ข้อมูลUpdate ณ. วันที่ | D3: 45924 | E3: เวลา | G3: 12
A4: วันรับออร์เดอร์/แบบ | B4: เลขที่ SO | C4: ชื่อลูกค้า | E4: 10.3 | I4: น้ำหนัก | L4: บิด/จับจีบ | M4: ถุงใน | Q4: =[1]หน้าผ้า!$AC$13 -> 44873 | S4: วิธีบรรจุ | T4: วันส่ง | U4: จำนวนส่ง | V4: ตัดเย็บ (ใบ) | W4: =[1]หน้าผ้า!$AJ$13 -> 44873 | X4: พิมพ์ (ใบ) | Y4: =[1]หน้าผ้า!$AM$13 -> 44876 | Z4: ผ้าทอ (เมตร) Updateณ | AB4: =[1]หน้าผ้า!$AR$12 -> 44876 | AD4: ผ้าเคลือบ(เมตร) | AF4: หมายเหตุ | AG4: เครื่อง
B5: เลขที่ SO | C5: ชื่อลูกค้า | D5: ตรา | E5: กว้าง | F5: ยาว | G5: สี | H5: เคลือบ | I5: กรัม/ใบ | J5: * | K5: aw | L5: บิด/จับจีบ | M5: กว้าง | N5: ยาว | O5: หนา | P5: ใช้(กก.) | Q5: Stock(กก.) | R5: ผลิต(กก.) | S5: วิธีบรรจุ | T5: วันส่ง | U5: จำนวนส่ง | V5: StockFG | W5: ค้างตัด | X5: พิมพ์แล้ว | Y5: ค้างพิมพ์ | Z5: ประเภท | AA5: ใช้ | AB5: Stock | AC5: ค้างทอ | AD5: Stock | AE5: ค้างเคลือบ | AF5: หมายเหตุ | AG5: ที่พิมพ์ได้ | AH5: process | AI5: Lead time | AJ5: วันที่ส่งPL | AK5: เคลือบ | AL5: ได้ ART | AM5: พิมพ์ | AN5: จีบ-บิด | AO5: ตัด-เย็บ | AP5: ทอ | AQ5: สวมถุง | AR5: เย็บปาก | AS5: PT | AT5: ม้วน | AU5: ตัด | AV5: ตอกตาไก่ | AW5: GROUP | AX5: ART | AY5: หมายเหตุปัญหา | AZ5: ราคา/ใบ | BA5: ราคารวม | BB5: workweek | BC5: เส้นเทป | BD5: จำนวน
A6: =[2]หน้าผ้า!C15 -> 0 | B6: =[2]หน้าผ้า!B15 -> 0 | C6: =[2]หน้าผ้า!E15 -> 0 | D6: =[2]หน้าผ้า!F15 -> 0 | E6: =[2]หน้าผ้า!G15 -> 12 | F6: =[2]หน้าผ้า!H15 -> 16 | G6: =[2]หน้าผ้า!I15 -> ขาว | H6: =[2]หน้าผ้า!J15 -> 0 | I6: =[2]หน้าผ้า!L15 -> 25 | J6: =[2]หน้าผ้า!M15 -> ± | K6: =[2]หน้าผ้า!N15 -> 5 | L6: =[2]หน้าผ้า!R15 -> 0 | M6: =[2]หน้าผ้า!T15 -> 0 | N6: =[2]หน้าผ้า!U15 -> 0 | O6: =[2]หน้าผ้า!V15 -> 0 | P6: =[2]หน้าผ้า!AB15 -> 0 | Q6: =[2]หน้าผ้า!AC15 -> 0 | R6: =[2]หน้าผ้า!AD15 -> 0 | S6: =[2]หน้าผ้า!Z15 -> 0 | T6: =[2]หน้าผ้า!X15 -> 0 | U6: =[2]หน้าผ้า!AA15 -> 0 | V6: =[2]หน้าผ้า!AJ15 -> 0 | W6: =[2]หน้าผ้า!AL15 -> 0 | X6: =[2]หน้าผ้า!AM15 -> 0 | Y6: =[2]หน้าผ้า!AN15 -> 0 | Z6: =[2]หน้าผ้า!AO15 -> WSWT1221750 | AA6: =[2]หน้าผ้า!AQ15 -> #REF! | AB6: =[2]หน้าผ้า!AR15 -> #REF! | AC6: =[2]หน้าผ้า!AS15 -> #REF! | AD6: =[2]หน้าผ้า!AT15 -> #REF! | AE6: =[2]หน้าผ้า!AU15 -> #REF! | AF6: =[2]หน้าผ้า!AI15 -> ระบุในSD | AG6: =[3]หน้าผ้า!DC18 -> < Ord 20,000 | AH6: =[2]หน้าผ้า!DL15 -> 0 | AI6: =[2]หน้าผ้า!DM15 -> 0 | AJ6: =[2]หน้าผ้า!DN15 -> 0 | AK6: =[2]หน้าผ้า!DQ15 -> 0 | AL6: =[2]หน้าผ้า!DR15 -> 0 | AM6: =[2]หน้าผ้า!DS15 -> 0 | AN6: =[2]หน้าผ้า!DT15 -> 0 | AO6: =[2]หน้าผ้า!DU15 -> 0 | AP6: =[2]หน้าผ้า!DP15 -> 0 | AQ6: =[2]หน้าผ้า!DW15 -> 0 | AR6: =[2]หน้าผ้า!DX15 -> 0 | AS6: =[2]หน้าผ้า!DY15 -> 0 | AT6: =[2]หน้าผ้า!DZ15 -> 0 | AU6: =[2]หน้าผ้า!EA15 -> 0 | AV6: =[2]หน้าผ้า!EB15 -> 0 | AW6: =[2]หน้าผ้า!EC15 -> 0 | AX6: =[2]หน้าผ้า!ED15 -> 0 | AY6: =[2]หน้าผ้า!AG15 -> 0 | AZ6: =[2]หน้าผ้า!EG15 -> 0 | BA6: =[2]หน้าผ้า!EH15 -> 0 | BB6: =[2]หน้าผ้า!EI15 -> 0 | BC6: =[2]หน้าผ้า!BZ15 -> WRWT120750/WRWT21750 | BD6: =[2]หน้าผ้า!CA15 -> 0
A7: =[2]หน้าผ้า!C16 -> 0 | B7: =[2]หน้าผ้า!B16 -> 0 | C7: =[2]หน้าผ้า!E16 -> 0 | D7: =[2]หน้าผ้า!F16 -> 0 | E7: =[2]หน้าผ้า!G16 -> 14 | F7: =[2]หน้าผ้า!H16 -> 22 | G7: =[2]หน้าผ้า!I16 -> ขาว | H7: =[2]หน้าผ้า!J16 -> 0 | I7: =[2]หน้าผ้า!L16 -> 36 | J7: =[2]หน้าผ้า!M16 -> ± | K7: =[2]หน้าผ้า!N16 -> 5 | L7: =[2]หน้าผ้า!R16 -> 0 | M7: =[2]หน้าผ้า!T16 -> 0 | N7: =[2]หน้าผ้า!U16 -> 0 | O7: =[2]หน้าผ้า!V16 -> 0 | P7: =[2]หน้าผ้า!AB16 -> 0 | Q7: =[2]หน้าผ้า!AC16 -> 0 | R7: =[2]หน้าผ้า!AD16 -> 0 | S7: =[2]หน้าผ้า!Z16 -> 0 | T7: =[2]หน้าผ้า!X16 -> 0 | U7: =[2]หน้าผ้า!AA16 -> 0 | V7: =[2]หน้าผ้า!AJ16 -> 0 | W7: =[2]หน้าผ้า!AL16 -> 0 | X7: =[2]หน้าผ้า!AM16 -> 0 | Y7: =[2]หน้าผ้า!AN16 -> 0 | Z7: =[2]หน้าผ้า!AO16 -> WSWT1425800 | AA7: =[2]หน้าผ้า!AQ16 -> #REF! | AB7: =[2]หน้าผ้า!AR16 -> #REF! | AC7: =[2]หน้าผ้า!AS16 -> #REF! | AD7: =[2]หน้าผ้า!AT16 -> #REF! | AE7: =[2]หน้าผ้า!AU16 -> #REF! | AF7: =[2]หน้าผ้า!AI16 -> ระบุในSD | AG7: =[3]หน้าผ้า!DC19 -> พร้อมส่ง | AH7: =[2]หน้าผ้า!DL16 -> 0 | AI7: =[2]หน้าผ้า!DM16 -> Lead time | AJ7: =[2]หน้าผ้า!DN16 -> 0 | AK7: =[2]หน้าผ้า!DQ16 -> 0 | AL7: =[2]หน้าผ้า!DR16 -> 0 | AM7: =[2]หน้าผ้า!DS16 -> 0 | AN7: =[2]หน้าผ้า!DT16 -> 0 | AO7: =[2]หน้าผ้า!DU16 -> 0 | AP7: =[2]หน้าผ้า!DP16 -> 0 | AQ7: =[2]หน้าผ้า!DW16 -> 0 | AR7: =[2]หน้าผ้า!DX16 -> 0 | AS7: =[2]หน้าผ้า!DY16 -> 0 | AT7: =[2]หน้าผ้า!DZ16 -> 0 | AU7: =[2]หน้าผ้า!EA16 -> 0 | AV7: =[2]หน้าผ้า!EB16 -> 0 | AW7: =[2]หน้าผ้า!EC16 -> 0 | AX7: =[2]หน้าผ้า!ED16 -> 0 | AY7: =[2]หน้าผ้า!AG16 -> 0 | AZ7: =[2]หน้าผ้า!EG16 -> 0 | BA7: =[2]หน้าผ้า!EH16 -> 0 | BB7: =[2]หน้าผ้า!EI16 -> 0 | BC7: =[2]หน้าผ้า!BZ16 -> WRWT140800/WRWT25800 | BD7: =[2]หน้าผ้า!CA16 -> 0
A8: =[2]หน้าผ้า!C17 -> 0 | B8: =[2]หน้าผ้า!B17 -> 0 | C8: =[2]หน้าผ้า!E17 -> 0 | D8: =[2]หน้าผ้า!F17 | E8: =[2]หน้าผ้า!G17 -> 16 | F8: =[2]หน้าผ้า!H17 -> 25 | G8: =[2]หน้าผ้า!I17 -> ขาว | H8: =[2]หน้าผ้า!J17 -> 0 | I8: =[2]หน้าผ้า!L17 -> 45 | J8: =[2]หน้าผ้า!M17 -> ± | K8: =[2]หน้าผ้า!N17 -> 5 | L8: =[2]หน้าผ้า!R17 -> 0 | M8: =[2]หน้าผ้า!T17 -> 0 | N8: =[2]หน้าผ้า!U17 -> 0 | O8: =[2]หน้าผ้า!V17 -> 0 | P8: =[2]หน้าผ้า!AB17 -> 0 | Q8: =[2]หน้าผ้า!AC17 -> 0 | R8: =[2]หน้าผ้า!AD17 -> 0 | S8: =[2]หน้าผ้า!Z17 -> 0 | T8: =[2]หน้าผ้า!X17 -> 0 | U8: =[2]หน้าผ้า!AA17 -> 0 | V8: =[2]หน้าผ้า!AJ17 -> 0 | W8: =[2]หน้าผ้า!AL17 -> 0 | X8: =[2]หน้าผ้า!AM17 -> 0 | Y8: =[2]หน้าผ้า!AN17 -> 0 | Z8: =[2]หน้าผ้า!AO17 -> WSWT1625800SM | AA8: =[2]หน้าผ้า!AQ17 -> #REF! | AB8: =[2]หน้าผ้า!AR17 -> #REF! | AC8: =[2]หน้าผ้า!AS17 -> #REF! | AD8: =[2]หน้าผ้า!AT17 -> #REF! | AE8: =[2]หน้าผ้า!AU17 -> #REF! | AF8: =[2]หน้าผ้า!AI17 -> ระบุในSD | AG8: =[3]หน้าผ้า!DC20 -> พร้อมส่ง | AH8: =[2]หน้าผ้า!DL17 -> 0 | AI8: =[2]หน้าผ้า!DM17 -> Lead time | AJ8: =[2]หน้าผ้า!DN17 -> 0 | AK8: =[2]หน้าผ้า!DQ17 -> 0 | AL8: =[2]หน้าผ้า!DR17 -> 0 | AM8: =[2]หน้าผ้า!DS17 -> 0 | AN8: =[2]หน้าผ้า!DT17 -> 0 | AO8: =[2]หน้าผ้า!DU17 -> 0 | AP8: =[2]หน้าผ้า!DP17 -> 0 | AQ8: =[2]หน้าผ้า!DW17 -> 0 | AR8: =[2]หน้าผ้า!DX17 -> 0 | AS8: =[2]หน้าผ้า!DY17 -> 0 | AT8: =[2]หน้าผ้า!DZ17 -> 0 | AU8: =[2]หน้าผ้า!EA17 -> 0 | AV8: =[2]หน้าผ้า!EB17 -> 0 | AW8: =[2]หน้าผ้า!EC17 -> 0 | AX8: =[2]หน้าผ้า!ED17 -> 0 | AY8: =[2]หน้าผ้า!AG17 -> 0 | AZ8: =[2]หน้าผ้า!EG17 -> 0 | BA8: =[2]หน้าผ้า!EH17 -> 0 | BB8: =[2]หน้าผ้า!EI17 -> 0 | BC8: =[2]หน้าผ้า!BZ17 -> WRWT160800/WRWT25800 | BD8: =[2]หน้าผ้า!CA17 -> 0
A9: =[2]หน้าผ้า!C18 -> 45897 | B9: =[2]หน้าผ้า!B18 -> MK68-001045 | C9: =[2]หน้าผ้า!E18 -> บจก.เคอรี่ฟลาวมิลล์ | D9: =[2]หน้าผ้า!F18 -> น้องเอินโดนัท 10กก | E9: =[2]หน้าผ้า!G18 -> 16 | F9: =[2]หน้าผ้า!H18 -> 25 | G9: =[2]หน้าผ้า!I18 -> ขาว | H9: =[2]หน้าผ้า!J18 -> 0 | I9: =[2]หน้าผ้า!L18 -> 45 | J9: =[2]หน้าผ้า!M18 -> ± | K9: =[2]หน้าผ้า!N18 -> 5 | L9: =[2]หน้าผ้า!R18 -> ไม่ | M9: =[2]หน้าผ้า!T18 -> ไม่สวมถุงใน | N9: =[2]หน้าผ้า!U18 -> 0 | O9: =[2]หน้าผ้า!V18 -> 0 | P9: =[2]หน้าผ้า!AB18 -> 0 | Q9: =[2]หน้าผ้า!AC18 -> 0 | R9: =[2]หน้าผ้า!AD18 -> 0 | S9: =[2]หน้าผ้า!Z18 -> ห่ออัดเบลแบน500 | T9: =[2]หน้าผ้า!X18 -> 45925 | U9: =[2]หน้าผ้า!AA18 -> 5000 | V9: =[2]หน้าผ้า!AJ18 -> 5000 | W9: =[2]หน้าผ้า!AL18 -> 0 | X9: =[2]หน้าผ้า!AM18 -> 5400 | Y9: =[2]หน้าผ้า!AN18 -> 0 | Z9: =[2]หน้าผ้า!AO18 -> WSWT1625800 | AA9: =[2]หน้าผ้า!AQ18 -> 0 | AB9: =[2]หน้าผ้า!AR18 -> 0 | AC9: =[2]หน้าผ้า!AS18 -> 0 | AD9: =[2]หน้าผ้า!AT18 -> 0 | AE9: =[2]หน้าผ้า!AU18 -> 0 | AF9: =[2]หน้าผ้า!AI18 -> 0 | AG9: =[3]หน้าผ้า!DC21 -> พร้อมส่ง | AH9: =[2]หน้าผ้า!DL18 -> P7 | AI9: =[2]หน้าผ้า!DM18 -> 2 | AJ9: =[2]หน้าผ้า!DN18 -> 45925 | AK9: =[2]หน้าผ้า!DQ18 -> 0 | AL9: =[2]หน้าผ้า!DR18 -> 45916 | AM9: =[2]หน้าผ้า!DS18 -> 45923 | AN9: =[2]หน้าผ้า!DT18 -> 45924 | AO9: =[2]หน้าผ้า!DU18 -> 45924 | AP9: =[2]หน้าผ้า!DP18 -> 45920 | AQ9: =[2]หน้าผ้า!DW18 -> 0 | AR9: =[2]หน้าผ้า!DX18 -> 0 | AS9: =[2]หน้าผ้า!DY18 -> 0 | AT9: =[2]หน้าผ้า!DZ18 -> 0 | AU9: =[2]หน้าผ้า!EA18 -> 0 | AV9: =[2]หน้าผ้า!EB18 -> 0 | AW9: =[2]หน้าผ้า!EC18 -> งานพิมพ์ | AX9: =[2]หน้าผ้า!ED18 -> / | AY9: =[2]หน้าผ้า!AG18 -> สีลอกทั้งหมด | AZ9: =[2]หน้าผ้า!EG18 -> 0 | BA9: =[2]หน้าผ้า!EH18 -> 0 | BB9: =[2]หน้าผ้า!EI18 -> 0 | BC9: =[2]หน้าผ้า!BZ18 -> WRWT25800/WRWT25800 | BD9: =[2]หน้าผ้า!CA18 -> 0
A10: =[2]หน้าผ้า!C19 -> 0 | B10: =[2]หน้าผ้า!B19 -> 0 | C10: =[2]หน้าผ้า!E19 -> 0 | D10: =[2]หน้าผ้า!F19 -> 0 | E10: =[2]หน้าผ้า!G19 -> 16 | F10: =[2]หน้าผ้า!H19 -> 25 | G10: =[2]หน้าผ้า!I19 -> ขาว | H10: =[2]หน้าผ้า!J19 -> 0 | I10: =[2]หน้าผ้า!L19 -> 45 | J10: =[2]หน้าผ้า!M19 -> ± | K10: =[2]หน้าผ้า!N19 -> 5 | L10: =[2]หน้าผ้า!R19 -> 0 | M10: =[2]หน้าผ้า!T19 -> 0 | N10: =[2]หน้าผ้า!U19 -> 0 | O10: =[2]หน้าผ้า!V19 -> 0 | P10: =[2]หน้าผ้า!AB19 -> 0 | Q10: =[2]หน้าผ้า!AC19 -> 0 | R10: =[2]หน้าผ้า!AD19 -> 0 | S10: =[2]หน้าผ้า!Z19 -> 0 | T10: =[2]หน้าผ้า!X19 -> 0 | U10: =[2]หน้าผ้า!AA19 -> 0 | V10: =[2]หน้าผ้า!AJ19 -> 0 | W10: =[2]หน้าผ้า!AL19 -> 0 | X10: =[2]หน้าผ้า!AM19 -> 0 | Y10: =[2]หน้าผ้า!AN19 -> 0 | Z10: =[2]หน้าผ้า!AO19 -> WSWT1625800 | AA10: =[2]หน้าผ้า!AQ19 -> 0 | AB10: =[2]หน้าผ้า!AR19 -> 0 | AC10: =[2]หน้าผ้า!AS19 -> 0 | AD10: =[2]หน้าผ้า!AT19 -> 0 | AE10: =[2]หน้าผ้า!AU19 -> 0 | AF10: =[2]หน้าผ้า!AI19 -> ระบุในSD | AG10: =[3]หน้าผ้า!DC22 -> ยังไม่ได้พิมพ์ | AH10: =[2]หน้าผ้า!DL19 -> 0 | AI10: =[2]หน้าผ้า!DM19 -> Lead time | AJ10: =[2]หน้าผ้า!DN19 -> 0 | AK10: =[2]หน้าผ้า!DQ19 -> 0 | AL10: =[2]หน้าผ้า!DR19 -> 0 | AM10: =[2]หน้าผ้า!DS19 -> 0 | AN10: =[2]หน้าผ้า!DT19 -> 0 | AO10: =[2]หน้าผ้า!DU19 -> 0 | AP10: =[2]หน้าผ้า!DP19 -> 0 | AQ10: =[2]หน้าผ้า!DW19 -> 0 | AR10: =[2]หน้าผ้า!DX19 -> 0 | AS10: =[2]หน้าผ้า!DY19 -> 0 | AT10: =[2]หน้าผ้า!DZ19 -> 0 | AU10: =[2]หน้าผ้า!EA19 -> 0 | AV10: =[2]หน้าผ้า!EB19 -> 0 | AW10: =[2]หน้าผ้า!EC19 -> 0 | AX10: =[2]หน้าผ้า!ED19 -> 0 | AY10: =[2]หน้าผ้า!AG19 -> 0 | AZ10: =[2]หน้าผ้า!EG19 -> 0 | BA10: =[2]หน้าผ้า!EH19 -> 0 | BB10: =[2]หน้าผ้า!EI19 -> 0 | BC10: =[2]หน้าผ้า!BZ19 -> WRWT160800/WRWT25800 | BD10: =[2]หน้าผ้า!CA19 -> 0
A11: =[2]หน้าผ้า!C20 -> 0 | B11: =[2]หน้าผ้า!B20 -> 0 | C11: =[2]หน้าผ้า!E20 -> 0 | D11: =[2]หน้าผ้า!F20 -> 0 | E11: =[2]หน้าผ้า!G20 -> 16 | F11: =[2]หน้าผ้า!H20 -> 25 | G11: =[2]หน้าผ้า!I20 -> 0 | H11: =[2]หน้าผ้า!J20 -> 0 | I11: =[2]หน้าผ้า!L20 -> 47 | J11: =[2]หน้าผ้า!M20 -> ± | K11: =[2]หน้าผ้า!N20 -> 5 | L11: =[2]หน้าผ้า!R20 -> 0 | M11: =[2]หน้าผ้า!T20 -> 0 | N11: =[2]หน้าผ้า!U20 -> 0 | O11: =[2]หน้าผ้า!V20 -> 0 | P11: =[2]หน้าผ้า!AB20 -> 0 | Q11: =[2]หน้าผ้า!AC20 -> 0 | R11: =[2]หน้าผ้า!AD20 -> 0 | S11: =[2]หน้าผ้า!Z20 -> 0 | T11: =[2]หน้าผ้า!X20 -> 0 | U11: =[2]หน้าผ้า!AA20 -> 0 | V11: =[2]หน้าผ้า!AJ20 -> 0 | W11: =[2]หน้าผ้า!AL20 -> 0 | X11: =[2]หน้าผ้า!AM20 -> 0 | Y11: =[2]หน้าผ้า!AN20 -> 0 | Z11: =[2]หน้าผ้า!AO20 -> WSWT1621720SMFX | AA11: =[2]หน้าผ้า!AQ20 -> #REF! | AB11: =[2]หน้าผ้า!AR20 -> #REF! | AC11: =[2]หน้าผ้า!AS20 -> #REF! | AD11: =[2]หน้าผ้า!AT20 -> #REF! | AE11: =[2]หน้าผ้า!AU20 -> #REF! | AF11: =[2]หน้าผ้า!AI20 -> ระบุในSD | AG11: =[3]หน้าผ้า!DC23 -> ยังไม่ได้พิมพ์ | AH11: =[2]หน้าผ้า!DL20 -> 0 | AI11: =[2]หน้าผ้า!DM20 -> 0 | AJ11: =[2]หน้าผ้า!DN20 -> 0 | AK11: =[2]หน้าผ้า!DQ20 -> 0 | AL11: =[2]หน้าผ้า!DR20 -> 0 | AM11: =[2]หน้าผ้า!DS20 -> 0 | AN11: =[2]หน้าผ้า!DT20 -> 0 | AO11: =[2]หน้าผ้า!DU20 -> 0 | AP11: =[2]หน้าผ้า!DP20 -> 0 | AQ11: =[2]หน้าผ้า!DW20 -> 0 | AR11: =[2]หน้าผ้า!DX20 -> 0 | AS11: =[2]หน้าผ้า!DY20 -> 0 | AT11: =[2]หน้าผ้า!DZ20 -> 0 | AU11: =[2]หน้าผ้า!EA20 -> 0 | AV11: =[2]หน้าผ้า!EB20 -> 0 | AW11: =[2]หน้าผ้า!EC20 -> 0 | AX11: =[2]หน้าผ้า!ED20 -> 0 | AY11: =[2]หน้าผ้า!AG20 -> 0 | AZ11: =[2]หน้าผ้า!EG20 -> 0 | BA11: =[2]หน้าผ้า!EH20 -> 0 | BB11: =[2]หน้าผ้า!EI20 -> 0 | BC11: =[2]หน้าผ้า!BZ20 -> WRWT160720/WRWT21720 | BD11: =[2]หน้าผ้า!CA20 -> 0
A12: =[2]หน้าผ้า!C21 -> 0 | B12: =[2]หน้าผ้า!B21 -> 0 | C12: =[2]หน้าผ้า!E21 -> 0 | D12: =[2]หน้าผ้า!F21 -> 0 | E12: =[2]หน้าผ้า!G21 -> 17 | F12: =[2]หน้าผ้า!H21 -> 26 | G12: =[2]หน้าผ้า!I21 -> 0 | H12: =[2]หน้าผ้า!J21 -> 0 | I12: =[2]หน้าผ้า!L21 -> 48 | J12: =[2]หน้าผ้า!M21 -> ± | K12: =[2]หน้าผ้า!N21 -> 5 | L12: =[2]หน้าผ้า!R21 -> 0 | M12: =[2]หน้าผ้า!T21 -> 0 | N12: =[2]หน้าผ้า!U21 -> 0 | O12: =[2]หน้าผ้า!V21 -> 0 | P12: =[2]หน้าผ้า!AB21 -> 0 | Q12: =[2]หน้าผ้า!AC21 -> 0 | R12: =[2]หน้าผ้า!AD21 -> 0 | S12: =[2]หน้าผ้า!Z21 -> 0 | T12: =[2]หน้าผ้า!X21 -> 0 | U12: =[2]หน้าผ้า!AA21 -> 0 | V12: =[2]หน้าผ้า!AJ21 -> 0 | W12: =[2]หน้าผ้า!AL21 -> 0 | X12: =[2]หน้าผ้า!AM21 -> 0 | Y12: =[2]หน้าผ้า!AN21 -> 0 | Z12: =[2]หน้าผ้า!AO21 -> WSWT1725800 | AA12: =[2]หน้าผ้า!AQ21 -> #REF! | AB12: =[2]หน้าผ้า!AR21 -> #REF! | AC12: =[2]หน้าผ้า!AS21 -> #REF! | AD12: =[2]หน้าผ้า!AT21 -> #REF! | AE12: =[2]หน้าผ้า!AU21 -> #REF! | AF12: =[2]หน้าผ้า!AI21 -> ระบุในSD | AG12: =[3]หน้าผ้า!DC24 -> ยังไม่ได้พิมพ์ | AH12: =[2]หน้าผ้า!DL21 -> 0 | AI12: =[2]หน้าผ้า!DM21 -> 0 | AJ12: =[2]หน้าผ้า!DN21 -> 0 | AK12: =[2]หน้าผ้า!DQ21 -> 0 | AL12: =[2]หน้าผ้า!DR21 -> 0 | AM12: =[2]หน้าผ้า!DS21 -> 0 | AN12: =[2]หน้าผ้า!DT21 -> 0 | AO12: =[2]หน้าผ้า!DU21 -> 0 | AP12: =[2]หน้าผ้า!DP21 -> 0 | AQ12: =[2]หน้าผ้า!DW21 -> 0 | AR12: =[2]หน้าผ้า!DX21 -> 0 | AS12: =[2]หน้าผ้า!DY21 -> 0 | AT12: =[2]หน้าผ้า!DZ21 -> 0 | AU12: =[2]หน้าผ้า!EA21 -> 0 | AV12: =[2]หน้าผ้า!EB21 -> 0 | AW12: =[2]หน้าผ้า!EC21 -> 0 | AX12: =[2]หน้าผ้า!ED21 -> 0 | AY12: =[2]หน้าผ้า!AG21 -> 0 | AZ12: =[2]หน้าผ้า!EG21 -> 0 | BA12: =[2]หน้าผ้า!EH21 -> 0 | BB12: =[2]หน้าผ้า!EI21 -> 0 | BC12: =[2]หน้าผ้า!BZ21 -> WRWT170800/WRWT25800 | BD12: =[2]หน้าผ้า!CA21 -> 0
A13: =[2]หน้าผ้า!C22 -> 45923 | B13: =[2]หน้าผ้า!B22 -> MK68-001164 | C13: =[2]หน้าผ้า!E22 -> ร้านเห็ดไพลิน | D13: =[2]หน้าผ้า!F22 -> เพชร | E13: =[2]หน้าผ้า!G22 -> 18 | F13: =[2]หน้าผ้า!H22 -> 28 | G13: =[2]หน้าผ้า!I22 -> ขาว | H13: =[2]หน้าผ้า!J22 -> 0 | I13: =[2]หน้าผ้า!L22 -> 50 | J13: =[2]หน้าผ้า!M22 -> ± | K13: =[2]หน้าผ้า!N22 -> 5 | L13: =[2]หน้าผ้า!R22 -> ไม่ | M13: =[2]หน้าผ้า!T22 -> 19 | N13: =[2]หน้าผ้า!U22 -> 29 | O13: =[2]หน้าผ้า!V22 -> 40 | P13: =[2]หน้าผ้า!AB22 -> 67.96838 | Q13: =[2]หน้าผ้า!AC22 -> 0 | R13: =[2]หน้าผ้า!AD22 -> 67.96838 | S13: =[2]หน้าผ้า!Z22 -> 500กระสอบ | T13: =[2]หน้าผ้า!X22 -> 45930 | U13: =[2]หน้าผ้า!AA22 -> 5000 | V13: =[2]หน้าผ้า!AJ22 -> 0 | W13: =[2]หน้าผ้า!AL22 -> 5000 | X13: =[2]หน้าผ้า!AM22 -> 0 | Y13: =[2]หน้าผ้า!AN22 -> 5250 | Z13: =[2]หน้าผ้า!AO22 -> WSWT1825800 | AA13: =[2]หน้าผ้า!AQ22 -> 4121.15 | AB13: =[2]หน้าผ้า!AR22 -> 2500 | AC13: =[2]หน้าผ้า!AS22 -> 1621.15 | AD13: =[2]หน้าผ้า!AT22 -> 0 | AE13: =[2]หน้าผ้า!AU22 -> 0 | AF13: =[2]หน้าผ้า!AI22 -> 0 | AG13: =[3]หน้าผ้า!DC25 -> ยังไม่ได้พิมพ์ | AH13: =[2]หน้าผ้า!DL22 -> P9 | AI13: =[2]หน้าผ้า!DM22 -> 3 | AJ13: =[2]หน้าผ้า!DN22 -> 45930 | AK13: =[2]หน้าผ้า!DQ22 -> 0 | AL13: =[2]หน้าผ้า!DR22 -> 45920 | AM13: =[2]หน้าผ้า!DS22 -> 45927 | AN13: =[2]หน้าผ้า!DT22 -> 45928 | AO13: =[2]หน้าผ้า!DU22 -> 45928 | AP13: =[2]หน้าผ้า!DP22 -> 45925 | AQ13: =[2]หน้าผ้า!DW22 -> 45929 | AR13: =[2]หน้าผ้า!DX22 -> 0 | AS13: =[2]หน้าผ้า!DY22 -> 0 | AT13: =[2]หน้าผ้า!DZ22 -> 0 | AU13: =[2]หน้าผ้า!EA22 -> 0 | AV13: =[2]หน้าผ้า!EB22 -> 0 | AW13: =[2]หน้าผ้า!EC22 -> งานพิมพ์ | AX13: =[2]หน้าผ้า!ED22 -> / | AY13: =[2]หน้าผ้า!AG22 -> 0 | AZ13: =[2]หน้าผ้า!EG22 -> 0 | BA13: =[2]หน้าผ้า!EH22 -> 0 | BB13: =[2]หน้าผ้า!EI22 -> 0 | BC13: =[2]หน้าผ้า!BZ22 -> WRWT25800/WRWT25800 | BD13: =[2]หน้าผ้า!CA22 -> 111.53512
A14: =[2]หน้าผ้า!C23 -> 45923 | B14: =[2]หน้าผ้า!B23 -> MK68-001161 | C14: =[2]หน้าผ้า!E23 -> หจก.อนนท์อุตสาหกรรม | D14: =[2]หน้าผ้า!F23 -> อนนท์ 20 กก. | E14: =[2]หน้าผ้า!G23 -> 18 | F14: =[2]หน้าผ้า!H23 -> 28 | G14: =[2]หน้าผ้า!I23 -> ขาว | H14: =[2]หน้าผ้า!J23 -> 0 | I14: =[2]หน้าผ้า!L23 -> 50 | J14: =[2]หน้าผ้า!M23 -> ± | K14: =[2]หน้าผ้า!N23 -> 5 | L14: =[2]หน้าผ้า!R23 -> ไม่ | M14: =[2]หน้าผ้า!T23 -> 19 | N14: =[2]หน้าผ้า!U23 -> 31 | O14: =[2]หน้าผ้า!V23 -> 40 | P14: =[2]หน้าผ้า!AB23 -> 72.655855 | Q14: =[2]หน้าผ้า!AC23 -> 0 | R14: =[2]หน้าผ้า!AD23 -> 72.655855 | S14: =[2]หน้าผ้า!Z23 -> 500กระสอบแบน | T14: =[2]หน้าผ้า!X23 -> 45950 | U14: =[2]หน้าผ้า!AA23 -> 5000 | V14: =[2]หน้าผ้า!AJ23 -> 0 | W14: =[2]หน้าผ้า!AL23 -> 5000 | X14: =[2]หน้าผ้า!AM23 -> 0 | Y14: =[2]หน้าผ้า!AN23 -> 5250 | Z14: =[2]หน้าผ้า!AO23 -> WSWT1825800 | AA14: =[2]หน้าผ้า!AQ23 -> 4121.15 | AB14: =[2]หน้าผ้า!AR23 -> 0 | AC14: =[2]หน้าผ้า!AS23 -> 4121.15 | AD14: =[2]หน้าผ้า!AT23 -> 0 | AE14: =[2]หน้าผ้า!AU23 -> 0 | AF14: =[2]หน้าผ้า!AI23 -> 0 | AG14: =[3]หน้าผ้า!DC26 -> ยังไม่ได้พิมพ์ | AH14: =[2]หน้าผ้า!DL23 -> P9 | AI14: =[2]หน้าผ้า!DM23 -> 3 | AJ14: =[2]หน้าผ้า!DN23 -> 45950 | AK14: =[2]หน้าผ้า!DQ23 -> 0 | AL14: =[2]หน้าผ้า!DR23 -> 45940 | AM14: =[2]หน้าผ้า!DS23 -> 45947 | AN14: =[2]หน้าผ้า!DT23 -> 45948 | AO14: =[2]หน้าผ้า!DU23 -> 45948 | AP14: =[2]หน้าผ้า!DP23 -> 45945 | AQ14: =[2]หน้าผ้า!DW23 -> 45949 | AR14: =[2]หน้าผ้า!DX23 -> 0 | AS14: =[2]หน้าผ้า!DY23 -> 0 | AT14: =[2]หน้าผ้า!DZ23 -> 0 | AU14: =[2]หน้าผ้า!EA23 -> 0 | AV14: =[2]หน้าผ้า!EB23 -> 0 | AW14: =[2]หน้าผ้า!EC23 -> งานพิมพ์ | AX14: =[2]หน้าผ้า!ED23 -> / | AY14: =[2]หน้าผ้า!AG23 -> 0 | AZ14: =[2]หน้าผ้า!EG23 -> 0 | BA14: =[2]หน้าผ้า!EH23 -> 0 | BB14: =[2]หน้าผ้า!EI23 -> 0 | BC14: =[2]หน้าผ้า!BZ23 -> WRWT25800/WRWT25800 | BD14: =[2]หน้าผ้า!CA23 -> 283.53512
A15: =[2]หน้าผ้า!C24 -> 45923 | B15: =[2]หน้าผ้า!B24 -> MK68-001162 | C15: =[2]หน้าผ้า!E24 -> หจก.อนนท์อุตสาหกรรม | D15: =[2]หน้าผ้า!F24 -> ดาว 20 กก. | E15: =[2]หน้าผ้า!G24 -> 18 | F15: =[2]หน้าผ้า!H24 -> 28 | G15: =[2]หน้าผ้า!I24 -> ขาว | H15: =[2]หน้าผ้า!J24 -> 0 | I15: =[2]หน้าผ้า!L24 -> 50 | J15: =[2]หน้าผ้า!M24 -> ± | K15: =[2]หน้าผ้า!N24 -> 5 | L15: =[2]หน้าผ้า!R24 -> ไม่ | M15: =[2]หน้าผ้า!T24 -> 19 | N15: =[2]หน้าผ้า!U24 -> 31 | O15: =[2]หน้าผ้า!V24 -> 40 | P15: =[2]หน้าผ้า!AB24 -> 363.27927 | Q15: =[2]หน้าผ้า!AC24 -> 0 | R15: =[2]หน้าผ้า!AD24 -> 363.27927 | S15: =[2]หน้าผ้า!Z24 -> 500กระสอบแบน | T15: =[2]หน้าผ้า!X24 -> 45950 | U15: =[2]หน้าผ้า!AA24 -> 25000 | V15: =[2]หน้าผ้า!AJ24 -> 0 | W15: =[2]หน้าผ้า!AL24 -> 25000 | X15: =[2]หน้าผ้า!AM24 -> 0 | Y15: =[2]หน้าผ้า!AN24 -> 26250 | Z15: =[2]หน้าผ้า!AO24 -> WSWT1825800 | AA15: =[2]หน้าผ้า!AQ24 -> 20605.75 | AB15: =[2]หน้าผ้า!AR24 -> 0 | AC15: =[2]หน้าผ้า!AS24 -> 20605.75 | AD15: =[2]หน้าผ้า!AT24 -> 0 | AE15: =[2]หน้าผ้า!AU24 -> 0 | AF15: =[2]หน้าผ้า!AI24 -> 0 | AG15: =[3]หน้าผ้า!DC27 -> ยังไม่ได้พิมพ์ | AH15: =[2]หน้าผ้า!DL24 -> P9 | AI15: =[2]หน้าผ้า!DM24 -> 3 | AJ15: =[2]หน้าผ้า!DN24 -> 45950 | AK15: =[2]หน้าผ้า!DQ24 -> 0 | AL15: =[2]หน้าผ้า!DR24 -> 45940 | AM15: =[2]หน้าผ้า!DS24 -> 45947 | AN15: =[2]หน้าผ้า!DT24 -> 45948 | AO15: =[2]หน้าผ้า!DU24 -> 45948 | AP15: =[2]หน้าผ้า!DP24 -> 45945 | AQ15: =[2]หน้าผ้า!DW24 -> 45949 | AR15: =[2]หน้าผ้า!DX24 -> 0 | AS15: =[2]หน้าผ้า!DY24 -> 0 | AT15: =[2]หน้าผ้า!DZ24 -> 0 | AU15: =[2]หน้าผ้า!EA24 -> 0 | AV15: =[2]หน้าผ้า!EB24 -> 0 | AW15: =[2]หน้าผ้า!EC24 -> งานพิมพ์ | AX15: =[2]หน้าผ้า!ED24 -> / | AY15: =[2]หน้าผ้า!AG24 -> 0 | AZ15: =[2]หน้าผ้า!EG24 -> 0 | BA15: =[2]หน้าผ้า!EH24 -> 0 | BB15: =[2]หน้าผ้า!EI24 -> 0 | BC15: =[2]หน้าผ้า!BZ24 -> WRWT25800/WRWT25800 | BD15: =[2]หน้าผ้า!CA24 -> 1417.6756
A16: =[2]หน้าผ้า!C25 -> 45923 | B16: =[2]หน้าผ้า!B25 -> MK68-001162 | C16: =[2]หน้าผ้า!E25 -> หจก.อนนท์อุตสาหกรรม | D16: =[2]หน้าผ้า!F25 -> ดาว 20 กก. | E16: =[2]หน้าผ้า!G25 -> 18 | F16: =[2]หน้าผ้า!H25 -> 28 | G16: =[2]หน้าผ้า!I25 -> ขาว | H16: =[2]หน้าผ้า!J25 -> 0 | I16: =[2]หน้าผ้า!L25 -> 50 | J16: =[2]หน้าผ้า!M25 -> ± | K16: =[2]หน้าผ้า!N25 -> 5 | L16: =[2]หน้าผ้า!R25 -> ไม่ | M16: =[2]หน้าผ้า!T25 -> 19 | N16: =[2]หน้าผ้า!U25 -> 31 | O16: =[2]หน้าผ้า!V25 -> 40 | P16: =[2]หน้าผ้า!AB25 -> 363.27927 | Q16: =[2]หน้าผ้า!AC25 -> 0 | R16: =[2]หน้าผ้า!AD25 -> 363.27927 | S16: =[2]หน้าผ้า!Z25 -> 500กระสอบแบน | T16: =[2]หน้าผ้า!X25 -> 45955 | U16: =[2]หน้าผ้า!AA25 -> 25000 | V16: =[2]หน้าผ้า!AJ25 -> 0 | W16: =[2]หน้าผ้า!AL25 -> 25000 | X16: =[2]หน้าผ้า!AM25 -> 0 | Y16: =[2]หน้าผ้า!AN25 -> 26250 | Z16: =[2]หน้าผ้า!AO25 -> WSWT1825800 | AA16: =[2]หน้าผ้า!AQ25 -> 20605.75 | AB16: =[2]หน้าผ้า!AR25 -> 0 | AC16: =[2]หน้าผ้า!AS25 -> 20605.75 | AD16: =[2]หน้าผ้า!AT25 -> 0 | AE16: =[2]หน้าผ้า!AU25 -> 0 | AF16: =[2]หน้าผ้า!AI25 -> 0 | AG16: =[3]หน้าผ้า!DC28 -> ยังไม่ได้พิมพ์ | AH16: =[2]หน้าผ้า!DL25 -> P9 | AI16: =[2]หน้าผ้า!DM25 -> 3 | AJ16: =[2]หน้าผ้า!DN25 -> 45955 | AK16: =[2]หน้าผ้า!DQ25 -> 0 | AL16: =[2]หน้าผ้า!DR25 -> 45945 | AM16: =[2]หน้าผ้า!DS25 -> 45952 | AN16: =[2]หน้าผ้า!DT25 -> 45953 | AO16: =[2]หน้าผ้า!DU25 -> 45953 | AP16: =[2]หน้าผ้า!DP25 -> 45950 | AQ16: =[2]หน้าผ้า!DW25 -> 45954 | AR16: =[2]หน้าผ้า!DX25 -> 0 | AS16: =[2]หน้าผ้า!DY25 -> 0 | AT16: =[2]หน้าผ้า!DZ25 -> 0 | AU16: =[2]หน้าผ้า!EA25 -> 0 | AV16: =[2]หน้าผ้า!EB25 -> 0 | AW16: =[2]หน้าผ้า!EC25 -> งานพิมพ์ | AX16: =[2]หน้าผ้า!ED25 -> / | AY16: =[2]หน้าผ้า!AG25 -> 0 | AZ16: =[2]หน้าผ้า!EG25 -> 0 | BA16: =[2]หน้าผ้า!EH25 -> 0 | BB16: =[2]หน้าผ้า!EI25 -> 0 | BC16: =[2]หน้าผ้า!BZ25 -> WRWT25800/WRWT25800 | BD16: =[2]หน้าผ้า!CA25 -> 1417.6756
A17: =[2]หน้าผ้า!C26 -> 45923 | B17: =[2]หน้าผ้า!B26 -> MK68-001162 | C17: =[2]หน้าผ้า!E26 -> หจก.อนนท์อุตสาหกรรม | D17: =[2]หน้าผ้า!F26 -> ดาว 20 กก. | E17: =[2]หน้าผ้า!G26 -> 18 | F17: =[2]หน้าผ้า!H26 -> 28 | G17: =[2]หน้าผ้า!I26 -> ขาว | H17: =[2]หน้าผ้า!J26 -> 0 | I17: =[2]หน้าผ้า!L26 -> 50 | J17: =[2]หน้าผ้า!M26 -> ± | K17: =[2]หน้าผ้า!N26 -> 5 | L17: =[2]หน้าผ้า!R26 -> ไม่ | M17: =[2]หน้าผ้า!T26 -> 19 | N17: =[2]หน้าผ้า!U26 -> 31 | O17: =[2]หน้าผ้า!V26 -> 40 | P17: =[2]หน้าผ้า!AB26 -> 363.27927 | Q17: =[2]หน้าผ้า!AC26 -> 0 | R17: =[2]หน้าผ้า!AD26 -> 363.27927 | S17: =[2]หน้าผ้า!Z26 -> 500กระสอบแบน | T17: =[2]หน้าผ้า!X26 -> 45958 | U17: =[2]หน้าผ้า!AA26 -> 25000 | V17: =[2]หน้าผ้า!AJ26 -> 0 | W17: =[2]หน้าผ้า!AL26 -> 25000 | X17: =[2]หน้าผ้า!AM26 -> 0 | Y17: =[2]หน้าผ้า!AN26 -> 26250 | Z17: =[2]หน้าผ้า!AO26 -> WSWT1825800 | AA17: =[2]หน้าผ้า!AQ26 -> 20605.75 | AB17: =[2]หน้าผ้า!AR26 -> 0 | AC17: =[2]หน้าผ้า!AS26 -> 20605.75 | AD17: =[2]หน้าผ้า!AT26 -> 0 | AE17: =[2]หน้าผ้า!AU26 -> 0 | AF17: =[2]หน้าผ้า!AI26 -> 0 | AG17: =[3]หน้าผ้า!DC29 -> พร้อมส่ง | AH17: =[2]หน้าผ้า!DL26 -> P9 | AI17: =[2]หน้าผ้า!DM26 -> 3 | AJ17: =[2]หน้าผ้า!DN26 -> 45958 | AK17: =[2]หน้าผ้า!DQ26 -> 0 | AL17: =[2]หน้าผ้า!DR26 -> 45948 | AM17: =[2]หน้าผ้า!DS26 -> 45955 | AN17: =[2]หน้าผ้า!DT26 -> 45956 | AO17: =[2]หน้าผ้า!DU26 -> 45956 | AP17: =[2]หน้าผ้า!DP26 -> 45953 | AQ17: =[2]หน้าผ้า!DW26 -> 45957 | AR17: =[2]หน้าผ้า!DX26 -> 0 | AS17: =[2]หน้าผ้า!DY26 -> 0 | AT17: =[2]หน้าผ้า!DZ26 -> 0 | AU17: =[2]หน้าผ้า!EA26 -> 0 | AV17: =[2]หน้าผ้า!EB26 -> 0 | AW17: =[2]หน้าผ้า!EC26 -> งานพิมพ์ | AX17: =[2]หน้าผ้า!ED26 -> / | AY17: =[2]หน้าผ้า!AG26 -> 0 | AZ17: =[2]หน้าผ้า!EG26 -> 0 | BA17: =[2]หน้าผ้า!EH26 -> 0 | BB17: =[2]หน้าผ้า!EI26 -> 0 | BC17: =[2]หน้าผ้า!BZ26 -> WRWT25800/WRWT25800 | BD17: =[2]หน้าผ้า!CA26 -> 1417.6756
... A575: =[2]หน้าผ้า!C584 -> 0 | B575: =[2]หน้าผ้า!B584 -> 0 | C575: =[2]หน้าผ้า!E584 -> 0 | D575: =[2]หน้าผ้า!F584 -> 0 | E575: =[2]หน้าผ้า!G584 -> 0 | F575: =[2]หน้าผ้า!H584 -> 0 | G575: =[2]หน้าผ้า!I584 -> 0 | H575: =[2]หน้าผ้า!J584 -> 0 | I575: =[2]หน้าผ้า!L584 -> 0 | J575: =[2]หน้าผ้า!M584 -> 0 | K575: =[2]หน้าผ้า!N584 -> 0 | L575: =[2]หน้าผ้า!R584 -> 0 | M575: =[2]หน้าผ้า!T584 -> 0 | N575: =[2]หน้าผ้า!U584 -> 0 | O575: =[2]หน้าผ้า!V584 -> 0 | P575: =[2]หน้าผ้า!AB584 -> 0 | Q575: =[2]หน้าผ้า!AC584 -> 0 | R575: =[2]หน้าผ้า!AD584 -> 0 | S575: =[2]หน้าผ้า!Z584 -> 0 | T575: =[2]หน้าผ้า!X584 -> 0 | U575: =[2]หน้าผ้า!AA584 -> 0 | V575: =[2]หน้าผ้า!AJ584 -> 0 | W575: =[2]หน้าผ้า!AL584 -> 0 | X575: =[2]หน้าผ้า!AM584 -> 0 | Y575: =[2]หน้าผ้า!AN584 -> 0 | Z575: =[2]หน้าผ้า!AO584 -> 0 | AA575: =[2]หน้าผ้า!AQ584 -> 0 | AB575: =[2]หน้าผ้า!AR584 -> 0 | AC575: =[2]หน้าผ้า!AS584 -> 0 | AD575: =[2]หน้าผ้า!AT584 -> 0 | AE575: =[2]หน้าผ้า!AU584 -> 0 | AF575: =[2]หน้าผ้า!AI584 -> 0 | AG575: =[3]หน้าผ้า!DC587 -> 0 | AH575: =[2]หน้าผ้า!DL584 -> 0 | AI575: =[2]หน้าผ้า!DM584 -> 0 | AJ575: =[2]หน้าผ้า!DN584 -> 0 | AK575: =[2]หน้าผ้า!DQ584 -> 0 | AL575: =[2]หน้าผ้า!DR584 -> 0 | AM575: =[2]หน้าผ้า!DS584 -> 0 | AN575: =[2]หน้าผ้า!DT584 -> 0 | AO575: =[2]หน้าผ้า!DU584 -> 0 | AP575: =[2]หน้าผ้า!DP584 -> 0 | AQ575: =[2]หน้าผ้า!DW584 -> 0 | AR575: =[2]หน้าผ้า!DX584 -> 0 | AS575: =[2]หน้าผ้า!DY584 -> 0 | AT575: =[2]หน้าผ้า!DZ584 -> 0 | AU575: =[2]หน้าผ้า!EA584 -> 0 | AV575: =[2]หน้าผ้า!EB584 -> 0 | AW575: =[2]หน้าผ้า!EC584 -> 0 | AX575: =[2]หน้าผ้า!ED584 -> 0 | AY575: =[2]หน้าผ้า!AG584 -> 0 | AZ575: =[2]หน้าผ้า!EG584 -> 0 | BA575: =[2]หน้าผ้า!EH584 -> 0 | BB575: =[2]หน้าผ้า!EI584 -> 0 | BC575: =[2]หน้าผ้า!BZ584 -> 0 | BD575: =[2]หน้าผ้า!CA584 -> 0

Sheet 9(Order+FC)
A2: เลขที่ SO | B2: (หลายรายการ)
A3: วันส่ง | B3: (หลายรายการ)
A4: ชื่อลูกค้า | B4: (ทั้งหมด)
K5: 9
A6: ประเภท | B6: ผลรวม ของ จำนวนส่ง | C6: ผลรวม ของ ค้างพิมพ์ | D6: ผลรวม ของ ค้างตัด | E6: ผลรวม ของ ใช้ | F6: ผลรวม ของ Stock | G6: ผลรวม ของ ค้างทอ
A7: WSWT1921720 | B7: 205000 | C7: 0 | D7: 30000 | E7: 0 | F7: 0 | G7: 0 | H7: =+J7-I7 -> 0 | J7: =G7 -> 0
A8: WSWT19251000SM | B8: 5040 | C8: 5292 | D8: 5040 | E8: 4999.0248 | F8: 4999.0248 | G8: 0 | H8: =+J8-I8 -> 0 | J8: =G8 -> 0
A9: WSWT1925800 | B9: 20000 | C9: 21000 | D9: 20000 | E9: 17602.2 | F9: 17602.2 | G9: 0 | H9: =+J9-I9 -> 0 | J9: =G9 -> 0
A10: WSWT2025800 | B10: 89360 | C10: 84000 | D10: 86360 | E10: 83820 | F10: 83820 | G10: 0 | H10: =+J10-I10 -> 0 | J10: =G10 -> 0
A11: WSWT2025800SM | B11: 171120 | C11: 68376 | D11: 72271 | E11: 70323.862 | F11: 70323.862 | G11: 0 | H11: =+J11-I11 -> 0 | J11: =G11 -> 0
A12: WSWT2121670SM | B12: 85000 | C12: 38850 | D12: 64000 | E12: 56774.08 | F12: 56774.08 | G12: 0 | H12: =+J12-I12 -> 0 | J12: =G12 -> 0 | K12: 40000 | L12: =+K5*K12 -> 360000 | M12: =+L12-J12 -> 360000
A13: WSWT2325650 | B13: 60000 | C13: 63000 | D13: 60000 | E13: 59512.2 | F13: 59512.2 | G13: 0 | H13: =+J13-I13 -> 0 | J13: =G13 -> 0 | K13: 14000 | L13: =+K13*K5 -> 126000 | M13: =+L13-J13 -> 126000
A14: WSWT2625650 | B14: 5000 | C14: 0 | D14: 0 | E14: 0 | F14: 0 | G14: 0 | H14: =+J14-I14 -> 0 | J14: =G14 -> 0
A15: WSWT2625800 | B15: 10000 | C15: 0 | D15: 10000 | E15: 12433.3 | F15: 12433.3 | G15: 0 | H15: =+J15-I15 -> 0 | J15: =G15 -> 0 | K15: 20000 | L15: =+K15*K5 -> 180000 | M15: =+L15-J15 -> 180000
A16: WSWT2625850SM | B16: 40000 | C16: 31526.25 | D16: 35900 | E16: 38606.951 | F16: 17295.635 | G16: 21311.316 | H16: =+J16-I16 -> 21311.316 | J16: =G16 -> 21311.316
A17: WSWT2825850 | B17: 105000 | C17: 51765 | D17: 54300 | E17: 65316.735 | F17: 5780 | G17: 59536.735 | H17: =+J17-I17 -> 59536.735 | J17: =G17 -> 59536.735
A18: ผลรวมทั้งหมด | B18: 795520 | C18: 363809.25 | D18: 437871 | E18: 409388.35 | F18: 328540.3 | G18: 80848.051 | H18: =+J18-I18 -> 80848.051 | J18: =G18 -> 80848.051
H19: 0 | I19: 54000 | J19: =G19 -> 0
H20: =+J20-I20 -> 0 | J20: =G20 -> 0
H21: =+J21-I21 -> 0 | J21: =G21 -> 0
H22: =+J22-I22 -> 0 | J22: =G22 -> 0
H23: =+J23-I23 -> 0 | J23: =G23 -> 0
H24: =+J24-I24 -> 0 | J24: =G24 -> 0
H25: =+J25-I25 -> 0 | J25: =G25 -> 0
H26: =+J26-I26 -> 0 | J26: =G26 -> 0
H27: =+J27-I27 -> 0 | J27: =G27 -> 0
H28: =+J28-I28 -> 0 | J28: =G28 -> 0 | M28: =+GETPIVOTDATA("ผลรวม ของ ใช้",$A$6)+H29+H33 -> 661084.45
H29: =SUM(H7:H28) -> 161696.1 | I29: =SUM(I7:I28) -> 54000 | J29: =SUM(J7:J28) -> 161696.1
H32: =+H26 -> 0 | I32: 85 | J32: =+(H32+H29)*I32 -> 13744169 | K32: =+J32/1000 -> 13744.169
H33: 90000 | I33: 95 | J33: =+H33*I33 -> 8550000 | K33: =+J33/1000 -> 8550
H35: =+H32+H33+H29 -> 251696.1 | K35: =+K32+K33 -> 22294.169
N36: 705222
A37: ยอดส่ง 1/2/68 - 17/2/68 | B37: 1565717 | H37: 15 | I37: =+H35/H37 -> 16779.74
N38: =+H35+N36 -> 956918.1
I39: =+H37*110000 -> 1650000
B41: =+B29+B37+B31-110000 -> 1455717 | C41: =+C29+C37+C31 -> 0 | D41: =+D29+D37+D31-110000 -> -110000 | E41: =+E29+E37+E31 -> 0 | F41: =+F29+F37+F31 -> 0 | G41: =+G29+G37+G31 -> 0
B43: 3218150
B45: =+B43-B41 -> 1762433
C47: =+C41/9 -> 0 | D47: =+D41/9 -> -12222.222

Sheet 9(Order)
A2: เลขที่ SO | B2: (หลายรายการ)
A3: วันส่ง | B3: (หลายรายการ)
A4: ชื่อลูกค้า | B4: (ทั้งหมด)
A6: ประเภท | B6: ผลรวม ของ จำนวนส่ง | C6: ผลรวม ของ ค้างพิมพ์ | D6: ผลรวม ของ ค้างตัด | E6: ผลรวม ของ ใช้ | F6: ผลรวม ของ Stock | G6: ผลรวม ของ ค้างทอ
A7: WSWT1625800 | B7: 5000 | C7: 0 | D7: 0 | E7: 0 | F7: 0 | G7: 0 | I7: =+K7-J7 -> 0 | K7: =G7 -> 0
A8: WSWT1725800 | B8: 10100 | C8: 10605 | D8: 10100 | E8: 7760.335 | F8: 7760.335 | G8: 0 | I8: =+K8-J8 -> 0 | K8: =G8 -> 0
A9: WSWT1825800SM | B9: 10000 | C9: 10500 | D9: 10000 | E9: 8801.1 | F9: 8801.1 | G9: 0 | I9: =+K9-J9 -> 0 | K9: =G9 -> 0
A10: WSWT1921720 | B10: 205000 | C10: 0 | D10: 30000 | E10: 0 | F10: 0 | G10: 0 | I10: =+K10-J10 -> 0 | K10: =G10 -> 0
A11: WSWT19251000SM | B11: 5040 | C11: 5292 | D11: 5040 | E11: 4999.0248 | F11: 4999.0248 | G11: 0 | I11: =+K11-J11 -> 0 | K11: =G11 -> 0
A12: WSWT1925800 | B12: 20000 | C12: 21000 | D12: 20000 | E12: 17602.2 | F12: 17602.2 | G12: 0 | I12: =+K12-J12 -> 0 | K12: =G12 -> 0
A13: WSWT2025650 | B13: 10000 | C13: 0 | D13: 10000 | E13: 8801.1 | F13: 4400 | G13: 4401.1 | I13: =+K13-J13 -> 4401.1 | K13: =G13 -> 4401.1
A14: WSWT2025800 | B14: 89360 | C14: 84000 | D14: 86360 | E14: 83820 | F14: 83820 | G14: 0 | I14: =+K14-J14 -> 0 | K14: =G14 -> 0
A15: WSWT2025800SM | B15: 171120 | C15: 68376 | D15: 72271 | E15: 70323.862 | F15: 70323.862 | G15: 0 | I15: =+K15-J15 -> 0 | K15: =G15 -> 0
A16: WSWT2025850 | B16: 12500 | C16: 13125 | D16: 12500 | E16: 14144.625 | F16: 14144.625 | G16: 0 | I16: =+K16-J16 -> 0 | K16: =G16 -> 0
A17: WSWT2121670SM | B17: 85000 | C17: 38850 | D17: 64000 | E17: 56774.08 | F17: 56774.08 | G17: 0 | I17: 0 | J17: 54000 | K17: =G17 -> 0
A18: WSWT2125800 | B18: 2500 | C18: 2625 | D18: 2500 | E18: 2339.975 | F18: 2339.975 | G18: 0 | I18: =+K18-J18 -> 0 | K18: =G18 -> 0
A19: WSWT2625650 | B19: 5000 | C19: 0 | D19: 0 | E19: 0 | F19: 0 | G19: 0 | I19: =+K19-J19 -> 0 | K19: =G19 -> 0
A20: WSWT2625850SM | B20: 40000 | C20: 31526.25 | D20: 35900 | E20: 38606.951 | F20: 17295.635 | G20: 21311.316 | I20: =+K20-J20 -> 21311.316 | K20: =G20 -> 21311.316
A21: WSWT2825850 | B21: 100000 | C21: 51765 | D21: 49300 | E21: 58541.285 | F21: 5780 | G21: 52761.285 | I21: =+K21-J21 -> 52761.285 | K21: =G21 -> 52761.285
A22: ผลรวมทั้งหมด | B22: 770620 | C22: 337664.25 | D22: 407971 | E22: 372514.54 | F22: 294040.84 | G22: 78473.701 | I22: =+K22-J22 -> 78473.701 | K22: =G22 -> 78473.701
I23: =+K23-J23 -> 0 | K23: =G23 -> 0
I24: =+K24-J24 -> 0 | K24: =G24 -> 0
I25: =+K25-J25 -> 0 | K25: =G25 -> 0
I26: =SUM(I7:I25) -> 156947.4 | J26: =SUM(J7:J25) -> 54000 | K26: =SUM(K7:K25) -> 156947.4
D34: =D18 -> 2500
D36: =D20 -> 35900
A37: ยอดส่ง 1/4/68 - 12/4/68 | B37: 887615
A38: Order+ส่ง | B38: =++B25+B37 -> 887615
A39: ประมาณการ | B39: 262000 | C39: 238350 | D39: 262000 | E39: 279847.04 | F39: 60825.09 | G39: 219021.95
A41: Order+ส่ง+ประมาณการ | B41: =+B25+B37+B39+B33 -> 1149615 | C41: =+C25+C37+C39+C33 -> 238350 | D41: =+D25+D37+D39+D33 -> 262000 | E41: =+E25+E37+E39+E33 -> 279847.04 | F41: =+F25+F37+F39+F33 -> 60825.09 | G41: =+G25+G37+G39+G33 -> 219021.95
B43: 3171376
B45: =+B41-B43 -> -2021761 | C45: =+$B$45 -> -2021761 | D45: =+$B$45 -> -2021761 | F45: =+$B$45 -> -2021761
D47: =+D41/6 -> 43666.667

Sheet 9(Order) แยกลูกค้า
A1: เลขที่ SO | B1: (หลายรายการ)
A2: วันส่ง | B2: (หลายรายการ)
A4: ประเภท | B4: ชื่อลูกค้า | C4: ผลรวม ของ จำนวนส่ง | D4: ผลรวม ของ ค้างพิมพ์ | E4: ผลรวม ของ ค้างตัด | F4: ผลรวม ของ Stock | G4: ผลรวม ของ ค้างทอ | I4: vn
A5: WSWT2025650 | B5: บจก.หนองบัวฟีด | C5: 10000 | D5: 0 | E5: 10000 | F5: 4400 | G5: 4401.1 | H5: =G5 -> 4401.1
A6: WSWT2025650 ผลรวม | C6: 10000 | D6: 0 | E6: 10000 | F6: 4400 | G6: 4401.1 | H6: =G6 -> 4401.1
A7: WSWT2025800SM | B7: บจก.เอ.เจ.ฟาร์ม่าแล็บ | C7: 8000 | D7: 0 | E7: 25 | F7: 0 | G7: 0 | H7: =G7 -> 0
A8: WSWT2025800SM ผลรวม | C8: 8000 | D8: 0 | E8: 25 | F8: 0 | G8: 0 | H8: =G8 -> 0
A9: WSWT2121670SM | B9: บจก.เอพีเอ็ม อะโกร | C9: 3000 | D9: 0 | E9: 0 | F9: 0 | G9: 0 | H9: =G9 -> 0
B10: บจก.หนองบัวฟีด | C10: 10000 | D10: 10500 | E10: 10000 | F10: 10756.9 | G10: 0 | H10: =G10 -> 0
A11: WSWT2121670SM ผลรวม | C11: 13000 | D11: 10500 | E11: 10000 | F11: 10756.9 | G11: 0 | H11: =G11 -> 0
A12: ผลรวมทั้งหมด | C12: 31000 | D12: 10500 | E12: 20025 | F12: 15156.9 | G12: 4401.1 | H12: =G12 -> 4401.1
H13: =G13 -> 0
H14: =G14 -> 0
H15: =G15 -> 0
H16: =G16 -> 0
H17: =G17 -> 0
H18: =G18 -> 0
H19: =G19 -> 0
H20: =G20 -> 0
H21: =G21 -> 0
H22: =G22 -> 0
H23: =G23 -> 0
H24: =G24 -> 0
... H65: =G65 -> 0
H70: =SUM(H5:H69) -> 13203.3
D119: Cap พิมพ์ | E119: Cap ตัด | F119: Stock 16/7 บ่าย | G119: Cap ทอ | I119: วันทงาน
B120: lส่ง | C120: 1-16/7 | D120: 160000 | E120: 160000 | G120: 120000 | I120: 12
C121: 1975256 | D121: =+D120*I120 -> 1920000 | E121: =+E120*I120 -> 1920000 | F121: 825147 | G121: =+G120*I120 -> 1440000
A122: เบทาโกรส่งแล้ว | B122: 20700 | C122: 424374
A123: เบทาโกรส่งแล้ว | B123: 20800 | C123: 155973
C126: รวมส่ง+ค้างส่ง | D126: ส่วนต่างCapคงเหลือ | E126: ส่วนต่างCapคงเหลือ | F126: คงเหลือ
C127: =+C50+C121 -> 1975256 | D127: =+D121-D50 -> 1920000 | E127: =+E121-E50 -> 1920000 | F127: =+F121-F50 -> 825147 | G127: =+G121-G50 -> 1440000
B129: 20700VN 20/7 | G129: 350000

Sheet 9(Fc) แยกลูกค้า
A1: เลขที่ SO | B1: ประมาณการ
A2: วันส่ง | B2: (หลายรายการ) | D2: 12
A4: ประเภท | B4: ชื่อลูกค้า | C4: ผลรวม ของ จำนวนส่ง | D4: ผลรวม ของ ค้างพิมพ์ | E4: ผลรวม ของ ค้างตัด | F4: ผลรวม ของ ใช้ | G4: ผลรวม ของ Stock | H4: ผลรวม ของ ค้างทอ
A5: WSWT2325650 | B5: พันธุ์ข้าว | C5: 30000 | D5: 31500 | E5: 30000 | F5: 29756.1 | G5: 29756.1 | H5: 0
B6: บจก.ซิเบลโก้(สบปราบ) | C6: 30000 | D6: 31500 | E6: 30000 | F6: 29756.1 | G6: 29756.1 | H6: 0
A7: WSWT2325650 ผลรวม | C7: 60000 | D7: 63000 | E7: 60000 | F7: 59512.2 | G7: 59512.2 | H7: 0
A8: WSWT2625800 | B8: บจก.ที.ซี.ยูเนี่ยน อโกรเทค | C8: 10000 | D8: 0 | E8: 10000 | F8: 12433.3 | G8: 12433.3 | H8: 0
A9: WSWT2625800 ผลรวม | C9: 10000 | D9: 0 | E9: 10000 | F9: 12433.3 | G9: 12433.3 | H9: 0
A10: WSWT2825850 | B10: บจก.ที.ซี.ยูเนี่ยน อโกรเทค | C10: 5000 | D10: 0 | E10: 5000 | F10: 6775.45 | G10: 0 | H10: 6775.45
A11: WSWT2825850 ผลรวม | C11: 5000 | D11: 0 | E11: 5000 | F11: 6775.45 | G11: 0 | H11: 6775.45
A12: ผลรวมทั้งหมด | C12: 75000 | D12: 63000 | E12: 75000 | F12: 78720.95 | G12: 71945.5 | H12: 6775.45
D119: Cap พิมพ์ | E119: Cap ตัด | F119: Stock 16/7 บ่าย | G119: Cap ทอ | I119: วันทงาน
B120: lส่ง | C120: 1-16/7 | D120: 160000 | E120: 160000 | G120: 120000 | I120: 12
C121: 1975256 | D121: =+D120*I120 -> 1920000 | E121: =+E120*I120 -> 1920000 | F121: 825147 | G121: =+G120*I120 -> 1440000
A122: เบทาโกรส่งแล้ว | B122: 20700 | C122: 424374
A123: เบทาโกรส่งแล้ว | B123: 20800 | C123: 155973
C126: รวมส่ง+ค้างส่ง | D126: ส่วนต่างCapคงเหลือ | E126: ส่วนต่างCapคงเหลือ | F126: คงเหลือ
C127: =+C50+C121 -> 1975256 | D127: =+D121-D50 -> 1920000 | E127: =+E121-E50 -> 1920000 | F127: =+F121-F50 -> 825147 | G127: =+G121-G50 -> 1440000
B129: 20700VN 20/7 | G129: 350000

Sheet 10(Order+Fc) แยกลูกค้า
A1: เลขที่ SO | B1: (หลายรายการ)
A2: วันส่ง | B2: (หลายรายการ) | D2: 12 | I2: เมตร | J2: vn | K2: ใบ | P2: วัน
A4: ประเภท | B4: ชื่อลูกค้า | C4: ผลรวม ของ จำนวนส่ง | D4: ผลรวม ของ ค้างพิมพ์ | E4: ผลรวม ของ ค้างตัด | F4: ผลรวม ของ ใช้ | G4: ผลรวม ของ Stock | H4: ผลรวม ของ ค้างทอ
A5: WSWT1921720 | B5: บจก.เคอรี่ฟลาวมิลล์ | C5: 215000 | D5: 57750 | E5: 155000 | F5: 99396.55 | G5: 99396.55 | H5: 0 | I5: =H5 -> 0
A6: WSWT1921720 ผลรวม | C6: 215000 | D6: 57750 | E6: 155000 | F6: 99396.55 | G6: 99396.55 | H6: 0
A7: WSWT19251000SM | B7: บจก.อินเทคค์ โกลบอล | C7: 10080 | D7: 10584 | E7: 10080 | F7: 10138.867 | G7: 5139.8424 | H7: 4999.0248 | I7: =H7 -> 4999.0248
A8: WSWT19251000SM ผลรวม | C8: 10080 | D8: 10584 | E8: 10080 | F8: 10138.867 | G8: 5139.8424 | H8: 4999.0248 | I8: =H8 -> 4999.0248
A9: WSWT1925800 | B9: บจก.ซีแมน | C9: 5800 | D9: 0 | E9: 0 | F9: 0 | G9: 0 | H9: 0 | I9: =H9 -> 0
A10: WSWT1925800 ผลรวม | C10: 5800 | D10: 0 | E10: 0 | F10: 0 | G10: 0 | H10: 0 | I10: =H10 -> 0
A11: WSWT2025650 | B11: บจก.หนกองบัวฟีด | C11: 5000 | D11: 0 | E11: 0 | F11: 0 | G11: 0 | H11: 0
A12: WSWT2025650 ผลรวม | C12: 5000 | D12: 0 | E12: 0 | F12: 0 | G12: 0 | H12: 0 | I12: =H12 -> 0
A13: WSWT2025800 | B13: บจก.เบทาโกร | C13: 103000 | D13: 0 | E13: 2000 | F13: 0 | G13: 0 | H13: 0
B14: บจก.อินเทคค์ โกลบอล | C14: 80393 | D14: 21155.4 | E14: 50393 | F14: 22144.982 | G14: 22144.982 | H14: 0 | I14: =H14 -> 0 | P14: 15000 | Q14: =+K14/P14 -> 0
A15: WSWT2025800 ผลรวม | C15: 183393 | D15: 21155.4 | E15: 52393 | F15: 22144.982 | G15: 22144.982 | H15: 0
A16: WSWT2025800SM | B16: บจก.อินเทคค์ โกลบอล | C16: 91933 | D16: 86964.15 | E16: 91933 | F16: 87478.167 | G16: 42098.068 | H16: 45380.099 | I16: =H16 -> 45380.099
B17: บจก.เอพีเอ็ม อะโกร | C17: 14000 | D17: 0 | E17: 10000 | F17: 0 | G17: 0 | H17: 0 | I17: =H17 -> 0
B18: บจก.วีซีเอฟ | C18: 20000 | D18: 0 | E18: 0 | F18: 0 | G18: 0 | H18: 0 | I18: =H18 -> 0
B19: บจก.กันยาวิ | C19: 8000 | D19: 8400 | E19: 8000 | F19: 8605.52 | G19: 8605.52 | H19: 0 | I19: =H19 -> 0
A20: WSWT2025800SM ผลรวม | C20: 133933 | D20: 95364.15 | E20: 109933 | F20: 96083.687 | G20: 50703.588 | H20: 45380.099 | I20: =H20 -> 45380.099 | P20: 16000 | Q20: =+K20/P20 -> 0
A21: WSWT2121670SM | B21: บจก.บลูฟาโล่ | C21: 5000 | D21: 0 | E21: 0 | F21: 0 | G21: 0 | H21: 0
B22: บจก.เอ็นบี ดิสทริบิวชั่น | C22: 30000 | D22: 0 | E22: 0 | F22: 0 | G22: 0 | H22: 0 | I22: =H22 -> 0
B23: บจก.หนองบัวฟีดมิลล์ | C23: 5000 | D23: 5250 | E23: 5000 | F23: 5378.45 | G23: 5378.45 | H23: 0
A24: WSWT2121670SM ผลรวม | C24: 40000 | D24: 5250 | E24: 5000 | F24: 5378.45 | G24: 5378.45 | H24: 0 | I24: =H24 -> 0
A25: WSWT2125650 | B25: บจก.หนองบัวฟีดมิลล์ | C25: 15000 | D25: 0 | E25: 15000 | F25: 16554.45 | G25: 16554.45 | H25: 0
A26: WSWT2125650 ผลรวม | C26: 15000 | D26: 0 | E26: 15000 | F26: 16554.45 | G26: 16554.45 | H26: 0 | I26: =H26 -> 0
A27: WSWT23211125120SMFX | B27: โรงสีธัญญกิจ(ราชบุรี) | C27: 10000 | D27: 0 | E27: 0 | F27: 0 | G27: 0 | H27: 0
A28: WSWT23211125120SMFX ผลรวม | C28: 10000 | D28: 0 | E28: 0 | F28: 0 | G28: 0 | H28: 0 | I28: =H28 -> 0
A29: WSWT2321750 | B29: คุณวัลภา เผ่าเต็ม | C29: 10000 | D29: 1560.3 | E29: 1500 | F29: 1678.3991 | G29: 0 | H29: 1678.3991 | I29: =H29 -> 1678.3991
A30: WSWT2321750 ผลรวม | C30: 10000 | D30: 1560.3 | E30: 1500 | F30: 1678.3991 | G30: 0 | H30: 1678.3991 | I30: =H30 -> 1678.3991
A31: WSWT2325650 | B31: พันธุ์ข้าว | C31: 30000 | D31: 31500 | E31: 30000 | F31: 29756.1 | G31: 29756.1 | H31: 0 | P31: 15000 | Q31: =+K31/P31 -> 0
B32: บจก.ซิเบลโก้(บางเลน) | C32: 10000 | D32: 0 | E32: 5000 | F32: 0 | G32: 0 | H32: 0 | I32: =H32 -> 0
B33: คุณปราสาท เจริญธรรมรักษา | C33: 5000 | D33: 5250 | E33: 5000 | F33: 4959.35 | G33: 4959.35 | H33: 0 | I33: =H33 -> 0
A34: WSWT2325650 ผลรวม | C34: 45000 | D34: 36750 | E34: 40000 | F34: 34715.45 | G34: 34715.45 | H34: 0 | I34: =H34 -> 0
A35: WSWT2625650 | B35: บจก.กบินทร์อินทรีย์ | C35: 8000 | D35: 8400 | E35: 8000 | F35: 9499.6 | G35: 1765 | H35: 7734.6 | I35: =H35 -> 7734.6
A36: WSWT2625650 ผลรวม | C36: 8000 | D36: 8400 | E36: 8000 | F36: 9499.6 | G36: 1765 | H36: 7734.6 | I36: =H36 -> 7734.6
A37: WSWT2625800 | B37: บจก.แลบอินเตอร์ | C37: 10000 | D37: 0 | E37: 0 | F37: 0 | G37: 0 | H37: 0 | I37: =H37 -> 0
A38: WSWT2625800 ผลรวม | C38: 10000 | D38: 0 | E38: 0 | F38: 0 | G38: 0 | H38: 0 | I38: =H38 -> 0
A39: WSWT2825850 | B39: บจก.ไทยร่วมใจน้ำมันพืช | C39: 53000 | D39: 52500 | E39: 50000 | F39: 59372.5 | G39: 59372.5 | H39: 0 | I39: =H39 -> 0
A40: WSWT2825850 ผลรวม | C40: 53000 | D40: 52500 | E40: 50000 | F40: 59372.5 | G40: 59372.5 | H40: 0 | I40: =H40 -> 0
A41: WSWTFCL022325650 | B41: คุณปราสาท เจริญธรรมรักษา | C41: 15000 | D41: 15750 | E41: 15000 | F41: 14878.05 | G41: 0 | H41: 14878.05
...

Sheet 10(Order)
A2: เลขที่ SO | B2: (หลายรายการ)
A3: วันส่ง | B3: (หลายรายการ)
A4: ชื่อลูกค้า | B4: (ทั้งหมด)
A6: ประเภท | B6: ผลรวม ของ จำนวนส่ง | C6: ผลรวม ของ ค้างพิมพ์ | D6: ผลรวม ของ ค้างตัด | E6: ผลรวม ของ ใช้ | F6: ผลรวม ของ Stock | G6: ผลรวม ของ ค้างทอ
A7: WSWT1921720 | B7: 130000 | C7: 52500 | D7: 130000 | E7: 121678.7 | F7: 0 | G7: 121678.7
A8: WSWT1925800 | B8: 90000 | C8: 94500 | D8: 90000 | E8: 79209.9 | F8: 13655 | G8: 65554.9
A9: WSWT2025800 | B9: 160363 | C9: 168381.15 | D9: 160363 | E9: 168020.33 | F9: 62865 | G9: 105155.33
A10: WSWT2025800SM | B10: 263520 | C10: 264982.2 | D10: 257293 | E10: 272379.98 | F10: 270190.45 | G10: 2189.53
A11: WSWT2025850 | B11: 320000 | C11: 336000 | D11: 320000 | E11: 355396.8 | F11: 72224.9 | G11: 283171.9 | L11: =76*2500 -> 190000
A12: WSWT2121670SM | B12: 9000 | C12: 6300 | D12: 9000 | E12: 6957.06 | F12: 6957.06 | G12: 0
A13: WSWT2625850SM | B13: 10000 | C13: 10500 | D13: 10000 | E13: 12433.3 | F13: 0 | G13: 12433.3
A14: ผลรวมทั้งหมด | B14: 982883 | C14: 933163.35 | D14: 976656 | E14: 1016076.1 | F14: 425892.41 | G14: 590183.66
A37: ยอดส่ง 1/1/68 - 17/1/68 | B37: 1287052
A38: Order+ส่ง | B38: =++B22+B37 -> 1287052
A39: ประมาณการ | I39: 0
A41: Order+ส่ง+ประมาณการ | B41: =+B22+B37+B39+B29 -> 1287052 | C41: =+C22+C37+C39+C29 -> 0 | D41: =+D22+D37+D39+D29 -> 0 | E41: =+E22+E37+E39+E29 -> 0 | F41: =+F22+F37+F39+F29 -> 0 | G41: =+G22+G37+G39+G29 -> 0
B43: 3000000 | I43: 9
B45: =+B41-B43 -> -1712948
D46: =+D22/I43 -> 0
C47: =+C41/I43 -> 0 | D47: =+D41/I43 -> 0 | G47: =+G41/I43 -> 0

Sheet 10(Order) แยกลูกค้า
A1: เลขที่ SO | B1: (หลายรายการ)
A2: วันส่ง | B2: รอแจ้ง
A4: ประเภท | B4: ชื่อลูกค้า | C4: ผลรวม ของ จำนวนส่ง | D4: ผลรวม ของ ค้างพิมพ์ | E4: ผลรวม ของ ค้างตัด | F4: ผลรวม ของ Stock | G4: ผลรวม ของ ค้างทอ | I4: vn
A5: WSWT19251000SM | B5: บจก.อินเทคค์ โกลบอล | C5: 503 | D5: 0 | E5: 503 | F5: 0 | G5: 0 | H5: =G5 -> 0
A6: WSWT19251000SM ผลรวม | C6: 503 | D6: 0 | E6: 503 | F6: 0 | G6: 0 | H6: =G6 -> 0
A7: WSWT2025800SM | B7: บจก.อินเทคค์ โกลบอล | C7: 3054 | D7: 252 | E7: 2529 | F7: 251.46 | G7: 0 | H7: =G7 -> 0
B8: บจก.เอพีเอ็ม อะโกร | C8: 8000 | D8: 5250 | E8: 5000 | F8: 5518.15 | G8: 0
A9: WSWT2025800SM ผลรวม | C9: 11054 | D9: 5502 | E9: 7529 | F9: 5769.61 | G9: 0 | H9: =G9 -> 0
A10: WSWT2121670SM | B10: บจก.ที.ซี.ยูเนี่ยน อโกรเทค | C10: 25000 | D10: 26250 | E10: 25000 | F10: 26892.25 | G10: 0 | H10: =G10 -> 0
B11: บจก.เอพีเอ็ม อะโกร | C11: 13000 | D11: 13156.5 | E11: 12530 | F11: 14107.884 | G11: 0
B12: บจก.เอสพีเอ็ม อาหารสัตว์ | C12: 11000 | D12: 11550 | E12: 11000 | F12: 12139.93 | G12: 0 | H12: =G12 -> 0
A13: WSWT2121670SM ผลรวม | C13: 49000 | D13: 50956.5 | E13: 48530 | F13: 53140.064 | G13: 0 | H13: =G13 -> 0
A14: WSWT2321112512551 | B14: บจก.น้ำตาลทิพย์สุโขทัย | C14: 437878 | D14: 458196.9 | E14: 436378 | F14: 20359 | G14: 449048.45 | H14: =G14 -> 449048.45
A15: WSWT2321112512551 ผลรวม | C15: 437878 | D15: 458196.9 | E15: 436378 | F15: 20359 | G15: 449048.45
A16: ผลรวมทั้งหมด | C16: 498435 | D16: 514655.4 | E16: 492940 | F16: 79268.674 | G16: 449048.45 | H16: =G16 -> 449048.45
H18: =G18 -> 0
H19: =G19 -> 0
H20: =G20 -> 0
H21: =G21 -> 0
H23: =G23 -> 0
H25: =G25 -> 0
H27: =G27 -> 0
H28: =G28 -> 0
H29: =G29 -> 0
H31: =G31 -> 0
H32: =G32 -> 0
H33: =G33 -> 0
... H68: =G68 -> 0
H70: =SUM(H5:H69) -> 898096.9
D119: Cap พิมพ์ | E119: Cap ตัด | F119: Stock 16/7 บ่าย | G119: Cap ทอ | I119: วันทงาน
B120: lส่ง | C120: 1-16/7 | D120: 160000 | E120: 160000 | G120: 120000 | I120: 12
C121: 1975256 | D121: =+D120*I120 -> 1920000 | E121: =+E120*I120 -> 1920000 | F121: 825147 | G121: =+G120*I120 -> 1440000
A122: เบทาโกรส่งแล้ว | B122: 20700 | C122: 424374
A123: เบทาโกรส่งแล้ว | B123: 20800 | C123: 155973
C126: รวมส่ง+ค้างส่ง | D126: ส่วนต่างCapคงเหลือ | E126: ส่วนต่างCapคงเหลือ | F126: คงเหลือ
C127: =+C50+C121 -> 1975256 | D127: =+D121-D50 -> 1920000 | E127: =+E121-E50 -> 1920000 | F127: =+F121-F50 -> 825147 | G127: =+G121-G50 -> 1440000
B129: 20700VN 20/7 | G129: 350000

Sheet 10(Fc) แยกลูกค้
A1: เลขที่ SO | B1: ประมาณการ
A2: วันส่ง | B2: (หลายรายการ) | D2: 12
A4: ประเภท | B4: ชื่อลูกค้า | C4: ผลรวม ของ จำนวนส่ง | D4: ผลรวม ของ ค้างพิมพ์ | E4: ผลรวม ของ ค้างตัด | F4: ผลรวม ของ ใช้ | G4: ผลรวม ของ Stock | H4: ผลรวม ของ ค้างทอ
A5: WSWT2325650 | B5: พันธุ์ข้าว | C5: 30000 | D5: 31500 | E5: 30000 | F5: 29756.1 | G5: 29756.1 | H5: 0
A6: WSWT2325650 ผลรวม | C6: 30000 | D6: 31500 | E6: 30000 | F6: 29756.1 | G6: 29756.1 | H6: 0
A7: WSWT2625650 | B7: บจก.กบินทร์อินทรีย์ | C7: 8000 | D7: 8400 | E7: 8000 | F7: 9499.6 | G7: 1765 | H7: 7734.6
A8: WSWT2625650 ผลรวม | C8: 8000 | D8: 8400 | E8: 8000 | F8: 9499.6 | G8: 1765 | H8: 7734.6
A9: ผลรวมทั้งหมด | C9: 38000 | D9: 39900 | E9: 38000 | F9: 39255.7 | G9: 31521.1 | H9: 7734.6
H43: =+GETPIVOTDATA("ผลรวม ของ ค้างทอ",$A$4)+H41 -> 7734.6
I119: วันทงาน
I120: 12
C121: 1975256 | D121: =+D120*I120 -> 0 | E121: =+E120*I120 -> 0 | F121: 825147 | G121: =+G120*I120 -> 0
A122: เบทาโกรส่งแล้ว | B122: 20700 | C122: 424374
A123: เบทาโกรส่งแล้ว | B123: 20800 | C123: 155973
C126: รวมส่ง+ค้างส่ง | D126: ส่วนต่างCapคงเหลือ | E126: ส่วนต่างCapคงเหลือ | F126: คงเหลือ
C127: =+C50+C121 -> 1975256 | D127: =+D121-D50 -> 0 | E127: =+E121-E50 -> 0 | F127: =+F121-F50 -> 825147 | G127: =+G121-G50 -> 0
B129: 20700VN 20/7 | G129: 350000

Sheet ค้างทอ2-9-68
A3: ผลรวม ของ ค้างทอ
A4: ป้ายชื่อแถว | B4: 45901 | C4: 45903 | D4: 45904 | E4: 45905 | F4: 45907 | G4: 45910 | H4: 45912 | I4: 45914 | J4: 45917 | K4: 45921 | L4: 45925 | M4: 45940 | N4: ผลรวมทั้งหมด
A5: WSWT1625800 | B5: 3702 | D5: 7404.1 | N5: =SUM(B5:M5) -> 11106.1
A6: WSWT1625800SM | C6: 0 | N6: =SUM(B6:M6) -> 0
A7: WSWT1825800SM | F7: 3841.75 | N7: =SUM(B7:M7) -> 3841.75
A8: WSWT1921720 | B8: 0 | D8: 4679.95 | N8: =SUM(B8:M8) -> 4679.95
A9: WSWT19251000SM | N9: =SUM(B9:M9) -> 0
A10: WSWT1925800 | E10: 55162.9 | N10: =SUM(B10:M10) -> 55162.9
A11: WSWT2025800 | B11: 0 | C11: 0 | G11: 0 | I11: 0 | J11: 0 | K11: 0 | N11: =SUM(B11:M11) -> 0
A12: WSWT2025800SM | C12: 0 | D12: 0 | E12: 0 | J12: 0 | L12: 4599.67 | N12: =SUM(B12:M12) -> 4599.67
A13: WSWT2121670SM | C13: 0 | K13: 0 | N13: =SUM(B13:M13) -> 0
A14: WSWT2325800 | D14: 0 | N14: =SUM(B14:M14) -> 0
A15: WSWT2625650 | B15: 1621 | N15: =SUM(B15:M15) -> 1621
A16: WSWT2625850SM | C16: 0 | D16: 0 | H16: 0 | L16: 37299.9 | M16: 12433.3 | N16: =SUM(B16:M16) -> 49733.2
A17: WSWT2825850 | D17: 0 | N17: =SUM(B17:M17) -> 0
A18: ผลรวมทั้งหมด | B18: =SUM(B5:B17) -> 5323 | C18: =SUM(C5:C17) -> 0 | D18: =SUM(D5:D17) -> 12084.05 | E18: =SUM(E5:E17) -> 55162.9 | F18: =SUM(F5:F17) -> 3841.75 | G18: =SUM(G5:G17) -> 0 | H18: =SUM(H5:H17) -> 0 | I18: =SUM(I5:I17) -> 0 | ... N18: =SUM(N5:N17) -> 130744.57

Sheet ค้างทอ20-9-68
A3: ผลรวม ของ ค้างทอ
A4: ป้ายชื่อแถว | B4: 45921 | C4: 45925 | D4: 45927 | E4: 45929 | F4: 45932 | G4: 45933 | H4: 45934 | I4: 45940 | J4: 45941 | K4: 45942 | L4: 45945 | M4: 45946 | N4: 45947 | O4: 45949 | P4: 45952 | Q4: 45953 | R4: 45954 | S4: 45955 | T4: 45956 | U4: ผลรวมทั้งหมด
A5: WSWT1625800 | U5: =SUM(B5:T5) -> 0
A6: WSWT1725800 | U6: =SUM(B6:T6) -> 0
A7: WSWT1825800 | U7: =SUM(B7:T7) -> 0
A8: WSWT1825800SM | U8: =SUM(B8:T8) -> 0
A9: WSWT1921720 | C9: 0 | D9: 23399.75 | E9: 23399.75 | F9: 37439.6 | K9: 37439.6 | U9: =SUM(B9:T9) -> 121678.7
A10: WSWT19251000SM | C10: 0 | U10: =SUM(B10:T10) -> 0
A11: WSWT1925800 | G11: 47952.7 | N11: 17602.2 | U11: =SUM(B11:T11) -> 65554.9
A12: WSWT2025650 | B12: 4401.1 | U12: =SUM(B12:T12) -> 4401.1
A13: WSWT2025800 | B13: 0 | C13: 0 | G13: 0 | I13: 20955 | K13: 31432.5 | N13: 26936.605 | O13: 25831.229 | U13: =SUM(B13:T13) -> 105155.33
A14: WSWT2025800SM | B14: 0 | C14: 0 | E14: 0 | F14: 0 | H14: 0 | I14: 0 | J14: 0 | K14: 0 | L14: 0 | M14: 0 | N14: 0 | O14: 0 | P14: 0 | Q14: 0 | R14: 0 | S14: 0 | T14: 2189.53 | U14: =SUM(B14:T14) -> 2189.53
A15: WSWT2025850 | B15: 0 | F15: 0 | H15: 11315.7 | I15: 11315.7 | J15: 5657.85 | K15: 35798.125 | L15: 16903.7 | M15: 24901.525 | N15: 14144.625 | O15: 33248.6 | P15: 21793.2 | Q15: 22352 | R15: 39046.15 | S15: 16135.35 | T15: 30559.375 | U15: =SUM(B15:T15) -> 283171.9
A16: WSWT2121670SM | B16: 0 | K16: 0 | T16: 0 | U16: =SUM(B16:T16) -> 0
A17: WSWT2125650 | U17: =SUM(B17:T17) -> 0
A18: WSWT2125800 | U18: =SUM(B18:T18) -> 0
A19: WSWT2321112512551 | U19: =SUM(B19:T19) -> 0
A20: WSWT2325650 | U20: =SUM(B20:T20) -> 0
A21: WSWT2625650 | U21: =SUM(B21:T21) -> 0
A22: WSWT2625800 | U22: =SUM(B22:T22) -> 0
A23: WSWT2625850SM | C23: 21311.316 | I23: 12433.3 | U23: =SUM(B23:T23) -> 33744.616
A24: WSWT2825850 | C24: 52761.285 | U24: =SUM(B24:T24) -> 52761.285
A25: ผลรวมทั้งหมด | B25: =SUM(B5:B24) -> 4401.1 | C25: =SUM(C5:C24) -> 74072.601 | D25: =SUM(D5:D24) -> 23399.75 | E25: =SUM(E5:E24) -> 23399.75 | F25: =SUM(F5:F24) -> 37439.6 | G25: =SUM(G5:G24) -> 47952.7 | H25: =SUM(H5:H24) -> 11315.7 | I25: =SUM(I5:I24) -> 44704 | ... U25: =SUM(U5:U24) -> 668657.36

Sheet 24-9-68
B2: เรียงกำหนดส่ง | D2: ลบ 0 | T2: เรียง 1
B3: ข้อมูลUpdate ณ. วันที่ | D3: 45924 | E3: เวลา | G3: 12
A4: วันรับออร์เดอร์/แบบ | B4: เลขที่ SO | C4: ชื่อลูกค้า | E4: 10.3 | I4: น้ำหนัก | L4: บิด/จับจีบ | M4: ถุงใน | Q4: 44873 | S4: วิธีบรรจุ | T4: วันส่ง | U4: จำนวนส่ง | V4: ตัดเย็บ (ใบ) | W4: 44873 | X4: พิมพ์ (ใบ) | Y4: 44876 | Z4: ผ้าทอ (เมตร) Updateณ | AB4: 44876 | AD4: ผ้าเคลือบ(เมตร) | AF4: หมายเหตุ | AG4: เครื่อง
B5: เลขที่ SO | C5: ชื่อลูกค้า | D5: ตรา | E5: กว้าง | F5: ยาว | G5: สี | H5: เคลือบ | I5: กรัม/ใบ | J5: * | K5: aw | L5: บิด/จับจีบ | M5: กว้าง | N5: ยาว | O5: หนา | P5: ใช้(กก.) | Q5: Stock(กก.) | R5: ผลิต(กก.) | S5: วิธีบรรจุ | T5: วันส่ง | U5: จำนวนส่ง | V5: StockFG | W5: ค้างตัด | X5: พิมพ์แล้ว | Y5: ค้างพิมพ์ | Z5: ประเภท | AA5: ใช้ | AB5: Stock | AC5: ค้างทอ | AD5: Stock | AE5: ค้างเคลือบ | AF5: หมายเหตุ | AG5: ที่พิมพ์ได้ | AH5: process | AI5: Lead time | AJ5: วันที่ส่งPL | AK5: เคลือบ | AL5: ได้ ART | AM5: พิมพ์ | AN5: จีบ-บิด | AO5: ตัด-เย็บ | AP5: ทอ | AQ5: สวมถุง | AR5: เย็บปาก | AS5: PT | AT5: ม้วน | AU5: ตัด | AV5: ตอกตาไก่ | AW5: GROUP | AX5: ART | AY5: หมายเหตุปัญหา | AZ5: ราคา/ใบ | BA5: ราคารวม | BB5: workweek | BC5: เส้นเทป | BD5: จำนวน
A6: 45897 | B6: MK68-001045 | C6: บจก.เคอรี่ฟลาวมิลล์ | D6: น้องเอินโดนัท 10กก | E6: 16 | F6: 25 | G6: ขาว | H6: 0 | I6: 45 | J6: ± | K6: 5 | L6: ไม่ | M6: ไม่สวมถุงใน | N6: 0 | O6: 0 | P6: 0 | Q6: 0 | R6: 0 | S6: ห่ออัดเบลแบน500 | T6: 45925 | U6: 5000 | V6: 5000 | W6: 0 | X6: 5400 | Y6: 0 | Z6: WSWT1625800 | AA6: 0 | AB6: 0 | AC6: 0 | AD6: 0 | AE6: 0 | AF6: 0 | AG6: พร้อมส่ง | AH6: P7 | AI6: 2 | AJ6: 45925 | AK6: 0 | AL6: 45916 | AM6: 45923 | AN6: 45924 | AO6: 45924 | AP6: 45920 | AQ6: 0 | AR6: 0 | AS6: 0 | AT6: 0 | AU6: 0 | AV6: 0 | AW6: งานพิมพ์ | AX6: / | AY6: สีลอกทั้งหมด | AZ6: 0 | BA6: 0 | BB6: 0 | BC6: WRWT25800/WRWT25800 | BD6: 0
A7: 0 | B7: 0 | C7: 0 | D7: 0 | E7: 16 | F7: 25 | G7: ขาว | H7: 0 | I7: 45 | J7: ± | K7: 5 | L7: 0 | M7: 0 | N7: 0 | O7: 0 | P7: 0 | Q7: 0 | R7: 0 | S7: 0 | U7: 0 | V7: 0 | W7: 0 | X7: 0 | Y7: 0 | Z7: WSWT1625800 | AA7: 0 | AB7: 0 | AC7: 0 | AD7: 0 | AE7: 0 | AF7: ระบุในSD | AG7: ยังไม่ได้พิมพ์ | AH7: 0 | AI7: Lead time | AJ7: 0 | AK7: 0 | AL7: 0 | AM7: 0 | AN7: 0 | AO7: 0 | AP7: 0 | AQ7: 0 | AR7: 0 | AS7: 0 | AT7: 0 | AU7: 0 | AV7: 0 | AW7: 0 | AX7: 0 | AY7: 0 | AZ7: 0 | BA7: 0 | BB7: 0 | BC7: WRWT160800/WRWT25800 | BD7: 0
A8: 45923 | B8: MK68-001164 | C8: ร้านเห็ดไพลิน | D8: เพชร | E8: 18 | F8: 28 | G8: ขาว | H8: 0 | I8: 50 | J8: ± | K8: 5 | L8: ไม่ | M8: 19 | N8: 29 | O8: 40 | P8: 67.96838 | Q8: 0 | R8: 67.96838 | S8: 500กระสอบ | T8: 45930 | U8: 5000 | V8: 0 | W8: 5000 | X8: 0 | Y8: 5250 | Z8: WSWT1825800 | AA8: 4121.15 | AB8: 2500 | AC8: 1621.15 | AD8: 0 | AE8: 0 | AF8: 0 | AG8: ยังไม่ได้พิมพ์ | AH8: P9 | AI8: 3 | AJ8: 45930 | AK8: 0 | AL8: 45920 | AM8: 45927 | AN8: 45928 | AO8: 45928 | AP8: 45925 | AQ8: 45929 | AR8: 0 | AS8: 0 | AT8: 0 | AU8: 0 | AV8: 0 | AW8: งานพิมพ์ | AX8: / | AY8: 0 | AZ8: 0 | BA8: 0 | BB8: 0 | BC8: WRWT25800/WRWT25800 | BD8: 111.53512
A9: 45923 | B9: MK68-001161 | C9: หจก.อนนท์อุตสาหกรรม | D9: อนนท์ 20 กก. | E9: 18 | F9: 28 | G9: ขาว | H9: 0 | I9: 50 | J9: ± | K9: 5 | L9: ไม่ | M9: 19 | N9: 31 | O9: 40 | P9: 72.655855 | Q9: 0 | R9: 72.655855 | S9: 500กระสอบแบน | T9: 45950 | U9: 5000 | V9: 0 | W9: 5000 | X9: 0 | Y9: 5250 | Z9: WSWT1825800 | AA9: 4121.15 | AB9: 0 | AC9: 4121.15 | AD9: 0 | AE9: 0 | AF9: 0 | AG9: ยังไม่ได้พิมพ์ | AH9: P9 | AI9: 3 | AJ9: 45950 | AK9: 0 | AL9: 45940 | AM9: 45947 | AN9: 45948 | AO9: 45948 | AP9: 45945 | AQ9: 45949 | AR9: 0 | AS9: 0 | AT9: 0 | AU9: 0 | AV9: 0 | AW9: งานพิมพ์ | AX9: / | AY9: 0 | AZ9: 0 | BA9: 0 | BB9: 0 | BC9: WRWT25800/WRWT25800 | BD9: 283.53512
A10: 45923 | B10: MK68-001162 | C10: หจก.อนนท์อุตสาหกรรม | D10: ดาว 20 กก. | E10: 18 | F10: 28 | G10: ขาว | H10: 0 | I10: 50 | J10: ± | K10: 5 | L10: ไม่ | M10: 19 | N10: 31 | O10: 40 | P10: 363.27927 | Q10: 0 | R10: 363.27927 | S10: 500กระสอบแบน | T10: 45950 | U10: 25000 | V10: 0 | W10: 25000 | X10: 0 | Y10: 26250 | Z10: WSWT1825800 | AA10: 20605.75 | AB10: 0 | AC10: 20605.75 | AD10: 0 | AE10: 0 | AF10: 0 | AG10: ยังไม่ได้พิมพ์ | AH10: P9 | AI10: 3 | AJ10: 45950 | AK10: 0 | AL10: 45940 | AM10: 45947 | AN10: 45948 | AO10: 45948 | AP10: 45945 | AQ10: 45949 | AR10: 0 | AS10: 0 | AT10: 0 | AU10: 0 | AV10: 0 | AW10: งานพิมพ์ | AX10: / | AY10: 0 | AZ10: 0 | BA10: 0 | BB10: 0 | BC10: WRWT25800/WRWT25800 | BD10: 1417.6756
A11: 45923 | B11: MK68-001162 | C11: หจก.อนนท์อุตสาหกรรม | D11: ดาว 20 กก. | E11: 18 | F11: 28 | G11: ขาว | H11: 0 | I11: 50 | J11: ± | K11: 5 | L11: ไม่ | M11: 19 | N11: 31 | O11: 40 | P11: 363.27927 | Q11: 0 | R11: 363.27927 | S11: 500กระสอบแบน | T11: 45955 | U11: 25000 | V11: 0 | W11: 25000 | X11: 0 | Y11: 26250 | Z11: WSWT1825800 | AA11: 20605.75 | AB11: 0 | AC11: 20605.75 | AD11: 0 | AE11: 0 | AF11: 0 | AG11: ยังไม่ได้พิมพ์ | AH11: P9 | AI11: 3 | AJ11: 45955 | AK11: 0 | AL11: 45945 | AM11: 45952 | AN11: 45953 | AO11: 45953 | AP11: 45950 | AQ11: 45954 | AR11: 0 | AS11: 0 | AT11: 0 | AU11: 0 | AV11: 0 | AW11: งานพิมพ์ | AX11: / | AY11: 0 | AZ11: 0 | BA11: 0 | BB11: 0 | BC11: WRWT25800/WRWT25800 | BD11: 1417.6756
A12: 45923 | B12: MK68-001162 | C12: หจก.อนนท์อุตสาหกรรม | D12: ดาว 20 กก. | E12: 18 | F12: 28 | G12: ขาว | H12: 0 | I12: 50 | J12: ± | K12: 5 | L12: ไม่ | M12: 19 | N12: 31 | O12: 40 | P12: 363.27927 | Q12: 0 | R12: 363.27927 | S12: 500กระสอบแบน | T12: 45958 | U12: 25000 | V12: 0 | W12: 25000 | X12: 0 | Y12: 26250 | Z12: WSWT1825800 | AA12: 20605.75 | AB12: 0 | AC12: 20605.75 | AD12: 0 | AE12: 0 | AF12: 0 | AG12: พร้อมส่ง | AH12: P9 | AI12: 3 | AJ12: 45958 | AK12: 0 | AL12: 45948 | AM12: 45955 | AN12: 45956 | AO12: 45956 | AP12: 45953 | AQ12: 45957 | AR12: 0 | AS12: 0 | AT12: 0 | AU12: 0 | AV12: 0 | AW12: งานพิมพ์ | AX12: / | AY12: 0 | AZ12: 0 | BA12: 0 | BB12: 0 | BC12: WRWT25800/WRWT25800 | BD12: 1417.6756
A13: 45923 | B13: MK68-001162 | C13: หจก.อนนท์อุตสาหกรรม | D13: ดาว 20 กก. | E13: 18 | F13: 28 | G13: ขาว | H13: 0 | I13: 50 | J13: ± | K13: 5 | L13: ไม่ | M13: 19 | N13: 31 | O13: 40 | P13: 363.27927 | Q13: 0 | R13: 363.27927 | S13: 500กระสอบแบน | T13: 45961 | U13: 25000 | V13: 0 | W13: 25000 | X13: 0 | Y13: 26250 | Z13: WSWT1825800 | AA13: 20605.75 | AB13: 0 | AC13: 20605.75 | AD13: 0 | AE13: 0 | AF13: 0 | AG13: พร้อมส่ง | AH13: P9 | AI13: 3 | AJ13: 45961 | AK13: 0 | AL13: 45951 | AM13: 45958 | AN13: 45959 | AO13: 45959 | AP13: 45956 | AQ13: 45960 | AR13: 0 | AS13: 0 | AT13: 0 | AU13: 0 | AV13: 0 | AW13: งานพิมพ์ | AX13: / | AY13: 0 | AZ13: 0 | BA13: 0 | BB13: 0 | BC13: WRWT25800/WRWT25800 | BD13: 1417.6756
A14: ประมาณการ | B14: ประมาณการ | C14: บจก.ฟาร์เธอร์ส วิง ซัพพลาย | D14: รถไฟ | E14: 18 | F14: 30 | G14: ขาว | H14: 0 | I14: 54 | J14: ± | K14: 5 | L14: บิด | M14: 19 | N14: 33 | O14: 40 | P14: 232.02999 | Q14: 0 | R14: 232.02999 | S14: 500กระสอบ | T14: รอแจ้ง | U14: 15000 | V14: 0 | W14: 15000 | X14: 0 | Y14: 15750 | Z14: WSWT1825800 | AA14: 13201.65 | AB14: 0 | AC14: 13201.65 | AD14: 0 | AE14: 0 | AF14: 0 | AG14: รอตัด | AH14: P9 | AI14: 3 | AJ14: รอแจ้ง | AK14: 0 | AL14: #VALUE! | AM14: #VALUE! | AN14: #VALUE! | AO14: #VALUE! | AP14: #VALUE! | AQ14: #VALUE! | AR14: 0 | AS14: 0 | AT14: 0 | AU14: 0 | AV14: 0 | AW14: งานพิมพ์ | AX14: รอART | AY14: 0 | AZ14: 0 | BA14: 0 | BB14: 0 | BC14: WRWT25800/WRWT25800 | BD14: 908.27352
A15: 0 | B15: 0 | E15: 18 | F15: 30 | G15: ขาว | H15: 0 | I15: 54 | J15: ± | K15: 5 | L15: 0 | M15: 0 | N15: 0 | O15: 0 | P15: 0 | Q15: 0 | R15: 0 | S15: 0 | U15: 0 | V15: 0 | W15: 0 | X15: 0 | Y15: 0 | Z15: WSWT1825800 | AA15: 103866.95 | AB15: 2500 | AC15: 101366.95 | AD15: 0 | AE15: 0 | AF15: ระบุในSD | AG15: ยังไม่ได้พิมพ์ | AH15: 0 | AI15: Lead time | AJ15: 0 | AK15: 0 | AL15: 0 | AM15: 0 | AN15: 0 | AO15: 0 | AP15: 0 | AQ15: 0 | AR15: 0 | AS15: 0 | AT15: 0 | AU15: 0 | AV15: 0 | AW15: 0 | AX15: 0 | AY15: 0 | AZ15: 0 | BA15: 0 | BB15: 0 | BC15: WRWT25800/WRWT25800 | BD15: 0
A16: 45916 | B16: MK68-001117 | C16: บจก.เอ็กเซลเล้นท์ ไพโอเนียร์ | D16: นกทอง | E16: 19 | F16: 30 | G16: ขาว | H16: 0 | I16: 60 | J16: ± | K16: 5 | L16: บิด | M16: ไม่สวมถุงใน | N16: 0 | O16: 0 | P16: 0 | Q16: 0 | R16: 0 | S16: 500กระสอบ | T16: 45925 | U16: 20000 | V16: 0 | W16: 20000 | X16: 20940 | Y16: 0 | Z16: WSWT1925800 | AA16: 0 | AB16: 0 | AC16: 0 | AD16: 0 | AE16: 0 | AF16: 0 | AG16: ยังไม่ได้พิมพ์ | AH16: P7 | AI16: 2 | AJ16: 45925 | AK16: 0 | AL16: 45916 | AM16: 45923 | AN16: 45924 | AO16: 45924 | AP16: 45920 | AQ16: 0 | AR16: 0 | AS16: 0 | AT16: 0 | AU16: 0 | AV16: 0 | AW16: งานพิมพ์ | AX16: / | AY16: 0 | AZ16: 0 | BA16: 0 | BB16: 0 | BC16: WRWT25800/WRWT25800 | BD16: 0
A17: 45920 | B17: MK68-001139 | C17: บจก.เพรซิเดนท์ฟลาวมิลล์ | D17: ผึ้งเหลือง | E17: 19 | F17: 30 | G17: ขาว | H17: 0 | I17: 60 | J17: ± | K17: 5 | L17: บิด | M17: ไม่สวมถุงใน | N17: 0 | O17: 0 | P17: 0 | Q17: 0 | R17: 0 | S17: 500กระสอบแบน | T17: 45938 | U17: 50000 | V17: 0 | W17: 50000 | X17: 0 | Y17: 52500 | Z17: WSWT1925800 | AA17: 44005.5 | AB17: 39260 | AC17: 4745.5 | AD17: 0 | AE17: 0 | AF17: 0 | AG17: ยังไม่ได้พิมพ์ | AH17: P7 | AI17: 2 | AJ17: 45938 | AK17: 0 | AL17: 45929 | AM17: 45936 | AN17: 45937 | AO17: 45937 | AP17: 45933 | AQ17: 0 | AR17: 0 | AS17: 0 | AT17: 0 | AU17: 0 | AV17: 0 | AW17: งานพิมพ์ | AX17: / | AY17: เย็น8/10 | AZ17: 0 | BA17: 0 | BB17: 0 | BC17: WRWT25800/WRWT25800 | BD17: 344.62876
A18: 45920 | B18: MK68-001140 | C18: บจก.เพรซิเดนท์ฟลาวมิลล์ | D18: ผึ้งชมพู | E18: 19 | F18: 30 | G18: ขาว | H18: 0 | I18: 60 | J18: ± | K18: 5 | L18: บิด | M18: ไม่สวมถุงใน | N18: 0 | O18: 0 | P18: 0 | Q18: 0 | R18: 0 | S18: 500กระสอบแบน | T18: 45938 | U18: 20000 | V18: 0 | W18: 20000 | X18: 0 | Y18: 21000 | Z18: WSWT1925800 | AA18: 17602.2 | AB18: 0 | AC18: 17602.2 | AD18: 0 | AE18: 0 | AF18: 0 | AG18: รอแบบ | AH18: P7 | AI18: 2 | AJ18: 45938 | AK18: 0 | AL18: 45929 | AM18: 45936 | AN18: 45937 | AO18: 45937 | AP18: 45933 | AQ18: 0 | AR18: 0 | AS18: 0 | AT18: 0 | AU18: 0 | AV18: 0 | AW18: งานพิมพ์ | AX18: / | AY18: เย็น8/10 | AZ18: 0 | BA18: 0 | BB18: 0 | BC18: WRWT25800/WRWT25800 | BD18: 1278.3109
A19: 45920 | B19: MK68-001140 | C19: บจก.เพรซิเดนท์ฟลาวมิลล์ | D19: ผึ้งชมพู | E19: 19 | F19: 30 | G19: ขาว | H19: 0 | I19: 60 | J19: ± | K19: 5 | L19: บิด | M19: ไม่สวมถุงใน | N19: 0 | O19: 0 | P19: 0 | Q19: 0 | R19: 0 | S19: 500กระสอบแบน | T19: 45952 | U19: 20000 | V19: 0 | W19: 20000 | X19: 0 | Y19: 21000 | Z19: WSWT1925800 | AA19: 17602.2 | AB19: 0 | AC19: 17602.2 | AD19: 0 | AE19: 0 | AF19: 0 | AG19: ยังไม่ได้พิมพ์ | AH19: P7 | AI19: 2 | AJ19: 45952 | AK19: 0 | AL19: 45943 | AM19: 45950 | AN19: 45951 | AO19: 45951 | AP19: 45947 | AQ19: 0 | AR19: 0 | AS19: 0 | AT19: 0 | AU19: 0 | AV19: 0 | AW19: งานพิมพ์ | AX19: / | AY19: 0 | AZ19: 0 | BA19: 0 | BB19: 0 | BC19: WRWT25800/WRWT25800 | BD19: 1278.3109
A20: ประมาณการ | B20: ประมาณการ | C20: บจก.ไลม์มาสเตอร์ | D20: LMC 25 kg | E20: 19 | F20: 32 | G20: ขาว | H20: 0 | I20: 64 | J20: ± | K20: 5 | L20: ไม่ | M20: 20 | N20: 35 | O20: 40 | P20: 341.36903 | Q20: 0 | R20: 341.36903 | S20: 500กระสอบแบน | T20: 45961 | U20: 20000 | V20: 233 | W20: 19767 | X20: 0 | Y20: 20755.35 | Z20: WSWT1925800 | AA20: 18501.714 | AB20: 0 | AC20: 18501.714 | AD20: 0 | AE20: 0 | AF20: 0 | AG20: พร้อมส่ง | AH20: P9 | AI20: 3 | AJ20: 45961 | AK20: 0 | AL20: 45951 | AM20: 45958 | AN20: 45959 | AO20: 45959 | AP20: 45956 | AQ20: 45960 | AR20: 0 | AS20: 0 | AT20: 0 | AU20: 0 | AV20: 0 | AW20: งานพิมพ์ | AX20: รอART | AY20: 0 | AZ20: 0 | BA20: 0 | BB20: 0 | BC20: WRWT25800/WRWT25800 | BD20: 1343.6356
A21: ประมาณการ | B21: ประมาณการ | C21: บจก.เอ็กเซลเล้นท์ | D21: รอแบบ | E21: 19 | F21: 30 | G21: ขาว | H21: 0 | I21: 60 | J21: ± | K21: 5 | L21: บิด | M21: ไม่สวมถุงใน | N21: 0 | O21: 0 | P21: 0 | Q21: 0 | R21: 0 | S21: 500กระสอบ | T21: 45961 | U21: 40000 | V21: 0 | W21: 40000 | X21: 0 | Y21: 42000 | Z21: WSWT1925800 | AA21: 35204.4 | AB21: 0 | AC21: 35204.4 | AD21: 0 | AE21: 0 | AF21: 0 | AG21: พร้อมส่ง | AH21: P7 | AI21: 2 | AJ21: 45961 | AK21: 0 | AL21: 45952 | AM21: 45959 | AN21: 45960 | AO21: 45960 | AP21: 45956 | AQ21: 0 | AR21: 0 | AS21: 0 | AT21: 0 | AU21: 0 | AV21: 0 | AW21: งานพิมพ์ | AX21: รอART | AY21: 0 | AZ21: 0 | BA21: 0 | BB21: 0 | BC21: WRWT25800/WRWT25800 | BD21: 2556.6218
