Workbook

Sheet Linkสูตรออร์เดอร์  (2)
B2: เรียงกำหนดส่ง | D2: ลบ 0 | T2: เรียง 1
B3: ข้อมูลUpdate ณ. วันที่ | D3: 45811 | E3: เวลา | G3: 11.03
A4: วันรับออร์เดอร์/แบบ | B4: เลขที่ SO | C4: ชื่อลูกค้า | E4: 10.3 | I4: น้ำหนัก | L4: บิด/จับจีบ | M4: ถุงใน | Q4: =[1]หน้าผ้า!$AC$13 -> 44873 | S4: วิธีบรรจุ | T4: วันส่ง | U4: จำนวนส่ง | V4: ตัดเย็บ (ใบ) | W4: =[1]หน้าผ้า!$AJ$13 -> 44873 | X4: พิมพ์ (ใบ) | Y4: =[1]หน้าผ้า!$AM$13 -> 44876 | Z4: ผ้าทอ (เมตร) Updateณ | AB4: =[1]หน้าผ้า!$AR$12 -> 44876 | AD4: ผ้าเคลือบ(เมตร) | AF4: หมายเหตุ | AG4: เครื่อง
B5: เลขที่ SO | C5: ชื่อลูกค้า | D5: ตรา | E5: กว้าง | F5: ยาว | G5: สี | H5: เคลือบ | I5: กรัม/ใบ | J5: * | K5: aw | L5: บิด/จับจีบ | M5: กว้าง | N5: ยาว | O5: หนา | P5: ใช้(กก.) | Q5: Stock(กก.) | R5: ผลิต(กก.) | S5: วิธีบรรจุ | T5: วันส่ง | U5: จำนวนส่ง | V5: StockFG | W5: ค้างตัด | X5: พิมพ์แล้ว | Y5: ค้างพิมพ์ | Z5: ประเภท | AA5: ใช้ | AB5: Stock | AC5: ค้างทอ | AD5: Stock | AE5: ค้างเคลือบ | AF5: หมายเหตุ | AG5: ที่พิมพ์ได้ | AH5: process | AI5: Lead time | AJ5: วันที่ส่งPL | AK5: เคลือบ | AL5: ได้ ART | AM5: พิมพ์ | AN5: จีบ-บิด | AO5: ตัด-เย็บ | AP5: ทอ | AQ5: สวมถุง | AR5: เย็บปาก | AS5: PT | AT5: ม้วน | AU5: ตัด | AV5: ตอกตาไก่ | AW5: GROUP | AX5: ART | AY5: หมายเหตุปัญหา | AZ5: ราคา/ใบ | BA5: ราคารวม | BB5: workweek | BC5: เส้นเทป | BD5: จำนวน
A6: =[2]หน้าผ้า!C15 -> 0 | B6: =[2]หน้าผ้า!B15 -> 0 | C6: =[2]หน้าผ้า!E15 -> 0 | D6: =[2]หน้าผ้า!F15 -> 0 | E6: =[2]หน้าผ้า!G15 -> 12 | F6: =[2]หน้าผ้า!H15 -> 16 | G6: =[2]หน้าผ้า!I15 -> ขาว | H6: =[2]หน้าผ้า!J15 -> 0 | I6: =[2]หน้าผ้า!L15 -> 25 | J6: =[2]หน้าผ้า!M15 -> ± | K6: =[2]หน้าผ้า!N15 -> 5 | L6: =[2]หน้าผ้า!R15 -> 0 | M6: =[2]หน้าผ้า!T15 -> 0 | N6: =[2]หน้าผ้า!U15 -> 0 | O6: =[2]หน้าผ้า!V15 -> 0 | P6: =[2]หน้าผ้า!AB15 -> 0 | Q6: =[2]หน้าผ้า!AC15 -> 0 | R6: =[2]หน้าผ้า!AD15 -> 0 | S6: =[2]หน้าผ้า!Z15 -> 0 | T6: =[2]หน้าผ้า!X15 -> 0 | U6: =[2]หน้าผ้า!AA15 -> 0 | V6: =[2]หน้าผ้า!AJ15 -> 0 | W6: =[2]หน้าผ้า!AL15 -> 0 | X6: =[2]หน้าผ้า!AM15 -> 0 | Y6: =[2]หน้าผ้า!AN15 -> 0 | Z6: =[2]หน้าผ้า!AO15 -> WSWT1221750 | AA6: =[2]หน้าผ้า!AQ15 -> #REF! | AB6: =[2]หน้าผ้า!AR15 -> #REF! | AC6: =[2]หน้าผ้า!AS15 -> #REF! | AD6: =[2]หน้าผ้า!AT15 -> #REF! | AE6: =[2]หน้าผ้า!AU15 -> #REF! | AF6: =[2]หน้าผ้า!AI15 -> ระบุในSD | AG6: =[3]หน้าผ้า!DC18 -> < Ord 20,000 | AH6: =[2]หน้าผ้า!DL15 -> 0 | AI6: =[2]หน้าผ้า!DM15 -> 0 | AJ6: =[2]หน้าผ้า!DN15 -> 0 | AK6: =[2]หน้าผ้า!DQ15 -> 0 | AL6: =[2]หน้าผ้า!DR15 -> 0 | AM6: =[2]หน้าผ้า!DS15 -> 0 | AN6: =[2]หน้าผ้า!DT15 -> 0 | AO6: =[2]หน้าผ้า!DU15 -> 0 | AP6: =[2]หน้าผ้า!DP15 -> 0 | AQ6: =[2]หน้าผ้า!DW15 -> 0 | AR6: =[2]หน้าผ้า!DX15 -> 0 | AS6: =[2]หน้าผ้า!DY15 -> 0 | AT6: =[2]หน้าผ้า!DZ15 -> 0 | AU6: =[2]หน้าผ้า!EA15 -> 0 | AV6: =[2]หน้าผ้า!EB15 -> 0 | AW6: =[2]หน้าผ้า!EC15 -> 0 | AX6: =[2]หน้าผ้า!ED15 -> 0 | AY6: =[2]หน้าผ้า!AG15 -> 0 | AZ6: =[2]หน้าผ้า!EG15 -> 0 | BA6: =[2]หน้าผ้า!EH15 -> 0 | BB6: =[2]หน้าผ้า!EI15 -> 0 | BC6: =[2]หน้าผ้า!BZ15 -> WRWT120750/WRWT21750 | BD6: =[2]หน้าผ้า!CA15 -> 0
A7: =[2]หน้าผ้า!C16 -> 45800 | B7: =[2]หน้าผ้า!B16 -> MK68-000701 | C7: =[2]หน้าผ้า!E16 -> หจก.ปึงเป้งน้ำ | D7: =[2]หน้าผ้า!F16 -> เกลือตรามือ 10กก | E7: =[2]หน้าผ้า!G16 -> 14 | F7: =[2]หน้าผ้า!H16 -> 22 | G7: =[2]หน้าผ้า!I16 -> ขาว | H7: =[2]หน้าผ้า!J16 -> ใส | I7: =[2]หน้าผ้า!L16 -> 42 | J7: =[2]หน้าผ้า!M16 -> ± | K7: =[2]หน้าผ้า!N16 -> 5 | L7: =[2]หน้าผ้า!R16 -> ไม่ | M7: =[2]หน้าผ้า!T16 -> ไม่สวมถุงใน | N7: =[2]หน้าผ้า!U16 -> 0 | O7: =[2]หน้าผ้า!V16 -> 0 | P7: =[2]หน้าผ้า!AB16 -> 0 | Q7: =[2]หน้าผ้า!AC16 -> 0 | R7: =[2]หน้าผ้า!AD16 -> 0 | S7: =[2]หน้าผ้า!Z16 -> 500กระสอบแบนเต็มใบ | T7: =[2]หน้าผ้า!X16 -> 45821 | U7: =[2]หน้าผ้า!AA16 -> 10000 | V7: =[2]หน้าผ้า!AJ16 -> 0 | W7: =[2]หน้าผ้า!AL16 -> 10000 | X7: =[2]หน้าผ้า!AM16 -> 0 | Y7: =[2]หน้าผ้า!AN16 -> 10500 | Z7: =[2]หน้าผ้า!AO16 -> WSWT1425800 | AA7: =[2]หน้าผ้า!AQ16 -> 6565.9 | AB7: =[2]หน้าผ้า!AR16 -> 1220 | AC7: =[2]หน้าผ้า!AS16 -> 5345.9 | AD7: =[2]หน้าผ้า!AT16 -> 1220 | AE7: =[2]หน้าผ้า!AU16 -> 5345.9 | AF7: =[2]หน้าผ้า!AI16 -> 0 | AG7: =[3]หน้าผ้า!DC19 -> พร้อมส่ง | AH7: =[2]หน้าผ้า!DL16 -> P6 | AI7: =[2]หน้าผ้า!DM16 -> 4 | AJ7: =[2]หน้าผ้า!DN16 -> 45821 | AK7: =[2]หน้าผ้า!DQ16 -> 45817 | AL7: =[2]หน้าผ้า!DR16 -> 45810 | AM7: =[2]หน้าผ้า!DS16 -> 45818 | AN7: =[2]หน้าผ้า!DT16 -> 45819 | AO7: =[2]หน้าผ้า!DU16 -> 45820 | AP7: =[2]หน้าผ้า!DP16 -> 45816 | AQ7: =[2]หน้าผ้า!DW16 -> 0 | AR7: =[2]หน้าผ้า!DX16 -> 0 | AS7: =[2]หน้าผ้า!DY16 -> 0 | AT7: =[2]หน้าผ้า!DZ16 -> 0 | AU7: =[2]หน้าผ้า!EA16 -> 0 | AV7: =[2]หน้าผ้า!EB16 -> 0 | AW7: =[2]หน้าผ้า!EC16 -> งานเคลือบ+พิมพ์ | AX7: =[2]หน้าผ้า!ED16 -> / | AY7: =[2]หน้าผ้า!AG16 -> 0 | AZ7: =[2]หน้าผ้า!EG16 -> 0 | BA7: =[2]หน้าผ้า!EH16 -> 0 | BB7: =[2]หน้าผ้า!EI16 -> 0 | BC7: =[2]หน้าผ้า!BZ16 -> WRWT25800/WRWT25800 | BD7: =[2]หน้าผ้า!CA16 -> 299.3704
A8: =[2]หน้าผ้า!C17 -> 0 | B8: =[2]หน้าผ้า!B17 -> 0 | C8: =[2]หน้าผ้า!E17 -> 0 | D8: =[2]หน้าผ้า!F17 -> 0 | E8: =[2]หน้าผ้า!G17 -> 14 | F8: =[2]หน้าผ้า!H17 -> 22 | G8: =[2]หน้าผ้า!I17 -> ขาว | H8: =[2]หน้าผ้า!J17 -> 0 | I8: =[2]หน้าผ้า!L17 -> 36 | J8: =[2]หน้าผ้า!M17 -> ± | K8: =[2]หน้าผ้า!N17 -> 5 | L8: =[2]หน้าผ้า!R17 -> 0 | M8: =[2]หน้าผ้า!T17 -> 0 | N8: =[2]หน้าผ้า!U17 -> 0 | O8: =[2]หน้าผ้า!V17 -> 0 | P8: =[2]หน้าผ้า!AB17 -> 0 | Q8: =[2]หน้าผ้า!AC17 -> 0 | R8: =[2]หน้าผ้า!AD17 -> 0 | S8: =[2]หน้าผ้า!Z17 -> 0 | T8: =[2]หน้าผ้า!X17 -> 0 | U8: =[2]หน้าผ้า!AA17 -> 0 | V8: =[2]หน้าผ้า!AJ17 -> 0 | W8: =[2]หน้าผ้า!AL17 -> 0 | X8: =[2]หน้าผ้า!AM17 -> 0 | Y8: =[2]หน้าผ้า!AN17 -> 0 | Z8: =[2]หน้าผ้า!AO17 -> WSWT1425800 | AA8: =[2]หน้าผ้า!AQ17 -> 6565.9 | AB8: =[2]หน้าผ้า!AR17 -> 1220 | AC8: =[2]หน้าผ้า!AS17 -> 5345.9 | AD8: =[2]หน้าผ้า!AT17 -> 1220 | AE8: =[2]หน้าผ้า!AU17 -> 5345.9 | AF8: =[2]หน้าผ้า!AI17 -> ระบุในSD | AG8: =[3]หน้าผ้า!DC20 -> พร้อมส่ง | AH8: =[2]หน้าผ้า!DL17 -> 0 | AI8: =[2]หน้าผ้า!DM17 -> Lead time | AJ8: =[2]หน้าผ้า!DN17 -> 0 | AK8: =[2]หน้าผ้า!DQ17 -> 0 | AL8: =[2]หน้าผ้า!DR17 -> 0 | AM8: =[2]หน้าผ้า!DS17 -> 0 | AN8: =[2]หน้าผ้า!DT17 -> 0 | AO8: =[2]หน้าผ้า!DU17 -> 0 | AP8: =[2]หน้าผ้า!DP17 -> 0 | AQ8: =[2]หน้าผ้า!DW17 -> 0 | AR8: =[2]หน้าผ้า!DX17 -> 0 | AS8: =[2]หน้าผ้า!DY17 -> 0 | AT8: =[2]หน้าผ้า!DZ17 -> 0 | AU8: =[2]หน้าผ้า!EA17 -> 0 | AV8: =[2]หน้าผ้า!EB17 -> 0 | AW8: =[2]หน้าผ้า!EC17 -> 0 | AX8: =[2]หน้าผ้า!ED17 -> 0 | AY8: =[2]หน้าผ้า!AG17 -> 0 | AZ8: =[2]หน้าผ้า!EG17 -> 0 | BA8: =[2]หน้าผ้า!EH17 -> 0 | BB8: =[2]หน้าผ้า!EI17 -> 0 | BC8: =[2]หน้าผ้า!BZ17 -> WRWT140800/WRWT25800 | BD8: =[2]หน้าผ้า!CA17 -> 0
A9: =[2]หน้าผ้า!C18 -> ประมาณการ | B9: =[2]หน้าผ้า!B18 -> ประมาณการ | C9: =[2]หน้าผ้า!E18 -> บจก.ซัน ซีเมนต์ โพรเซส | D9: =[2]หน้าผ้า!F18 -> พระอาทิตย์(ปูนนอน-ชริงค์) | E9: =[2]หน้าผ้า!G18 -> 16 | F9: =[2]หน้าผ้า!H18 -> 25 | G9: =[2]หน้าผ้า!I18 -> ขาว | H9: =[2]หน้าผ้า!J18 -> ใส | I9: =[2]หน้าผ้า!L18 -> 50 | J9: =[2]หน้าผ้า!M18 -> ± | K9: =[2]หน้าผ้า!N18 -> 5 | L9: =[2]หน้าผ้า!R18 -> บิด | M9: =[2]หน้าผ้า!T18 -> 19 | N9: =[2]หน้าผ้า!U18 -> 28 | O9: =[2]หน้าผ้า!V18 -> 40 | P9: =[2]หน้าผ้า!AB18 -> 65.624643 | Q9: =[2]หน้าผ้า!AC18 -> 0 | R9: =[2]หน้าผ้า!AD18 -> 65.624643 | S9: =[2]หน้าผ้า!Z18 -> 500กระสอบ | T9: =[2]หน้าผ้า!X18 -> รอแจ้ง | U9: =[2]หน้าผ้า!AA18 -> 5000 | V9: =[2]หน้าผ้า!AJ18 -> 0 | W9: =[2]หน้าผ้า!AL18 -> 5000 | X9: =[2]หน้าผ้า!AM18 -> 0 | Y9: =[2]หน้าผ้า!AN18 -> 5250 | Z9: =[2]หน้าผ้า!AO18 -> WSWT1625800SM | AA9: =[2]หน้าผ้า!AQ18 -> 3702.05 | AB9: =[2]หน้าผ้า!AR18 -> 3372 | AC9: =[2]หน้าผ้า!AS18 -> 330.05 | AD9: =[2]หน้าผ้า!AT18 -> 0 | AE9: =[2]หน้าผ้า!AU18 -> 3702.05 | AF9: =[2]หน้าผ้า!AI18 -> 0 | AG9: =[3]หน้าผ้า!DC21 -> พร้อมส่ง | AH9: =[2]หน้าผ้า!DL18 -> P8 | AI9: =[2]หน้าผ้า!DM18 -> 4 | AJ9: =[2]หน้าผ้า!DN18 -> รอแจ้ง | AK9: =[2]หน้าผ้า!DQ18 -> #VALUE! | AL9: =[2]หน้าผ้า!DR18 -> #VALUE! | AM9: =[2]หน้าผ้า!DS18 -> #VALUE! | AN9: =[2]หน้าผ้า!DT18 -> #VALUE! | AO9: =[2]หน้าผ้า!DU18 -> #VALUE! | AP9: =[2]หน้าผ้า!DP18 -> #VALUE! | AQ9: =[2]หน้าผ้า!DW18 -> #VALUE! | AR9: =[2]หน้าผ้า!DX18 -> 0 | AS9: =[2]หน้าผ้า!DY18 -> 0 | AT9: =[2]หน้าผ้า!DZ18 -> 0 | AU9: =[2]หน้าผ้า!EA18 -> 0 | AV9: =[2]หน้าผ้า!EB18 -> 0 | AW9: =[2]หน้าผ้า!EC18 -> งานเคลือบ+พิมพ์ | AX9: =[2]หน้าผ้า!ED18 -> รอART | AY9: =[2]หน้าผ้า!AG18 -> 0 | AZ9: =[2]หน้าผ้า!EG18 -> 0 | BA9: =[2]หน้าผ้า!EH18 -> 0 | BB9: =[2]หน้าผ้า!EI18 -> 0 | BC9: =[2]หน้าผ้า!BZ18 -> WRWT25800/WRWT25800 | BD9: =[2]หน้าผ้า!CA18 -> 18.776178
A10: =[2]หน้าผ้า!C19 -> 0 | B10: =[2]หน้าผ้า!B19 -> 0 | C10: =[2]หน้าผ้า!E19 -> 0 | D10: =[2]หน้าผ้า!F19 | E10: =[2]หน้าผ้า!G19 -> 16 | F10: =[2]หน้าผ้า!H19 -> 25 | G10: =[2]หน้าผ้า!I19 -> ขาว | H10: =[2]หน้าผ้า!J19 -> 0 | I10: =[2]หน้าผ้า!L19 -> 45 | J10: =[2]หน้าผ้า!M19 -> ± | K10: =[2]หน้าผ้า!N19 -> 5 | L10: =[2]หน้าผ้า!R19 -> 0 | M10: =[2]หน้าผ้า!T19 -> 0 | N10: =[2]หน้าผ้า!U19 -> 0 | O10: =[2]หน้าผ้า!V19 -> 0 | P10: =[2]หน้าผ้า!AB19 -> 0 | Q10: =[2]หน้าผ้า!AC19 -> 0 | R10: =[2]หน้าผ้า!AD19 -> 0 | S10: =[2]หน้าผ้า!Z19 -> 0 | T10: =[2]หน้าผ้า!X19 -> 0 | U10: =[2]หน้าผ้า!AA19 -> 0 | V10: =[2]หน้าผ้า!AJ19 -> 0 | W10: =[2]หน้าผ้า!AL19 -> 0 | X10: =[2]หน้าผ้า!AM19 -> 0 | Y10: =[2]หน้าผ้า!AN19 -> 0 | Z10: =[2]หน้าผ้า!AO19 -> WSWT1625800SM | AA10: =[2]หน้าผ้า!AQ19 -> 3702.05 | AB10: =[2]หน้าผ้า!AR19 -> 3372 | AC10: =[2]หน้าผ้า!AS19 -> 330.05 | AD10: =[2]หน้าผ้า!AT19 -> 0 | AE10: =[2]หน้าผ้า!AU19 -> 3702.05 | AF10: =[2]หน้าผ้า!AI19 -> ระบุในSD | AG10: =[3]หน้าผ้า!DC22 -> พิมพ์ไม่ครบ | AH10: =[2]หน้าผ้า!DL19 -> 0 | AI10: =[2]หน้าผ้า!DM19 -> Lead time | AJ10: =[2]หน้าผ้า!DN19 -> 0 | AK10: =[2]หน้าผ้า!DQ19 -> 0 | AL10: =[2]หน้าผ้า!DR19 -> 0 | AM10: =[2]หน้าผ้า!DS19 -> 0 | AN10: =[2]หน้าผ้า!DT19 -> 0 | AO10: =[2]หน้าผ้า!DU19 -> 0 | AP10: =[2]หน้าผ้า!DP19 -> 0 | AQ10: =[2]หน้าผ้า!DW19 -> 0 | AR10: =[2]หน้าผ้า!DX19 -> 0 | AS10: =[2]หน้าผ้า!DY19 -> 0 | AT10: =[2]หน้าผ้า!DZ19 -> 0 | AU10: =[2]หน้าผ้า!EA19 -> 0 | AV10: =[2]หน้าผ้า!EB19 -> 0 | AW10: =[2]หน้าผ้า!EC19 -> 0 | AX10: =[2]หน้าผ้า!ED19 -> 0 | AY10: =[2]หน้าผ้า!AG19 -> 0 | AZ10: =[2]หน้าผ้า!EG19 -> 0 | BA10: =[2]หน้าผ้า!EH19 -> 0 | BB10: =[2]หน้าผ้า!EI19 -> 0 | BC10: =[2]หน้าผ้า!BZ19 -> WRWT160800/WRWT25800 | BD10: =[2]หน้าผ้า!CA19 -> 0
A11: =[2]หน้าผ้า!C20 -> 0 | B11: =[2]หน้าผ้า!B20 -> 0 | C11: =[2]หน้าผ้า!E20 -> 0 | D11: =[2]หน้าผ้า!F20 -> 0 | E11: =[2]หน้าผ้า!G20 -> 16 | F11: =[2]หน้าผ้า!H20 -> 25 | G11: =[2]หน้าผ้า!I20 -> ขาว | H11: =[2]หน้าผ้า!J20 -> 0 | I11: =[2]หน้าผ้า!L20 -> 45 | J11: =[2]หน้าผ้า!M20 -> ± | K11: =[2]หน้าผ้า!N20 -> 5 | L11: =[2]หน้าผ้า!R20 -> 0 | M11: =[2]หน้าผ้า!T20 -> 0 | N11: =[2]หน้าผ้า!U20 -> 0 | O11: =[2]หน้าผ้า!V20 -> 0 | P11: =[2]หน้าผ้า!AB20 -> 0 | Q11: =[2]หน้าผ้า!AC20 -> 0 | R11: =[2]หน้าผ้า!AD20 -> 0 | S11: =[2]หน้าผ้า!Z20 -> 0 | T11: =[2]หน้าผ้า!X20 -> 0 | U11: =[2]หน้าผ้า!AA20 -> 0 | V11: =[2]หน้าผ้า!AJ20 -> 0 | W11: =[2]หน้าผ้า!AL20 -> 0 | X11: =[2]หน้าผ้า!AM20 -> 0 | Y11: =[2]หน้าผ้า!AN20 -> 0 | Z11: =[2]หน้าผ้า!AO20 -> WSWT1625800 | AA11: =[2]หน้าผ้า!AQ20 -> #REF! | AB11: =[2]หน้าผ้า!AR20 -> #REF! | AC11: =[2]หน้าผ้า!AS20 -> #REF! | AD11: =[2]หน้าผ้า!AT20 -> #REF! | AE11: =[2]หน้าผ้า!AU20 -> #REF! | AF11: =[2]หน้าผ้า!AI20 -> ระบุในSD | AG11: =[3]หน้าผ้า!DC23 -> พร้อมส่ง | AH11: =[2]หน้าผ้า!DL20 -> 0 | AI11: =[2]หน้าผ้า!DM20 -> Lead time | AJ11: =[2]หน้าผ้า!DN20 -> 0 | AK11: =[2]หน้าผ้า!DQ20 -> 0 | AL11: =[2]หน้าผ้า!DR20 -> 0 | AM11: =[2]หน้าผ้า!DS20 -> 0 | AN11: =[2]หน้าผ้า!DT20 -> 0 | AO11: =[2]หน้าผ้า!DU20 -> 0 | AP11: =[2]หน้าผ้า!DP20 -> 0 | AQ11: =[2]หน้าผ้า!DW20 -> 0 | AR11: =[2]หน้าผ้า!DX20 -> 0 | AS11: =[2]หน้าผ้า!DY20 -> 0 | AT11: =[2]หน้าผ้า!DZ20 -> 0 | AU11: =[2]หน้าผ้า!EA20 -> 0 | AV11: =[2]หน้าผ้า!EB20 -> 0 | AW11: =[2]หน้าผ้า!EC20 -> 0 | AX11: =[2]หน้าผ้า!ED20 -> 0 | AY11: =[2]หน้าผ้า!AG20 -> 0 | AZ11: =[2]หน้าผ้า!EG20 -> 0 | BA11: =[2]หน้าผ้า!EH20 -> 0 | BB11: =[2]หน้าผ้า!EI20 -> 0 | BC11: =[2]หน้าผ้า!BZ20 -> WRWT160800/WRWT25800 | BD11: =[2]หน้าผ้า!CA20 -> 0
A12: =[2]หน้าผ้า!C21 -> 0 | B12: =[2]หน้าผ้า!B21 -> 0 | C12: =[2]หน้าผ้า!E21 -> 0 | D12: =[2]หน้าผ้า!F21 -> 0 | E12: =[2]หน้าผ้า!G21 -> 16 | F12: =[2]หน้าผ้า!H21 -> 25 | G12: =[2]หน้าผ้า!I21 -> 0 | H12: =[2]หน้าผ้า!J21 -> 0 | I12: =[2]หน้าผ้า!L21 -> 47 | J12: =[2]หน้าผ้า!M21 -> ± | K12: =[2]หน้าผ้า!N21 -> 5 | L12: =[2]หน้าผ้า!R21 -> 0 | M12: =[2]หน้าผ้า!T21 -> 0 | N12: =[2]หน้าผ้า!U21 -> 0 | O12: =[2]หน้าผ้า!V21 -> 0 | P12: =[2]หน้าผ้า!AB21 -> 0 | Q12: =[2]หน้าผ้า!AC21 -> 0 | R12: =[2]หน้าผ้า!AD21 -> 0 | S12: =[2]หน้าผ้า!Z21 -> 0 | T12: =[2]หน้าผ้า!X21 -> 0 | U12: =[2]หน้าผ้า!AA21 -> 0 | V12: =[2]หน้าผ้า!AJ21 -> 0 | W12: =[2]หน้าผ้า!AL21 -> 0 | X12: =[2]หน้าผ้า!AM21 -> 0 | Y12: =[2]หน้าผ้า!AN21 -> 0 | Z12: =[2]หน้าผ้า!AO21 -> WSWT1621720SMFX | AA12: =[2]หน้าผ้า!AQ21 -> #REF! | AB12: =[2]หน้าผ้า!AR21 -> #REF! | AC12: =[2]หน้าผ้า!AS21 -> #REF! | AD12: =[2]หน้าผ้า!AT21 -> #REF! | AE12: =[2]หน้าผ้า!AU21 -> #REF! | AF12: =[2]หน้าผ้า!AI21 -> ระบุในSD | AG12: =[3]หน้าผ้า!DC24 -> ยังไม่ได้พิมพ์ | AH12: =[2]หน้าผ้า!DL21 -> 0 | AI12: =[2]หน้าผ้า!DM21 -> 0 | AJ12: =[2]หน้าผ้า!DN21 -> 0 | AK12: =[2]หน้าผ้า!DQ21 -> 0 | AL12: =[2]หน้าผ้า!DR21 -> 0 | AM12: =[2]หน้าผ้า!DS21 -> 0 | AN12: =[2]หน้าผ้า!DT21 -> 0 | AO12: =[2]หน้าผ้า!DU21 -> 0 | AP12: =[2]หน้าผ้า!DP21 -> 0 | AQ12: =[2]หน้าผ้า!DW21 -> 0 | AR12: =[2]หน้าผ้า!DX21 -> 0 | AS12: =[2]หน้าผ้า!DY21 -> 0 | AT12: =[2]หน้าผ้า!DZ21 -> 0 | AU12: =[2]หน้าผ้า!EA21 -> 0 | AV12: =[2]หน้าผ้า!EB21 -> 0 | AW12: =[2]หน้าผ้า!EC21 -> 0 | AX12: =[2]หน้าผ้า!ED21 -> 0 | AY12: =[2]หน้าผ้า!AG21 -> 0 | AZ12: =[2]หน้าผ้า!EG21 -> 0 | BA12: =[2]หน้าผ้า!EH21 -> 0 | BB12: =[2]หน้าผ้า!EI21 -> 0 | BC12: =[2]หน้าผ้า!BZ21 -> WRWT160720/WRWT21720 | BD12: =[2]หน้าผ้า!CA21 -> 0
A13: =[2]หน้าผ้า!C22 -> 45805 | B13: =[2]หน้าผ้า!B22 -> MK68-000717 | C13: =[2]หน้าผ้า!E22 -> บจก.โรงสีข้าวธัญญาวัฒน์ | D13: =[2]หน้าผ้า!F22 -> LUNG SHIN 12Kg. | E13: =[2]หน้าผ้า!G22 -> 17 | F13: =[2]หน้าผ้า!H22 -> 26 | G13: =[2]หน้าผ้า!I22 -> ขาว | H13: =[2]หน้าผ้า!J22 -> 0 | I13: =[2]หน้าผ้า!L22 -> 48 | J13: =[2]หน้าผ้า!M22 -> ± | K13: =[2]หน้าผ้า!N22 -> 5 | L13: =[2]หน้าผ้า!R22 -> ไม่ | M13: =[2]หน้าผ้า!T22 -> ไม่สวมถุงใน | N13: =[2]หน้าผ้า!U22 -> 0 | O13: =[2]หน้าผ้า!V22 -> 0 | P13: =[2]หน้าผ้า!AB22 -> 0 | Q13: =[2]หน้าผ้า!AC22 -> 0 | R13: =[2]หน้าผ้า!AD22 -> 0 | S13: =[2]หน้าผ้า!Z22 -> 500กระสอบแบน | T13: =[2]หน้าผ้า!X22 -> 45813 | U13: =[2]หน้าผ้า!AA22 -> 10200 | V13: =[2]หน้าผ้า!AJ22 -> 0 | W13: =[2]หน้าผ้า!AL22 -> 10200 | X13: =[2]หน้าผ้า!AM22 -> 9000 | Y13: =[2]หน้าผ้า!AN22 -> 1260 | Z13: =[2]หน้าผ้า!AO22 -> WSWT1725800 | AA13: =[2]หน้าผ้า!AQ22 -> 968.121 | AB13: =[2]หน้าผ้า!AR22 -> 968.121 | AC13: =[2]หน้าผ้า!AS22 -> 0 | AD13: =[2]หน้าผ้า!AT22 -> 0 | AE13: =[2]หน้าผ้า!AU22 -> 0 | AF13: =[2]หน้าผ้า!AI22 -> 0 | AG13: =[3]หน้าผ้า!DC25 -> พร้อมส่ง | AH13: =[2]หน้าผ้า!DL22 -> P7 | AI13: =[2]หน้าผ้า!DM22 -> 2 | AJ13: =[2]หน้าผ้า!DN22 -> 45813 | AK13: =[2]หน้าผ้า!DQ22 -> 0 | AL13: =[2]หน้าผ้า!DR22 -> 45804 | AM13: =[2]หน้าผ้า!DS22 -> 45811 | AN13: =[2]หน้าผ้า!DT22 -> 45812 | AO13: =[2]หน้าผ้า!DU22 -> 45812 | AP13: =[2]หน้าผ้า!DP22 -> 45808 | AQ13: =[2]หน้าผ้า!DW22 -> 0 | AR13: =[2]หน้าผ้า!DX22 -> 0 | AS13: =[2]หน้าผ้า!DY22 -> 0 | AT13: =[2]หน้าผ้า!DZ22 -> 0 | AU13: =[2]หน้าผ้า!EA22 -> 0 | AV13: =[2]หน้าผ้า!EB22 -> 0 | AW13: =[2]หน้าผ้า!EC22 -> งานพิมพ์ | AX13: =[2]หน้าผ้า!ED22 -> รอART | AY13: =[2]หน้าผ้า!AG22 -> 0 | AZ13: =[2]หน้าผ้า!EG22 -> 0 | BA13: =[2]หน้าผ้า!EH22 -> 0 | BB13: =[2]หน้าผ้า!EI22 -> 0 | BC13: =[2]หน้าผ้า!BZ22 -> WRWT25800/WRWT25800 | BD13: =[2]หน้าผ้า!CA22 -> 0
A14: =[2]หน้าผ้า!C23 -> 0 | B14: =[2]หน้าผ้า!B23 -> 0 | C14: =[2]หน้าผ้า!E23 -> 0 | D14: =[2]หน้าผ้า!F23 -> 0 | E14: =[2]หน้าผ้า!G23 -> 17 | F14: =[2]หน้าผ้า!H23 -> 26 | G14: =[2]หน้าผ้า!I23 -> 0 | H14: =[2]หน้าผ้า!J23 -> 0 | I14: =[2]หน้าผ้า!L23 -> 48 | J14: =[2]หน้าผ้า!M23 -> ± | K14: =[2]หน้าผ้า!N23 -> 5 | L14: =[2]หน้าผ้า!R23 -> 0 | M14: =[2]หน้าผ้า!T23 -> 0 | N14: =[2]หน้าผ้า!U23 -> 0 | O14: =[2]หน้าผ้า!V23 -> 0 | P14: =[2]หน้าผ้า!AB23 -> 0 | Q14: =[2]หน้าผ้า!AC23 -> 0 | R14: =[2]หน้าผ้า!AD23 -> 0 | S14: =[2]หน้าผ้า!Z23 -> 0 | T14: =[2]หน้าผ้า!X23 -> 0 | U14: =[2]หน้าผ้า!AA23 -> 0 | V14: =[2]หน้าผ้า!AJ23 -> 0 | W14: =[2]หน้าผ้า!AL23 -> 0 | X14: =[2]หน้าผ้า!AM23 -> 0 | Y14: =[2]หน้าผ้า!AN23 -> 0 | Z14: =[2]หน้าผ้า!AO23 -> WSWT1725800 | AA14: =[2]หน้าผ้า!AQ23 -> 968.121 | AB14: =[2]หน้าผ้า!AR23 -> 968.121 | AC14: =[2]หน้าผ้า!AS23 -> 0 | AD14: =[2]หน้าผ้า!AT23 -> 0 | AE14: =[2]หน้าผ้า!AU23 -> 0 | AF14: =[2]หน้าผ้า!AI23 -> ระบุในSD | AG14: =[3]หน้าผ้า!DC26 -> ยังไม่ได้พิมพ์ | AH14: =[2]หน้าผ้า!DL23 -> 0 | AI14: =[2]หน้าผ้า!DM23 -> 0 | AJ14: =[2]หน้าผ้า!DN23 -> 0 | AK14: =[2]หน้าผ้า!DQ23 -> 0 | AL14: =[2]หน้าผ้า!DR23 -> 0 | AM14: =[2]หน้าผ้า!DS23 -> 0 | AN14: =[2]หน้าผ้า!DT23 -> 0 | AO14: =[2]หน้าผ้า!DU23 -> 0 | AP14: =[2]หน้าผ้า!DP23 -> 0 | AQ14: =[2]หน้าผ้า!DW23 -> 0 | AR14: =[2]หน้าผ้า!DX23 -> 0 | AS14: =[2]หน้าผ้า!DY23 -> 0 | AT14: =[2]หน้าผ้า!DZ23 -> 0 | AU14: =[2]หน้าผ้า!EA23 -> 0 | AV14: =[2]หน้าผ้า!EB23 -> 0 | AW14: =[2]หน้าผ้า!EC23 -> 0 | AX14: =[2]หน้าผ้า!ED23 -> 0 | AY14: =[2]หน้าผ้า!AG23 -> 0 | AZ14: =[2]หน้าผ้า!EG23 -> 0 | BA14: =[2]หน้าผ้า!EH23 -> 0 | BB14: =[2]หน้าผ้า!EI23 -> 0 | BC14: =[2]หน้าผ้า!BZ23 -> WRWT170800/WRWT25800 | BD14: =[2]หน้าผ้า!CA23 -> 0
A15: =[2]หน้าผ้า!C24 -> ประมาณการ | B15: =[2]หน้าผ้า!B24 -> ประมาณการ | C15: =[2]หน้าผ้า!E24 -> บจก.ฟาร์เธอร์ส วิง ซัพพลาย | D15: =[2]หน้าผ้า!F24 -> รถไฟ | E15: =[2]หน้าผ้า!G24 -> 18 | F15: =[2]หน้าผ้า!H24 -> 30 | G15: =[2]หน้าผ้า!I24 -> ขาว | H15: =[2]หน้าผ้า!J24 -> 0 | I15: =[2]หน้าผ้า!L24 -> 54 | J15: =[2]หน้าผ้า!M24 -> ± | K15: =[2]หน้าผ้า!N24 -> 5 | L15: =[2]หน้าผ้า!R24 -> บิด | M15: =[2]หน้าผ้า!T24 -> 19 | N15: =[2]หน้าผ้า!U24 -> 33 | O15: =[2]หน้าผ้า!V24 -> 40 | P15: =[2]หน้าผ้า!AB24 -> 232.02999 | Q15: =[2]หน้าผ้า!AC24 -> 0 | R15: =[2]หน้าผ้า!AD24 -> 232.02999 | S15: =[2]หน้าผ้า!Z24 -> 500กระสอบ | T15: =[2]หน้าผ้า!X24 -> 45838 | U15: =[2]หน้าผ้า!AA24 -> 15000 | V15: =[2]หน้าผ้า!AJ24 -> 0 | W15: =[2]หน้าผ้า!AL24 -> 15000 | X15: =[2]หน้าผ้า!AM24 -> 0 | Y15: =[2]หน้าผ้า!AN24 -> 15750 | Z15: =[2]หน้าผ้า!AO24 -> WSWT1825800 | AA15: =[2]หน้าผ้า!AQ24 -> 13201.65 | AB15: =[2]หน้าผ้า!AR24 -> 6301 | AC15: =[2]หน้าผ้า!AS24 -> 6900.65 | AD15: =[2]หน้าผ้า!AT24 -> 0 | AE15: =[2]หน้าผ้า!AU24 -> 0 | AF15: =[2]หน้าผ้า!AI24 -> 0 | AG15: =[3]หน้าผ้า!DC27 -> ยังไม่ได้พิมพ์ | AH15: =[2]หน้าผ้า!DL24 -> P9 | AI15: =[2]หน้าผ้า!DM24 -> 3 | AJ15: =[2]หน้าผ้า!DN24 -> 45838 | AK15: =[2]หน้าผ้า!DQ24 -> 0 | AL15: =[2]หน้าผ้า!DR24 -> 45828 | AM15: =[2]หน้าผ้า!DS24 -> 45835 | AN15: =[2]หน้าผ้า!DT24 -> 45836 | AO15: =[2]หน้าผ้า!DU24 -> 45836 | AP15: =[2]หน้าผ้า!DP24 -> 45833 | AQ15: =[2]หน้าผ้า!DW24 -> 45837 | AR15: =[2]หน้าผ้า!DX24 -> 0 | AS15: =[2]หน้าผ้า!DY24 -> 0 | AT15: =[2]หน้าผ้า!DZ24 -> 0 | AU15: =[2]หน้าผ้า!EA24 -> 0 | AV15: =[2]หน้าผ้า!EB24 -> 0 | AW15: =[2]หน้าผ้า!EC24 -> งานพิมพ์ | AX15: =[2]หน้าผ้า!ED24 -> รอART | AY15: =[2]หน้าผ้า!AG24 -> 0 | AZ15: =[2]หน้าผ้า!EG24 -> 0 | BA15: =[2]หน้าผ้า!EH24 -> 0 | BB15: =[2]หน้าผ้า!EI24 -> 0 | BC15: =[2]หน้าผ้า!BZ24 -> WRWT25800/WRWT25800 | BD15: =[2]หน้าผ้า!CA24 -> 474.76472
A16: =[2]หน้าผ้า!C25 -> 0 | B16: =[2]หน้าผ้า!B25 -> 0 | C16: =[2]หน้าผ้า!E25 | D16: =[2]หน้าผ้า!F25 | E16: =[2]หน้าผ้า!G25 -> 18 | F16: =[2]หน้าผ้า!H25 -> 30 | G16: =[2]หน้าผ้า!I25 -> ขาว | H16: =[2]หน้าผ้า!J25 -> 0 | I16: =[2]หน้าผ้า!L25 -> 54 | J16: =[2]หน้าผ้า!M25 -> ± | K16: =[2]หน้าผ้า!N25 -> 5 | L16: =[2]หน้าผ้า!R25 -> 0 | M16: =[2]หน้าผ้า!T25 -> 0 | N16: =[2]หน้าผ้า!U25 -> 0 | O16: =[2]หน้าผ้า!V25 -> 0 | P16: =[2]หน้าผ้า!AB25 -> 0 | Q16: =[2]หน้าผ้า!AC25 -> 0 | R16: =[2]หน้าผ้า!AD25 -> 0 | S16: =[2]หน้าผ้า!Z25 -> 0 | T16: =[2]หน้าผ้า!X25 -> 0 | U16: =[2]หน้าผ้า!AA25 -> 0 | V16: =[2]หน้าผ้า!AJ25 -> 0 | W16: =[2]หน้าผ้า!AL25 -> 0 | X16: =[2]หน้าผ้า!AM25 -> 0 | Y16: =[2]หน้าผ้า!AN25 -> 0 | Z16: =[2]หน้าผ้า!AO25 -> WSWT1825800 | AA16: =[2]หน้าผ้า!AQ25 -> 13201.65 | AB16: =[2]หน้าผ้า!AR25 -> 6301 | AC16: =[2]หน้าผ้า!AS25 -> 6900.65 | AD16: =[2]หน้าผ้า!AT25 -> 0 | AE16: =[2]หน้าผ้า!AU25 -> 0 | AF16: =[2]หน้าผ้า!AI25 -> ระบุในSD | AG16: =[3]หน้าผ้า!DC28 -> ยังไม่ได้พิมพ์ | AH16: =[2]หน้าผ้า!DL25 -> 0 | AI16: =[2]หน้าผ้า!DM25 -> Lead time | AJ16: =[2]หน้าผ้า!DN25 -> 0 | AK16: =[2]หน้าผ้า!DQ25 -> 0 | AL16: =[2]หน้าผ้า!DR25 -> 0 | AM16: =[2]หน้าผ้า!DS25 -> 0 | AN16: =[2]หน้าผ้า!DT25 -> 0 | AO16: =[2]หน้าผ้า!DU25 -> 0 | AP16: =[2]หน้าผ้า!DP25 -> 0 | AQ16: =[2]หน้าผ้า!DW25 -> 0 | AR16: =[2]หน้าผ้า!DX25 -> 0 | AS16: =[2]หน้าผ้า!DY25 -> 0 | AT16: =[2]หน้าผ้า!DZ25 -> 0 | AU16: =[2]หน้าผ้า!EA25 -> 0 | AV16: =[2]หน้าผ้า!EB25 -> 0 | AW16: =[2]หน้าผ้า!EC25 -> 0 | AX16: =[2]หน้าผ้า!ED25 -> 0 | AY16: =[2]หน้าผ้า!AG25 -> 0 | AZ16: =[2]หน้าผ้า!EG25 -> 0 | BA16: =[2]หน้าผ้า!EH25 -> 0 | BB16: =[2]หน้าผ้า!EI25 -> 0 | BC16: =[2]หน้าผ้า!BZ25 -> WRWT25800/WRWT25800 | BD16: =[2]หน้าผ้า!CA25 -> 0
A17: =[2]หน้าผ้า!C26 -> 45797 | B17: =[2]หน้าผ้า!B26 -> MK68-000686 | C17: =[2]หน้าผ้า!E26 -> บจก.ซิเบลโก้ | D17: =[2]หน้าผ้า!F26 -> PORTARYTE | E17: =[2]หน้าผ้า!G26 -> 18 | F17: =[2]หน้าผ้า!H26 -> 30 | G17: =[2]หน้าผ้า!I26 -> ขาว | H17: =[2]หน้าผ้า!J26 -> ใส | I17: =[2]หน้าผ้า!L26 -> 74 | J17: =[2]หน้าผ้า!M26 -> ± | K17: =[2]หน้าผ้า!N26 -> 5 | L17: =[2]หน้าผ้า!R26 -> ไม่ | M17: =[2]หน้าผ้า!T26 -> ไม่สวมถุงใน | N17: =[2]หน้าผ้า!U26 -> 0 | O17: =[2]หน้าผ้า!V26 -> 0 | P17: =[2]หน้าผ้า!AB26 -> 0 | Q17: =[2]หน้าผ้า!AC26 -> 0 | R17: =[2]หน้าผ้า!AD26 -> 0 | S17: =[2]หน้าผ้า!Z26 -> 500กระสอบ | T17: =[2]หน้าผ้า!X26 -> 45813 | U17: =[2]หน้าผ้า!AA26 -> 10000 | V17: =[2]หน้าผ้า!AJ26 -> 0 | W17: =[2]หน้าผ้า!AL26 -> 10000 | X17: =[2]หน้าผ้า!AM26 -> 0 | Y17: =[2]หน้าผ้า!AN26 -> 10500 | Z17: =[2]หน้าผ้า!AO26 -> WSWT1825800SM | AA17: =[2]หน้าผ้า!AQ26 -> 8801.1 | AB17: =[2]หน้าผ้า!AR26 -> 8801.1 | AC17: =[2]หน้าผ้า!AS26 -> 0 | AD17: =[2]หน้าผ้า!AT26 -> 0 | AE17: =[2]หน้าผ้า!AU26 -> 8801.1 | AF17: =[2]หน้าผ้า!AI26 -> ห้ามเกิน-ขาดได้5% | AG17: =[3]หน้าผ้า!DC29 -> ยังไม่ได้พิมพ์ | AH17: =[2]หน้าผ้า!DL26 -> P6 | AI17: =[2]หน้าผ้า!DM26 -> 4 | AJ17: =[2]หน้าผ้า!DN26 -> 45813 | AK17: =[2]หน้าผ้า!DQ26 -> 45809 | AL17: =[2]หน้าผ้า!DR26 -> 45802 | AM17: =[2]หน้าผ้า!DS26 -> 45810 | AN17: =[2]หน้าผ้า!DT26 -> 45811 | AO17: =[2]หน้าผ้า!DU26 -> 45812 | AP17: =[2]หน้าผ้า!DP26 -> 45808 | AQ17: =[2]หน้าผ้า!DW26 -> 0 | AR17: =[2]หน้าผ้า!DX26 -> 0 | AS17: =[2]หน้าผ้า!DY26 -> 0 | AT17: =[2]หน้าผ้า!DZ26 -> 0 | AU17: =[2]หน้าผ้า!EA26 -> 0 | AV17: =[2]หน้าผ้า!EB26 -> 0 | AW17: =[2]หน้าผ้า!EC26 -> งานเคลือบ+พิมพ์ | AX17: =[2]หน้าผ้า!ED26 -> / | AY17: =[2]หน้าผ้า!AG26 -> 0 | AZ17: =[2]หน้าผ้า!EG26 -> 0 | BA17: =[2]หน้าผ้า!EH26 -> 0 | BB17: =[2]หน้าผ้า!EI26 -> 0 | BC17: =[2]หน้าผ้า!BZ26 -> WRWT25800/WRWT25800 | BD17: =[2]หน้าผ้า!CA26 -> 0
... A575: =[2]หน้าผ้า!C584 -> 0 | B575: =[2]หน้าผ้า!B584 -> 0 | C575: =[2]หน้าผ้า!E584 -> 0 | D575: =[2]หน้าผ้า!F584 -> 0 | E575: =[2]หน้าผ้า!G584 -> 0 | F575: =[2]หน้าผ้า!H584 -> 0 | G575: =[2]หน้าผ้า!I584 -> 0 | H575: =[2]หน้าผ้า!J584 -> 0 | I575: =[2]หน้าผ้า!L584 -> 0 | J575: =[2]หน้าผ้า!M584 -> 0 | K575: =[2]หน้าผ้า!N584 -> 0 | L575: =[2]หน้าผ้า!R584 -> 0 | M575: =[2]หน้าผ้า!T584 -> 0 | N575: =[2]หน้าผ้า!U584 -> 0 | O575: =[2]หน้าผ้า!V584 -> 0 | P575: =[2]หน้าผ้า!AB584 -> 0 | Q575: =[2]หน้าผ้า!AC584 -> 0 | R575: =[2]หน้าผ้า!AD584 -> 0 | S575: =[2]หน้าผ้า!Z584 -> 0 | T575: =[2]หน้าผ้า!X584 -> 0 | U575: =[2]หน้าผ้า!AA584 -> 0 | V575: =[2]หน้าผ้า!AJ584 -> 0 | W575: =[2]หน้าผ้า!AL584 -> 0 | X575: =[2]หน้าผ้า!AM584 -> 0 | Y575: =[2]หน้าผ้า!AN584 -> 0 | Z575: =[2]หน้าผ้า!AO584 -> 0 | AA575: =[2]หน้าผ้า!AQ584 -> 0 | AB575: =[2]หน้าผ้า!AR584 -> 0 | AC575: =[2]หน้าผ้า!AS584 -> 0 | AD575: =[2]หน้าผ้า!AT584 -> 0 | AE575: =[2]หน้าผ้า!AU584 -> 0 | AF575: =[2]หน้าผ้า!AI584 -> 0 | AG575: =[3]หน้าผ้า!DC587 -> 0 | AH575: =[2]หน้าผ้า!DL584 -> 0 | AI575: =[2]หน้าผ้า!DM584 -> 0 | AJ575: =[2]หน้าผ้า!DN584 -> 0 | AK575: =[2]หน้าผ้า!DQ584 -> 0 | AL575: =[2]หน้าผ้า!DR584 -> 0 | AM575: =[2]หน้าผ้า!DS584 -> 0 | AN575: =[2]หน้าผ้า!DT584 -> 0 | AO575: =[2]หน้าผ้า!DU584 -> 0 | AP575: =[2]หน้าผ้า!DP584 -> 0 | AQ575: =[2]หน้าผ้า!DW584 -> 0 | AR575: =[2]หน้าผ้า!DX584 -> 0 | AS575: =[2]หน้าผ้า!DY584 -> 0 | AT575: =[2]หน้าผ้า!DZ584 -> 0 | AU575: =[2]หน้าผ้า!EA584 -> 0 | AV575: =[2]หน้าผ้า!EB584 -> 0 | AW575: =[2]หน้าผ้า!EC584 -> 0 | AX575: =[2]หน้าผ้า!ED584 -> 0 | AY575: =[2]หน้าผ้า!AG584 -> 0 | AZ575: =[2]หน้าผ้า!EG584 -> 0 | BA575: =[2]หน้าผ้า!EH584 -> 0 | BB575: =[2]หน้าผ้า!EI584 -> 0 | BC575: =[2]หน้าผ้า!BZ584 -> 0 | BD575: =[2]หน้าผ้า!CA584 -> 0

Sheet 4(Order+FC) (-4)
A2: เลขที่ SO | B2: (หลายรายการ)
A3: วันส่ง | B3: รอแจ้ง
A4: ชื่อลูกค้า | B4: (ทั้งหมด)
A6: ประเภท | B6: ผลรวม ของ จำนวนส่ง | C6: ผลรวม ของ ค้างพิมพ์ | D6: ผลรวม ของ ค้างตัด | E6: ผลรวม ของ Stock | F6: ผลรวม ของ ใช้ | G6: ผลรวม ของ ค้างทอ
A7: WSWT1625800SM | B7: 5000 | C7: 5250 | D7: 5000 | E7: 3372 | F7: 3702.05 | G7: 330.05 | H7: =+J7-I7 -> 330.05 | J7: =G7 -> 330.05
A8: WSWT1825800SM | B8: 10000 | C8: 10500 | D8: 10000 | E8: 3198 | F8: 8801.1 | G8: 5603.1 | H8: =+J8-I8 -> 5603.1 | J8: =G8 -> 5603.1
A9: WSWT1921720 | B9: 600000 | C9: 630000 | D9: 600000 | E9: 0 | F9: 528066 | G9: 528066 | H9: =+J9-I9 -> 528066 | J9: =G9 -> 528066
A10: WSWT1925800 | B10: 10000 | C10: 10500 | D10: 10000 | E10: 0 | F10: 9359.9 | G10: 9359.9 | H10: =+J10-I10 -> 9359.9 | J10: =G10 -> 9359.9
A11: WSWT2025700 | B11: 50000 | C11: 0 | D11: 50000 | E11: 9009 | F11: 55181.5 | G11: 46172.5 | H11: =+J11-I11 -> 46172.5 | J11: =G11 -> 46172.5
A12: WSWT2025800 | B12: 110000 | C12: 115500 | D12: 110000 | E12: 0 | F12: 115252.5 | G12: 115252.5 | H12: =+J12-I12 -> 115252.5 | J12: =G12 -> 115252.5
A13: WSWT2025800SM | B13: 69250 | C13: 66150 | D13: 69183 | E13: 0 | F13: 68578.73 | G13: 68578.73 | H13: =+J13-I13 -> 68578.73 | J13: =G13 -> 68578.73
A14: WSWT2121670SM | B14: 71000 | C14: 74550 | D14: 71000 | E14: 0 | F14: 77743.05 | G14: 77743.05 | H14: =+J14-I14 -> 77743.05 | J14: =G14 -> 77743.05
A15: WSWT2321112512551 | B15: 106278 | C15: 111591.9 | D15: 106278 | E15: 0 | F15: 114322.18 | G15: 114322.18 | H15: =+J15-I15 -> 114322.18 | J15: =G15 -> 114322.18
A16: WSWT2625650 | B16: 50000 | C16: 10500 | D16: 50000 | E16: 0 | F16: 60490.1 | G16: 60490.1 | H16: =+J16-I16 -> 60490.1 | J16: =G16 -> 60490.1
A17: WSWT2625800 | B17: 30000 | C17: 0 | D17: 30000 | E17: 6278 | F17: 37299.9 | G17: 31021.9 | H17: 0 | I17: 160000 | J17: =G17 -> 31021.9
A18: WSWT2625850SM | B18: 20000 | C18: 21000 | D18: 20000 | E18: 7700 | F18: 24866.6 | G18: 17166.6 | H18: =+J18-I18 -> 17166.6 | J18: =G18 -> 17166.6
A19: ผลรวมทั้งหมด | B19: 1131528 | C19: 1055541.9 | D19: 1131461 | E19: 29557 | F19: 1103663.6 | G19: 1074106.6 | H19: =+J19-I19 -> 1074106.6 | J19: =G19 -> 1074106.6
H20: =+J20-I20 -> 0 | J20: =G20 -> 0
H21: =+J21-I21 -> 0 | J21: =G21 -> 0
H22: =+J22-I22 -> 0 | J22: =G22 -> 0
H23: =+J23-I23 -> 0 | J23: =G23 -> 0
H24: =+J24-I24 -> 0 | J24: =G24 -> 0
H25: =+J25-I25 -> 0 | J25: =G25 -> 0
H27: =SUM(H8:H25) -> 2116861.3 | J27: =SUM(J8:J25) -> 2147883.2
M28: =+GETPIVOTDATA("ผลรวม ของ ใช้",$A$6)+H29+H31 -> 1193663.6
H30: =+H27 -> 2116861.3
A31: กรม | B31: 70000 | C31: 70000 | D31: 70000 | G31: 90000 | H31: 90000 | I31: 95 | J31: =+H31*I31 -> 8550000 | K31: =+J31/1000 -> 8550
G33: 160000 | H33: =+H29+H30 -> 2116861.3 | I33: 85 | J33: =+H33*I33 -> 1.7993321e+08 | K33: =+J33/1000 -> 179933.21
H34: =+H30+H31+H29 -> 2206861.3
H35: 15 | I35: =+H34/H35 -> 147124.08 | K35: =+K33+K31 -> 188483.21
N36: 705222
A37: ยอดส่ง 1/2/68 - 10/2/68 | B37: 817879 | I37: =+H35*100000 -> 1500000
N38: =+H34+N36 -> 2912083.3
H39: 16 | I39: =+H39*90000 -> 1440000
B41: =+B26+B37+B31 -> 887879 | C41: =+C26+C37+C31 -> 70000 | D41: =+D26+D37+D31 -> 70000 | E41: =+E26+E37+E31 -> 0 | F41: =+F26+F37+F31 -> 0
B43: 2992955
B45: =+B43-B41 -> 2105076 | C45: =+C32+($B$45*1) -> 2105076 | D45: =+D32+($B$45*1) -> 2105076 | E45: =+E31+($B$45*1) -> 2105076 | F45: =+F30+($B$45*1) -> 2105076 | G45: =+G30+($B$45*1) -> 2105076
C47: =+C41/13 -> 5384.6154 | D47: =+D41/15 -> 4666.6667
B49: 16 | C49: 135000 | D49: 135000
C50: =+B49*C49 -> 2160000 | D50: =+B49*D49 -> 2160000
...

Sheet 4(Order+FC)
A2: เลขที่ SO | B2: (หลายรายการ)
A3: วันส่ง | B3: (หลายรายการ)
A4: ชื่อลูกค้า | B4: (ทั้งหมด)
K5: 9
A6: ประเภท | B6: ผลรวม ของ จำนวนส่ง | C6: ผลรวม ของ ค้างพิมพ์ | D6: ผลรวม ของ ค้างตัด | E6: ผลรวม ของ ใช้ | F6: ผลรวม ของ Stock | G6: ผลรวม ของ ค้างทอ
A7: WSWT1625800 | B7: 10000 | C7: 0 | D7: 10000 | E7: 0 | F7: 0 | G7: 0 | H7: =+J7-I7 -> 0 | J7: =G7 -> 0
A8: WSWT1921720 | B8: 90000 | C8: 41976.9 | D8: 74828 | E8: 40423.788 | F8: 8801.1 | G8: 31622.688 | H8: =+J8-I8 -> 31622.688 | J8: =G8 -> 31622.688
A9: WSWT1925800 | B9: 118000 | C9: 54869.85 | D9: 118000 | E9: 45972.484 | F9: 8242.3 | G9: 37730.184 | H9: =+J9-I9 -> 37730.184 | J9: =G9 -> 37730.184
A10: WSWT2025700 | B10: 10000 | C10: 0 | D10: 10000 | E10: 8801.1 | F10: 0 | G10: 8801.1 | H10: =+J10-I10 -> 8801.1 | J10: =G10 -> 8801.1
A11: WSWT2025800 | B11: 193960 | C11: 70687.05 | D11: 193960 | E11: 74062.357 | F11: 50571 | G11: 23491.357 | H11: =+J11-I11 -> 23491.357 | J11: =G11 -> 23491.357
A12: WSWT2025800SM | B12: 142160 | C12: 123783.45 | D12: 139160 | E12: 123659.07 | F12: 74605.09 | G12: 49053.98 | H12: =+J12-I12 -> 49053.98 | J12: =G12 -> 49053.98 | K12: 40000 | L12: =+K5*K12 -> 360000 | M12: =+L12-J12 -> 310946.02
A13: WSWT2121670SM | B13: 82000 | C13: 54153.75 | D13: 79000 | E13: 55670.991 | F13: 17415.391 | G13: 38255.6 | H13: =+J13-I13 -> 38255.6 | J13: =G13 -> 38255.6 | K13: 14000 | L13: =+K13*K5 -> 126000 | M13: =+L13-J13 -> 87744.4
A14: WSWT2321750 | B14: 8000 | C14: 0 | D14: 8000 | E14: 0 | F14: 0 | G14: 0 | H14: =+J14-I14 -> 0 | J14: =G14 -> 0
A15: WSWT2325650 | B15: 40000 | C15: 0 | D15: 40000 | E15: 0 | F15: 0 | G15: 0 | H15: =+J15-I15 -> 0 | J15: =G15 -> 0 | K15: 20000 | L15: =+K15*K5 -> 180000 | M15: =+L15-J15 -> 180000
A16: WSWT2625650 | B16: 12563 | C16: 8400 | D16: 8000 | E16: 9499.6 | F16: 6749.8 | G16: 2749.8 | H16: =+J16-I16 -> 2749.8 | J16: =G16 -> 2749.8
A17: WSWT2625850SM | B17: 10000 | C17: 0 | D17: 10000 | E17: 0 | F17: 0 | G17: 0 | H17: =+J17-I17 -> 0 | J17: =G17 -> 0
A18: WSWT2825850 | B18: 31500 | C18: 0 | D18: 10500 | E18: 0 | F18: 0 | G18: 0 | H18: =+J18-I18 -> 0 | J18: =G18 -> 0
A19: ผลรวมทั้งหมด | B19: 748183 | C19: 353871 | D19: 701448 | E19: 358089.39 | F19: 166384.68 | G19: 191704.71 | H19: 0 | I19: 54000 | J19: =G19 -> 191704.71
H20: =+J20-I20 -> 0 | J20: =G20 -> 0
H21: =+J21-I21 -> 0 | J21: =G21 -> 0
H22: =+J22-I22 -> 0 | J22: =G22 -> 0
H23: =+J23-I23 -> 0 | J23: =G23 -> 0
H24: =+J24-I24 -> 0 | J24: =G24 -> 0
H25: =+J25-I25 -> 0 | J25: =G25 -> 0
H26: =+J26-I26 -> 0 | J26: =G26 -> 0
H27: =+J27-I27 -> 0 | J27: =G27 -> 0
H28: =+J28-I28 -> 0 | J28: =G28 -> 0 | M28: =+GETPIVOTDATA("ผลรวม ของ ใช้",$A$6)+H29+H33 -> 639794.1
H29: =SUM(H7:H28) -> 191704.71 | I29: =SUM(I7:I28) -> 54000 | J29: =SUM(J7:J28) -> 383409.42
H32: =+H26 -> 0 | I32: 85 | J32: =+(H32+H29)*I32 -> 16294900 | K32: =+J32/1000 -> 16294.9
H33: 90000 | I33: 95 | J33: =+H33*I33 -> 8550000 | K33: =+J33/1000 -> 8550
H35: =+H32+H33+H29 -> 281704.71 | K35: =+K32+K33 -> 24844.9
N36: 705222
A37: ยอดส่ง 1/2/68 - 17/2/68 | B37: 1565717 | H37: 15 | I37: =+H35/H37 -> 18780.314
N38: =+H35+N36 -> 986926.71
I39: =+H37*110000 -> 1650000
B41: =+B29+B37+B31-110000 -> 1455717 | C41: =+C29+C37+C31 -> 0 | D41: =+D29+D37+D31-110000 -> -110000 | E41: =+E29+E37+E31 -> 0 | F41: =+F29+F37+F31 -> 0 | G41: =+G29+G37+G31 -> 0
B43: 3218150
B45: =+B43-B41 -> 1762433
C47: =+C41/9 -> 0 | D47: =+D41/9 -> -12222.222

Sheet 4(Order)
A2: เลขที่ SO | B2: (หลายรายการ)
A3: วันส่ง | B3: (หลายรายการ)
A4: ชื่อลูกค้า | B4: (ทั้งหมด)
A6: ประเภท | B6: ผลรวม ของ จำนวนส่ง | C6: ผลรวม ของ ค้างพิมพ์ | D6: ผลรวม ของ ค้างตัด | E6: ผลรวม ของ ใช้ | F6: ผลรวม ของ Stock | G6: ผลรวม ของ ค้างทอ
A7: WSWT1725800 | B7: 24200 | C7: 25410 | D7: 24200 | E7: 18594.07 | F7: 15615 | G7: 2979.07 | I7: =+K7-J7 -> 2979.07 | K7: =G7 -> 2979.07
A8: WSWT1921720 | B8: 75000 | C8: 30846.9 | D8: 59828 | E8: 31508.273 | F8: 0 | G8: 31508.273 | I8: =+K8-J8 -> 31508.273 | K8: =G8 -> 31508.273
A9: WSWT1925800 | B9: 101500 | C9: 43913.1 | D9: 63322 | E9: 36807.96 | F9: 2500 | G9: 34307.96 | I9: =+K9-J9 -> 34307.96 | K9: =G9 -> 34307.96
A10: WSWT2025700 | B10: 10000 | C10: 0 | D10: 10000 | E10: 8801.1 | F10: 8801.1 | G10: 0 | I10: =+K10-J10 -> 0 | K10: =G10 -> 0
A11: WSWT2025800 | B11: 160920 | C11: 41566.35 | D11: 103577 | E11: 43551.143 | F11: 17000 | G11: 26551.143 | I11: =+K11-J11 -> 26551.143 | K11: =G11 -> 26551.143
A12: WSWT2025800SM | B12: 146096 | C12: 100203.6 | D12: 143096 | E12: 100180.41 | F12: 73200.844 | G12: 26979.563 | I12: =+K12-J12 -> 26979.563 | K12: =G12 -> 26979.563
A13: WSWT2121670SM | B13: 73000 | C13: 36839.25 | D13: 73000 | E13: 37852.724 | F13: 13107.024 | G13: 24745.7 | I13: =+K13-J13 -> 24745.7 | K13: =G13 -> 24745.7
A14: WSWT2125650 | B14: 10000 | C14: 0 | D14: 10000 | E14: 11036.3 | F14: 11036.3 | G14: 0 | I14: =+K14-J14 -> 0 | K14: =G14 -> 0
A15: WSWT2125800 | B15: 6600 | C15: 0 | D15: 6600 | E15: 0 | F15: 0 | G15: 0 | I15: =+K15-J15 -> 0 | K15: =G15 -> 0
A16: WSWT2321750 | B16: 8000 | C16: 0 | D16: 8000 | E16: 0 | F16: 0 | G16: 0 | I16: =+K16-J16 -> 0 | K16: =G16 -> 0
A17: WSWT2325650 | B17: 15000 | C17: 0 | D17: 15000 | E17: 0 | F17: 0 | G17: 0 | I17: 0 | J17: 54000 | K17: =G17 -> 0
A18: WSWT2625650 | B18: 8000 | C18: 8400 | D18: 8000 | E18: 9499.6 | F18: 6749.8 | G18: 2749.8 | I18: =+K18-J18 -> 2749.8 | K18: =G18 -> 2749.8
A19: WSWT2625850SM | B19: 10000 | C19: 0 | D19: 10000 | E19: 0 | F19: 0 | G19: 0 | I19: =+K19-J19 -> 0 | K19: =G19 -> 0
A20: WSWT2825850 | B20: 36500 | C20: 0 | D20: 5000 | E20: 5657.85 | F20: 4280 | G20: 1377.85 | I20: =+K20-J20 -> 1377.85 | K20: =G20 -> 1377.85
A21: WSWTFCL022325650 | B21: 10000 | C21: 2331 | D21: 10000 | E21: 2312.049 | F21: 2312.049 | G21: 0 | I21: =+K21-J21 -> 0 | K21: =G21 -> 0
A22: ผลรวมทั้งหมด | B22: 694816 | C22: 289510.2 | D22: 549623 | E22: 305801.48 | F22: 154602.12 | G22: 151199.36 | I22: =+K22-J22 -> 151199.36 | K22: =G22 -> 151199.36
I23: =+K23-J23 -> 0 | K23: =G23 -> 0
D24: 30000 | I24: =+K24-J24 -> 0 | K24: =G24 -> 0
D25: =+D7 -> 24200 | I25: =+K25-J25 -> 0 | K25: =G25 -> 0
D26: =+D8 -> 59828 | I26: =SUM(I7:I25) -> 302398.72 | J26: =SUM(J7:J25) -> 54000 | K26: =SUM(K7:K25) -> 302398.72
D28: =+D10 -> 10000
D30: =+D12 -> 143096
D31: =+D13 -> 73000
D32: =+D14 -> 10000
D33: =+D15 -> 6600
D34: =D18 -> 8000
D36: =D20 -> 5000
A37: ยอดส่ง 1/4/68 - 12/4/68 | B37: 887615
A38: Order+ส่ง | B38: =++B25+B37 -> 887615
A39: ประมาณการ | B39: 262000 | C39: 238350 | D39: 262000 | E39: 279847.04 | F39: 60825.09 | G39: 219021.95
A41: Order+ส่ง+ประมาณการ | B41: =+B25+B37+B39+B33 -> 1149615 | C41: =+C25+C37+C39+C33 -> 238350 | D41: =+D25+D37+D39+D33 -> 292800 | E41: =+E25+E37+E39+E33 -> 279847.04 | F41: =+F25+F37+F39+F33 -> 60825.09 | G41: =+G25+G37+G39+G33 -> 219021.95
B43: 3171376
B45: =+B41-B43 -> -2021761 | C45: =+$B$45 -> -2021761 | D45: =+$B$45 -> -2021761 | F45: =+$B$45 -> -2021761
D47: =+D41/6 -> 48800

Sheet 4(Order) แยกลูกค้า
A1: เลขที่ SO | B1: (หลายรายการ)
A2: วันส่ง | B2: (หลายรายการ)
A4: ประเภท | B4: ชื่อลูกค้า | C4: ผลรวม ของ จำนวนส่ง | D4: ผลรวม ของ ค้างพิมพ์ | E4: ผลรวม ของ ค้างตัด | F4: ผลรวม ของ Stock | G4: ผลรวม ของ ค้างทอ | I4: vn
A5: WSWT1625800 | B5: บจก.เคอรี่ฟลาวมิลล์ | C5: 10000 | D5: 0 | E5: 10000 | F5: 0 | G5: 0 | H5: =G5 -> 0
A6: WSWT1625800 ผลรวม | C6: 10000 | D6: 0 | E6: 10000 | F6: 0 | G6: 0 | H6: =G6 -> 0
A7: WSWT1725800 | B7: โรงสีข้าวธัญญาวัฒน์ | C7: 24200 | D7: 25410 | E7: 24200 | F7: 15615 | G7: 2979.07 | H7: =G7 -> 2979.07
A8: WSWT1725800 ผลรวม | C8: 24200 | D8: 25410 | E8: 24200 | F8: 15615 | G8: 2979.07 | H8: =G8 -> 2979.07
A9: WSWT1921720 | B9: บจก.เคอรี่ฟลาวมิลล์ | C9: 90000 | D9: 41976.9 | E9: 74828 | F9: 8801.1 | G9: 31622.688 | H9: =G9 -> 31622.688
A10: WSWT1921720 ผลรวม | C10: 90000 | D10: 41976.9 | E10: 74828 | F10: 8801.1 | G10: 31622.688 | H10: =G10 -> 31622.688
A11: WSWT1925800 | B11: บจก.เพรซิเดนท์ฟลาวมิลล์ | C11: 60000 | D11: 12869.85 | E11: 60000 | F11: 0 | G11: 11326.884 | H11: =G11 -> 11326.884
B12: บจก.ซีแมน | C12: 28000 | D12: 10500 | E12: 28000 | F12: 8242.3 | G12: 0 | H12: =G12 -> 0
B13: บจก.เอ็กเซลเล้นท์ | C13: 30000 | D13: 31500 | E13: 30000 | F13: 0 | G13: 26403.3 | H13: =G13 -> 26403.3
A14: WSWT1925800 ผลรวม | C14: 118000 | D14: 54869.85 | E14: 118000 | F14: 8242.3 | G14: 37730.184 | H14: =G14 -> 37730.184
A15: WSWT2025700 | B15: บจก.หนองบัวฟีดมิลล์ | C15: 10000 | D15: 0 | E15: 10000 | F15: 0 | G15: 8801.1 | H15: =G15 -> 8801.1
A16: WSWT2025700 ผลรวม | C16: 10000 | D16: 0 | E16: 10000 | F16: 0 | G16: 8801.1 | H16: =G16 -> 8801.1
A17: WSWT2025800 | B17: บจก.เบทาโกร | C17: 65000 | D17: 0 | E17: 65000 | F17: 0 | G17: 0 | H17: =G17 -> 0
B18: บจก.อินเทคค์ โกลบอล | C18: 128960 | D18: 70687.05 | E18: 128960 | F18: 50571 | G18: 23491.357 | H18: =G18 -> 23491.357
A19: WSWT2025800 ผลรวม | C19: 193960 | D19: 70687.05 | E19: 193960 | F19: 50571 | G19: 23491.357 | H19: =G19 -> 23491.357
A20: WSWT2025800SM | B20: บจก.เบทาโกร | C20: 12000 | D20: 0 | E20: 9000 | F20: 0 | G20: 0 | H20: =G20 -> 0
B21: บจก.อินเทคค์ โกลบอล | C21: 130160 | D21: 123783.45 | E21: 130160 | F21: 74605.09 | G21: 49053.98 | H21: =G21 -> 49053.98
A22: WSWT2025800SM ผลรวม | C22: 142160 | D22: 123783.45 | E22: 139160 | F22: 74605.09 | G22: 49053.98 | H22: =G22 -> 49053.98
A23: WSWT2121670SM | B23: บจก.เอพีเอ็ม อะโกร | C23: 3000 | D23: 0 | E23: 0 | F23: 0 | G23: 0 | H23: =G23 -> 0
B24: บจก.แอมโก้เวท | C24: 60000 | D24: 40503.75 | E24: 60000 | F24: 14188.321 | G24: 27498.7 | H24: =G24 -> 27498.7
B25: บจก.หนองบัวฟีดมิลล์ | C25: 10000 | D25: 10500 | E25: 10000 | F25: 0 | G25: 10756.9 | H25: =G25 -> 10756.9
B26: ร้านกัลยาพาณิชย์ | C26: 6000 | D26: 0 | E26: 6000 | F26: 0 | G26: 0 | H26: =G26 -> 0
B27: บจก.เอเซียอควาเซอร์วิสเซส | C27: 3000 | D27: 3150 | E27: 3000 | F27: 3227.07 | G27: 0 | H27: =G27 -> 0
A28: WSWT2121670SM ผลรวม | C28: 82000 | D28: 54153.75 | E28: 79000 | F28: 17415.391 | G28: 38255.6 | H28: =G28 -> 38255.6
A29: WSWT2125800 | B29: โรงสีข้าวธัญญาวัฒน์ | C29: 6600 | D29: 0 | E29: 6600 | F29: 0 | G29: 0 | H29: =G29 -> 0
A30: WSWT2125800 ผลรวม | C30: 6600 | D30: 0 | E30: 6600 | F30: 0 | G30: 0 | H30: =G30 -> 0
A31: WSWT2321750 | B31: บจก.ปริ้นซ์ อโกร ไซแอนส์ | C31: 8000 | D31: 0 | E31: 8000 | F31: 0 | G31: 0 | H31: =G31 -> 0
A32: WSWT2321750 ผลรวม | C32: 8000 | D32: 0 | E32: 8000 | F32: 0 | G32: 0 | H32: =G32 -> 0
A33: WSWT2325650 | B33: คุณปราสาท เจริญธรรมรักษา | C33: 40000 | D33: 0 | E33: 40000 | F33: 0 | G33: 0 | H33: =G33 -> 0
A34: WSWT2325650 ผลรวม | C34: 40000 | D34: 0 | E34: 40000 | F34: 0 | G34: 0 | H34: =G34 -> 0
A35: WSWT2625650 | B35: บจก.กบินทร์อินทรีย์ | C35: 8000 | D35: 8400 | E35: 8000 | F35: 6749.8 | G35: 2749.8 | H35: =G35 -> 2749.8
B36: คุณธนนท์ อุทัยไพศาลวงศ์ | C36: 4563 | D36: 0 | E36: 0 | F36: 0 | G36: 0 | H36: =G36 -> 0
A37: WSWT2625650 ผลรวม | C37: 12563 | D37: 8400 | E37: 8000 | F37: 6749.8 | G37: 2749.8 | H37: =G37 -> 2749.8
A38: WSWT2625850SM | B38: บจก.ที.ซี.ยูเนี่ยน อโกรเทค | C38: 10000 | D38: 0 | E38: 10000 | F38: 0 | G38: 0 | H38: =G38 -> 0
A39: WSWT2625850SM ผลรวม | C39: 10000 | D39: 0 | E39: 10000 | F39: 0 | G39: 0 | H39: =G39 -> 0
A40: WSWT2825850 | B40: บจก.ไทยร่วมใจน้ำมันพืช | C40: 31500 | D40: 0 | E40: 10500 | F40: 0 | G40: 0 | H40: =G40 -> 0
A41: WSWT2825850 ผลรวม | C41: 31500 | D41: 0 | E41: 10500 | F41: 0 | G41: 0 | H41: =G41 -> 0
...

Sheet 4(Fc) แยกลูกค้า
A1: เลขที่ SO | B1: ประมาณการ
A2: วันส่ง | B2: (หลายรายการ) | D2: 12
A4: ประเภท | B4: ชื่อลูกค้า | C4: ผลรวม ของ จำนวนส่ง | D4: ผลรวม ของ ค้างพิมพ์ | E4: ผลรวม ของ ค้างตัด | F4: ผลรวม ของ ใช้ | G4: ผลรวม ของ Stock | H4: ผลรวม ของ ค้างทอ
A5: ผลรวมทั้งหมด
D119: Cap พิมพ์ | E119: Cap ตัด | F119: Stock 16/7 บ่าย | G119: Cap ทอ | I119: วันทงาน
B120: lส่ง | C120: 1-16/7 | D120: 160000 | E120: 160000 | G120: 120000 | I120: 12
C121: 1975256 | D121: =+D120*I120 -> 1920000 | E121: =+E120*I120 -> 1920000 | F121: 825147 | G121: =+G120*I120 -> 1440000
A122: เบทาโกรส่งแล้ว | B122: 20700 | C122: 424374
A123: เบทาโกรส่งแล้ว | B123: 20800 | C123: 155973
C126: รวมส่ง+ค้างส่ง | D126: ส่วนต่างCapคงเหลือ | E126: ส่วนต่างCapคงเหลือ | F126: คงเหลือ
C127: =+C50+C121 -> 1975256 | D127: =+D121-D50 -> 1920000 | E127: =+E121-E50 -> 1920000 | F127: =+F121-F50 -> 825147 | G127: =+G121-G50 -> 1440000
B129: 20700VN 20/7 | G129: 350000

Sheet 3(Order+Fc) แยกลูกค้า
A1: เลขที่ SO | B1: (หลายรายการ)
A2: วันส่ง | B2: (หลายรายการ) | D2: 12 | I2: เมตร | J2: vn | K2: ใบ | P2: วัน
A4: ประเภท | B4: ชื่อลูกค้า | C4: ผลรวม ของ จำนวนส่ง | D4: ผลรวม ของ ค้างพิมพ์ | E4: ผลรวม ของ ค้างตัด | F4: ผลรวม ของ Stock | G4: ผลรวม ของ ใช้ | H4: ผลรวม ของ ค้างทอ
A5: WSWT1621720SMFX | B5: โรงสีขธัญญกิจ(ราชบุรี) | C5: 10000 | D5: 10500 | E5: 10000 | F5: 7404.1 | G5: 7404.1 | H5: 0 | I5: =H5 -> 0
A6: WSWT1621720SMFX ผลรวม | C6: 10000 | D6: 10500 | E6: 10000 | F6: 7404.1 | G6: 7404.1 | H6: 0
A7: WSWT1825800 | B7: บจก.เกียเอ็นเนอร์ยี่ | C7: 2000 | D7: 0 | E7: 0 | F7: 0 | G7: 0 | H7: 0 | I7: =H7 -> 0
A8: WSWT1825800 ผลรวม | C8: 2000 | D8: 0 | E8: 0 | F8: 0 | G8: 0 | H8: 0 | I8: =H8 -> 0
A9: WSWT1921720 | B9: บจก.เคอรี่ฟลาวมิลล์ | C9: 225000 | D9: 225750 | E9: 225000 | F9: 0 | G9: 199701.15 | H9: 199701.15 | I9: =H9 -> 199701.15
A10: WSWT1921720 ผลรวม | C10: 225000 | D10: 225750 | E10: 225000 | F10: 0 | G10: 199701.15 | H10: 199701.15 | I10: =H10 -> 199701.15
A11: WSWT1925800 | B11: บจก.เพรซิเดนท์ฟลาวมิลล์ | C11: 82000 | D11: 4830 | E11: 82000 | F11: 0 | G11: 4250.9313 | H11: 4250.9313
B12: บจก.ซีแมน | C12: 27812 | D12: 15225 | E12: 27812 | F12: 0 | G12: 12548.902 | H12: 12548.902 | I12: =H12 -> 12548.902
B13: บจก.ไลม์มาสเตอร์ | C13: 10000 | D13: 10500 | E13: 10000 | F13: 0 | G13: 9359.9 | H13: 9359.9
B14: บจก.เอ็กเซลเล้นท์ | C14: 30000 | D14: 31500 | E14: 30000 | F14: 0 | G14: 26403.3 | H14: 26403.3 | I14: =H14 -> 26403.3 | P14: 15000 | Q14: =+K14/P14 -> 0
B15: บจก.ไอทีอี | C15: 5000 | D15: 5250 | E15: 5000 | F15: 0 | G15: 4959.35 | H15: 4959.35
A16: WSWT1925800 ผลรวม | C16: 154812 | D16: 67305 | E16: 154812 | F16: 0 | G16: 57522.383 | H16: 57522.383 | I16: =H16 -> 57522.383
A17: WSWT1925800SM | B17: บจก.เอเชี่ยนเคมิคัล | C17: 15000 | D17: 15750 | E17: 15000 | F17: 3891 | G17: 11525.25 | H17: 7634.25 | I17: =H17 -> 7634.25
A18: WSWT1925800SM ผลรวม | C18: 15000 | D18: 15750 | E18: 15000 | F18: 3891 | G18: 11525.25 | H18: 7634.25 | I18: =H18 -> 7634.25
A19: WSWT2025650 | B19: บจก.หนองบัวฟีดมิลล์ | C19: 20000 | D19: 0 | E19: 20000 | F19: 0 | G19: 17602.2 | H19: 17602.2 | I19: =H19 -> 17602.2
B20: บจก.เอเชียเหมืองแร่ | C20: 20000 | D20: 21000 | E20: 20000 | F20: 0 | G20: 18719.8 | H20: 18719.8 | I20: =H20 -> 18719.8 | P20: 16000 | Q20: =+K20/P20 -> 0
A21: WSWT2025650 ผลรวม | C21: 40000 | D21: 21000 | E21: 40000 | F21: 0 | G21: 36322 | H21: 36322
A22: WSWT2025700 | B22: บจก.เบทาโกร | C22: 5000 | D22: 0 | E22: 0 | F22: 0 | G22: 0 | H22: 0 | I22: =H22 -> 0
B23: บจก.เอ็กซ์เซลเล้นท์ | C23: 10000 | D23: 7928.55 | E23: 10000 | F23: 8259.7394 | G23: 8259.7394 | H23: 0
A24: WSWT2025700 ผลรวม | C24: 15000 | D24: 7928.55 | E24: 10000 | F24: 8259.7394 | G24: 8259.7394 | H24: 0 | I24: =H24 -> 0
A25: WSWT2025800 | B25: บจก.ไทยธรรมดี | C25: 25000 | D25: 0 | E25: 0 | F25: 0 | G25: 0 | H25: 0
B26: บจก.เบทาโกร | C26: 295000 | D26: 241500 | E26: 250000 | F26: 26892.25 | G26: 247408.7 | H26: 220516.45 | I26: =H26 -> 220516.45
B27: บจก.อินเทคค์ โกลบอล | C27: 200000 | D27: 210000 | E27: 200000 | F27: 0 | G27: 209550 | H27: 209550
A28: WSWT2025800 ผลรวม | C28: 520000 | D28: 451500 | E28: 450000 | F28: 26892.25 | G28: 456958.7 | H28: 430066.45 | I28: =H28 -> 430066.45
A29: WSWT2025800SM | B29: บจก.อินเทคค์ โกลบอล | C29: 133840 | D29: 136418.1 | E29: 133840 | F29: 0 | G29: 137693.31 | H29: 137693.31 | I29: =H29 -> 137693.31
B30: บจก.เอพีเอ็ม อะโกร | C30: 13297 | D30: 5561.85 | E30: 5297 | F30: 4000 | G30: 5845.9281 | H30: 1845.9281 | I30: =H30 -> 1845.9281
B31: บจก.เอสพีเอ็ม อาหารสัตว์ | C31: 19000 | D31: 11195.1 | E31: 16662 | F31: 3227.07 | G31: 11683.083 | H31: 8456.0131 | P31: 15000 | Q31: =+K31/P31 -> 0
B32: บจก.วีซีเอฟ | C32: 80000 | D32: 78750 | E32: 80000 | F32: 3000 | G32: 80676.75 | H32: 77676.75 | I32: =H32 -> 77676.75
B33: บจก.เสบียง 111 | C33: 10000 | D33: 0 | E33: 10000 | F33: 10756.9 | G33: 10756.9 | H33: 0 | I33: =H33 -> 0
A34: WSWT2025800SM ผลรวม | C34: 256137 | D34: 231925.05 | E34: 245799 | F34: 20983.97 | G34: 246655.98 | H34: 225672.01 | I34: =H34 -> 225672.01
A35: WSWT2121670SM | B35: บจก.ที.ซี.ยูเนี่ยน อโกรเทค | C35: 42000 | D35: 44100 | E35: 42000 | F35: 0 | G35: 45178.98 | H35: 45178.98 | I35: =H35 -> 45178.98
B36: บจก.เอพีเอ็ม อะโกร | C36: 20000 | D36: 10500 | E36: 20000 | F36: 0 | G36: 11036.3 | H36: 11036.3 | I36: =H36 -> 11036.3
B37: บจก.แอมโก้เวท | C37: 39128 | D37: 21000 | E37: 39128 | F37: 0 | G37: 21513.8 | H37: 21513.8 | I37: =H37 -> 21513.8
B38: บจก.หนองบัวฟีดมิลล์ | C38: 5000 | D38: 5250 | E38: 5000 | F38: 0 | G38: 5378.45 | H38: 5378.45 | I38: =H38 -> 5378.45
B39: บจก.เอ็นบี ดิสทริบิวชั่น | C39: 20000 | D39: 21000 | E39: 20000 | F39: 0 | G39: 21513.8 | H39: 21513.8 | I39: =H39 -> 21513.8
B40: คุณนพวินทร์ รัตนเศรษฐ์เมธา | C40: 5000 | D40: 5250 | E40: 5000 | F40: 5378.45 | G40: 5378.45 | H40: 0 | I40: =H40 -> 0
B41: บจก.หนองบัว อโกรฟอร์ไลฟ์ | C41: 10000 | D41: 10500 | E41: 10000 | F41: 0 | G41: 10756.9 | H41: 10756.9
...

Sheet 5(Order)
A2: เลขที่ SO | B2: (หลายรายการ)
A3: วันส่ง | B3: (หลายรายการ)
A4: ชื่อลูกค้า | B4: (ทั้งหมด)
A6: ประเภท | B6: ผลรวม ของ จำนวนส่ง | C6: ผลรวม ของ ค้างพิมพ์ | D6: ผลรวม ของ ค้างตัด | E6: ผลรวม ของ ใช้ | F6: ผลรวม ของ Stock | G6: ผลรวม ของ ค้างทอ
A7: WSWT1621720SMFX | B7: 10000 | C7: 10500 | D7: 10000 | E7: 7404.1 | F7: 7404.1 | G7: 0
A8: WSWT1825800 | B8: 2000 | C8: 0 | D8: 0 | E8: 0 | F8: 0 | G8: 0
A9: WSWT1921720 | B9: 75000 | C9: 68250 | D9: 75000 | E9: 67684.65 | F9: 0 | G9: 67684.65
A10: WSWT1925800 | B10: 109812 | C10: 20055 | D10: 109812 | E10: 16799.833 | F10: 0 | G10: 16799.833
A11: WSWT1925800SM | B11: 15000 | C11: 15750 | D11: 15000 | E11: 11525.25 | F11: 3891 | G11: 7634.25 | L11: =76*2500 -> 190000
A12: WSWT2025700 | B12: 15000 | C12: 7928.55 | D12: 10000 | E12: 8259.7394 | F12: 8259.7394 | G12: 0
A13: WSWT2025800 | B13: 120000 | C13: 31500 | D13: 50000 | E13: 32270.7 | F13: 26892.25 | G13: 5378.45
A14: WSWT2025800SM | B14: 106137 | C14: 74425.05 | D14: 95799 | E14: 88096.475 | F14: 20983.97 | G14: 67112.505
A15: WSWT2121670SM | B15: 101128 | C15: 75600 | D15: 101128 | E15: 77729.08 | F15: 5378.45 | G15: 72350.63
A16: WSWT2125650 | B16: 22000 | C16: 0 | D16: 18900 | E16: 20858.607 | F16: 1990 | G16: 18868.607
A17: WSWT2321750 | B17: 23000 | C17: 12831 | D17: 15000 | E17: 13393.556 | F17: 8183 | G17: 5210.5559
A18: WSWT2325650 | B18: 25000 | C18: 7381.5 | D18: 25000 | E18: 7321.4884 | F18: 1593.7317 | G18: 5727.7567
A19: WSWT2625650 | B19: 10000 | C19: 0 | D19: 10000 | E19: 11315.7 | F19: 3553 | G19: 7762.7
A20: WSWT2625850SM | B20: 90000 | C20: 63273 | D20: 85954 | E20: 74939.229 | F20: 74939.229 | G20: 0
A21: WSWT2825850 | B21: 50000 | C21: 46539.15 | D21: 44323 | E21: 52631.346 | F21: 30583 | G21: 22048.346
A22: ผลรวมทั้งหมด | B22: 774077 | C22: 434033.25 | D22: 665916 | E22: 490229.75 | F22: 193651.47 | G22: 296578.28
A37: ยอดส่ง 1/1/68 - 17/1/68 | B37: 1287052
A38: Order+ส่ง | B38: =++B22+B37 -> 2061129
A39: ประมาณการ | I39: 0
A41: Order+ส่ง+ประมาณการ | B41: =+B22+B37+B39+B29 -> 2061129 | C41: =+C22+C37+C39+C29 -> 434033.25 | D41: =+D22+D37+D39+D29 -> 665916 | E41: =+E22+E37+E39+E29 -> 490229.75 | F41: =+F22+F37+F39+F29 -> 193651.47 | G41: =+G22+G37+G39+G29 -> 296578.28
B43: 3000000 | I43: 9
B45: =+B41-B43 -> -938871
D46: =+D22/I43 -> 73990.667
C47: =+C41/I43 -> 48225.917 | D47: =+D41/I43 -> 73990.667 | G47: =+G41/I43 -> 32953.143

Sheet 3(Order) แยกลูกค้า
A1: เลขที่ SO | B1: (หลายรายการ)
A2: วันส่ง | B2: รอแจ้ง
A4: ประเภท | B4: ชื่อลูกค้า | C4: ผลรวม ของ จำนวนส่ง | D4: ผลรวม ของ ค้างพิมพ์ | E4: ผลรวม ของ ค้างตัด | F4: ผลรวม ของ Stock | G4: ผลรวม ของ ค้างทอ | I4: vn
A5: WSWT2025800SM | B5: บจก.อินเทคค์ โกลบอล | C5: 6250 | D5: 0 | E5: 6183 | F5: 0 | G5: 0 | H5: =G5 -> 0
A6: WSWT2025800SM ผลรวม | C6: 6250 | D6: 0 | E6: 6183 | F6: 0 | G6: 0 | H6: =G6 -> 0
A7: WSWT2121670SM | B7: บจก.ที.ซี.ยูเนี่ยน อโกรเทค | C7: 32000 | D7: 33600 | E7: 32000 | F7: 34422.08 | G7: 0 | H7: =G7 -> 0
B8: บจก.เอพีเอ็ม อะโกร | C8: 14000 | D8: 14700 | E8: 14000 | F8: 0 | G8: 15450.82
B9: บจก.เอสพีเอ็ม อาหารสัตว์ | C9: 5000 | D9: 5250 | E9: 5000 | F9: 0 | G9: 5518.15 | H9: =G9 -> 5518.15
A10: WSWT2121670SM ผลรวม | C10: 51000 | D10: 53550 | E10: 51000 | F10: 34422.08 | G10: 20968.97 | H10: =G10 -> 20968.97
A11: WSWT2321112512551 | B11: บจก.น้ำตาลทิพย์สุโขทัย | C11: 106278 | D11: 111591.9 | E11: 106278 | F11: 0 | G11: 114322.18
A12: WSWT2321112512551 ผลรวม | C12: 106278 | D12: 111591.9 | E12: 106278 | F12: 0 | G12: 114322.18 | H12: =G12 -> 114322.18
A13: WSWT2625800 | B13: บจก.ที.ซี.ยูเนี่ยน อโกรเทค | C13: 10000 | D13: 0 | E13: 10000 | F13: 6278 | G13: 6155.3 | H13: =G13 -> 6155.3
A14: WSWT2625800 ผลรวม | C14: 10000 | D14: 0 | E14: 10000 | F14: 6278 | G14: 6155.3 | H14: =G14 -> 6155.3
A15: ผลรวมทั้งหมด | C15: 173528 | D15: 165141.9 | E15: 173461 | F15: 40700.08 | G15: 141446.45
H16: =G16 -> 0
H18: =G18 -> 0
H19: =G19 -> 0
H20: =G20 -> 0
H21: =G21 -> 0
H23: =G23 -> 0
H25: =G25 -> 0
H27: =G27 -> 0
H28: =G28 -> 0
H29: =G29 -> 0
H31: =G31 -> 0
H32: =G32 -> 0
... H68: =G68 -> 0
H70: =SUM(H5:H69) -> 153119.9
D119: Cap พิมพ์ | E119: Cap ตัด | F119: Stock 16/7 บ่าย | G119: Cap ทอ | I119: วันทงาน
B120: lส่ง | C120: 1-16/7 | D120: 160000 | E120: 160000 | G120: 120000 | I120: 12
C121: 1975256 | D121: =+D120*I120 -> 1920000 | E121: =+E120*I120 -> 1920000 | F121: 825147 | G121: =+G120*I120 -> 1440000
A122: เบทาโกรส่งแล้ว | B122: 20700 | C122: 424374
A123: เบทาโกรส่งแล้ว | B123: 20800 | C123: 155973
C126: รวมส่ง+ค้างส่ง | D126: ส่วนต่างCapคงเหลือ | E126: ส่วนต่างCapคงเหลือ | F126: คงเหลือ
C127: =+C50+C121 -> 1975256 | D127: =+D121-D50 -> 1920000 | E127: =+E121-E50 -> 1920000 | F127: =+F121-F50 -> 825147 | G127: =+G121-G50 -> 1440000
B129: 20700VN 20/7 | G129: 350000

Sheet 5(Fc) แยกลูกค้
A1: เลขที่ SO | B1: ประมาณการ
A2: วันส่ง | B2: (หลายรายการ) | D2: 12
A4: ประเภท | B4: ชื่อลูกค้า | C4: ผลรวม ของ จำนวนส่ง | D4: ผลรวม ของ ค้างพิมพ์ | E4: ผลรวม ของ ค้างตัด | F4: ผลรวม ของ Stock | G4: ผลรวม ของ ใช้ | H4: ผลรวม ของ ค้างทอ
A5: WSWT1921720 | B5: บจก.เคอรี่ฟลาวมิลล์ | C5: 150000 | D5: 157500 | E5: 150000 | F5: 0 | G5: 132016.5 | H5: 132016.5
A6: WSWT1921720 ผลรวม | C6: 150000 | D6: 157500 | E6: 150000 | F6: 0 | G6: 132016.5 | H6: 132016.5
A7: WSWT1925800 | B7: บจก.ไลม์มาสเตอร์ | C7: 10000 | D7: 10500 | E7: 10000 | F7: 0 | G7: 9359.9 | H7: 9359.9
B8: บจก.เอ็กเซลเล้นท์ | C8: 30000 | D8: 31500 | E8: 30000 | F8: 0 | G8: 26403.3 | H8: 26403.3
B9: บจก.ไอทีอี | C9: 5000 | D9: 5250 | E9: 5000 | F9: 0 | G9: 4959.35 | H9: 4959.35
A10: WSWT1925800 ผลรวม | C10: 45000 | D10: 47250 | E10: 45000 | F10: 0 | G10: 40722.55 | H10: 40722.55
A11: WSWT2025650 | B11: บจก.หนองบัวฟีดมิลล์ | C11: 20000 | D11: 0 | E11: 20000 | F11: 0 | G11: 17602.2 | H11: 17602.2
B12: บจก.เอเชียเหมืองแร่ | C12: 20000 | D12: 21000 | E12: 20000 | F12: 0 | G12: 18719.8 | H12: 18719.8
A13: WSWT2025650 ผลรวม | C13: 40000 | D13: 21000 | E13: 40000 | F13: 0 | G13: 36322 | H13: 36322
A14: WSWT2025800 | B14: บจก.เบทาโกร | C14: 200000 | D14: 210000 | E14: 200000 | F14: 0 | G14: 215138 | H14: 215138
B15: บจก.อินเทคค์ โกลบอล | C15: 200000 | D15: 210000 | E15: 200000 | F15: 0 | G15: 209550 | H15: 209550
A16: WSWT2025800 ผลรวม | C16: 400000 | D16: 420000 | E16: 400000 | F16: 0 | G16: 424688 | H16: 424688
A17: WSWT2025800SM | B17: บจก.อินเทคค์ โกลบอล | C17: 100000 | D17: 105000 | E17: 100000 | F17: 0 | G17: 104775 | H17: 104775
B18: บจก.วีซีเอฟ | C18: 50000 | D18: 52500 | E18: 50000 | F18: 0 | G18: 53784.5 | H18: 53784.5
A19: WSWT2025800SM ผลรวม | C19: 150000 | D19: 157500 | E19: 150000 | F19: 0 | G19: 158559.5 | H19: 158559.5
A20: WSWT2121670SM | B20: บจก.ที.ซี.ยูเนี่ยน อโกรเทค | C20: 10000 | D20: 10500 | E20: 10000 | F20: 0 | G20: 10756.9 | H20: 10756.9
B21: บจก.แอมโก้เวท | C21: 20000 | D21: 21000 | E21: 20000 | F21: 0 | G21: 21513.8 | H21: 21513.8
B22: บจก.หนองบัว อโกรฟอร์ไลฟ์ | C22: 10000 | D22: 10500 | E22: 10000 | F22: 0 | G22: 10756.9 | H22: 10756.9
A23: WSWT2121670SM ผลรวม | C23: 40000 | D23: 42000 | E23: 40000 | F23: 0 | G23: 43027.6 | H23: 43027.6
A24: WSWT2125650 | B24: บจก.หนองบัวฟีดมิลล์ | C24: 5000 | D24: 0 | E24: 5000 | F24: 0 | G24: 5518.15 | H24: 5518.15
A25: WSWT2125650 ผลรวม | C25: 5000 | D25: 0 | E25: 5000 | F25: 0 | G25: 5518.15 | H25: 5518.15
A26: WSWT2321750 | B26: คุณวัลภา เผ่าเต้ม | C26: 10000 | D26: 10500 | E26: 10000 | F26: 0 | G26: 10756.9 | H26: 10756.9
A27: WSWT2321750 ผลรวม | C27: 10000 | D27: 10500 | E27: 10000 | F27: 0 | G27: 10756.9 | H27: 10756.9
A28: WSWT2325650 | B28: บจก.ซิเบลโก้(บางเลน) | C28: 10000 | D28: 10500 | E28: 10000 | F28: 0 | G28: 11036.3 | H28: 11036.3
B29: พันธุ์ข้าว | C29: 40000 | D29: 42000 | E29: 40000 | F29: 0 | G29: 39674.8 | H29: 39674.8
B30: บจก.ซิเบลโก้(สบปราบ) | C30: 20000 | D30: 21000 | E30: 20000 | F30: 0 | G30: 19837.4 | H30: 19837.4
A31: WSWT2325650 ผลรวม | C31: 70000 | D31: 73500 | E31: 70000 | F31: 0 | G31: 70548.5 | H31: 70548.5
A32: WSWT2625800 | B32: บจก.ที.ซี.ยูเนี่ยน อโกรเทค | C32: 10000 | D32: 0 | E32: 10000 | F32: 6978 | G32: 12433.3 | H32: 5455.3
A33: WSWT2625800 ผลรวม | C33: 10000 | D33: 0 | E33: 10000 | F33: 6978 | G33: 12433.3 | H33: 5455.3
A34: WSWT2625850SM | B34: บจก.ที.ซี.ยูเนี่ยน อโกรเทค | C34: 20000 | D34: 21000 | E34: 20000 | F34: 0 | G34: 24866.6 | H34: 24866.6
A35: WSWT2625850SM ผลรวม | C35: 20000 | D35: 21000 | E35: 20000 | F35: 0 | G35: 24866.6 | H35: 24866.6
A36: WSWT2825850 | B36: บจก.ที.ซี.ยูเนี่ยน อโกรเทค | C36: 10000 | D36: 0 | E36: 10000 | F36: 0 | G36: 13550.9 | H36: 13550.9
A37: WSWT2825850 ผลรวม | C37: 10000 | D37: 0 | E37: 10000 | F37: 0 | G37: 13550.9 | H37: 13550.9
A38: ผลรวมทั้งหมด | C38: 950000 | D38: 950250 | E38: 950000 | F38: 6978 | G38: 973010.5 | H38: 966032.5
H41: 296578.28
H43: =+GETPIVOTDATA("ผลรวม ของ ค้างทอ",$A$4)+H41 -> 1262610.8
I119: วันทงาน
...

Sheet ค้างทอ3-5-68
A3: ผลรวม ของ ค้างทอ
A4: ป้ายชื่อแถว | B4: 45778 | C4: 45779 | D4: 45780 | E4: 45781 | F4: 45782 | G4: 45784 | H4: 45785 | I4: 45786 | J4: 45787 | K4: 45788 | L4: 45789 | M4: 45792 | N4: 45793 | O4: 45795 | P4: 45798 | Q4: 45802 | R4: ผลรวมทั้งหมด
A5: WSWT1621720SMFX | F5: 0 | R5: =SUM(B5:Q5) -> 0
A6: WSWT1825800 | C6: 0 | R6: =SUM(B6:Q6) -> 0
A7: WSWT1921720 | B7: 5683.1 | D7: 22002.75 | H7: 22002.75 | J7: 23679.15 | R7: =SUM(B7:Q7) -> 73367.75
A8: WSWT1925800 | D8: 72169.02 | F8: 12548.902 | R8: =SUM(B8:Q8) -> 84717.922
A9: WSWT2025700 | E9: 2527.45 | J9: 0 | R9: =SUM(B9:Q9) -> 2527.45
A10: WSWT2025800 | B10: 0 | C10: 22975.25 | E10: 18745.888 | H10: 21513.8 | J10: 5378.45 | K10: 10756.9 | P10: 16135.35 | R10: =SUM(B10:Q10) -> 95505.638
A11: WSWT2025800SM | B11: 39296.912 | C11: 10756.9 | F11: 3227.07 | G11: 1845.9281 | H11: 3310.89 | I11: 0 | J11: 0 | L11: 5145.1231 | N11: 0 | R11: =SUM(B11:Q11) -> 63582.823
A12: WSWT2121670SM | C12: 0 | D12: 21513.8 | I12: 6621.78 | J12: 34422.08 | Q12: 4414.52 | R12: =SUM(B12:Q12) -> 66972.18
A13: WSWT2125650 | B13: 2442.28 | D13: 4304.157 | R13: =SUM(B13:Q13) -> 6746.437
A14: WSWT2125800 | D14: 0 | R14: =SUM(B14:Q14) -> 0
A15: WSWT2221940 | O15: 240385.29 | R15: =SUM(B15:Q15) -> 240385.29
A16: WSWT2321750 | D16: 5305.9 | H16: 3904.75 | R16: =SUM(B16:Q16) -> 9210.65
A17: WSWT2325650 | B17: 1225.15 | D17: 19837.4 | R17: =SUM(B17:Q17) -> 21062.55
A18: WSWT2625650 | B18: 446.97015 | R18: =SUM(B18:Q18) -> 446.97015
A19: WSWT2625850SM | C19: 0 | H19: 0 | I19: 0 | M19: 0 | R19: =SUM(B19:Q19) -> 0
A20: WSWT2825850 | M20: 35433.346 | R20: =SUM(B20:Q20) -> 35433.346
A21: ผลรวมทั้งหมด | B21: =SUM(B5:B20) -> 49094.412 | C21: =SUM(C5:C20) -> 33732.15 | D21: =SUM(D5:D20) -> 145133.03 | E21: =SUM(E5:E20) -> 21273.338 | F21: =SUM(F5:F20) -> 15775.972 | G21: =SUM(G5:G20) -> 1845.9281 | H21: =SUM(H5:H20) -> 50732.19 | I21: =SUM(I5:I20) -> 6621.78 | ... R21: =SUM(R5:R20) -> 699959

Sheet 3-6-68
B2: เรียงกำหนดส่ง | D2: ลบ 0 | T2: เรียง 1
B3: ข้อมูลUpdate ณ. วันที่ | D3: 45811 | E3: เวลา | G3: 11.03
A4: วันรับออร์เดอร์/แบบ | B4: เลขที่ SO | C4: ชื่อลูกค้า | E4: 10.3 | I4: น้ำหนัก | L4: บิด/จับจีบ | M4: ถุงใน | Q4: 44873 | S4: วิธีบรรจุ | T4: วันส่ง | U4: จำนวนส่ง | V4: ตัดเย็บ (ใบ) | W4: 44873 | X4: พิมพ์ (ใบ) | Y4: 44876 | Z4: ผ้าทอ (เมตร) Updateณ | AB4: 44876 | AD4: ผ้าเคลือบ(เมตร) | AF4: หมายเหตุ | AG4: เครื่อง
B5: เลขที่ SO | C5: ชื่อลูกค้า | D5: ตรา | E5: กว้าง | F5: ยาว | G5: สี | H5: เคลือบ | I5: กรัม/ใบ | J5: * | K5: aw | L5: บิด/จับจีบ | M5: กว้าง | N5: ยาว | O5: หนา | P5: ใช้(กก.) | Q5: Stock(กก.) | R5: ผลิต(กก.) | S5: วิธีบรรจุ | T5: วันส่ง | U5: จำนวนส่ง | V5: StockFG | W5: ค้างตัด | X5: พิมพ์แล้ว | Y5: ค้างพิมพ์ | Z5: ประเภท | AA5: ใช้ | AB5: Stock | AC5: ค้างทอ | AD5: Stock | AE5: ค้างเคลือบ | AF5: หมายเหตุ | AG5: ที่พิมพ์ได้ | AH5: process | AI5: Lead time | AJ5: วันที่ส่งPL | AK5: เคลือบ | AL5: ได้ ART | AM5: พิมพ์ | AN5: จีบ-บิด | AO5: ตัด-เย็บ | AP5: ทอ | AQ5: สวมถุง | AR5: เย็บปาก | AS5: PT | AT5: ม้วน | AU5: ตัด | AV5: ตอกตาไก่ | AW5: GROUP | AX5: ART | AY5: หมายเหตุปัญหา | AZ5: ราคา/ใบ | BA5: ราคารวม | BB5: workweek | BC5: เส้นเทป | BD5: จำนวน
A6: 45800 | B6: MK68-000701 | C6: หจก.ปึงเป้งน้ำ | D6: เกลือตรามือ 10กก | E6: 14 | F6: 22 | G6: ขาว | H6: ใส | I6: 42 | J6: ± | K6: 5 | L6: ไม่ | M6: ไม่สวมถุงใน | N6: 0 | O6: 0 | P6: 0 | Q6: 0 | R6: 0 | S6: 500กระสอบแบนเต็มใบ | T6: 45821 | U6: 10000 | V6: 0 | W6: 10000 | X6: 0 | Y6: 10500 | Z6: WSWT1425800 | AA6: 6565.9 | AB6: 1220 | AC6: 5345.9 | AD6: 1220 | AE6: 5345.9 | AF6: 0 | AG6: พร้อมส่ง | AH6: P6 | AI6: 4 | AJ6: 45821 | AK6: 45817 | AL6: 45810 | AM6: 45818 | AN6: 45819 | AO6: 45820 | AP6: 45816 | AQ6: 0 | AR6: 0 | AS6: 0 | AT6: 0 | AU6: 0 | AV6: 0 | AW6: งานเคลือบ+พิมพ์ | AX6: / | AY6: 0 | AZ6: 0 | BA6: 0 | BB6: 0 | BC6: WRWT25800/WRWT25800 | BD6: 299.3704
A7: 0 | B7: 0 | C7: 0 | D7: 0 | E7: 14 | F7: 22 | G7: ขาว | H7: 0 | I7: 36 | J7: ± | K7: 5 | L7: 0 | M7: 0 | N7: 0 | O7: 0 | P7: 0 | Q7: 0 | R7: 0 | S7: 0 | U7: 0 | V7: 0 | W7: 0 | X7: 0 | Y7: 0 | Z7: WSWT1425800 | AA7: 6565.9 | AB7: 1220 | AC7: 5345.9 | AD7: 1220 | AE7: 5345.9 | AF7: ระบุในSD | AG7: พร้อมส่ง | AH7: 0 | AI7: Lead time | AJ7: 0 | AK7: 0 | AL7: 0 | AM7: 0 | AN7: 0 | AO7: 0 | AP7: 0 | AQ7: 0 | AR7: 0 | AS7: 0 | AT7: 0 | AU7: 0 | AV7: 0 | AW7: 0 | AX7: 0 | AY7: 0 | AZ7: 0 | BA7: 0 | BB7: 0 | BC7: WRWT140800/WRWT25800 | BD7: 0
A8: ประมาณการ | B8: ประมาณการ | C8: บจก.ซัน ซีเมนต์ โพรเซส | D8: พระอาทิตย์(ปูนนอน-ชริงค์) | E8: 16 | F8: 25 | G8: ขาว | H8: ใส | I8: 50 | J8: ± | K8: 5 | L8: บิด | M8: 19 | N8: 28 | O8: 40 | P8: 65.624643 | Q8: 0 | R8: 65.624643 | S8: 500กระสอบ | T8: รอแจ้ง | U8: 5000 | V8: 0 | W8: 5000 | X8: 0 | Y8: 5250 | Z8: WSWT1625800SM | AA8: 3702.05 | AB8: 3372 | AC8: 330.05 | AD8: 0 | AE8: 3702.05 | AF8: 0 | AG8: พร้อมส่ง | AH8: P8 | AI8: 4 | AJ8: รอแจ้ง | AK8: #VALUE! | AL8: #VALUE! | AM8: #VALUE! | AN8: #VALUE! | AO8: #VALUE! | AP8: #VALUE! | AQ8: #VALUE! | AR8: 0 | AS8: 0 | AT8: 0 | AU8: 0 | AV8: 0 | AW8: งานเคลือบ+พิมพ์ | AX8: รอART | AY8: 0 | AZ8: 0 | BA8: 0 | BB8: 0 | BC8: WRWT25800/WRWT25800 | BD8: 18.776178
A9: 0 | B9: 0 | C9: 0 | E9: 16 | F9: 25 | G9: ขาว | H9: 0 | I9: 45 | J9: ± | K9: 5 | L9: 0 | M9: 0 | N9: 0 | O9: 0 | P9: 0 | Q9: 0 | R9: 0 | S9: 0 | U9: 0 | V9: 0 | W9: 0 | X9: 0 | Y9: 0 | Z9: WSWT1625800SM | AA9: 3702.05 | AB9: 3372 | AC9: 330.05 | AD9: 0 | AE9: 3702.05 | AF9: ระบุในSD | AG9: พิมพ์ไม่ครบ | AH9: 0 | AI9: Lead time | AJ9: 0 | AK9: 0 | AL9: 0 | AM9: 0 | AN9: 0 | AO9: 0 | AP9: 0 | AQ9: 0 | AR9: 0 | AS9: 0 | AT9: 0 | AU9: 0 | AV9: 0 | AW9: 0 | AX9: 0 | AY9: 0 | AZ9: 0 | BA9: 0 | BB9: 0 | BC9: WRWT160800/WRWT25800 | BD9: 0
A10: 45805 | B10: MK68-000717 | C10: บจก.โรงสีข้าวธัญญาวัฒน์ | D10: LUNG SHIN 12Kg. | E10: 17 | F10: 26 | G10: ขาว | H10: 0 | I10: 48 | J10: ± | K10: 5 | L10: ไม่ | M10: ไม่สวมถุงใน | N10: 0 | O10: 0 | P10: 0 | Q10: 0 | R10: 0 | S10: 500กระสอบแบน | T10: 45813 | U10: 10200 | V10: 0 | W10: 10200 | X10: 9000 | Y10: 1260 | Z10: WSWT1725800 | AA10: 968.121 | AB10: 968.121 | AC10: 0 | AD10: 0 | AE10: 0 | AF10: 0 | AG10: พร้อมส่ง | AH10: P7 | AI10: 2 | AJ10: 45813 | AK10: 0 | AL10: 45804 | AM10: 45811 | AN10: 45812 | AO10: 45812 | AP10: 45808 | AQ10: 0 | AR10: 0 | AS10: 0 | AT10: 0 | AU10: 0 | AV10: 0 | AW10: งานพิมพ์ | AX10: รอART | AY10: 0 | AZ10: 0 | BA10: 0 | BB10: 0 | BC10: WRWT25800/WRWT25800 | BD10: 0
