Workbook

Sheet Linkสูตรออร์เดอร์  (2)
B2: เรียงกำหนดส่ง | D2: ลบ 0 | T2: เรียง 1
B3: ข้อมูลUpdate ณ. วันที่ | D3: 45969 | E3: เวลา | G3: 9.19
A4: วันรับออร์เดอร์/แบบ | B4: เลขที่ SO | C4: ชื่อลูกค้า | E4: 10.3 | I4: น้ำหนัก | L4: บิด/จับจีบ | M4: ถุงใน | Q4: =[1]หน้าผ้า!$AC$13 -> 44873 | S4: วิธีบรรจุ | T4: วันส่ง | U4: จำนวนส่ง | V4: ตัดเย็บ (ใบ) | W4: =[1]หน้าผ้า!$AJ$13 -> 44873 | X4: พิมพ์ (ใบ) | Y4: =[1]หน้าผ้า!$AM$13 -> 44876 | Z4: ผ้าทอ (เมตร) Updateณ | AB4: =[1]หน้าผ้า!$AR$12 -> 44876 | AD4: ผ้าเคลือบ(เมตร) | AF4: หมายเหตุ | AG4: เครื่อง
B5: เลขที่ SO | C5: ชื่อลูกค้า | D5: ตรา | E5: กว้าง | F5: ยาว | G5: สี | H5: เคลือบ | I5: กรัม/ใบ | J5: * | K5: aw | L5: บิด/จับจีบ | M5: กว้าง | N5: ยาว | O5: หนา | P5: ใช้(กก.) | Q5: Stock(กก.) | R5: ผลิต(กก.) | S5: วิธีบรรจุ | T5: วันส่ง | U5: จำนวนส่ง | V5: StockFG | W5: ค้างตัด | X5: พิมพ์แล้ว | Y5: ค้างพิมพ์ | Z5: ประเภท | AA5: ใช้ | AB5: Stock | AC5: ค้างทอ | AD5: Stock | AE5: ค้างเคลือบ | AF5: หมายเหตุ | AG5: ที่พิมพ์ได้ | AH5: process | AI5: Lead time | AJ5: วันที่ส่งPL | AK5: เคลือบ | AL5: ได้ ART | AM5: พิมพ์ | AN5: จีบ-บิด | AO5: ตัด-เย็บ | AP5: ทอ | AQ5: สวมถุง | AR5: เย็บปาก | AS5: PT | AT5: ม้วน | AU5: ตัด | AV5: ตอกตาไก่ | AW5: GROUP | AX5: ART | AY5: หมายเหตุปัญหา | AZ5: ราคา/ใบ | BA5: ราคารวม | BB5: workweek | BC5: เส้นเทป | BD5: จำนวน
A6: =[2]หน้าผ้า!C15 -> 0 | B6: =[2]หน้าผ้า!B15 -> 0 | C6: =[2]หน้าผ้า!E15 -> 0 | D6: =[2]หน้าผ้า!F15 -> 0 | E6: =[2]หน้าผ้า!G15 -> 12 | F6: =[2]หน้าผ้า!H15 -> 16 | G6: =[2]หน้าผ้า!I15 -> ขาว | H6: =[2]หน้าผ้า!J15 -> 0 | I6: =[2]หน้าผ้า!L15 -> 25 | J6: =[2]หน้าผ้า!M15 -> ± | K6: =[2]หน้าผ้า!N15 -> 5 | L6: =[2]หน้าผ้า!R15 -> 0 | M6: =[2]หน้าผ้า!T15 -> 0 | N6: =[2]หน้าผ้า!U15 -> 0 | O6: =[2]หน้าผ้า!V15 -> 0 | P6: =[2]หน้าผ้า!AB15 -> 0 | Q6: =[2]หน้าผ้า!AC15 -> 0 | R6: =[2]หน้าผ้า!AD15 -> 0 | S6: =[2]หน้าผ้า!Z15 -> 0 | T6: =[2]หน้าผ้า!X15 -> 0 | U6: =[2]หน้าผ้า!AA15 -> 0 | V6: =[2]หน้าผ้า!AJ15 -> 0 | W6: =[2]หน้าผ้า!AL15 -> 0 | X6: =[2]หน้าผ้า!AM15 -> 0 | Y6: =[2]หน้าผ้า!AN15 -> 0 | Z6: =[2]หน้าผ้า!AO15 -> WSWT1221750 | AA6: =[2]หน้าผ้า!AQ15 -> #REF! | AB6: =[2]หน้าผ้า!AR15 -> #REF! | AC6: =[2]หน้าผ้า!AS15 -> #REF! | AD6: =[2]หน้าผ้า!AT15 -> #REF! | AE6: =[2]หน้าผ้า!AU15 -> #REF! | AF6: =[2]หน้าผ้า!AI15 -> ระบุในSD | AG6: =[3]หน้าผ้า!DC18 -> < Ord 20,000 | AH6: =[2]หน้าผ้า!DL15 -> 0 | AI6: =[2]หน้าผ้า!DM15 -> 0 | AJ6: =[2]หน้าผ้า!DN15 -> 0 | AK6: =[2]หน้าผ้า!DQ15 -> 0 | AL6: =[2]หน้าผ้า!DR15 -> 0 | AM6: =[2]หน้าผ้า!DS15 -> 0 | AN6: =[2]หน้าผ้า!DT15 -> 0 | AO6: =[2]หน้าผ้า!DU15 -> 0 | AP6: =[2]หน้าผ้า!DP15 -> 0 | AQ6: =[2]หน้าผ้า!DW15 -> 0 | AR6: =[2]หน้าผ้า!DX15 -> 0 | AS6: =[2]หน้าผ้า!DY15 -> 0 | AT6: =[2]หน้าผ้า!DZ15 -> 0 | AU6: =[2]หน้าผ้า!EA15 -> 0 | AV6: =[2]หน้าผ้า!EB15 -> 0 | AW6: =[2]หน้าผ้า!EC15 -> 0 | AX6: =[2]หน้าผ้า!ED15 -> 0 | AY6: =[2]หน้าผ้า!AG15 -> 0 | AZ6: =[2]หน้าผ้า!EG15 -> 0 | BA6: =[2]หน้าผ้า!EH15 -> 0 | BB6: =[2]หน้าผ้า!EI15 -> 0 | BC6: =[2]หน้าผ้า!BZ15 -> WRWT120750/WRWT21750 | BD6: =[2]หน้าผ้า!CA15 -> 0
A7: =[2]หน้าผ้า!C16 -> 0 | B7: =[2]หน้าผ้า!B16 -> 0 | C7: =[2]หน้าผ้า!E16 -> 0 | D7: =[2]หน้าผ้า!F16 -> 0 | E7: =[2]หน้าผ้า!G16 -> 14 | F7: =[2]หน้าผ้า!H16 -> 22 | G7: =[2]หน้าผ้า!I16 -> ขาว | H7: =[2]หน้าผ้า!J16 -> 0 | I7: =[2]หน้าผ้า!L16 -> 36 | J7: =[2]หน้าผ้า!M16 -> ± | K7: =[2]หน้าผ้า!N16 -> 5 | L7: =[2]หน้าผ้า!R16 -> 0 | M7: =[2]หน้าผ้า!T16 -> 0 | N7: =[2]หน้าผ้า!U16 -> 0 | O7: =[2]หน้าผ้า!V16 -> 0 | P7: =[2]หน้าผ้า!AB16 -> 0 | Q7: =[2]หน้าผ้า!AC16 -> 0 | R7: =[2]หน้าผ้า!AD16 -> 0 | S7: =[2]หน้าผ้า!Z16 -> 0 | T7: =[2]หน้าผ้า!X16 -> 0 | U7: =[2]หน้าผ้า!AA16 -> 0 | V7: =[2]หน้าผ้า!AJ16 -> 0 | W7: =[2]หน้าผ้า!AL16 -> 0 | X7: =[2]หน้าผ้า!AM16 -> 0 | Y7: =[2]หน้าผ้า!AN16 -> 0 | Z7: =[2]หน้าผ้า!AO16 -> WSWT1425800 | AA7: =[2]หน้าผ้า!AQ16 -> #REF! | AB7: =[2]หน้าผ้า!AR16 -> #REF! | AC7: =[2]หน้าผ้า!AS16 -> #REF! | AD7: =[2]หน้าผ้า!AT16 -> #REF! | AE7: =[2]หน้าผ้า!AU16 -> #REF! | AF7: =[2]หน้าผ้า!AI16 -> ระบุในSD | AG7: =[3]หน้าผ้า!DC19 -> พร้อมส่ง | AH7: =[2]หน้าผ้า!DL16 -> 0 | AI7: =[2]หน้าผ้า!DM16 -> Lead time | AJ7: =[2]หน้าผ้า!DN16 -> 0 | AK7: =[2]หน้าผ้า!DQ16 -> 0 | AL7: =[2]หน้าผ้า!DR16 -> 0 | AM7: =[2]หน้าผ้า!DS16 -> 0 | AN7: =[2]หน้าผ้า!DT16 -> 0 | AO7: =[2]หน้าผ้า!DU16 -> 0 | AP7: =[2]หน้าผ้า!DP16 -> 0 | AQ7: =[2]หน้าผ้า!DW16 -> 0 | AR7: =[2]หน้าผ้า!DX16 -> 0 | AS7: =[2]หน้าผ้า!DY16 -> 0 | AT7: =[2]หน้าผ้า!DZ16 -> 0 | AU7: =[2]หน้าผ้า!EA16 -> 0 | AV7: =[2]หน้าผ้า!EB16 -> 0 | AW7: =[2]หน้าผ้า!EC16 -> 0 | AX7: =[2]หน้าผ้า!ED16 -> 0 | AY7: =[2]หน้าผ้า!AG16 -> 0 | AZ7: =[2]หน้าผ้า!EG16 -> 0 | BA7: =[2]หน้าผ้า!EH16 -> 0 | BB7: =[2]หน้าผ้า!EI16 -> 0 | BC7: =[2]หน้าผ้า!BZ16 -> WRWT140800/WRWT25800 | BD7: =[2]หน้าผ้า!CA16 -> 0
A8: =[2]หน้าผ้า!C17 -> 0 | B8: =[2]หน้าผ้า!B17 -> 0 | C8: =[2]หน้าผ้า!E17 -> 0 | D8: =[2]หน้าผ้า!F17 | E8: =[2]หน้าผ้า!G17 -> 16 | F8: =[2]หน้าผ้า!H17 -> 25 | G8: =[2]หน้าผ้า!I17 -> ขาว | H8: =[2]หน้าผ้า!J17 -> 0 | I8: =[2]หน้าผ้า!L17 -> 45 | J8: =[2]หน้าผ้า!M17 -> ± | K8: =[2]หน้าผ้า!N17 -> 5 | L8: =[2]หน้าผ้า!R17 -> 0 | M8: =[2]หน้าผ้า!T17 -> 0 | N8: =[2]หน้าผ้า!U17 -> 0 | O8: =[2]หน้าผ้า!V17 -> 0 | P8: =[2]หน้าผ้า!AB17 -> 0 | Q8: =[2]หน้าผ้า!AC17 -> 0 | R8: =[2]หน้าผ้า!AD17 -> 0 | S8: =[2]หน้าผ้า!Z17 -> 0 | T8: =[2]หน้าผ้า!X17 -> 0 | U8: =[2]หน้าผ้า!AA17 -> 0 | V8: =[2]หน้าผ้า!AJ17 -> 0 | W8: =[2]หน้าผ้า!AL17 -> 0 | X8: =[2]หน้าผ้า!AM17 -> 0 | Y8: =[2]หน้าผ้า!AN17 -> 0 | Z8: =[2]หน้าผ้า!AO17 -> WSWT1625800SM | AA8: =[2]หน้าผ้า!AQ17 -> #REF! | AB8: =[2]หน้าผ้า!AR17 -> #REF! | AC8: =[2]หน้าผ้า!AS17 -> #REF! | AD8: =[2]หน้าผ้า!AT17 -> #REF! | AE8: =[2]หน้าผ้า!AU17 -> #REF! | AF8: =[2]หน้าผ้า!AI17 -> ระบุในSD | AG8: =[3]หน้าผ้า!DC20 -> พร้อมส่ง | AH8: =[2]หน้าผ้า!DL17 -> 0 | AI8: =[2]หน้าผ้า!DM17 -> Lead time | AJ8: =[2]หน้าผ้า!DN17 -> 0 | AK8: =[2]หน้าผ้า!DQ17 -> 0 | AL8: =[2]หน้าผ้า!DR17 -> 0 | AM8: =[2]หน้าผ้า!DS17 -> 0 | AN8: =[2]หน้าผ้า!DT17 -> 0 | AO8: =[2]หน้าผ้า!DU17 -> 0 | AP8: =[2]หน้าผ้า!DP17 -> 0 | AQ8: =[2]หน้าผ้า!DW17 -> 0 | AR8: =[2]หน้าผ้า!DX17 -> 0 | AS8: =[2]หน้าผ้า!DY17 -> 0 | AT8: =[2]หน้าผ้า!DZ17 -> 0 | AU8: =[2]หน้าผ้า!EA17 -> 0 | AV8: =[2]หน้าผ้า!EB17 -> 0 | AW8: =[2]หน้าผ้า!EC17 -> 0 | AX8: =[2]หน้าผ้า!ED17 -> 0 | AY8: =[2]หน้าผ้า!AG17 -> 0 | AZ8: =[2]หน้าผ้า!EG17 -> 0 | BA8: =[2]หน้าผ้า!EH17 -> 0 | BB8: =[2]หน้าผ้า!EI17 -> 0 | BC8: =[2]หน้าผ้า!BZ17 -> WRWT160800/WRWT25800 | BD8: =[2]หน้าผ้า!CA17 -> 0
A9: =[2]หน้าผ้า!C18 -> ประมาณการ | B9: =[2]หน้าผ้า!B18 -> ประมาณการ | C9: =[2]หน้าผ้า!E18 -> บจก.เคอรี่ฟลาวมิลล์ | D9: =[2]หน้าผ้า!F18 -> โบว์แดง 10กก | E9: =[2]หน้าผ้า!G18 -> 16 | F9: =[2]หน้าผ้า!H18 -> 25 | G9: =[2]หน้าผ้า!I18 -> ขาว | H9: =[2]หน้าผ้า!J18 -> 0 | I9: =[2]หน้าผ้า!L18 -> 45 | J9: =[2]หน้าผ้า!M18 -> ± | K9: =[2]หน้าผ้า!N18 -> 5 | L9: =[2]หน้าผ้า!R18 -> ไม่ | M9: =[2]หน้าผ้า!T18 -> ไม่สวมถุงใน | N9: =[2]หน้าผ้า!U18 -> 0 | O9: =[2]หน้าผ้า!V18 -> 0 | P9: =[2]หน้าผ้า!AB18 -> 0 | Q9: =[2]หน้าผ้า!AC18 -> 0 | R9: =[2]หน้าผ้า!AD18 -> 0 | S9: =[2]หน้าผ้า!Z18 -> ห่ออัดเบลแบน500 | T9: =[2]หน้าผ้า!X18 -> รอแจ้ง | U9: =[2]หน้าผ้า!AA18 -> 5000 | V9: =[2]หน้าผ้า!AJ18 -> 5333 | W9: =[2]หน้าผ้า!AL18 -> 0 | X9: =[2]หน้าผ้า!AM18 -> 5370 | Y9: =[2]หน้าผ้า!AN18 -> 0 | Z9: =[2]หน้าผ้า!AO18 -> WSWT1625800 | AA9: =[2]หน้าผ้า!AQ18 -> 0 | AB9: =[2]หน้าผ้า!AR18 -> 0 | AC9: =[2]หน้าผ้า!AS18 -> 0 | AD9: =[2]หน้าผ้า!AT18 -> 0 | AE9: =[2]หน้าผ้า!AU18 -> 0 | AF9: =[2]หน้าผ้า!AI18 -> 0 | AG9: =[3]หน้าผ้า!DC21 -> ยังไม่ได้พิมพ์ | AH9: =[2]หน้าผ้า!DL18 -> P7 | AI9: =[2]หน้าผ้า!DM18 -> 2 | AJ9: =[2]หน้าผ้า!DN18 -> รอแจ้ง | AK9: =[2]หน้าผ้า!DQ18 -> 0 | AL9: =[2]หน้าผ้า!DR18 -> #VALUE! | AM9: =[2]หน้าผ้า!DS18 -> #VALUE! | AN9: =[2]หน้าผ้า!DT18 -> #VALUE! | AO9: =[2]หน้าผ้า!DU18 -> #VALUE! | AP9: =[2]หน้าผ้า!DP18 -> #VALUE! | AQ9: =[2]หน้าผ้า!DW18 -> 0 | AR9: =[2]หน้าผ้า!DX18 -> 0 | AS9: =[2]หน้าผ้า!DY18 -> 0 | AT9: =[2]หน้าผ้า!DZ18 -> 0 | AU9: =[2]หน้าผ้า!EA18 -> 0 | AV9: =[2]หน้าผ้า!EB18 -> 0 | AW9: =[2]หน้าผ้า!EC18 -> งานพิมพ์ | AX9: =[2]หน้าผ้า!ED18 -> / | AY9: =[2]หน้าผ้า!AG18 -> รอเก็บลบสีผสม | AZ9: =[2]หน้าผ้า!EG18 -> 0 | BA9: =[2]หน้าผ้า!EH18 -> 0 | BB9: =[2]หน้าผ้า!EI18 -> 0 | BC9: =[2]หน้าผ้า!BZ18 -> WRWT25800/WRWT25800 | BD9: =[2]หน้าผ้า!CA18 -> 0
A10: =[2]หน้าผ้า!C19 -> 0 | B10: =[2]หน้าผ้า!B19 -> 0 | C10: =[2]หน้าผ้า!E19 -> 0 | D10: =[2]หน้าผ้า!F19 -> 0 | E10: =[2]หน้าผ้า!G19 -> 16 | F10: =[2]หน้าผ้า!H19 -> 25 | G10: =[2]หน้าผ้า!I19 -> ขาว | H10: =[2]หน้าผ้า!J19 -> 0 | I10: =[2]หน้าผ้า!L19 -> 45 | J10: =[2]หน้าผ้า!M19 -> ± | K10: =[2]หน้าผ้า!N19 -> 5 | L10: =[2]หน้าผ้า!R19 -> 0 | M10: =[2]หน้าผ้า!T19 -> 0 | N10: =[2]หน้าผ้า!U19 -> 0 | O10: =[2]หน้าผ้า!V19 -> 0 | P10: =[2]หน้าผ้า!AB19 -> 0 | Q10: =[2]หน้าผ้า!AC19 -> 0 | R10: =[2]หน้าผ้า!AD19 -> 0 | S10: =[2]หน้าผ้า!Z19 -> 0 | T10: =[2]หน้าผ้า!X19 -> 0 | U10: =[2]หน้าผ้า!AA19 -> 0 | V10: =[2]หน้าผ้า!AJ19 -> 0 | W10: =[2]หน้าผ้า!AL19 -> 0 | X10: =[2]หน้าผ้า!AM19 -> 0 | Y10: =[2]หน้าผ้า!AN19 -> 0 | Z10: =[2]หน้าผ้า!AO19 -> WSWT1625800 | AA10: =[2]หน้าผ้า!AQ19 -> 0 | AB10: =[2]หน้าผ้า!AR19 -> 0 | AC10: =[2]หน้าผ้า!AS19 -> 0 | AD10: =[2]หน้าผ้า!AT19 -> 0 | AE10: =[2]หน้าผ้า!AU19 -> 0 | AF10: =[2]หน้าผ้า!AI19 -> ระบุในSD | AG10: =[3]หน้าผ้า!DC22 -> พร้อมส่ง | AH10: =[2]หน้าผ้า!DL19 -> 0 | AI10: =[2]หน้าผ้า!DM19 -> Lead time | AJ10: =[2]หน้าผ้า!DN19 -> 0 | AK10: =[2]หน้าผ้า!DQ19 -> 0 | AL10: =[2]หน้าผ้า!DR19 -> 0 | AM10: =[2]หน้าผ้า!DS19 -> 0 | AN10: =[2]หน้าผ้า!DT19 -> 0 | AO10: =[2]หน้าผ้า!DU19 -> 0 | AP10: =[2]หน้าผ้า!DP19 -> 0 | AQ10: =[2]หน้าผ้า!DW19 -> 0 | AR10: =[2]หน้าผ้า!DX19 -> 0 | AS10: =[2]หน้าผ้า!DY19 -> 0 | AT10: =[2]หน้าผ้า!DZ19 -> 0 | AU10: =[2]หน้าผ้า!EA19 -> 0 | AV10: =[2]หน้าผ้า!EB19 -> 0 | AW10: =[2]หน้าผ้า!EC19 -> 0 | AX10: =[2]หน้าผ้า!ED19 -> 0 | AY10: =[2]หน้าผ้า!AG19 -> 0 | AZ10: =[2]หน้าผ้า!EG19 -> 0 | BA10: =[2]หน้าผ้า!EH19 -> 0 | BB10: =[2]หน้าผ้า!EI19 -> 0 | BC10: =[2]หน้าผ้า!BZ19 -> WRWT160800/WRWT25800 | BD10: =[2]หน้าผ้า!CA19 -> 0
A11: =[2]หน้าผ้า!C20 -> 0 | B11: =[2]หน้าผ้า!B20 -> 0 | C11: =[2]หน้าผ้า!E20 -> 0 | D11: =[2]หน้าผ้า!F20 -> 0 | E11: =[2]หน้าผ้า!G20 -> 16 | F11: =[2]หน้าผ้า!H20 -> 25 | G11: =[2]หน้าผ้า!I20 -> 0 | H11: =[2]หน้าผ้า!J20 -> 0 | I11: =[2]หน้าผ้า!L20 -> 47 | J11: =[2]หน้าผ้า!M20 -> ± | K11: =[2]หน้าผ้า!N20 -> 5 | L11: =[2]หน้าผ้า!R20 -> 0 | M11: =[2]หน้าผ้า!T20 -> 0 | N11: =[2]หน้าผ้า!U20 -> 0 | O11: =[2]หน้าผ้า!V20 -> 0 | P11: =[2]หน้าผ้า!AB20 -> 0 | Q11: =[2]หน้าผ้า!AC20 -> 0 | R11: =[2]หน้าผ้า!AD20 -> 0 | S11: =[2]หน้าผ้า!Z20 -> 0 | T11: =[2]หน้าผ้า!X20 -> 0 | U11: =[2]หน้าผ้า!AA20 -> 0 | V11: =[2]หน้าผ้า!AJ20 -> 0 | W11: =[2]หน้าผ้า!AL20 -> 0 | X11: =[2]หน้าผ้า!AM20 -> 0 | Y11: =[2]หน้าผ้า!AN20 -> 0 | Z11: =[2]หน้าผ้า!AO20 -> WSWT1621720SMFX | AA11: =[2]หน้าผ้า!AQ20 -> #REF! | AB11: =[2]หน้าผ้า!AR20 -> #REF! | AC11: =[2]หน้าผ้า!AS20 -> #REF! | AD11: =[2]หน้าผ้า!AT20 -> #REF! | AE11: =[2]หน้าผ้า!AU20 -> #REF! | AF11: =[2]หน้าผ้า!AI20 -> ระบุในSD | AG11: =[3]หน้าผ้า!DC23 -> พร้อมส่ง | AH11: =[2]หน้าผ้า!DL20 -> 0 | AI11: =[2]หน้าผ้า!DM20 -> 0 | AJ11: =[2]หน้าผ้า!DN20 -> 0 | AK11: =[2]หน้าผ้า!DQ20 -> 0 | AL11: =[2]หน้าผ้า!DR20 -> 0 | AM11: =[2]หน้าผ้า!DS20 -> 0 | AN11: =[2]หน้าผ้า!DT20 -> 0 | AO11: =[2]หน้าผ้า!DU20 -> 0 | AP11: =[2]หน้าผ้า!DP20 -> 0 | AQ11: =[2]หน้าผ้า!DW20 -> 0 | AR11: =[2]หน้าผ้า!DX20 -> 0 | AS11: =[2]หน้าผ้า!DY20 -> 0 | AT11: =[2]หน้าผ้า!DZ20 -> 0 | AU11: =[2]หน้าผ้า!EA20 -> 0 | AV11: =[2]หน้าผ้า!EB20 -> 0 | AW11: =[2]หน้าผ้า!EC20 -> 0 | AX11: =[2]หน้าผ้า!ED20 -> 0 | AY11: =[2]หน้าผ้า!AG20 -> 0 | AZ11: =[2]หน้าผ้า!EG20 -> 0 | BA11: =[2]หน้าผ้า!EH20 -> 0 | BB11: =[2]หน้าผ้า!EI20 -> 0 | BC11: =[2]หน้าผ้า!BZ20 -> WRWT160720/WRWT21720 | BD11: =[2]หน้าผ้า!CA20 -> 0
A12: =[2]หน้าผ้า!C21 -> 0 | B12: =[2]หน้าผ้า!B21 -> ใบรับคำสั่งซื้อ | C12: =[2]หน้าผ้า!E21 -> โรงสีข้าวธัญญาวัฒน์ | D12: =[2]หน้าผ้า!F21 -> LUNG SHIN 12kg | E12: =[2]หน้าผ้า!G21 -> 17 | F12: =[2]หน้าผ้า!H21 -> 26 | G12: =[2]หน้าผ้า!I21 -> ขาว | H12: =[2]หน้าผ้า!J21 -> 0 | I12: =[2]หน้าผ้า!L21 -> 48 | J12: =[2]หน้าผ้า!M21 -> ± | K12: =[2]หน้าผ้า!N21 -> 5 | L12: =[2]หน้าผ้า!R21 -> ไม่ | M12: =[2]หน้าผ้า!T21 -> ไม่สวมถุงใน | N12: =[2]หน้าผ้า!U21 -> 0 | O12: =[2]หน้าผ้า!V21 -> 0 | P12: =[2]หน้าผ้า!AB21 -> 0 | Q12: =[2]หน้าผ้า!AC21 -> 0 | R12: =[2]หน้าผ้า!AD21 -> 0 | S12: =[2]หน้าผ้า!Z21 -> 500กระสอบแบน | T12: =[2]หน้าผ้า!X21 -> 45980 | U12: =[2]หน้าผ้า!AA21 -> 12100 | V12: =[2]หน้าผ้า!AJ21 -> 0 | W12: =[2]หน้าผ้า!AL21 -> 12100 | X12: =[2]หน้าผ้า!AM21 -> 0 | Y12: =[2]หน้าผ้า!AN21 -> 12705 | Z12: =[2]หน้าผ้า!AO21 -> WSWT1725800 | AA12: =[2]หน้าผ้า!AQ21 -> 9297.035 | AB12: =[2]หน้าผ้า!AR21 -> 0 | AC12: =[2]หน้าผ้า!AS21 -> 9297.035 | AD12: =[2]หน้าผ้า!AT21 -> 0 | AE12: =[2]หน้าผ้า!AU21 -> 0 | AF12: =[2]หน้าผ้า!AI21 -> 0 | AG12: =[3]หน้าผ้า!DC24 -> พร้อมส่ง | AH12: =[2]หน้าผ้า!DL21 -> P7 | AI12: =[2]หน้าผ้า!DM21 -> 2 | AJ12: =[2]หน้าผ้า!DN21 -> 45980 | AK12: =[2]หน้าผ้า!DQ21 -> 0 | AL12: =[2]หน้าผ้า!DR21 -> 45971 | AM12: =[2]หน้าผ้า!DS21 -> 45978 | AN12: =[2]หน้าผ้า!DT21 -> 45979 | AO12: =[2]หน้าผ้า!DU21 -> 45979 | AP12: =[2]หน้าผ้า!DP21 -> 45975 | AQ12: =[2]หน้าผ้า!DW21 -> 0 | AR12: =[2]หน้าผ้า!DX21 -> 0 | AS12: =[2]หน้าผ้า!DY21 -> 0 | AT12: =[2]หน้าผ้า!DZ21 -> 0 | AU12: =[2]หน้าผ้า!EA21 -> 0 | AV12: =[2]หน้าผ้า!EB21 -> 0 | AW12: =[2]หน้าผ้า!EC21 -> งานพิมพ์ | AX12: =[2]หน้าผ้า!ED21 -> รอART | AY12: =[2]หน้าผ้า!AG21 -> 0 | AZ12: =[2]หน้าผ้า!EG21 -> 0 | BA12: =[2]หน้าผ้า!EH21 -> 0 | BB12: =[2]หน้าผ้า!EI21 -> 0 | BC12: =[2]หน้าผ้า!BZ21 -> WRWT25800/WRWT25800 | BD12: =[2]หน้าผ้า!CA21 -> 604.10067
A13: =[2]หน้าผ้า!C22 -> 0 | B13: =[2]หน้าผ้า!B22 -> 0 | C13: =[2]หน้าผ้า!E22 -> 0 | D13: =[2]หน้าผ้า!F22 -> 0 | E13: =[2]หน้าผ้า!G22 -> 17 | F13: =[2]หน้าผ้า!H22 -> 26 | G13: =[2]หน้าผ้า!I22 -> 0 | H13: =[2]หน้าผ้า!J22 -> 0 | I13: =[2]หน้าผ้า!L22 -> 48 | J13: =[2]หน้าผ้า!M22 -> ± | K13: =[2]หน้าผ้า!N22 -> 5 | L13: =[2]หน้าผ้า!R22 -> 0 | M13: =[2]หน้าผ้า!T22 -> 0 | N13: =[2]หน้าผ้า!U22 -> 0 | O13: =[2]หน้าผ้า!V22 -> 0 | P13: =[2]หน้าผ้า!AB22 -> 0 | Q13: =[2]หน้าผ้า!AC22 -> 0 | R13: =[2]หน้าผ้า!AD22 -> 0 | S13: =[2]หน้าผ้า!Z22 -> 0 | T13: =[2]หน้าผ้า!X22 -> 0 | U13: =[2]หน้าผ้า!AA22 -> 0 | V13: =[2]หน้าผ้า!AJ22 -> 0 | W13: =[2]หน้าผ้า!AL22 -> 0 | X13: =[2]หน้าผ้า!AM22 -> 0 | Y13: =[2]หน้าผ้า!AN22 -> 0 | Z13: =[2]หน้าผ้า!AO22 -> WSWT1725800 | AA13: =[2]หน้าผ้า!AQ22 -> 9297.035 | AB13: =[2]หน้าผ้า!AR22 -> 0 | AC13: =[2]หน้าผ้า!AS22 -> 9297.035 | AD13: =[2]หน้าผ้า!AT22 -> 0 | AE13: =[2]หน้าผ้า!AU22 -> 0 | AF13: =[2]หน้าผ้า!AI22 -> ระบุในSD | AG13: =[3]หน้าผ้า!DC25 -> ผ้าขาว | AH13: =[2]หน้าผ้า!DL22 -> 0 | AI13: =[2]หน้าผ้า!DM22 -> 0 | AJ13: =[2]หน้าผ้า!DN22 -> 0 | AK13: =[2]หน้าผ้า!DQ22 -> 0 | AL13: =[2]หน้าผ้า!DR22 -> 0 | AM13: =[2]หน้าผ้า!DS22 -> 0 | AN13: =[2]หน้าผ้า!DT22 -> 0 | AO13: =[2]หน้าผ้า!DU22 -> 0 | AP13: =[2]หน้าผ้า!DP22 -> 0 | AQ13: =[2]หน้าผ้า!DW22 -> 0 | AR13: =[2]หน้าผ้า!DX22 -> 0 | AS13: =[2]หน้าผ้า!DY22 -> 0 | AT13: =[2]หน้าผ้า!DZ22 -> 0 | AU13: =[2]หน้าผ้า!EA22 -> 0 | AV13: =[2]หน้าผ้า!EB22 -> 0 | AW13: =[2]หน้าผ้า!EC22 -> 0 | AX13: =[2]หน้าผ้า!ED22 -> 0 | AY13: =[2]หน้าผ้า!AG22 -> 0 | AZ13: =[2]หน้าผ้า!EG22 -> 0 | BA13: =[2]หน้าผ้า!EH22 -> 0 | BB13: =[2]หน้าผ้า!EI22 -> 0 | BC13: =[2]หน้าผ้า!BZ22 -> WRWT170800/WRWT25800 | BD13: =[2]หน้าผ้า!CA22 -> 0
A14: =[2]หน้าผ้า!C23 -> 45950 | B14: =[2]หน้าผ้า!B23 -> MK68-001247 | C14: =[2]หน้าผ้า!E23 -> บจก.ฟาเธอร์ส วิง ซัพพลาย | D14: =[2]หน้าผ้า!F23 -> รถไฟฟ้า | E14: =[2]หน้าผ้า!G23 -> 18 | F14: =[2]หน้าผ้า!H23 -> 30 | G14: =[2]หน้าผ้า!I23 -> ขาว | H14: =[2]หน้าผ้า!J23 -> 0 | I14: =[2]หน้าผ้า!L23 -> 54 | J14: =[2]หน้าผ้า!M23 -> ± | K14: =[2]หน้าผ้า!N23 -> 5 | L14: =[2]หน้าผ้า!R23 -> บิด | M14: =[2]หน้าผ้า!T23 -> 19 | N14: =[2]หน้าผ้า!U23 -> 33 | O14: =[2]หน้าผ้า!V23 -> 40 | P14: =[2]หน้าผ้า!AB23 -> 0 | Q14: =[2]หน้าผ้า!AC23 -> 0 | R14: =[2]หน้าผ้า!AD23 -> 0 | S14: =[2]หน้าผ้า!Z23 -> 500กระสอบ | T14: =[2]หน้าผ้า!X23 -> 45968 | U14: =[2]หน้าผ้า!AA23 -> 5000 | V14: =[2]หน้าผ้า!AJ23 -> 5000 | W14: =[2]หน้าผ้า!AL23 -> 0 | X14: =[2]หน้าผ้า!AM23 -> 5400 | Y14: =[2]หน้าผ้า!AN23 -> 0 | Z14: =[2]หน้าผ้า!AO23 -> WSWT1825800 | AA14: =[2]หน้าผ้า!AQ23 -> 0 | AB14: =[2]หน้าผ้า!AR23 -> 0 | AC14: =[2]หน้าผ้า!AS23 -> 0 | AD14: =[2]หน้าผ้า!AT23 -> 0 | AE14: =[2]หน้าผ้า!AU23 -> 0 | AF14: =[2]หน้าผ้า!AI23 -> 0 | AG14: =[3]หน้าผ้า!DC26 -> ยังไม่ได้พิมพ์ | AH14: =[2]หน้าผ้า!DL23 -> P9 | AI14: =[2]หน้าผ้า!DM23 -> 3 | AJ14: =[2]หน้าผ้า!DN23 -> 45968 | AK14: =[2]หน้าผ้า!DQ23 -> 0 | AL14: =[2]หน้าผ้า!DR23 -> 45958 | AM14: =[2]หน้าผ้า!DS23 -> 45965 | AN14: =[2]หน้าผ้า!DT23 -> 45966 | AO14: =[2]หน้าผ้า!DU23 -> 45966 | AP14: =[2]หน้าผ้า!DP23 -> 45963 | AQ14: =[2]หน้าผ้า!DW23 -> 45967 | AR14: =[2]หน้าผ้า!DX23 -> 0 | AS14: =[2]หน้าผ้า!DY23 -> 0 | AT14: =[2]หน้าผ้า!DZ23 -> 0 | AU14: =[2]หน้าผ้า!EA23 -> 0 | AV14: =[2]หน้าผ้า!EB23 -> 0 | AW14: =[2]หน้าผ้า!EC23 -> งานพิมพ์ | AX14: =[2]หน้าผ้า!ED23 -> / | AY14: =[2]หน้าผ้า!AG23 -> รอส่ง ลูกค้ารับเอง | AZ14: =[2]หน้าผ้า!EG23 -> 0 | BA14: =[2]หน้าผ้า!EH23 -> 0 | BB14: =[2]หน้าผ้า!EI23 -> 0 | BC14: =[2]หน้าผ้า!BZ23 -> WRWT25800/WRWT25800 | BD14: =[2]หน้าผ้า!CA23 -> 0
A15: =[2]หน้าผ้า!C24 -> 45950 | B15: =[2]หน้าผ้า!B24 -> MK68-001247 | C15: =[2]หน้าผ้า!E24 -> บจก.ฟาเธอร์ส วิง ซัพพลาย | D15: =[2]หน้าผ้า!F24 -> รถไฟฟ้าปูนขาวเย็น | E15: =[2]หน้าผ้า!G24 -> 18 | F15: =[2]หน้าผ้า!H24 -> 30 | G15: =[2]หน้าผ้า!I24 -> ขาว | H15: =[2]หน้าผ้า!J24 -> 0 | I15: =[2]หน้าผ้า!L24 -> 54 | J15: =[2]หน้าผ้า!M24 -> ± | K15: =[2]หน้าผ้า!N24 -> 5 | L15: =[2]หน้าผ้า!R24 -> บิด | M15: =[2]หน้าผ้า!T24 -> 19 | N15: =[2]หน้าผ้า!U24 -> 33 | O15: =[2]หน้าผ้า!V24 -> 40 | P15: =[2]หน้าผ้า!AB24 -> 0 | Q15: =[2]หน้าผ้า!AC24 -> 0 | R15: =[2]หน้าผ้า!AD24 -> 0 | S15: =[2]หน้าผ้า!Z24 -> 500กระสอบ | T15: =[2]หน้าผ้า!X24 -> 45968 | U15: =[2]หน้าผ้า!AA24 -> 20000 | V15: =[2]หน้าผ้า!AJ24 -> 20057 | W15: =[2]หน้าผ้า!AL24 -> 0 | X15: =[2]หน้าผ้า!AM24 -> 20800 | Y15: =[2]หน้าผ้า!AN24 -> 0 | Z15: =[2]หน้าผ้า!AO24 -> WSWT1825800 | AA15: =[2]หน้าผ้า!AQ24 -> 0 | AB15: =[2]หน้าผ้า!AR24 -> 0 | AC15: =[2]หน้าผ้า!AS24 -> 0 | AD15: =[2]หน้าผ้า!AT24 -> 0 | AE15: =[2]หน้าผ้า!AU24 -> 0 | AF15: =[2]หน้าผ้า!AI24 -> 0 | AG15: =[3]หน้าผ้า!DC27 -> พร้อมส่ง | AH15: =[2]หน้าผ้า!DL24 -> P9 | AI15: =[2]หน้าผ้า!DM24 -> 3 | AJ15: =[2]หน้าผ้า!DN24 -> 45968 | AK15: =[2]หน้าผ้า!DQ24 -> 0 | AL15: =[2]หน้าผ้า!DR24 -> 45958 | AM15: =[2]หน้าผ้า!DS24 -> 45965 | AN15: =[2]หน้าผ้า!DT24 -> 45966 | AO15: =[2]หน้าผ้า!DU24 -> 45966 | AP15: =[2]หน้าผ้า!DP24 -> 45963 | AQ15: =[2]หน้าผ้า!DW24 -> 45967 | AR15: =[2]หน้าผ้า!DX24 -> 0 | AS15: =[2]หน้าผ้า!DY24 -> 0 | AT15: =[2]หน้าผ้า!DZ24 -> 0 | AU15: =[2]หน้าผ้า!EA24 -> 0 | AV15: =[2]หน้าผ้า!EB24 -> 0 | AW15: =[2]หน้าผ้า!EC24 -> งานพิมพ์ | AX15: =[2]หน้าผ้า!ED24 -> / | AY15: =[2]หน้าผ้า!AG24 -> รอส่ง ลูกค้ารับเอง | AZ15: =[2]หน้าผ้า!EG24 -> 0 | BA15: =[2]หน้าผ้า!EH24 -> 0 | BB15: =[2]หน้าผ้า!EI24 -> 0 | BC15: =[2]หน้าผ้า!BZ24 -> WRWT25800/WRWT25800 | BD15: =[2]หน้าผ้า!CA24 -> 0
A16: =[2]หน้าผ้า!C25 -> 45950 | B16: =[2]หน้าผ้า!B25 -> MK68-001247 | C16: =[2]หน้าผ้า!E25 -> บจก.ฟาเธอร์ส วิง ซัพพลาย | D16: =[2]หน้าผ้า!F25 -> ไม่พิมพ์ | E16: =[2]หน้าผ้า!G25 -> 18 | F16: =[2]หน้าผ้า!H25 -> 30 | G16: =[2]หน้าผ้า!I25 -> ขาว | H16: =[2]หน้าผ้า!J25 -> 0 | I16: =[2]หน้าผ้า!L25 -> 54 | J16: =[2]หน้าผ้า!M25 -> ± | K16: =[2]หน้าผ้า!N25 -> 5 | L16: =[2]หน้าผ้า!R25 -> ไม่ | M16: =[2]หน้าผ้า!T25 -> 19 | N16: =[2]หน้าผ้า!U25 -> 33 | O16: =[2]หน้าผ้า!V25 -> 40 | P16: =[2]หน้าผ้า!AB25 -> 0 | Q16: =[2]หน้าผ้า!AC25 -> 0 | R16: =[2]หน้าผ้า!AD25 -> 0 | S16: =[2]หน้าผ้า!Z25 -> 500กระสอบ | T16: =[2]หน้าผ้า!X25 -> 45968 | U16: =[2]หน้าผ้า!AA25 -> 3000 | V16: =[2]หน้าผ้า!AJ25 -> 3064 | W16: =[2]หน้าผ้า!AL25 -> 0 | X16: =[2]หน้าผ้า!AM25 -> 0 | Y16: =[2]หน้าผ้า!AN25 -> 0 | Z16: =[2]หน้าผ้า!AO25 -> WSWT1825800 | AA16: =[2]หน้าผ้า!AQ25 -> 0 | AB16: =[2]หน้าผ้า!AR25 -> 0 | AC16: =[2]หน้าผ้า!AS25 -> 0 | AD16: =[2]หน้าผ้า!AT25 -> 0 | AE16: =[2]หน้าผ้า!AU25 -> 0 | AF16: =[2]หน้าผ้า!AI25 -> 0 | AG16: =[3]หน้าผ้า!DC28 -> ยังไม่ได้พิมพ์ | AH16: =[2]หน้าผ้า!DL25 -> P9 | AI16: =[2]หน้าผ้า!DM25 -> 3 | AJ16: =[2]หน้าผ้า!DN25 -> 45968 | AK16: =[2]หน้าผ้า!DQ25 -> 0 | AL16: =[2]หน้าผ้า!DR25 -> 0 | AM16: =[2]หน้าผ้า!DS25 -> 0 | AN16: =[2]หน้าผ้า!DT25 -> 0 | AO16: =[2]หน้าผ้า!DU25 -> 45964 | AP16: =[2]หน้าผ้า!DP25 -> 45963 | AQ16: =[2]หน้าผ้า!DW25 -> 45965 | AR16: =[2]หน้าผ้า!DX25 -> 0 | AS16: =[2]หน้าผ้า!DY25 -> 0 | AT16: =[2]หน้าผ้า!DZ25 -> 0 | AU16: =[2]หน้าผ้า!EA25 -> 0 | AV16: =[2]หน้าผ้า!EB25 -> 0 | AW16: =[2]หน้าผ้า!EC25 -> ตัด | AX16: =[2]หน้าผ้า!ED25 -> 0 | AY16: =[2]หน้าผ้า!AG25 -> รอส่ง ลูกค้ารับเอง | AZ16: =[2]หน้าผ้า!EG25 -> 0 | BA16: =[2]หน้าผ้า!EH25 -> 0 | BB16: =[2]หน้าผ้า!EI25 -> 0 | BC16: =[2]หน้าผ้า!BZ25 -> WRWT25800/WRWT25800 | BD16: =[2]หน้าผ้า!CA25 -> 0
A17: =[2]หน้าผ้า!C26 -> 45923 | B17: =[2]หน้าผ้า!B26 -> MK68-001162 | C17: =[2]หน้าผ้า!E26 -> หจก.อนนท์อุตสาหกรรม | D17: =[2]หน้าผ้า!F26 -> ดาว 20 กก. | E17: =[2]หน้าผ้า!G26 -> 18 | F17: =[2]หน้าผ้า!H26 -> 28 | G17: =[2]หน้าผ้า!I26 -> ขาว | H17: =[2]หน้าผ้า!J26 -> 0 | I17: =[2]หน้าผ้า!L26 -> 50 | J17: =[2]หน้าผ้า!M26 -> ± | K17: =[2]หน้าผ้า!N26 -> 5 | L17: =[2]หน้าผ้า!R26 -> ไม่ | M17: =[2]หน้าผ้า!T26 -> 19 | N17: =[2]หน้าผ้า!U26 -> 31 | O17: =[2]หน้าผ้า!V26 -> 40 | P17: =[2]หน้าผ้า!AB26 -> 1453.1171 | Q17: =[2]หน้าผ้า!AC26 -> 0 | R17: =[2]หน้าผ้า!AD26 -> 1453.1171 | S17: =[2]หน้าผ้า!Z26 -> 500กระสอบแบน | T17: =[2]หน้าผ้า!X26 -> 45989 | U17: =[2]หน้าผ้า!AA26 -> 100000 | V17: =[2]หน้าผ้า!AJ26 -> 0 | W17: =[2]หน้าผ้า!AL26 -> 100000 | X17: =[2]หน้าผ้า!AM26 -> 0 | Y17: =[2]หน้าผ้า!AN26 -> 105000 | Z17: =[2]หน้าผ้า!AO26 -> WSWT1825800 | AA17: =[2]หน้าผ้า!AQ26 -> 82423 | AB17: =[2]หน้าผ้า!AR26 -> 49747 | AC17: =[2]หน้าผ้า!AS26 -> 32676 | AD17: =[2]หน้าผ้า!AT26 -> 0 | AE17: =[2]หน้าผ้า!AU26 -> 0 | AF17: =[2]หน้าผ้า!AI26 -> 0 | AG17: =[3]หน้าผ้า!DC29 -> ยังไม่ได้พิมพ์ | AH17: =[2]หน้าผ้า!DL26 -> P9 | AI17: =[2]หน้าผ้า!DM26 -> 3 | AJ17: =[2]หน้าผ้า!DN26 -> 45989 | AK17: =[2]หน้าผ้า!DQ26 -> 0 | AL17: =[2]หน้าผ้า!DR26 -> 45979 | AM17: =[2]หน้าผ้า!DS26 -> 45986 | AN17: =[2]หน้าผ้า!DT26 -> 45987 | AO17: =[2]หน้าผ้า!DU26 -> 45987 | AP17: =[2]หน้าผ้า!DP26 -> 45984 | AQ17: =[2]หน้าผ้า!DW26 -> 45988 | AR17: =[2]หน้าผ้า!DX26 -> 0 | AS17: =[2]หน้าผ้า!DY26 -> 0 | AT17: =[2]หน้าผ้า!DZ26 -> 0 | AU17: =[2]หน้าผ้า!EA26 -> 0 | AV17: =[2]หน้าผ้า!EB26 -> 0 | AW17: =[2]หน้าผ้า!EC26 -> งานพิมพ์ | AX17: =[2]หน้าผ้า!ED26 -> / | AY17: =[2]หน้าผ้า!AG26 -> 0 | AZ17: =[2]หน้าผ้า!EG26 -> 0 | BA17: =[2]หน้าผ้า!EH26 -> 0 | BB17: =[2]หน้าผ้า!EI26 -> 0 | BC17: =[2]หน้าผ้า!BZ26 -> WRWT25800/WRWT25800 | BD17: =[2]หน้าผ้า!CA26 -> 2248.1088
... A575: =[2]หน้าผ้า!C584 -> 0 | B575: =[2]หน้าผ้า!B584 -> 0 | C575: =[2]หน้าผ้า!E584 -> 0 | D575: =[2]หน้าผ้า!F584 -> 0 | E575: =[2]หน้าผ้า!G584 -> 0 | F575: =[2]หน้าผ้า!H584 -> 0 | G575: =[2]หน้าผ้า!I584 -> 0 | H575: =[2]หน้าผ้า!J584 -> 0 | I575: =[2]หน้าผ้า!L584 -> 0 | J575: =[2]หน้าผ้า!M584 -> 0 | K575: =[2]หน้าผ้า!N584 -> 0 | L575: =[2]หน้าผ้า!R584 -> 0 | M575: =[2]หน้าผ้า!T584 -> 0 | N575: =[2]หน้าผ้า!U584 -> 0 | O575: =[2]หน้าผ้า!V584 -> 0 | P575: =[2]หน้าผ้า!AB584 -> 0 | Q575: =[2]หน้าผ้า!AC584 -> 0 | R575: =[2]หน้าผ้า!AD584 -> 0 | S575: =[2]หน้าผ้า!Z584 -> 0 | T575: =[2]หน้าผ้า!X584 -> 0 | U575: =[2]หน้าผ้า!AA584 -> 0 | V575: =[2]หน้าผ้า!AJ584 -> 0 | W575: =[2]หน้าผ้า!AL584 -> 0 | X575: =[2]หน้าผ้า!AM584 -> 0 | Y575: =[2]หน้าผ้า!AN584 -> 0 | Z575: =[2]หน้าผ้า!AO584 -> 0 | AA575: =[2]หน้าผ้า!AQ584 -> 0 | AB575: =[2]หน้าผ้า!AR584 -> 0 | AC575: =[2]หน้าผ้า!AS584 -> 0 | AD575: =[2]หน้าผ้า!AT584 -> 0 | AE575: =[2]หน้าผ้า!AU584 -> 0 | AF575: =[2]หน้าผ้า!AI584 -> 0 | AG575: =[3]หน้าผ้า!DC587 -> 0 | AH575: =[2]หน้าผ้า!DL584 -> 0 | AI575: =[2]หน้าผ้า!DM584 -> 0 | AJ575: =[2]หน้าผ้า!DN584 -> 0 | AK575: =[2]หน้าผ้า!DQ584 -> 0 | AL575: =[2]หน้าผ้า!DR584 -> 0 | AM575: =[2]หน้าผ้า!DS584 -> 0 | AN575: =[2]หน้าผ้า!DT584 -> 0 | AO575: =[2]หน้าผ้า!DU584 -> 0 | AP575: =[2]หน้าผ้า!DP584 -> 0 | AQ575: =[2]หน้าผ้า!DW584 -> 0 | AR575: =[2]หน้าผ้า!DX584 -> 0 | AS575: =[2]หน้าผ้า!DY584 -> 0 | AT575: =[2]หน้าผ้า!DZ584 -> 0 | AU575: =[2]หน้าผ้า!EA584 -> 0 | AV575: =[2]หน้าผ้า!EB584 -> 0 | AW575: =[2]หน้าผ้า!EC584 -> 0 | AX575: =[2]หน้าผ้า!ED584 -> 0 | AY575: =[2]หน้าผ้า!AG584 -> 0 | AZ575: =[2]หน้าผ้า!EG584 -> 0 | BA575: =[2]หน้าผ้า!EH584 -> 0 | BB575: =[2]หน้าผ้า!EI584 -> 0 | BC575: =[2]หน้าผ้า!BZ584 -> 0 | BD575: =[2]หน้าผ้า!CA584 -> 0

Sheet 11(Order+FC)
A2: เลขที่ SO | B2: (ทั้งหมด)
A3: วันส่ง | B3: (หลายรายการ)
A4: ชื่อลูกค้า | B4: (ทั้งหมด)
K5: 9
A6: ประเภท | B6: ผลรวม ของ จำนวนส่ง | C6: ผลรวม ของ ค้างพิมพ์ | D6: ผลรวม ของ ค้างตัด | E6: ผลรวม ของ ใช้ | F6: ผลรวม ของ Stock | G6: ผลรวม ของ ค้างทอ
A7: WSWT1825800 | B7: 130000 | C7: 136500 | D7: 130000 | E7: 104635.3 | F7: 77173.8 | G7: 27461.5 | H7: =+J7-I7 -> 27461.5 | J7: =G7 -> 27461.5
A8: WSWT1921720 | B8: 390000 | C8: 362250 | D8: 345000 | E8: 322916.55 | F8: 78141.2 | G8: 244775.35 | H8: =+J8-I8 -> 244775.35 | J8: =G8 -> 244775.35
A9: WSWT1925800 | B9: 170000 | C9: 170819.25 | D9: 162685 | E9: 144285.28 | F9: 89787.475 | G9: 54497.8 | H9: =+J9-I9 -> 54497.8 | J9: =G9 -> 54497.8
A10: WSWT2025800SM | B10: 186381 | C10: 149865.45 | D10: 153812 | E10: 157650.91 | F10: 49255.007 | G10: 108395.9 | H10: =+J10-I10 -> 108395.9 | J10: =G10 -> 108395.9
A11: WSWT2025850 | B11: 428000 | C11: 320528.25 | D11: 319182 | E11: 337667.66 | F11: 0 | G11: 337667.66 | H11: =+J11-I11 -> 337667.66 | J11: =G11 -> 337667.66
A12: WSWT2121670SM | B12: 120000 | C12: 126000 | D12: 120000 | E12: 129082.8 | F12: 129082.8 | G12: 0 | H12: =+J12-I12 -> 0 | J12: =G12 -> 0 | K12: 40000 | L12: =+K5*K12 -> 360000 | M12: =+L12-J12 -> 360000
A13: WSWT23211125120SMFX | B13: 10000 | C13: 10500 | D13: 10000 | E13: 10756.9 | F13: 4270 | G13: 6486.9 | H13: =+J13-I13 -> 6486.9 | J13: =G13 -> 6486.9 | K13: 14000 | L13: =+K13*K5 -> 126000 | M13: =+L13-J13 -> 119513.1
A14: WSWT2325650 | B14: 30000 | C14: 31500 | D14: 30000 | E14: 29756.1 | F14: 4911 | G14: 24845.1 | H14: =+J14-I14 -> 24845.1 | J14: =G14 -> 24845.1
A15: WSWT2825850 | B15: 50000 | C15: 52500 | D15: 50000 | E15: 59372.5 | F15: 3504 | G15: 55868.5 | H15: =+J15-I15 -> 55868.5 | J15: =G15 -> 55868.5 | K15: 20000 | L15: =+K15*K5 -> 180000 | M15: =+L15-J15 -> 124131.5
A16: WSWTFCL022325650 | B16: 13000 | C16: 13650 | D16: 13000 | E16: 12894.31 | F16: 12894.31 | G16: 0 | H16: =+J16-I16 -> 0 | J16: =G16 -> 0
A17: WSWTSCL052325650 | B17: 5000 | C17: 5250 | D17: 5000 | E17: 4959.35 | F17: 0 | G17: 4959.35 | H17: =+J17-I17 -> 4959.35 | J17: =G17 -> 4959.35
A18: ผลรวมทั้งหมด | B18: 1532381 | C18: 1379362.9 | D18: 1338679 | E18: 1313977.6 | F18: 449019.59 | G18: 864958.06 | H18: =+J18-I18 -> 864958.06 | J18: =G18 -> 864958.06
H19: 0 | I19: 54000 | J19: =G19 -> 0
H20: =+J20-I20 -> 0 | J20: =G20 -> 0
H21: =+J21-I21 -> 0 | J21: =G21 -> 0
H22: =+J22-I22 -> 0 | J22: =G22 -> 0
H23: =+J23-I23 -> 0 | J23: =G23 -> 0
H24: =+J24-I24 -> 0 | J24: =G24 -> 0
H25: =+J25-I25 -> 0 | J25: =G25 -> 0
H26: =+J26-I26 -> 0 | J26: =G26 -> 0
H27: =+J27-I27 -> 0 | J27: =G27 -> 0
H28: =+J28-I28 -> 0 | J28: =G28 -> 0 | M28: =+GETPIVOTDATA("ผลรวม ของ ใช้",$A$6)+H29+H33 -> 3133893.8
H29: =SUM(H7:H28) -> 1729916.1 | I29: =SUM(I7:I28) -> 54000 | J29: =SUM(J7:J28) -> 1729916.1
H32: =+H26 -> 0 | I32: 85 | J32: =+(H32+H29)*I32 -> 1.4704287e+08 | K32: =+J32/1000 -> 147042.87
H33: 90000 | I33: 95 | J33: =+H33*I33 -> 8550000 | K33: =+J33/1000 -> 8550
H35: =+H32+H33+H29 -> 1819916.1 | K35: =+K32+K33 -> 155592.87
N36: 705222
A37: ยอดส่ง 1/2/68 - 17/2/68 | B37: 1565717 | H37: 15 | I37: =+H35/H37 -> 121327.74
N38: =+H35+N36 -> 2525138.1
I39: =+H37*110000 -> 1650000
B41: =+B29+B37+B31-110000 -> 1455717 | C41: =+C29+C37+C31 -> 0 | D41: =+D29+D37+D31-110000 -> -110000 | E41: =+E29+E37+E31 -> 0 | F41: =+F29+F37+F31 -> 0 | G41: =+G29+G37+G31 -> 0
B43: 3218150
B45: =+B43-B41 -> 1762433
C47: =+C41/9 -> 0 | D47: =+D41/9 -> -12222.222

Sheet 11(Order)
A2: เลขที่ SO | B2: (หลายรายการ)
A3: วันส่ง | B3: (หลายรายการ)
A4: ชื่อลูกค้า | B4: (ทั้งหมด)
A6: ประเภท | B6: ผลรวม ของ จำนวนส่ง | C6: ผลรวม ของ ค้างพิมพ์ | D6: ผลรวม ของ ค้างตัด | E6: ผลรวม ของ ใช้ | F6: ผลรวม ของ Stock | G6: ผลรวม ของ ค้างทอ
A7: WSWT1825800 | B7: 130000 | C7: 136500 | D7: 130000 | E7: 104635.3 | F7: 77173.8 | G7: 27461.5
A8: WSWT1921720 | B8: 165000 | C8: 126000 | D8: 120000 | E8: 112318.8 | F8: 78141.2 | G8: 34177.6
A9: WSWT1925800 | B9: 110000 | C9: 108063.9 | D9: 102918 | E9: 90579.161 | F9: 71285.761 | G9: 19293.4
A10: WSWT2025800SM | B10: 175679 | C10: 149865.45 | D10: 146998 | E10: 157650.91 | F10: 49255.007 | G10: 108395.9
A11: WSWT2025850 | B11: 428000 | C11: 320528.25 | D11: 319182 | E11: 337667.66 | F11: 0 | G11: 337667.66
A12: WSWT2121670SM | B12: 120000 | C12: 126000 | D12: 120000 | E12: 129082.8 | F12: 129082.8 | G12: 0
A13: WSWT23211125120SMFX | B13: 10000 | C13: 10500 | D13: 10000 | E13: 10756.9 | F13: 4270 | G13: 6486.9
A14: WSWTFCL022325650 | B14: 13000 | C14: 13650 | D14: 13000 | E14: 12894.31 | F14: 12894.31 | G14: 0
A15: WSWTSCL052325650 | B15: 5000 | C15: 5250 | D15: 5000 | E15: 4959.35 | F15: 0 | G15: 4959.35
A16: ผลรวมทั้งหมด | B16: 1156679 | C16: 996357.6 | D16: 967098 | E16: 960545.18 | F16: 422102.88 | G16: 538442.31
D34: =D18 -> 0
D36: =D20 -> 0
A37: ยอดส่ง 1/4/68 - 12/4/68 | B37: 887615
A38: Order+ส่ง | B38: =++B25+B37 -> 887615
A39: ประมาณการ | B39: 262000 | C39: 238350 | D39: 262000 | E39: 279847.04 | F39: 60825.09 | G39: 219021.95
A41: Order+ส่ง+ประมาณการ | B41: =+B25+B37+B39+B33 -> 1149615 | C41: =+C25+C37+C39+C33 -> 238350 | D41: =+D25+D37+D39+D33 -> 262000 | E41: =+E25+E37+E39+E33 -> 279847.04 | F41: =+F25+F37+F39+F33 -> 60825.09 | G41: =+G25+G37+G39+G33 -> 219021.95
B43: 3171376
B45: =+B41-B43 -> -2021761 | C45: =+$B$45 -> -2021761 | D45: =+$B$45 -> -2021761 | F45: =+$B$45 -> -2021761
D47: =+D41/6 -> 43666.667

Sheet 11(Order) แยกลูกค้า
A1: เลขที่ SO | B1: (หลายรายการ)
A2: วันส่ง | B2: (หลายรายการ)
A4: ประเภท | B4: ชื่อลูกค้า | C4: ผลรวม ของ จำนวนส่ง | D4: ผลรวม ของ ค้างพิมพ์ | E4: ผลรวม ของ ค้างตัด | F4: ผลรวม ของ Stock | G4: ผลรวม ของ ค้างทอ | I4: vn
A5: WSWT1825800 | B5: หจก.อนนท์อุตสาหกรรม | C5: 50000 | D5: 52500 | E5: 50000 | F5: 41211.5 | G5: 0 | H5: =G5 -> 0
A6: WSWT1825800 ผลรวม | C6: 50000 | D6: 52500 | E6: 50000 | F6: 41211.5 | G6: 0 | H6: =G6 -> 0
A7: WSWT1925800 | B7: บจก.เพรซิเดนท์ฟลาวมิลล์ | C7: 110000 | D7: 112808.85 | E7: 107437 | F7: 0 | G7: 94556.378 | H7: =G7 -> 94556.378
A8: WSWT1925800 ผลรวม | C8: 110000 | D8: 112808.85 | E8: 107437 | F8: 0 | G8: 94556.378 | H8: =G8 -> 94556.378
A9: WSWT2025800SM | B9: บจก.เอพีเอ็ม อะโกร | C9: 13000 | D9: 13650 | E9: 13000 | F9: 14347.19 | G9: 0 | H9: =G9 -> 0
B10: บจก.เอสพีเอ็ม อาหารสัตว์ | C10: 27000 | D10: 18900 | E10: 18500 | F10: 16554.45 | G10: 3310.89 | H10: =G10 -> 3310.89
B11: บจก.ซันฟีด | C11: 129500 | D11: 119415.45 | E11: 116600 | F11: 6213.4369 | G11: 119432.2 | H11: =G11 -> 119432.2
A12: WSWT2025800SM ผลรวม | C12: 169500 | D12: 151965.45 | E12: 148100 | F12: 37115.077 | G12: 122743.09 | H12: =G12 -> 122743.09
A13: WSWT2025850 | B13: บจก.ซันฟีด | C13: 436000 | D13: 381675 | E13: 395697 | F13: 39046.15 | G13: 362682.16 | H13: =G13 -> 362682.16
A14: WSWT2025850 ผลรวม | C14: 436000 | D14: 381675 | E14: 395697 | F14: 39046.15 | G14: 362682.16 | H14: =G14 -> 362682.16
A15: WSWT2825850 | B15: บจก.ไทยร่วมใจน้ำมันพืช | C15: 50000 | D15: 52500 | E15: 50000 | F15: 59372.5 | G15: 0 | H15: =G15 -> 0
A16: WSWT2825850 ผลรวม | C16: 50000 | D16: 52500 | E16: 50000 | F16: 59372.5 | G16: 0 | H16: =G16 -> 0
A17: WSWTFCL022325650 | B17: คุณปราสาท เจริญธรรมรักษา | C17: 13000 | D17: 13650 | E17: 13000 | F17: 2255 | G17: 10639.31 | H17: =G17 -> 10639.31
A18: WSWTFCL022325650 ผลรวม | C18: 13000 | D18: 13650 | E18: 13000 | F18: 2255 | G18: 10639.31 | H18: =G18 -> 10639.31
A19: WSWTSCL052325650 | B19: คุณปราสาท เจริญธรรมรักษา | C19: 5000 | D19: 5250 | E19: 5000 | F19: 3294 | G19: 1665.35 | H19: =G19 -> 1665.35
A20: WSWTSCL052325650 ผลรวม | C20: 5000 | D20: 5250 | E20: 5000 | F20: 3294 | G20: 1665.35 | H20: =G20 -> 1665.35
A21: ผลรวมทั้งหมด | C21: 833500 | D21: 770349.3 | E21: 769234 | F21: 182294.23 | G21: 592286.28 | H21: =G21 -> 592286.28
H22: =G22 -> 0
H23: =G23 -> 0
H24: =G24 -> 0
H25: =G25 -> 0
H26: =G26 -> 0
H27: =G27 -> 0
H28: =G28 -> 0
H29: =G29 -> 0
H30: =G30 -> 0
H31: =G31 -> 0
H32: =G32 -> 0
H33: =G33 -> 0
... H65: =G65 -> 0
H70: =SUM(H5:H69) -> 1776858.8
D119: Cap พิมพ์ | E119: Cap ตัด | F119: Stock 16/7 บ่าย | G119: Cap ทอ | I119: วันทงาน
B120: lส่ง | C120: 1-16/7 | D120: 160000 | E120: 160000 | G120: 120000 | I120: 12
C121: 1975256 | D121: =+D120*I120 -> 1920000 | E121: =+E120*I120 -> 1920000 | F121: 825147 | G121: =+G120*I120 -> 1440000
A122: เบทาโกรส่งแล้ว | B122: 20700 | C122: 424374
A123: เบทาโกรส่งแล้ว | B123: 20800 | C123: 155973
C126: รวมส่ง+ค้างส่ง | D126: ส่วนต่างCapคงเหลือ | E126: ส่วนต่างCapคงเหลือ | F126: คงเหลือ
...

Sheet 9(Fc) แยกลูกค้า
A1: เลขที่ SO | B1: ประมาณการ
A2: วันส่ง | B2: (หลายรายการ) | D2: 12
A4: ประเภท | B4: ชื่อลูกค้า | C4: ผลรวม ของ จำนวนส่ง | D4: ผลรวม ของ ค้างพิมพ์ | E4: ผลรวม ของ ค้างตัด | F4: ผลรวม ของ ใช้ | G4: ผลรวม ของ Stock | H4: ผลรวม ของ ค้างทอ
A5: WSWT1921720 | B5: บจก.เคอรี่ฟลาวมิลล์ | C5: 225000 | D5: 236250 | E5: 225000 | F5: 210597.75 | G5: 0 | H5: 210597.75
A6: WSWT1921720 ผลรวม | C6: 225000 | D6: 236250 | E6: 225000 | F6: 210597.75 | G6: 0 | H6: 210597.75
A7: WSWT1925800 | B7: บจก.เพรซิเดนท์ฟลาวมิลล์ | C7: 140000 | D7: 147000 | E7: 140000 | F7: 123215.4 | G7: 0 | H7: 123215.4
B8: บจก.ไลม์มาสเตอร์ | C8: 20000 | D8: 20755.35 | E8: 19767 | F8: 18501.714 | G8: 0 | H8: 18501.714
B9: บจก.เอ็กเซลเล้นท์ | C9: 40000 | D9: 42000 | E9: 40000 | F9: 35204.4 | G9: 0 | H9: 35204.4
A10: WSWT1925800 ผลรวม | C10: 200000 | D10: 209755.35 | E10: 199767 | F10: 176921.51 | G10: 0 | H10: 176921.51
A11: WSWT2025800 | B11: บจก.อินเทคค์ โกลบอล | C11: 290000 | D11: 304500 | E11: 290000 | F11: 303847.5 | G11: 0 | H11: 303847.5
A12: WSWT2025800 ผลรวม | C12: 290000 | D12: 304500 | E12: 290000 | F12: 303847.5 | G12: 0 | H12: 303847.5
A13: WSWT2025800SM | B13: บจก.ไทยธรรมดี | C13: 20000 | D13: 21000 | E13: 20000 | F13: 21513.8 | G13: 0 | H13: 21513.8
B14: บจก.อินเทคค์ โกลบอล | C14: 100000 | D14: 105000 | E14: 100000 | F14: 104775 | G14: 0 | H14: 104775
B15: บจก.เอสพีเอ็ม อาหารสัตว์ | C15: 20000 | D15: 21000 | E15: 20000 | F15: 22072.6 | G15: 0 | H15: 22072.6
B16: บจก.ซันฟีด | C16: 305000 | D16: 320250 | E16: 305000 | F16: 336607.15 | G16: 0 | H16: 336607.15
A17: WSWT2025800SM ผลรวม | C17: 445000 | D17: 467250 | E17: 445000 | F17: 484968.55 | G17: 0 | H17: 484968.55
A18: WSWT2325650 | B18: พันธุ์ข้าว | C18: 30000 | D18: 31500 | E18: 30000 | F18: 29756.1 | G18: 29756.1 | H18: 0
A19: WSWT2325650 ผลรวม | C19: 30000 | D19: 31500 | E19: 30000 | F19: 29756.1 | G19: 29756.1 | H19: 0
A20: WSWT2625800 | B20: บจก.ที.ซี.ยูเนี่ยน อโกรเทค | C20: 10000 | D20: 0 | E20: 10000 | F20: 12433.3 | G20: 12433.3 | H20: 0
A21: WSWT2625800 ผลรวม | C21: 10000 | D21: 0 | E21: 10000 | F21: 12433.3 | G21: 12433.3 | H21: 0
A22: WSWT2825850 | B22: บจก.ที.ซี.ยูเนี่ยน อโกรเทค | C22: 5000 | D22: 0 | E22: 5000 | F22: 6775.45 | G22: 0 | H22: 6775.45
A23: WSWT2825850 ผลรวม | C23: 5000 | D23: 0 | E23: 5000 | F23: 6775.45 | G23: 0 | H23: 6775.45
A24: ผลรวมทั้งหมด | C24: 1205000 | D24: 1249255.4 | E24: 1204767 | F24: 1225300.2 | G24: 42189.4 | H24: 1183110.8
D119: Cap พิมพ์ | E119: Cap ตัด | F119: Stock 16/7 บ่าย | G119: Cap ทอ | I119: วันทงาน
B120: lส่ง | C120: 1-16/7 | D120: 160000 | E120: 160000 | G120: 120000 | I120: 12
C121: 1975256 | D121: =+D120*I120 -> 1920000 | E121: =+E120*I120 -> 1920000 | F121: 825147 | G121: =+G120*I120 -> 1440000
A122: เบทาโกรส่งแล้ว | B122: 20700 | C122: 424374
A123: เบทาโกรส่งแล้ว | B123: 20800 | C123: 155973
C126: รวมส่ง+ค้างส่ง | D126: ส่วนต่างCapคงเหลือ | E126: ส่วนต่างCapคงเหลือ | F126: คงเหลือ
C127: =+C50+C121 -> 1975256 | D127: =+D121-D50 -> 1920000 | E127: =+E121-E50 -> 1920000 | F127: =+F121-F50 -> 825147 | G127: =+G121-G50 -> 1440000
B129: 20700VN 20/7 | G129: 350000

Sheet 10(Order+Fc) แยกลูกค้า
A1: เลขที่ SO | B1: (หลายรายการ)
A2: วันส่ง | B2: (หลายรายการ) | D2: 12 | I2: เมตร | J2: vn | K2: ใบ | P2: วัน
A4: ประเภท | B4: ชื่อลูกค้า | C4: ผลรวม ของ จำนวนส่ง | D4: ผลรวม ของ ค้างพิมพ์ | E4: ผลรวม ของ ค้างตัด | F4: ผลรวม ของ ใช้ | G4: ผลรวม ของ Stock | H4: ผลรวม ของ ค้างทอ
A5: WSWT1425800 | B5: หจก.ปึงเป้งน้ำ | C5: 10000 | D5: 10500 | E5: 10000 | F5: 6565.9 | G5: 3028 | H5: 3537.9 | I5: =H5 -> 3537.9
A6: WSWT1425800 ผลรวม | C6: 10000 | D6: 10500 | E6: 10000 | F6: 6565.9 | G6: 3028 | H6: 3537.9
A7: WSWT1625800 | B7: บจก.เคอรี่ฟลาวมิลล์ | C7: 5000 | D7: 0 | E7: 5000 | F7: 0 | G7: 0 | H7: 0 | I7: =H7 -> 0
A8: WSWT1625800 ผลรวม | C8: 5000 | D8: 0 | E8: 5000 | F8: 0 | G8: 0 | H8: 0 | I8: =H8 -> 0
A9: WSWT1825800 | B9: หจก.อนนท์อุตสาหกรรม | C9: 50000 | D9: 52500 | E9: 50000 | F9: 41211.5 | G9: 41211.5 | H9: 0 | I9: =H9 -> 0
A10: WSWT1825800 ผลรวม | C10: 50000 | D10: 52500 | E10: 50000 | F10: 41211.5 | G10: 41211.5 | H10: 0 | I10: =H10 -> 0
A11: WSWT1921720 | B11: บจก.เคอรี่ฟลาวมิลล์ | C11: 395000 | D11: 236250 | E11: 254200 | F11: 210597.75 | G11: 51686 | H11: 158911.75
A12: WSWT1921720 ผลรวม | C12: 395000 | D12: 236250 | E12: 254200 | F12: 210597.75 | G12: 51686 | H12: 158911.75
A13: WSWT1925800 | B13: บจก.เพรซิเดนท์ฟลาวมิลล์ | C13: 20000 | D13: 0 | E13: 0 | F13: 0 | G13: 0 | H13: 0 | I13: =H13 -> 0
B14: บจก.ไลม์มาสเตอร์ | C14: 20000 | D14: 20755.35 | E14: 19767 | F14: 18501.714 | G14: 0 | H14: 18501.714 | I14: =H14 -> 18501.714 | P14: 15000 | Q14: =+K14/P14 -> 0
B15: บจก.เอ็กเซลเล้นท์ | C15: 20000 | D15: 21000 | E15: 20000 | F15: 17602.2 | G15: 12640 | H15: 4962.2 | I15: =H15 -> 4962.2
A16: WSWT1925800 ผลรวม | C16: 60000 | D16: 41755.35 | E16: 39767 | F16: 36103.914 | G16: 12640 | H16: 23463.914
A17: WSWT2025700 | B17: บจก.หนองบัวฟีด | C17: 5000 | D17: 0 | E17: 5000 | F17: 4400.55 | G17: 0 | H17: 4400.55 | I17: =H17 -> 4400.55
A18: WSWT2025700 ผลรวม | C18: 5000 | D18: 0 | E18: 5000 | F18: 4400.55 | G18: 0 | H18: 4400.55 | K18: =7*2000 -> 14000
A19: WSWT2025800 | B19: บจก.เคอรี่ฟลาวมิลล์ | C19: 15000 | D19: 0 | E19: 12000 | F19: 0 | G19: 0 | H19: 0 | I19: =H19 -> 0 | K19: 7000
B20: บจก.อินเทคค์ โกลบอล | C20: 296826 | D20: 304500 | E20: 290000 | F20: 303847.5 | G20: 36749 | H20: 267098.5 | I20: =H20-100000 -> 167098.5 | K20: 9000 | P20: 16000 | Q20: =+K20/P20 -> 0.5625
B21: โรงสีข้าวธัญญาวัฒน์ | C21: 4000 | D21: 0 | E21: 1555 | F21: 0 | G21: 0 | H21: 0 | I21: =H21 -> 0
A22: WSWT2025800 ผลรวม | C22: 315826 | D22: 304500 | E22: 303555 | F22: 303847.5 | G22: 36749 | H22: 267098.5
A23: WSWT2025800SM | B23: บจก.อินเทคค์ โกลบอล | C23: 100000 | D23: 105000 | E23: 100000 | F23: 104775 | G23: 21900 | H23: 82875 | I23: =H23 -> 82875
B24: บจก.เอพีเอ็ม อะโกร | C24: 9000 | D24: 6300 | E24: 9000 | F24: 6789.42 | G24: 6789.42 | H24: 0 | I24: =H24 -> 0
B25: บจก.เอสพีเอ็ม อาหารสัตว์ | C25: 15179 | D25: 3150 | E25: 4020 | F25: 3310.89 | G25: 3310.89 | H25: 0 | I25: =H25 -> 0
B26: บจก.ซันฟีด | C26: 50755 | D26: 8925 | E26: 9079 | F26: 9380.855 | G26: 9380.855 | H26: 0 | I26: =H26 -> 0
A27: WSWT2025800SM ผลรวม | C27: 174934 | D27: 123375 | E27: 122099 | F27: 124256.17 | G27: 41381.165 | H27: 82875
A28: WSWT2025850 | B28: บจก.ซันฟีด | C28: 158300 | D28: 24675 | E28: 38517 | F28: 26116.915 | G28: 26116.915 | H28: 0 | I28: =H28 -> 0
A29: WSWT2025850 ผลรวม | C29: 158300 | D29: 24675 | E29: 38517 | F29: 26116.915 | G29: 26116.915 | H29: 0 | I29: =H29 -> 0
A30: WSWT2121670SM | B30: บจก.เอสพีเอ็ม อาหารสัตว์ | C30: 3000 | D30: 0 | E30: 0 | F30: 0 | G30: 0 | H30: 0 | I30: =H30 -> 0
B31: บจก.แอมโก้เวท | C31: 65000 | D31: 10500 | E31: 26000 | F31: 11832.59 | G31: 11832.59 | H31: 0 | I31: =H31 -> 0 | P31: 15000 | Q31: =+K31/P31 -> 0
B32: คุณนพวินทร์ รัตนเศรษฐ์เมธา | C32: 5000 | D32: 0 | E32: 263 | F32: 0 | G32: 0 | H32: 0 | I32: =H32 -> 0
A33: WSWT2121670SM ผลรวม | C33: 73000 | D33: 10500 | E33: 26263 | F33: 11832.59 | G33: 11832.59 | H33: 0 | I33: =H33 -> 0
A34: WSWT2125650 | B34: บจก.ไลม์มาสเตอร์ | C34: 20000 | D34: 0 | E34: 20000 | F34: 0 | G34: 0 | H34: 0 | I34: =H34 -> 0
B35: บจก.หนองบัวฟีด | C35: 15000 | D35: 0 | E35: 15000 | F35: 16554.45 | G35: 16554.45 | H35: 0 | I35: =H35 -> 0
A36: WSWT2125650 ผลรวม | C36: 35000 | D36: 0 | E36: 35000 | F36: 16554.45 | G36: 16554.45 | H36: 0 | I36: =H36 -> 0
A37: WSWT2321750 | B37: บจก.แอมโก้เวท | C37: 5000 | D37: 0 | E37: 0 | F37: 0 | G37: 0 | H37: 0 | I37: =H37 -> 0
A38: WSWT2321750 ผลรวม | C38: 5000 | D38: 0 | E38: 0 | F38: 0 | G38: 0 | H38: 0 | I38: =H38 -> 0
A39: WSWT2325650 | B39: พันธุ์ข้าว | C39: 30000 | D39: 31500 | E39: 30000 | F39: 29756.1 | G39: 29756.1 | H39: 0 | I39: =H39 -> 0
B40: บจก.ซิเบลโก้(บางเลน) | C40: 5000 | D40: 0 | E40: 0 | F40: 0 | G40: 0 | H40: 0 | I40: =H40 -> 0
A41: WSWT2325650 ผลรวม | C41: 35000 | D41: 31500 | E41: 30000 | F41: 29756.1 | G41: 29756.1 | H41: 0 | I41: =H41 -> 0
...

Sheet 10(Order)
A2: เลขที่ SO | B2: (ทั้งหมด)
A3: วันส่ง | B3: (หลายรายการ)
A4: ชื่อลูกค้า | B4: (ทั้งหมด)
A6: ประเภท | B6: ผลรวม ของ จำนวนส่ง | C6: ผลรวม ของ ค้างพิมพ์ | D6: ผลรวม ของ ค้างตัด | E6: ผลรวม ของ ใช้ | F6: ผลรวม ของ Stock | G6: ผลรวม ของ ค้างทอ
A7: WSWT1425800 | B7: 10000 | C7: 10500 | D7: 10000 | E7: 6565.9 | F7: 6565.9 | G7: 0
A8: WSWT1825800 | B8: 38000 | C8: 12915 | D8: 35700 | E8: 10145.643 | F8: 10145.643 | G8: 0
A9: WSWT1921720 | B9: 25000 | C9: 0 | D9: 0 | E9: 0 | F9: 0 | G9: 0
A10: WSWT19251000SM | B10: 10080 | C10: 5292 | D10: 10080 | E10: 4999.0248 | F10: 4999.0248 | G10: 0 | K10: =25*32.24 -> 806
A11: WSWT1925800 | B11: 10000 | C11: 10500 | D11: 10000 | E11: 8801.1 | F11: 8801.1 | G11: 0 | L11: =76*2500 -> 190000
A12: WSWT2025800 | B12: 198408 | C12: 148547.7 | D12: 161160 | E12: 150854 | F12: 124440.5 | G12: 26413.5
A13: WSWT2025800SM | B13: 168284 | C13: 120794.1 | D13: 122260 | E13: 120535.26 | F13: 99652.755 | G13: 20882.5
A14: WSWT2025850 | B14: 99000 | C14: 750.75 | D14: 2518 | E14: 809.07255 | F14: 809.07255 | G14: 0
A15: WSWT2121670SM | B15: 98000 | C15: 91476 | D15: 93263 | E15: 94019.525 | F15: 94019.525 | G15: 0
A16: WSWT2321750 | B16: 25000 | C16: 26250 | D16: 25000 | E16: 26892.25 | F16: 9620 | G16: 17272.25
A17: WSWT2625800 | B17: 10000 | C17: 10500 | D17: 10000 | E17: 11595.1 | F17: 11595.1 | G17: 0
A18: WSWT2625850SM | B18: 25000 | C18: 10500 | D18: 10000 | E18: 12433.3 | F18: 12433.3 | G18: 0
A19: WSWTSCL052325650 | B19: 20000 | C19: 15750 | D19: 20000 | E19: 14878.05 | F19: 12502.7 | G19: 2375.35
A20: ผลรวมทั้งหมด | B20: 736772 | C20: 463775.55 | D20: 509981 | E20: 462528.22 | F20: 395584.62 | G20: 66943.6
A37: ยอดส่ง 1/1/68 - 17/1/68 | B37: 1287052
A38: Order+ส่ง | B38: =++B22+B37 -> 1287052
A39: ประมาณการ | I39: 0
A41: Order+ส่ง+ประมาณการ | B41: =+B22+B37+B39+B29 -> 1287052 | C41: =+C22+C37+C39+C29 -> 0 | D41: =+D22+D37+D39+D29 -> 0 | E41: =+E22+E37+E39+E29 -> 0 | F41: =+F22+F37+F39+F29 -> 0 | G41: =+G22+G37+G39+G29 -> 0
B43: 3000000 | I43: 9
B45: =+B41-B43 -> -1712948
D46: =+D22/I43 -> 0
C47: =+C41/I43 -> 0 | D47: =+D41/I43 -> 0 | G47: =+G41/I43 -> 0

Sheet 10(Order) แยกลูกค้า
A1: เลขที่ SO | B1: (หลายรายการ)
A2: วันส่ง | B2: (หลายรายการ)
A4: ประเภท | B4: ชื่อลูกค้า | C4: ผลรวม ของ จำนวนส่ง | D4: ผลรวม ของ ค้างพิมพ์ | E4: ผลรวม ของ ค้างตัด | F4: ผลรวม ของ Stock | G4: ผลรวม ของ ค้างทอ | I4: vn
A5: WSWT1425800 | B5: หจก.ปึงเป้งน้ำ | C5: 10000 | D5: 10500 | E5: 10000 | F5: 3028 | G5: 3537.9 | H5: =G5 -> 3537.9
A6: WSWT1425800 ผลรวม | C6: 10000 | D6: 10500 | E6: 10000 | F6: 3028 | G6: 3537.9 | H6: =G6 -> 3537.9
A7: WSWT1625800 | B7: บจก.เคอรี่ฟลาวมิลล์ | C7: 5000 | D7: 0 | E7: 5000 | F7: 0 | G7: 0 | H7: =G7 -> 0
A8: WSWT1625800 ผลรวม | C8: 5000 | D8: 0 | E8: 5000 | F8: 0 | G8: 0
A9: WSWT1825800 | B9: หจก.อนนท์อุตสาหกรรม | C9: 50000 | D9: 52500 | E9: 50000 | F9: 41211.5 | G9: 0 | H9: =G9 -> 0
A10: WSWT1825800 ผลรวม | C10: 50000 | D10: 52500 | E10: 50000 | F10: 41211.5 | G10: 0 | H10: =G10 -> 0
A11: WSWT1921720 | B11: บจก.เคอรี่ฟลาวมิลล์ | C11: 395000 | D11: 236250 | E11: 254200 | F11: 51686 | G11: 158911.75
A12: WSWT1921720 ผลรวม | C12: 395000 | D12: 236250 | E12: 254200 | F12: 51686 | G12: 158911.75 | H12: =G12 -> 158911.75
A13: WSWT1925800 | B13: บจก.เพรซิเดนท์ฟลาวมิลล์ | C13: 20000 | D13: 0 | E13: 0 | F13: 0 | G13: 0 | H13: =G13 -> 0
B14: บจก.ไลม์มาสเตอร์ | C14: 20000 | D14: 20755.35 | E14: 19767 | F14: 0 | G14: 18501.714 | H14: =G14 -> 18501.714
B15: บจก.เอ็กเซลเล้นท์ | C15: 20000 | D15: 21000 | E15: 20000 | F15: 12640 | G15: 4962.2
A16: WSWT1925800 ผลรวม | C16: 60000 | D16: 41755.35 | E16: 39767 | F16: 12640 | G16: 23463.914 | H16: =G16 -> 23463.914
A17: WSWT2025700 | B17: บจก.หนองบัวฟีด | C17: 5000 | D17: 0 | E17: 5000 | F17: 0 | G17: 4400.55
A18: WSWT2025700 ผลรวม | C18: 5000 | D18: 0 | E18: 5000 | F18: 0 | G18: 4400.55 | H18: =G18 -> 4400.55
A19: WSWT2025800 | B19: บจก.เคอรี่ฟลาวมิลล์ | C19: 15000 | D19: 0 | E19: 12000 | F19: 0 | G19: 0 | H19: =G19 -> 0
B20: บจก.อินเทคค์ โกลบอล | C20: 296826 | D20: 304500 | E20: 290000 | F20: 36749 | G20: 267098.5 | H20: =G20 -> 267098.5
B21: โรงสีข้าวธัญญาวัฒน์ | C21: 4000 | D21: 0 | E21: 1555 | F21: 0 | G21: 0 | H21: =G21 -> 0
A22: WSWT2025800 ผลรวม | C22: 315826 | D22: 304500 | E22: 303555 | F22: 36749 | G22: 267098.5
A23: WSWT2025800SM | B23: บจก.อินเทคค์ โกลบอล | C23: 100000 | D23: 105000 | E23: 100000 | F23: 21900 | G23: 82875 | H23: =G23 -> 82875
B24: บจก.เอพีเอ็ม อะโกร | C24: 9000 | D24: 6300 | E24: 9000 | F24: 6789.42 | G24: 0
B25: บจก.เอสพีเอ็ม อาหารสัตว์ | C25: 15179 | D25: 3150 | E25: 4020 | F25: 3310.89 | G25: 0 | H25: =G25 -> 0
B26: บจก.ซันฟีด | C26: 50755 | D26: 8925 | E26: 9079 | F26: 9380.855 | G26: 0
A27: WSWT2025800SM ผลรวม | C27: 174934 | D27: 123375 | E27: 122099 | F27: 41381.165 | G27: 82875 | H27: =G27 -> 82875
A28: WSWT2025850 | B28: บจก.ซันฟีด | C28: 158300 | D28: 24675 | E28: 38517 | F28: 26116.915 | G28: 0 | H28: =G28 -> 0
A29: WSWT2025850 ผลรวม | C29: 158300 | D29: 24675 | E29: 38517 | F29: 26116.915 | G29: 0 | H29: =G29 -> 0
A30: WSWT2121670SM | B30: บจก.เอสพีเอ็ม อาหารสัตว์ | C30: 3000 | D30: 0 | E30: 0 | F30: 0 | G30: 0
B31: บจก.แอมโก้เวท | C31: 65000 | D31: 10500 | E31: 26000 | F31: 11832.59 | G31: 0 | H31: =G31 -> 0
B32: คุณนพวินทร์ รัตนเศรษฐ์เมธา | C32: 5000 | D32: 0 | E32: 263 | F32: 0 | G32: 0 | H32: =G32 -> 0
A33: WSWT2121670SM ผลรวม | C33: 73000 | D33: 10500 | E33: 26263 | F33: 11832.59 | G33: 0 | H33: =G33 -> 0
A34: WSWT2125650 | B34: บจก.ไลม์มาสเตอร์ | C34: 20000 | D34: 0 | E34: 20000 | F34: 0 | G34: 0 | H34: =G34 -> 0
B35: บจก.หนองบัวฟีด | C35: 15000 | D35: 0 | E35: 15000 | F35: 16554.45 | G35: 0 | H35: =G35 -> 0
A36: WSWT2125650 ผลรวม | C36: 35000 | D36: 0 | E36: 35000 | F36: 16554.45 | G36: 0 | H36: =G36 -> 0
A37: WSWT2321750 | B37: บจก.แอมโก้เวท | C37: 5000 | D37: 0 | E37: 0 | F37: 0 | G37: 0 | H37: =G37 -> 0
A38: WSWT2321750 ผลรวม | C38: 5000 | D38: 0 | E38: 0 | F38: 0 | G38: 0 | H38: =G38 -> 0
A39: WSWT2325650 | B39: พันธุ์ข้าว | C39: 30000 | D39: 31500 | E39: 30000 | F39: 29756.1 | G39: 0 | H39: =G39 -> 0
B40: บจก.ซิเบลโก้(บางเลน) | C40: 5000 | D40: 0 | E40: 0 | F40: 0 | G40: 0
A41: WSWT2325650 ผลรวม | C41: 35000 | D41: 31500 | E41: 30000 | F41: 29756.1 | G41: 0 | H41: =G41 -> 0
...

Sheet 10(Fc) แยกลูกค้
A1: เลขที่ SO | B1: ประมาณการ
A2: วันส่ง | B2: (หลายรายการ) | D2: 12
A4: ประเภท | B4: ชื่อลูกค้า | C4: ผลรวม ของ จำนวนส่ง | D4: ผลรวม ของ ค้างพิมพ์ | E4: ผลรวม ของ ค้างตัด | F4: ผลรวม ของ ใช้ | G4: ผลรวม ของ Stock | H4: ผลรวม ของ ค้างทอ
A5: WSWT1921720 | B5: บจก.เคอรี่ฟลาวมิลล์ | C5: 225000 | D5: 236250 | E5: 225000 | F5: 210597.75 | G5: 51686 | H5: 158911.75
A6: WSWT1921720 ผลรวม | C6: 225000 | D6: 236250 | E6: 225000 | F6: 210597.75 | G6: 51686 | H6: 158911.75
A7: WSWT1925800 | B7: บจก.ไลม์มาสเตอร์ | C7: 20000 | D7: 20755.35 | E7: 19767 | F7: 18501.714 | G7: 0 | H7: 18501.714
A8: WSWT1925800 ผลรวม | C8: 20000 | D8: 20755.35 | E8: 19767 | F8: 18501.714 | G8: 0 | H8: 18501.714
A9: WSWT2025800 | B9: บจก.อินเทคค์ โกลบอล | C9: 290000 | D9: 304500 | E9: 290000 | F9: 303847.5 | G9: 36749 | H9: 267098.5
A10: WSWT2025800 ผลรวม | C10: 290000 | D10: 304500 | E10: 290000 | F10: 303847.5 | G10: 36749 | H10: 267098.5
A11: WSWT2025800SM | B11: บจก.อินเทคค์ โกลบอล | C11: 100000 | D11: 105000 | E11: 100000 | F11: 104775 | G11: 21900 | H11: 82875
A12: WSWT2025800SM ผลรวม | C12: 100000 | D12: 105000 | E12: 100000 | F12: 104775 | G12: 21900 | H12: 82875
A13: WSWT2325650 | B13: พันธุ์ข้าว | C13: 30000 | D13: 31500 | E13: 30000 | F13: 29756.1 | G13: 29756.1 | H13: 0
A14: WSWT2325650 ผลรวม | C14: 30000 | D14: 31500 | E14: 30000 | F14: 29756.1 | G14: 29756.1 | H14: 0
A15: WSWT2825850 | B15: บจก.ที.ซี.ยูเนี่ยน อโกรเทค | C15: 5000 | D15: 0 | E15: 5000 | F15: 6775.45 | G15: 6775.45 | H15: 0
A16: WSWT2825850 ผลรวม | C16: 5000 | D16: 0 | E16: 5000 | F16: 6775.45 | G16: 6775.45 | H16: 0
A17: ผลรวมทั้งหมด | C17: 670000 | D17: 698005.35 | E17: 669767 | F17: 674253.51 | G17: 146866.55 | H17: 527386.96
I119: วันทงาน
I120: 12
C121: 1975256 | D121: =+D120*I120 -> 0 | E121: =+E120*I120 -> 0 | F121: 825147 | G121: =+G120*I120 -> 0
A122: เบทาโกรส่งแล้ว | B122: 20700 | C122: 424374
A123: เบทาโกรส่งแล้ว | B123: 20800 | C123: 155973
C126: รวมส่ง+ค้างส่ง | D126: ส่วนต่างCapคงเหลือ | E126: ส่วนต่างCapคงเหลือ | F126: คงเหลือ
C127: =+C50+C121 -> 1975256 | D127: =+D121-D50 -> 0 | E127: =+E121-E50 -> 0 | F127: =+F121-F50 -> 825147 | G127: =+G121-G50 -> 0
B129: 20700VN 20/7 | G129: 350000

Sheet ค้างตัดเดือน11
A2: งานรอตัด 8/11 | B2: 99615
A3: ผลรวม ของ ค้างตัด
A4: ป้ายชื่อแถว | B4: 45969 | C4: 45971 | D4: 45972 | E4: 45973 | F4: 45974 | G4: 45975 | H4: 45976 | I4: 45977 | J4: 45978 | K4: 45979 | L4: 45980 | M4: 45981 | N4: 45982 | O4: 45985 | P4: 45986 | Q4: 45987 | R4: 45988 | S4: 45989 | T4: 45990 | U4: 45991 | V4: ผลรวมทั้งหมด
A5: 21 | D5: 0 | N5: 0 | S5: 2500 | V5: =SUM(B5:U5) -> 2500
A6: 331 | C6: 2500 | S6: 2500 | V6: =SUM(B6:U6) -> 5000
A7: 575 | N7: 3500 | V7: =SUM(B7:U7) -> 3500
A8: 913 | F8: 5000 | V8: =SUM(B8:U8) -> 5000
A9: 931 | P9: 5000 | V9: =SUM(B9:U9) -> 5000
A10: 932 | D10: 2500 | O10: 2500 | V10: =SUM(B10:U10) -> 5000
A11: 935 | D11: 10000 | G11: 5000 | K11: 5000 | M11: 10000 | P11: 5000 | Q11: 5000 | S11: 5000 | V11: =SUM(B11:U11) -> 45000
A12: 952 | E12: 5000 | J12: 5000 | M12: 5000 | P12: 5000 | S12: 5000 | V12: =SUM(B12:U12) -> 25000
A13: 953 | D13: 0 | K13: 10000 | Q13: 5000 | V13: =SUM(B13:U13) -> 15000
A14: 964 | D14: 3500 | V14: =SUM(B14:U14) -> 3500
A15: 915 พี | C15: 0 | G15: 5000 | J15: 5000 | M15: 5000 | O15: 5000 | S15: 5000 | V15: =SUM(B15:U15) -> 25000
A16: 915 เอ็ม | C16: 0 | D16: 0 | G16: 0 | J16: 10000 | L16: 5000 | N16: 5000 | O16: 5000 | Q16: 10000 | S16: 5000 | V16: =SUM(B16:U16) -> 40000
A17: 935 เอ | C17: 0 | G17: 0 | J17: 6075 | L17: 10000 | N17: 5000 | O17: 5000 | Q17: 10000 | S17: 5000 | V17: =SUM(B17:U17) -> 41075
A18: 935 แอล | E18: 0 | G18: 5000 | K18: 5000 | N18: 5000 | Q18: 7500 | V18: =SUM(B18:U18) -> 22500
A19: 952 เอส | G19: 0 | K19: 0 | Q19: 1800 | V19: =SUM(B19:U19) -> 1800
A20: 953 เอส | G20: 2500 | S20: 2500 | V20: =SUM(B20:U20) -> 5000
A21: A.C.C.ภาษาอังกฤษ | J21: 10000 | V21: =SUM(B21:U21) -> 10000
A22: A.C.C.ภาษาอังกฤษ 8-118 | J22: 10000 | V22: =SUM(B22:U22) -> 10000
A23: APM 914 | S23: 3000 | V23: =SUM(B23:U23) -> 3000
A24: BS(แต้มฟ้า) | H24: 5000 | V24: =SUM(B24:U24) -> 5000
A25: Green for white sugar | G25: 48600 | N25: 50100 | S25: 50100 | V25: =SUM(B25:U25) -> 148800
A26: HARD FLOUR | H26: 5000 | V26: =SUM(B26:U26) -> 5000
A27: JET 002 | L27: 5000 | V27: =SUM(B27:U27) -> 5000
A28: JET 153 | L28: 5000 | V28: =SUM(B28:U28) -> 5000
A29: JET 333 | D29: 20000 | V29: =SUM(B29:U29) -> 20000
A30: JET 405โปรตีน 18% | L30: 10000 | V30: =SUM(B30:U30) -> 10000
A31: LUNG SHIN 12kg | L31: 12100 | V31: =SUM(B31:U31) -> 12100
A32: LUNG SHIN 30kg | F32: 3250 | V32: =SUM(B32:U32) -> 3250
A33: NOVA S2 | I33: 3000 | V33: =SUM(B33:U33) -> 3000
A34: SPEED PLUS 222ลาว | H34: 5000 | V34: =SUM(B34:U34) -> 5000
A35: SPEED PLUS 333ลาว | H35: 5000 | V35: =SUM(B35:U35) -> 5000
A36: SPM190 GOAL | Q36: 4000 | V36: =SUM(B36:U36) -> 4000
A37: TRJ | F37: 45472 | V37: =SUM(B37:U37) -> 45472
A38: U-FEED U2(เอส) | S38: 3000 | V38: =SUM(B38:U38) -> 3000
A39: U-FEED U4(เอส) | J39: 6000 | V39: =SUM(B39:U39) -> 6000
A40: U-GOAT14 | O40: 3000 | V40: =SUM(B40:U40) -> 3000
A41: VC 105 | G41: 10000 | V41: =SUM(B41:U41) -> 10000
...

Sheet ค้างทอ8-11-68
A3: ค้างทอ 8/11
A4: ผลรวม ของ ค้างทอ
A5: ป้ายชื่อแถว | B5: 45964 | C5: 45966 | D5: 45967 | E5: 45968 | F5: 45969 | G5: 45970 | H5: 45971 | I5: 45973 | J5: 45974 | K5: 45975 | L5: 45976 | M5: 45977 | N5: 45980 | O5: 45981 | P5: 45982 | Q5: 45983 | R5: 45984 | S5: ผลรวมทั้งหมด | T5: ประมาณการ
A6: WSWT1725800 | K6: 9297.035 | S6: =SUM(B6:R6) -> 9297.035
A7: WSWT1825800 | R7: 32676 | S7: =SUM(B7:R7) -> 32676
A8: WSWT1825800SM | J8: 3899.55 | S8: =SUM(B8:R8) -> 3899.55
A9: WSWT1921720 | F9: 0 | H9: 39488.35 | S9: =SUM(B9:R9) -> 39488.35
A10: WSWT1925800 | K10: 22598.107 | S10: =SUM(B10:R10) -> 22598.107
A11: WSWT1925800SM | I11: 334.5 | S11: =SUM(B11:R11) -> 334.5
A12: WSWT2025800 | D12: 0 | L12: 14349.5 | S12: =SUM(B12:R12) -> 14349.5 | T12: 73342.5
A13: WSWT2025800SM | C13: 0 | D13: 0 | E13: 0 | G13: 0 | I13: 0 | J13: 0 | K13: 0 | L13: 0 | M13: 0 | N13: 0 | O13: 0 | P13: 0 | Q13: 0 | R13: 0 | S13: =SUM(B13:R13) -> 0 | T13: 94297.5
A14: WSWT2025850 | C14: 0 | D14: 0 | E14: 5657.85 | G14: 17727.93 | I14: 28009.85 | J14: 5378.45 | K14: 21932.9 | L14: 16414.75 | M14: 16414.75 | N14: 21220.43 | O14: 11036.3 | P14: 35518.725 | R14: 33248.6 | S14: =SUM(B14:R14) -> 212560.54
A15: WSWT2121670SM | D15: 0 | E15: 0 | H15: 0 | J15: 0 | K15: 0 | L15: 4756.9 | S15: =SUM(B15:R15) -> 4756.9
A16: WSWT2125650 | D16: 0 | I16: 0 | S16: =SUM(B16:R16) -> 0
A17: WSWT2125800 | F17: 0 | S17: =SUM(B17:R17) -> 0
A18: WSWT2321112512551 | G18: 34588.495 | M18: 53892.069 | R18: 53892.069 | S18: =SUM(B18:R18) -> 142372.63
A19: WSWT2325650 | E19: 0 | S19: =SUM(B19:R19) -> 0
A20: WSWT262575051 | B20: 1911.2277 | S20: =SUM(B20:R20) -> 1911.2277
A21: WSWT2625800 | D21: 7059.3 | H21: 12433.3 | S21: =SUM(B21:R21) -> 19492.6
A22: WSWT2825850 | F22: 12860.726 | S22: =SUM(B22:R22) -> 12860.726
A23: WSWTFCL022325650 | G23: 3439.35 | S23: =SUM(B23:R23) -> 3439.35
A24: WSWTSCL052325650 | G24: 0 | S24: =SUM(B24:R24) -> 0
A25: ผลรวมทั้งหมด | B25: =SUM(B6:B24) -> 1911.2277 | C25: =SUM(C6:C24) -> 0 | D25: =SUM(D6:D24) -> 7059.3 | E25: =SUM(E6:E24) -> 5657.85 | F25: =SUM(F6:F24) -> 12860.726 | G25: =SUM(G6:G24) -> 55755.775 | H25: =SUM(H6:H24) -> 51921.65 | I25: =SUM(I6:I24) -> 28344.35 | ... S25: =SUM(S6:S24) -> 520037.01

Sheet 8-11-68
B2: เรียงกำหนดส่ง | D2: ลบ 0 | T2: เรียง 1
B3: ข้อมูลUpdate ณ. วันที่ | D3: 45969 | E3: เวลา | G3: 9.19
A4: วันรับออร์เดอร์/แบบ | B4: เลขที่ SO | C4: ชื่อลูกค้า | E4: 10.3 | I4: น้ำหนัก | L4: บิด/จับจีบ | M4: ถุงใน | Q4: 44873 | S4: วิธีบรรจุ | T4: วันส่ง | U4: จำนวนส่ง | V4: ตัดเย็บ (ใบ) | W4: 44873 | X4: พิมพ์ (ใบ) | Y4: 44876 | Z4: ผ้าทอ (เมตร) Updateณ | AB4: 44876 | AD4: ผ้าเคลือบ(เมตร) | AF4: หมายเหตุ | AG4: เครื่อง
B5: เลขที่ SO | C5: ชื่อลูกค้า | D5: ตรา | E5: กว้าง | F5: ยาว | G5: สี | H5: เคลือบ | I5: กรัม/ใบ | J5: * | K5: aw | L5: บิด/จับจีบ | M5: กว้าง | N5: ยาว | O5: หนา | P5: ใช้(กก.) | Q5: Stock(กก.) | R5: ผลิต(กก.) | S5: วิธีบรรจุ | T5: วันส่ง | U5: จำนวนส่ง | V5: StockFG | W5: ค้างตัด | X5: พิมพ์แล้ว | Y5: ค้างพิมพ์ | Z5: ประเภท | AA5: ใช้ | AB5: Stock | AC5: ค้างทอ | AD5: Stock | AE5: ค้างเคลือบ | AF5: หมายเหตุ | AG5: ที่พิมพ์ได้ | AH5: process | AI5: Lead time | AJ5: วันที่ส่งPL | AK5: เคลือบ | AL5: ได้ ART | AM5: พิมพ์ | AN5: จีบ-บิด | AO5: ตัด-เย็บ | AP5: ทอ | AQ5: สวมถุง | AR5: เย็บปาก | AS5: PT | AT5: ม้วน | AU5: ตัด | AV5: ตอกตาไก่ | AW5: GROUP | AX5: ART | AY5: หมายเหตุปัญหา | AZ5: ราคา/ใบ | BA5: ราคารวม | BB5: workweek | BC5: เส้นเทป | BD5: จำนวน
A6: ประมาณการ | B6: ประมาณการ | C6: บจก.เคอรี่ฟลาวมิลล์ | D6: โบว์แดง 10กก | E6: 16 | F6: 25 | G6: ขาว | H6: 0 | I6: 45 | J6: ± | K6: 5 | L6: ไม่ | M6: ไม่สวมถุงใน | N6: 0 | O6: 0 | P6: 0 | Q6: 0 | R6: 0 | S6: ห่ออัดเบลแบน500 | T6: รอแจ้ง | U6: 5000 | V6: 5333 | W6: 0 | X6: 5370 | Y6: 0 | Z6: WSWT1625800 | AA6: 0 | AB6: 0 | AC6: 0 | AD6: 0 | AE6: 0 | AF6: 0 | AG6: ยังไม่ได้พิมพ์ | AH6: P7 | AI6: 2 | AJ6: รอแจ้ง | AK6: 0 | AL6: #VALUE! | AM6: #VALUE! | AN6: #VALUE! | AO6: #VALUE! | AP6: #VALUE! | AQ6: 0 | AR6: 0 | AS6: 0 | AT6: 0 | AU6: 0 | AV6: 0 | AW6: งานพิมพ์ | AX6: / | AY6: รอเก็บลบสีผสม | AZ6: 0 | BA6: 0 | BB6: 0 | BC6: WRWT25800/WRWT25800 | BD6: 0
A7: 0 | B7: 0 | C7: 0 | D7: 0 | E7: 16 | F7: 25 | G7: ขาว | H7: 0 | I7: 45 | J7: ± | K7: 5 | L7: 0 | M7: 0 | N7: 0 | O7: 0 | P7: 0 | Q7: 0 | R7: 0 | S7: 0 | U7: 0 | V7: 0 | W7: 0 | X7: 0 | Y7: 0 | Z7: WSWT1625800 | AA7: 0 | AB7: 0 | AC7: 0 | AD7: 0 | AE7: 0 | AF7: ระบุในSD | AG7: พร้อมส่ง | AH7: 0 | AI7: Lead time | AJ7: 0 | AK7: 0 | AL7: 0 | AM7: 0 | AN7: 0 | AO7: 0 | AP7: 0 | AQ7: 0 | AR7: 0 | AS7: 0 | AT7: 0 | AU7: 0 | AV7: 0 | AW7: 0 | AX7: 0 | AY7: 0 | AZ7: 0 | BA7: 0 | BB7: 0 | BC7: WRWT160800/WRWT25800 | BD7: 0
A8: 0 | B8: ใบรับคำสั่งซื้อ | C8: โรงสีข้าวธัญญาวัฒน์ | D8: LUNG SHIN 12kg | E8: 17 | F8: 26 | G8: ขาว | H8: 0 | I8: 48 | J8: ± | K8: 5 | L8: ไม่ | M8: ไม่สวมถุงใน | N8: 0 | O8: 0 | P8: 0 | Q8: 0 | R8: 0 | S8: 500กระสอบแบน | T8: 45980 | U8: 12100 | V8: 0 | W8: 12100 | X8: 0 | Y8: 12705 | Z8: WSWT1725800 | AA8: 9297.035 | AB8: 0 | AC8: 9297.035 | AD8: 0 | AE8: 0 | AF8: 0 | AG8: พร้อมส่ง | AH8: P7 | AI8: 2 | AJ8: 45980 | AK8: 0 | AL8: 45971 | AM8: 45978 | AN8: 45979 | AO8: 45979 | AP8: 45975 | AQ8: 0 | AR8: 0 | AS8: 0 | AT8: 0 | AU8: 0 | AV8: 0 | AW8: งานพิมพ์ | AX8: รอART | AY8: 0 | AZ8: 0 | BA8: 0 | BB8: 0 | BC8: WRWT25800/WRWT25800 | BD8: 604.10067
A9: 0 | B9: 0 | C9: 0 | D9: 0 | E9: 17 | F9: 26 | G9: 0 | H9: 0 | I9: 48 | J9: ± | K9: 5 | L9: 0 | M9: 0 | N9: 0 | O9: 0 | P9: 0 | Q9: 0 | R9: 0 | S9: 0 | U9: 0 | V9: 0 | W9: 0 | X9: 0 | Y9: 0 | Z9: WSWT1725800 | AA9: 9297.035 | AB9: 0 | AC9: 9297.035 | AD9: 0 | AE9: 0 | AF9: ระบุในSD | AG9: ผ้าขาว | AH9: 0 | AI9: 0 | AJ9: 0 | AK9: 0 | AL9: 0 | AM9: 0 | AN9: 0 | AO9: 0 | AP9: 0 | AQ9: 0 | AR9: 0 | AS9: 0 | AT9: 0 | AU9: 0 | AV9: 0 | AW9: 0 | AX9: 0 | AY9: 0 | AZ9: 0 | BA9: 0 | BB9: 0 | BC9: WRWT170800/WRWT25800 | BD9: 0
A10: 45950 | B10: MK68-001247 | C10: บจก.ฟาเธอร์ส วิง ซัพพลาย | D10: รถไฟฟ้า | E10: 18 | F10: 30 | G10: ขาว | H10: 0 | I10: 54 | J10: ± | K10: 5 | L10: บิด | M10: 19 | N10: 33 | O10: 40 | P10: 0 | Q10: 0 | R10: 0 | S10: 500กระสอบ | T10: 45968 | U10: 5000 | V10: 5000 | W10: 0 | X10: 5400 | Y10: 0 | Z10: WSWT1825800 | AA10: 0 | AB10: 0 | AC10: 0 | AD10: 0 | AE10: 0 | AF10: 0 | AG10: ยังไม่ได้พิมพ์ | AH10: P9 | AI10: 3 | AJ10: 45968 | AK10: 0 | AL10: 45958 | AM10: 45965 | AN10: 45966 | AO10: 45966 | AP10: 45963 | AQ10: 45967 | AR10: 0 | AS10: 0 | AT10: 0 | AU10: 0 | AV10: 0 | AW10: งานพิมพ์ | AX10: / | AY10: รอส่ง ลูกค้ารับเอง | AZ10: 0 | BA10: 0 | BB10: 0 | BC10: WRWT25800/WRWT25800 | BD10: 0
A11: 45950 | B11: MK68-001247 | C11: บจก.ฟาเธอร์ส วิง ซัพพลาย | D11: รถไฟฟ้าปูนขาวเย็น | E11: 18 | F11: 30 | G11: ขาว | H11: 0 | I11: 54 | J11: ± | K11: 5 | L11: บิด | M11: 19 | N11: 33 | O11: 40 | P11: 0 | Q11: 0 | R11: 0 | S11: 500กระสอบ | T11: 45968 | U11: 20000 | V11: 20057 | W11: 0 | X11: 20800 | Y11: 0 | Z11: WSWT1825800 | AA11: 0 | AB11: 0 | AC11: 0 | AD11: 0 | AE11: 0 | AF11: 0 | AG11: พร้อมส่ง | AH11: P9 | AI11: 3 | AJ11: 45968 | AK11: 0 | AL11: 45958 | AM11: 45965 | AN11: 45966 | AO11: 45966 | AP11: 45963 | AQ11: 45967 | AR11: 0 | AS11: 0 | AT11: 0 | AU11: 0 | AV11: 0 | AW11: งานพิมพ์ | AX11: / | AY11: รอส่ง ลูกค้ารับเอง | AZ11: 0 | BA11: 0 | BB11: 0 | BC11: WRWT25800/WRWT25800 | BD11: 0
A12: 45950 | B12: MK68-001247 | C12: บจก.ฟาเธอร์ส วิง ซัพพลาย | D12: ไม่พิมพ์ | E12: 18 | F12: 30 | G12: ขาว | H12: 0 | I12: 54 | J12: ± | K12: 5 | L12: ไม่ | M12: 19 | N12: 33 | O12: 40 | P12: 0 | Q12: 0 | R12: 0 | S12: 500กระสอบ | T12: 45968 | U12: 3000 | V12: 3064 | W12: 0 | X12: 0 | Y12: 0 | Z12: WSWT1825800 | AA12: 0 | AB12: 0 | AC12: 0 | AD12: 0 | AE12: 0 | AF12: 0 | AG12: ยังไม่ได้พิมพ์ | AH12: P9 | AI12: 3 | AJ12: 45968 | AK12: 0 | AL12: 0 | AM12: 0 | AN12: 0 | AO12: 45964 | AP12: 45963 | AQ12: 45965 | AR12: 0 | AS12: 0 | AT12: 0 | AU12: 0 | AV12: 0 | AW12: ตัด | AX12: 0 | AY12: รอส่ง ลูกค้ารับเอง | AZ12: 0 | BA12: 0 | BB12: 0 | BC12: WRWT25800/WRWT25800 | BD12: 0
