Workbook

Sheet Linkสูตรออร์เดอร์  (2)
B2: เรียงกำหนดส่ง | D2: ลบ 0 | T2: เรียง 1
B3: ข้อมูลUpdate ณ. วันที่ | D3: 45883 | E3: เวลา | G3: 10.53
A4: วันรับออร์เดอร์/แบบ | B4: เลขที่ SO | C4: ชื่อลูกค้า | E4: 10.3 | I4: น้ำหนัก | L4: บิด/จับจีบ | M4: ถุงใน | Q4: =[1]หน้าผ้า!$AC$13 -> 44873 | S4: วิธีบรรจุ | T4: วันส่ง | U4: จำนวนส่ง | V4: ตัดเย็บ (ใบ) | W4: =[1]หน้าผ้า!$AJ$13 -> 44873 | X4: พิมพ์ (ใบ) | Y4: =[1]หน้าผ้า!$AM$13 -> 44876 | Z4: ผ้าทอ (เมตร) Updateณ | AB4: =[1]หน้าผ้า!$AR$12 -> 44876 | AD4: ผ้าเคลือบ(เมตร) | AF4: หมายเหตุ | AG4: เครื่อง
B5: เลขที่ SO | C5: ชื่อลูกค้า | D5: ตรา | E5: กว้าง | F5: ยาว | G5: สี | H5: เคลือบ | I5: กรัม/ใบ | J5: * | K5: aw | L5: บิด/จับจีบ | M5: กว้าง | N5: ยาว | O5: หนา | P5: ใช้(กก.) | Q5: Stock(กก.) | R5: ผลิต(กก.) | S5: วิธีบรรจุ | T5: วันส่ง | U5: จำนวนส่ง | V5: StockFG | W5: ค้างตัด | X5: พิมพ์แล้ว | Y5: ค้างพิมพ์ | Z5: ประเภท | AA5: ใช้ | AB5: Stock | AC5: ค้างทอ | AD5: Stock | AE5: ค้างเคลือบ | AF5: หมายเหตุ | AG5: ที่พิมพ์ได้ | AH5: process | AI5: Lead time | AJ5: วันที่ส่งPL | AK5: เคลือบ | AL5: ได้ ART | AM5: พิมพ์ | AN5: จีบ-บิด | AO5: ตัด-เย็บ | AP5: ทอ | AQ5: สวมถุง | AR5: เย็บปาก | AS5: PT | AT5: ม้วน | AU5: ตัด | AV5: ตอกตาไก่ | AW5: GROUP | AX5: ART | AY5: หมายเหตุปัญหา | AZ5: ราคา/ใบ | BA5: ราคารวม | BB5: workweek | BC5: เส้นเทป | BD5: จำนวน
A6: =[2]หน้าผ้า!C15 -> 0 | B6: =[2]หน้าผ้า!B15 -> 0 | C6: =[2]หน้าผ้า!E15 -> 0 | D6: =[2]หน้าผ้า!F15 -> 0 | E6: =[2]หน้าผ้า!G15 -> 12 | F6: =[2]หน้าผ้า!H15 -> 16 | G6: =[2]หน้าผ้า!I15 -> ขาว | H6: =[2]หน้าผ้า!J15 -> 0 | I6: =[2]หน้าผ้า!L15 -> 25 | J6: =[2]หน้าผ้า!M15 -> ± | K6: =[2]หน้าผ้า!N15 -> 5 | L6: =[2]หน้าผ้า!R15 -> 0 | M6: =[2]หน้าผ้า!T15 -> 0 | N6: =[2]หน้าผ้า!U15 -> 0 | O6: =[2]หน้าผ้า!V15 -> 0 | P6: =[2]หน้าผ้า!AB15 -> 0 | Q6: =[2]หน้าผ้า!AC15 -> 0 | R6: =[2]หน้าผ้า!AD15 -> 0 | S6: =[2]หน้าผ้า!Z15 -> 0 | T6: =[2]หน้าผ้า!X15 -> 0 | U6: =[2]หน้าผ้า!AA15 -> 0 | V6: =[2]หน้าผ้า!AJ15 -> 0 | W6: =[2]หน้าผ้า!AL15 -> 0 | X6: =[2]หน้าผ้า!AM15 -> 0 | Y6: =[2]หน้าผ้า!AN15 -> 0 | Z6: =[2]หน้าผ้า!AO15 -> WSWT1221750 | AA6: =[2]หน้าผ้า!AQ15 -> #REF! | AB6: =[2]หน้าผ้า!AR15 -> #REF! | AC6: =[2]หน้าผ้า!AS15 -> #REF! | AD6: =[2]หน้าผ้า!AT15 -> #REF! | AE6: =[2]หน้าผ้า!AU15 -> #REF! | AF6: =[2]หน้าผ้า!AI15 -> ระบุในSD | AG6: =[3]หน้าผ้า!DC18 -> < Ord 20,000 | AH6: =[2]หน้าผ้า!DL15 -> 0 | AI6: =[2]หน้าผ้า!DM15 -> 0 | AJ6: =[2]หน้าผ้า!DN15 -> 0 | AK6: =[2]หน้าผ้า!DQ15 -> 0 | AL6: =[2]หน้าผ้า!DR15 -> 0 | AM6: =[2]หน้าผ้า!DS15 -> 0 | AN6: =[2]หน้าผ้า!DT15 -> 0 | AO6: =[2]หน้าผ้า!DU15 -> 0 | AP6: =[2]หน้าผ้า!DP15 -> 0 | AQ6: =[2]หน้าผ้า!DW15 -> 0 | AR6: =[2]หน้าผ้า!DX15 -> 0 | AS6: =[2]หน้าผ้า!DY15 -> 0 | AT6: =[2]หน้าผ้า!DZ15 -> 0 | AU6: =[2]หน้าผ้า!EA15 -> 0 | AV6: =[2]หน้าผ้า!EB15 -> 0 | AW6: =[2]หน้าผ้า!EC15 -> 0 | AX6: =[2]หน้าผ้า!ED15 -> 0 | AY6: =[2]หน้าผ้า!AG15 -> 0 | AZ6: =[2]หน้าผ้า!EG15 -> 0 | BA6: =[2]หน้าผ้า!EH15 -> 0 | BB6: =[2]หน้าผ้า!EI15 -> 0 | BC6: =[2]หน้าผ้า!BZ15 -> WRWT120750/WRWT21750 | BD6: =[2]หน้าผ้า!CA15 -> 0
A7: =[2]หน้าผ้า!C16 -> 45860 | B7: =[2]หน้าผ้า!B16 -> MK68-000920 | C7: =[2]หน้าผ้า!E16 -> หจก.ปึงเป้งน้ำ | D7: =[2]หน้าผ้า!F16 -> เกลือตรามือ 10กก. | E7: =[2]หน้าผ้า!G16 -> 14 | F7: =[2]หน้าผ้า!H16 -> 22 | G7: =[2]หน้าผ้า!I16 -> ขาว | H7: =[2]หน้าผ้า!J16 -> ใส | I7: =[2]หน้าผ้า!L16 -> 42 | J7: =[2]หน้าผ้า!M16 -> ± | K7: =[2]หน้าผ้า!N16 -> 5 | L7: =[2]หน้าผ้า!R16 -> ไม่ | M7: =[2]หน้าผ้า!T16 -> ไม่สวมถุงใน | N7: =[2]หน้าผ้า!U16 -> 0 | O7: =[2]หน้าผ้า!V16 -> 0 | P7: =[2]หน้าผ้า!AB16 -> 0 | Q7: =[2]หน้าผ้า!AC16 -> 0 | R7: =[2]หน้าผ้า!AD16 -> 0 | S7: =[2]หน้าผ้า!Z16 -> 500กระสอบแบน | T7: =[2]หน้าผ้า!X16 -> 45884 | U7: =[2]หน้าผ้า!AA16 -> 10000 | V7: =[2]หน้าผ้า!AJ16 -> 10000 | W7: =[2]หน้าผ้า!AL16 -> 0 | X7: =[2]หน้าผ้า!AM16 -> 10710 | Y7: =[2]หน้าผ้า!AN16 -> 0 | Z7: =[2]หน้าผ้า!AO16 -> WSWT1425800 | AA7: =[2]หน้าผ้า!AQ16 -> 0 | AB7: =[2]หน้าผ้า!AR16 -> 0 | AC7: =[2]หน้าผ้า!AS16 -> 0 | AD7: =[2]หน้าผ้า!AT16 -> 0 | AE7: =[2]หน้าผ้า!AU16 -> 0 | AF7: =[2]หน้าผ้า!AI16 -> ลบสีทั้งหมด | AG7: =[3]หน้าผ้า!DC19 -> ยังไม่ได้พิมพ์ | AH7: =[2]หน้าผ้า!DL16 -> P6 | AI7: =[2]หน้าผ้า!DM16 -> 4 | AJ7: =[2]หน้าผ้า!DN16 -> 45884 | AK7: =[2]หน้าผ้า!DQ16 -> 45880 | AL7: =[2]หน้าผ้า!DR16 -> 45873 | AM7: =[2]หน้าผ้า!DS16 -> 45881 | AN7: =[2]หน้าผ้า!DT16 -> 45882 | AO7: =[2]หน้าผ้า!DU16 -> 45883 | AP7: =[2]หน้าผ้า!DP16 -> 45879 | AQ7: =[2]หน้าผ้า!DW16 -> 0 | AR7: =[2]หน้าผ้า!DX16 -> 0 | AS7: =[2]หน้าผ้า!DY16 -> 0 | AT7: =[2]หน้าผ้า!DZ16 -> 0 | AU7: =[2]หน้าผ้า!EA16 -> 0 | AV7: =[2]หน้าผ้า!EB16 -> 0 | AW7: =[2]หน้าผ้า!EC16 -> งานเคลือบ+พิมพ์ | AX7: =[2]หน้าผ้า!ED16 -> / | AY7: =[2]หน้าผ้า!AG16 -> 0 | AZ7: =[2]หน้าผ้า!EG16 -> 0 | BA7: =[2]หน้าผ้า!EH16 -> 0 | BB7: =[2]หน้าผ้า!EI16 -> 0 | BC7: =[2]หน้าผ้า!BZ16 -> WRWT25800/WRWT25800 | BD7: =[2]หน้าผ้า!CA16 -> 0
A8: =[2]หน้าผ้า!C17 -> 0 | B8: =[2]หน้าผ้า!B17 -> 0 | C8: =[2]หน้าผ้า!E17 -> 0 | D8: =[2]หน้าผ้า!F17 -> 0 | E8: =[2]หน้าผ้า!G17 -> 14 | F8: =[2]หน้าผ้า!H17 -> 22 | G8: =[2]หน้าผ้า!I17 -> ขาว | H8: =[2]หน้าผ้า!J17 -> 0 | I8: =[2]หน้าผ้า!L17 -> 36 | J8: =[2]หน้าผ้า!M17 -> ± | K8: =[2]หน้าผ้า!N17 -> 5 | L8: =[2]หน้าผ้า!R17 -> 0 | M8: =[2]หน้าผ้า!T17 -> 0 | N8: =[2]หน้าผ้า!U17 -> 0 | O8: =[2]หน้าผ้า!V17 -> 0 | P8: =[2]หน้าผ้า!AB17 -> 0 | Q8: =[2]หน้าผ้า!AC17 -> 0 | R8: =[2]หน้าผ้า!AD17 -> 0 | S8: =[2]หน้าผ้า!Z17 -> 0 | T8: =[2]หน้าผ้า!X17 -> 0 | U8: =[2]หน้าผ้า!AA17 -> 0 | V8: =[2]หน้าผ้า!AJ17 -> 0 | W8: =[2]หน้าผ้า!AL17 -> 0 | X8: =[2]หน้าผ้า!AM17 -> 0 | Y8: =[2]หน้าผ้า!AN17 -> 0 | Z8: =[2]หน้าผ้า!AO17 -> WSWT1425800 | AA8: =[2]หน้าผ้า!AQ17 -> 0 | AB8: =[2]หน้าผ้า!AR17 -> 0 | AC8: =[2]หน้าผ้า!AS17 -> 0 | AD8: =[2]หน้าผ้า!AT17 -> 0 | AE8: =[2]หน้าผ้า!AU17 -> 0 | AF8: =[2]หน้าผ้า!AI17 -> ระบุในSD | AG8: =[3]หน้าผ้า!DC20 -> พร้อมส่ง | AH8: =[2]หน้าผ้า!DL17 -> 0 | AI8: =[2]หน้าผ้า!DM17 -> Lead time | AJ8: =[2]หน้าผ้า!DN17 -> 0 | AK8: =[2]หน้าผ้า!DQ17 -> 0 | AL8: =[2]หน้าผ้า!DR17 -> 0 | AM8: =[2]หน้าผ้า!DS17 -> 0 | AN8: =[2]หน้าผ้า!DT17 -> 0 | AO8: =[2]หน้าผ้า!DU17 -> 0 | AP8: =[2]หน้าผ้า!DP17 -> 0 | AQ8: =[2]หน้าผ้า!DW17 -> 0 | AR8: =[2]หน้าผ้า!DX17 -> 0 | AS8: =[2]หน้าผ้า!DY17 -> 0 | AT8: =[2]หน้าผ้า!DZ17 -> 0 | AU8: =[2]หน้าผ้า!EA17 -> 0 | AV8: =[2]หน้าผ้า!EB17 -> 0 | AW8: =[2]หน้าผ้า!EC17 -> 0 | AX8: =[2]หน้าผ้า!ED17 -> 0 | AY8: =[2]หน้าผ้า!AG17 -> 0 | AZ8: =[2]หน้าผ้า!EG17 -> 0 | BA8: =[2]หน้าผ้า!EH17 -> 0 | BB8: =[2]หน้าผ้า!EI17 -> 0 | BC8: =[2]หน้าผ้า!BZ17 -> WRWT140800/WRWT25800 | BD8: =[2]หน้าผ้า!CA17 -> 0
A9: =[2]หน้าผ้า!C18 -> 45842 | B9: =[2]หน้าผ้า!B18 -> MK68-000868 | C9: =[2]หน้าผ้า!E18 -> พีมินเนอร์ | D9: =[2]หน้าผ้า!F18 -> พี-มินเนอร์ นิวพลัส | E9: =[2]หน้าผ้า!G18 -> 16 | F9: =[2]หน้าผ้า!H18 -> 28 | G9: =[2]หน้าผ้า!I18 -> ขาว | H9: =[2]หน้าผ้า!J18 -> ใส | I9: =[2]หน้าผ้า!L18 -> 56 | J9: =[2]หน้าผ้า!M18 -> ± | K9: =[2]หน้าผ้า!N18 -> 5 | L9: =[2]หน้าผ้า!R18 -> ไม่ | M9: =[2]หน้าผ้า!T18 -> 19 | N9: =[2]หน้าผ้า!U18 -> 31 | O9: =[2]หน้าผ้า!V18 -> 40 | P9: =[2]หน้าผ้า!AB18 -> 1.1334313 | Q9: =[2]หน้าผ้า!AC18 -> 0 | R9: =[2]หน้าผ้า!AD18 -> 1.1334313 | S9: =[2]หน้าผ้า!Z18 -> 500กระสอบ | T9: =[2]หน้าผ้า!X18 -> รอส่ง | U9: =[2]หน้าผ้า!AA18 -> 4000 | V9: =[2]หน้าผ้า!AJ18 -> 3922 | W9: =[2]หน้าผ้า!AL18 -> 78 | X9: =[2]หน้าผ้า!AM18 -> 5295 | Y9: =[2]หน้าผ้า!AN18 -> 0 | Z9: =[2]หน้าผ้า!AO18 -> WSWT1625800SM | AA9: =[2]หน้าผ้า!AQ18 -> 0 | AB9: =[2]หน้าผ้า!AR18 -> 0 | AC9: =[2]หน้าผ้า!AS18 -> 0 | AD9: =[2]หน้าผ้า!AT18 -> 0 | AE9: =[2]หน้าผ้า!AU18 -> 0 | AF9: =[2]หน้าผ้า!AI18 -> รอส่ง รอลูกค้ามารับเอง | AG9: =[3]หน้าผ้า!DC21 -> พร้อมส่ง | AH9: =[2]หน้าผ้า!DL18 -> P8 | AI9: =[2]หน้าผ้า!DM18 -> 4 | AJ9: =[2]หน้าผ้า!DN18 -> รอส่ง | AK9: =[2]หน้าผ้า!DQ18 -> #VALUE! | AL9: =[2]หน้าผ้า!DR18 -> #VALUE! | AM9: =[2]หน้าผ้า!DS18 -> #VALUE! | AN9: =[2]หน้าผ้า!DT18 -> #VALUE! | AO9: =[2]หน้าผ้า!DU18 -> #VALUE! | AP9: =[2]หน้าผ้า!DP18 -> #VALUE! | AQ9: =[2]หน้าผ้า!DW18 -> #VALUE! | AR9: =[2]หน้าผ้า!DX18 -> 0 | AS9: =[2]หน้าผ้า!DY18 -> 0 | AT9: =[2]หน้าผ้า!DZ18 -> 0 | AU9: =[2]หน้าผ้า!EA18 -> 0 | AV9: =[2]หน้าผ้า!EB18 -> 0 | AW9: =[2]หน้าผ้า!EC18 -> งานเคลือบ+พิมพ์ | AX9: =[2]หน้าผ้า!ED18 -> / | AY9: =[2]หน้าผ้า!AG18 -> 0 | AZ9: =[2]หน้าผ้า!EG18 -> 0 | BA9: =[2]หน้าผ้า!EH18 -> 0 | BB9: =[2]หน้าผ้า!EI18 -> 0 | BC9: =[2]หน้าผ้า!BZ18 -> WRWT25800/WRWT25800 | BD9: =[2]หน้าผ้า!CA18 -> 0
A10: =[2]หน้าผ้า!C19 -> ประมาณการ | B10: =[2]หน้าผ้า!B19 -> ประมาณการ | C10: =[2]หน้าผ้า!E19 -> บจก.ซัน ซีเมนต์ โพรเซส | D10: =[2]หน้าผ้า!F19 -> พระอาทิตย์(ปูนนอน-ชริงค์) | E10: =[2]หน้าผ้า!G19 -> 16 | F10: =[2]หน้าผ้า!H19 -> 25 | G10: =[2]หน้าผ้า!I19 -> ขาว | H10: =[2]หน้าผ้า!J19 -> ใส | I10: =[2]หน้าผ้า!L19 -> 50 | J10: =[2]หน้าผ้า!M19 -> ± | K10: =[2]หน้าผ้า!N19 -> 5 | L10: =[2]หน้าผ้า!R19 -> บิด | M10: =[2]หน้าผ้า!T19 -> 19 | N10: =[2]หน้าผ้า!U19 -> 28 | O10: =[2]หน้าผ้า!V19 -> 40 | P10: =[2]หน้าผ้า!AB19 -> 65.624643 | Q10: =[2]หน้าผ้า!AC19 -> 0 | R10: =[2]หน้าผ้า!AD19 -> 65.624643 | S10: =[2]หน้าผ้า!Z19 -> 500กระสอบ | T10: =[2]หน้าผ้า!X19 -> รอแจ้ง | U10: =[2]หน้าผ้า!AA19 -> 5000 | V10: =[2]หน้าผ้า!AJ19 -> 0 | W10: =[2]หน้าผ้า!AL19 -> 5000 | X10: =[2]หน้าผ้า!AM19 -> 0 | Y10: =[2]หน้าผ้า!AN19 -> 5250 | Z10: =[2]หน้าผ้า!AO19 -> WSWT1625800SM | AA10: =[2]หน้าผ้า!AQ19 -> 3702.05 | AB10: =[2]หน้าผ้า!AR19 -> 0 | AC10: =[2]หน้าผ้า!AS19 -> 3702.05 | AD10: =[2]หน้าผ้า!AT19 -> 0 | AE10: =[2]หน้าผ้า!AU19 -> 3702.05 | AF10: =[2]หน้าผ้า!AI19 -> 0 | AG10: =[3]หน้าผ้า!DC22 -> พร้อมส่ง | AH10: =[2]หน้าผ้า!DL19 -> P8 | AI10: =[2]หน้าผ้า!DM19 -> 4 | AJ10: =[2]หน้าผ้า!DN19 -> รอแจ้ง | AK10: =[2]หน้าผ้า!DQ19 -> #VALUE! | AL10: =[2]หน้าผ้า!DR19 -> #VALUE! | AM10: =[2]หน้าผ้า!DS19 -> #VALUE! | AN10: =[2]หน้าผ้า!DT19 -> #VALUE! | AO10: =[2]หน้าผ้า!DU19 -> #VALUE! | AP10: =[2]หน้าผ้า!DP19 -> #VALUE! | AQ10: =[2]หน้าผ้า!DW19 -> #VALUE! | AR10: =[2]หน้าผ้า!DX19 -> 0 | AS10: =[2]หน้าผ้า!DY19 -> 0 | AT10: =[2]หน้าผ้า!DZ19 -> 0 | AU10: =[2]หน้าผ้า!EA19 -> 0 | AV10: =[2]หน้าผ้า!EB19 -> 0 | AW10: =[2]หน้าผ้า!EC19 -> งานเคลือบ+พิมพ์ | AX10: =[2]หน้าผ้า!ED19 -> รอART | AY10: =[2]หน้าผ้า!AG19 -> 0 | AZ10: =[2]หน้าผ้า!EG19 -> 0 | BA10: =[2]หน้าผ้า!EH19 -> 0 | BB10: =[2]หน้าผ้า!EI19 -> 0 | BC10: =[2]หน้าผ้า!BZ19 -> WRWT25800/WRWT25800 | BD10: =[2]หน้าผ้า!CA19 -> 210.60551
A11: =[2]หน้าผ้า!C20 -> 0 | B11: =[2]หน้าผ้า!B20 -> 0 | C11: =[2]หน้าผ้า!E20 -> 0 | D11: =[2]หน้าผ้า!F20 | E11: =[2]หน้าผ้า!G20 -> 16 | F11: =[2]หน้าผ้า!H20 -> 25 | G11: =[2]หน้าผ้า!I20 -> ขาว | H11: =[2]หน้าผ้า!J20 -> 0 | I11: =[2]หน้าผ้า!L20 -> 45 | J11: =[2]หน้าผ้า!M20 -> ± | K11: =[2]หน้าผ้า!N20 -> 5 | L11: =[2]หน้าผ้า!R20 -> 0 | M11: =[2]หน้าผ้า!T20 -> 0 | N11: =[2]หน้าผ้า!U20 -> 0 | O11: =[2]หน้าผ้า!V20 -> 0 | P11: =[2]หน้าผ้า!AB20 -> 0 | Q11: =[2]หน้าผ้า!AC20 -> 0 | R11: =[2]หน้าผ้า!AD20 -> 0 | S11: =[2]หน้าผ้า!Z20 -> 0 | T11: =[2]หน้าผ้า!X20 -> 0 | U11: =[2]หน้าผ้า!AA20 -> 0 | V11: =[2]หน้าผ้า!AJ20 -> 0 | W11: =[2]หน้าผ้า!AL20 -> 0 | X11: =[2]หน้าผ้า!AM20 -> 0 | Y11: =[2]หน้าผ้า!AN20 -> 0 | Z11: =[2]หน้าผ้า!AO20 -> WSWT1625800SM | AA11: =[2]หน้าผ้า!AQ20 -> 3702.05 | AB11: =[2]หน้าผ้า!AR20 -> 0 | AC11: =[2]หน้าผ้า!AS20 -> 3702.05 | AD11: =[2]หน้าผ้า!AT20 -> 0 | AE11: =[2]หน้าผ้า!AU20 -> 3702.05 | AF11: =[2]หน้าผ้า!AI20 -> ระบุในSD | AG11: =[3]หน้าผ้า!DC23 -> พร้อมส่ง | AH11: =[2]หน้าผ้า!DL20 -> 0 | AI11: =[2]หน้าผ้า!DM20 -> Lead time | AJ11: =[2]หน้าผ้า!DN20 -> 0 | AK11: =[2]หน้าผ้า!DQ20 -> 0 | AL11: =[2]หน้าผ้า!DR20 -> 0 | AM11: =[2]หน้าผ้า!DS20 -> 0 | AN11: =[2]หน้าผ้า!DT20 -> 0 | AO11: =[2]หน้าผ้า!DU20 -> 0 | AP11: =[2]หน้าผ้า!DP20 -> 0 | AQ11: =[2]หน้าผ้า!DW20 -> 0 | AR11: =[2]หน้าผ้า!DX20 -> 0 | AS11: =[2]หน้าผ้า!DY20 -> 0 | AT11: =[2]หน้าผ้า!DZ20 -> 0 | AU11: =[2]หน้าผ้า!EA20 -> 0 | AV11: =[2]หน้าผ้า!EB20 -> 0 | AW11: =[2]หน้าผ้า!EC20 -> 0 | AX11: =[2]หน้าผ้า!ED20 -> 0 | AY11: =[2]หน้าผ้า!AG20 -> 0 | AZ11: =[2]หน้าผ้า!EG20 -> 0 | BA11: =[2]หน้าผ้า!EH20 -> 0 | BB11: =[2]หน้าผ้า!EI20 -> 0 | BC11: =[2]หน้าผ้า!BZ20 -> WRWT160800/WRWT25800 | BD11: =[2]หน้าผ้า!CA20 -> 0
A12: =[2]หน้าผ้า!C21 -> 0 | B12: =[2]หน้าผ้า!B21 -> 0 | C12: =[2]หน้าผ้า!E21 -> 0 | D12: =[2]หน้าผ้า!F21 -> 0 | E12: =[2]หน้าผ้า!G21 -> 16 | F12: =[2]หน้าผ้า!H21 -> 25 | G12: =[2]หน้าผ้า!I21 -> ขาว | H12: =[2]หน้าผ้า!J21 -> 0 | I12: =[2]หน้าผ้า!L21 -> 45 | J12: =[2]หน้าผ้า!M21 -> ± | K12: =[2]หน้าผ้า!N21 -> 5 | L12: =[2]หน้าผ้า!R21 -> 0 | M12: =[2]หน้าผ้า!T21 -> 0 | N12: =[2]หน้าผ้า!U21 -> 0 | O12: =[2]หน้าผ้า!V21 -> 0 | P12: =[2]หน้าผ้า!AB21 -> 0 | Q12: =[2]หน้าผ้า!AC21 -> 0 | R12: =[2]หน้าผ้า!AD21 -> 0 | S12: =[2]หน้าผ้า!Z21 -> 0 | T12: =[2]หน้าผ้า!X21 -> 0 | U12: =[2]หน้าผ้า!AA21 -> 0 | V12: =[2]หน้าผ้า!AJ21 -> 0 | W12: =[2]หน้าผ้า!AL21 -> 0 | X12: =[2]หน้าผ้า!AM21 -> 0 | Y12: =[2]หน้าผ้า!AN21 -> 0 | Z12: =[2]หน้าผ้า!AO21 -> WSWT1625800 | AA12: =[2]หน้าผ้า!AQ21 -> #REF! | AB12: =[2]หน้าผ้า!AR21 -> #REF! | AC12: =[2]หน้าผ้า!AS21 -> #REF! | AD12: =[2]หน้าผ้า!AT21 -> #REF! | AE12: =[2]หน้าผ้า!AU21 -> #REF! | AF12: =[2]หน้าผ้า!AI21 -> ระบุในSD | AG12: =[3]หน้าผ้า!DC24 -> ยังไม่ได้พิมพ์ | AH12: =[2]หน้าผ้า!DL21 -> 0 | AI12: =[2]หน้าผ้า!DM21 -> Lead time | AJ12: =[2]หน้าผ้า!DN21 -> 0 | AK12: =[2]หน้าผ้า!DQ21 -> 0 | AL12: =[2]หน้าผ้า!DR21 -> 0 | AM12: =[2]หน้าผ้า!DS21 -> 0 | AN12: =[2]หน้าผ้า!DT21 -> 0 | AO12: =[2]หน้าผ้า!DU21 -> 0 | AP12: =[2]หน้าผ้า!DP21 -> 0 | AQ12: =[2]หน้าผ้า!DW21 -> 0 | AR12: =[2]หน้าผ้า!DX21 -> 0 | AS12: =[2]หน้าผ้า!DY21 -> 0 | AT12: =[2]หน้าผ้า!DZ21 -> 0 | AU12: =[2]หน้าผ้า!EA21 -> 0 | AV12: =[2]หน้าผ้า!EB21 -> 0 | AW12: =[2]หน้าผ้า!EC21 -> 0 | AX12: =[2]หน้าผ้า!ED21 -> 0 | AY12: =[2]หน้าผ้า!AG21 -> 0 | AZ12: =[2]หน้าผ้า!EG21 -> 0 | BA12: =[2]หน้าผ้า!EH21 -> 0 | BB12: =[2]หน้าผ้า!EI21 -> 0 | BC12: =[2]หน้าผ้า!BZ21 -> WRWT160800/WRWT25800 | BD12: =[2]หน้าผ้า!CA21 -> 0
A13: =[2]หน้าผ้า!C22 -> 0 | B13: =[2]หน้าผ้า!B22 -> 0 | C13: =[2]หน้าผ้า!E22 -> 0 | D13: =[2]หน้าผ้า!F22 -> 0 | E13: =[2]หน้าผ้า!G22 -> 16 | F13: =[2]หน้าผ้า!H22 -> 25 | G13: =[2]หน้าผ้า!I22 -> 0 | H13: =[2]หน้าผ้า!J22 -> 0 | I13: =[2]หน้าผ้า!L22 -> 47 | J13: =[2]หน้าผ้า!M22 -> ± | K13: =[2]หน้าผ้า!N22 -> 5 | L13: =[2]หน้าผ้า!R22 -> 0 | M13: =[2]หน้าผ้า!T22 -> 0 | N13: =[2]หน้าผ้า!U22 -> 0 | O13: =[2]หน้าผ้า!V22 -> 0 | P13: =[2]หน้าผ้า!AB22 -> 0 | Q13: =[2]หน้าผ้า!AC22 -> 0 | R13: =[2]หน้าผ้า!AD22 -> 0 | S13: =[2]หน้าผ้า!Z22 -> 0 | T13: =[2]หน้าผ้า!X22 -> 0 | U13: =[2]หน้าผ้า!AA22 -> 0 | V13: =[2]หน้าผ้า!AJ22 -> 0 | W13: =[2]หน้าผ้า!AL22 -> 0 | X13: =[2]หน้าผ้า!AM22 -> 0 | Y13: =[2]หน้าผ้า!AN22 -> 0 | Z13: =[2]หน้าผ้า!AO22 -> WSWT1621720SMFX | AA13: =[2]หน้าผ้า!AQ22 -> #REF! | AB13: =[2]หน้าผ้า!AR22 -> #REF! | AC13: =[2]หน้าผ้า!AS22 -> #REF! | AD13: =[2]หน้าผ้า!AT22 -> #REF! | AE13: =[2]หน้าผ้า!AU22 -> #REF! | AF13: =[2]หน้าผ้า!AI22 -> ระบุในSD | AG13: =[3]หน้าผ้า!DC25 -> พร้อมส่ง | AH13: =[2]หน้าผ้า!DL22 -> 0 | AI13: =[2]หน้าผ้า!DM22 -> 0 | AJ13: =[2]หน้าผ้า!DN22 -> 0 | AK13: =[2]หน้าผ้า!DQ22 -> 0 | AL13: =[2]หน้าผ้า!DR22 -> 0 | AM13: =[2]หน้าผ้า!DS22 -> 0 | AN13: =[2]หน้าผ้า!DT22 -> 0 | AO13: =[2]หน้าผ้า!DU22 -> 0 | AP13: =[2]หน้าผ้า!DP22 -> 0 | AQ13: =[2]หน้าผ้า!DW22 -> 0 | AR13: =[2]หน้าผ้า!DX22 -> 0 | AS13: =[2]หน้าผ้า!DY22 -> 0 | AT13: =[2]หน้าผ้า!DZ22 -> 0 | AU13: =[2]หน้าผ้า!EA22 -> 0 | AV13: =[2]หน้าผ้า!EB22 -> 0 | AW13: =[2]หน้าผ้า!EC22 -> 0 | AX13: =[2]หน้าผ้า!ED22 -> 0 | AY13: =[2]หน้าผ้า!AG22 -> 0 | AZ13: =[2]หน้าผ้า!EG22 -> 0 | BA13: =[2]หน้าผ้า!EH22 -> 0 | BB13: =[2]หน้าผ้า!EI22 -> 0 | BC13: =[2]หน้าผ้า!BZ22 -> WRWT160720/WRWT21720 | BD13: =[2]หน้าผ้า!CA22 -> 0
A14: =[2]หน้าผ้า!C23 -> 0 | B14: =[2]หน้าผ้า!B23 -> 0 | C14: =[2]หน้าผ้า!E23 -> 0 | D14: =[2]หน้าผ้า!F23 -> 0 | E14: =[2]หน้าผ้า!G23 -> 17 | F14: =[2]หน้าผ้า!H23 -> 26 | G14: =[2]หน้าผ้า!I23 -> 0 | H14: =[2]หน้าผ้า!J23 -> 0 | I14: =[2]หน้าผ้า!L23 -> 48 | J14: =[2]หน้าผ้า!M23 -> ± | K14: =[2]หน้าผ้า!N23 -> 5 | L14: =[2]หน้าผ้า!R23 -> 0 | M14: =[2]หน้าผ้า!T23 -> 0 | N14: =[2]หน้าผ้า!U23 -> 0 | O14: =[2]หน้าผ้า!V23 -> 0 | P14: =[2]หน้าผ้า!AB23 -> 0 | Q14: =[2]หน้าผ้า!AC23 -> 0 | R14: =[2]หน้าผ้า!AD23 -> 0 | S14: =[2]หน้าผ้า!Z23 -> 0 | T14: =[2]หน้าผ้า!X23 -> 0 | U14: =[2]หน้าผ้า!AA23 -> 0 | V14: =[2]หน้าผ้า!AJ23 -> 0 | W14: =[2]หน้าผ้า!AL23 -> 0 | X14: =[2]หน้าผ้า!AM23 -> 0 | Y14: =[2]หน้าผ้า!AN23 -> 0 | Z14: =[2]หน้าผ้า!AO23 -> WSWT1725800 | AA14: =[2]หน้าผ้า!AQ23 -> #REF! | AB14: =[2]หน้าผ้า!AR23 -> #REF! | AC14: =[2]หน้าผ้า!AS23 -> #REF! | AD14: =[2]หน้าผ้า!AT23 -> #REF! | AE14: =[2]หน้าผ้า!AU23 -> #REF! | AF14: =[2]หน้าผ้า!AI23 -> ระบุในSD | AG14: =[3]หน้าผ้า!DC26 -> พร้อมส่ง | AH14: =[2]หน้าผ้า!DL23 -> 0 | AI14: =[2]หน้าผ้า!DM23 -> 0 | AJ14: =[2]หน้าผ้า!DN23 -> 0 | AK14: =[2]หน้าผ้า!DQ23 -> 0 | AL14: =[2]หน้าผ้า!DR23 -> 0 | AM14: =[2]หน้าผ้า!DS23 -> 0 | AN14: =[2]หน้าผ้า!DT23 -> 0 | AO14: =[2]หน้าผ้า!DU23 -> 0 | AP14: =[2]หน้าผ้า!DP23 -> 0 | AQ14: =[2]หน้าผ้า!DW23 -> 0 | AR14: =[2]หน้าผ้า!DX23 -> 0 | AS14: =[2]หน้าผ้า!DY23 -> 0 | AT14: =[2]หน้าผ้า!DZ23 -> 0 | AU14: =[2]หน้าผ้า!EA23 -> 0 | AV14: =[2]หน้าผ้า!EB23 -> 0 | AW14: =[2]หน้าผ้า!EC23 -> 0 | AX14: =[2]หน้าผ้า!ED23 -> 0 | AY14: =[2]หน้าผ้า!AG23 -> 0 | AZ14: =[2]หน้าผ้า!EG23 -> 0 | BA14: =[2]หน้าผ้า!EH23 -> 0 | BB14: =[2]หน้าผ้า!EI23 -> 0 | BC14: =[2]หน้าผ้า!BZ23 -> WRWT170800/WRWT25800 | BD14: =[2]หน้าผ้า!CA23 -> 0
A15: =[2]หน้าผ้า!C24 -> ประมาณการ | B15: =[2]หน้าผ้า!B24 -> ประมาณการ | C15: =[2]หน้าผ้า!E24 -> บจก.ฟาร์เธอร์ส วิง ซัพพลาย | D15: =[2]หน้าผ้า!F24 -> รถไฟ | E15: =[2]หน้าผ้า!G24 -> 18 | F15: =[2]หน้าผ้า!H24 -> 30 | G15: =[2]หน้าผ้า!I24 -> ขาว | H15: =[2]หน้าผ้า!J24 -> 0 | I15: =[2]หน้าผ้า!L24 -> 54 | J15: =[2]หน้าผ้า!M24 -> ± | K15: =[2]หน้าผ้า!N24 -> 5 | L15: =[2]หน้าผ้า!R24 -> บิด | M15: =[2]หน้าผ้า!T24 -> 19 | N15: =[2]หน้าผ้า!U24 -> 33 | O15: =[2]หน้าผ้า!V24 -> 40 | P15: =[2]หน้าผ้า!AB24 -> 232.02999 | Q15: =[2]หน้าผ้า!AC24 -> 0 | R15: =[2]หน้าผ้า!AD24 -> 232.02999 | S15: =[2]หน้าผ้า!Z24 -> 500กระสอบ | T15: =[2]หน้าผ้า!X24 -> รอแจ้ง | U15: =[2]หน้าผ้า!AA24 -> 15000 | V15: =[2]หน้าผ้า!AJ24 -> 0 | W15: =[2]หน้าผ้า!AL24 -> 15000 | X15: =[2]หน้าผ้า!AM24 -> 0 | Y15: =[2]หน้าผ้า!AN24 -> 15750 | Z15: =[2]หน้าผ้า!AO24 -> WSWT1825800 | AA15: =[2]หน้าผ้า!AQ24 -> 13201.65 | AB15: =[2]หน้าผ้า!AR24 -> 2599 | AC15: =[2]หน้าผ้า!AS24 -> 10602.65 | AD15: =[2]หน้าผ้า!AT24 -> 0 | AE15: =[2]หน้าผ้า!AU24 -> 0 | AF15: =[2]หน้าผ้า!AI24 -> 0 | AG15: =[3]หน้าผ้า!DC27 -> รอตัด | AH15: =[2]หน้าผ้า!DL24 -> P9 | AI15: =[2]หน้าผ้า!DM24 -> 3 | AJ15: =[2]หน้าผ้า!DN24 -> รอแจ้ง | AK15: =[2]หน้าผ้า!DQ24 -> 0 | AL15: =[2]หน้าผ้า!DR24 -> #VALUE! | AM15: =[2]หน้าผ้า!DS24 -> #VALUE! | AN15: =[2]หน้าผ้า!DT24 -> #VALUE! | AO15: =[2]หน้าผ้า!DU24 -> #VALUE! | AP15: =[2]หน้าผ้า!DP24 -> #VALUE! | AQ15: =[2]หน้าผ้า!DW24 -> #VALUE! | AR15: =[2]หน้าผ้า!DX24 -> 0 | AS15: =[2]หน้าผ้า!DY24 -> 0 | AT15: =[2]หน้าผ้า!DZ24 -> 0 | AU15: =[2]หน้าผ้า!EA24 -> 0 | AV15: =[2]หน้าผ้า!EB24 -> 0 | AW15: =[2]หน้าผ้า!EC24 -> งานพิมพ์ | AX15: =[2]หน้าผ้า!ED24 -> รอART | AY15: =[2]หน้าผ้า!AG24 -> 0 | AZ15: =[2]หน้าผ้า!EG24 -> 0 | BA15: =[2]หน้าผ้า!EH24 -> 0 | BB15: =[2]หน้าผ้า!EI24 -> 0 | BC15: =[2]หน้าผ้า!BZ24 -> WRWT25800/WRWT25800 | BD15: =[2]หน้าผ้า!CA24 -> 729.46232
A16: =[2]หน้าผ้า!C25 -> 0 | B16: =[2]หน้าผ้า!B25 -> 0 | C16: =[2]หน้าผ้า!E25 | D16: =[2]หน้าผ้า!F25 | E16: =[2]หน้าผ้า!G25 -> 18 | F16: =[2]หน้าผ้า!H25 -> 30 | G16: =[2]หน้าผ้า!I25 -> ขาว | H16: =[2]หน้าผ้า!J25 -> 0 | I16: =[2]หน้าผ้า!L25 -> 54 | J16: =[2]หน้าผ้า!M25 -> ± | K16: =[2]หน้าผ้า!N25 -> 5 | L16: =[2]หน้าผ้า!R25 -> 0 | M16: =[2]หน้าผ้า!T25 -> 0 | N16: =[2]หน้าผ้า!U25 -> 0 | O16: =[2]หน้าผ้า!V25 -> 0 | P16: =[2]หน้าผ้า!AB25 -> 0 | Q16: =[2]หน้าผ้า!AC25 -> 0 | R16: =[2]หน้าผ้า!AD25 -> 0 | S16: =[2]หน้าผ้า!Z25 -> 0 | T16: =[2]หน้าผ้า!X25 -> 0 | U16: =[2]หน้าผ้า!AA25 -> 0 | V16: =[2]หน้าผ้า!AJ25 -> 0 | W16: =[2]หน้าผ้า!AL25 -> 0 | X16: =[2]หน้าผ้า!AM25 -> 0 | Y16: =[2]หน้าผ้า!AN25 -> 0 | Z16: =[2]หน้าผ้า!AO25 -> WSWT1825800 | AA16: =[2]หน้าผ้า!AQ25 -> 13201.65 | AB16: =[2]หน้าผ้า!AR25 -> 2599 | AC16: =[2]หน้าผ้า!AS25 -> 10602.65 | AD16: =[2]หน้าผ้า!AT25 -> 0 | AE16: =[2]หน้าผ้า!AU25 -> 0 | AF16: =[2]หน้าผ้า!AI25 -> ระบุในSD | AG16: =[3]หน้าผ้า!DC28 -> พิมพ์ไม่ครบ | AH16: =[2]หน้าผ้า!DL25 -> 0 | AI16: =[2]หน้าผ้า!DM25 -> Lead time | AJ16: =[2]หน้าผ้า!DN25 -> 0 | AK16: =[2]หน้าผ้า!DQ25 -> 0 | AL16: =[2]หน้าผ้า!DR25 -> 0 | AM16: =[2]หน้าผ้า!DS25 -> 0 | AN16: =[2]หน้าผ้า!DT25 -> 0 | AO16: =[2]หน้าผ้า!DU25 -> 0 | AP16: =[2]หน้าผ้า!DP25 -> 0 | AQ16: =[2]หน้าผ้า!DW25 -> 0 | AR16: =[2]หน้าผ้า!DX25 -> 0 | AS16: =[2]หน้าผ้า!DY25 -> 0 | AT16: =[2]หน้าผ้า!DZ25 -> 0 | AU16: =[2]หน้าผ้า!EA25 -> 0 | AV16: =[2]หน้าผ้า!EB25 -> 0 | AW16: =[2]หน้าผ้า!EC25 -> 0 | AX16: =[2]หน้าผ้า!ED25 -> 0 | AY16: =[2]หน้าผ้า!AG25 -> 0 | AZ16: =[2]หน้าผ้า!EG25 -> 0 | BA16: =[2]หน้าผ้า!EH25 -> 0 | BB16: =[2]หน้าผ้า!EI25 -> 0 | BC16: =[2]หน้าผ้า!BZ25 -> WRWT25800/WRWT25800 | BD16: =[2]หน้าผ้า!CA25 -> 0
A17: =[2]หน้าผ้า!C26 -> 0 | B17: =[2]หน้าผ้า!B26 -> 0 | C17: =[2]หน้าผ้า!E26 -> 0 | D17: =[2]หน้าผ้า!F26 | E17: =[2]หน้าผ้า!G26 -> 18 | F17: =[2]หน้าผ้า!H26 -> 25 | G17: =[2]หน้าผ้า!I26 -> ขาว | H17: =[2]หน้าผ้า!J26 -> 0 | I17: =[2]หน้าผ้า!L26 -> 50 | J17: =[2]หน้าผ้า!M26 -> ± | K17: =[2]หน้าผ้า!N26 -> 5 | L17: =[2]หน้าผ้า!R26 -> 0 | M17: =[2]หน้าผ้า!T26 -> 0 | N17: =[2]หน้าผ้า!U26 -> 0 | O17: =[2]หน้าผ้า!V26 -> 0 | P17: =[2]หน้าผ้า!AB26 -> 0 | Q17: =[2]หน้าผ้า!AC26 -> 0 | R17: =[2]หน้าผ้า!AD26 -> 0 | S17: =[2]หน้าผ้า!Z26 -> 0 | T17: =[2]หน้าผ้า!X26 -> 0 | U17: =[2]หน้าผ้า!AA26 -> 0 | V17: =[2]หน้าผ้า!AJ26 -> 0 | W17: =[2]หน้าผ้า!AL26 -> 0 | X17: =[2]หน้าผ้า!AM26 -> 0 | Y17: =[2]หน้าผ้า!AN26 -> 0 | Z17: =[2]หน้าผ้า!AO26 -> WSWT1825800SM | AA17: =[2]หน้าผ้า!AQ26 -> #REF! | AB17: =[2]หน้าผ้า!AR26 -> #REF! | AC17: =[2]หน้าผ้า!AS26 -> #REF! | AD17: =[2]หน้าผ้า!AT26 -> #REF! | AE17: =[2]หน้าผ้า!AU26 -> #REF! | AF17: =[2]หน้าผ้า!AI26 -> ระบุในSD | AG17: =[3]หน้าผ้า!DC29 -> ยังไม่ได้พิมพ์ | AH17: =[2]หน้าผ้า!DL26 -> 0 | AI17: =[2]หน้าผ้า!DM26 -> Lead time | AJ17: =[2]หน้าผ้า!DN26 -> 0 | AK17: =[2]หน้าผ้า!DQ26 -> 0 | AL17: =[2]หน้าผ้า!DR26 -> 0 | AM17: =[2]หน้าผ้า!DS26 -> 0 | AN17: =[2]หน้าผ้า!DT26 -> 0 | AO17: =[2]หน้าผ้า!DU26 -> 0 | AP17: =[2]หน้าผ้า!DP26 -> 0 | AQ17: =[2]หน้าผ้า!DW26 -> 0 | AR17: =[2]หน้าผ้า!DX26 -> 0 | AS17: =[2]หน้าผ้า!DY26 -> 0 | AT17: =[2]หน้าผ้า!DZ26 -> 0 | AU17: =[2]หน้าผ้า!EA26 -> 0 | AV17: =[2]หน้าผ้า!EB26 -> 0 | AW17: =[2]หน้าผ้า!EC26 -> 0 | AX17: =[2]หน้าผ้า!ED26 -> 0 | AY17: =[2]หน้าผ้า!AG26 -> 0 | AZ17: =[2]หน้าผ้า!EG26 -> 0 | BA17: =[2]หน้าผ้า!EH26 -> 0 | BB17: =[2]หน้าผ้า!EI26 -> 0 | BC17: =[2]หน้าผ้า!BZ26 -> WRWT180800/WRWT25800 | BD17: =[2]หน้าผ้า!CA26 -> 0
... A575: =[2]หน้าผ้า!C584 -> 0 | B575: =[2]หน้าผ้า!B584 -> 0 | C575: =[2]หน้าผ้า!E584 -> 0 | D575: =[2]หน้าผ้า!F584 -> 0 | E575: =[2]หน้าผ้า!G584 -> 0 | F575: =[2]หน้าผ้า!H584 -> 0 | G575: =[2]หน้าผ้า!I584 -> 0 | H575: =[2]หน้าผ้า!J584 -> 0 | I575: =[2]หน้าผ้า!L584 -> 0 | J575: =[2]หน้าผ้า!M584 -> 0 | K575: =[2]หน้าผ้า!N584 -> 0 | L575: =[2]หน้าผ้า!R584 -> 0 | M575: =[2]หน้าผ้า!T584 -> 0 | N575: =[2]หน้าผ้า!U584 -> 0 | O575: =[2]หน้าผ้า!V584 -> 0 | P575: =[2]หน้าผ้า!AB584 -> 0 | Q575: =[2]หน้าผ้า!AC584 -> 0 | R575: =[2]หน้าผ้า!AD584 -> 0 | S575: =[2]หน้าผ้า!Z584 -> 0 | T575: =[2]หน้าผ้า!X584 -> 0 | U575: =[2]หน้าผ้า!AA584 -> 0 | V575: =[2]หน้าผ้า!AJ584 -> 0 | W575: =[2]หน้าผ้า!AL584 -> 0 | X575: =[2]หน้าผ้า!AM584 -> 0 | Y575: =[2]หน้าผ้า!AN584 -> 0 | Z575: =[2]หน้าผ้า!AO584 -> 0 | AA575: =[2]หน้าผ้า!AQ584 -> 0 | AB575: =[2]หน้าผ้า!AR584 -> 0 | AC575: =[2]หน้าผ้า!AS584 -> 0 | AD575: =[2]หน้าผ้า!AT584 -> 0 | AE575: =[2]หน้าผ้า!AU584 -> 0 | AF575: =[2]หน้าผ้า!AI584 -> 0 | AG575: =[3]หน้าผ้า!DC587 -> 0 | AH575: =[2]หน้าผ้า!DL584 -> 0 | AI575: =[2]หน้าผ้า!DM584 -> 0 | AJ575: =[2]หน้าผ้า!DN584 -> 0 | AK575: =[2]หน้าผ้า!DQ584 -> 0 | AL575: =[2]หน้าผ้า!DR584 -> 0 | AM575: =[2]หน้าผ้า!DS584 -> 0 | AN575: =[2]หน้าผ้า!DT584 -> 0 | AO575: =[2]หน้าผ้า!DU584 -> 0 | AP575: =[2]หน้าผ้า!DP584 -> 0 | AQ575: =[2]หน้าผ้า!DW584 -> 0 | AR575: =[2]หน้าผ้า!DX584 -> 0 | AS575: =[2]หน้าผ้า!DY584 -> 0 | AT575: =[2]หน้าผ้า!DZ584 -> 0 | AU575: =[2]หน้าผ้า!EA584 -> 0 | AV575: =[2]หน้าผ้า!EB584 -> 0 | AW575: =[2]หน้าผ้า!EC584 -> 0 | AX575: =[2]หน้าผ้า!ED584 -> 0 | AY575: =[2]หน้าผ้า!AG584 -> 0 | AZ575: =[2]หน้าผ้า!EG584 -> 0 | BA575: =[2]หน้าผ้า!EH584 -> 0 | BB575: =[2]หน้าผ้า!EI584 -> 0 | BC575: =[2]หน้าผ้า!BZ584 -> 0 | BD575: =[2]หน้าผ้า!CA584 -> 0

Sheet 4(Order+FC)
A2: เลขที่ SO | B2: (หลายรายการ)
A3: วันส่ง | B3: (หลายรายการ)
A4: ชื่อลูกค้า | B4: (ทั้งหมด)
K5: 9
A6: ประเภท | B6: ผลรวม ของ จำนวนส่ง | C6: ผลรวม ของ ค้างพิมพ์ | D6: ผลรวม ของ ค้างตัด | E6: ผลรวม ของ ใช้ | F6: ผลรวม ของ Stock | G6: ผลรวม ของ ค้างทอ
A7: WSWT1625800SM | B7: 5000 | C7: 5250 | D7: 5000 | E7: 4121.15 | F7: 3175 | G7: 946.15 | H7: =+J7-I7 -> 946.15 | J7: =G7 -> 946.15
A8: WSWT1825800 | B8: 15000 | C8: 15750 | D8: 15000 | E8: 13201.65 | F8: 6301 | G8: 6900.65 | H8: =+J8-I8 -> 6900.65 | J8: =G8 -> 6900.65
A9: WSWT1825800SM | B9: 5000 | C9: 0 | D9: 5000 | E9: 0 | F9: 0 | G9: 0 | H9: =+J9-I9 -> 0 | J9: =G9 -> 0
A10: WSWT1921720 | B10: 660000 | C10: 642600 | D10: 652206 | E10: 608030.28 | F10: 67964.05 | G10: 540066.23 | H10: =+J10-I10 -> 540066.23 | J10: =G10 -> 540066.23
A11: WSWT1925800 | B11: 190000 | C11: 156905.7 | D11: 187450 | E11: 130578.42 | F11: 32419.416 | G11: 98159 | H11: =+J11-I11 -> 98159 | J11: =G11 -> 98159
A12: WSWT2025650 | B12: 30000 | C12: 10500 | D12: 30000 | E12: 28359.1 | F12: 0 | G12: 28359.1 | H12: =+J12-I12 -> 28359.1 | J12: =G12 -> 28359.1 | K12: 40000 | L12: =+K5*K12 -> 360000 | M12: =+L12-J12 -> 331640.9
A13: WSWT2025800 | B13: 358907 | C13: 283092.6 | D13: 353907 | E13: 288507.63 | F13: 76716.989 | G13: 211790.64 | H13: =+J13-I13 -> 211790.64 | J13: =G13 -> 211790.64 | K13: 14000 | L13: =+K13*K5 -> 126000 | M13: =+L13-J13 -> -85790.644
A14: WSWT2025800SM | B14: 296127 | C14: 284550 | D14: 292809 | E14: 292238.43 | F14: 17378.68 | G14: 274859.75 | H14: =+J14-I14 -> 274859.75 | J14: =G14 -> 274859.75
A15: WSWT2121670SM | B15: 359000 | C15: 367500 | D15: 353179 | E15: 376491.5 | F15: 80270.7 | G15: 296220.8 | H15: =+J15-I15 -> 296220.8 | J15: =G15 -> 296220.8 | K15: 20000 | L15: =+K15*K5 -> 180000 | M15: =+L15-J15 -> -116220.8
A16: WSWT2125650 | B16: 50000 | C16: 10500 | D16: 49900 | E16: 53953.537 | F16: 18812.7 | G16: 35140.837 | H16: =+J16-I16 -> 35140.837 | J16: =G16 -> 35140.837
A17: WSWT2321112512551 | B17: 96600 | C17: 44967.3 | D17: 46311 | E17: 46067.5 | F17: 46067.5 | G17: 0 | H17: =+J17-I17 -> 0 | J17: =G17 -> 0
A18: WSWT2321112512551VN | B18: 100000 | C18: 0 | D18: 0 | E18: 0 | F18: 0 | G18: 0 | H18: =+J18-I18 -> 0 | J18: =G18 -> 0
A19: WSWT2321750 | B19: 15000 | C19: 15750 | D19: 15000 | E19: 16135.35 | F19: 7327 | G19: 8808.35 | H19: 0 | I19: 54000 | J19: =G19 -> 8808.35
A20: WSWT2325650 | B20: 90000 | C20: 73500 | D20: 77754 | E20: 69430.9 | F20: 29756.1 | G20: 39674.8 | H20: =+J20-I20 -> 39674.8 | J20: =G20 -> 39674.8
A21: WSWT2625650 | B21: 8000 | C21: 8400 | D21: 8000 | E21: 9499.6 | F21: 0 | G21: 9499.6 | H21: =+J21-I21 -> 9499.6 | J21: =G21 -> 9499.6
A22: WSWT262575051 | B22: 10000 | C22: 0 | D22: 10000 | E22: 11315.7 | F22: 6000 | G22: 5315.7 | H22: =+J22-I22 -> 5315.7 | J22: =G22 -> 5315.7
A23: WSWT2625800 | B23: 10000 | C23: 0 | D23: 10000 | E23: 12433.3 | F23: 12433.3 | G23: 0 | H23: =+J23-I23 -> 0 | J23: =G23 -> 0
A24: WSWT2625850SM | B24: 106500 | C24: 85575 | D24: 99114 | E24: 119981.34 | F24: 9788 | G24: 110193.34 | H24: =+J24-I24 -> 110193.34 | J24: =G24 -> 110193.34
A25: WSWT2825850 | B25: 55000 | C25: 52500 | D25: 55000 | E25: 66147.95 | F25: 11275.45 | G25: 54872.5 | H25: =+J25-I25 -> 54872.5 | J25: =G25 -> 54872.5
A26: ผลรวมทั้งหมด | B26: 2460134 | C26: 2057340.6 | D26: 2265630 | E26: 2146493.3 | F26: 425685.88 | G26: 1720807.5 | H26: =+J26-I26 -> 1720807.5 | J26: =G26 -> 1720807.5
H27: =+J27-I27 -> 0 | J27: =G27 -> 0
H28: =+J28-I28 -> 0 | J28: =G28 -> 0 | M28: =+GETPIVOTDATA("ผลรวม ของ ใช้",$A$6)+H29+H33 -> 5669299.9
H29: =SUM(H7:H28) -> 3432806.6 | I29: =SUM(I7:I28) -> 54000 | J29: =SUM(J7:J28) -> 3441614.9
H32: =+H26 -> 1720807.5 | I32: 85 | J32: =+(H32+H29)*I32 -> 4.3805719e+08 | K32: =+J32/1000 -> 438057.19
H33: 90000 | I33: 95 | J33: =+H33*I33 -> 8550000 | K33: =+J33/1000 -> 8550
H35: =+H32+H33+H29 -> 5243614 | K35: =+K32+K33 -> 446607.19
N36: 705222
A37: ยอดส่ง 1/2/68 - 17/2/68 | B37: 1565717 | H37: 15 | I37: =+H35/H37 -> 349574.27
N38: =+H35+N36 -> 5948836
I39: =+H37*110000 -> 1650000
B41: =+B29+B37+B31-110000 -> 1455717 | C41: =+C29+C37+C31 -> 0 | D41: =+D29+D37+D31-110000 -> -110000 | E41: =+E29+E37+E31 -> 0 | F41: =+F29+F37+F31 -> 0 | G41: =+G29+G37+G31 -> 0
B43: 3218150
B45: =+B43-B41 -> 1762433
C47: =+C41/9 -> 0 | D47: =+D41/9 -> -12222.222

Sheet 9(Order)
A2: เลขที่ SO | B2: (หลายรายการ)
A3: วันส่ง | B3: (หลายรายการ)
A4: ชื่อลูกค้า | B4: (ทั้งหมด)
A6: ประเภท | B6: ผลรวม ของ จำนวนส่ง | C6: ผลรวม ของ ค้างพิมพ์ | D6: ผลรวม ของ ค้างตัด | E6: ผลรวม ของ ใช้ | F6: ผลรวม ของ Stock | G6: ผลรวม ของ ค้างทอ
A7: WSWT2321112512551 | B7: 100000 | C7: 105000 | D7: 100000 | E7: 107569 | F7: 0 | G7: 107569 | I7: =+K7-J7 -> 107569 | K7: =G7 -> 107569
A8: ผลรวมทั้งหมด | B8: 100000 | C8: 105000 | D8: 100000 | E8: 107569 | F8: 0 | G8: 107569 | I8: =+K8-J8 -> 107569 | K8: =G8 -> 107569
I9: =+K9-J9 -> 0 | K9: =G9 -> 0
I10: =+K10-J10 -> 0 | K10: =G10 -> 0
I11: =+K11-J11 -> 0 | K11: =G11 -> 0
I12: =+K12-J12 -> 0 | K12: =G12 -> 0
I13: =+K13-J13 -> 0 | K13: =G13 -> 0
I14: =+K14-J14 -> 0 | K14: =G14 -> 0
I15: =+K15-J15 -> 0 | K15: =G15 -> 0
I16: =+K16-J16 -> 0 | K16: =G16 -> 0
I17: 0 | J17: 54000 | K17: =G17 -> 0
I18: =+K18-J18 -> 0 | K18: =G18 -> 0
I19: =+K19-J19 -> 0 | K19: =G19 -> 0
I20: =+K20-J20 -> 0 | K20: =G20 -> 0
I21: =+K21-J21 -> 0 | K21: =G21 -> 0
I22: =+K22-J22 -> 0 | K22: =G22 -> 0
I23: =+K23-J23 -> 0 | K23: =G23 -> 0
I24: =+K24-J24 -> 0 | K24: =G24 -> 0
I25: =+K25-J25 -> 0 | K25: =G25 -> 0
I26: =SUM(I7:I25) -> 215138 | J26: =SUM(J7:J25) -> 54000 | K26: =SUM(K7:K25) -> 215138
D34: =D18 -> 0
D36: =D20 -> 0
A37: ยอดส่ง 1/4/68 - 12/4/68 | B37: 887615
A38: Order+ส่ง | B38: =++B25+B37 -> 887615
A39: ประมาณการ | B39: 262000 | C39: 238350 | D39: 262000 | E39: 279847.04 | F39: 60825.09 | G39: 219021.95
A41: Order+ส่ง+ประมาณการ | B41: =+B25+B37+B39+B33 -> 1149615 | C41: =+C25+C37+C39+C33 -> 238350 | D41: =+D25+D37+D39+D33 -> 262000 | E41: =+E25+E37+E39+E33 -> 279847.04 | F41: =+F25+F37+F39+F33 -> 60825.09 | G41: =+G25+G37+G39+G33 -> 219021.95
B43: 3171376
B45: =+B41-B43 -> -2021761 | C45: =+$B$45 -> -2021761 | D45: =+$B$45 -> -2021761 | F45: =+$B$45 -> -2021761
D47: =+D41/6 -> 43666.667

Sheet 7(Order) แยกลูกค้า
A1: เลขที่ SO | B1: (หลายรายการ)
A2: วันส่ง | B2: (หลายรายการ)
A4: ประเภท | B4: ชื่อลูกค้า | C4: ผลรวม ของ จำนวนส่ง | D4: ผลรวม ของ ค้างพิมพ์ | E4: ผลรวม ของ ค้างตัด | F4: ผลรวม ของ Stock | G4: ผลรวม ของ ค้างทอ | I4: vn
A5: WSWT1625800SM | B5: พีมินเนอร์ | C5: 4000 | D5: 0 | E5: 78 | F5: 0 | G5: 0 | H5: =G5 -> 0
A6: WSWT1625800SM ผลรวม | C6: 4000 | D6: 0 | E6: 78 | F6: 0 | G6: 0 | H6: =G6 -> 0
A7: WSWT1725800 | B7: โรงสีข้าวธัญญาวัฒน์ | C7: 30250 | D7: 31762.5 | E7: 30250 | F7: 23242.588 | G7: 0 | H7: =G7 -> 0
A8: WSWT1725800 ผลรวม | C8: 30250 | D8: 31762.5 | E8: 30250 | F8: 23242.588 | G8: 0 | H8: =G8 -> 0
A9: WSWT1921720 | B9: บจก.เคอรี่ฟลาวมิลล์ | C9: 60000 | D9: 0 | E9: 715 | F9: 0 | G9: 0 | H9: =G9 -> 0
A10: WSWT1921720 ผลรวม | C10: 60000 | D10: 0 | E10: 715 | F10: 0 | G10: 0 | H10: =G10 -> 0
A11: WSWT1925800SM | B11: บจก.เอเชี่ยนเคมิคัล | C11: 15000 | D11: 15750 | E11: 15000 | F11: 11525.25 | G11: 0 | H11: =G11 -> 0
A12: WSWT1925800SM ผลรวม | C12: 15000 | D12: 15750 | E12: 15000 | F12: 11525.25 | G12: 0 | H12: =G12 -> 0
A13: WSWT2021750 | B13: คุณสมบัติ นิมวชิรวัฒนา | C13: 5000 | D13: 0 | E13: 0 | F13: 0 | G13: 0 | H13: =G13 -> 0
A14: WSWT2021750 ผลรวม | C14: 5000 | D14: 0 | E14: 0 | F14: 0 | G14: 0 | H14: =G14 -> 0
A15: WSWT2025800 | B15: บจก.เคอรี่ฟลาวมิลล์ | C15: 5000 | D15: 0 | E15: 0 | F15: 0 | G15: 0 | H15: =G15 -> 0
B16: บจก.อินเทคค์ โกลบอล | C16: 239360 | D16: 187027.05 | E16: 193360 | F16: 195810.91 | G16: 0 | H16: =G16 -> 0
A17: WSWT2025800 ผลรวม | C17: 244360 | D17: 187027.05 | E17: 193360 | F17: 195810.91 | G17: 0 | H17: =G17 -> 0
A18: WSWT2025800SM | B18: บจก.อินเทคค์ โกลบอล | C18: 49152 | D18: 15876 | E18: 35299 | F18: 15841.98 | G18: 0 | H18: =G18 -> 0
B19: บจก.วีซีเอฟ | C19: 25000 | D19: 0 | E19: 122 | F19: 0 | G19: 0 | H19: =G19 -> 0
A20: WSWT2025800SM ผลรวม | C20: 74152 | D20: 15876 | E20: 35421 | F20: 15841.98 | G20: 0 | H20: =G20 -> 0
A21: WSWT2121670SM | B21: บจก.เอ็นบี ดิสทริบิวชั่น | C21: 20000 | D21: 1827 | E21: 2000 | F21: 1965.2856 | G21: 0 | H21: =G21 -> 0
A22: WSWT2121670SM ผลรวม | C22: 20000 | D22: 1827 | E22: 2000 | F22: 1965.2856 | G22: 0 | H22: =G22 -> 0
A23: WSWT2125800 | B23: โรงสีข้าวธัญญาวัฒน์ | C23: 4100 | D23: 0 | E23: 4100 | F23: 0 | G23: 0 | H23: =G23 -> 0
A24: WSWT2125800 ผลรวม | C24: 4100 | D24: 0 | E24: 4100 | F24: 0 | G24: 0 | H24: =G24 -> 0
A25: WSWT262575051 | B25: คุณธนนท์ อุทัยไพศาลวงศ์ | C25: 10000 | D25: 0 | E25: 0 | F25: 0 | G25: 0 | H25: =G25 -> 0
A26: WSWT262575051 ผลรวม | C26: 10000 | D26: 0 | E26: 0 | F26: 0 | G26: 0 | H26: =G26 -> 0
A27: WSWT2625850SM | B27: บจก.ที.ซี.ยูเนี่ยน อโกรเทค | C27: 15000 | D27: 0 | E27: 15000 | F27: 18649.95 | G27: 0 | H27: =G27 -> 0
A28: WSWT2625850SM ผลรวม | C28: 15000 | D28: 0 | E28: 15000 | F28: 18649.95 | G28: 0 | H28: =G28 -> 0
A29: ผลรวมทั้งหมด | C29: 481862 | D29: 252242.55 | E29: 295924 | F29: 267035.96 | G29: 0 | H29: =G29 -> 0
H30: =G30 -> 0
H31: =G31 -> 0
H32: =G32 -> 0
H33: =G33 -> 0
H34: =G34 -> 0
H35: =G35 -> 0
H36: =G36 -> 0
H37: =G37 -> 0
H38: =G38 -> 0
H39: =G39 -> 0
H40: =G40 -> 0
H41: =G41 -> 0
...

Sheet 7(Fc) แยกลูกค้า
A1: เลขที่ SO | B1: ประมาณการ
A2: วันส่ง | B2: (หลายรายการ) | D2: 12
A4: ประเภท | B4: ชื่อลูกค้า | C4: ผลรวม ของ จำนวนส่ง | D4: ผลรวม ของ ค้างพิมพ์ | E4: ผลรวม ของ ค้างตัด | F4: ผลรวม ของ ใช้ | G4: ผลรวม ของ Stock | H4: ผลรวม ของ ค้างทอ
A5: WSWT1625800SM | B5: บจก.ซัน ซีเมนต์ โพรเซส | C5: 5000 | D5: 5250 | E5: 5000 | F5: 3702.05 | G5: 0 | H5: 3702.05
A6: WSWT1625800SM ผลรวม | C6: 5000 | D6: 5250 | E6: 5000 | F6: 3702.05 | G6: 0 | H6: 3702.05
A7: WSWT1825800 | B7: บจก.ฟาร์เธอร์ส วิง ซัพพลาย | C7: 15000 | D7: 15750 | E7: 15000 | F7: 13201.65 | G7: 6301 | H7: 6900.65
A8: WSWT1825800 ผลรวม | C8: 15000 | D8: 15750 | E8: 15000 | F8: 13201.65 | G8: 6301 | H8: 6900.65
A9: WSWT1921720 | B9: บจก.เคอรี่ฟลาวมิลล์ | C9: 572000 | D9: 600600 | E9: 572000 | F9: 503422.92 | G9: 17840 | H9: 485582.92
A10: WSWT1921720 ผลรวม | C10: 572000 | D10: 600600 | E10: 572000 | F10: 503422.92 | G10: 17840 | H10: 485582.92
A11: WSWT1925800 | B11: บจก.ไลม์มาสเตอร์ | C11: 20000 | D11: 21000 | E11: 20000 | F11: 18719.8 | G11: 0 | H11: 18719.8
B12: บจก.เอ็กเซลเล้นท์ | C12: 40000 | D12: 42000 | E12: 40000 | F12: 35204.4 | G12: 0 | H12: 35204.4
B13: บจก.ซีแมน | C13: 60000 | D13: 63000 | E13: 60000 | F13: 49453.8 | G13: 0 | H13: 49453.8
A14: WSWT1925800 ผลรวม | C14: 120000 | D14: 126000 | E14: 120000 | F14: 103378 | G14: 0 | H14: 103378
A15: WSWT1925800SM | B15: บจก.เอเชี่ยนเคมิคัล | C15: 15000 | D15: 15750 | E15: 15000 | F15: 11525.25 | G15: 11525.25 | H15: 0
A16: WSWT1925800SM ผลรวม | C16: 15000 | D16: 15750 | E16: 15000 | F16: 11525.25 | G16: 11525.25 | H16: 0
A17: WSWT2025650 | B17: บจก.หนองบัวฟีดมิลล์ | C17: 20000 | D17: 0 | E17: 20000 | F17: 17602.2 | G17: 0 | H17: 17602.2
A18: WSWT2025650 ผลรวม | C18: 20000 | D18: 0 | E18: 20000 | F18: 17602.2 | G18: 0 | H18: 17602.2
A19: WSWT2025800 | B19: บจก.อินเทคค์ โกลบอล | C19: 55000 | D19: 57750 | E19: 55000 | F19: 57626.25 | G19: 0 | H19: 57626.25
A20: WSWT2025800 ผลรวม | C20: 55000 | D20: 57750 | E20: 55000 | F20: 57626.25 | G20: 0 | H20: 57626.25
A21: WSWT2025800SM | B21: บจก.ไทยธรรมดี | C21: 20000 | D21: 21000 | E21: 20000 | F21: 21513.8 | G21: 0 | H21: 21513.8
B22: บจก.อินเทคค์ โกลบอล | C22: 100000 | D22: 105000 | E22: 100000 | F22: 104775 | G22: 0 | H22: 104775
B23: บจก.เอสพีเอ็ม อาหารสัตว์ | C23: 20000 | D23: 21000 | E23: 20000 | F23: 22072.6 | G23: 0 | H23: 22072.6
B24: บจก.ซันฟีด | C24: 100000 | D24: 105000 | E24: 100000 | F24: 110363 | G24: 0 | H24: 110363
A25: WSWT2025800SM ผลรวม | C25: 240000 | D25: 252000 | E25: 240000 | F25: 258724.4 | G25: 0 | H25: 258724.4
A26: WSWT2025850 | B26: บจก.ซันฟีด | C26: 100000 | D26: 105000 | E26: 100000 | F26: 113157 | G26: 0 | H26: 113157
A27: WSWT2025850 ผลรวม | C27: 100000 | D27: 105000 | E27: 100000 | F27: 113157 | G27: 0 | H27: 113157
A28: WSWT2121670SM | B28: บจก.ที.ซี.ยูเนี่ยน อโกรเทค | C28: 10000 | D28: 10500 | E28: 10000 | F28: 10756.9 | G28: 10756.9 | H28: 0
B29: บจก.แอมโก้เวท | C29: 300000 | D29: 315000 | E29: 300000 | F29: 322707 | G29: 0 | H29: 322707
B30: บจก.เอ็นบี | C30: 20000 | D30: 21000 | E30: 20000 | F30: 21513.8 | G30: 0 | H30: 21513.8
A31: WSWT2121670SM ผลรวม | C31: 330000 | D31: 346500 | E31: 330000 | F31: 354977.7 | G31: 10756.9 | H31: 344220.8
A32: WSWT2125650 | B32: บจก.หนองบัวฟีดมิลล์ | C32: 30000 | D32: 0 | E32: 30000 | F32: 33108.9 | G32: 4212 | H32: 28896.9
B33: บจก.ไลม์มาสเตอร์ | C33: 10000 | D33: 10500 | E33: 10000 | F33: 9918.7 | G33: 9918.7 | H33: 0
A34: WSWT2125650 ผลรวม | C34: 40000 | D34: 10500 | E34: 40000 | F34: 43027.6 | G34: 14130.7 | H34: 28896.9
A35: WSWT2325650 | B35: พันธุ์ข้าว | C35: 40000 | D35: 42000 | E35: 40000 | F35: 39674.8 | G35: 0 | H35: 39674.8
B36: บจก.ซิเบลโก้(สบปราบ) | C36: 30000 | D36: 31500 | E36: 30000 | F36: 29756.1 | G36: 29756.1 | H36: 0
A37: WSWT2325650 ผลรวม | C37: 70000 | D37: 73500 | E37: 70000 | F37: 69430.9 | G37: 29756.1 | H37: 39674.8
A38: WSWT2625650 | B38: บจก.กบินทร์อินทรีย์ | C38: 8000 | D38: 8400 | E38: 8000 | F38: 9499.6 | G38: 0 | H38: 9499.6
A39: WSWT2625650 ผลรวม | C39: 8000 | D39: 8400 | E39: 8000 | F39: 9499.6 | G39: 0 | H39: 9499.6
A40: WSWT2625800 | B40: บจก.ที.ซี.ยูเนี่ยน อโกรเทค | C40: 10000 | D40: 0 | E40: 10000 | F40: 12433.3 | G40: 12433.3 | H40: 0
A41: WSWT2625800 ผลรวม | C41: 10000 | D41: 0 | E41: 10000 | F41: 12433.3 | G41: 12433.3 | H41: 0
...

Sheet 8(Order+Fc) แยกลูกค้า
A1: เลขที่ SO | B1: (หลายรายการ)
A2: วันส่ง | B2: (หลายรายการ) | D2: 12 | I2: เมตร | J2: vn | K2: ใบ | P2: วัน
A4: ประเภท | B4: ชื่อลูกค้า | C4: ผลรวม ของ จำนวนส่ง | D4: ผลรวม ของ ค้างพิมพ์ | E4: ผลรวม ของ ค้างตัด | F4: ผลรวม ของ ใช้ | G4: ผลรวม ของ Stock | H4: ผลรวม ของ ค้างทอ
A5: WSWT1425800 | B5: หจก.ปึงเป้งน้ำ | C5: 10000 | D5: 0 | E5: 0 | F5: 0 | G5: 0 | H5: 0 | I5: =H5 -> 0
A6: WSWT1425800 ผลรวม | C6: 10000 | D6: 0 | E6: 0 | F6: 0 | G6: 0 | H6: 0
A7: WSWT1921720 | B7: บจก.เคอรี่ฟลาวมิลล์ | C7: 195000 | D7: 110250 | E7: 155000 | F7: 146196.05 | G7: 118603.45 | H7: 27592.6 | I7: =H7 -> 27592.6
A8: WSWT1921720 ผลรวม | C8: 195000 | D8: 110250 | E8: 155000 | F8: 146196.05 | G8: 118603.45 | H8: 27592.6 | I8: =H8 -> 27592.6
A9: WSWT19251000SM | B9: บจก.อินเทคค์ โกลบอล | C9: 5040 | D9: 5292 | E9: 5040 | F9: 4999.0248 | G9: 4999.0248 | H9: 0 | I9: =H9 -> 0
A10: WSWT19251000SM ผลรวม | C10: 5040 | D10: 5292 | E10: 5040 | F10: 4999.0248 | G10: 4999.0248 | H10: 0 | I10: =H10 -> 0
A11: WSWT1925800 | B11: บจก.เพรซิเดนท์ฟลาวมิลล์ | C11: 30000 | D11: 31500 | E11: 30000 | F11: 26403.3 | G11: 26403.3 | H11: 0
B12: บจก.ซีแมน | C12: 40000 | D12: 11182.5 | E12: 37500 | F12: 9216.952 | G12: 9216.952 | H12: 0 | I12: =H12 -> 0
B13: บจก.เอ็กเซลเล้นท์ | C13: 5000 | D13: 0 | E13: 5000 | F13: 0 | G13: 0 | H13: 0
A14: WSWT1925800 ผลรวม | C14: 75000 | D14: 42682.5 | E14: 72500 | F14: 35620.252 | G14: 35620.252 | H14: 0 | I14: =H14 -> 0 | P14: 15000 | Q14: =+K14/P14 -> 0
A15: WSWT1925800SM | B15: บจก.เอเชี่ยนเคมิคัล | C15: 10000 | D15: 10500 | E15: 10000 | F15: 7683.5 | G15: 7683.5 | H15: 0
A16: WSWT1925800SM ผลรวม | C16: 10000 | D16: 10500 | E16: 10000 | F16: 7683.5 | G16: 7683.5 | H16: 0 | I16: =H16 -> 0
A17: WSWT2025700 | B17: บจก.เอ็มทีเอส | C17: 5000 | D17: 0 | E17: 5000 | F17: 0 | G17: 0 | H17: 0 | I17: =H17 -> 0
A18: WSWT2025700 ผลรวม | C18: 5000 | D18: 0 | E18: 5000 | F18: 0 | G18: 0 | H18: 0 | I18: =H18 -> 0
A19: WSWT2025800 | B19: บจก.เบทาโกร | C19: 210000 | D19: 145509 | E19: 190000 | F19: 151897.11 | G19: 151897.11 | H19: 0 | I19: =H19 -> 0
B20: บจก.อินเทคค์ โกลบอล | C20: 227120 | D20: 179019.75 | E20: 201680 | F20: 178662.07 | G20: 87540.568 | H20: 91121.5 | I20: =H20 -> 91121.5 | P20: 16000 | Q20: =+K20/P20 -> 0
B21: โรงสีข้าวธัญญาวัฒน์ | C21: 9200 | D21: 9510.9 | E21: 9058 | F21: 8478.1974 | G21: 8478.1974 | H21: 0
A22: WSWT2025800 ผลรวม | C22: 446320 | D22: 334039.65 | E22: 400738 | F22: 339037.37 | G22: 247915.87 | H22: 91121.5 | I22: =H22 -> 91121.5
A23: WSWT2025800SM | B23: บจก.อินเทคค์ โกลบอล | C23: 126109 | D23: 132414.45 | E23: 126109 | F23: 131977.17 | G23: 27202.174 | H23: 104775
B24: บจก.เอพีเอ็ม อะโกร | C24: 26000 | D24: 18900 | E24: 22000 | F24: 19865.34 | G24: 0 | H24: 19865.34 | I24: =H24 -> 19865.34
B25: บจก.วีซีเอฟ | C25: 100000 | D25: 21000 | E25: 45000 | F25: 21513.8 | G25: 20565.9 | H25: 947.9
B26: คุณนพวินทร์ รัตนเศรษฐ์เมธา | C26: 5000 | D26: 5250 | E26: 5000 | F26: 5518.15 | G26: 5518.15 | H26: 0 | I26: =H26 -> 0
A27: WSWT2025800SM ผลรวม | C27: 257109 | D27: 177564.45 | E27: 198109 | F27: 178874.46 | G27: 53286.224 | H27: 125588.24
A28: WSWT2121670SM | B28: บจก.เอพีเอ็ม อะโกร | C28: 4000 | D28: 0 | E28: 0 | F28: 0 | G28: 0 | H28: 0 | I28: =H28 -> 0
B29: บจก.บลูฟาโล่ | C29: 5000 | D29: 0 | E29: 0 | F29: 0 | G29: 0 | H29: 0 | I29: =H29 -> 0
B30: บจก.เอ็นบี ดิสทริบิวชั่น | C30: 30000 | D30: 31500 | E30: 30000 | F30: 32270.7 | G30: 32270.7 | H30: 0 | I30: =H30 -> 0
B31: บจก.ทีเจทีเทรดเดอร์ | C31: 1000 | D31: 0 | E31: 1000 | F31: 1103.63 | G31: 1103.63 | H31: 0 | P31: 15000 | Q31: =+K31/P31 -> 0
A32: WSWT2121670SM ผลรวม | C32: 40000 | D32: 31500 | E32: 31000 | F32: 33374.33 | G32: 33374.33 | H32: 0 | I32: =H32 -> 0
A33: WSWT2125650 | B33: บจก.ไลม์มาสเตอร์ | C33: 20000 | D33: 21000 | E33: 20000 | F33: 19837.4 | G33: 19837.4 | H33: 0 | I33: =H33 -> 0
B34: ทีเจที | C34: 1500 | D34: 0 | E34: 0 | F34: 0 | G34: 0 | H34: 0 | I34: =H34 -> 0
A35: WSWT2125650 ผลรวม | C35: 21500 | D35: 21000 | E35: 20000 | F35: 19837.4 | G35: 19837.4 | H35: 0 | I35: =H35 -> 0
A36: WSWT23211125120SMFX | B36: โรงสีธัญญกิจ(ราชบุรี) | C36: 10000 | D36: 10500 | E36: 10000 | F36: 10756.9 | G36: 0 | H36: 10756.9 | I36: =H36 -> 10756.9
A37: WSWT23211125120SMFX ผลรวม | C37: 10000 | D37: 10500 | E37: 10000 | F37: 10756.9 | G37: 0 | H37: 10756.9 | I37: =H37 -> 10756.9
A38: WSWT2321112512551 | B38: บจก.น้ำตาลทิพย์สุโขทัย | C38: 100000 | D38: 18708.9 | E38: 50000 | F38: 20124.977 | G38: 12962 | H38: 7162.9766 | I38: =H38 -> 7162.9766
A39: WSWT2321112512551 ผลรวม | C39: 100000 | D39: 18708.9 | E39: 50000 | F39: 20124.977 | G39: 12962 | H39: 7162.9766 | I39: =H39 -> 7162.9766
A40: WSWT2325650 | B40: พันธุ์ข้าว | C40: 30000 | D40: 31500 | E40: 30000 | F40: 29756.1 | G40: 25382 | H40: 4374.1 | I40: =H40 -> 4374.1
B41: บจก.ซิเบลโก้(สบปราบ) | C41: 30000 | D41: 31500 | E41: 30000 | F41: 29756.1 | G41: 0 | H41: 29756.1
...

Sheet 8(Order)
A2: เลขที่ SO | B2: (หลายรายการ)
A3: วันส่ง | B3: (หลายรายการ)
A4: ชื่อลูกค้า | B4: (ทั้งหมด)
A6: ประเภท | B6: ผลรวม ของ จำนวนส่ง | C6: ผลรวม ของ ค้างพิมพ์ | D6: ผลรวม ของ ค้างตัด | E6: ผลรวม ของ ใช้ | F6: ผลรวม ของ Stock | G6: ผลรวม ของ ค้างทอ
A7: WSWT1425800 | B7: 10000 | C7: 0 | D7: 0 | E7: 0 | F7: 0 | G7: 0
A8: WSWT1921720 | B8: 195000 | C8: 110250 | D8: 155000 | E8: 146196.05 | F8: 118603.45 | G8: 27592.6
A9: WSWT19251000SM | B9: 5040 | C9: 5292 | D9: 5040 | E9: 4999.0248 | F9: 4999.0248 | G9: 0
A10: WSWT1925800 | B10: 75000 | C10: 42682.5 | D10: 72500 | E10: 35620.252 | F10: 35620.252 | G10: 0
A11: WSWT1925800SM | B11: 10000 | C11: 10500 | D11: 10000 | E11: 7683.5 | F11: 7683.5 | G11: 0 | L11: =76*2500 -> 190000
A12: WSWT2025700 | B12: 5000 | C12: 0 | D12: 5000 | E12: 0 | F12: 0 | G12: 0
A13: WSWT2025800 | B13: 276320 | C13: 155539.65 | D13: 230738 | E13: 160919.87 | F13: 160919.87 | G13: 0
A14: WSWT2025800SM | B14: 157109 | C14: 72564.45 | D14: 98109 | E14: 74099.464 | F14: 53286.224 | G14: 20813.24
A15: WSWT2121670SM | B15: 40000 | C15: 31500 | D15: 31000 | E15: 33374.33 | F15: 33374.33 | G15: 0
A16: WSWT2125650 | B16: 21500 | C16: 21000 | D16: 20000 | E16: 19837.4 | F16: 19837.4 | G16: 0
A17: WSWT23211125120SMFX | B17: 10000 | C17: 10500 | D17: 10000 | E17: 10756.9 | F17: 0 | G17: 10756.9
A18: WSWT2321112512551 | B18: 100000 | C18: 18708.9 | D18: 50000 | E18: 20124.977 | F18: 12962 | G18: 7162.9766
A19: WSWT2325650 | B19: 20000 | C19: 21000 | D19: 20000 | E19: 22072.6 | F19: 22072.6 | G19: 0
A20: WSWT262575051 | B20: 5000 | C20: 0 | D20: 0 | E20: 0 | F20: 0 | G20: 0
A21: WSWT2625800 | B21: 10000 | C21: 10087.35 | D21: 9607 | E21: 11139.413 | F21: 11139.413 | G21: 0
A22: WSWT2625850SM | B22: 15000 | C22: 0 | D22: 0 | E22: 0 | F22: 0 | G22: 0
A23: WSWT2825850 | B23: 84000 | C23: 52500 | D23: 50000 | E23: 59372.5 | F23: 34819 | G23: 24553.5
... A25: ผลรวมทั้งหมด | B25: 1048969 | C25: 572624.85 | D25: 776994 | E25: 616114.99 | F25: 525235.77 | G25: 90879.217
A37: ยอดส่ง 1/1/68 - 17/1/68 | B37: 1287052
A38: Order+ส่ง | B38: =++B22+B37 -> 1302052
A39: ประมาณการ | I39: 0
A41: Order+ส่ง+ประมาณการ | B41: =+B22+B37+B39+B29 -> 1302052 | C41: =+C22+C37+C39+C29 -> 0 | D41: =+D22+D37+D39+D29 -> 0 | E41: =+E22+E37+E39+E29 -> 0 | F41: =+F22+F37+F39+F29 -> 0 | G41: =+G22+G37+G39+G29 -> 0
B43: 3000000 | I43: 9
B45: =+B41-B43 -> -1697948
D46: =+D22/I43 -> 0
C47: =+C41/I43 -> 0 | D47: =+D41/I43 -> 0 | G47: =+G41/I43 -> 0

Sheet 6(Order) แยกลูกค้า
A1: เลขที่ SO | B1: (หลายรายการ)
A2: วันส่ง | B2: รอแจ้ง
A4: ประเภท | B4: ชื่อลูกค้า | C4: ผลรวม ของ จำนวนส่ง | D4: ผลรวม ของ ค้างพิมพ์ | E4: ผลรวม ของ ค้างตัด | F4: ผลรวม ของ Stock | G4: ผลรวม ของ ค้างทอ | I4: vn
A5: WSWT1921720 | B5: บจก.เคอรี่ฟลาวมิลล์ | C5: 5000 | D5: 0 | E5: 5000 | F5: 0 | G5: 0 | H5: =G5 -> 0
A6: WSWT1921720 ผลรวม | C6: 5000 | D6: 0 | E6: 5000 | F6: 0 | G6: 0 | H6: =G6 -> 0
A7: WSWT19251000SM | B7: บจก.อินเทคค์ โกลบอล | C7: 503 | D7: 0 | E7: 503 | F7: 0 | G7: 0 | H7: =G7 -> 0
A8: WSWT19251000SM ผลรวม | C8: 503 | D8: 0 | E8: 503 | F8: 0 | G8: 0
A9: WSWT2025800SM | B9: บจก.อินเทคค์ โกลบอล | C9: 13286 | D9: 0 | E9: 13219 | F9: 0 | G9: 0 | H9: =G9 -> 0
B10: บจก.เอพีเอ็ม อะโกร | C10: 5000 | D10: 5250 | E10: 5000 | F10: 0 | G10: 5518.15 | H10: =G10 -> 5518.15
B11: บจก.เอสพีเอ็ม อาหารสัตว์ | C11: 23000 | D11: 24150 | E11: 23000 | F11: 0 | G11: 25551.13
A12: WSWT2025800SM ผลรวม | C12: 41286 | D12: 29400 | E12: 41219 | F12: 0 | G12: 31069.28 | H12: =G12 -> 31069.28
A13: WSWT2121670SM | B13: บจก.ที.ซี.ยูเนี่ยน อโกรเทค | C13: 40000 | D13: 42000 | E13: 40000 | F13: 43027.6 | G13: 0 | H13: =G13 -> 0
B14: บจก.เอพีเอ็ม อะโกร | C14: 7000 | D14: 7350 | E14: 7000 | F14: 7725.41 | G14: 0 | H14: =G14 -> 0
B15: บจก.เอสพีเอ็ม อาหารสัตว์ | C15: 5000 | D15: 5250 | E15: 5000 | F15: 0 | G15: 5518.15
A16: WSWT2121670SM ผลรวม | C16: 52000 | D16: 54600 | E16: 52000 | F16: 50753.01 | G16: 5518.15 | H16: =G16 -> 5518.15
A17: WSWT2321112512551 | B17: บจก.น้ำตาลทิพย์สุโขทัย | C17: 436278 | D17: 458091.9 | E17: 436278 | F17: 0 | G17: 469299.88
A18: WSWT2321112512551 ผลรวม | C18: 436278 | D18: 458091.9 | E18: 436278 | F18: 0 | G18: 469299.88 | H18: =G18 -> 469299.88
A19: WSWT2321750 | B19: บจก.แอมโก้เวท | C19: 1000 | D19: 0 | E19: 1000 | F19: 1159.51 | G19: 0 | H19: =G19 -> 0
A20: WSWT2321750 ผลรวม | C20: 1000 | D20: 0 | E20: 1000 | F20: 1159.51 | G20: 0 | H20: =G20 -> 0
A21: ผลรวมทั้งหมด | C21: 536067 | D21: 542091.9 | E21: 536000 | F21: 51912.52 | G21: 505887.31 | H21: =G21 -> 505887.31
H23: =G23 -> 0
H25: =G25 -> 0
H27: =G27 -> 0
H28: =G28 -> 0
H29: =G29 -> 0
H31: =G31 -> 0
H32: =G32 -> 0
H33: =G33 -> 0
H34: =G34 -> 0
H35: =G35 -> 0
H36: =G36 -> 0
H37: =G37 -> 0
... H68: =G68 -> 0
H70: =SUM(H5:H69) -> 1017292.8
D119: Cap พิมพ์ | E119: Cap ตัด | F119: Stock 16/7 บ่าย | G119: Cap ทอ | I119: วันทงาน
B120: lส่ง | C120: 1-16/7 | D120: 160000 | E120: 160000 | G120: 120000 | I120: 12
C121: 1975256 | D121: =+D120*I120 -> 1920000 | E121: =+E120*I120 -> 1920000 | F121: 825147 | G121: =+G120*I120 -> 1440000
A122: เบทาโกรส่งแล้ว | B122: 20700 | C122: 424374
A123: เบทาโกรส่งแล้ว | B123: 20800 | C123: 155973
C126: รวมส่ง+ค้างส่ง | D126: ส่วนต่างCapคงเหลือ | E126: ส่วนต่างCapคงเหลือ | F126: คงเหลือ
...

Sheet 6(Fc) แยกลูกค้
A1: เลขที่ SO | B1: ประมาณการ
A2: วันส่ง | B2: (หลายรายการ) | D2: 12
A4: ประเภท | B4: ชื่อลูกค้า | C4: ผลรวม ของ จำนวนส่ง | D4: ผลรวม ของ ค้างพิมพ์ | E4: ผลรวม ของ ค้างตัด | F4: ผลรวม ของ Stock | G4: ผลรวม ของ ใช้ | H4: ผลรวม ของ ค้างทอ
A5: WSWT1921720 | B5: บจก.เคอรี่ฟลาวมิลล์ | C5: 250000 | D5: 262500 | E5: 250000 | F5: 0 | G5: 233997.5 | H5: 233997.5
A6: WSWT1921720 ผลรวม | C6: 250000 | D6: 262500 | E6: 250000 | F6: 0 | G6: 233997.5 | H6: 233997.5
A7: WSWT1925800 | B7: บจก.เพรซิเดนท์ฟลาวมิลล์ | C7: 140000 | D7: 147000 | E7: 140000 | F7: 56115 | G7: 123215.4 | H7: 67100.4
B8: บจก.ไลม์มาสเตอร์ | C8: 20000 | D8: 20755.35 | E8: 19767 | F8: 18501.714 | G8: 18501.714 | H8: 0
B9: บจก.เอ็กเซลเล้นท์ | C9: 40000 | D9: 42000 | E9: 40000 | F9: 0 | G9: 35204.4 | H9: 35204.4
A10: WSWT1925800 ผลรวม | C10: 200000 | D10: 209755.35 | E10: 199767 | F10: 74616.714 | G10: 176921.51 | H10: 102304.8
A11: WSWT2025800 | B11: บจก.อินเทคค์ โกลบอล | C11: 250000 | D11: 262500 | E11: 250000 | F11: 0 | G11: 261937.5 | H11: 261937.5
A12: WSWT2025800 ผลรวม | C12: 250000 | D12: 262500 | E12: 250000 | F12: 0 | G12: 261937.5 | H12: 261937.5
A13: WSWT2025800SM | B13: บจก.ไทยธรรมดี | C13: 20000 | D13: 21000 | E13: 20000 | F13: 0 | G13: 21513.8 | H13: 21513.8
B14: บจก.อินเทคค์ โกลบอล | C14: 100000 | D14: 105000 | E14: 100000 | F14: 56666 | G14: 104775 | H14: 48109
B15: บจก.เอสพีเอ็ม อาหารสัตว์ | C15: 20000 | D15: 21000 | E15: 20000 | F15: 0 | G15: 22072.6 | H15: 22072.6
A16: WSWT2025800SM ผลรวม | C16: 140000 | D16: 147000 | E16: 140000 | F16: 56666 | G16: 148361.4 | H16: 91695.4
A17: WSWT2121670SM | B17: บจก.แอมโก้เวท | C17: 300000 | D17: 315000 | E17: 300000 | F17: 159370 | G17: 322707 | H17: 163337
B18: บจก.เอ็นบี ดิสทริบิวชั่น | C18: 40000 | D18: 42000 | E18: 40000 | F18: 43027.6 | G18: 43027.6 | H18: 0
A19: WSWT2121670SM ผลรวม | C19: 340000 | D19: 357000 | E19: 340000 | F19: 202397.6 | G19: 365734.6 | H19: 163337
A20: ผลรวมทั้งหมด | C20: 1180000 | D20: 1238755.4 | E20: 1179767 | F20: 333680.31 | G20: 1186952.5 | H20: 853272.2
H43: =+GETPIVOTDATA("ผลรวม ของ ค้างทอ",$A$4)+H41 -> 853272.2
I119: วันทงาน
I120: 12
C121: 1975256 | D121: =+D120*I120 -> 0 | E121: =+E120*I120 -> 0 | F121: 825147 | G121: =+G120*I120 -> 0
A122: เบทาโกรส่งแล้ว | B122: 20700 | C122: 424374
A123: เบทาโกรส่งแล้ว | B123: 20800 | C123: 155973
C126: รวมส่ง+ค้างส่ง | D126: ส่วนต่างCapคงเหลือ | E126: ส่วนต่างCapคงเหลือ | F126: คงเหลือ
C127: =+C50+C121 -> 1975256 | D127: =+D121-D50 -> 0 | E127: =+E121-E50 -> 0 | F127: =+F121-F50 -> 825147 | G127: =+G121-G50 -> 0
B129: 20700VN 20/7 | G129: 350000

Sheet ค้างทอ2-8-68
A3: ผลรวม ของ ค้างทอ
A4: ป้ายชื่อแถว | B4: 45870 | C4: 45871 | D4: 45872 | E4: 45873 | F4: 45875 | G4: 45877 | H4: 45878 | I4: 45879 | J4: 45880 | K4: 45882 | L4: 45883 | M4: 45884 | N4: 45885 | O4: 45887 | P4: 45889 | Q4: 45890 | R4: 45892 | S4: 45893 | T4: ผลรวมทั้งหมด
A5: WSWT1425800 | G5: 2699.72 | I5: 0 | T5: =SUM(B5:S5) -> 2699.72
A6: WSWT1825800SM | H6: 1160.1 | T6: =SUM(B6:S6) -> 1160.1
A7: WSWT1921720 | B7: 5001.9 | C7: 28079.7 | D7: 37439.6 | E7: 14039.85 | H7: 19837.4 | J7: 14039.85 | L7: 23399.75 | N7: 23958.55 | O7: 23399.75 | Q7: 23399.75 | R7: 23958.55 | S7: 37439.6 | T7: =SUM(B7:S7) -> 273994.25
A8: WSWT1925800 | M8: 32969.2 | T8: =SUM(B8:S8) -> 32969.2
A9: WSWT2025800 | M9: 61976.09 | P9: 26892.25 | T9: =SUM(B9:S9) -> 88868.34
A10: WSWT2025800SM | C10: 0 | M10: 0 | P10: 2497.45 | T10: =SUM(B10:S10) -> 2497.45
A11: WSWT2121670SM | D11: 0 | F11: 0 | T11: =SUM(B11:S11) -> 0
A12: WSWT2321112512551 | H12: 0 | K12: 47828.5 | T12: =SUM(B12:S12) -> 47828.5
A13: WSWT2325650 | H13: 0 | T13: =SUM(B13:S13) -> 0
A14: WSWT2625850SM | B14: 0 | H14: 0 | K14: 4019.95 | T14: =SUM(B14:S14) -> 4019.95
A15: WSWT2825850 | H15: 21379.051 | T15: =SUM(B15:S15) -> 21379.051
A16: ผลรวมทั้งหมด | B16: =SUM(B5:B15) -> 5001.9 | C16: =SUM(C5:C15) -> 28079.7 | D16: =SUM(D5:D15) -> 37439.6 | E16: =SUM(E5:E15) -> 14039.85 | F16: =SUM(F5:F15) -> 0 | G16: =SUM(G5:G15) -> 2699.72 | H16: =SUM(H5:H15) -> 42376.551 | I16: =SUM(I5:I15) -> 0 | ... T16: =SUM(T5:T15) -> 475416.56

Sheet 14-8-68
B2: เรียงกำหนดส่ง | D2: ลบ 0 | T2: เรียง 1
B3: ข้อมูลUpdate ณ. วันที่ | D3: 45883 | E3: เวลา | G3: 10.53
A4: วันรับออร์เดอร์/แบบ | B4: เลขที่ SO | C4: ชื่อลูกค้า | E4: 10.3 | I4: น้ำหนัก | L4: บิด/จับจีบ | M4: ถุงใน | Q4: 44873 | S4: วิธีบรรจุ | T4: วันส่ง | U4: จำนวนส่ง | V4: ตัดเย็บ (ใบ) | W4: 44873 | X4: พิมพ์ (ใบ) | Y4: 44876 | Z4: ผ้าทอ (เมตร) Updateณ | AB4: 44876 | AD4: ผ้าเคลือบ(เมตร) | AF4: หมายเหตุ | AG4: เครื่อง
A5: วันรับออร์เดอร์/แบบ | B5: เลขที่ SO | C5: ชื่อลูกค้า | D5: ตรา | E5: กว้าง | F5: ยาว | G5: สี | H5: เคลือบ | I5: กรัม/ใบ | J5: * | K5: aw | L5: บิด/จับจีบ | M5: กว้าง | N5: ยาว | O5: หนา | P5: ใช้(กก.) | Q5: Stock(กก.) | R5: ผลิต(กก.) | S5: วิธีบรรจุ | T5: วันส่ง | U5: จำนวนส่ง | V5: StockFG | W5: ค้างตัด | X5: พิมพ์แล้ว | Y5: ค้างพิมพ์ | Z5: ประเภท | AA5: ใช้ | AB5: Stock | AC5: ค้างทอ | AD5: Stock | AE5: ค้างเคลือบ | AF5: หมายเหตุ | AG5: ที่พิมพ์ได้ | AH5: process | AI5: Lead time | AJ5: วันที่ส่งPL | AK5: เคลือบ | AL5: ได้ ART | AM5: พิมพ์ | AN5: จีบ-บิด | AO5: ตัด-เย็บ | AP5: ทอ | AQ5: สวมถุง | AR5: เย็บปาก | AS5: PT | AT5: ม้วน | AU5: ตัด | AV5: ตอกตาไก่ | AW5: GROUP | AX5: ART | AY5: หมายเหตุปัญหา | AZ5: ราคา/ใบ | BA5: ราคารวม | BB5: workweek | BC5: เส้นเทป | BD5: จำนวน
A6: 45860 | B6: MK68-000920 | C6: หจก.ปึงเป้งน้ำ | D6: เกลือตรามือ 10กก. | E6: 14 | F6: 22 | G6: ขาว | H6: ใส | I6: 42 | J6: ± | K6: 5 | L6: ไม่ | M6: ไม่สวมถุงใน | N6: 0 | O6: 0 | P6: 0 | Q6: 0 | R6: 0 | S6: 500กระสอบแบน | T6: 45884 | U6: 10000 | V6: 10000 | W6: 0 | X6: 10710 | Y6: 0 | Z6: WSWT1425800 | AA6: 0 | AB6: 0 | AC6: 0 | AD6: 0 | AE6: 0 | AF6: ลบสีทั้งหมด | AG6: ยังไม่ได้พิมพ์ | AH6: P6 | AI6: 4 | AJ6: 45884 | AK6: 45880 | AL6: 45873 | AM6: 45881 | AN6: 45882 | AO6: 45883 | AP6: 45879 | AQ6: 0 | AR6: 0 | AS6: 0 | AT6: 0 | AU6: 0 | AV6: 0 | AW6: งานเคลือบ+พิมพ์ | AX6: / | AY6: 0 | AZ6: 0 | BA6: 0 | BB6: 0 | BC6: WRWT25800/WRWT25800 | BD6: 0
A7: 0 | B7: 0 | C7: 0 | D7: 0 | E7: 14 | F7: 22 | G7: ขาว | H7: 0 | I7: 36 | J7: ± | K7: 5 | L7: 0 | M7: 0 | N7: 0 | O7: 0 | P7: 0 | Q7: 0 | R7: 0 | S7: 0 | U7: 0 | V7: 0 | W7: 0 | X7: 0 | Y7: 0 | Z7: WSWT1425800 | AA7: 0 | AB7: 0 | AC7: 0 | AD7: 0 | AE7: 0 | AF7: ระบุในSD | AG7: พร้อมส่ง | AH7: 0 | AI7: Lead time | AJ7: 0 | AK7: 0 | AL7: 0 | AM7: 0 | AN7: 0 | AO7: 0 | AP7: 0 | AQ7: 0 | AR7: 0 | AS7: 0 | AT7: 0 | AU7: 0 | AV7: 0 | AW7: 0 | AX7: 0 | AY7: 0 | AZ7: 0 | BA7: 0 | BB7: 0 | BC7: WRWT140800/WRWT25800 | BD7: 0
A8: 45842 | B8: MK68-000868 | C8: พีมินเนอร์ | D8: พี-มินเนอร์ นิวพลัส | E8: 16 | F8: 28 | G8: ขาว | H8: ใส | I8: 56 | J8: ± | K8: 5 | L8: ไม่ | M8: 19 | N8: 31 | O8: 40 | P8: 1.1334313 | Q8: 0 | R8: 1.1334313 | S8: 500กระสอบ | T8: รอส่ง | U8: 4000 | V8: 3922 | W8: 78 | X8: 5295 | Y8: 0 | Z8: WSWT1625800SM | AA8: 0 | AB8: 0 | AC8: 0 | AD8: 0 | AE8: 0 | AF8: รอส่ง รอลูกค้ามารับเอง | AG8: พร้อมส่ง | AH8: P8 | AI8: 4 | AJ8: รอส่ง | AK8: #VALUE! | AL8: #VALUE! | AM8: #VALUE! | AN8: #VALUE! | AO8: #VALUE! | AP8: #VALUE! | AQ8: #VALUE! | AR8: 0 | AS8: 0 | AT8: 0 | AU8: 0 | AV8: 0 | AW8: งานเคลือบ+พิมพ์ | AX8: / | AY8: 0 | AZ8: 0 | BA8: 0 | BB8: 0 | BC8: WRWT25800/WRWT25800 | BD8: 0
A9: ประมาณการ | B9: ประมาณการ | C9: บจก.ซัน ซีเมนต์ โพรเซส | D9: พระอาทิตย์(ปูนนอน-ชริงค์) | E9: 16 | F9: 25 | G9: ขาว | H9: ใส | I9: 50 | J9: ± | K9: 5 | L9: บิด | M9: 19 | N9: 28 | O9: 40 | P9: 65.624643 | Q9: 0 | R9: 65.624643 | S9: 500กระสอบ | T9: รอแจ้ง | U9: 5000 | V9: 0 | W9: 5000 | X9: 0 | Y9: 5250 | Z9: WSWT1625800SM | AA9: 3702.05 | AB9: 0 | AC9: 3702.05 | AD9: 0 | AE9: 3702.05 | AF9: 0 | AG9: พร้อมส่ง | AH9: P8 | AI9: 4 | AJ9: รอแจ้ง | AK9: #VALUE! | AL9: #VALUE! | AM9: #VALUE! | AN9: #VALUE! | AO9: #VALUE! | AP9: #VALUE! | AQ9: #VALUE! | AR9: 0 | AS9: 0 | AT9: 0 | AU9: 0 | AV9: 0 | AW9: งานเคลือบ+พิมพ์ | AX9: รอART | AY9: 0 | AZ9: 0 | BA9: 0 | BB9: 0 | BC9: WRWT25800/WRWT25800 | BD9: 210.60551
A10: 0 | B10: 0 | C10: 0 | E10: 16 | F10: 25 | G10: ขาว | H10: 0 | I10: 45 | J10: ± | K10: 5 | L10: 0 | M10: 0 | N10: 0 | O10: 0 | P10: 0 | Q10: 0 | R10: 0 | S10: 0 | U10: 0 | V10: 0 | W10: 0 | X10: 0 | Y10: 0 | Z10: WSWT1625800SM | AA10: 3702.05 | AB10: 0 | AC10: 3702.05 | AD10: 0 | AE10: 3702.05 | AF10: ระบุในSD | AG10: พร้อมส่ง | AH10: 0 | AI10: Lead time | AJ10: 0 | AK10: 0 | AL10: 0 | AM10: 0 | AN10: 0 | AO10: 0 | AP10: 0 | AQ10: 0 | AR10: 0 | AS10: 0 | AT10: 0 | AU10: 0 | AV10: 0 | AW10: 0 | AX10: 0 | AY10: 0 | AZ10: 0 | BA10: 0 | BB10: 0 | BC10: WRWT160800/WRWT25800 | BD10: 0
A11: ประมาณการ | B11: ประมาณการ | C11: บจก.ฟาร์เธอร์ส วิง ซัพพลาย | D11: รถไฟ | E11: 18 | F11: 30 | G11: ขาว | H11: 0 | I11: 54 | J11: ± | K11: 5 | L11: บิด | M11: 19 | N11: 33 | O11: 40 | P11: 232.02999 | Q11: 0 | R11: 232.02999 | S11: 500กระสอบ | T11: รอแจ้ง | U11: 15000 | V11: 0 | W11: 15000 | X11: 0 | Y11: 15750 | Z11: WSWT1825800 | AA11: 13201.65 | AB11: 2599 | AC11: 10602.65 | AD11: 0 | AE11: 0 | AF11: 0 | AG11: รอตัด | AH11: P9 | AI11: 3 | AJ11: รอแจ้ง | AK11: 0 | AL11: #VALUE! | AM11: #VALUE! | AN11: #VALUE! | AO11: #VALUE! | AP11: #VALUE! | AQ11: #VALUE! | AR11: 0 | AS11: 0 | AT11: 0 | AU11: 0 | AV11: 0 | AW11: งานพิมพ์ | AX11: รอART | AY11: 0 | AZ11: 0 | BA11: 0 | BB11: 0 | BC11: WRWT25800/WRWT25800 | BD11: 729.46232
A12: 0 | B12: 0 | E12: 18 | F12: 30 | G12: ขาว | H12: 0 | I12: 54 | J12: ± | K12: 5 | L12: 0 | M12: 0 | N12: 0 | O12: 0 | P12: 0 | Q12: 0 | R12: 0 | S12: 0 | U12: 0 | V12: 0 | W12: 0 | X12: 0 | Y12: 0 | Z12: WSWT1825800 | AA12: 13201.65 | AB12: 2599 | AC12: 10602.65 | AD12: 0 | AE12: 0 | AF12: ระบุในSD | AG12: พิมพ์ไม่ครบ | AH12: 0 | AI12: Lead time | AJ12: 0 | AK12: 0 | AL12: 0 | AM12: 0 | AN12: 0 | AO12: 0 | AP12: 0 | AQ12: 0 | AR12: 0 | AS12: 0 | AT12: 0 | AU12: 0 | AV12: 0 | AW12: 0 | AX12: 0 | AY12: 0 | AZ12: 0 | BA12: 0 | BB12: 0 | BC12: WRWT25800/WRWT25800 | BD12: 0
A13: 45875 | B13: MK68-000974 | C13: บจก.เอ็กเซลเล้นท์ | D13: แชมป์เปี้ยนเหลือง | E13: 19 | F13: 30 | G13: ขาว | H13: 0 | I13: 60 | J13: ± | K13: 5 | L13: บิด | M13: ไม่สวมถุงใน | N13: 0 | O13: 0 | P13: 0 | Q13: 0 | R13: 0 | S13: 500กระสอบ | T13: 45885 | U13: 5000 | V13: 0 | W13: 5000 | X13: 5400 | Y13: 0 | Z13: WSWT1925800 | AA13: 0 | AB13: 0 | AC13: 0 | AD13: 0 | AE13: 0 | AF13: 0 | AG13: ยังไม่ได้พิมพ์ | AH13: P7 | AI13: 2 | AJ13: 45885 | AK13: 0 | AL13: 45876 | AM13: 45883 | AN13: 45884 | AO13: 45884 | AP13: 45880 | AQ13: 0 | AR13: 0 | AS13: 0 | AT13: 0 | AU13: 0 | AV13: 0 | AW13: งานพิมพ์ | AX13: / | AY13: 0 | AZ13: 0 | BA13: 0 | BB13: 0 | BC13: WRWT25800/WRWT25800 | BD13: 0
A14: 45870 | B14: MK68-000951 | C14: บจก.ซีแมน | D14: W30 | E14: 19 | F14: 28 | G14: ขาว | H14: 0 | I14: 56 | J14: ± | K14: 5 | L14: ไม่ | M14: 20 | N14: 30 | O14: 90 | P14: 1248.9652 | Q14: 0 | R14: 1248.9652 | S14: มัด100 | T14: 45889 | U14: 40000 | V14: 2500 | W14: 37500 | X14: 29350 | Y14: 11182.5 | Z14: WSWT1925800 | AA14: 9216.952 | AB14: 9216.952 | AC14: 0 | AD14: 0 | AE14: 0 | AF14: 0 | AG14: รอแบบ | AH14: P9 | AI14: 3 | AJ14: 45889 | AK14: 0 | AL14: 45879 | AM14: 45886 | AN14: 45887 | AO14: 45887 | AP14: 45884 | AQ14: 45888 | AR14: 0 | AS14: 0 | AT14: 0 | AU14: 0 | AV14: 0 | AW14: งานพิมพ์ | AX14: / | AY14: 0 | AZ14: 0 | BA14: 0 | BB14: 0 | BC14: WRWT25800/WRWT25800 | BD14: 0
A15: 45882 | B15: MK68-000996 | C15: บจก.เพรซิเดนท์ฟลาวมิลล์ | D15: ผึ้งชมพู | E15: 19 | F15: 30 | G15: ขาว | H15: 0 | I15: 60 | J15: ± | K15: 5 | L15: บิด | M15: ไม่สวมถุงใน | N15: 0 | O15: 0 | P15: 0 | Q15: 0 | R15: 0 | S15: 500กระสอบ | T15: 45889 | U15: 30000 | V15: 0 | W15: 30000 | X15: 0 | Y15: 31500 | Z15: WSWT1925800 | AA15: 26403.3 | AB15: 26403.3 | AC15: 0 | AD15: 0 | AE15: 0 | AF15: 0 | AG15: ยังไม่ได้พิมพ์ | AH15: P7 | AI15: 2 | AJ15: 45889 | AK15: 0 | AL15: 45880 | AM15: 45887 | AN15: 45888 | AO15: 45888 | AP15: 45884 | AQ15: 0 | AR15: 0 | AS15: 0 | AT15: 0 | AU15: 0 | AV15: 0 | AW15: งานพิมพ์ | AX15: รอART | AY15: 20/8/2025 เย็น | AZ15: 0 | BA15: 0 | BB15: 0 | BC15: WRWT25800/WRWT25800 | BD15: 0
