Workbook

Sheet 30-7-68
B2: เรียงกำหนดส่ง | D2: ลบ 0 | T2: เรียง 1
B3: ข้อมูลUpdate ณ. วันที่ | D3: 45868 | E3: เวลา | G3: 10.38
A4: วันรับออร์เดอร์/แบบ | B4: เลขที่ SO | C4: ชื่อลูกค้า | E4: 10.3 | I4: น้ำหนัก | L4: บิด/จับจีบ | M4: ถุงใน | Q4: 44873 | S4: วิธีบรรจุ | T4: วันส่ง | U4: จำนวนส่ง | V4: ตัดเย็บ (ใบ) | W4: 44873 | X4: พิมพ์ (ใบ) | Y4: 44876 | Z4: ผ้าทอ (เมตร) Updateณ | AB4: 44876 | AD4: ผ้าเคลือบ(เมตร) | AF4: หมายเหตุ | AG4: เครื่อง
A5: วันรับออร์เดอร์/แบบ | B5: เลขที่ SO | C5: ชื่อลูกค้า | D5: ตรา | E5: กว้าง | F5: ยาว | G5: สี | H5: เคลือบ | I5: กรัม/ใบ | J5: * | K5: aw | L5: บิด/จับจีบ | M5: กว้าง | N5: ยาว | O5: หนา | P5: ใช้(กก.) | Q5: Stock(กก.) | R5: ผลิต(กก.) | S5: วิธีบรรจุ | T5: วันส่ง | U5: จำนวนส่ง | V5: StockFG | W5: ค้างตัด | X5: พิมพ์แล้ว | Y5: ค้างพิมพ์ | Z5: ประเภท | AA5: ใช้ | AB5: Stock | AC5: ค้างทอ | AD5: Stock | AE5: ค้างเคลือบ | AF5: หมายเหตุ | AG5: ที่พิมพ์ได้ | AH5: process | AI5: Lead time | AJ5: วันที่ส่งPL | AK5: เคลือบ | AL5: ได้ ART | AM5: พิมพ์ | AN5: จีบ-บิด | AO5: ตัด-เย็บ | AP5: ทอ | AQ5: สวมถุง | AR5: เย็บปาก | AS5: PT | AT5: ม้วน | AU5: ตัด | AV5: ตอกตาไก่ | AW5: GROUP | AX5: ART | AY5: หมายเหตุปัญหา | AZ5: ราคา/ใบ | BA5: ราคารวม | BB5: workweek | BC5: เส้นเทป | BD5: จำนวน
A6: 45860 | B6: MK68-000920 | C6: หจก.ปึงเป้งน้ำ | D6: เกลือตรามือ 10กก. | E6: 14 | F6: 22 | G6: ขาว | H6: ใส | I6: 42 | J6: ± | K6: 5 | L6: ไม่ | M6: ไม่สวมถุงใน | N6: 0 | O6: 0 | P6: 0 | Q6: 0 | R6: 0 | S6: 500กระสอบแบน | T6: 45884 | U6: 10000 | V6: 0 | W6: 10000 | X6: 0 | Y6: 10500 | Z6: WSWT1425800 | AA6: 6565.9 | AB6: 6565.9 | AC6: 0 | AD6: 0 | AE6: 6565.9 | AF6: 0 | AG6: ยังไม่ได้พิมพ์ | AH6: P6 | AI6: 4 | AJ6: 45884 | AK6: 45880 | AL6: 45873 | AM6: 45881 | AN6: 45882 | AO6: 45883 | AP6: 45879 | AQ6: 0 | AR6: 0 | AS6: 0 | AT6: 0 | AU6: 0 | AV6: 0 | AW6: งานเคลือบ+พิมพ์ | AX6: / | AY6: 0 | AZ6: 0 | BA6: 0 | BB6: 0 | BC6: WRWT25800/WRWT25800 | BD6: 0
A7: 0 | B7: 0 | C7: 0 | D7: 0 | E7: 14 | F7: 22 | G7: ขาว | H7: 0 | I7: 36 | J7: ± | K7: 5 | L7: 0 | M7: 0 | N7: 0 | O7: 0 | P7: 0 | Q7: 0 | R7: 0 | S7: 0 | U7: 0 | V7: 0 | W7: 0 | X7: 0 | Y7: 0 | Z7: WSWT1425800 | AA7: 6565.9 | AB7: 6565.9 | AC7: 0 | AD7: 0 | AE7: 6565.9 | AF7: ระบุในSD | AG7: พร้อมส่ง | AH7: 0 | AI7: Lead time | AJ7: 0 | AK7: 0 | AL7: 0 | AM7: 0 | AN7: 0 | AO7: 0 | AP7: 0 | AQ7: 0 | AR7: 0 | AS7: 0 | AT7: 0 | AU7: 0 | AV7: 0 | AW7: 0 | AX7: 0 | AY7: 0 | AZ7: 0 | BA7: 0 | BB7: 0 | BC7: WRWT140800/WRWT25800 | BD7: 0
A8: 45842 | B8: MK68-000868 | C8: พีมินเนอร์ | D8: พี-มินเนอร์ นิวพลัส | E8: 16 | F8: 28 | G8: ขาว | H8: ใส | I8: 56 | J8: ± | K8: 5 | L8: ไม่ | M8: 19 | N8: 31 | O8: 40 | P8: 1.1334313 | Q8: 0 | R8: 1.1334313 | S8: 500กระสอบ | T8: 45869 | U8: 4000 | V8: 3922 | W8: 78 | X8: 5295 | Y8: 0 | Z8: WSWT1625800SM | AA8: 0 | AB8: 0 | AC8: 0 | AD8: 0 | AE8: 0 | AF8: รอส่ง รอลูกค้ามารับเอง | AG8: พร้อมส่ง | AH8: P8 | AI8: 4 | AJ8: 45869 | AK8: 45865 | AL8: 45859 | AM8: 45866 | AN8: 45867 | AO8: 45867 | AP8: 45864 | AQ8: 45868 | AR8: 0 | AS8: 0 | AT8: 0 | AU8: 0 | AV8: 0 | AW8: งานเคลือบ+พิมพ์ | AX8: / | AY8: 0 | AZ8: 0 | BA8: 0 | BB8: 0 | BC8: WRWT25800/WRWT25800 | BD8: 0
A9: ประมาณการ | B9: ประมาณการ | C9: บจก.ซัน ซีเมนต์ โพรเซส | D9: พระอาทิตย์(ปูนนอน-ชริงค์) | E9: 16 | F9: 25 | G9: ขาว | H9: ใส | I9: 50 | J9: ± | K9: 5 | L9: บิด | M9: 19 | N9: 28 | O9: 40 | P9: 65.624643 | Q9: 0 | R9: 65.624643 | S9: 500กระสอบ | T9: รอแจ้ง | U9: 5000 | V9: 0 | W9: 5000 | X9: 0 | Y9: 5250 | Z9: WSWT1625800SM | AA9: 3702.05 | AB9: 0 | AC9: 3702.05 | AD9: 0 | AE9: 3702.05 | AF9: 0 | AG9: พร้อมส่ง | AH9: P8 | AI9: 4 | AJ9: รอแจ้ง | AK9: #VALUE! | AL9: #VALUE! | AM9: #VALUE! | AN9: #VALUE! | AO9: #VALUE! | AP9: #VALUE! | AQ9: #VALUE! | AR9: 0 | AS9: 0 | AT9: 0 | AU9: 0 | AV9: 0 | AW9: งานเคลือบ+พิมพ์ | AX9: รอART | AY9: 0 | AZ9: 0 | BA9: 0 | BB9: 0 | BC9: WRWT25800/WRWT25800 | BD9: 210.60551
A10: 0 | B10: 0 | C10: 0 | E10: 16 | F10: 25 | G10: ขาว | H10: 0 | I10: 45 | J10: ± | K10: 5 | L10: 0 | M10: 0 | N10: 0 | O10: 0 | P10: 0 | Q10: 0 | R10: 0 | S10: 0 | U10: 0 | V10: 0 | W10: 0 | X10: 0 | Y10: 0 | Z10: WSWT1625800SM | AA10: 3702.05 | AB10: 0 | AC10: 3702.05 | AD10: 0 | AE10: 3702.05 | AF10: ระบุในSD | AG10: พร้อมส่ง | AH10: 0 | AI10: Lead time | AJ10: 0 | AK10: 0 | AL10: 0 | AM10: 0 | AN10: 0 | AO10: 0 | AP10: 0 | AQ10: 0 | AR10: 0 | AS10: 0 | AT10: 0 | AU10: 0 | AV10: 0 | AW10: 0 | AX10: 0 | AY10: 0 | AZ10: 0 | BA10: 0 | BB10: 0 | BC10: WRWT160800/WRWT25800 | BD10: 0
A11: ประมาณการ | B11: ประมาณการ | C11: บจก.ฟาร์เธอร์ส วิง ซัพพลาย | D11: รถไฟ | E11: 18 | F11: 30 | G11: ขาว | H11: 0 | I11: 54 | J11: ± | K11: 5 | L11: บิด | M11: 19 | N11: 33 | O11: 40 | P11: 232.02999 | Q11: 0 | R11: 232.02999 | S11: 500กระสอบ | T11: รอแจ้ง | U11: 15000 | V11: 0 | W11: 15000 | X11: 0 | Y11: 15750 | Z11: WSWT1825800 | AA11: 13201.65 | AB11: 6301 | AC11: 6900.65 | AD11: 0 | AE11: 0 | AF11: 0 | AG11: พร้อมส่ง | AH11: P9 | AI11: 3 | AJ11: รอแจ้ง | AK11: 0 | AL11: #VALUE! | AM11: #VALUE! | AN11: #VALUE! | AO11: #VALUE! | AP11: #VALUE! | AQ11: #VALUE! | AR11: 0 | AS11: 0 | AT11: 0 | AU11: 0 | AV11: 0 | AW11: งานพิมพ์ | AX11: รอART | AY11: 0 | AZ11: 0 | BA11: 0 | BB11: 0 | BC11: WRWT25800/WRWT25800 | BD11: 474.76472
A12: 0 | B12: 0 | E12: 18 | F12: 30 | G12: ขาว | H12: 0 | I12: 54 | J12: ± | K12: 5 | L12: 0 | M12: 0 | N12: 0 | O12: 0 | P12: 0 | Q12: 0 | R12: 0 | S12: 0 | U12: 0 | V12: 0 | W12: 0 | X12: 0 | Y12: 0 | Z12: WSWT1825800 | AA12: 13201.65 | AB12: 6301 | AC12: 6900.65 | AD12: 0 | AE12: 0 | AF12: ระบุในSD | AG12: ยังไม่ได้พิมพ์ | AH12: 0 | AI12: Lead time | AJ12: 0 | AK12: 0 | AL12: 0 | AM12: 0 | AN12: 0 | AO12: 0 | AP12: 0 | AQ12: 0 | AR12: 0 | AS12: 0 | AT12: 0 | AU12: 0 | AV12: 0 | AW12: 0 | AX12: 0 | AY12: 0 | AZ12: 0 | BA12: 0 | BB12: 0 | BC12: WRWT25800/WRWT25800 | BD12: 0
A13: 45860 | B13: MK68-000917 | C13: บจก.ซิเบลโก้(บางเลน) | D13: PORTARYTE B15 | E13: 18 | F13: 30 | G13: ขาว | H13: ใส | I13: 74 | J13: ± | K13: 5 | L13: ไม่ | M13: ไม่สวมถุงใน | N13: 0 | O13: 0 | P13: 0 | Q13: 0 | R13: 0 | S13: 500กระสอบแบน | T13: 45883 | U13: 10000 | V13: 0 | W13: 10000 | X13: 0 | Y13: 10500 | Z13: WSWT1825800SM | AA13: 8801.1 | AB13: 6990 | AC13: 1811.1 | AD13: 1997 | AE13: 6804.1 | AF13: 0 | AG13: ยังไม่ได้พิมพ์ | AH13: P6 | AI13: 4 | AJ13: 45883 | AK13: 45879 | AL13: 45872 | AM13: 45880 | AN13: 45881 | AO13: 45882 | AP13: 45878 | AQ13: 0 | AR13: 0 | AS13: 0 | AT13: 0 | AU13: 0 | AV13: 0 | AW13: งานเคลือบ+พิมพ์ | AX13: / | AY13: 0 | AZ13: 0 | BA13: 0 | BB13: 0 | BC13: WRWT25800/WRWT25800 | BD13: 115.9104
A14: 0 | B14: 0 | C14: 0 | E14: 18 | F14: 25 | G14: ขาว | H14: 0 | I14: 50 | J14: ± | K14: 5 | L14: 0 | M14: 0 | N14: 0 | O14: 0 | P14: 0 | Q14: 0 | R14: 0 | S14: 0 | U14: 0 | V14: 0 | W14: 0 | X14: 0 | Y14: 0 | Z14: WSWT1825800SM | AA14: 8801.1 | AB14: 6990 | AC14: 1811.1 | AD14: 1997 | AE14: 6804.1 | AF14: ระบุในSD | AG14: รอแบบ | AH14: 0 | AI14: Lead time | AJ14: 0 | AK14: 0 | AL14: 0 | AM14: 0 | AN14: 0 | AO14: 0 | AP14: 0 | AQ14: 0 | AR14: 0 | AS14: 0 | AT14: 0 | AU14: 0 | AV14: 0 | AW14: 0 | AX14: 0 | AY14: 0 | AZ14: 0 | BA14: 0 | BB14: 0 | BC14: WRWT180800/WRWT25800 | BD14: 0
A15: ประมาณการ | B15: ประมาณการ | C15: บจก.เพรซิเดนท์ฟลาวมิลล์ | D15: ผึ้งเหลือง | E15: 19 | F15: 30 | G15: ขาว | H15: 0 | I15: 60 | J15: ± | K15: 5 | L15: บิด | M15: ไม่สวมถุงใน | N15: 0 | O15: 0 | P15: 0 | Q15: 0 | R15: 0 | S15: 500กระสอบ | T15: 45894 | U15: 100000 | V15: 0 | W15: 100000 | X15: 0 | Y15: 105000 | Z15: WSWT1925800 | AA15: 88011 | AB15: 56115 | AC15: 31896 | AD15: 0 | AE15: 0 | AF15: 0 | AG15: ยังไม่ได้พิมพ์ | AH15: P7 | AI15: 2 | AJ15: 45894 | AK15: 0 | AL15: 45885 | AM15: 45892 | AN15: 45893 | AO15: 45893 | AP15: 45889 | AQ15: 0 | AR15: 0 | AS15: 0 | AT15: 0 | AU15: 0 | AV15: 0 | AW15: งานพิมพ์ | AX15: รอART | AY15: 0 | AZ15: 0 | BA15: 0 | BB15: 0 | BC15: WRWT25800/WRWT25800 | BD15: 2316.3584
A16: ประมาณการ | B16: ประมาณการ | C16: บจก.เพรซิเดนท์ฟลาวมิลล์ | D16: ผึ้งชมพู | E16: 19 | F16: 30 | G16: ขาว | H16: 0 | I16: 60 | J16: ± | K16: 5 | L16: บิด | M16: ไม่สวมถุงใน | N16: 0 | O16: 0 | P16: 0 | Q16: 0 | R16: 0 | S16: 500กระสอบ | T16: 45894 | U16: 40000 | V16: 0 | W16: 40000 | X16: 0 | Y16: 42000 | Z16: WSWT1925800 | AA16: 35204.4 | AB16: 0 | AC16: 35204.4 | AD16: 0 | AE16: 0 | AF16: 0 | AG16: พร้อมส่ง | AH16: P7 | AI16: 2 | AJ16: 45894 | AK16: 0 | AL16: 45885 | AM16: 45892 | AN16: 45893 | AO16: 45893 | AP16: 45889 | AQ16: 0 | AR16: 0 | AS16: 0 | AT16: 0 | AU16: 0 | AV16: 0 | AW16: งานพิมพ์ | AX16: รอART | AY16: 0 | AZ16: 0 | BA16: 0 | BB16: 0 | BC16: WRWT25800/WRWT25800 | BD16: 2556.6218
A17: ประมาณการ | B17: ประมาณการ | C17: บจก.เอ็กเซลเล้นท์ | D17: รอแบบ | E17: 19 | F17: 30 | G17: ขาว | H17: 0 | I17: 60 | J17: ± | K17: 5 | L17: บิด | M17: ไม่สวมถุงใน | N17: 0 | O17: 0 | P17: 0 | Q17: 0 | R17: 0 | S17: 500กระสอบ | T17: 45894 | U17: 40000 | V17: 0 | W17: 40000 | X17: 0 | Y17: 42000 | Z17: WSWT1925800 | AA17: 35204.4 | AB17: 0 | AC17: 35204.4 | AD17: 0 | AE17: 0 | AF17: 0 | AG17: พร้อมส่ง | AH17: P7 | AI17: 2 | AJ17: 45894 | AK17: 0 | AL17: 45885 | AM17: 45892 | AN17: 45893 | AO17: 45893 | AP17: 45889 | AQ17: 0 | AR17: 0 | AS17: 0 | AT17: 0 | AU17: 0 | AV17: 0 | AW17: งานพิมพ์ | AX17: / | AY17: 0 | AZ17: 0 | BA17: 0 | BB17: 0 | BC17: WRWT25800/WRWT25800 | BD17: 2556.6218
A18: ประมาณการ | B18: ประมาณการ | C18: บจก.ไลม์มาสเตอร์ | D18: LMC 25 kg | E18: 19 | F18: 32 | G18: ขาว | H18: 0 | I18: 64 | J18: ± | K18: 5 | L18: ไม่ | M18: 20 | N18: 35 | O18: 40 | P18: 341.36903 | Q18: 0 | R18: 341.36903 | S18: 500กระสอบแบน | T18: 45894 | U18: 20000 | V18: 233 | W18: 19767 | X18: 0 | Y18: 20755.35 | Z18: WSWT1925800 | AA18: 18501.714 | AB18: 18501.714 | AC18: 0 | AD18: 0 | AE18: 0 | AF18: 0 | AG18: พร้อมส่ง | AH18: P9 | AI18: 3 | AJ18: 45894 | AK18: 0 | AL18: 45884 | AM18: 45891 | AN18: 45892 | AO18: 45892 | AP18: 45889 | AQ18: 45893 | AR18: 0 | AS18: 0 | AT18: 0 | AU18: 0 | AV18: 0 | AW18: งานพิมพ์ | AX18: รอART | AY18: 0 | AZ18: 0 | BA18: 0 | BB18: 0 | BC18: WRWT25800/WRWT25800 | BD18: 0
A19: 0 | B19: 0 | C19: 0 | D19: 0 | E19: 19 | F19: 30 | G19: ขาว | H19: 0 | I19: 60 | J19: ± | K19: 5 | L19: 0 | M19: 0 | N19: 0 | O19: 0 | P19: 0 | Q19: 0 | R19: 0 | S19: 0 | U19: 0 | V19: 0 | W19: 0 | X19: 0 | Y19: 0 | Z19: WSWT1925800 | AA19: 176921.51 | AB19: 74616.714 | AC19: 102304.8 | AD19: 0 | AE19: 0 | AF19: ระบุในSD | AG19: พร้อมส่ง | AH19: 0 | AI19: Lead time | AJ19: 0 | AK19: 0 | AL19: 0 | AM19: 0 | AN19: 0 | AO19: 0 | AP19: 0 | AQ19: 0 | AR19: 0 | AS19: 0 | AT19: 0 | AU19: 0 | AV19: 0 | AW19: 0 | AX19: 0 | AY19: 0 | AZ19: 0 | BA19: 0 | BB19: 0 | BC19: WRWT25800/WRWT25800 | BD19: 0
A20: 45854 | B20: MK68-000890 | C20: บจก.เคอรี่ฟลาวมิลล์ | D20: HARD FLOUR | E20: 19 | F20: 32 | G20: ขาว | H20: 0 | I20: 67 | J20: + | K20: 5 | L20: บิด | M20: ไม่สวมถุงใน | N20: 0 | O20: 0 | P20: 0 | Q20: 0 | R20: 0 | S20: ห่ออัดเบลแบน500 | T20: 45869 | U20: 5000 | V20: 5220 | W20: 0 | X20: 5400 | Y20: 0 | Z20: WSWT1921720 | AA20: 0 | AB20: 0 | AC20: 0 | AD20: 0 | AE20: 0 | AF20: PDR250226 | AG20: พร้อมส่ง | AH20: P7 | AI20: 2 | AJ20: 45869 | AK20: 0 | AL20: 45860 | AM20: 45867 | AN20: 45868 | AO20: 45868 | AP20: 45864 | AQ20: 0 | AR20: 0 | AS20: 0 | AT20: 0 | AU20: 0 | AV20: 0 | AW20: งานพิมพ์ | AX20: / | AY20: 0 | AZ20: 0 | BA20: 0 | BB20: 0 | BC20: WRWT21720/WRWT25800 | BD20: 0
A21: 45854 | B21: MK68-000890 | C21: บจก.เคอรี่ฟลาวมิลล์ | D21: ดอกไม้เขียว | E21: 19 | F21: 32 | G21: ขาว | H21: 0 | I21: 67 | J21: + | K21: 5 | L21: บิด | M21: ไม่สวมถุงใน | N21: 0 | O21: 0 | P21: 0 | Q21: 0 | R21: 0 | S21: ห่ออัดเบลแบน500 | T21: 45869 | U21: 5000 | V21: 5000 | W21: 0 | X21: 5198 | Y21: 0 | Z21: WSWT1921720 | AA21: 0 | AB21: 0 | AC21: 0 | AD21: 0 | AE21: 0 | AF21: PDR250226 | AG21: พร้อมส่ง | AH21: P7 | AI21: 2 | AJ21: 45869 | AK21: 0 | AL21: 45860 | AM21: 45867 | AN21: 45868 | AO21: 45868 | AP21: 45864 | AQ21: 0 | AR21: 0 | AS21: 0 | AT21: 0 | AU21: 0 | AV21: 0 | AW21: งานพิมพ์ | AX21: / | AY21: 0 | AZ21: 0 | BA21: 0 | BB21: 0 | BC21: WRWT21720/WRWT25800 | BD21: 0
A22: 45854 | B22: MK68-000890 | C22: บจก.เคอรี่ฟลาวมิลล์ | D22: 997 | E22: 19 | F22: 32 | G22: ขาว | H22: 0 | I22: 67 | J22: + | K22: 5 | L22: ไม่ | M22: ไม่สวมถุงใน | N22: 0 | O22: 0 | P22: 0 | Q22: 0 | R22: 0 | S22: ห่ออัดเบลแบน500 | T22: 45869 | U22: 5000 | V22: 5124 | W22: 0 | X22: 5300 | Y22: 0 | Z22: WSWT1921720 | AA22: 0 | AB22: 0 | AC22: 0 | AD22: 0 | AE22: 0 | AF22: PDR250226 | AG22: พร้อมส่ง | AH22: P7 | AI22: 2 | AJ22: 45869 | AK22: 0 | AL22: 45860 | AM22: 45867 | AN22: 45868 | AO22: 45868 | AP22: 45864 | AQ22: 0 | AR22: 0 | AS22: 0 | AT22: 0 | AU22: 0 | AV22: 0 | AW22: งานพิมพ์ | AX22: / | AY22: 0 | AZ22: 0 | BA22: 0 | BB22: 0 | BC22: WRWT21720/WRWT25800 | BD22: 0
A23: 45854 | B23: MK68-000891 | C23: บจก.เคอรี่ฟลาวมิลล์ | D23: ถุงเขียว | E23: 19 | F23: 32 | G23: ขาว | H23: 0 | I23: 67 | J23: + | K23: 5 | L23: บิด | M23: ไม่สวมถุงใน | N23: 0 | O23: 0 | P23: 0 | Q23: 0 | R23: 0 | S23: ห่ออัดเบลแบน500 | T23: 45869 | U23: 10000 | V23: 10000 | W23: 0 | X23: 10300 | Y23: 0 | Z23: WSWT1921720 | AA23: 0 | AB23: 0 | AC23: 0 | AD23: 0 | AE23: 0 | AF23: PDR250227 | AG23: พร้อมส่ง | AH23: P7 | AI23: 2 | AJ23: 45869 | AK23: 0 | AL23: 45860 | AM23: 45867 | AN23: 45868 | AO23: 45868 | AP23: 45864 | AQ23: 0 | AR23: 0 | AS23: 0 | AT23: 0 | AU23: 0 | AV23: 0 | AW23: งานพิมพ์ | AX23: / | AY23: 0 | AZ23: 0 | BA23: 0 | BB23: 0 | BC23: WRWT21720/WRWT25800 | BD23: 0
A24: 45854 | B24: MK68-000890 | C24: บจก.เคอรี่ฟลาวมิลล์ | D24: ปลาโลมาเทา | E24: 19 | F24: 32 | G24: ขาว | H24: 0 | I24: 67 | J24: + | K24: 5 | L24: บิด | M24: ไม่สวมถุงใน | N24: 0 | O24: 0 | P24: 0 | Q24: 0 | R24: 0 | S24: ห่ออัดเบลแบน500 | T24: 45871 | U24: 5000 | V24: 5000 | W24: 0 | X24: 5200 | Y24: 0 | Z24: WSWT1921720 | AA24: 0 | AB24: 0 | AC24: 0 | AD24: 0 | AE24: 0 | AF24: PDR250228 | AG24: พร้อมส่ง | AH24: P7 | AI24: 2 | AJ24: 45871 | AK24: 0 | AL24: 45862 | AM24: 45869 | AN24: 45870 | AO24: 45870 | AP24: 45866 | AQ24: 0 | AR24: 0 | AS24: 0 | AT24: 0 | AU24: 0 | AV24: 0 | AW24: งานพิมพ์ | AX24: / | AY24: 0 | AZ24: 0 | BA24: 0 | BB24: 0 | BC24: WRWT21720/WRWT25800 | BD24: 0
A25: 45854 | B25: MK68-000890 | C25: บจก.เคอรี่ฟลาวมิลล์ | D25: ถุงเขียว | E25: 19 | F25: 32 | G25: ขาว | H25: 0 | I25: 67 | J25: + | K25: 5 | L25: บิด | M25: ไม่สวมถุงใน | N25: 0 | O25: 0 | P25: 0 | Q25: 0 | R25: 0 | S25: ห่ออัดเบลแบน500 | T25: 45871 | U25: 10000 | V25: 10000 | W25: 0 | X25: 11110 | Y25: 0 | Z25: WSWT1921720 | AA25: 0 | AB25: 0 | AC25: 0 | AD25: 0 | AE25: 0 | AF25: PDR250228 | AG25: พร้อมส่ง | AH25: P7 | AI25: 2 | AJ25: 45871 | AK25: 0 | AL25: 45862 | AM25: 45869 | AN25: 45870 | AO25: 45870 | AP25: 45866 | AQ25: 0 | AR25: 0 | AS25: 0 | AT25: 0 | AU25: 0 | AV25: 0 | AW25: งานพิมพ์ | AX25: / | AY25: 0 | AZ25: 0 | BA25: 0 | BB25: 0 | BC25: WRWT21720/WRWT25800 | BD25: 0
A26: 45854 | B26: MK68-000890 | C26: บจก.เคอรี่ฟลาวมิลล์ | D26: ถุงทองแซนวิช | E26: 19 | F26: 32 | G26: ขาว | H26: 0 | I26: 67 | J26: + | K26: 5 | L26: บิด | M26: ไม่สวมถุงใน | N26: 0 | O26: 0 | P26: 0 | Q26: 0 | R26: 0 | S26: ห่ออัดเบลแบน500 | T26: 45871 | U26: 5000 | V26: 5000 | W26: 0 | X26: 5500 | Y26: 0 | Z26: WSWT1921720 | AA26: 0 | AB26: 0 | AC26: 0 | AD26: 0 | AE26: 0 | AF26: PDR250228 | AG26: รอตัด | AH26: P7 | AI26: 2 | AJ26: 45871 | AK26: 0 | AL26: 45862 | AM26: 45869 | AN26: 45870 | AO26: 45870 | AP26: 45866 | AQ26: 0 | AR26: 0 | AS26: 0 | AT26: 0 | AU26: 0 | AV26: 0 | AW26: งานพิมพ์ | AX26: / | AY26: รอผสม 1200 | AZ26: 0 | BA26: 0 | BB26: 0 | BC26: WRWT21720/WRWT25800 | BD26: 0
A27: 45854 | B27: MK68-000890 | C27: บจก.เคอรี่ฟลาวมิลล์ | D27: ถุงเงิน | E27: 19 | F27: 32 | G27: ขาว | H27: 0 | I27: 67 | J27: + | K27: 5 | L27: บิด | M27: ไม่สวมถุงใน | N27: 0 | O27: 0 | P27: 0 | Q27: 0 | R27: 0 | S27: ห่ออัดเบลแบน500 | T27: 45871 | U27: 5000 | V27: 5000 | W27: 0 | X27: 5250 | Y27: 0 | Z27: WSWT1921720 | AA27: 0 | AB27: 0 | AC27: 0 | AD27: 0 | AE27: 0 | AF27: PDR250228 | AG27: พร้อมส่ง | AH27: P7 | AI27: 2 | AJ27: 45871 | AK27: 0 | AL27: 45862 | AM27: 45869 | AN27: 45870 | AO27: 45870 | AP27: 45866 | AQ27: 0 | AR27: 0 | AS27: 0 | AT27: 0 | AU27: 0 | AV27: 0 | AW27: งานพิมพ์ | AX27: / | AY27: 0 | AZ27: 0 | BA27: 0 | BB27: 0 | BC27: WRWT21720/WRWT25800 | BD27: 0
A28: 45854 | B28: MK68-000891 | C28: บจก.เคอรี่ฟลาวมิลล์ | D28: ปลาโลมาแดง | E28: 19 | F28: 32 | G28: ขาว | H28: 0 | I28: 67 | J28: + | K28: 5 | L28: บิด | M28: ไม่สวมถุงใน | N28: 0 | O28: 0 | P28: 0 | Q28: 0 | R28: 0 | S28: ห่ออัดเบลแบน500 | T28: 45871 | U28: 5000 | V28: 5000 | W28: 0 | X28: 5250 | Y28: 0 | Z28: WSWT1921720 | AA28: 0 | AB28: 0 | AC28: 0 | AD28: 0 | AE28: 0 | AF28: PDR250229 | AG28: พร้อมส่ง | AH28: P7 | AI28: 2 | AJ28: 45871 | AK28: 0 | AL28: 45862 | AM28: 45869 | AN28: 45870 | AO28: 45870 | AP28: 45866 | AQ28: 0 | AR28: 0 | AS28: 0 | AT28: 0 | AU28: 0 | AV28: 0 | AW28: งานพิมพ์ | AX28: / | AY28: 0 | AZ28: 0 | BA28: 0 | BB28: 0 | BC28: WRWT21720/WRWT25800 | BD28: 0
A29: 45854 | B29: MK68-000891 | C29: บจก.เคอรี่ฟลาวมิลล์ | D29: ดอกไม้เหลือง | E29: 19 | F29: 32 | G29: ขาว | H29: 0 | I29: 67 | J29: + | K29: 5 | L29: บิด | M29: ไม่สวมถุงใน | N29: 0 | O29: 0 | P29: 0 | Q29: 0 | R29: 0 | S29: ห่ออัดเบลแบน500 | T29: 45871 | U29: 5000 | V29: 0 | W29: 5000 | X29: 5200 | Y29: 0 | Z29: WSWT1921720 | AA29: 0 | AB29: 0 | AC29: 0 | AD29: 0 | AE29: 0 | AF29: PDR250229 | AG29: รอตัด | AH29: P7 | AI29: 2 | AJ29: 45871 | AK29: 0 | AL29: 45862 | AM29: 45869 | AN29: 45870 | AO29: 45870 | AP29: 45866 | AQ29: 0 | AR29: 0 | AS29: 0 | AT29: 0 | AU29: 0 | AV29: 0 | AW29: งานพิมพ์ | AX29: / | AY29: 0 | AZ29: 0 | BA29: 0 | BB29: 0 | BC29: WRWT21720/WRWT25800 | BD29: 0
A30: 45854 | B30: MK68-000891 | C30: บจก.เคอรี่ฟลาวมิลล์ | D30: FW-Y | E30: 19 | F30: 32 | G30: ขาว | H30: 0 | I30: 67 | J30: + | K30: 5 | L30: ไม่ | M30: ไม่สวมถุงใน | N30: 0 | O30: 0 | P30: 0 | Q30: 0 | R30: 0 | S30: ห่ออัดเบลแบน500 | T30: 45871 | U30: 5000 | V30: 5000 | W30: 0 | X30: 5250 | Y30: 0 | Z30: WSWT1921720 | AA30: 0 | AB30: 0 | AC30: 0 | AD30: 0 | AE30: 0 | AF30: PDR250229 | AG30: ยังไม่ได้พิมพ์ | AH30: P7 | AI30: 2 | AJ30: 45871 | AK30: 0 | AL30: 45862 | AM30: 45869 | AN30: 45870 | AO30: 45870 | AP30: 45866 | AQ30: 0 | AR30: 0 | AS30: 0 | AT30: 0 | AU30: 0 | AV30: 0 | AW30: งานพิมพ์ | AX30: / | AY30: 0 | AZ30: 0 | BA30: 0 | BB30: 0 | BC30: WRWT21720/WRWT25800 | BD30: 0
A31: 45854 | B31: MK68-000891 | C31: บจก.เคอรี่ฟลาวมิลล์ | D31: 8S | E31: 19 | F31: 32 | G31: ขาว | H31: 0 | I31: 67 | J31: + | K31: 5 | L31: ไม่ | M31: ไม่สวมถุงใน | N31: 0 | O31: 0 | P31: 0 | Q31: 0 | R31: 0 | S31: ห่ออัดเบลแบน500 | T31: 45871 | U31: 5000 | V31: 5000 | W31: 0 | X31: 5300 | Y31: 0 | Z31: WSWT1921720 | AA31: 0 | AB31: 0 | AC31: 0 | AD31: 0 | AE31: 0 | AF31: PDR250229 | AG31: พร้อมส่ง | AH31: P7 | AI31: 2 | AJ31: 45871 | AK31: 0 | AL31: 45862 | AM31: 45869 | AN31: 45870 | AO31: 45870 | AP31: 45866 | AQ31: 0 | AR31: 0 | AS31: 0 | AT31: 0 | AU31: 0 | AV31: 0 | AW31: งานพิมพ์ | AX31: / | AY31: 0 | AZ31: 0 | BA31: 0 | BB31: 0 | BC31: WRWT21720/WRWT25800 | BD31: 0
A32: 45854 | B32: MK68-000891 | C32: บจก.เคอรี่ฟลาวมิลล์ | D32: หีบเพลงแดง | E32: 19 | F32: 32 | G32: ขาว | H32: 0 | I32: 67 | J32: + | K32: 5 | L32: บิด | M32: ไม่สวมถุงใน | N32: 0 | O32: 0 | P32: 0 | Q32: 0 | R32: 0 | S32: ห่ออัดเบลแบน500 | T32: 45871 | U32: 5000 | V32: 0 | W32: 5000 | X32: 5400 | Y32: 0 | Z32: WSWT1921720 | AA32: 0 | AB32: 0 | AC32: 0 | AD32: 0 | AE32: 0 | AF32: PDR250229 | AG32: รอตัด | AH32: P7 | AI32: 2 | AJ32: 45871 | AK32: 0 | AL32: 45862 | AM32: 45869 | AN32: 45870 | AO32: 45870 | AP32: 45866 | AQ32: 0 | AR32: 0 | AS32: 0 | AT32: 0 | AU32: 0 | AV32: 0 | AW32: งานพิมพ์ | AX32: / | AY32: 0 | AZ32: 0 | BA32: 0 | BB32: 0 | BC32: WRWT21720/WRWT25800 | BD32: 0
A33: 45854 | B33: MK68-000890 | C33: บจก.เคอรี่ฟลาวมิลล์ | D33: ถุงเขียว | E33: 19 | F33: 32 | G33: ขาว | H33: 0 | I33: 67 | J33: + | K33: 5 | L33: บิด | M33: ไม่สวมถุงใน | N33: 0 | O33: 0 | P33: 0 | Q33: 0 | R33: 0 | S33: ห่ออัดเบลแบน500 | T33: 45874 | U33: 10000 | V33: 0 | W33: 10000 | X33: 0 | Y33: 10500 | Z33: WSWT1921720 | AA33: 9359.9 | AB33: 9359.9 | AC33: 0 | AD33: 0 | AE33: 0 | AF33: PDR250230 | AG33: รอตัด | AH33: P7 | AI33: 2 | AJ33: 45874 | AK33: 0 | AL33: 45865 | AM33: 45872 | AN33: 45873 | AO33: 45873 | AP33: 45869 | AQ33: 0 | AR33: 0 | AS33: 0 | AT33: 0 | AU33: 0 | AV33: 0 | AW33: งานพิมพ์ | AX33: / | AY33: 0 | AZ33: 0 | BA33: 0 | BB33: 0 | BC33: WRWT21720/WRWT25800 | BD33: 0
A34: 45854 | B34: MK68-000890 | C34: บจก.เคอรี่ฟลาวมิลล์ | D34: แต้มแดง | E34: 19 | F34: 32 | G34: ขาว | H34: 0 | I34: 67 | J34: + | K34: 5 | L34: บิด | M34: ไม่สวมถุงใน | N34: 0 | O34: 0 | P34: 0 | Q34: 0 | R34: 0 | S34: ห่ออัดเบลแบน500 | T34: 45874 | U34: 5000 | V34: 5000 | W34: 0 | X34: 5800 | Y34: 0 | Z34: WSWT1921720 | AA34: 0 | AB34: 0 | AC34: 0 | AD34: 0 | AE34: 0 | AF34: PDR250230 | AG34: ยังไม่ได้พิมพ์ | AH34: P7 | AI34: 2 | AJ34: 45874 | AK34: 0 | AL34: 45865 | AM34: 45872 | AN34: 45873 | AO34: 45873 | AP34: 45869 | AQ34: 0 | AR34: 0 | AS34: 0 | AT34: 0 | AU34: 0 | AV34: 0 | AW34: งานพิมพ์ | AX34: / | AY34: 0 | AZ34: 0 | BA34: 0 | BB34: 0 | BC34: WRWT21720/WRWT25800 | BD34: 0
A35: 45854 | B35: MK68-000890 | C35: บจก.เคอรี่ฟลาวมิลล์ | D35: ปลาโลมาแดง | E35: 19 | F35: 32 | G35: ขาว | H35: 0 | I35: 67 | J35: + | K35: 5 | L35: บิด | M35: ไม่สวมถุงใน | N35: 0 | O35: 0 | P35: 0 | Q35: 0 | R35: 0 | S35: ห่ออัดเบลแบน500 | T35: 45874 | U35: 5000 | V35: 0 | W35: 5000 | X35: 5250 | Y35: 0 | Z35: WSWT1921720 | AA35: 0 | AB35: 0 | AC35: 0 | AD35: 0 | AE35: 0 | AF35: PDR250230 | AG35: ยังไม่ได้พิมพ์ | AH35: P7 | AI35: 2 | AJ35: 45874 | AK35: 0 | AL35: 45865 | AM35: 45872 | AN35: 45873 | AO35: 45873 | AP35: 45869 | AQ35: 0 | AR35: 0 | AS35: 0 | AT35: 0 | AU35: 0 | AV35: 0 | AW35: งานพิมพ์ | AX35: / | AY35: 0 | AZ35: 0 | BA35: 0 | BB35: 0 | BC35: WRWT21720/WRWT25800 | BD35: 0
A36: 45854 | B36: MK68-000890 | C36: บจก.เคอรี่ฟลาวมิลล์ | D36: ดอกไม้เหลือง | E36: 19 | F36: 32 | G36: ขาว | H36: 0 | I36: 67 | J36: + | K36: 5 | L36: บิด | M36: ไม่สวมถุงใน | N36: 0 | O36: 0 | P36: 0 | Q36: 0 | R36: 0 | S36: ห่ออัดเบลแบน500 | T36: 45874 | U36: 5000 | V36: 0 | W36: 5000 | X36: 5200 | Y36: 0 | Z36: WSWT1921720 | AA36: 0 | AB36: 0 | AC36: 0 | AD36: 0 | AE36: 0 | AF36: PDR250230 | AG36: ยังไม่ได้พิมพ์ | AH36: P7 | AI36: 2 | AJ36: 45874 | AK36: 0 | AL36: 45865 | AM36: 45872 | AN36: 45873 | AO36: 45873 | AP36: 45869 | AQ36: 0 | AR36: 0 | AS36: 0 | AT36: 0 | AU36: 0 | AV36: 0 | AW36: งานพิมพ์ | AX36: / | AY36: 0 | AZ36: 0 | BA36: 0 | BB36: 0 | BC36: WRWT21720/WRWT25800 | BD36: 0
A37: 45854 | B37: MK68-000891 | C37: บจก.เคอรี่ฟลาวมิลล์ | D37: ดอกไม้ม่วง | E37: 19 | F37: 32 | G37: ขาว | H37: 0 | I37: 67 | J37: + | K37: 5 | L37: บิด | M37: ไม่สวมถุงใน | N37: 0 | O37: 0 | P37: 0 | Q37: 0 | R37: 0 | S37: ห่ออัดเบลแบน500 | T37: 45874 | U37: 5000 | V37: 0 | W37: 5000 | X37: 0 | Y37: 5250 | Z37: WSWT1921720 | AA37: 4679.95 | AB37: 4679.95 | AC37: 0 | AD37: 0 | AE37: 0 | AF37: PDR250231 | AG37: พิมพ์ไม่ครบ | AH37: P7 | AI37: 2 | AJ37: 45874 | AK37: 0 | AL37: 45865 | AM37: 45872 | AN37: 45873 | AO37: 45873 | AP37: 45869 | AQ37: 0 | AR37: 0 | AS37: 0 | AT37: 0 | AU37: 0 | AV37: 0 | AW37: งานพิมพ์ | AX37: / | AY37: 0 | AZ37: 0 | BA37: 0 | BB37: 0 | BC37: WRWT21720/WRWT25800 | BD37: 0
A38: 45854 | B38: MK68-000891 | C38: บจก.เคอรี่ฟลาวมิลล์ | D38: ดอกไม้แดง | E38: 19 | F38: 32 | G38: ขาว | H38: 0 | I38: 67 | J38: + | K38: 5 | L38: บิด | M38: ไม่สวมถุงใน | N38: 0 | O38: 0 | P38: 0 | Q38: 0 | R38: 0 | S38: ห่ออัดเบลแบน500 | T38: 45874 | U38: 5000 | V38: 0 | W38: 5000 | X38: 0 | Y38: 5250 | Z38: WSWT1921720 | AA38: 4679.95 | AB38: 3561 | AC38: 1118.95 | AD38: 0 | AE38: 0 | AF38: PDR250231 | AG38: พร้อมส่ง | AH38: P7 | AI38: 2 | AJ38: 45874 | AK38: 0 | AL38: 45865 | AM38: 45872 | AN38: 45873 | AO38: 45873 | AP38: 45869 | AQ38: 0 | AR38: 0 | AS38: 0 | AT38: 0 | AU38: 0 | AV38: 0 | AW38: งานพิมพ์ | AX38: / | AY38: 0 | AZ38: 0 | BA38: 0 | BB38: 0 | BC38: WRWT21720/WRWT25800 | BD38: 84.284287
... A40: 45854 | B40: MK68-000891 | C40: บจก.เคอรี่ฟลาวมิลล์ | D40: หีบเพลงเหลือง | E40: 19 | F40: 32 | G40: ขาว | H40: 0 | I40: 67 | J40: + | K40: 5 | L40: บิด | M40: ไม่สวมถุงใน | N40: 0 | O40: 0 | P40: 0 | Q40: 0 | R40: 0 | S40: ห่ออัดเบลแบน500 | T40: 45874 | U40: 5000 | V40: 0 | W40: 5000 | X40: 2400 | Y40: 2730 | Z40: WSWT1921720 | AA40: 2555.2527 | AB40: 2555.2527 | AC40: 0 | AD40: 0 | AE40: 0 | AF40: PDR250231 | AG40: ยังไม่ได้พิมพ์ | AH40: P7 | AI40: 2 | AJ40: 45874 | AK40: 0 | AL40: 45865 | AM40: 45872 | AN40: 45873 | AO40: 45873 | AP40: 45869 | AQ40: 0 | AR40: 0 | AS40: 0 | AT40: 0 | AU40: 0 | AV40: 0 | AW40: งานพิมพ์ | AX40: / | AY40: 0 | AZ40: 0 | BA40: 0 | BB40: 0 | BC40: WRWT21720/WRWT25800 | BD40: 0
A41: 45857 | B41: MK68-000909 | C41: บจก.เคอรี่ฟลาวมิลล์ | D41: ปลาโลมาเทา | E41: 19 | F41: 32 | G41: ขาว | H41: 0 | I41: 67 | J41: + | K41: 5 | L41: บิด | M41: ไม่สวมถุงใน | N41: 0 | O41: 0 | P41: 0 | Q41: 0 | R41: 0 | S41: ห่ออัดเบลแบน500 | T41: 45874 | U41: 5000 | V41: 5000 | W41: 0 | X41: 5200 | Y41: 0 | Z41: WSWT1921720 | AA41: 0 | AB41: 0 | AC41: 0 | AD41: 0 | AE41: 0 | AF41: PDR250235 | AG41: พร้อมส่ง | AH41: P7 | AI41: 2 | AJ41: 45874 | AK41: 0 | AL41: 45865 | AM41: 45872 | AN41: 45873 | AO41: 45873 | AP41: 45869 | AQ41: 0 | AR41: 0 | AS41: 0 | AT41: 0 | AU41: 0 | AV41: 0 | AW41: งานพิมพ์ | AX41: / | AY41: ลบสี | AZ41: 0 | BA41: 0 | BB41: 0 | BC41: WRWT21720/WRWT25800 | BD41: 0
A42: 45854 | B42: MK68-000890 | C42: บจก.เคอรี่ฟลาวมิลล์ | D42: ปลาโลมาเทา | E42: 19 | F42: 32 | G42: ขาว | H42: 0 | I42: 67 | J42: + | K42: 5 | L42: บิด | M42: ไม่สวมถุงใน | N42: 0 | O42: 0 | P42: 0 | Q42: 0 | R42: 0 | S42: ห่ออัดเบลแบน500 | T42: 45876 | U42: 5000 | V42: 0 | W42: 5000 | X42: 0 | Y42: 5250 | Z42: WSWT1921720 | AA42: 4679.95 | AB42: 0 | AC42: 4679.95 | AD42: 0 | AE42: 0 | AF42: PDR250232 | AG42: รอตัด | AH42: P7 | AI42: 2 | AJ42: 45876 | AK42: 0 | AL42: 45867 | AM42: 45874 | AN42: 45875 | AO42: 45875 | AP42: 45871 | AQ42: 0 | AR42: 0 | AS42: 0 | AT42: 0 | AU42: 0 | AV42: 0 | AW42: งานพิมพ์ | AX42: / | AY42: 0 | AZ42: 0 | BA42: 0 | BB42: 0 | BC42: WRWT21720/WRWT25800 | BD42: 352.51463
...

Sheet 29-7-68
B2: เรียงกำหนดส่ง | D2: ลบ 0 | T2: เรียง 1
B3: ข้อมูลUpdate ณ. วันที่ | D3: 45864 | E3: เวลา | G3: 9.31
A4: วันรับออร์เดอร์/แบบ | B4: เลขที่ SO | C4: ชื่อลูกค้า | E4: 10.3 | I4: น้ำหนัก | L4: บิด/จับจีบ | M4: ถุงใน | Q4: =[1]หน้าผ้า!$AC$13 -> 44873 | S4: วิธีบรรจุ | T4: วันส่ง | U4: จำนวนส่ง | V4: ตัดเย็บ (ใบ) | W4: =[1]หน้าผ้า!$AJ$13 -> 44873 | X4: พิมพ์ (ใบ) | Y4: =[1]หน้าผ้า!$AM$13 -> 44876 | Z4: ผ้าทอ (เมตร) Updateณ | AB4: =[1]หน้าผ้า!$AR$12 -> 44876 | AD4: ผ้าเคลือบ(เมตร) | AF4: หมายเหตุ | AG4: เครื่อง
B5: เลขที่ SO | C5: ชื่อลูกค้า | D5: ตรา | E5: กว้าง | F5: ยาว | G5: สี | H5: เคลือบ | I5: กรัม/ใบ | J5: * | K5: aw | L5: บิด/จับจีบ | M5: กว้าง | N5: ยาว | O5: หนา | P5: ใช้(กก.) | Q5: Stock(กก.) | R5: ผลิต(กก.) | S5: วิธีบรรจุ | T5: วันส่ง | U5: จำนวนส่ง | V5: StockFG | W5: ค้างตัด | X5: พิมพ์แล้ว | Y5: ค้างพิมพ์ | Z5: ประเภท | AA5: ใช้ | AB5: Stock | AC5: ค้างทอ | AD5: Stock | AE5: ค้างเคลือบ | AF5: หมายเหตุ | AG5: ที่พิมพ์ได้ | AH5: process | AI5: Lead time | AJ5: วันที่ส่งPL | AK5: เคลือบ | AL5: ได้ ART | AM5: พิมพ์ | AN5: จีบ-บิด | AO5: ตัด-เย็บ | AP5: ทอ | AQ5: สวมถุง | AR5: เย็บปาก | AS5: PT | AT5: ม้วน | AU5: ตัด | AV5: ตอกตาไก่ | AW5: GROUP | AX5: ART | AY5: หมายเหตุปัญหา | AZ5: ราคา/ใบ | BA5: ราคารวม | BB5: workweek | BC5: เส้นเทป | BD5: จำนวน
A6: =[2]หน้าผ้า!C16 -> 45860 | B6: =[2]หน้าผ้า!B16 -> MK68-000920 | C6: =[2]หน้าผ้า!E16 -> หจก.ปึงเป้งน้ำ | D6: =[2]หน้าผ้า!F16 -> เกลือตรามือ 10กก. | E6: =[2]หน้าผ้า!G16 -> 14 | F6: =[2]หน้าผ้า!H16 -> 22 | G6: =[2]หน้าผ้า!I16 -> ขาว | H6: =[2]หน้าผ้า!J16 -> ใส | I6: =[2]หน้าผ้า!L16 -> 42 | J6: =[2]หน้าผ้า!M16 -> ± | K6: =[2]หน้าผ้า!N16 -> 5 | L6: =[2]หน้าผ้า!R16 -> ไม่ | M6: =[2]หน้าผ้า!T16 -> ไม่สวมถุงใน | N6: =[2]หน้าผ้า!U16 -> 0 | O6: =[2]หน้าผ้า!V16 -> 0 | P6: =[2]หน้าผ้า!AB16 -> 0 | Q6: =[2]หน้าผ้า!AC16 -> 0 | R6: =[2]หน้าผ้า!AD16 -> 0 | S6: =[2]หน้าผ้า!Z16 -> 500กระสอบแบน | T6: =[2]หน้าผ้า!X16 -> 45884 | U6: =[2]หน้าผ้า!AA16 -> 10000 | V6: =[2]หน้าผ้า!AJ16 -> 0 | W6: =[2]หน้าผ้า!AL16 -> 10000 | X6: =[2]หน้าผ้า!AM16 -> 0 | Y6: =[2]หน้าผ้า!AN16 -> 10500 | Z6: =[2]หน้าผ้า!AO16 -> WSWT1425800 | AA6: =[2]หน้าผ้า!AQ16 -> 6565.9 | AB6: =[2]หน้าผ้า!AR16 -> 6565.9 | AC6: =[2]หน้าผ้า!AS16 -> 0 | AD6: =[2]หน้าผ้า!AT16 -> 0 | AE6: =[2]หน้าผ้า!AU16 -> 6565.9 | AF6: =[2]หน้าผ้า!AI16 -> 0 | AG6: =[3]หน้าผ้า!DC19 -> ยังไม่ได้พิมพ์ | AH6: =[2]หน้าผ้า!DL16 -> P6 | AI6: =[2]หน้าผ้า!DM16 -> 4 | AJ6: =[2]หน้าผ้า!DN16 -> 45884 | AK6: =[2]หน้าผ้า!DQ16 -> 45880 | AL6: =[2]หน้าผ้า!DR16 -> 45873 | AM6: =[2]หน้าผ้า!DS16 -> 45881 | AN6: =[2]หน้าผ้า!DT16 -> 45882 | AO6: =[2]หน้าผ้า!DU16 -> 45883 | AP6: =[2]หน้าผ้า!DP16 -> 45879 | AQ6: =[2]หน้าผ้า!DW16 -> 0 | AR6: =[2]หน้าผ้า!DX16 -> 0 | AS6: =[2]หน้าผ้า!DY16 -> 0 | AT6: =[2]หน้าผ้า!DZ16 -> 0 | AU6: =[2]หน้าผ้า!EA16 -> 0 | AV6: =[2]หน้าผ้า!EB16 -> 0 | AW6: =[2]หน้าผ้า!EC16 -> งานเคลือบ+พิมพ์ | AX6: =[2]หน้าผ้า!ED16 -> / | AY6: =[2]หน้าผ้า!AG16 -> 0 | AZ6: =[2]หน้าผ้า!EG16 -> 0 | BA6: =[2]หน้าผ้า!EH16 -> 0 | BB6: =[2]หน้าผ้า!EI16 -> 0 | BC6: =[2]หน้าผ้า!BZ16 -> WRWT25800/WRWT25800 | BD6: =[2]หน้าผ้า!CA16 -> 0
A7: =[2]หน้าผ้า!C17 -> 0 | B7: =[2]หน้าผ้า!B17 -> 0 | C7: =[2]หน้าผ้า!E17 -> 0 | D7: =[2]หน้าผ้า!F17 -> 0 | E7: =[2]หน้าผ้า!G17 -> 14 | F7: =[2]หน้าผ้า!H17 -> 22 | G7: =[2]หน้าผ้า!I17 -> ขาว | H7: =[2]หน้าผ้า!J17 -> 0 | I7: =[2]หน้าผ้า!L17 -> 36 | J7: =[2]หน้าผ้า!M17 -> ± | K7: =[2]หน้าผ้า!N17 -> 5 | L7: =[2]หน้าผ้า!R17 -> 0 | M7: =[2]หน้าผ้า!T17 -> 0 | N7: =[2]หน้าผ้า!U17 -> 0 | O7: =[2]หน้าผ้า!V17 -> 0 | P7: =[2]หน้าผ้า!AB17 -> 0 | Q7: =[2]หน้าผ้า!AC17 -> 0 | R7: =[2]หน้าผ้า!AD17 -> 0 | S7: =[2]หน้าผ้า!Z17 -> 0 | U7: =[2]หน้าผ้า!AA17 -> 0 | V7: =[2]หน้าผ้า!AJ17 -> 0 | W7: =[2]หน้าผ้า!AL17 -> 0 | X7: =[2]หน้าผ้า!AM17 -> 0 | Y7: =[2]หน้าผ้า!AN17 -> 0 | Z7: =[2]หน้าผ้า!AO17 -> WSWT1425800 | AA7: =[2]หน้าผ้า!AQ17 -> 6565.9 | AB7: =[2]หน้าผ้า!AR17 -> 6565.9 | AC7: =[2]หน้าผ้า!AS17 -> 0 | AD7: =[2]หน้าผ้า!AT17 -> 0 | AE7: =[2]หน้าผ้า!AU17 -> 6565.9 | AF7: =[2]หน้าผ้า!AI17 -> ระบุในSD | AG7: =[3]หน้าผ้า!DC20 -> พร้อมส่ง | AH7: =[2]หน้าผ้า!DL17 -> 0 | AI7: =[2]หน้าผ้า!DM17 -> Lead time | AJ7: =[2]หน้าผ้า!DN17 -> 0 | AK7: =[2]หน้าผ้า!DQ17 -> 0 | AL7: =[2]หน้าผ้า!DR17 -> 0 | AM7: =[2]หน้าผ้า!DS17 -> 0 | AN7: =[2]หน้าผ้า!DT17 -> 0 | AO7: =[2]หน้าผ้า!DU17 -> 0 | AP7: =[2]หน้าผ้า!DP17 -> 0 | AQ7: =[2]หน้าผ้า!DW17 -> 0 | AR7: =[2]หน้าผ้า!DX17 -> 0 | AS7: =[2]หน้าผ้า!DY17 -> 0 | AT7: =[2]หน้าผ้า!DZ17 -> 0 | AU7: =[2]หน้าผ้า!EA17 -> 0 | AV7: =[2]หน้าผ้า!EB17 -> 0 | AW7: =[2]หน้าผ้า!EC17 -> 0 | AX7: =[2]หน้าผ้า!ED17 -> 0 | AY7: =[2]หน้าผ้า!AG17 -> 0 | AZ7: =[2]หน้าผ้า!EG17 -> 0 | BA7: =[2]หน้าผ้า!EH17 -> 0 | BB7: =[2]หน้าผ้า!EI17 -> 0 | BC7: =[2]หน้าผ้า!BZ17 -> WRWT140800/WRWT25800 | BD7: =[2]หน้าผ้า!CA17 -> 0
A8: =[2]หน้าผ้า!C18 -> 45842 | B8: =[2]หน้าผ้า!B18 -> MK68-000868 | C8: =[2]หน้าผ้า!E18 -> พีมินเนอร์ | D8: =[2]หน้าผ้า!F18 -> พี-มินเนอร์ นิวพลัส | E8: =[2]หน้าผ้า!G18 -> 16 | F8: =[2]หน้าผ้า!H18 -> 28 | G8: =[2]หน้าผ้า!I18 -> ขาว | H8: =[2]หน้าผ้า!J18 -> ใส | I8: =[2]หน้าผ้า!L18 -> 56 | J8: =[2]หน้าผ้า!M18 -> ± | K8: =[2]หน้าผ้า!N18 -> 5 | L8: =[2]หน้าผ้า!R18 -> ไม่ | M8: =[2]หน้าผ้า!T18 -> 19 | N8: =[2]หน้าผ้า!U18 -> 31 | O8: =[2]หน้าผ้า!V18 -> 40 | P8: =[2]หน้าผ้า!AB18 -> 1.1334313 | Q8: =[2]หน้าผ้า!AC18 -> 0 | R8: =[2]หน้าผ้า!AD18 -> 1.1334313 | S8: =[2]หน้าผ้า!Z18 -> 500กระสอบ | T8: =[2]หน้าผ้า!X18 -> 45869 | U8: =[2]หน้าผ้า!AA18 -> 4000 | V8: =[2]หน้าผ้า!AJ18 -> 3922 | W8: =[2]หน้าผ้า!AL18 -> 78 | X8: =[2]หน้าผ้า!AM18 -> 5295 | Y8: =[2]หน้าผ้า!AN18 -> 0 | Z8: =[2]หน้าผ้า!AO18 -> WSWT1625800SM | AA8: =[2]หน้าผ้า!AQ18 -> 0 | AB8: =[2]หน้าผ้า!AR18 -> 0 | AC8: =[2]หน้าผ้า!AS18 -> 0 | AD8: =[2]หน้าผ้า!AT18 -> 0 | AE8: =[2]หน้าผ้า!AU18 -> 0 | AF8: =[2]หน้าผ้า!AI18 -> รอส่ง รอลูกค้ามารับเอง | AG8: =[3]หน้าผ้า!DC21 -> พร้อมส่ง | AH8: =[2]หน้าผ้า!DL18 -> P8 | AI8: =[2]หน้าผ้า!DM18 -> 4 | AJ8: =[2]หน้าผ้า!DN18 -> 45869 | AK8: =[2]หน้าผ้า!DQ18 -> 45865 | AL8: =[2]หน้าผ้า!DR18 -> 45859 | AM8: =[2]หน้าผ้า!DS18 -> 45866 | AN8: =[2]หน้าผ้า!DT18 -> 45867 | AO8: =[2]หน้าผ้า!DU18 -> 45867 | AP8: =[2]หน้าผ้า!DP18 -> 45864 | AQ8: =[2]หน้าผ้า!DW18 -> 45868 | AR8: =[2]หน้าผ้า!DX18 -> 0 | AS8: =[2]หน้าผ้า!DY18 -> 0 | AT8: =[2]หน้าผ้า!DZ18 -> 0 | AU8: =[2]หน้าผ้า!EA18 -> 0 | AV8: =[2]หน้าผ้า!EB18 -> 0 | AW8: =[2]หน้าผ้า!EC18 -> งานเคลือบ+พิมพ์ | AX8: =[2]หน้าผ้า!ED18 -> / | AY8: =[2]หน้าผ้า!AG18 -> 0 | AZ8: =[2]หน้าผ้า!EG18 -> 0 | BA8: =[2]หน้าผ้า!EH18 -> 0 | BB8: =[2]หน้าผ้า!EI18 -> 0 | BC8: =[2]หน้าผ้า!BZ18 -> WRWT25800/WRWT25800 | BD8: =[2]หน้าผ้า!CA18 -> 0
A9: =[2]หน้าผ้า!C19 -> ประมาณการ | B9: =[2]หน้าผ้า!B19 -> ประมาณการ | C9: =[2]หน้าผ้า!E19 -> บจก.ซัน ซีเมนต์ โพรเซส | D9: =[2]หน้าผ้า!F19 -> พระอาทิตย์(ปูนนอน-ชริงค์) | E9: =[2]หน้าผ้า!G19 -> 16 | F9: =[2]หน้าผ้า!H19 -> 25 | G9: =[2]หน้าผ้า!I19 -> ขาว | H9: =[2]หน้าผ้า!J19 -> ใส | I9: =[2]หน้าผ้า!L19 -> 50 | J9: =[2]หน้าผ้า!M19 -> ± | K9: =[2]หน้าผ้า!N19 -> 5 | L9: =[2]หน้าผ้า!R19 -> บิด | M9: =[2]หน้าผ้า!T19 -> 19 | N9: =[2]หน้าผ้า!U19 -> 28 | O9: =[2]หน้าผ้า!V19 -> 40 | P9: =[2]หน้าผ้า!AB19 -> 65.624643 | Q9: =[2]หน้าผ้า!AC19 -> 0 | R9: =[2]หน้าผ้า!AD19 -> 65.624643 | S9: =[2]หน้าผ้า!Z19 -> 500กระสอบ | T9: =[2]หน้าผ้า!X19 -> รอแจ้ง | U9: =[2]หน้าผ้า!AA19 -> 5000 | V9: =[2]หน้าผ้า!AJ19 -> 0 | W9: =[2]หน้าผ้า!AL19 -> 5000 | X9: =[2]หน้าผ้า!AM19 -> 0 | Y9: =[2]หน้าผ้า!AN19 -> 5250 | Z9: =[2]หน้าผ้า!AO19 -> WSWT1625800SM | AA9: =[2]หน้าผ้า!AQ19 -> 3702.05 | AB9: =[2]หน้าผ้า!AR19 -> 0 | AC9: =[2]หน้าผ้า!AS19 -> 3702.05 | AD9: =[2]หน้าผ้า!AT19 -> 0 | AE9: =[2]หน้าผ้า!AU19 -> 3702.05 | AF9: =[2]หน้าผ้า!AI19 -> 0 | AG9: =[3]หน้าผ้า!DC22 -> พร้อมส่ง | AH9: =[2]หน้าผ้า!DL19 -> P8 | AI9: =[2]หน้าผ้า!DM19 -> 4 | AJ9: =[2]หน้าผ้า!DN19 -> รอแจ้ง | AK9: =[2]หน้าผ้า!DQ19 -> #VALUE! | AL9: =[2]หน้าผ้า!DR19 -> #VALUE! | AM9: =[2]หน้าผ้า!DS19 -> #VALUE! | AN9: =[2]หน้าผ้า!DT19 -> #VALUE! | AO9: =[2]หน้าผ้า!DU19 -> #VALUE! | AP9: =[2]หน้าผ้า!DP19 -> #VALUE! | AQ9: =[2]หน้าผ้า!DW19 -> #VALUE! | AR9: =[2]หน้าผ้า!DX19 -> 0 | AS9: =[2]หน้าผ้า!DY19 -> 0 | AT9: =[2]หน้าผ้า!DZ19 -> 0 | AU9: =[2]หน้าผ้า!EA19 -> 0 | AV9: =[2]หน้าผ้า!EB19 -> 0 | AW9: =[2]หน้าผ้า!EC19 -> งานเคลือบ+พิมพ์ | AX9: =[2]หน้าผ้า!ED19 -> รอART | AY9: =[2]หน้าผ้า!AG19 -> 0 | AZ9: =[2]หน้าผ้า!EG19 -> 0 | BA9: =[2]หน้าผ้า!EH19 -> 0 | BB9: =[2]หน้าผ้า!EI19 -> 0 | BC9: =[2]หน้าผ้า!BZ19 -> WRWT25800/WRWT25800 | BD9: =[2]หน้าผ้า!CA19 -> 210.60551
A10: =[2]หน้าผ้า!C20 -> 0 | B10: =[2]หน้าผ้า!B20 -> 0 | C10: =[2]หน้าผ้า!E20 -> 0 | D10: =[2]หน้าผ้า!F20 | E10: =[2]หน้าผ้า!G20 -> 16 | F10: =[2]หน้าผ้า!H20 -> 25 | G10: =[2]หน้าผ้า!I20 -> ขาว | H10: =[2]หน้าผ้า!J20 -> 0 | I10: =[2]หน้าผ้า!L20 -> 45 | J10: =[2]หน้าผ้า!M20 -> ± | K10: =[2]หน้าผ้า!N20 -> 5 | L10: =[2]หน้าผ้า!R20 -> 0 | M10: =[2]หน้าผ้า!T20 -> 0 | N10: =[2]หน้าผ้า!U20 -> 0 | O10: =[2]หน้าผ้า!V20 -> 0 | P10: =[2]หน้าผ้า!AB20 -> 0 | Q10: =[2]หน้าผ้า!AC20 -> 0 | R10: =[2]หน้าผ้า!AD20 -> 0 | S10: =[2]หน้าผ้า!Z20 -> 0 | U10: =[2]หน้าผ้า!AA20 -> 0 | V10: =[2]หน้าผ้า!AJ20 -> 0 | W10: =[2]หน้าผ้า!AL20 -> 0 | X10: =[2]หน้าผ้า!AM20 -> 0 | Y10: =[2]หน้าผ้า!AN20 -> 0 | Z10: =[2]หน้าผ้า!AO20 -> WSWT1625800SM | AA10: =[2]หน้าผ้า!AQ20 -> 3702.05 | AB10: =[2]หน้าผ้า!AR20 -> 0 | AC10: =[2]หน้าผ้า!AS20 -> 3702.05 | AD10: =[2]หน้าผ้า!AT20 -> 0 | AE10: =[2]หน้าผ้า!AU20 -> 3702.05 | AF10: =[2]หน้าผ้า!AI20 -> ระบุในSD | AG10: =[3]หน้าผ้า!DC23 -> พร้อมส่ง | AH10: =[2]หน้าผ้า!DL20 -> 0 | AI10: =[2]หน้าผ้า!DM20 -> Lead time | AJ10: =[2]หน้าผ้า!DN20 -> 0 | AK10: =[2]หน้าผ้า!DQ20 -> 0 | AL10: =[2]หน้าผ้า!DR20 -> 0 | AM10: =[2]หน้าผ้า!DS20 -> 0 | AN10: =[2]หน้าผ้า!DT20 -> 0 | AO10: =[2]หน้าผ้า!DU20 -> 0 | AP10: =[2]หน้าผ้า!DP20 -> 0 | AQ10: =[2]หน้าผ้า!DW20 -> 0 | AR10: =[2]หน้าผ้า!DX20 -> 0 | AS10: =[2]หน้าผ้า!DY20 -> 0 | AT10: =[2]หน้าผ้า!DZ20 -> 0 | AU10: =[2]หน้าผ้า!EA20 -> 0 | AV10: =[2]หน้าผ้า!EB20 -> 0 | AW10: =[2]หน้าผ้า!EC20 -> 0 | AX10: =[2]หน้าผ้า!ED20 -> 0 | AY10: =[2]หน้าผ้า!AG20 -> 0 | AZ10: =[2]หน้าผ้า!EG20 -> 0 | BA10: =[2]หน้าผ้า!EH20 -> 0 | BB10: =[2]หน้าผ้า!EI20 -> 0 | BC10: =[2]หน้าผ้า!BZ20 -> WRWT160800/WRWT25800 | BD10: =[2]หน้าผ้า!CA20 -> 0
A11: =[2]หน้าผ้า!C23 -> 0 | B11: =[2]หน้าผ้า!B23 -> 0 | C11: =[2]หน้าผ้า!E23 -> 0 | D11: =[2]หน้าผ้า!F23 -> 0 | E11: =[2]หน้าผ้า!G23 -> 17 | F11: =[2]หน้าผ้า!H23 -> 26 | G11: =[2]หน้าผ้า!I23 -> 0 | H11: =[2]หน้าผ้า!J23 -> 0 | I11: =[2]หน้าผ้า!L23 -> 48 | J11: =[2]หน้าผ้า!M23 -> ± | K11: =[2]หน้าผ้า!N23 -> 5 | L11: =[2]หน้าผ้า!R23 -> 0 | M11: =[2]หน้าผ้า!T23 -> 0 | N11: =[2]หน้าผ้า!U23 -> 0 | O11: =[2]หน้าผ้า!V23 -> 0 | P11: =[2]หน้าผ้า!AB23 -> 0 | Q11: =[2]หน้าผ้า!AC23 -> 0 | R11: =[2]หน้าผ้า!AD23 -> 0 | S11: =[2]หน้าผ้า!Z23 -> 0 | T11: =[2]หน้าผ้า!X23 -> 0 | U11: =[2]หน้าผ้า!AA23 -> 0 | V11: =[2]หน้าผ้า!AJ23 -> 0 | W11: =[2]หน้าผ้า!AL23 -> 0 | X11: =[2]หน้าผ้า!AM23 -> 0 | Y11: =[2]หน้าผ้า!AN23 -> 0 | Z11: =[2]หน้าผ้า!AO23 -> WSWT1725800 | AA11: =[2]หน้าผ้า!AQ23 -> #REF! | AB11: =[2]หน้าผ้า!AR23 -> #REF! | AC11: =[2]หน้าผ้า!AS23 -> #REF! | AD11: =[2]หน้าผ้า!AT23 -> #REF! | AE11: =[2]หน้าผ้า!AU23 -> #REF! | AF11: =[2]หน้าผ้า!AI23 -> ระบุในSD | AG11: =[3]หน้าผ้า!DC26 -> ยังไม่ได้พิมพ์ | AH11: =[2]หน้าผ้า!DL23 -> 0 | AI11: =[2]หน้าผ้า!DM23 -> 0 | AJ11: =[2]หน้าผ้า!DN23 -> 0 | AK11: =[2]หน้าผ้า!DQ23 -> 0 | AL11: =[2]หน้าผ้า!DR23 -> 0 | AM11: =[2]หน้าผ้า!DS23 -> 0 | AN11: =[2]หน้าผ้า!DT23 -> 0 | AO11: =[2]หน้าผ้า!DU23 -> 0 | AP11: =[2]หน้าผ้า!DP23 -> 0 | AQ11: =[2]หน้าผ้า!DW23 -> 0 | AR11: =[2]หน้าผ้า!DX23 -> 0 | AS11: =[2]หน้าผ้า!DY23 -> 0 | AT11: =[2]หน้าผ้า!DZ23 -> 0 | AU11: =[2]หน้าผ้า!EA23 -> 0 | AV11: =[2]หน้าผ้า!EB23 -> 0 | AW11: =[2]หน้าผ้า!EC23 -> 0 | AX11: =[2]หน้าผ้า!ED23 -> 0 | AY11: =[2]หน้าผ้า!AG23 -> 0 | AZ11: =[2]หน้าผ้า!EG23 -> 0 | BA11: =[2]หน้าผ้า!EH23 -> 0 | BB11: =[2]หน้าผ้า!EI23 -> 0 | BC11: =[2]หน้าผ้า!BZ23 -> WRWT170800/WRWT25800 | BD11: =[2]หน้าผ้า!CA23 -> 0
A12: =[2]หน้าผ้า!C24 -> ประมาณการ | B12: =[2]หน้าผ้า!B24 -> ประมาณการ | C12: =[2]หน้าผ้า!E24 -> บจก.ฟาร์เธอร์ส วิง ซัพพลาย | D12: =[2]หน้าผ้า!F24 -> รถไฟ | E12: =[2]หน้าผ้า!G24 -> 18 | F12: =[2]หน้าผ้า!H24 -> 30 | G12: =[2]หน้าผ้า!I24 -> ขาว | H12: =[2]หน้าผ้า!J24 -> 0 | I12: =[2]หน้าผ้า!L24 -> 54 | J12: =[2]หน้าผ้า!M24 -> ± | K12: =[2]หน้าผ้า!N24 -> 5 | L12: =[2]หน้าผ้า!R24 -> บิด | M12: =[2]หน้าผ้า!T24 -> 19 | N12: =[2]หน้าผ้า!U24 -> 33 | O12: =[2]หน้าผ้า!V24 -> 40 | P12: =[2]หน้าผ้า!AB24 -> 232.02999 | Q12: =[2]หน้าผ้า!AC24 -> 0 | R12: =[2]หน้าผ้า!AD24 -> 232.02999 | S12: =[2]หน้าผ้า!Z24 -> 500กระสอบ | U12: =[2]หน้าผ้า!AA24 -> 15000 | V12: =[2]หน้าผ้า!AJ24 -> 0 | W12: =[2]หน้าผ้า!AL24 -> 15000 | X12: =[2]หน้าผ้า!AM24 -> 0 | Y12: =[2]หน้าผ้า!AN24 -> 15750 | Z12: =[2]หน้าผ้า!AO24 -> WSWT1825800 | AA12: =[2]หน้าผ้า!AQ24 -> 13201.65 | AB12: =[2]หน้าผ้า!AR24 -> 6301 | AC12: =[2]หน้าผ้า!AS24 -> 6900.65 | AD12: =[2]หน้าผ้า!AT24 -> 0 | AE12: =[2]หน้าผ้า!AU24 -> 0 | AF12: =[2]หน้าผ้า!AI24 -> 0 | AG12: =[3]หน้าผ้า!DC27 -> พร้อมส่ง | AH12: =[2]หน้าผ้า!DL24 -> P9 | AI12: =[2]หน้าผ้า!DM24 -> 3 | AJ12: =[2]หน้าผ้า!DN24 -> รอแจ้ง | AK12: =[2]หน้าผ้า!DQ24 -> 0 | AL12: =[2]หน้าผ้า!DR24 -> #VALUE! | AM12: =[2]หน้าผ้า!DS24 -> #VALUE! | AN12: =[2]หน้าผ้า!DT24 -> #VALUE! | AO12: =[2]หน้าผ้า!DU24 -> #VALUE! | AP12: =[2]หน้าผ้า!DP24 -> #VALUE! | AQ12: =[2]หน้าผ้า!DW24 -> #VALUE! | AR12: =[2]หน้าผ้า!DX24 -> 0 | AS12: =[2]หน้าผ้า!DY24 -> 0 | AT12: =[2]หน้าผ้า!DZ24 -> 0 | AU12: =[2]หน้าผ้า!EA24 -> 0 | AV12: =[2]หน้าผ้า!EB24 -> 0 | AW12: =[2]หน้าผ้า!EC24 -> งานพิมพ์ | AX12: =[2]หน้าผ้า!ED24 -> รอART | AY12: =[2]หน้าผ้า!AG24 -> 0 | AZ12: =[2]หน้าผ้า!EG24 -> 0 | BA12: =[2]หน้าผ้า!EH24 -> 0 | BB12: =[2]หน้าผ้า!EI24 -> 0 | BC12: =[2]หน้าผ้า!BZ24 -> WRWT25800/WRWT25800 | BD12: =[2]หน้าผ้า!CA24 -> 474.76472
A13: =[2]หน้าผ้า!C25 -> 0 | B13: =[2]หน้าผ้า!B25 -> 0 | C13: =[2]หน้าผ้า!E25 | D13: =[2]หน้าผ้า!F25 | E13: =[2]หน้าผ้า!G25 -> 18 | F13: =[2]หน้าผ้า!H25 -> 30 | G13: =[2]หน้าผ้า!I25 -> ขาว | H13: =[2]หน้าผ้า!J25 -> 0 | I13: =[2]หน้าผ้า!L25 -> 54 | J13: =[2]หน้าผ้า!M25 -> ± | K13: =[2]หน้าผ้า!N25 -> 5 | L13: =[2]หน้าผ้า!R25 -> 0 | M13: =[2]หน้าผ้า!T25 -> 0 | N13: =[2]หน้าผ้า!U25 -> 0 | O13: =[2]หน้าผ้า!V25 -> 0 | P13: =[2]หน้าผ้า!AB25 -> 0 | Q13: =[2]หน้าผ้า!AC25 -> 0 | R13: =[2]หน้าผ้า!AD25 -> 0 | S13: =[2]หน้าผ้า!Z25 -> 0 | T13: =[2]หน้าผ้า!X25 -> 0 | U13: =[2]หน้าผ้า!AA25 -> 0 | V13: =[2]หน้าผ้า!AJ25 -> 0 | W13: =[2]หน้าผ้า!AL25 -> 0 | X13: =[2]หน้าผ้า!AM25 -> 0 | Y13: =[2]หน้าผ้า!AN25 -> 0 | Z13: =[2]หน้าผ้า!AO25 -> WSWT1825800 | AA13: =[2]หน้าผ้า!AQ25 -> 13201.65 | AB13: =[2]หน้าผ้า!AR25 -> 6301 | AC13: =[2]หน้าผ้า!AS25 -> 6900.65 | AD13: =[2]หน้าผ้า!AT25 -> 0 | AE13: =[2]หน้าผ้า!AU25 -> 0 | AF13: =[2]หน้าผ้า!AI25 -> ระบุในSD | AG13: =[3]หน้าผ้า!DC28 -> ยังไม่ได้พิมพ์ | AH13: =[2]หน้าผ้า!DL25 -> 0 | AI13: =[2]หน้าผ้า!DM25 -> Lead time | AJ13: =[2]หน้าผ้า!DN25 -> 0 | AK13: =[2]หน้าผ้า!DQ25 -> 0 | AL13: =[2]หน้าผ้า!DR25 -> 0 | AM13: =[2]หน้าผ้า!DS25 -> 0 | AN13: =[2]หน้าผ้า!DT25 -> 0 | AO13: =[2]หน้าผ้า!DU25 -> 0 | AP13: =[2]หน้าผ้า!DP25 -> 0 | AQ13: =[2]หน้าผ้า!DW25 -> 0 | AR13: =[2]หน้าผ้า!DX25 -> 0 | AS13: =[2]หน้าผ้า!DY25 -> 0 | AT13: =[2]หน้าผ้า!DZ25 -> 0 | AU13: =[2]หน้าผ้า!EA25 -> 0 | AV13: =[2]หน้าผ้า!EB25 -> 0 | AW13: =[2]หน้าผ้า!EC25 -> 0 | AX13: =[2]หน้าผ้า!ED25 -> 0 | AY13: =[2]หน้าผ้า!AG25 -> 0 | AZ13: =[2]หน้าผ้า!EG25 -> 0 | BA13: =[2]หน้าผ้า!EH25 -> 0 | BB13: =[2]หน้าผ้า!EI25 -> 0 | BC13: =[2]หน้าผ้า!BZ25 -> WRWT25800/WRWT25800 | BD13: =[2]หน้าผ้า!CA25 -> 0
A14: =[2]หน้าผ้า!C26 -> 45860 | B14: =[2]หน้าผ้า!B26 -> MK68-000917 | C14: =[2]หน้าผ้า!E26 -> บจก.ซิเบลโก้(บางเลน) | D14: =[2]หน้าผ้า!F26 -> PORTARYTE B15 | E14: =[2]หน้าผ้า!G26 -> 18 | F14: =[2]หน้าผ้า!H26 -> 30 | G14: =[2]หน้าผ้า!I26 -> ขาว | H14: =[2]หน้าผ้า!J26 -> ใส | I14: =[2]หน้าผ้า!L26 -> 74 | J14: =[2]หน้าผ้า!M26 -> ± | K14: =[2]หน้าผ้า!N26 -> 5 | L14: =[2]หน้าผ้า!R26 -> ไม่ | M14: =[2]หน้าผ้า!T26 -> ไม่สวมถุงใน | N14: =[2]หน้าผ้า!U26 -> 0 | O14: =[2]หน้าผ้า!V26 -> 0 | P14: =[2]หน้าผ้า!AB26 -> 0 | Q14: =[2]หน้าผ้า!AC26 -> 0 | R14: =[2]หน้าผ้า!AD26 -> 0 | S14: =[2]หน้าผ้า!Z26 -> 500กระสอบแบน | U14: =[2]หน้าผ้า!AA26 -> 10000 | V14: =[2]หน้าผ้า!AJ26 -> 0 | W14: =[2]หน้าผ้า!AL26 -> 10000 | X14: =[2]หน้าผ้า!AM26 -> 0 | Y14: =[2]หน้าผ้า!AN26 -> 10500 | Z14: =[2]หน้าผ้า!AO26 -> WSWT1825800SM | AA14: =[2]หน้าผ้า!AQ26 -> 8801.1 | AB14: =[2]หน้าผ้า!AR26 -> 6990 | AC14: =[2]หน้าผ้า!AS26 -> 1811.1 | AD14: =[2]หน้าผ้า!AT26 -> 1997 | AE14: =[2]หน้าผ้า!AU26 -> 6804.1 | AF14: =[2]หน้าผ้า!AI26 -> 0 | AG14: =[3]หน้าผ้า!DC29 -> ยังไม่ได้พิมพ์ | AH14: =[2]หน้าผ้า!DL26 -> P6 | AI14: =[2]หน้าผ้า!DM26 -> 4 | AJ14: =[2]หน้าผ้า!DN26 -> 45883 | AK14: =[2]หน้าผ้า!DQ26 -> 45879 | AL14: =[2]หน้าผ้า!DR26 -> 45872 | AM14: =[2]หน้าผ้า!DS26 -> 45880 | AN14: =[2]หน้าผ้า!DT26 -> 45881 | AO14: =[2]หน้าผ้า!DU26 -> 45882 | AP14: =[2]หน้าผ้า!DP26 -> 45878 | AQ14: =[2]หน้าผ้า!DW26 -> 0 | AR14: =[2]หน้าผ้า!DX26 -> 0 | AS14: =[2]หน้าผ้า!DY26 -> 0 | AT14: =[2]หน้าผ้า!DZ26 -> 0 | AU14: =[2]หน้าผ้า!EA26 -> 0 | AV14: =[2]หน้าผ้า!EB26 -> 0 | AW14: =[2]หน้าผ้า!EC26 -> งานเคลือบ+พิมพ์ | AX14: =[2]หน้าผ้า!ED26 -> / | AY14: =[2]หน้าผ้า!AG26 -> 0 | AZ14: =[2]หน้าผ้า!EG26 -> 0 | BA14: =[2]หน้าผ้า!EH26 -> 0 | BB14: =[2]หน้าผ้า!EI26 -> 0 | BC14: =[2]หน้าผ้า!BZ26 -> WRWT25800/WRWT25800 | BD14: =[2]หน้าผ้า!CA26 -> 115.9104
A15: =[2]หน้าผ้า!C27 -> 0 | B15: =[2]หน้าผ้า!B27 -> 0 | C15: =[2]หน้าผ้า!E27 -> 0 | D15: =[2]หน้าผ้า!F27 | E15: =[2]หน้าผ้า!G27 -> 18 | F15: =[2]หน้าผ้า!H27 -> 25 | G15: =[2]หน้าผ้า!I27 -> ขาว | H15: =[2]หน้าผ้า!J27 -> 0 | I15: =[2]หน้าผ้า!L27 -> 50 | J15: =[2]หน้าผ้า!M27 -> ± | K15: =[2]หน้าผ้า!N27 -> 5 | L15: =[2]หน้าผ้า!R27 -> 0 | M15: =[2]หน้าผ้า!T27 -> 0 | N15: =[2]หน้าผ้า!U27 -> 0 | O15: =[2]หน้าผ้า!V27 -> 0 | P15: =[2]หน้าผ้า!AB27 -> 0 | Q15: =[2]หน้าผ้า!AC27 -> 0 | R15: =[2]หน้าผ้า!AD27 -> 0 | S15: =[2]หน้าผ้า!Z27 -> 0 | T15: =[2]หน้าผ้า!X27 -> 0 | U15: =[2]หน้าผ้า!AA27 -> 0 | V15: =[2]หน้าผ้า!AJ27 -> 0 | W15: =[2]หน้าผ้า!AL27 -> 0 | X15: =[2]หน้าผ้า!AM27 -> 0 | Y15: =[2]หน้าผ้า!AN27 -> 0 | Z15: =[2]หน้าผ้า!AO27 -> WSWT1825800SM | AA15: =[2]หน้าผ้า!AQ27 -> 8801.1 | AB15: =[2]หน้าผ้า!AR27 -> 6990 | AC15: =[2]หน้าผ้า!AS27 -> 1811.1 | AD15: =[2]หน้าผ้า!AT27 -> 1997 | AE15: =[2]หน้าผ้า!AU27 -> 6804.1 | AF15: =[2]หน้าผ้า!AI27 -> ระบุในSD | AG15: =[3]หน้าผ้า!DC30 -> รอแบบ | AH15: =[2]หน้าผ้า!DL27 -> 0 | AI15: =[2]หน้าผ้า!DM27 -> Lead time | AJ15: =[2]หน้าผ้า!DN27 -> 0 | AK15: =[2]หน้าผ้า!DQ27 -> 0 | AL15: =[2]หน้าผ้า!DR27 -> 0 | AM15: =[2]หน้าผ้า!DS27 -> 0 | AN15: =[2]หน้าผ้า!DT27 -> 0 | AO15: =[2]หน้าผ้า!DU27 -> 0 | AP15: =[2]หน้าผ้า!DP27 -> 0 | AQ15: =[2]หน้าผ้า!DW27 -> 0 | AR15: =[2]หน้าผ้า!DX27 -> 0 | AS15: =[2]หน้าผ้า!DY27 -> 0 | AT15: =[2]หน้าผ้า!DZ27 -> 0 | AU15: =[2]หน้าผ้า!EA27 -> 0 | AV15: =[2]หน้าผ้า!EB27 -> 0 | AW15: =[2]หน้าผ้า!EC27 -> 0 | AX15: =[2]หน้าผ้า!ED27 -> 0 | AY15: =[2]หน้าผ้า!AG27 -> 0 | AZ15: =[2]หน้าผ้า!EG27 -> 0 | BA15: =[2]หน้าผ้า!EH27 -> 0 | BB15: =[2]หน้าผ้า!EI27 -> 0 | BC15: =[2]หน้าผ้า!BZ27 -> WRWT180800/WRWT25800 | BD15: =[2]หน้าผ้า!CA27 -> 0
A16: =[2]หน้าผ้า!C28 -> ประมาณการ | B16: =[2]หน้าผ้า!B28 -> ประมาณการ | C16: =[2]หน้าผ้า!E28 -> บจก.เพรซิเดนท์ฟลาวมิลล์ | D16: =[2]หน้าผ้า!F28 -> ผึ้งเหลือง | E16: =[2]หน้าผ้า!G28 -> 19 | F16: =[2]หน้าผ้า!H28 -> 30 | G16: =[2]หน้าผ้า!I28 -> ขาว | H16: =[2]หน้าผ้า!J28 -> 0 | I16: =[2]หน้าผ้า!L28 -> 60 | J16: =[2]หน้าผ้า!M28 -> ± | K16: =[2]หน้าผ้า!N28 -> 5 | L16: =[2]หน้าผ้า!R28 -> บิด | M16: =[2]หน้าผ้า!T28 -> ไม่สวมถุงใน | N16: =[2]หน้าผ้า!U28 -> 0 | O16: =[2]หน้าผ้า!V28 -> 0 | P16: =[2]หน้าผ้า!AB28 -> 0 | Q16: =[2]หน้าผ้า!AC28 -> 0 | R16: =[2]หน้าผ้า!AD28 -> 0 | S16: =[2]หน้าผ้า!Z28 -> 500กระสอบ | U16: =[2]หน้าผ้า!AA28 -> 100000 | V16: =[2]หน้าผ้า!AJ28 -> 0 | W16: =[2]หน้าผ้า!AL28 -> 100000 | X16: =[2]หน้าผ้า!AM28 -> 0 | Y16: =[2]หน้าผ้า!AN28 -> 105000 | Z16: =[2]หน้าผ้า!AO28 -> WSWT1925800 | AA16: =[2]หน้าผ้า!AQ28 -> 88011 | AB16: =[2]หน้าผ้า!AR28 -> 56115 | AC16: =[2]หน้าผ้า!AS28 -> 31896 | AD16: =[2]หน้าผ้า!AT28 -> 0 | AE16: =[2]หน้าผ้า!AU28 -> 0 | AF16: =[2]หน้าผ้า!AI28 -> 0 | AG16: =[3]หน้าผ้า!DC31 -> ยังไม่ได้พิมพ์ | AH16: =[2]หน้าผ้า!DL28 -> P7 | AI16: =[2]หน้าผ้า!DM28 -> 2 | AJ16: =[2]หน้าผ้า!DN28 -> 45894 | AK16: =[2]หน้าผ้า!DQ28 -> 0 | AL16: =[2]หน้าผ้า!DR28 -> 45885 | AM16: =[2]หน้าผ้า!DS28 -> 45892 | AN16: =[2]หน้าผ้า!DT28 -> 45893 | AO16: =[2]หน้าผ้า!DU28 -> 45893 | AP16: =[2]หน้าผ้า!DP28 -> 45889 | AQ16: =[2]หน้าผ้า!DW28 -> 0 | AR16: =[2]หน้าผ้า!DX28 -> 0 | AS16: =[2]หน้าผ้า!DY28 -> 0 | AT16: =[2]หน้าผ้า!DZ28 -> 0 | AU16: =[2]หน้าผ้า!EA28 -> 0 | AV16: =[2]หน้าผ้า!EB28 -> 0 | AW16: =[2]หน้าผ้า!EC28 -> งานพิมพ์ | AX16: =[2]หน้าผ้า!ED28 -> รอART | AY16: =[2]หน้าผ้า!AG28 -> 0 | AZ16: =[2]หน้าผ้า!EG28 -> 0 | BA16: =[2]หน้าผ้า!EH28 -> 0 | BB16: =[2]หน้าผ้า!EI28 -> 0 | BC16: =[2]หน้าผ้า!BZ28 -> WRWT25800/WRWT25800 | BD16: =[2]หน้าผ้า!CA28 -> 2316.3584
A17: =[2]หน้าผ้า!C29 -> ประมาณการ | B17: =[2]หน้าผ้า!B29 -> ประมาณการ | C17: =[2]หน้าผ้า!E29 -> บจก.เพรซิเดนท์ฟลาวมิลล์ | D17: =[2]หน้าผ้า!F29 -> ผึ้งชมพู | E17: =[2]หน้าผ้า!G29 -> 19 | F17: =[2]หน้าผ้า!H29 -> 30 | G17: =[2]หน้าผ้า!I29 -> ขาว | H17: =[2]หน้าผ้า!J29 -> 0 | I17: =[2]หน้าผ้า!L29 -> 60 | J17: =[2]หน้าผ้า!M29 -> ± | K17: =[2]หน้าผ้า!N29 -> 5 | L17: =[2]หน้าผ้า!R29 -> บิด | M17: =[2]หน้าผ้า!T29 -> ไม่สวมถุงใน | N17: =[2]หน้าผ้า!U29 -> 0 | O17: =[2]หน้าผ้า!V29 -> 0 | P17: =[2]หน้าผ้า!AB29 -> 0 | Q17: =[2]หน้าผ้า!AC29 -> 0 | R17: =[2]หน้าผ้า!AD29 -> 0 | S17: =[2]หน้าผ้า!Z29 -> 500กระสอบ | T17: =[2]หน้าผ้า!X29 -> 45894 | U17: =[2]หน้าผ้า!AA29 -> 40000 | V17: =[2]หน้าผ้า!AJ29 -> 0 | W17: =[2]หน้าผ้า!AL29 -> 40000 | X17: =[2]หน้าผ้า!AM29 -> 0 | Y17: =[2]หน้าผ้า!AN29 -> 42000 | Z17: =[2]หน้าผ้า!AO29 -> WSWT1925800 | AA17: =[2]หน้าผ้า!AQ29 -> 35204.4 | AB17: =[2]หน้าผ้า!AR29 -> 0 | AC17: =[2]หน้าผ้า!AS29 -> 35204.4 | AD17: =[2]หน้าผ้า!AT29 -> 0 | AE17: =[2]หน้าผ้า!AU29 -> 0 | AF17: =[2]หน้าผ้า!AI29 -> 0 | AG17: =[3]หน้าผ้า!DC32 -> พร้อมส่ง | AH17: =[2]หน้าผ้า!DL29 -> P7 | AI17: =[2]หน้าผ้า!DM29 -> 2 | AJ17: =[2]หน้าผ้า!DN29 -> 45894 | AK17: =[2]หน้าผ้า!DQ29 -> 0 | AL17: =[2]หน้าผ้า!DR29 -> 45885 | AM17: =[2]หน้าผ้า!DS29 -> 45892 | AN17: =[2]หน้าผ้า!DT29 -> 45893 | AO17: =[2]หน้าผ้า!DU29 -> 45893 | AP17: =[2]หน้าผ้า!DP29 -> 45889 | AQ17: =[2]หน้าผ้า!DW29 -> 0 | AR17: =[2]หน้าผ้า!DX29 -> 0 | AS17: =[2]หน้าผ้า!DY29 -> 0 | AT17: =[2]หน้าผ้า!DZ29 -> 0 | AU17: =[2]หน้าผ้า!EA29 -> 0 | AV17: =[2]หน้าผ้า!EB29 -> 0 | AW17: =[2]หน้าผ้า!EC29 -> งานพิมพ์ | AX17: =[2]หน้าผ้า!ED29 -> รอART | AY17: =[2]หน้าผ้า!AG29 -> 0 | AZ17: =[2]หน้าผ้า!EG29 -> 0 | BA17: =[2]หน้าผ้า!EH29 -> 0 | BB17: =[2]หน้าผ้า!EI29 -> 0 | BC17: =[2]หน้าผ้า!BZ29 -> WRWT25800/WRWT25800 | BD17: =[2]หน้าผ้า!CA29 -> 2556.6218
A18: =[2]หน้าผ้า!C30 -> ประมาณการ | B18: =[2]หน้าผ้า!B30 -> ประมาณการ | C18: =[2]หน้าผ้า!E30 -> บจก.เอ็กเซลเล้นท์ | D18: =[2]หน้าผ้า!F30 -> รอแบบ | E18: =[2]หน้าผ้า!G30 -> 19 | F18: =[2]หน้าผ้า!H30 -> 30 | G18: =[2]หน้าผ้า!I30 -> ขาว | H18: =[2]หน้าผ้า!J30 -> 0 | I18: =[2]หน้าผ้า!L30 -> 60 | J18: =[2]หน้าผ้า!M30 -> ± | K18: =[2]หน้าผ้า!N30 -> 5 | L18: =[2]หน้าผ้า!R30 -> บิด | M18: =[2]หน้าผ้า!T30 -> ไม่สวมถุงใน | N18: =[2]หน้าผ้า!U30 -> 0 | O18: =[2]หน้าผ้า!V30 -> 0 | P18: =[2]หน้าผ้า!AB30 -> 0 | Q18: =[2]หน้าผ้า!AC30 -> 0 | R18: =[2]หน้าผ้า!AD30 -> 0 | S18: =[2]หน้าผ้า!Z30 -> 500กระสอบ | T18: =[2]หน้าผ้า!X30 -> 45894 | U18: =[2]หน้าผ้า!AA30 -> 40000 | V18: =[2]หน้าผ้า!AJ30 -> 0 | W18: =[2]หน้าผ้า!AL30 -> 40000 | X18: =[2]หน้าผ้า!AM30 -> 0 | Y18: =[2]หน้าผ้า!AN30 -> 42000 | Z18: =[2]หน้าผ้า!AO30 -> WSWT1925800 | AA18: =[2]หน้าผ้า!AQ30 -> 35204.4 | AB18: =[2]หน้าผ้า!AR30 -> 0 | AC18: =[2]หน้าผ้า!AS30 -> 35204.4 | AD18: =[2]หน้าผ้า!AT30 -> 0 | AE18: =[2]หน้าผ้า!AU30 -> 0 | AF18: =[2]หน้าผ้า!AI30 -> 0 | AG18: =[3]หน้าผ้า!DC33 -> พร้อมส่ง | AH18: =[2]หน้าผ้า!DL30 -> P7 | AI18: =[2]หน้าผ้า!DM30 -> 2 | AJ18: =[2]หน้าผ้า!DN30 -> 45894 | AK18: =[2]หน้าผ้า!DQ30 -> 0 | AL18: =[2]หน้าผ้า!DR30 -> 45885 | AM18: =[2]หน้าผ้า!DS30 -> 45892 | AN18: =[2]หน้าผ้า!DT30 -> 45893 | AO18: =[2]หน้าผ้า!DU30 -> 45893 | AP18: =[2]หน้าผ้า!DP30 -> 45889 | AQ18: =[2]หน้าผ้า!DW30 -> 0 | AR18: =[2]หน้าผ้า!DX30 -> 0 | AS18: =[2]หน้าผ้า!DY30 -> 0 | AT18: =[2]หน้าผ้า!DZ30 -> 0 | AU18: =[2]หน้าผ้า!EA30 -> 0 | AV18: =[2]หน้าผ้า!EB30 -> 0 | AW18: =[2]หน้าผ้า!EC30 -> งานพิมพ์ | AX18: =[2]หน้าผ้า!ED30 -> / | AY18: =[2]หน้าผ้า!AG30 -> 0 | AZ18: =[2]หน้าผ้า!EG30 -> 0 | BA18: =[2]หน้าผ้า!EH30 -> 0 | BB18: =[2]หน้าผ้า!EI30 -> 0 | BC18: =[2]หน้าผ้า!BZ30 -> WRWT25800/WRWT25800 | BD18: =[2]หน้าผ้า!CA30 -> 2556.6218
A19: =[2]หน้าผ้า!C31 -> ประมาณการ | B19: =[2]หน้าผ้า!B31 -> ประมาณการ | C19: =[2]หน้าผ้า!E31 -> บจก.ไลม์มาสเตอร์ | D19: =[2]หน้าผ้า!F31 -> LMC 25 kg | E19: =[2]หน้าผ้า!G31 -> 19 | F19: =[2]หน้าผ้า!H31 -> 32 | G19: =[2]หน้าผ้า!I31 -> ขาว | H19: =[2]หน้าผ้า!J31 -> 0 | I19: =[2]หน้าผ้า!L31 -> 64 | J19: =[2]หน้าผ้า!M31 -> ± | K19: =[2]หน้าผ้า!N31 -> 5 | L19: =[2]หน้าผ้า!R31 -> ไม่ | M19: =[2]หน้าผ้า!T31 -> 20 | N19: =[2]หน้าผ้า!U31 -> 35 | O19: =[2]หน้าผ้า!V31 -> 40 | P19: =[2]หน้าผ้า!AB31 -> 341.36903 | Q19: =[2]หน้าผ้า!AC31 -> 0 | R19: =[2]หน้าผ้า!AD31 -> 341.36903 | S19: =[2]หน้าผ้า!Z31 -> 500กระสอบแบน | T19: =[2]หน้าผ้า!X31 -> 45894 | U19: =[2]หน้าผ้า!AA31 -> 20000 | V19: =[2]หน้าผ้า!AJ31 -> 233 | W19: =[2]หน้าผ้า!AL31 -> 19767 | X19: =[2]หน้าผ้า!AM31 -> 0 | Y19: =[2]หน้าผ้า!AN31 -> 20755.35 | Z19: =[2]หน้าผ้า!AO31 -> WSWT1925800 | AA19: =[2]หน้าผ้า!AQ31 -> 18501.714 | AB19: =[2]หน้าผ้า!AR31 -> 18501.714 | AC19: =[2]หน้าผ้า!AS31 -> 0 | AD19: =[2]หน้าผ้า!AT31 -> 0 | AE19: =[2]หน้าผ้า!AU31 -> 0 | AF19: =[2]หน้าผ้า!AI31 -> 0 | AG19: =[3]หน้าผ้า!DC34 -> พร้อมส่ง | AH19: =[2]หน้าผ้า!DL31 -> P9 | AI19: =[2]หน้าผ้า!DM31 -> 3 | AJ19: =[2]หน้าผ้า!DN31 -> 45894 | AK19: =[2]หน้าผ้า!DQ31 -> 0 | AL19: =[2]หน้าผ้า!DR31 -> 45884 | AM19: =[2]หน้าผ้า!DS31 -> 45891 | AN19: =[2]หน้าผ้า!DT31 -> 45892 | AO19: =[2]หน้าผ้า!DU31 -> 45892 | AP19: =[2]หน้าผ้า!DP31 -> 45889 | AQ19: =[2]หน้าผ้า!DW31 -> 45893 | AR19: =[2]หน้าผ้า!DX31 -> 0 | AS19: =[2]หน้าผ้า!DY31 -> 0 | AT19: =[2]หน้าผ้า!DZ31 -> 0 | AU19: =[2]หน้าผ้า!EA31 -> 0 | AV19: =[2]หน้าผ้า!EB31 -> 0 | AW19: =[2]หน้าผ้า!EC31 -> งานพิมพ์ | AX19: =[2]หน้าผ้า!ED31 -> รอART | AY19: =[2]หน้าผ้า!AG31 -> 0 | AZ19: =[2]หน้าผ้า!EG31 -> 0 | BA19: =[2]หน้าผ้า!EH31 -> 0 | BB19: =[2]หน้าผ้า!EI31 -> 0 | BC19: =[2]หน้าผ้า!BZ31 -> WRWT25800/WRWT25800 | BD19: =[2]หน้าผ้า!CA31 -> 0
A20: =[2]หน้าผ้า!C32 -> 0 | B20: =[2]หน้าผ้า!B32 -> 0 | C20: =[2]หน้าผ้า!E32 -> 0 | D20: =[2]หน้าผ้า!F32 -> 0 | E20: =[2]หน้าผ้า!G32 -> 19 | F20: =[2]หน้าผ้า!H32 -> 30 | G20: =[2]หน้าผ้า!I32 -> ขาว | H20: =[2]หน้าผ้า!J32 -> 0 | I20: =[2]หน้าผ้า!L32 -> 60 | J20: =[2]หน้าผ้า!M32 -> ± | K20: =[2]หน้าผ้า!N32 -> 5 | L20: =[2]หน้าผ้า!R32 -> 0 | M20: =[2]หน้าผ้า!T32 -> 0 | N20: =[2]หน้าผ้า!U32 -> 0 | O20: =[2]หน้าผ้า!V32 -> 0 | P20: =[2]หน้าผ้า!AB32 -> 0 | Q20: =[2]หน้าผ้า!AC32 -> 0 | R20: =[2]หน้าผ้า!AD32 -> 0 | S20: =[2]หน้าผ้า!Z32 -> 0 | T20: =[2]หน้าผ้า!X32 -> 0 | U20: =[2]หน้าผ้า!AA32 -> 0 | V20: =[2]หน้าผ้า!AJ32 -> 0 | W20: =[2]หน้าผ้า!AL32 -> 0 | X20: =[2]หน้าผ้า!AM32 -> 0 | Y20: =[2]หน้าผ้า!AN32 -> 0 | Z20: =[2]หน้าผ้า!AO32 -> WSWT1925800 | AA20: =[2]หน้าผ้า!AQ32 -> 176921.51 | AB20: =[2]หน้าผ้า!AR32 -> 74616.714 | AC20: =[2]หน้าผ้า!AS32 -> 102304.8 | AD20: =[2]หน้าผ้า!AT32 -> 0 | AE20: =[2]หน้าผ้า!AU32 -> 0 | AF20: =[2]หน้าผ้า!AI32 -> ระบุในSD | AG20: =[3]หน้าผ้า!DC35 -> พร้อมส่ง | AH20: =[2]หน้าผ้า!DL32 -> 0 | AI20: =[2]หน้าผ้า!DM32 -> Lead time | AJ20: =[2]หน้าผ้า!DN32 -> 0 | AK20: =[2]หน้าผ้า!DQ32 -> 0 | AL20: =[2]หน้าผ้า!DR32 -> 0 | AM20: =[2]หน้าผ้า!DS32 -> 0 | AN20: =[2]หน้าผ้า!DT32 -> 0 | AO20: =[2]หน้าผ้า!DU32 -> 0 | AP20: =[2]หน้าผ้า!DP32 -> 0 | AQ20: =[2]หน้าผ้า!DW32 -> 0 | AR20: =[2]หน้าผ้า!DX32 -> 0 | AS20: =[2]หน้าผ้า!DY32 -> 0 | AT20: =[2]หน้าผ้า!DZ32 -> 0 | AU20: =[2]หน้าผ้า!EA32 -> 0 | AV20: =[2]หน้าผ้า!EB32 -> 0 | AW20: =[2]หน้าผ้า!EC32 -> 0 | AX20: =[2]หน้าผ้า!ED32 -> 0 | AY20: =[2]หน้าผ้า!AG32 -> 0 | AZ20: =[2]หน้าผ้า!EG32 -> 0 | BA20: =[2]หน้าผ้า!EH32 -> 0 | BB20: =[2]หน้าผ้า!EI32 -> 0 | BC20: =[2]หน้าผ้า!BZ32 -> WRWT25800/WRWT25800 | BD20: =[2]หน้าผ้า!CA32 -> 0
A21: =[2]หน้าผ้า!C33 -> 45854 | B21: =[2]หน้าผ้า!B33 -> MK68-000890 | C21: =[2]หน้าผ้า!E33 -> บจก.เคอรี่ฟลาวมิลล์ | D21: =[2]หน้าผ้า!F33 -> HARD FLOUR | E21: =[2]หน้าผ้า!G33 -> 19 | F21: =[2]หน้าผ้า!H33 -> 32 | G21: =[2]หน้าผ้า!I33 -> ขาว | H21: =[2]หน้าผ้า!J33 -> 0 | I21: =[2]หน้าผ้า!L33 -> 67 | J21: =[2]หน้าผ้า!M33 -> + | K21: =[2]หน้าผ้า!N33 -> 5 | L21: =[2]หน้าผ้า!R33 -> บิด | M21: =[2]หน้าผ้า!T33 -> ไม่สวมถุงใน | N21: =[2]หน้าผ้า!U33 -> 0 | O21: =[2]หน้าผ้า!V33 -> 0 | P21: =[2]หน้าผ้า!AB33 -> 0 | Q21: =[2]หน้าผ้า!AC33 -> 0 | R21: =[2]หน้าผ้า!AD33 -> 0 | S21: =[2]หน้าผ้า!Z33 -> ห่ออัดเบลแบน500 | U21: =[2]หน้าผ้า!AA33 -> 5000 | V21: =[2]หน้าผ้า!AJ33 -> 5220 | W21: =[2]หน้าผ้า!AL33 -> 0 | X21: =[2]หน้าผ้า!AM33 -> 5400 | Y21: =[2]หน้าผ้า!AN33 -> 0 | Z21: =[2]หน้าผ้า!AO33 -> WSWT1921720 | AA21: =[2]หน้าผ้า!AQ33 -> 0 | AB21: =[2]หน้าผ้า!AR33 -> 0 | AC21: =[2]หน้าผ้า!AS33 -> 0 | AD21: =[2]หน้าผ้า!AT33 -> 0 | AE21: =[2]หน้าผ้า!AU33 -> 0 | AF21: =[2]หน้าผ้า!AI33 -> PDR250226 | AG21: =[3]หน้าผ้า!DC36 -> พร้อมส่ง | AH21: =[2]หน้าผ้า!DL33 -> P7 | AI21: =[2]หน้าผ้า!DM33 -> 2 | AJ21: =[2]หน้าผ้า!DN33 -> 45869 | AK21: =[2]หน้าผ้า!DQ33 -> 0 | AL21: =[2]หน้าผ้า!DR33 -> 45860 | AM21: =[2]หน้าผ้า!DS33 -> 45867 | AN21: =[2]หน้าผ้า!DT33 -> 45868 | AO21: =[2]หน้าผ้า!DU33 -> 45868 | AP21: =[2]หน้าผ้า!DP33 -> 45864 | AQ21: =[2]หน้าผ้า!DW33 -> 0 | AR21: =[2]หน้าผ้า!DX33 -> 0 | AS21: =[2]หน้าผ้า!DY33 -> 0 | AT21: =[2]หน้าผ้า!DZ33 -> 0 | AU21: =[2]หน้าผ้า!EA33 -> 0 | AV21: =[2]หน้าผ้า!EB33 -> 0 | AW21: =[2]หน้าผ้า!EC33 -> งานพิมพ์ | AX21: =[2]หน้าผ้า!ED33 -> / | AY21: =[2]หน้าผ้า!AG33 -> 0 | AZ21: =[2]หน้าผ้า!EG33 -> 0 | BA21: =[2]หน้าผ้า!EH33 -> 0 | BB21: =[2]หน้าผ้า!EI33 -> 0 | BC21: =[2]หน้าผ้า!BZ33 -> WRWT21720/WRWT25800 | BD21: =[2]หน้าผ้า!CA33 -> 0
A22: =[2]หน้าผ้า!C34 -> 45854 | B22: =[2]หน้าผ้า!B34 -> MK68-000890 | C22: =[2]หน้าผ้า!E34 -> บจก.เคอรี่ฟลาวมิลล์ | D22: =[2]หน้าผ้า!F34 -> ดอกไม้เขียว | E22: =[2]หน้าผ้า!G34 -> 19 | F22: =[2]หน้าผ้า!H34 -> 32 | G22: =[2]หน้าผ้า!I34 -> ขาว | H22: =[2]หน้าผ้า!J34 -> 0 | I22: =[2]หน้าผ้า!L34 -> 67 | J22: =[2]หน้าผ้า!M34 -> + | K22: =[2]หน้าผ้า!N34 -> 5 | L22: =[2]หน้าผ้า!R34 -> บิด | M22: =[2]หน้าผ้า!T34 -> ไม่สวมถุงใน | N22: =[2]หน้าผ้า!U34 -> 0 | O22: =[2]หน้าผ้า!V34 -> 0 | P22: =[2]หน้าผ้า!AB34 -> 0 | Q22: =[2]หน้าผ้า!AC34 -> 0 | R22: =[2]หน้าผ้า!AD34 -> 0 | S22: =[2]หน้าผ้า!Z34 -> ห่ออัดเบลแบน500 | T22: =[2]หน้าผ้า!X34 -> 45869 | U22: =[2]หน้าผ้า!AA34 -> 5000 | V22: =[2]หน้าผ้า!AJ34 -> 5000 | W22: =[2]หน้าผ้า!AL34 -> 0 | X22: =[2]หน้าผ้า!AM34 -> 5198 | Y22: =[2]หน้าผ้า!AN34 -> 0 | Z22: =[2]หน้าผ้า!AO34 -> WSWT1921720 | AA22: =[2]หน้าผ้า!AQ34 -> 0 | AB22: =[2]หน้าผ้า!AR34 -> 0 | AC22: =[2]หน้าผ้า!AS34 -> 0 | AD22: =[2]หน้าผ้า!AT34 -> 0 | AE22: =[2]หน้าผ้า!AU34 -> 0 | AF22: =[2]หน้าผ้า!AI34 -> PDR250226 | AG22: =[3]หน้าผ้า!DC37 -> พร้อมส่ง | AH22: =[2]หน้าผ้า!DL34 -> P7 | AI22: =[2]หน้าผ้า!DM34 -> 2 | AJ22: =[2]หน้าผ้า!DN34 -> 45869 | AK22: =[2]หน้าผ้า!DQ34 -> 0 | AL22: =[2]หน้าผ้า!DR34 -> 45860 | AM22: =[2]หน้าผ้า!DS34 -> 45867 | AN22: =[2]หน้าผ้า!DT34 -> 45868 | AO22: =[2]หน้าผ้า!DU34 -> 45868 | AP22: =[2]หน้าผ้า!DP34 -> 45864 | AQ22: =[2]หน้าผ้า!DW34 -> 0 | AR22: =[2]หน้าผ้า!DX34 -> 0 | AS22: =[2]หน้าผ้า!DY34 -> 0 | AT22: =[2]หน้าผ้า!DZ34 -> 0 | AU22: =[2]หน้าผ้า!EA34 -> 0 | AV22: =[2]หน้าผ้า!EB34 -> 0 | AW22: =[2]หน้าผ้า!EC34 -> งานพิมพ์ | AX22: =[2]หน้าผ้า!ED34 -> / | AY22: =[2]หน้าผ้า!AG34 -> 0 | AZ22: =[2]หน้าผ้า!EG34 -> 0 | BA22: =[2]หน้าผ้า!EH34 -> 0 | BB22: =[2]หน้าผ้า!EI34 -> 0 | BC22: =[2]หน้าผ้า!BZ34 -> WRWT21720/WRWT25800 | BD22: =[2]หน้าผ้า!CA34 -> 0
A23: =[2]หน้าผ้า!C35 -> 45854 | B23: =[2]หน้าผ้า!B35 -> MK68-000890 | C23: =[2]หน้าผ้า!E35 -> บจก.เคอรี่ฟลาวมิลล์ | D23: =[2]หน้าผ้า!F35 -> 997 | E23: =[2]หน้าผ้า!G35 -> 19 | F23: =[2]หน้าผ้า!H35 -> 32 | G23: =[2]หน้าผ้า!I35 -> ขาว | H23: =[2]หน้าผ้า!J35 -> 0 | I23: =[2]หน้าผ้า!L35 -> 67 | J23: =[2]หน้าผ้า!M35 -> + | K23: =[2]หน้าผ้า!N35 -> 5 | L23: =[2]หน้าผ้า!R35 -> ไม่ | M23: =[2]หน้าผ้า!T35 -> ไม่สวมถุงใน | N23: =[2]หน้าผ้า!U35 -> 0 | O23: =[2]หน้าผ้า!V35 -> 0 | P23: =[2]หน้าผ้า!AB35 -> 0 | Q23: =[2]หน้าผ้า!AC35 -> 0 | R23: =[2]หน้าผ้า!AD35 -> 0 | S23: =[2]หน้าผ้า!Z35 -> ห่ออัดเบลแบน500 | T23: =[2]หน้าผ้า!X35 -> 45869 | U23: =[2]หน้าผ้า!AA35 -> 5000 | V23: =[2]หน้าผ้า!AJ35 -> 5124 | W23: =[2]หน้าผ้า!AL35 -> 0 | X23: =[2]หน้าผ้า!AM35 -> 5300 | Y23: =[2]หน้าผ้า!AN35 -> 0 | Z23: =[2]หน้าผ้า!AO35 -> WSWT1921720 | AA23: =[2]หน้าผ้า!AQ35 -> 0 | AB23: =[2]หน้าผ้า!AR35 -> 0 | AC23: =[2]หน้าผ้า!AS35 -> 0 | AD23: =[2]หน้าผ้า!AT35 -> 0 | AE23: =[2]หน้าผ้า!AU35 -> 0 | AF23: =[2]หน้าผ้า!AI35 -> PDR250226 | AG23: =[3]หน้าผ้า!DC38 -> พร้อมส่ง | AH23: =[2]หน้าผ้า!DL35 -> P7 | AI23: =[2]หน้าผ้า!DM35 -> 2 | AJ23: =[2]หน้าผ้า!DN35 -> 45869 | AK23: =[2]หน้าผ้า!DQ35 -> 0 | AL23: =[2]หน้าผ้า!DR35 -> 45860 | AM23: =[2]หน้าผ้า!DS35 -> 45867 | AN23: =[2]หน้าผ้า!DT35 -> 45868 | AO23: =[2]หน้าผ้า!DU35 -> 45868 | AP23: =[2]หน้าผ้า!DP35 -> 45864 | AQ23: =[2]หน้าผ้า!DW35 -> 0 | AR23: =[2]หน้าผ้า!DX35 -> 0 | AS23: =[2]หน้าผ้า!DY35 -> 0 | AT23: =[2]หน้าผ้า!DZ35 -> 0 | AU23: =[2]หน้าผ้า!EA35 -> 0 | AV23: =[2]หน้าผ้า!EB35 -> 0 | AW23: =[2]หน้าผ้า!EC35 -> งานพิมพ์ | AX23: =[2]หน้าผ้า!ED35 -> / | AY23: =[2]หน้าผ้า!AG35 -> 0 | AZ23: =[2]หน้าผ้า!EG35 -> 0 | BA23: =[2]หน้าผ้า!EH35 -> 0 | BB23: =[2]หน้าผ้า!EI35 -> 0 | BC23: =[2]หน้าผ้า!BZ35 -> WRWT21720/WRWT25800 | BD23: =[2]หน้าผ้า!CA35 -> 0
