Workbook

Sheet Linkสูตรออร์เดอร์  (2)
B2: เรียงกำหนดส่ง | D2: ลบ 0 | T2: เรียง 1
B3: ข้อมูลUpdate ณ. วันที่ | D3: 45831 | E3: เวลา | G3: 11.43
A4: วันรับออร์เดอร์/แบบ | B4: เลขที่ SO | C4: ชื่อลูกค้า | E4: 10.3 | I4: น้ำหนัก | L4: บิด/จับจีบ | M4: ถุงใน | Q4: =[1]หน้าผ้า!$AC$13 -> 44873 | S4: วิธีบรรจุ | T4: วันส่ง | U4: จำนวนส่ง | V4: ตัดเย็บ (ใบ) | W4: =[1]หน้าผ้า!$AJ$13 -> 44873 | X4: พิมพ์ (ใบ) | Y4: =[1]หน้าผ้า!$AM$13 -> 44876 | Z4: ผ้าทอ (เมตร) Updateณ | AB4: =[1]หน้าผ้า!$AR$12 -> 44876 | AD4: ผ้าเคลือบ(เมตร) | AF4: หมายเหตุ | AG4: เครื่อง
B5: เลขที่ SO | C5: ชื่อลูกค้า | D5: ตรา | E5: กว้าง | F5: ยาว | G5: สี | H5: เคลือบ | I5: กรัม/ใบ | J5: * | K5: aw | L5: บิด/จับจีบ | M5: กว้าง | N5: ยาว | O5: หนา | P5: ใช้(กก.) | Q5: Stock(กก.) | R5: ผลิต(กก.) | S5: วิธีบรรจุ | T5: วันส่ง | U5: จำนวนส่ง | V5: StockFG | W5: ค้างตัด | X5: พิมพ์แล้ว | Y5: ค้างพิมพ์ | Z5: ประเภท | AA5: ใช้ | AB5: Stock | AC5: ค้างทอ | AD5: Stock | AE5: ค้างเคลือบ | AF5: หมายเหตุ | AG5: ที่พิมพ์ได้ | AH5: process | AI5: Lead time | AJ5: วันที่ส่งPL | AK5: เคลือบ | AL5: ได้ ART | AM5: พิมพ์ | AN5: จีบ-บิด | AO5: ตัด-เย็บ | AP5: ทอ | AQ5: สวมถุง | AR5: เย็บปาก | AS5: PT | AT5: ม้วน | AU5: ตัด | AV5: ตอกตาไก่ | AW5: GROUP | AX5: ART | AY5: หมายเหตุปัญหา | AZ5: ราคา/ใบ | BA5: ราคารวม | BB5: workweek | BC5: เส้นเทป | BD5: จำนวน
A6: =[2]หน้าผ้า!C15 -> 0 | B6: =[2]หน้าผ้า!B15 -> 0 | C6: =[2]หน้าผ้า!E15 -> 0 | D6: =[2]หน้าผ้า!F15 -> 0 | E6: =[2]หน้าผ้า!G15 -> 12 | F6: =[2]หน้าผ้า!H15 -> 16 | G6: =[2]หน้าผ้า!I15 -> ขาว | H6: =[2]หน้าผ้า!J15 -> 0 | I6: =[2]หน้าผ้า!L15 -> 25 | J6: =[2]หน้าผ้า!M15 -> ± | K6: =[2]หน้าผ้า!N15 -> 5 | L6: =[2]หน้าผ้า!R15 -> 0 | M6: =[2]หน้าผ้า!T15 -> 0 | N6: =[2]หน้าผ้า!U15 -> 0 | O6: =[2]หน้าผ้า!V15 -> 0 | P6: =[2]หน้าผ้า!AB15 -> 0 | Q6: =[2]หน้าผ้า!AC15 -> 0 | R6: =[2]หน้าผ้า!AD15 -> 0 | S6: =[2]หน้าผ้า!Z15 -> 0 | T6: =[2]หน้าผ้า!X15 -> 0 | U6: =[2]หน้าผ้า!AA15 -> 0 | V6: =[2]หน้าผ้า!AJ15 -> 0 | W6: =[2]หน้าผ้า!AL15 -> 0 | X6: =[2]หน้าผ้า!AM15 -> 0 | Y6: =[2]หน้าผ้า!AN15 -> 0 | Z6: =[2]หน้าผ้า!AO15 -> WSWT1221750 | AA6: =[2]หน้าผ้า!AQ15 -> #REF! | AB6: =[2]หน้าผ้า!AR15 -> #REF! | AC6: =[2]หน้าผ้า!AS15 -> #REF! | AD6: =[2]หน้าผ้า!AT15 -> #REF! | AE6: =[2]หน้าผ้า!AU15 -> #REF! | AF6: =[2]หน้าผ้า!AI15 -> ระบุในSD | AG6: =[3]หน้าผ้า!DC18 -> < Ord 20,000 | AH6: =[2]หน้าผ้า!DL15 -> 0 | AI6: =[2]หน้าผ้า!DM15 -> 0 | AJ6: =[2]หน้าผ้า!DN15 -> 0 | AK6: =[2]หน้าผ้า!DQ15 -> 0 | AL6: =[2]หน้าผ้า!DR15 -> 0 | AM6: =[2]หน้าผ้า!DS15 -> 0 | AN6: =[2]หน้าผ้า!DT15 -> 0 | AO6: =[2]หน้าผ้า!DU15 -> 0 | AP6: =[2]หน้าผ้า!DP15 -> 0 | AQ6: =[2]หน้าผ้า!DW15 -> 0 | AR6: =[2]หน้าผ้า!DX15 -> 0 | AS6: =[2]หน้าผ้า!DY15 -> 0 | AT6: =[2]หน้าผ้า!DZ15 -> 0 | AU6: =[2]หน้าผ้า!EA15 -> 0 | AV6: =[2]หน้าผ้า!EB15 -> 0 | AW6: =[2]หน้าผ้า!EC15 -> 0 | AX6: =[2]หน้าผ้า!ED15 -> 0 | AY6: =[2]หน้าผ้า!AG15 -> 0 | AZ6: =[2]หน้าผ้า!EG15 -> 0 | BA6: =[2]หน้าผ้า!EH15 -> 0 | BB6: =[2]หน้าผ้า!EI15 -> 0 | BC6: =[2]หน้าผ้า!BZ15 -> WRWT120750/WRWT21750 | BD6: =[2]หน้าผ้า!CA15 -> 0
A7: =[2]หน้าผ้า!C16 -> 0 | B7: =[2]หน้าผ้า!B16 -> 0 | C7: =[2]หน้าผ้า!E16 -> 0 | D7: =[2]หน้าผ้า!F16 -> 0 | E7: =[2]หน้าผ้า!G16 -> 14 | F7: =[2]หน้าผ้า!H16 -> 22 | G7: =[2]หน้าผ้า!I16 -> ขาว | H7: =[2]หน้าผ้า!J16 -> 0 | I7: =[2]หน้าผ้า!L16 -> 36 | J7: =[2]หน้าผ้า!M16 -> ± | K7: =[2]หน้าผ้า!N16 -> 5 | L7: =[2]หน้าผ้า!R16 -> 0 | M7: =[2]หน้าผ้า!T16 -> 0 | N7: =[2]หน้าผ้า!U16 -> 0 | O7: =[2]หน้าผ้า!V16 -> 0 | P7: =[2]หน้าผ้า!AB16 -> 0 | Q7: =[2]หน้าผ้า!AC16 -> 0 | R7: =[2]หน้าผ้า!AD16 -> 0 | S7: =[2]หน้าผ้า!Z16 -> 0 | T7: =[2]หน้าผ้า!X16 -> 0 | U7: =[2]หน้าผ้า!AA16 -> 0 | V7: =[2]หน้าผ้า!AJ16 -> 0 | W7: =[2]หน้าผ้า!AL16 -> 0 | X7: =[2]หน้าผ้า!AM16 -> 0 | Y7: =[2]หน้าผ้า!AN16 -> 0 | Z7: =[2]หน้าผ้า!AO16 -> WSWT1425800 | AA7: =[2]หน้าผ้า!AQ16 -> #REF! | AB7: =[2]หน้าผ้า!AR16 -> #REF! | AC7: =[2]หน้าผ้า!AS16 -> #REF! | AD7: =[2]หน้าผ้า!AT16 -> #REF! | AE7: =[2]หน้าผ้า!AU16 -> #REF! | AF7: =[2]หน้าผ้า!AI16 -> ระบุในSD | AG7: =[3]หน้าผ้า!DC19 -> ยังไม่ได้พิมพ์ | AH7: =[2]หน้าผ้า!DL16 -> 0 | AI7: =[2]หน้าผ้า!DM16 -> Lead time | AJ7: =[2]หน้าผ้า!DN16 -> 0 | AK7: =[2]หน้าผ้า!DQ16 -> 0 | AL7: =[2]หน้าผ้า!DR16 -> 0 | AM7: =[2]หน้าผ้า!DS16 -> 0 | AN7: =[2]หน้าผ้า!DT16 -> 0 | AO7: =[2]หน้าผ้า!DU16 -> 0 | AP7: =[2]หน้าผ้า!DP16 -> 0 | AQ7: =[2]หน้าผ้า!DW16 -> 0 | AR7: =[2]หน้าผ้า!DX16 -> 0 | AS7: =[2]หน้าผ้า!DY16 -> 0 | AT7: =[2]หน้าผ้า!DZ16 -> 0 | AU7: =[2]หน้าผ้า!EA16 -> 0 | AV7: =[2]หน้าผ้า!EB16 -> 0 | AW7: =[2]หน้าผ้า!EC16 -> 0 | AX7: =[2]หน้าผ้า!ED16 -> 0 | AY7: =[2]หน้าผ้า!AG16 -> 0 | AZ7: =[2]หน้าผ้า!EG16 -> 0 | BA7: =[2]หน้าผ้า!EH16 -> 0 | BB7: =[2]หน้าผ้า!EI16 -> 0 | BC7: =[2]หน้าผ้า!BZ16 -> WRWT140800/WRWT25800 | BD7: =[2]หน้าผ้า!CA16 -> 0
A8: =[2]หน้าผ้า!C17 -> ประมาณการ | B8: =[2]หน้าผ้า!B17 -> ประมาณการ | C8: =[2]หน้าผ้า!E17 -> บจก.ซัน ซีเมนต์ โพรเซส | D8: =[2]หน้าผ้า!F17 -> พระอาทิตย์(ปูนนอน-ชริงค์) | E8: =[2]หน้าผ้า!G17 -> 16 | F8: =[2]หน้าผ้า!H17 -> 25 | G8: =[2]หน้าผ้า!I17 -> ขาว | H8: =[2]หน้าผ้า!J17 -> ใส | I8: =[2]หน้าผ้า!L17 -> 50 | J8: =[2]หน้าผ้า!M17 -> ± | K8: =[2]หน้าผ้า!N17 -> 5 | L8: =[2]หน้าผ้า!R17 -> บิด | M8: =[2]หน้าผ้า!T17 -> 19 | N8: =[2]หน้าผ้า!U17 -> 28 | O8: =[2]หน้าผ้า!V17 -> 40 | P8: =[2]หน้าผ้า!AB17 -> 65.624643 | Q8: =[2]หน้าผ้า!AC17 -> 0 | R8: =[2]หน้าผ้า!AD17 -> 65.624643 | S8: =[2]หน้าผ้า!Z17 -> 500กระสอบ | T8: =[2]หน้าผ้า!X17 -> 45868 | U8: =[2]หน้าผ้า!AA17 -> 5000 | V8: =[2]หน้าผ้า!AJ17 -> 0 | W8: =[2]หน้าผ้า!AL17 -> 5000 | X8: =[2]หน้าผ้า!AM17 -> 0 | Y8: =[2]หน้าผ้า!AN17 -> 5250 | Z8: =[2]หน้าผ้า!AO17 -> WSWT1625800SM | AA8: =[2]หน้าผ้า!AQ17 -> 3702.05 | AB8: =[2]หน้าผ้า!AR17 -> 3372 | AC8: =[2]หน้าผ้า!AS17 -> 330.05 | AD8: =[2]หน้าผ้า!AT17 -> 0 | AE8: =[2]หน้าผ้า!AU17 -> 3702.05 | AF8: =[2]หน้าผ้า!AI17 -> 0 | AG8: =[3]หน้าผ้า!DC20 -> พร้อมส่ง | AH8: =[2]หน้าผ้า!DL17 -> P8 | AI8: =[2]หน้าผ้า!DM17 -> 4 | AJ8: =[2]หน้าผ้า!DN17 -> 45868 | AK8: =[2]หน้าผ้า!DQ17 -> 45864 | AL8: =[2]หน้าผ้า!DR17 -> 45858 | AM8: =[2]หน้าผ้า!DS17 -> 45865 | AN8: =[2]หน้าผ้า!DT17 -> 45866 | AO8: =[2]หน้าผ้า!DU17 -> 45866 | AP8: =[2]หน้าผ้า!DP17 -> 45863 | AQ8: =[2]หน้าผ้า!DW17 -> 45867 | AR8: =[2]หน้าผ้า!DX17 -> 0 | AS8: =[2]หน้าผ้า!DY17 -> 0 | AT8: =[2]หน้าผ้า!DZ17 -> 0 | AU8: =[2]หน้าผ้า!EA17 -> 0 | AV8: =[2]หน้าผ้า!EB17 -> 0 | AW8: =[2]หน้าผ้า!EC17 -> งานเคลือบ+พิมพ์ | AX8: =[2]หน้าผ้า!ED17 -> รอART | AY8: =[2]หน้าผ้า!AG17 -> 0 | AZ8: =[2]หน้าผ้า!EG17 -> 0 | BA8: =[2]หน้าผ้า!EH17 -> 0 | BB8: =[2]หน้าผ้า!EI17 -> 0 | BC8: =[2]หน้าผ้า!BZ17 -> WRWT25800/WRWT25800 | BD8: =[2]หน้าผ้า!CA17 -> 18.776178
A9: =[2]หน้าผ้า!C18 -> 0 | B9: =[2]หน้าผ้า!B18 -> 0 | C9: =[2]หน้าผ้า!E18 -> 0 | D9: =[2]หน้าผ้า!F18 | E9: =[2]หน้าผ้า!G18 -> 16 | F9: =[2]หน้าผ้า!H18 -> 25 | G9: =[2]หน้าผ้า!I18 -> ขาว | H9: =[2]หน้าผ้า!J18 -> 0 | I9: =[2]หน้าผ้า!L18 -> 45 | J9: =[2]หน้าผ้า!M18 -> ± | K9: =[2]หน้าผ้า!N18 -> 5 | L9: =[2]หน้าผ้า!R18 -> 0 | M9: =[2]หน้าผ้า!T18 -> 0 | N9: =[2]หน้าผ้า!U18 -> 0 | O9: =[2]หน้าผ้า!V18 -> 0 | P9: =[2]หน้าผ้า!AB18 -> 0 | Q9: =[2]หน้าผ้า!AC18 -> 0 | R9: =[2]หน้าผ้า!AD18 -> 0 | S9: =[2]หน้าผ้า!Z18 -> 0 | T9: =[2]หน้าผ้า!X18 -> 0 | U9: =[2]หน้าผ้า!AA18 -> 0 | V9: =[2]หน้าผ้า!AJ18 -> 0 | W9: =[2]หน้าผ้า!AL18 -> 0 | X9: =[2]หน้าผ้า!AM18 -> 0 | Y9: =[2]หน้าผ้า!AN18 -> 0 | Z9: =[2]หน้าผ้า!AO18 -> WSWT1625800SM | AA9: =[2]หน้าผ้า!AQ18 -> 3702.05 | AB9: =[2]หน้าผ้า!AR18 -> 3372 | AC9: =[2]หน้าผ้า!AS18 -> 330.05 | AD9: =[2]หน้าผ้า!AT18 -> 0 | AE9: =[2]หน้าผ้า!AU18 -> 3702.05 | AF9: =[2]หน้าผ้า!AI18 -> ระบุในSD | AG9: =[3]หน้าผ้า!DC21 -> พร้อมส่ง | AH9: =[2]หน้าผ้า!DL18 -> 0 | AI9: =[2]หน้าผ้า!DM18 -> Lead time | AJ9: =[2]หน้าผ้า!DN18 -> 0 | AK9: =[2]หน้าผ้า!DQ18 -> 0 | AL9: =[2]หน้าผ้า!DR18 -> 0 | AM9: =[2]หน้าผ้า!DS18 -> 0 | AN9: =[2]หน้าผ้า!DT18 -> 0 | AO9: =[2]หน้าผ้า!DU18 -> 0 | AP9: =[2]หน้าผ้า!DP18 -> 0 | AQ9: =[2]หน้าผ้า!DW18 -> 0 | AR9: =[2]หน้าผ้า!DX18 -> 0 | AS9: =[2]หน้าผ้า!DY18 -> 0 | AT9: =[2]หน้าผ้า!DZ18 -> 0 | AU9: =[2]หน้าผ้า!EA18 -> 0 | AV9: =[2]หน้าผ้า!EB18 -> 0 | AW9: =[2]หน้าผ้า!EC18 -> 0 | AX9: =[2]หน้าผ้า!ED18 -> 0 | AY9: =[2]หน้าผ้า!AG18 -> 0 | AZ9: =[2]หน้าผ้า!EG18 -> 0 | BA9: =[2]หน้าผ้า!EH18 -> 0 | BB9: =[2]หน้าผ้า!EI18 -> 0 | BC9: =[2]หน้าผ้า!BZ18 -> WRWT160800/WRWT25800 | BD9: =[2]หน้าผ้า!CA18 -> 0
A10: =[2]หน้าผ้า!C19 -> 45827 | B10: =[2]หน้าผ้า!B19 -> MK68-000809 | C10: =[2]หน้าผ้า!E19 -> บจก.เคอรี่ฟลาวมิลล์ | D10: =[2]หน้าผ้า!F19 -> โบว์แดง 10กก | E10: =[2]หน้าผ้า!G19 -> 16 | F10: =[2]หน้าผ้า!H19 -> 25 | G10: =[2]หน้าผ้า!I19 -> ขาว | H10: =[2]หน้าผ้า!J19 -> 0 | I10: =[2]หน้าผ้า!L19 -> 45 | J10: =[2]หน้าผ้า!M19 -> ± | K10: =[2]หน้าผ้า!N19 -> 5 | L10: =[2]หน้าผ้า!R19 -> ไม่ | M10: =[2]หน้าผ้า!T19 -> ไม่สวมถุงใน | N10: =[2]หน้าผ้า!U19 -> 0 | O10: =[2]หน้าผ้า!V19 -> 0 | P10: =[2]หน้าผ้า!AB19 -> 0 | Q10: =[2]หน้าผ้า!AC19 -> 0 | R10: =[2]หน้าผ้า!AD19 -> 0 | S10: =[2]หน้าผ้า!Z19 -> ห่ออัดเบลแบน500 | T10: =[2]หน้าผ้า!X19 -> 45836 | U10: =[2]หน้าผ้า!AA19 -> 5000 | V10: =[2]หน้าผ้า!AJ19 -> 0 | W10: =[2]หน้าผ้า!AL19 -> 5000 | X10: =[2]หน้าผ้า!AM19 -> 0 | Y10: =[2]หน้าผ้า!AN19 -> 5250 | Z10: =[2]หน้าผ้า!AO19 -> WSWT1625800 | AA10: =[2]หน้าผ้า!AQ19 -> 3702.05 | AB10: =[2]หน้าผ้า!AR19 -> 3702.05 | AC10: =[2]หน้าผ้า!AS19 -> 0 | AD10: =[2]หน้าผ้า!AT19 -> 0 | AE10: =[2]หน้าผ้า!AU19 -> 0 | AF10: =[2]หน้าผ้า!AI19 -> 0 | AG10: =[3]หน้าผ้า!DC22 -> พร้อมส่ง | AH10: =[2]หน้าผ้า!DL19 -> P7 | AI10: =[2]หน้าผ้า!DM19 -> 2 | AJ10: =[2]หน้าผ้า!DN19 -> 45836 | AK10: =[2]หน้าผ้า!DQ19 -> 0 | AL10: =[2]หน้าผ้า!DR19 -> 45827 | AM10: =[2]หน้าผ้า!DS19 -> 45834 | AN10: =[2]หน้าผ้า!DT19 -> 45835 | AO10: =[2]หน้าผ้า!DU19 -> 45835 | AP10: =[2]หน้าผ้า!DP19 -> 45831 | AQ10: =[2]หน้าผ้า!DW19 -> 0 | AR10: =[2]หน้าผ้า!DX19 -> 0 | AS10: =[2]หน้าผ้า!DY19 -> 0 | AT10: =[2]หน้าผ้า!DZ19 -> 0 | AU10: =[2]หน้าผ้า!EA19 -> 0 | AV10: =[2]หน้าผ้า!EB19 -> 0 | AW10: =[2]หน้าผ้า!EC19 -> งานพิมพ์ | AX10: =[2]หน้าผ้า!ED19 -> 0 | AY10: =[2]หน้าผ้า!AG19 -> 0 | AZ10: =[2]หน้าผ้า!EG19 -> 0 | BA10: =[2]หน้าผ้า!EH19 -> 0 | BB10: =[2]หน้าผ้า!EI19 -> 0 | BC10: =[2]หน้าผ้า!BZ19 -> WRWT25800/WRWT25800 | BD10: =[2]หน้าผ้า!CA19 -> 0
A11: =[2]หน้าผ้า!C20 -> 0 | B11: =[2]หน้าผ้า!B20 -> 0 | C11: =[2]หน้าผ้า!E20 -> 0 | D11: =[2]หน้าผ้า!F20 -> 0 | E11: =[2]หน้าผ้า!G20 -> 16 | F11: =[2]หน้าผ้า!H20 -> 25 | G11: =[2]หน้าผ้า!I20 -> ขาว | H11: =[2]หน้าผ้า!J20 -> 0 | I11: =[2]หน้าผ้า!L20 -> 45 | J11: =[2]หน้าผ้า!M20 -> ± | K11: =[2]หน้าผ้า!N20 -> 5 | L11: =[2]หน้าผ้า!R20 -> 0 | M11: =[2]หน้าผ้า!T20 -> 0 | N11: =[2]หน้าผ้า!U20 -> 0 | O11: =[2]หน้าผ้า!V20 -> 0 | P11: =[2]หน้าผ้า!AB20 -> 0 | Q11: =[2]หน้าผ้า!AC20 -> 0 | R11: =[2]หน้าผ้า!AD20 -> 0 | S11: =[2]หน้าผ้า!Z20 -> 0 | T11: =[2]หน้าผ้า!X20 -> 0 | U11: =[2]หน้าผ้า!AA20 -> 0 | V11: =[2]หน้าผ้า!AJ20 -> 0 | W11: =[2]หน้าผ้า!AL20 -> 0 | X11: =[2]หน้าผ้า!AM20 -> 0 | Y11: =[2]หน้าผ้า!AN20 -> 0 | Z11: =[2]หน้าผ้า!AO20 -> WSWT1625800 | AA11: =[2]หน้าผ้า!AQ20 -> 3702.05 | AB11: =[2]หน้าผ้า!AR20 -> 3702.05 | AC11: =[2]หน้าผ้า!AS20 -> 0 | AD11: =[2]หน้าผ้า!AT20 -> 0 | AE11: =[2]หน้าผ้า!AU20 -> 0 | AF11: =[2]หน้าผ้า!AI20 -> ระบุในSD | AG11: =[3]หน้าผ้า!DC23 -> ยังไม่ได้พิมพ์ | AH11: =[2]หน้าผ้า!DL20 -> 0 | AI11: =[2]หน้าผ้า!DM20 -> Lead time | AJ11: =[2]หน้าผ้า!DN20 -> 0 | AK11: =[2]หน้าผ้า!DQ20 -> 0 | AL11: =[2]หน้าผ้า!DR20 -> 0 | AM11: =[2]หน้าผ้า!DS20 -> 0 | AN11: =[2]หน้าผ้า!DT20 -> 0 | AO11: =[2]หน้าผ้า!DU20 -> 0 | AP11: =[2]หน้าผ้า!DP20 -> 0 | AQ11: =[2]หน้าผ้า!DW20 -> 0 | AR11: =[2]หน้าผ้า!DX20 -> 0 | AS11: =[2]หน้าผ้า!DY20 -> 0 | AT11: =[2]หน้าผ้า!DZ20 -> 0 | AU11: =[2]หน้าผ้า!EA20 -> 0 | AV11: =[2]หน้าผ้า!EB20 -> 0 | AW11: =[2]หน้าผ้า!EC20 -> 0 | AX11: =[2]หน้าผ้า!ED20 -> 0 | AY11: =[2]หน้าผ้า!AG20 -> 0 | AZ11: =[2]หน้าผ้า!EG20 -> 0 | BA11: =[2]หน้าผ้า!EH20 -> 0 | BB11: =[2]หน้าผ้า!EI20 -> 0 | BC11: =[2]หน้าผ้า!BZ20 -> WRWT160800/WRWT25800 | BD11: =[2]หน้าผ้า!CA20 -> 0
A12: =[2]หน้าผ้า!C21 -> 0 | B12: =[2]หน้าผ้า!B21 -> 0 | C12: =[2]หน้าผ้า!E21 -> 0 | D12: =[2]หน้าผ้า!F21 -> 0 | E12: =[2]หน้าผ้า!G21 -> 16 | F12: =[2]หน้าผ้า!H21 -> 25 | G12: =[2]หน้าผ้า!I21 -> 0 | H12: =[2]หน้าผ้า!J21 -> 0 | I12: =[2]หน้าผ้า!L21 -> 47 | J12: =[2]หน้าผ้า!M21 -> ± | K12: =[2]หน้าผ้า!N21 -> 5 | L12: =[2]หน้าผ้า!R21 -> 0 | M12: =[2]หน้าผ้า!T21 -> 0 | N12: =[2]หน้าผ้า!U21 -> 0 | O12: =[2]หน้าผ้า!V21 -> 0 | P12: =[2]หน้าผ้า!AB21 -> 0 | Q12: =[2]หน้าผ้า!AC21 -> 0 | R12: =[2]หน้าผ้า!AD21 -> 0 | S12: =[2]หน้าผ้า!Z21 -> 0 | T12: =[2]หน้าผ้า!X21 -> 0 | U12: =[2]หน้าผ้า!AA21 -> 0 | V12: =[2]หน้าผ้า!AJ21 -> 0 | W12: =[2]หน้าผ้า!AL21 -> 0 | X12: =[2]หน้าผ้า!AM21 -> 0 | Y12: =[2]หน้าผ้า!AN21 -> 0 | Z12: =[2]หน้าผ้า!AO21 -> WSWT1621720SMFX | AA12: =[2]หน้าผ้า!AQ21 -> #REF! | AB12: =[2]หน้าผ้า!AR21 -> #REF! | AC12: =[2]หน้าผ้า!AS21 -> #REF! | AD12: =[2]หน้าผ้า!AT21 -> #REF! | AE12: =[2]หน้าผ้า!AU21 -> #REF! | AF12: =[2]หน้าผ้า!AI21 -> ระบุในSD | AG12: =[3]หน้าผ้า!DC24 -> พร้อมส่ง | AH12: =[2]หน้าผ้า!DL21 -> 0 | AI12: =[2]หน้าผ้า!DM21 -> 0 | AJ12: =[2]หน้าผ้า!DN21 -> 0 | AK12: =[2]หน้าผ้า!DQ21 -> 0 | AL12: =[2]หน้าผ้า!DR21 -> 0 | AM12: =[2]หน้าผ้า!DS21 -> 0 | AN12: =[2]หน้าผ้า!DT21 -> 0 | AO12: =[2]หน้าผ้า!DU21 -> 0 | AP12: =[2]หน้าผ้า!DP21 -> 0 | AQ12: =[2]หน้าผ้า!DW21 -> 0 | AR12: =[2]หน้าผ้า!DX21 -> 0 | AS12: =[2]หน้าผ้า!DY21 -> 0 | AT12: =[2]หน้าผ้า!DZ21 -> 0 | AU12: =[2]หน้าผ้า!EA21 -> 0 | AV12: =[2]หน้าผ้า!EB21 -> 0 | AW12: =[2]หน้าผ้า!EC21 -> 0 | AX12: =[2]หน้าผ้า!ED21 -> 0 | AY12: =[2]หน้าผ้า!AG21 -> 0 | AZ12: =[2]หน้าผ้า!EG21 -> 0 | BA12: =[2]หน้าผ้า!EH21 -> 0 | BB12: =[2]หน้าผ้า!EI21 -> 0 | BC12: =[2]หน้าผ้า!BZ21 -> WRWT160720/WRWT21720 | BD12: =[2]หน้าผ้า!CA21 -> 0
A13: =[2]หน้าผ้า!C22 -> 0 | B13: =[2]หน้าผ้า!B22 -> 0 | C13: =[2]หน้าผ้า!E22 -> 0 | D13: =[2]หน้าผ้า!F22 -> 0 | E13: =[2]หน้าผ้า!G22 -> 17 | F13: =[2]หน้าผ้า!H22 -> 26 | G13: =[2]หน้าผ้า!I22 -> 0 | H13: =[2]หน้าผ้า!J22 -> 0 | I13: =[2]หน้าผ้า!L22 -> 48 | J13: =[2]หน้าผ้า!M22 -> ± | K13: =[2]หน้าผ้า!N22 -> 5 | L13: =[2]หน้าผ้า!R22 -> 0 | M13: =[2]หน้าผ้า!T22 -> 0 | N13: =[2]หน้าผ้า!U22 -> 0 | O13: =[2]หน้าผ้า!V22 -> 0 | P13: =[2]หน้าผ้า!AB22 -> 0 | Q13: =[2]หน้าผ้า!AC22 -> 0 | R13: =[2]หน้าผ้า!AD22 -> 0 | S13: =[2]หน้าผ้า!Z22 -> 0 | T13: =[2]หน้าผ้า!X22 -> 0 | U13: =[2]หน้าผ้า!AA22 -> 0 | V13: =[2]หน้าผ้า!AJ22 -> 0 | W13: =[2]หน้าผ้า!AL22 -> 0 | X13: =[2]หน้าผ้า!AM22 -> 0 | Y13: =[2]หน้าผ้า!AN22 -> 0 | Z13: =[2]หน้าผ้า!AO22 -> WSWT1725800 | AA13: =[2]หน้าผ้า!AQ22 -> #REF! | AB13: =[2]หน้าผ้า!AR22 -> #REF! | AC13: =[2]หน้าผ้า!AS22 -> #REF! | AD13: =[2]หน้าผ้า!AT22 -> #REF! | AE13: =[2]หน้าผ้า!AU22 -> #REF! | AF13: =[2]หน้าผ้า!AI22 -> ระบุในSD | AG13: =[3]หน้าผ้า!DC25 -> ยังไม่ได้พิมพ์ | AH13: =[2]หน้าผ้า!DL22 -> 0 | AI13: =[2]หน้าผ้า!DM22 -> 0 | AJ13: =[2]หน้าผ้า!DN22 -> 0 | AK13: =[2]หน้าผ้า!DQ22 -> 0 | AL13: =[2]หน้าผ้า!DR22 -> 0 | AM13: =[2]หน้าผ้า!DS22 -> 0 | AN13: =[2]หน้าผ้า!DT22 -> 0 | AO13: =[2]หน้าผ้า!DU22 -> 0 | AP13: =[2]หน้าผ้า!DP22 -> 0 | AQ13: =[2]หน้าผ้า!DW22 -> 0 | AR13: =[2]หน้าผ้า!DX22 -> 0 | AS13: =[2]หน้าผ้า!DY22 -> 0 | AT13: =[2]หน้าผ้า!DZ22 -> 0 | AU13: =[2]หน้าผ้า!EA22 -> 0 | AV13: =[2]หน้าผ้า!EB22 -> 0 | AW13: =[2]หน้าผ้า!EC22 -> 0 | AX13: =[2]หน้าผ้า!ED22 -> 0 | AY13: =[2]หน้าผ้า!AG22 -> 0 | AZ13: =[2]หน้าผ้า!EG22 -> 0 | BA13: =[2]หน้าผ้า!EH22 -> 0 | BB13: =[2]หน้าผ้า!EI22 -> 0 | BC13: =[2]หน้าผ้า!BZ22 -> WRWT170800/WRWT25800 | BD13: =[2]หน้าผ้า!CA22 -> 0
A14: =[2]หน้าผ้า!C23 -> ประมาณการ | B14: =[2]หน้าผ้า!B23 -> ประมาณการ | C14: =[2]หน้าผ้า!E23 -> บจก.ฟาร์เธอร์ส วิง ซัพพลาย | D14: =[2]หน้าผ้า!F23 -> รถไฟ | E14: =[2]หน้าผ้า!G23 -> 18 | F14: =[2]หน้าผ้า!H23 -> 30 | G14: =[2]หน้าผ้า!I23 -> ขาว | H14: =[2]หน้าผ้า!J23 -> 0 | I14: =[2]หน้าผ้า!L23 -> 54 | J14: =[2]หน้าผ้า!M23 -> ± | K14: =[2]หน้าผ้า!N23 -> 5 | L14: =[2]หน้าผ้า!R23 -> บิด | M14: =[2]หน้าผ้า!T23 -> 19 | N14: =[2]หน้าผ้า!U23 -> 33 | O14: =[2]หน้าผ้า!V23 -> 40 | P14: =[2]หน้าผ้า!AB23 -> 232.02999 | Q14: =[2]หน้าผ้า!AC23 -> 0 | R14: =[2]หน้าผ้า!AD23 -> 232.02999 | S14: =[2]หน้าผ้า!Z23 -> 500กระสอบ | T14: =[2]หน้าผ้า!X23 -> 45868 | U14: =[2]หน้าผ้า!AA23 -> 15000 | V14: =[2]หน้าผ้า!AJ23 -> 0 | W14: =[2]หน้าผ้า!AL23 -> 15000 | X14: =[2]หน้าผ้า!AM23 -> 0 | Y14: =[2]หน้าผ้า!AN23 -> 15750 | Z14: =[2]หน้าผ้า!AO23 -> WSWT1825800 | AA14: =[2]หน้าผ้า!AQ23 -> 13201.65 | AB14: =[2]หน้าผ้า!AR23 -> 6301 | AC14: =[2]หน้าผ้า!AS23 -> 6900.65 | AD14: =[2]หน้าผ้า!AT23 -> 0 | AE14: =[2]หน้าผ้า!AU23 -> 0 | AF14: =[2]หน้าผ้า!AI23 -> 0 | AG14: =[3]หน้าผ้า!DC26 -> ยังไม่ได้พิมพ์ | AH14: =[2]หน้าผ้า!DL23 -> P9 | AI14: =[2]หน้าผ้า!DM23 -> 3 | AJ14: =[2]หน้าผ้า!DN23 -> 45868 | AK14: =[2]หน้าผ้า!DQ23 -> 0 | AL14: =[2]หน้าผ้า!DR23 -> 45858 | AM14: =[2]หน้าผ้า!DS23 -> 45865 | AN14: =[2]หน้าผ้า!DT23 -> 45866 | AO14: =[2]หน้าผ้า!DU23 -> 45866 | AP14: =[2]หน้าผ้า!DP23 -> 45863 | AQ14: =[2]หน้าผ้า!DW23 -> 45867 | AR14: =[2]หน้าผ้า!DX23 -> 0 | AS14: =[2]หน้าผ้า!DY23 -> 0 | AT14: =[2]หน้าผ้า!DZ23 -> 0 | AU14: =[2]หน้าผ้า!EA23 -> 0 | AV14: =[2]หน้าผ้า!EB23 -> 0 | AW14: =[2]หน้าผ้า!EC23 -> งานพิมพ์ | AX14: =[2]หน้าผ้า!ED23 -> รอART | AY14: =[2]หน้าผ้า!AG23 -> 0 | AZ14: =[2]หน้าผ้า!EG23 -> 0 | BA14: =[2]หน้าผ้า!EH23 -> 0 | BB14: =[2]หน้าผ้า!EI23 -> 0 | BC14: =[2]หน้าผ้า!BZ23 -> WRWT25800/WRWT25800 | BD14: =[2]หน้าผ้า!CA23 -> 474.76472
A15: =[2]หน้าผ้า!C24 -> 0 | B15: =[2]หน้าผ้า!B24 -> 0 | C15: =[2]หน้าผ้า!E24 | D15: =[2]หน้าผ้า!F24 | E15: =[2]หน้าผ้า!G24 -> 18 | F15: =[2]หน้าผ้า!H24 -> 30 | G15: =[2]หน้าผ้า!I24 -> ขาว | H15: =[2]หน้าผ้า!J24 -> 0 | I15: =[2]หน้าผ้า!L24 -> 54 | J15: =[2]หน้าผ้า!M24 -> ± | K15: =[2]หน้าผ้า!N24 -> 5 | L15: =[2]หน้าผ้า!R24 -> 0 | M15: =[2]หน้าผ้า!T24 -> 0 | N15: =[2]หน้าผ้า!U24 -> 0 | O15: =[2]หน้าผ้า!V24 -> 0 | P15: =[2]หน้าผ้า!AB24 -> 0 | Q15: =[2]หน้าผ้า!AC24 -> 0 | R15: =[2]หน้าผ้า!AD24 -> 0 | S15: =[2]หน้าผ้า!Z24 -> 0 | T15: =[2]หน้าผ้า!X24 -> 0 | U15: =[2]หน้าผ้า!AA24 -> 0 | V15: =[2]หน้าผ้า!AJ24 -> 0 | W15: =[2]หน้าผ้า!AL24 -> 0 | X15: =[2]หน้าผ้า!AM24 -> 0 | Y15: =[2]หน้าผ้า!AN24 -> 0 | Z15: =[2]หน้าผ้า!AO24 -> WSWT1825800 | AA15: =[2]หน้าผ้า!AQ24 -> 13201.65 | AB15: =[2]หน้าผ้า!AR24 -> 6301 | AC15: =[2]หน้าผ้า!AS24 -> 6900.65 | AD15: =[2]หน้าผ้า!AT24 -> 0 | AE15: =[2]หน้าผ้า!AU24 -> 0 | AF15: =[2]หน้าผ้า!AI24 -> ระบุในSD | AG15: =[3]หน้าผ้า!DC27 -> พร้อมส่ง | AH15: =[2]หน้าผ้า!DL24 -> 0 | AI15: =[2]หน้าผ้า!DM24 -> Lead time | AJ15: =[2]หน้าผ้า!DN24 -> 0 | AK15: =[2]หน้าผ้า!DQ24 -> 0 | AL15: =[2]หน้าผ้า!DR24 -> 0 | AM15: =[2]หน้าผ้า!DS24 -> 0 | AN15: =[2]หน้าผ้า!DT24 -> 0 | AO15: =[2]หน้าผ้า!DU24 -> 0 | AP15: =[2]หน้าผ้า!DP24 -> 0 | AQ15: =[2]หน้าผ้า!DW24 -> 0 | AR15: =[2]หน้าผ้า!DX24 -> 0 | AS15: =[2]หน้าผ้า!DY24 -> 0 | AT15: =[2]หน้าผ้า!DZ24 -> 0 | AU15: =[2]หน้าผ้า!EA24 -> 0 | AV15: =[2]หน้าผ้า!EB24 -> 0 | AW15: =[2]หน้าผ้า!EC24 -> 0 | AX15: =[2]หน้าผ้า!ED24 -> 0 | AY15: =[2]หน้าผ้า!AG24 -> 0 | AZ15: =[2]หน้าผ้า!EG24 -> 0 | BA15: =[2]หน้าผ้า!EH24 -> 0 | BB15: =[2]หน้าผ้า!EI24 -> 0 | BC15: =[2]หน้าผ้า!BZ24 -> WRWT25800/WRWT25800 | BD15: =[2]หน้าผ้า!CA24 -> 0
A16: =[2]หน้าผ้า!C25 -> 45797 | B16: =[2]หน้าผ้า!B25 -> MK68-000687 | C16: =[2]หน้าผ้า!E25 -> บจก.ซิเบลโก้(บางเลน) | D16: =[2]หน้าผ้า!F25 -> PORTARYTE | E16: =[2]หน้าผ้า!G25 -> 18 | F16: =[2]หน้าผ้า!H25 -> 30 | G16: =[2]หน้าผ้า!I25 -> ขาว | H16: =[2]หน้าผ้า!J25 -> ใส | I16: =[2]หน้าผ้า!L25 -> 74 | J16: =[2]หน้าผ้า!M25 -> ± | K16: =[2]หน้าผ้า!N25 -> 5 | L16: =[2]หน้าผ้า!R25 -> ไม่ | M16: =[2]หน้าผ้า!T25 -> ไม่สวมถุงใน | N16: =[2]หน้าผ้า!U25 -> 0 | O16: =[2]หน้าผ้า!V25 -> 0 | P16: =[2]หน้าผ้า!AB25 -> 0 | Q16: =[2]หน้าผ้า!AC25 -> 0 | R16: =[2]หน้าผ้า!AD25 -> 0 | S16: =[2]หน้าผ้า!Z25 -> 500กระสอบ | T16: =[2]หน้าผ้า!X25 -> 45834 | U16: =[2]หน้าผ้า!AA25 -> 10000 | V16: =[2]หน้าผ้า!AJ25 -> 0 | W16: =[2]หน้าผ้า!AL25 -> 10000 | X16: =[2]หน้าผ้า!AM25 -> 0 | Y16: =[2]หน้าผ้า!AN25 -> 10500 | Z16: =[2]หน้าผ้า!AO25 -> WSWT1825800SM | AA16: =[2]หน้าผ้า!AQ25 -> 8801.1 | AB16: =[2]หน้าผ้า!AR25 -> 8801.1 | AC16: =[2]หน้าผ้า!AS25 -> 0 | AD16: =[2]หน้าผ้า!AT25 -> 0 | AE16: =[2]หน้าผ้า!AU25 -> 8801.1 | AF16: =[2]หน้าผ้า!AI25 -> ห้ามเกิน-ขาดได้5% | AG16: =[3]หน้าผ้า!DC28 -> ยังไม่ได้พิมพ์ | AH16: =[2]หน้าผ้า!DL25 -> P6 | AI16: =[2]หน้าผ้า!DM25 -> 4 | AJ16: =[2]หน้าผ้า!DN25 -> 45834 | AK16: =[2]หน้าผ้า!DQ25 -> 45830 | AL16: =[2]หน้าผ้า!DR25 -> 45823 | AM16: =[2]หน้าผ้า!DS25 -> 45831 | AN16: =[2]หน้าผ้า!DT25 -> 45832 | AO16: =[2]หน้าผ้า!DU25 -> 45833 | AP16: =[2]หน้าผ้า!DP25 -> 45829 | AQ16: =[2]หน้าผ้า!DW25 -> 0 | AR16: =[2]หน้าผ้า!DX25 -> 0 | AS16: =[2]หน้าผ้า!DY25 -> 0 | AT16: =[2]หน้าผ้า!DZ25 -> 0 | AU16: =[2]หน้าผ้า!EA25 -> 0 | AV16: =[2]หน้าผ้า!EB25 -> 0 | AW16: =[2]หน้าผ้า!EC25 -> งานเคลือบ+พิมพ์ | AX16: =[2]หน้าผ้า!ED25 -> / | AY16: =[2]หน้าผ้า!AG25 -> 0 | AZ16: =[2]หน้าผ้า!EG25 -> 0 | BA16: =[2]หน้าผ้า!EH25 -> 0 | BB16: =[2]หน้าผ้า!EI25 -> 0 | BC16: =[2]หน้าผ้า!BZ25 -> WRWT25800/WRWT25800 | BD16: =[2]หน้าผ้า!CA25 -> 0
A17: =[2]หน้าผ้า!C26 -> 45824 | B17: =[2]หน้าผ้า!B26 -> MK68-000794 | C17: =[2]หน้าผ้า!E26 -> บจก.ซิเบลโก้(บางเลน) | D17: =[2]หน้าผ้า!F26 -> FELDSPAR K200BL | E17: =[2]หน้าผ้า!G26 -> 18 | F17: =[2]หน้าผ้า!H26 -> 30 | G17: =[2]หน้าผ้า!I26 -> ขาว | H17: =[2]หน้าผ้า!J26 -> ใส | I17: =[2]หน้าผ้า!L26 -> 74 | J17: =[2]หน้าผ้า!M26 -> ± | K17: =[2]หน้าผ้า!N26 -> 5 | L17: =[2]หน้าผ้า!R26 -> ไม่ | M17: =[2]หน้าผ้า!T26 -> ไม่สวมถุงใน | N17: =[2]หน้าผ้า!U26 -> 0 | O17: =[2]หน้าผ้า!V26 -> 0 | P17: =[2]หน้าผ้า!AB26 -> 0 | Q17: =[2]หน้าผ้า!AC26 -> 0 | R17: =[2]หน้าผ้า!AD26 -> 0 | S17: =[2]หน้าผ้า!Z26 -> 500กระสอบ | T17: =[2]หน้าผ้า!X26 -> 45834 | U17: =[2]หน้าผ้า!AA26 -> 5000 | V17: =[2]หน้าผ้า!AJ26 -> 0 | W17: =[2]หน้าผ้า!AL26 -> 5000 | X17: =[2]หน้าผ้า!AM26 -> 0 | Y17: =[2]หน้าผ้า!AN26 -> 5250 | Z17: =[2]หน้าผ้า!AO26 -> WSWT1825800SM | AA17: =[2]หน้าผ้า!AQ26 -> 4400.55 | AB17: =[2]หน้าผ้า!AR26 -> 4400.55 | AC17: =[2]หน้าผ้า!AS26 -> 0 | AD17: =[2]หน้าผ้า!AT26 -> 0 | AE17: =[2]หน้าผ้า!AU26 -> 4400.55 | AF17: =[2]หน้าผ้า!AI26 -> ห้ามเกิน-ขาดได้5% | AG17: =[3]หน้าผ้า!DC29 -> ยังไม่ได้พิมพ์ | AH17: =[2]หน้าผ้า!DL26 -> P6 | AI17: =[2]หน้าผ้า!DM26 -> 4 | AJ17: =[2]หน้าผ้า!DN26 -> 45834 | AK17: =[2]หน้าผ้า!DQ26 -> 45830 | AL17: =[2]หน้าผ้า!DR26 -> 45823 | AM17: =[2]หน้าผ้า!DS26 -> 45831 | AN17: =[2]หน้าผ้า!DT26 -> 45832 | AO17: =[2]หน้าผ้า!DU26 -> 45833 | AP17: =[2]หน้าผ้า!DP26 -> 45829 | AQ17: =[2]หน้าผ้า!DW26 -> 0 | AR17: =[2]หน้าผ้า!DX26 -> 0 | AS17: =[2]หน้าผ้า!DY26 -> 0 | AT17: =[2]หน้าผ้า!DZ26 -> 0 | AU17: =[2]หน้าผ้า!EA26 -> 0 | AV17: =[2]หน้าผ้า!EB26 -> 0 | AW17: =[2]หน้าผ้า!EC26 -> งานเคลือบ+พิมพ์ | AX17: =[2]หน้าผ้า!ED26 -> / | AY17: =[2]หน้าผ้า!AG26 -> 0 | AZ17: =[2]หน้าผ้า!EG26 -> 0 | BA17: =[2]หน้าผ้า!EH26 -> 0 | BB17: =[2]หน้าผ้า!EI26 -> 0 | BC17: =[2]หน้าผ้า!BZ26 -> WRWT25800/WRWT25800 | BD17: =[2]หน้าผ้า!CA26 -> 0
... A575: =[2]หน้าผ้า!C584 -> 0 | B575: =[2]หน้าผ้า!B584 -> 0 | C575: =[2]หน้าผ้า!E584 -> 0 | D575: =[2]หน้าผ้า!F584 -> 0 | E575: =[2]หน้าผ้า!G584 -> 0 | F575: =[2]หน้าผ้า!H584 -> 0 | G575: =[2]หน้าผ้า!I584 -> 0 | H575: =[2]หน้าผ้า!J584 -> 0 | I575: =[2]หน้าผ้า!L584 -> 0 | J575: =[2]หน้าผ้า!M584 -> 0 | K575: =[2]หน้าผ้า!N584 -> 0 | L575: =[2]หน้าผ้า!R584 -> 0 | M575: =[2]หน้าผ้า!T584 -> 0 | N575: =[2]หน้าผ้า!U584 -> 0 | O575: =[2]หน้าผ้า!V584 -> 0 | P575: =[2]หน้าผ้า!AB584 -> 0 | Q575: =[2]หน้าผ้า!AC584 -> 0 | R575: =[2]หน้าผ้า!AD584 -> 0 | S575: =[2]หน้าผ้า!Z584 -> 0 | T575: =[2]หน้าผ้า!X584 -> 0 | U575: =[2]หน้าผ้า!AA584 -> 0 | V575: =[2]หน้าผ้า!AJ584 -> 0 | W575: =[2]หน้าผ้า!AL584 -> 0 | X575: =[2]หน้าผ้า!AM584 -> 0 | Y575: =[2]หน้าผ้า!AN584 -> 0 | Z575: =[2]หน้าผ้า!AO584 -> 0 | AA575: =[2]หน้าผ้า!AQ584 -> 0 | AB575: =[2]หน้าผ้า!AR584 -> 0 | AC575: =[2]หน้าผ้า!AS584 -> 0 | AD575: =[2]หน้าผ้า!AT584 -> 0 | AE575: =[2]หน้าผ้า!AU584 -> 0 | AF575: =[2]หน้าผ้า!AI584 -> 0 | AG575: =[3]หน้าผ้า!DC587 -> 0 | AH575: =[2]หน้าผ้า!DL584 -> 0 | AI575: =[2]หน้าผ้า!DM584 -> 0 | AJ575: =[2]หน้าผ้า!DN584 -> 0 | AK575: =[2]หน้าผ้า!DQ584 -> 0 | AL575: =[2]หน้าผ้า!DR584 -> 0 | AM575: =[2]หน้าผ้า!DS584 -> 0 | AN575: =[2]หน้าผ้า!DT584 -> 0 | AO575: =[2]หน้าผ้า!DU584 -> 0 | AP575: =[2]หน้าผ้า!DP584 -> 0 | AQ575: =[2]หน้าผ้า!DW584 -> 0 | AR575: =[2]หน้าผ้า!DX584 -> 0 | AS575: =[2]หน้าผ้า!DY584 -> 0 | AT575: =[2]หน้าผ้า!DZ584 -> 0 | AU575: =[2]หน้าผ้า!EA584 -> 0 | AV575: =[2]หน้าผ้า!EB584 -> 0 | AW575: =[2]หน้าผ้า!EC584 -> 0 | AX575: =[2]หน้าผ้า!ED584 -> 0 | AY575: =[2]หน้าผ้า!AG584 -> 0 | AZ575: =[2]หน้าผ้า!EG584 -> 0 | BA575: =[2]หน้าผ้า!EH584 -> 0 | BB575: =[2]หน้าผ้า!EI584 -> 0 | BC575: =[2]หน้าผ้า!BZ584 -> 0 | BD575: =[2]หน้าผ้า!CA584 -> 0

Sheet 4(Order+FC) (-4)
A2: เลขที่ SO | B2: (หลายรายการ)
A3: วันส่ง | B3: รอแจ้ง
A4: ชื่อลูกค้า | B4: (ทั้งหมด)
A6: ประเภท | B6: ผลรวม ของ จำนวนส่ง | C6: ผลรวม ของ ค้างพิมพ์ | D6: ผลรวม ของ ค้างตัด | E6: ผลรวม ของ Stock | F6: ผลรวม ของ ใช้ | G6: ผลรวม ของ ค้างทอ
A7: WSWT1625800SM | B7: 5000 | C7: 5250 | D7: 5000 | E7: 3372 | F7: 3702.05 | G7: 330.05 | H7: =+J7-I7 -> 330.05 | J7: =G7 -> 330.05
A8: WSWT1825800SM | B8: 10000 | C8: 10500 | D8: 10000 | E8: 3198 | F8: 8801.1 | G8: 5603.1 | H8: =+J8-I8 -> 5603.1 | J8: =G8 -> 5603.1
A9: WSWT1921720 | B9: 600000 | C9: 630000 | D9: 600000 | E9: 0 | F9: 528066 | G9: 528066 | H9: =+J9-I9 -> 528066 | J9: =G9 -> 528066
A10: WSWT1925800 | B10: 10000 | C10: 10500 | D10: 10000 | E10: 0 | F10: 9359.9 | G10: 9359.9 | H10: =+J10-I10 -> 9359.9 | J10: =G10 -> 9359.9
A11: WSWT2025700 | B11: 50000 | C11: 0 | D11: 50000 | E11: 9009 | F11: 55181.5 | G11: 46172.5 | H11: =+J11-I11 -> 46172.5 | J11: =G11 -> 46172.5
A12: WSWT2025800 | B12: 110000 | C12: 115500 | D12: 110000 | E12: 0 | F12: 115252.5 | G12: 115252.5 | H12: =+J12-I12 -> 115252.5 | J12: =G12 -> 115252.5
A13: WSWT2025800SM | B13: 69250 | C13: 66150 | D13: 69183 | E13: 0 | F13: 68578.73 | G13: 68578.73 | H13: =+J13-I13 -> 68578.73 | J13: =G13 -> 68578.73
A14: WSWT2121670SM | B14: 71000 | C14: 74550 | D14: 71000 | E14: 0 | F14: 77743.05 | G14: 77743.05 | H14: =+J14-I14 -> 77743.05 | J14: =G14 -> 77743.05
A15: WSWT2321112512551 | B15: 106278 | C15: 111591.9 | D15: 106278 | E15: 0 | F15: 114322.18 | G15: 114322.18 | H15: =+J15-I15 -> 114322.18 | J15: =G15 -> 114322.18
A16: WSWT2625650 | B16: 50000 | C16: 10500 | D16: 50000 | E16: 0 | F16: 60490.1 | G16: 60490.1 | H16: =+J16-I16 -> 60490.1 | J16: =G16 -> 60490.1
A17: WSWT2625800 | B17: 30000 | C17: 0 | D17: 30000 | E17: 6278 | F17: 37299.9 | G17: 31021.9 | H17: 0 | I17: 160000 | J17: =G17 -> 31021.9
A18: WSWT2625850SM | B18: 20000 | C18: 21000 | D18: 20000 | E18: 7700 | F18: 24866.6 | G18: 17166.6 | H18: =+J18-I18 -> 17166.6 | J18: =G18 -> 17166.6
A19: ผลรวมทั้งหมด | B19: 1131528 | C19: 1055541.9 | D19: 1131461 | E19: 29557 | F19: 1103663.6 | G19: 1074106.6 | H19: =+J19-I19 -> 1074106.6 | J19: =G19 -> 1074106.6
H20: =+J20-I20 -> 0 | J20: =G20 -> 0
H21: =+J21-I21 -> 0 | J21: =G21 -> 0
H22: =+J22-I22 -> 0 | J22: =G22 -> 0
H23: =+J23-I23 -> 0 | J23: =G23 -> 0
H24: =+J24-I24 -> 0 | J24: =G24 -> 0
H25: =+J25-I25 -> 0 | J25: =G25 -> 0
H27: =SUM(H8:H25) -> 2116861.3 | J27: =SUM(J8:J25) -> 2147883.2
M28: =+GETPIVOTDATA("ผลรวม ของ ใช้",$A$6)+H29+H31 -> 1193663.6
H30: =+H27 -> 2116861.3
A31: กรม | B31: 70000 | C31: 70000 | D31: 70000 | G31: 90000 | H31: 90000 | I31: 95 | J31: =+H31*I31 -> 8550000 | K31: =+J31/1000 -> 8550
G33: 160000 | H33: =+H29+H30 -> 2116861.3 | I33: 85 | J33: =+H33*I33 -> 1.7993321e+08 | K33: =+J33/1000 -> 179933.21
H34: =+H30+H31+H29 -> 2206861.3
H35: 15 | I35: =+H34/H35 -> 147124.08 | K35: =+K33+K31 -> 188483.21
N36: 705222
A37: ยอดส่ง 1/2/68 - 10/2/68 | B37: 817879 | I37: =+H35*100000 -> 1500000
N38: =+H34+N36 -> 2912083.3
H39: 16 | I39: =+H39*90000 -> 1440000
B41: =+B26+B37+B31 -> 887879 | C41: =+C26+C37+C31 -> 70000 | D41: =+D26+D37+D31 -> 70000 | E41: =+E26+E37+E31 -> 0 | F41: =+F26+F37+F31 -> 0
B43: 2992955
B45: =+B43-B41 -> 2105076 | C45: =+C32+($B$45*1) -> 2105076 | D45: =+D32+($B$45*1) -> 2105076 | E45: =+E31+($B$45*1) -> 2105076 | F45: =+F30+($B$45*1) -> 2105076 | G45: =+G30+($B$45*1) -> 2105076
C47: =+C41/13 -> 5384.6154 | D47: =+D41/15 -> 4666.6667
B49: 16 | C49: 135000 | D49: 135000
C50: =+B49*C49 -> 2160000 | D50: =+B49*D49 -> 2160000
...

Sheet 4(Order+FC)
A2: เลขที่ SO | B2: (หลายรายการ)
A3: วันส่ง | B3: (หลายรายการ)
A4: ชื่อลูกค้า | B4: (ทั้งหมด)
K5: 9
A6: ประเภท | B6: ผลรวม ของ จำนวนส่ง | C6: ผลรวม ของ ค้างพิมพ์ | D6: ผลรวม ของ ค้างตัด | E6: ผลรวม ของ ใช้ | F6: ผลรวม ของ Stock | G6: ผลรวม ของ ค้างทอ
A7: WSWT1625800 | B7: 10000 | C7: 0 | D7: 10000 | E7: 0 | F7: 0 | G7: 0 | H7: =+J7-I7 -> 0 | J7: =G7 -> 0
A8: WSWT1921720 | B8: 90000 | C8: 41976.9 | D8: 74828 | E8: 40423.788 | F8: 8801.1 | G8: 31622.688 | H8: =+J8-I8 -> 31622.688 | J8: =G8 -> 31622.688
A9: WSWT1925800 | B9: 118000 | C9: 54869.85 | D9: 118000 | E9: 45972.484 | F9: 8242.3 | G9: 37730.184 | H9: =+J9-I9 -> 37730.184 | J9: =G9 -> 37730.184
A10: WSWT2025700 | B10: 10000 | C10: 0 | D10: 10000 | E10: 8801.1 | F10: 0 | G10: 8801.1 | H10: =+J10-I10 -> 8801.1 | J10: =G10 -> 8801.1
A11: WSWT2025800 | B11: 193960 | C11: 70687.05 | D11: 193960 | E11: 74062.357 | F11: 50571 | G11: 23491.357 | H11: =+J11-I11 -> 23491.357 | J11: =G11 -> 23491.357
A12: WSWT2025800SM | B12: 142160 | C12: 123783.45 | D12: 139160 | E12: 123659.07 | F12: 74605.09 | G12: 49053.98 | H12: =+J12-I12 -> 49053.98 | J12: =G12 -> 49053.98 | K12: 40000 | L12: =+K5*K12 -> 360000 | M12: =+L12-J12 -> 310946.02
A13: WSWT2121670SM | B13: 82000 | C13: 54153.75 | D13: 79000 | E13: 55670.991 | F13: 17415.391 | G13: 38255.6 | H13: =+J13-I13 -> 38255.6 | J13: =G13 -> 38255.6 | K13: 14000 | L13: =+K13*K5 -> 126000 | M13: =+L13-J13 -> 87744.4
A14: WSWT2321750 | B14: 8000 | C14: 0 | D14: 8000 | E14: 0 | F14: 0 | G14: 0 | H14: =+J14-I14 -> 0 | J14: =G14 -> 0
A15: WSWT2325650 | B15: 40000 | C15: 0 | D15: 40000 | E15: 0 | F15: 0 | G15: 0 | H15: =+J15-I15 -> 0 | J15: =G15 -> 0 | K15: 20000 | L15: =+K15*K5 -> 180000 | M15: =+L15-J15 -> 180000
A16: WSWT2625650 | B16: 12563 | C16: 8400 | D16: 8000 | E16: 9499.6 | F16: 6749.8 | G16: 2749.8 | H16: =+J16-I16 -> 2749.8 | J16: =G16 -> 2749.8
A17: WSWT2625850SM | B17: 10000 | C17: 0 | D17: 10000 | E17: 0 | F17: 0 | G17: 0 | H17: =+J17-I17 -> 0 | J17: =G17 -> 0
A18: WSWT2825850 | B18: 31500 | C18: 0 | D18: 10500 | E18: 0 | F18: 0 | G18: 0 | H18: =+J18-I18 -> 0 | J18: =G18 -> 0
A19: ผลรวมทั้งหมด | B19: 748183 | C19: 353871 | D19: 701448 | E19: 358089.39 | F19: 166384.68 | G19: 191704.71 | H19: 0 | I19: 54000 | J19: =G19 -> 191704.71
H20: =+J20-I20 -> 0 | J20: =G20 -> 0
H21: =+J21-I21 -> 0 | J21: =G21 -> 0
H22: =+J22-I22 -> 0 | J22: =G22 -> 0
H23: =+J23-I23 -> 0 | J23: =G23 -> 0
H24: =+J24-I24 -> 0 | J24: =G24 -> 0
H25: =+J25-I25 -> 0 | J25: =G25 -> 0
H26: =+J26-I26 -> 0 | J26: =G26 -> 0
H27: =+J27-I27 -> 0 | J27: =G27 -> 0
H28: =+J28-I28 -> 0 | J28: =G28 -> 0 | M28: =+GETPIVOTDATA("ผลรวม ของ ใช้",$A$6)+H29+H33 -> 639794.1
H29: =SUM(H7:H28) -> 191704.71 | I29: =SUM(I7:I28) -> 54000 | J29: =SUM(J7:J28) -> 383409.42
H32: =+H26 -> 0 | I32: 85 | J32: =+(H32+H29)*I32 -> 16294900 | K32: =+J32/1000 -> 16294.9
H33: 90000 | I33: 95 | J33: =+H33*I33 -> 8550000 | K33: =+J33/1000 -> 8550
H35: =+H32+H33+H29 -> 281704.71 | K35: =+K32+K33 -> 24844.9
N36: 705222
A37: ยอดส่ง 1/2/68 - 17/2/68 | B37: 1565717 | H37: 15 | I37: =+H35/H37 -> 18780.314
N38: =+H35+N36 -> 986926.71
I39: =+H37*110000 -> 1650000
B41: =+B29+B37+B31-110000 -> 1455717 | C41: =+C29+C37+C31 -> 0 | D41: =+D29+D37+D31-110000 -> -110000 | E41: =+E29+E37+E31 -> 0 | F41: =+F29+F37+F31 -> 0 | G41: =+G29+G37+G31 -> 0
B43: 3218150
B45: =+B43-B41 -> 1762433
C47: =+C41/9 -> 0 | D47: =+D41/9 -> -12222.222

Sheet 7(Order)
A2: เลขที่ SO | B2: (หลายรายการ)
A3: วันส่ง | B3: (หลายรายการ)
A4: ชื่อลูกค้า | B4: (ทั้งหมด)
A6: ประเภท | B6: ผลรวม ของ จำนวนส่ง | C6: ผลรวม ของ ค้างพิมพ์ | D6: ผลรวม ของ ค้างตัด | E6: ผลรวม ของ ใช้ | F6: ผลรวม ของ Stock | G6: ผลรวม ของ ค้างทอ
A7: WSWT1921720 | B7: 25000 | C7: 21000 | D7: 25000 | E7: 17881.6 | F7: 0 | G7: 17881.6 | I7: =+K7-J7 -> 17881.6 | K7: =G7 -> 17881.6
A8: WSWT19251000SM | B8: 10080 | C8: 10584 | D8: 10080 | E8: 10138.867 | F8: 4000 | G8: 6138.8672 | I8: =+K8-J8 -> 6138.8672 | K8: =G8 -> 6138.8672
A9: WSWT1925800 | B9: 140000 | C9: 147000 | D9: 140000 | E9: 123215.4 | F9: 0 | G9: 123215.4 | I9: =+K9-J9 -> 123215.4 | K9: =G9 -> 123215.4
A10: WSWT2025800 | B10: 435000 | C10: 441000 | D10: 430000 | E10: 447878.2 | F10: 0 | G10: 447878.2 | I10: =+K10-J10 -> 447878.2 | K10: =G10 -> 447878.2
A11: WSWT2025800SM | B11: 16895 | C11: 11856.6 | D11: 13577 | E11: 12053.643 | F11: 3602.9105 | G11: 8450.7324 | I11: =+K11-J11 -> 8450.7324 | K11: =G11 -> 8450.7324
A12: WSWT2121670SM | B12: 11000 | C12: 11550 | D12: 11000 | E12: 12139.93 | F12: 0 | G12: 12139.93 | I12: =+K12-J12 -> 12139.93 | K12: =G12 -> 12139.93
A13: WSWT2321112512551 | B13: 50000 | C13: 52500 | D13: 50000 | E13: 53784.5 | F13: 0 | G13: 53784.5 | I13: =+K13-J13 -> 53784.5 | K13: =G13 -> 53784.5
A14: WSWT2321112512551VN | B14: 100000 | C14: 105000 | D14: 100000 | E14: 107569 | F14: 0 | G14: 107569 | I14: =+K14-J14 -> 107569 | K14: =G14 -> 107569
A15: WSWT2325650 | B15: 20000 | C15: 21000 | D15: 20000 | E15: 20619.72 | F15: 20619.72 | G15: 0 | I15: =+K15-J15 -> 0 | K15: =G15 -> 0
A16: ผลรวมทั้งหมด | B16: 807975 | C16: 821490.6 | D16: 799657 | E16: 805280.86 | F16: 28222.63 | G16: 777058.23 | I16: =+K16-J16 -> 777058.23 | K16: =G16 -> 777058.23
I17: 0 | J17: 54000 | K17: =G17 -> 0
I18: =+K18-J18 -> 0 | K18: =G18 -> 0
I19: =+K19-J19 -> 0 | K19: =G19 -> 0
I20: =+K20-J20 -> 0 | K20: =G20 -> 0
I21: =+K21-J21 -> 0 | K21: =G21 -> 0
I22: =+K22-J22 -> 0 | K22: =G22 -> 0
I23: =+K23-J23 -> 0 | K23: =G23 -> 0
I24: =+K24-J24 -> 0 | K24: =G24 -> 0
I25: =+K25-J25 -> 0 | K25: =G25 -> 0
I26: =SUM(I7:I25) -> 1554116.5 | J26: =SUM(J7:J25) -> 54000 | K26: =SUM(K7:K25) -> 1554116.5
D28: =+D10 -> 430000
D30: =+D12 -> 11000
D31: =+D13 -> 50000
D32: =+D14 -> 100000
D33: =+D15 -> 20000
D34: =D18 -> 0
D36: =D20 -> 0
A37: ยอดส่ง 1/4/68 - 12/4/68 | B37: 887615
A38: Order+ส่ง | B38: =++B25+B37 -> 887615
A39: ประมาณการ | B39: 262000 | C39: 238350 | D39: 262000 | E39: 279847.04 | F39: 60825.09 | G39: 219021.95
A41: Order+ส่ง+ประมาณการ | B41: =+B25+B37+B39+B33 -> 1149615 | C41: =+C25+C37+C39+C33 -> 238350 | D41: =+D25+D37+D39+D33 -> 282000 | E41: =+E25+E37+E39+E33 -> 279847.04 | F41: =+F25+F37+F39+F33 -> 60825.09 | G41: =+G25+G37+G39+G33 -> 219021.95
B43: 3171376
B45: =+B41-B43 -> -2021761 | C45: =+$B$45 -> -2021761 | D45: =+$B$45 -> -2021761 | F45: =+$B$45 -> -2021761
D47: =+D41/6 -> 47000

Sheet 7(Order) แยกลูกค้า
A1: เลขที่ SO | B1: (หลายรายการ)
A2: วันส่ง | B2: รอแจ้ง
A4: ประเภท | B4: ชื่อลูกค้า | C4: ผลรวม ของ จำนวนส่ง | D4: ผลรวม ของ ค้างพิมพ์ | E4: ผลรวม ของ ค้างตัด | F4: ผลรวม ของ Stock | G4: ผลรวม ของ ค้างทอ | I4: vn
A5: WSWT1921720 | B5: บจก.เคอรี่ฟลาวมิลล์ | C5: 10000 | D5: 0 | E5: 10000 | F5: 0 | G5: 0 | H5: =G5 -> 0
A6: WSWT1921720 ผลรวม | C6: 10000 | D6: 0 | E6: 10000 | F6: 0 | G6: 0 | H6: =G6 -> 0
A7: WSWT2025800SM | B7: บจก.อินเทคค์ โกลบอล | C7: 2540 | D7: 0 | E7: 2473 | F7: 0 | G7: 0 | H7: =G7 -> 0
B8: บจก.เอสพีเอ็ม อาหารสัตว์ | C8: 3000 | D8: 3150 | E8: 3000 | F8: 0 | G8: 3478.53 | H8: =G8 -> 3478.53
A9: WSWT2025800SM ผลรวม | C9: 5540 | D9: 3150 | E9: 5473 | F9: 0 | G9: 3478.53 | H9: =G9 -> 3478.53
A10: WSWT2121670SM | B10: บจก.ที.ซี.ยูเนี่ยน อโกรเทค | C10: 32000 | D10: 33600 | E10: 32000 | F10: 0 | G10: 34422.08 | H10: =G10 -> 34422.08
B11: บจก.เอสพีเอ็ม อาหารสัตว์ | C11: 5000 | D11: 5250 | E11: 5000 | F11: 0 | G11: 5518.15 | H11: =G11 -> 5518.15
A12: WSWT2121670SM ผลรวม | C12: 37000 | D12: 38850 | E12: 37000 | F12: 0 | G12: 39940.23 | H12: =G12 -> 39940.23
A13: WSWT2321112512551 | B13: บจก.น้ำตาลทิพย์สุโขทัย | C13: 306278 | D13: 321591.9 | E13: 306278 | F13: 0 | G13: 329460.18 | H13: =G13 -> 329460.18
A14: WSWT2321112512551 ผลรวม | C14: 306278 | D14: 321591.9 | E14: 306278 | F14: 0 | G14: 329460.18 | H14: =G14 -> 329460.18
A15: WSWT2321112512551VN | B15: บจก.น้ำตาลทิพย์สุโขทัย | C15: 325000 | D15: 341250 | E15: 325000 | F15: 0 | G15: 349599.25 | H15: =G15 -> 349599.25
A16: WSWT2321112512551VN ผลรวม | C16: 325000 | D16: 341250 | E16: 325000 | F16: 0 | G16: 349599.25 | H16: =G16 -> 349599.25
A17: WSWT2321750 | B17: บจก.แอมโก้เวท | C17: 1000 | D17: 0 | E17: 1000 | F17: 1159.51 | G17: 0 | H17: =G17 -> 0
A18: WSWT2321750 ผลรวม | C18: 1000 | D18: 0 | E18: 1000 | F18: 1159.51 | G18: 0 | H18: =G18 -> 0
A19: ผลรวมทั้งหมด | C19: 684818 | D19: 704841.9 | E19: 684751 | F19: 1159.51 | G19: 722478.19 | H19: =G19 -> 722478.19
H20: =G20 -> 0
H21: =G21 -> 0
H22: =G22 -> 0
H23: =G23 -> 0
H24: =G24 -> 0
H25: =G25 -> 0
H26: =G26 -> 0
H27: =G27 -> 0
H28: =G28 -> 0
H29: =G29 -> 0
H30: =G30 -> 0
H31: =G31 -> 0
... H65: =G65 -> 0
H70: =SUM(H5:H69) -> 2167434.6
D119: Cap พิมพ์ | E119: Cap ตัด | F119: Stock 16/7 บ่าย | G119: Cap ทอ | I119: วันทงาน
B120: lส่ง | C120: 1-16/7 | D120: 160000 | E120: 160000 | G120: 120000 | I120: 12
C121: 1975256 | D121: =+D120*I120 -> 1920000 | E121: =+E120*I120 -> 1920000 | F121: 825147 | G121: =+G120*I120 -> 1440000
A122: เบทาโกรส่งแล้ว | B122: 20700 | C122: 424374
A123: เบทาโกรส่งแล้ว | B123: 20800 | C123: 155973
C126: รวมส่ง+ค้างส่ง | D126: ส่วนต่างCapคงเหลือ | E126: ส่วนต่างCapคงเหลือ | F126: คงเหลือ
C127: =+C50+C121 -> 1975256 | D127: =+D121-D50 -> 1920000 | E127: =+E121-E50 -> 1920000 | F127: =+F121-F50 -> 825147 | G127: =+G121-G50 -> 1440000
B129: 20700VN 20/7 | G129: 350000

Sheet 7(Fc) แยกลูกค้า
A1: เลขที่ SO | B1: ประมาณการ
A2: วันส่ง | B2: รอแจ้ง | D2: 12
A4: ประเภท | B4: ชื่อลูกค้า | C4: ผลรวม ของ จำนวนส่ง | D4: ผลรวม ของ ค้างพิมพ์ | E4: ผลรวม ของ ค้างตัด | F4: ผลรวม ของ ใช้ | G4: ผลรวม ของ Stock | H4: ผลรวม ของ ค้างทอ
A5: WSWT2121670SM | B5: บจก.ที.ซี.ยูเนี่ยน อโกรเทค | C5: 10000 | D5: 10500 | E5: 10000 | F5: 10756.9 | G5: 0 | H5: 10756.9
B6: บจก.เอพีเอ็ม อะโกร | C6: 10000 | D6: 10500 | E6: 10000 | F6: 11595.1 | G6: 0 | H6: 11595.1
A7: WSWT2121670SM ผลรวม | C7: 20000 | D7: 21000 | E7: 20000 | F7: 22352 | G7: 0 | H7: 22352
A8: ผลรวมทั้งหมด | C8: 20000 | D8: 21000 | E8: 20000 | F8: 22352 | G8: 0 | H8: 22352
D119: Cap พิมพ์ | E119: Cap ตัด | F119: Stock 16/7 บ่าย | G119: Cap ทอ | I119: วันทงาน
B120: lส่ง | C120: 1-16/7 | D120: 160000 | E120: 160000 | G120: 120000 | I120: 12
C121: 1975256 | D121: =+D120*I120 -> 1920000 | E121: =+E120*I120 -> 1920000 | F121: 825147 | G121: =+G120*I120 -> 1440000
A122: เบทาโกรส่งแล้ว | B122: 20700 | C122: 424374
A123: เบทาโกรส่งแล้ว | B123: 20800 | C123: 155973
C126: รวมส่ง+ค้างส่ง | D126: ส่วนต่างCapคงเหลือ | E126: ส่วนต่างCapคงเหลือ | F126: คงเหลือ
C127: =+C50+C121 -> 1975256 | D127: =+D121-D50 -> 1920000 | E127: =+E121-E50 -> 1920000 | F127: =+F121-F50 -> 825147 | G127: =+G121-G50 -> 1440000
B129: 20700VN 20/7 | G129: 350000

Sheet 6(Order+Fc) แยกลูกค้า
A1: เลขที่ SO | B1: (หลายรายการ)
A2: วันส่ง | B2: (หลายรายการ) | D2: 12 | I2: เมตร | J2: vn | K2: ใบ | P2: วัน
A4: ประเภท | B4: ชื่อลูกค้า | C4: ผลรวม ของ จำนวนส่ง | D4: ผลรวม ของ ค้างพิมพ์ | E4: ผลรวม ของ ค้างตัด | F4: ผลรวม ของ Stock | G4: ผลรวม ของ ใช้ | H4: ผลรวม ของ ค้างทอ
A5: WSWT1425800 | B5: หจก.ปึงเป้งน้ำ | C5: 10000 | D5: 10500 | E5: 10000 | F5: 1220 | G5: 6565.9 | H5: 5345.9 | I5: =H5 -> 5345.9
A6: WSWT1425800 ผลรวม | C6: 10000 | D6: 10500 | E6: 10000 | F6: 1220 | G6: 6565.9 | H6: 5345.9
A7: WSWT1725800 | B7: บจก.โรงสีข้าวธัญญาวัฒน์ | C7: 10200 | D7: 0 | E7: 1700 | F7: 0 | G7: 0 | H7: 0 | I7: =H7 -> 0
A8: WSWT1725800 ผลรวม | C8: 10200 | D8: 0 | E8: 1700 | F8: 0 | G8: 0 | H8: 0 | I8: =H8 -> 0
A9: WSWT1825800 | B9: บจก.ฟาร์เธอร์ส วิง ซัพพลาย | C9: 15000 | D9: 15750 | E9: 15000 | F9: 6301 | G9: 13201.65 | H9: 6900.65 | I9: =H9 -> 6900.65
A10: WSWT1825800 ผลรวม | C10: 15000 | D10: 15750 | E10: 15000 | F10: 6301 | G10: 13201.65 | H10: 6900.65 | I10: =H10 -> 6900.65
A11: WSWT1825800SM | B11: บจก.ซิเบลโก้ | C11: 20000 | D11: 21000 | E11: 20000 | F11: 17602.2 | G11: 17602.2 | H11: 0
B12: บจก.ไบโอกรีนนิค | C12: 10000 | D12: 10500 | E12: 10000 | F12: 2398 | G12: 8242.3 | H12: 5844.3 | I12: =H12 -> 5844.3
A13: WSWT1825800SM ผลรวม | C13: 30000 | D13: 31500 | E13: 30000 | F13: 20000.2 | G13: 25844.5 | H13: 5844.3
A14: WSWT1921720 | B14: บจก.เคอรี่ฟลาวมิลล์ | C14: 400000 | D14: 384079.5 | E14: 395000 | F14: 63621.629 | G14: 334623.53 | H14: 271001.9 | I14: =H14 -> 271001.9 | P14: 15000 | Q14: =+K14/P14 -> 0
A15: WSWT1921720 ผลรวม | C15: 400000 | D15: 384079.5 | E15: 395000 | F15: 63621.629 | G15: 334623.53 | H15: 271001.9
A16: WSWT1925800 | B16: บจก.เพรซิเดนท์ฟลาวมิลล์ | C16: 70000 | D16: 73500 | E16: 70000 | F16: 61607.7 | G16: 61607.7 | H16: 0 | I16: =H16 -> 0
B17: บจก.ไลม์มาสเตอร์ | C17: 10000 | D17: 10500 | E17: 10000 | F17: 0 | G17: 9359.9 | H17: 9359.9 | I17: =H17 -> 9359.9
A18: WSWT1925800 ผลรวม | C18: 80000 | D18: 84000 | E18: 80000 | F18: 61607.7 | G18: 70967.6 | H18: 9359.9 | I18: =H18 -> 9359.9
A19: WSWT1925800SM | B19: บจก.ไมโครอินโนเวท | C19: 10000 | D19: 10500 | E19: 10000 | F19: 9918.7 | G19: 9918.7 | H19: 0 | I19: =H19 -> 0
A20: WSWT1925800SM ผลรวม | C20: 10000 | D20: 10500 | E20: 10000 | F20: 9918.7 | G20: 9918.7 | H20: 0 | I20: =H20 -> 0 | P20: 16000 | Q20: =+K20/P20 -> 0
A21: WSWT2021850UV | B21: กรุงเทพมหานคร | C21: 1345000 | D21: 1011260.2 | E21: 1345000 | F21: 316435 | G21: 920971.9 | H21: 604536.9
A22: WSWT2021850UV ผลรวม | C22: 1345000 | D22: 1011260.2 | E22: 1345000 | F22: 316435 | G22: 920971.9 | H22: 604536.9 | I22: =H22 -> 604536.9
A23: WSWT2025650 | B23: บจก.เอเชียเหมืองแร่ | C23: 20000 | D23: 21000 | E23: 20000 | F23: 0 | G23: 18719.8 | H23: 18719.8
A24: WSWT2025650 ผลรวม | C24: 20000 | D24: 21000 | E24: 20000 | F24: 0 | G24: 18719.8 | H24: 18719.8 | I24: =H24 -> 18719.8
A25: WSWT2025800 | B25: บจก.เบทาโกร | C25: 143000 | D25: 0 | E25: 124 | F25: 0 | G25: 0 | H25: 0
B26: บจก.อินเทคค์ โกลบอล | C26: 100640 | D26: 105000 | E26: 100640 | F26: 97126 | G26: 104775 | H26: 7649 | I26: =H26 -> 7649
A27: WSWT2025800 ผลรวม | C27: 243640 | D27: 105000 | E27: 100764 | F27: 97126 | G27: 104775 | H27: 7649
A28: WSWT2025800SM | B28: บจก.ไทยธรรมดี | C28: 40000 | D28: 42000 | E28: 40000 | F28: 0 | G28: 43027.6 | H28: 43027.6 | I28: =H28 -> 43027.6
B29: บจก.อินเทคค์ โกลบอล | C29: 169508 | D29: 146629.35 | E29: 168200 | F29: 37778.722 | G29: 147834.38 | H29: 110055.66 | I29: =H29 -> 110055.66
B30: บจก.เอพีเอ็ม อะโกร | C30: 12000 | D30: 9450 | E30: 12000 | F30: 0 | G30: 9932.67 | H30: 9932.67 | I30: =H30 -> 9932.67
B31: บจก.เอสพีเอ็ม อาหารสัตว์ | C31: 30500 | D31: 26250 | E31: 25000 | F31: 5111 | G31: 27590.75 | H31: 22479.75 | P31: 15000 | Q31: =+K31/P31 -> 0
B32: บจก.เอ.เจ.ฟาร์ม่าแล็บ | C32: 20000 | D32: 21000 | E32: 20000 | F32: 19837.4 | G32: 19837.4 | H32: 0 | I32: =H32 -> 0
B33: คุณชายชล จันทร์สว่างกูล | C33: 11500 | D33: 12075 | E33: 11500 | F33: 0 | G33: 11406.505 | H33: 11406.505 | I33: =H33 -> 11406.505
B34: บจก.มารีน หรีดเดอร์ | C34: 10000 | D34: 10500 | E34: 10000 | F34: 0 | G34: 8801.1 | H34: 8801.1 | I34: =H34 -> 8801.1
A35: WSWT2025800SM ผลรวม | C35: 293508 | D35: 267904.35 | E35: 286700 | F35: 62727.122 | G35: 268430.41 | H35: 205703.29 | I35: =H35 -> 205703.29
A36: WSWT2121670SM | B36: บจก.ที.ซี.ยูเนี่ยน อโกรเทค | C36: 24000 | D36: 25200 | E36: 24000 | F36: 0 | G36: 25816.56 | H36: 25816.56 | I36: =H36 -> 25816.56
B37: บจก.เอพีเอ็ม อะโกร | C37: 28000 | D37: 29400 | E37: 28000 | F37: 0 | G37: 31739.84 | H37: 31739.84 | I37: =H37 -> 31739.84
B38: บจก.แอมโก้เวท | C38: 310000 | D38: 315504 | E38: 310000 | F38: 45721.128 | G38: 325400.53 | H38: 279679.4 | I38: =H38 -> 279679.4
A39: WSWT2121670SM ผลรวม | C39: 362000 | D39: 370104 | E39: 362000 | F39: 45721.128 | G39: 382956.93 | H39: 337235.8 | I39: =H39 -> 337235.8
A40: WSWT2125650 | B40: บจก.หนองบัวฟีดมิลล์ | C40: 5000 | D40: 0 | E40: 5000 | F40: 0 | G40: 5518.15 | H40: 5518.15 | I40: =H40 -> 5518.15
B41: บจก.ไลม์มาสเตอร์ | C41: 10000 | D41: 10500 | E41: 10000 | F41: 0 | G41: 9918.7 | H41: 9918.7
...

Sheet 6(Order)
A2: เลขที่ SO | B2: (หลายรายการ)
A3: วันส่ง | B3: (หลายรายการ)
A4: ชื่อลูกค้า | B4: (ทั้งหมด)
A6: ประเภท | B6: ผลรวม ของ จำนวนส่ง | C6: ผลรวม ของ ค้างพิมพ์ | D6: ผลรวม ของ ค้างตัด | E6: ผลรวม ของ ใช้ | F6: ผลรวม ของ Stock | G6: ผลรวม ของ ค้างทอ
A7: WSWT1625800 | B7: 5000 | C7: 5250 | D7: 5000 | E7: 3702.05 | F7: 3702.05 | G7: 0
A8: WSWT1825800SM | B8: 15000 | C8: 15750 | D8: 15000 | E8: 13201.65 | F8: 13201.65 | G8: 0
A9: WSWT1921720 | B9: 135000 | C9: 82645.5 | D9: 134000 | E9: 98033.309 | F9: 3428.4685 | G9: 94604.84
A10: WSWT1925800 | B10: 30000 | C10: 31500 | D10: 30000 | E10: 24726.9 | F10: 22584 | G10: 2142.9
A11: WSWT1925800SM | B11: 20000 | C11: 0 | D11: 20000 | E11: 0 | F11: 0 | G11: 0 | L11: =76*2500 -> 190000
A12: WSWT2021850UV | B12: 1345000 | C12: 258829.2 | D12: 385000 | E12: 235720.15 | F12: 96032.176 | G12: 139687.98
A13: WSWT2025800 | B13: 155640 | C13: 15818.25 | D13: 145640 | E13: 15719.306 | F13: 15719.306 | G13: 0
A14: WSWT2025800SM | B14: 72918 | C14: 32804.1 | D14: 72242 | E14: 32733.806 | F14: 32733.806 | G14: 0
A15: WSWT2121670SM | B15: 165000 | C15: 157500 | D15: 165000 | E15: 161353.5 | F15: 67292.5 | G15: 94061
A16: WSWT2221940 | B16: 239700 | C16: 0 | D16: 60700 | E16: 0 | F16: 0 | G16: 0
A17: WSWT2321112512551 | B17: 108000 | C17: 48384 | D17: 100080 | E17: 49567.795 | F17: 7500 | G17: 42067.795
A18: WSWT2325650 | B18: 5000 | C18: 5250 | D18: 5000 | E18: 5518.15 | F18: 5518.15 | G18: 0
A19: WSWT262575051 | B19: 5000 | C19: 0 | D19: 0 | E19: 0 | F19: 0 | G19: 0
A20: WSWT2625850SM | B20: 40000 | C20: 10500 | D20: 40000 | E20: 49733.2 | F20: 49733.2 | G20: 0
A21: WSWT2825850 | B21: 50000 | C21: 0 | D21: 41661 | E21: 0 | F21: 0 | G21: 0
A22: ผลรวมทั้งหมด | B22: 2391258 | C22: 664231.05 | D22: 1219323 | E22: 690009.82 | F22: 317445.31 | G22: 372564.51
A37: ยอดส่ง 1/1/68 - 17/1/68 | B37: 1287052
A38: Order+ส่ง | B38: =++B22+B37 -> 3678310
A39: ประมาณการ | I39: 0
A41: Order+ส่ง+ประมาณการ | B41: =+B22+B37+B39+B29 -> 3678310 | C41: =+C22+C37+C39+C29 -> 664231.05 | D41: =+D22+D37+D39+D29 -> 1219323 | E41: =+E22+E37+E39+E29 -> 690009.82 | F41: =+F22+F37+F39+F29 -> 317445.31 | G41: =+G22+G37+G39+G29 -> 372564.51
B43: 3000000 | I43: 9
B45: =+B41-B43 -> 678310
D46: =+D22/I43 -> 135480.33
C47: =+C41/I43 -> 73803.45 | D47: =+D41/I43 -> 135480.33 | G47: =+G41/I43 -> 41396.057

Sheet 6(Order) แยกลูกค้า
A1: เลขที่ SO | B1: (หลายรายการ)
A2: วันส่ง | B2: (หลายรายการ)
A4: ประเภท | B4: ชื่อลูกค้า | C4: ผลรวม ของ จำนวนส่ง | D4: ผลรวม ของ ค้างพิมพ์ | E4: ผลรวม ของ ค้างตัด | F4: ผลรวม ของ Stock | G4: ผลรวม ของ ค้างทอ | I4: vn
A5: WSWT1621720SMFX | B5: โรงสีลิ้มย่งฮวด | C5: 5000 | D5: 0 | E5: 5000 | F5: 0 | G5: 0 | H5: =G5 -> 0
A6: WSWT1621720SMFX ผลรวม | C6: 5000 | D6: 0 | E6: 5000 | F6: 0 | G6: 0 | H6: =G6 -> 0
A7: WSWT1825800SM | B7: บจก.ซิเบลโก้(บางเลน) | C7: 15000 | D7: 15750 | E7: 15000 | F7: 13201.65 | G7: 0 | H7: =G7 -> 0
A8: WSWT1825800SM ผลรวม | C8: 15000 | D8: 15750 | E8: 15000 | F8: 13201.65 | G8: 0
A9: WSWT1921720 | B9: บจก.เคอรี่ฟลาวมิลล์ | C9: 165000 | D9: 89250 | E9: 139778 | F9: 8801.1 | G9: 94046.04 | H9: =G9 -> 94046.04
A10: WSWT1921720 ผลรวม | C10: 165000 | D10: 89250 | E10: 139778 | F10: 8801.1 | G10: 94046.04 | H10: =G10 -> 94046.04
A11: WSWT1925800 | B11: บจก.ซีแมนอินดัสตรี | C11: 30000 | D11: 31500 | E11: 30000 | F11: 17584 | G11: 7142.9
A12: WSWT1925800 ผลรวม | C12: 30000 | D12: 31500 | E12: 30000 | F12: 17584 | G12: 7142.9 | H12: =G12 -> 7142.9
A13: WSWT1925800SM | B13: บจก.ไมโครอินโนเวท | C13: 20000 | D13: 0 | E13: 20000 | F13: 0 | G13: 0 | H13: =G13 -> 0
A14: WSWT1925800SM ผลรวม | C14: 20000 | D14: 0 | E14: 20000 | F14: 0 | G14: 0 | H14: =G14 -> 0
A15: WSWT2021850UV | B15: กองระบบท่อระบายน้ำสำนักการระบายน้ำ | C15: 1345000 | D15: 458403.75 | E15: 505000 | F15: 144227.54 | G15: 273248.55
A16: WSWT2021850UV ผลรวม | C16: 1345000 | D16: 458403.75 | E16: 505000 | F16: 144227.54 | G16: 273248.55 | H16: =G16 -> 273248.55
A17: WSWT2025650 | B17: บจก.เอเชียเหมืองแร่ | C17: 20000 | D17: 0 | E17: 20000 | F17: 0 | G17: 0
A18: WSWT2025650 ผลรวม | C18: 20000 | D18: 0 | E18: 20000 | F18: 0 | G18: 0 | H18: =G18 -> 0
A19: WSWT2025800 | B19: บจก.เคอรี่ฟลาวมิลล์ | C19: 5000 | D19: 5250 | E19: 5000 | F19: 4679.95 | G19: 0 | H19: =G19 -> 0
B20: บจก.เบทาโกร | C20: 100000 | D20: 0 | E20: 90000 | F20: 0 | G20: 0 | H20: =G20 -> 0
B21: บจก.อินเทคค์ โกลบอล | C21: 110640 | D21: 116172 | E21: 110640 | F21: 112177 | G21: 3746.06 | H21: =G21 -> 3746.06
B22: Lao-Thai German Starch Co.,Ltd | C22: 25000 | D22: 0 | E22: 25000 | F22: 0 | G22: 0
A23: WSWT2025800 ผลรวม | C23: 240640 | D23: 121422 | E23: 230640 | F23: 116856.95 | G23: 3746.06 | H23: =G23 -> 3746.06
A24: WSWT2025800SM | B24: บจก.อินเทคค์ โกลบอล | C24: 39131 | D24: 32804.1 | E24: 37615 | F24: 32733.806 | G24: 0
B25: บจก.เอพีเอ็ม อะโกร | C25: 6000 | D25: 6300 | E25: 6000 | F25: 6621.78 | G25: 0 | H25: =G25 -> 0
B26: บจก.เอ.เจ.ฟาร์ม่าแล็บ | C26: 16000 | D26: 0 | E26: 160 | F26: 0 | G26: 0
B27: บจก.มารีน หรีดเดอร์ | C27: 10000 | D27: 0 | E27: 0 | F27: 0 | G27: 0 | H27: =G27 -> 0
B28: บจก.วีซีเอฟ | C28: 55000 | D28: 8792.7 | E28: 55000 | F28: 9189.297 | G28: 0 | H28: =G28 -> 0
A29: WSWT2025800SM ผลรวม | C29: 126131 | D29: 47896.8 | E29: 98775 | F29: 48544.882 | G29: 0 | H29: =G29 -> 0
A30: WSWT2121670SM | B30: บจก.ที.ซี.ยูเนี่ยน อโกรเทค | C30: 8000 | D30: 8400 | E30: 8000 | F30: 0 | G30: 8605.52
B31: บจก.เอพีเอ็ม อะโกร | C31: 11000 | D31: 0 | E31: 11000 | F31: 0 | G31: 0 | H31: =G31 -> 0
B32: บจก.เอสพีเอ็ม อาหารสัตว์ | C32: 5000 | D32: 0 | E32: 232 | F32: 0 | G32: 0 | H32: =G32 -> 0
B33: บจก.หนองบัวฟีดมิลล์ | C33: 10000 | D33: 10500 | E33: 10000 | F33: 10756.9 | G33: 0 | H33: =G33 -> 0
B34: คุณนพวินทร์ รัตนเศรษฐ์เมธา | C34: 5000 | D34: 0 | E34: 288 | F34: 0 | G34: 0 | H34: =G34 -> 0
B35: บจก.บลูฟาโล่ | C35: 13000 | D35: 0 | E35: 13000 | F35: 0 | G35: 0 | H35: =G35 -> 0
A36: WSWT2121670SM ผลรวม | C36: 52000 | D36: 18900 | E36: 42520 | F36: 10756.9 | G36: 8605.52 | H36: =G36 -> 8605.52
A37: WSWT2221940 | B37: กรมการข้าว | C37: 239700 | D37: 60679.5 | E37: 142800 | F37: 51990 | G37: 8196.1757 | H37: =G37 -> 8196.1757
A38: WSWT2221940 ผลรวม | C38: 239700 | D38: 60679.5 | E38: 142800 | F38: 51990 | G38: 8196.1757 | H38: =G38 -> 8196.1757
A39: WSWT2321112512551 | B39: บจก.น้ำตาลทิพย์สุโขทัย | C39: 155393 | D39: 57723.75 | E39: 109793 | F39: 1101.2376 | G39: 58087.26 | H39: =G39 -> 58087.26
A40: WSWT2321112512551 ผลรวม | C40: 155393 | D40: 57723.75 | E40: 109793 | F40: 1101.2376 | G40: 58087.26
A41: WSWT2325650 | B41: บจก.ซิเบลโก้(บางเลน) | C41: 5000 | D41: 5250 | E41: 5000 | F41: 5518.15 | G41: 0 | H41: =G41 -> 0
...

Sheet 6(Fc) แยกลูกค้
A1: เลขที่ SO | B1: ประมาณการ
A2: วันส่ง | B2: (หลายรายการ) | D2: 12
A4: ประเภท | B4: ชื่อลูกค้า | C4: ผลรวม ของ จำนวนส่ง | D4: ผลรวม ของ ค้างพิมพ์ | E4: ผลรวม ของ ค้างตัด | F4: ผลรวม ของ Stock | G4: ผลรวม ของ ใช้ | H4: ผลรวม ของ ค้างทอ
A5: ผลรวมทั้งหมด
H41: 296578.28
H43: =+GETPIVOTDATA("ผลรวม ของ ค้างทอ",$A$4)+H41 -> 296578.28
I119: วันทงาน
I120: 12
C121: 1975256 | D121: =+D120*I120 -> 0 | E121: =+E120*I120 -> 0 | F121: 825147 | G121: =+G120*I120 -> 0
A122: เบทาโกรส่งแล้ว | B122: 20700 | C122: 424374
A123: เบทาโกรส่งแล้ว | B123: 20800 | C123: 155973
C126: รวมส่ง+ค้างส่ง | D126: ส่วนต่างCapคงเหลือ | E126: ส่วนต่างCapคงเหลือ | F126: คงเหลือ
C127: =+C50+C121 -> 1975256 | D127: =+D121-D50 -> 0 | E127: =+E121-E50 -> 0 | F127: =+F121-F50 -> 825147 | G127: =+G121-G50 -> 0
B129: 20700VN 20/7 | G129: 350000

Sheet ค้างทอ11-6-68
A3: ผลรวม ของ ค้างทอ
A4: ป้ายชื่อแถว | B4: 45816 | C4: 45817 | D4: 45819 | E4: 45820 | F4: 45821 | G4: 45822 | H4: 45823 | I4: 45824 | J4: 45826 | K4: 45827 | L4: 45828 | M4: 45829 | N4: 45830 | O4: 45833 | P4: ผลรวมทั้งหมด
A5: WSWT1425800 | B5: 1008.9 | P5: =SUM(B5:O5) -> 1008.9
A6: WSWT1621720SMFX | I6: 0 | P6: =SUM(B6:O6) -> 0
A7: WSWT1825800SM | M7: 2801.1 | P7: =SUM(B7:O7) -> 2801.1
A8: WSWT1921720 | C8: 15206.6 | E8: 13117.83 | G8: 40443.15 | H8: 13760.45 | I8: 13201.65 | P8: =SUM(B8:O8) -> 95729.68
A9: WSWT1925800SM | K9: 19837.4 | P9: =SUM(B9:O9) -> 19837.4
A10: WSWT2021850UV | O10: 457803.58 | P10: =SUM(B10:O10) -> 457803.58
A11: WSWT2025650 | H11: 11061.8 | P11: =SUM(B11:O11) -> 11061.8
A12: WSWT2025800 | F12: 0 | G12: 0 | J12: 0 | K12: 0 | O12: 0 | P12: =SUM(B12:O12) -> 0
A13: WSWT2025800SM | B13: 0 | C13: 0 | J13: 0 | N13: 12942.35 | O13: 0 | P13: =SUM(B13:O13) -> 12942.35
A14: WSWT2121670SM | B14: 41753.69 | C14: 0 | D14: 3310.89 | E14: 10756.9 | I14: 10756.9 | J14: 16554.45 | O14: 8605.52 | P14: =SUM(B14:O14) -> 91738.35
A15: WSWT2125650 | D15: 15012.45 | P15: =SUM(B15:O15) -> 15012.45
A16: WSWT2125800 | C16: 0 | P16: =SUM(B16:O16) -> 0
A17: WSWT2221940 | L17: 85100.279 | P17: =SUM(B17:O17) -> 85100.279
A18: WSWT2321112512551 | J18: 0 | N18: 51959.26 | P18: =SUM(B18:O18) -> 51959.26
A19: WSWT2625650 | B19: 5997.321 | P19: =SUM(B19:O19) -> 5997.321
A20: WSWT262575051 | H20: 0 | P20: =SUM(B20:O20) -> 0
A21: WSWT2625800 | E21: 0 | P21: =SUM(B21:O21) -> 0
A22: WSWT2625850SM | E22: 0 | N22: 0 | P22: =SUM(B22:O22) -> 0
A23: WSWT2825850 | D23: 19315.466 | P23: =SUM(B23:O23) -> 19315.466
A24: ผลรวมทั้งหมด | B24: =SUM(B5:B23) -> 48759.911 | C24: =SUM(C5:C23) -> 15206.6 | D24: =SUM(D5:D23) -> 37638.806 | E24: =SUM(E5:E23) -> 23874.73 | F24: =SUM(F5:F23) -> 0 | G24: =SUM(G5:G23) -> 40443.15 | H24: =SUM(H5:H23) -> 24822.25 | I24: =SUM(I5:I23) -> 23958.55 | ... P24: =SUM(P5:P23) -> 870307.93

Sheet 23-6-68
B2: เรียงกำหนดส่ง | D2: ลบ 0 | T2: เรียง 1
B3: ข้อมูลUpdate ณ. วันที่ | D3: 45831 | E3: เวลา | G3: 11.43
A4: วันรับออร์เดอร์/แบบ | B4: เลขที่ SO | C4: ชื่อลูกค้า | E4: 10.3 | I4: น้ำหนัก | L4: บิด/จับจีบ | M4: ถุงใน | Q4: 44873 | S4: วิธีบรรจุ | T4: วันส่ง | U4: จำนวนส่ง | V4: ตัดเย็บ (ใบ) | W4: 44873 | X4: พิมพ์ (ใบ) | Y4: 44876 | Z4: ผ้าทอ (เมตร) Updateณ | AB4: 44876 | AD4: ผ้าเคลือบ(เมตร) | AF4: หมายเหตุ | AG4: เครื่อง
B5: เลขที่ SO | C5: ชื่อลูกค้า | D5: ตรา | E5: กว้าง | F5: ยาว | G5: สี | H5: เคลือบ | I5: กรัม/ใบ | J5: * | K5: aw | L5: บิด/จับจีบ | M5: กว้าง | N5: ยาว | O5: หนา | P5: ใช้(กก.) | Q5: Stock(กก.) | R5: ผลิต(กก.) | S5: วิธีบรรจุ | T5: วันส่ง | U5: จำนวนส่ง | V5: StockFG | W5: ค้างตัด | X5: พิมพ์แล้ว | Y5: ค้างพิมพ์ | Z5: ประเภท | AA5: ใช้ | AB5: Stock | AC5: ค้างทอ | AD5: Stock | AE5: ค้างเคลือบ | AF5: หมายเหตุ | AG5: ที่พิมพ์ได้ | AH5: process | AI5: Lead time | AJ5: วันที่ส่งPL | AK5: เคลือบ | AL5: ได้ ART | AM5: พิมพ์ | AN5: จีบ-บิด | AO5: ตัด-เย็บ | AP5: ทอ | AQ5: สวมถุง | AR5: เย็บปาก | AS5: PT | AT5: ม้วน | AU5: ตัด | AV5: ตอกตาไก่ | AW5: GROUP | AX5: ART | AY5: หมายเหตุปัญหา | AZ5: ราคา/ใบ | BA5: ราคารวม | BB5: workweek | BC5: เส้นเทป | BD5: จำนวน
A6: ประมาณการ | B6: ประมาณการ | C6: บจก.ซัน ซีเมนต์ โพรเซส | D6: พระอาทิตย์(ปูนนอน-ชริงค์) | E6: 16 | F6: 25 | G6: ขาว | H6: ใส | I6: 50 | J6: ± | K6: 5 | L6: บิด | M6: 19 | N6: 28 | O6: 40 | P6: 65.624643 | Q6: 0 | R6: 65.624643 | S6: 500กระสอบ | T6: 45868 | U6: 5000 | V6: 0 | W6: 5000 | X6: 0 | Y6: 5250 | Z6: WSWT1625800SM | AA6: 3702.05 | AB6: 3372 | AC6: 330.05 | AD6: 0 | AE6: 3702.05 | AF6: 0 | AG6: พร้อมส่ง | AH6: P8 | AI6: 4 | AJ6: 45868 | AK6: 45864 | AL6: 45858 | AM6: 45865 | AN6: 45866 | AO6: 45866 | AP6: 45863 | AQ6: 45867 | AR6: 0 | AS6: 0 | AT6: 0 | AU6: 0 | AV6: 0 | AW6: งานเคลือบ+พิมพ์ | AX6: รอART | AY6: 0 | AZ6: 0 | BA6: 0 | BB6: 0 | BC6: WRWT25800/WRWT25800 | BD6: 18.776178
A7: 0 | B7: 0 | C7: 0 | E7: 16 | F7: 25 | G7: ขาว | H7: 0 | I7: 45 | J7: ± | K7: 5 | L7: 0 | M7: 0 | N7: 0 | O7: 0 | P7: 0 | Q7: 0 | R7: 0 | S7: 0 | U7: 0 | V7: 0 | W7: 0 | X7: 0 | Y7: 0 | Z7: WSWT1625800SM | AA7: 3702.05 | AB7: 3372 | AC7: 330.05 | AD7: 0 | AE7: 3702.05 | AF7: ระบุในSD | AG7: พร้อมส่ง | AH7: 0 | AI7: Lead time | AJ7: 0 | AK7: 0 | AL7: 0 | AM7: 0 | AN7: 0 | AO7: 0 | AP7: 0 | AQ7: 0 | AR7: 0 | AS7: 0 | AT7: 0 | AU7: 0 | AV7: 0 | AW7: 0 | AX7: 0 | AY7: 0 | AZ7: 0 | BA7: 0 | BB7: 0 | BC7: WRWT160800/WRWT25800 | BD7: 0
A8: 45827 | B8: MK68-000809 | C8: บจก.เคอรี่ฟลาวมิลล์ | D8: โบว์แดง 10กก | E8: 16 | F8: 25 | G8: ขาว | H8: 0 | I8: 45 | J8: ± | K8: 5 | L8: ไม่ | M8: ไม่สวมถุงใน | N8: 0 | O8: 0 | P8: 0 | Q8: 0 | R8: 0 | S8: ห่ออัดเบลแบน500 | T8: 45836 | U8: 5000 | V8: 0 | W8: 5000 | X8: 0 | Y8: 5250 | Z8: WSWT1625800 | AA8: 3702.05 | AB8: 3702.05 | AC8: 0 | AD8: 0 | AE8: 0 | AF8: 0 | AG8: พร้อมส่ง | AH8: P7 | AI8: 2 | AJ8: 45836 | AK8: 0 | AL8: 45827 | AM8: 45834 | AN8: 45835 | AO8: 45835 | AP8: 45831 | AQ8: 0 | AR8: 0 | AS8: 0 | AT8: 0 | AU8: 0 | AV8: 0 | AW8: งานพิมพ์ | AX8: 0 | AY8: 0 | AZ8: 0 | BA8: 0 | BB8: 0 | BC8: WRWT25800/WRWT25800 | BD8: 0
A9: 0 | B9: 0 | C9: 0 | D9: 0 | E9: 16 | F9: 25 | G9: ขาว | H9: 0 | I9: 45 | J9: ± | K9: 5 | L9: 0 | M9: 0 | N9: 0 | O9: 0 | P9: 0 | Q9: 0 | R9: 0 | S9: 0 | U9: 0 | V9: 0 | W9: 0 | X9: 0 | Y9: 0 | Z9: WSWT1625800 | AA9: 3702.05 | AB9: 3702.05 | AC9: 0 | AD9: 0 | AE9: 0 | AF9: ระบุในSD | AG9: ยังไม่ได้พิมพ์ | AH9: 0 | AI9: Lead time | AJ9: 0 | AK9: 0 | AL9: 0 | AM9: 0 | AN9: 0 | AO9: 0 | AP9: 0 | AQ9: 0 | AR9: 0 | AS9: 0 | AT9: 0 | AU9: 0 | AV9: 0 | AW9: 0 | AX9: 0 | AY9: 0 | AZ9: 0 | BA9: 0 | BB9: 0 | BC9: WRWT160800/WRWT25800 | BD9: 0
A10: ประมาณการ | B10: ประมาณการ | C10: บจก.ฟาร์เธอร์ส วิง ซัพพลาย | D10: รถไฟ | E10: 18 | F10: 30 | G10: ขาว | H10: 0 | I10: 54 | J10: ± | K10: 5 | L10: บิด | M10: 19 | N10: 33 | O10: 40 | P10: 232.02999 | Q10: 0 | R10: 232.02999 | S10: 500กระสอบ | T10: 45868 | U10: 15000 | V10: 0 | W10: 15000 | X10: 0 | Y10: 15750 | Z10: WSWT1825800 | AA10: 13201.65 | AB10: 6301 | AC10: 6900.65 | AD10: 0 | AE10: 0 | AF10: 0 | AG10: ยังไม่ได้พิมพ์ | AH10: P9 | AI10: 3 | AJ10: 45868 | AK10: 0 | AL10: 45858 | AM10: 45865 | AN10: 45866 | AO10: 45866 | AP10: 45863 | AQ10: 45867 | AR10: 0 | AS10: 0 | AT10: 0 | AU10: 0 | AV10: 0 | AW10: งานพิมพ์ | AX10: รอART | AY10: 0 | AZ10: 0 | BA10: 0 | BB10: 0 | BC10: WRWT25800/WRWT25800 | BD10: 474.76472
A11: 0 | B11: 0 | E11: 18 | F11: 30 | G11: ขาว | H11: 0 | I11: 54 | J11: ± | K11: 5 | L11: 0 | M11: 0 | N11: 0 | O11: 0 | P11: 0 | Q11: 0 | R11: 0 | S11: 0 | U11: 0 | V11: 0 | W11: 0 | X11: 0 | Y11: 0 | Z11: WSWT1825800 | AA11: 13201.65 | AB11: 6301 | AC11: 6900.65 | AD11: 0 | AE11: 0 | AF11: ระบุในSD | AG11: พร้อมส่ง | AH11: 0 | AI11: Lead time | AJ11: 0 | AK11: 0 | AL11: 0 | AM11: 0 | AN11: 0 | AO11: 0 | AP11: 0 | AQ11: 0 | AR11: 0 | AS11: 0 | AT11: 0 | AU11: 0 | AV11: 0 | AW11: 0 | AX11: 0 | AY11: 0 | AZ11: 0 | BA11: 0 | BB11: 0 | BC11: WRWT25800/WRWT25800 | BD11: 0
A12: 45797 | B12: MK68-000687 | C12: บจก.ซิเบลโก้(บางเลน) | D12: PORTARYTE | E12: 18 | F12: 30 | G12: ขาว | H12: ใส | I12: 74 | J12: ± | K12: 5 | L12: ไม่ | M12: ไม่สวมถุงใน | N12: 0 | O12: 0 | P12: 0 | Q12: 0 | R12: 0 | S12: 500กระสอบ | T12: 45834 | U12: 10000 | V12: 0 | W12: 10000 | X12: 0 | Y12: 10500 | Z12: WSWT1825800SM | AA12: 8801.1 | AB12: 8801.1 | AC12: 0 | AD12: 0 | AE12: 8801.1 | AF12: ห้ามเกิน-ขาดได้5% | AG12: ยังไม่ได้พิมพ์ | AH12: P6 | AI12: 4 | AJ12: 45834 | AK12: 45830 | AL12: 45823 | AM12: 45831 | AN12: 45832 | AO12: 45833 | AP12: 45829 | AQ12: 0 | AR12: 0 | AS12: 0 | AT12: 0 | AU12: 0 | AV12: 0 | AW12: งานเคลือบ+พิมพ์ | AX12: / | AY12: 0 | AZ12: 0 | BA12: 0 | BB12: 0 | BC12: WRWT25800/WRWT25800 | BD12: 0
A13: 45824 | B13: MK68-000794 | C13: บจก.ซิเบลโก้(บางเลน) | D13: FELDSPAR K200BL | E13: 18 | F13: 30 | G13: ขาว | H13: ใส | I13: 74 | J13: ± | K13: 5 | L13: ไม่ | M13: ไม่สวมถุงใน | N13: 0 | O13: 0 | P13: 0 | Q13: 0 | R13: 0 | S13: 500กระสอบ | T13: 45834 | U13: 5000 | V13: 0 | W13: 5000 | X13: 0 | Y13: 5250 | Z13: WSWT1825800SM | AA13: 4400.55 | AB13: 4400.55 | AC13: 0 | AD13: 0 | AE13: 4400.55 | AF13: ห้ามเกิน-ขาดได้5% | AG13: ยังไม่ได้พิมพ์ | AH13: P6 | AI13: 4 | AJ13: 45834 | AK13: 45830 | AL13: 45823 | AM13: 45831 | AN13: 45832 | AO13: 45833 | AP13: 45829 | AQ13: 0 | AR13: 0 | AS13: 0 | AT13: 0 | AU13: 0 | AV13: 0 | AW13: งานเคลือบ+พิมพ์ | AX13: / | AY13: 0 | AZ13: 0 | BA13: 0 | BB13: 0 | BC13: WRWT25800/WRWT25800 | BD13: 0
A14: 0 | B14: 0 | C14: 0 | E14: 18 | F14: 25 | G14: ขาว | H14: 0 | I14: 50 | J14: ± | K14: 5 | L14: 0 | M14: 0 | N14: 0 | O14: 0 | P14: 0 | Q14: 0 | R14: 0 | S14: 0 | U14: 0 | V14: 0 | W14: 0 | X14: 0 | Y14: 0 | Z14: WSWT1825800SM | AA14: 13201.65 | AB14: 13201.65 | AC14: 0 | AD14: 0 | AE14: 13201.65 | AF14: ระบุในSD | AG14: ยังไม่ได้พิมพ์ | AH14: 0 | AI14: Lead time | AJ14: 0 | AK14: 0 | AL14: 0 | AM14: 0 | AN14: 0 | AO14: 0 | AP14: 0 | AQ14: 0 | AR14: 0 | AS14: 0 | AT14: 0 | AU14: 0 | AV14: 0 | AW14: 0 | AX14: 0 | AY14: 0 | AZ14: 0 | BA14: 0 | BB14: 0 | BC14: WRWT180800/WRWT25800 | BD14: 0
