Workbook

Sheet Linkสูตรออร์เดอร์  (2)
B2: เรียงกำหนดส่ง | D2: ลบ 0 | T2: เรียง 1
B3: ข้อมูลUpdate ณ. วันที่ | D3: 45818 | E3: เวลา | G3: 11.04
A4: วันรับออร์เดอร์/แบบ | B4: เลขที่ SO | C4: ชื่อลูกค้า | E4: 10.3 | I4: น้ำหนัก | L4: บิด/จับจีบ | M4: ถุงใน | Q4: =[1]หน้าผ้า!$AC$13 -> 44873 | S4: วิธีบรรจุ | T4: วันส่ง | U4: จำนวนส่ง | V4: ตัดเย็บ (ใบ) | W4: =[1]หน้าผ้า!$AJ$13 -> 44873 | X4: พิมพ์ (ใบ) | Y4: =[1]หน้าผ้า!$AM$13 -> 44876 | Z4: ผ้าทอ (เมตร) Updateณ | AB4: =[1]หน้าผ้า!$AR$12 -> 44876 | AD4: ผ้าเคลือบ(เมตร) | AF4: หมายเหตุ | AG4: เครื่อง
B5: เลขที่ SO | C5: ชื่อลูกค้า | D5: ตรา | E5: กว้าง | F5: ยาว | G5: สี | H5: เคลือบ | I5: กรัม/ใบ | J5: * | K5: aw | L5: บิด/จับจีบ | M5: กว้าง | N5: ยาว | O5: หนา | P5: ใช้(กก.) | Q5: Stock(กก.) | R5: ผลิต(กก.) | S5: วิธีบรรจุ | T5: วันส่ง | U5: จำนวนส่ง | V5: StockFG | W5: ค้างตัด | X5: พิมพ์แล้ว | Y5: ค้างพิมพ์ | Z5: ประเภท | AA5: ใช้ | AB5: Stock | AC5: ค้างทอ | AD5: Stock | AE5: ค้างเคลือบ | AF5: หมายเหตุ | AG5: ที่พิมพ์ได้ | AH5: process | AI5: Lead time | AJ5: วันที่ส่งPL | AK5: เคลือบ | AL5: ได้ ART | AM5: พิมพ์ | AN5: จีบ-บิด | AO5: ตัด-เย็บ | AP5: ทอ | AQ5: สวมถุง | AR5: เย็บปาก | AS5: PT | AT5: ม้วน | AU5: ตัด | AV5: ตอกตาไก่ | AW5: GROUP | AX5: ART | AY5: หมายเหตุปัญหา | AZ5: ราคา/ใบ | BA5: ราคารวม | BB5: workweek | BC5: เส้นเทป | BD5: จำนวน
A6: =[2]หน้าผ้า!C15 -> 0 | B6: =[2]หน้าผ้า!B15 -> 0 | C6: =[2]หน้าผ้า!E15 -> 0 | D6: =[2]หน้าผ้า!F15 -> 0 | E6: =[2]หน้าผ้า!G15 -> 12 | F6: =[2]หน้าผ้า!H15 -> 16 | G6: =[2]หน้าผ้า!I15 -> ขาว | H6: =[2]หน้าผ้า!J15 -> 0 | I6: =[2]หน้าผ้า!L15 -> 25 | J6: =[2]หน้าผ้า!M15 -> ± | K6: =[2]หน้าผ้า!N15 -> 5 | L6: =[2]หน้าผ้า!R15 -> 0 | M6: =[2]หน้าผ้า!T15 -> 0 | N6: =[2]หน้าผ้า!U15 -> 0 | O6: =[2]หน้าผ้า!V15 -> 0 | P6: =[2]หน้าผ้า!AB15 -> 0 | Q6: =[2]หน้าผ้า!AC15 -> 0 | R6: =[2]หน้าผ้า!AD15 -> 0 | S6: =[2]หน้าผ้า!Z15 -> 0 | T6: =[2]หน้าผ้า!X15 -> 0 | U6: =[2]หน้าผ้า!AA15 -> 0 | V6: =[2]หน้าผ้า!AJ15 -> 0 | W6: =[2]หน้าผ้า!AL15 -> 0 | X6: =[2]หน้าผ้า!AM15 -> 0 | Y6: =[2]หน้าผ้า!AN15 -> 0 | Z6: =[2]หน้าผ้า!AO15 -> WSWT1221750 | AA6: =[2]หน้าผ้า!AQ15 -> #REF! | AB6: =[2]หน้าผ้า!AR15 -> #REF! | AC6: =[2]หน้าผ้า!AS15 -> #REF! | AD6: =[2]หน้าผ้า!AT15 -> #REF! | AE6: =[2]หน้าผ้า!AU15 -> #REF! | AF6: =[2]หน้าผ้า!AI15 -> ระบุในSD | AG6: =[3]หน้าผ้า!DC18 -> < Ord 20,000 | AH6: =[2]หน้าผ้า!DL15 -> 0 | AI6: =[2]หน้าผ้า!DM15 -> 0 | AJ6: =[2]หน้าผ้า!DN15 -> 0 | AK6: =[2]หน้าผ้า!DQ15 -> 0 | AL6: =[2]หน้าผ้า!DR15 -> 0 | AM6: =[2]หน้าผ้า!DS15 -> 0 | AN6: =[2]หน้าผ้า!DT15 -> 0 | AO6: =[2]หน้าผ้า!DU15 -> 0 | AP6: =[2]หน้าผ้า!DP15 -> 0 | AQ6: =[2]หน้าผ้า!DW15 -> 0 | AR6: =[2]หน้าผ้า!DX15 -> 0 | AS6: =[2]หน้าผ้า!DY15 -> 0 | AT6: =[2]หน้าผ้า!DZ15 -> 0 | AU6: =[2]หน้าผ้า!EA15 -> 0 | AV6: =[2]หน้าผ้า!EB15 -> 0 | AW6: =[2]หน้าผ้า!EC15 -> 0 | AX6: =[2]หน้าผ้า!ED15 -> 0 | AY6: =[2]หน้าผ้า!AG15 -> 0 | AZ6: =[2]หน้าผ้า!EG15 -> 0 | BA6: =[2]หน้าผ้า!EH15 -> 0 | BB6: =[2]หน้าผ้า!EI15 -> 0 | BC6: =[2]หน้าผ้า!BZ15 -> WRWT120750/WRWT21750 | BD6: =[2]หน้าผ้า!CA15 -> 0
A7: =[2]หน้าผ้า!C16 -> 45800 | B7: =[2]หน้าผ้า!B16 -> MK68-000701 | C7: =[2]หน้าผ้า!E16 -> หจก.ปึงเป้งน้ำ | D7: =[2]หน้าผ้า!F16 -> เกลือตรามือ 10กก | E7: =[2]หน้าผ้า!G16 -> 14 | F7: =[2]หน้าผ้า!H16 -> 22 | G7: =[2]หน้าผ้า!I16 -> ขาว | H7: =[2]หน้าผ้า!J16 -> ใส | I7: =[2]หน้าผ้า!L16 -> 42 | J7: =[2]หน้าผ้า!M16 -> ± | K7: =[2]หน้าผ้า!N16 -> 5 | L7: =[2]หน้าผ้า!R16 -> ไม่ | M7: =[2]หน้าผ้า!T16 -> ไม่สวมถุงใน | N7: =[2]หน้าผ้า!U16 -> 0 | O7: =[2]หน้าผ้า!V16 -> 0 | P7: =[2]หน้าผ้า!AB16 -> 0 | Q7: =[2]หน้าผ้า!AC16 -> 0 | R7: =[2]หน้าผ้า!AD16 -> 0 | S7: =[2]หน้าผ้า!Z16 -> 500กระสอบแบนเต็มใบ | T7: =[2]หน้าผ้า!X16 -> 45821 | U7: =[2]หน้าผ้า!AA16 -> 10000 | V7: =[2]หน้าผ้า!AJ16 -> 0 | W7: =[2]หน้าผ้า!AL16 -> 10000 | X7: =[2]หน้าผ้า!AM16 -> 0 | Y7: =[2]หน้าผ้า!AN16 -> 10500 | Z7: =[2]หน้าผ้า!AO16 -> WSWT1425800 | AA7: =[2]หน้าผ้า!AQ16 -> 6565.9 | AB7: =[2]หน้าผ้า!AR16 -> 5557 | AC7: =[2]หน้าผ้า!AS16 -> 1008.9 | AD7: =[2]หน้าผ้า!AT16 -> 1220 | AE7: =[2]หน้าผ้า!AU16 -> 5345.9 | AF7: =[2]หน้าผ้า!AI16 -> 0 | AG7: =[3]หน้าผ้า!DC19 -> พร้อมส่ง | AH7: =[2]หน้าผ้า!DL16 -> P6 | AI7: =[2]หน้าผ้า!DM16 -> 4 | AJ7: =[2]หน้าผ้า!DN16 -> 45821 | AK7: =[2]หน้าผ้า!DQ16 -> 45817 | AL7: =[2]หน้าผ้า!DR16 -> 45810 | AM7: =[2]หน้าผ้า!DS16 -> 45818 | AN7: =[2]หน้าผ้า!DT16 -> 45819 | AO7: =[2]หน้าผ้า!DU16 -> 45820 | AP7: =[2]หน้าผ้า!DP16 -> 45816 | AQ7: =[2]หน้าผ้า!DW16 -> 0 | AR7: =[2]หน้าผ้า!DX16 -> 0 | AS7: =[2]หน้าผ้า!DY16 -> 0 | AT7: =[2]หน้าผ้า!DZ16 -> 0 | AU7: =[2]หน้าผ้า!EA16 -> 0 | AV7: =[2]หน้าผ้า!EB16 -> 0 | AW7: =[2]หน้าผ้า!EC16 -> งานเคลือบ+พิมพ์ | AX7: =[2]หน้าผ้า!ED16 -> / | AY7: =[2]หน้าผ้า!AG16 -> 0 | AZ7: =[2]หน้าผ้า!EG16 -> 0 | BA7: =[2]หน้าผ้า!EH16 -> 0 | BB7: =[2]หน้าผ้า!EI16 -> 0 | BC7: =[2]หน้าผ้า!BZ16 -> WRWT25800/WRWT25800 | BD7: =[2]หน้าผ้า!CA16 -> 56.4984
A8: =[2]หน้าผ้า!C17 -> 0 | B8: =[2]หน้าผ้า!B17 -> 0 | C8: =[2]หน้าผ้า!E17 -> 0 | D8: =[2]หน้าผ้า!F17 -> 0 | E8: =[2]หน้าผ้า!G17 -> 14 | F8: =[2]หน้าผ้า!H17 -> 22 | G8: =[2]หน้าผ้า!I17 -> ขาว | H8: =[2]หน้าผ้า!J17 -> 0 | I8: =[2]หน้าผ้า!L17 -> 36 | J8: =[2]หน้าผ้า!M17 -> ± | K8: =[2]หน้าผ้า!N17 -> 5 | L8: =[2]หน้าผ้า!R17 -> 0 | M8: =[2]หน้าผ้า!T17 -> 0 | N8: =[2]หน้าผ้า!U17 -> 0 | O8: =[2]หน้าผ้า!V17 -> 0 | P8: =[2]หน้าผ้า!AB17 -> 0 | Q8: =[2]หน้าผ้า!AC17 -> 0 | R8: =[2]หน้าผ้า!AD17 -> 0 | S8: =[2]หน้าผ้า!Z17 -> 0 | T8: =[2]หน้าผ้า!X17 -> 0 | U8: =[2]หน้าผ้า!AA17 -> 0 | V8: =[2]หน้าผ้า!AJ17 -> 0 | W8: =[2]หน้าผ้า!AL17 -> 0 | X8: =[2]หน้าผ้า!AM17 -> 0 | Y8: =[2]หน้าผ้า!AN17 -> 0 | Z8: =[2]หน้าผ้า!AO17 -> WSWT1425800 | AA8: =[2]หน้าผ้า!AQ17 -> 6565.9 | AB8: =[2]หน้าผ้า!AR17 -> 5557 | AC8: =[2]หน้าผ้า!AS17 -> 1008.9 | AD8: =[2]หน้าผ้า!AT17 -> 1220 | AE8: =[2]หน้าผ้า!AU17 -> 5345.9 | AF8: =[2]หน้าผ้า!AI17 -> ระบุในSD | AG8: =[3]หน้าผ้า!DC20 -> พร้อมส่ง | AH8: =[2]หน้าผ้า!DL17 -> 0 | AI8: =[2]หน้าผ้า!DM17 -> Lead time | AJ8: =[2]หน้าผ้า!DN17 -> 0 | AK8: =[2]หน้าผ้า!DQ17 -> 0 | AL8: =[2]หน้าผ้า!DR17 -> 0 | AM8: =[2]หน้าผ้า!DS17 -> 0 | AN8: =[2]หน้าผ้า!DT17 -> 0 | AO8: =[2]หน้าผ้า!DU17 -> 0 | AP8: =[2]หน้าผ้า!DP17 -> 0 | AQ8: =[2]หน้าผ้า!DW17 -> 0 | AR8: =[2]หน้าผ้า!DX17 -> 0 | AS8: =[2]หน้าผ้า!DY17 -> 0 | AT8: =[2]หน้าผ้า!DZ17 -> 0 | AU8: =[2]หน้าผ้า!EA17 -> 0 | AV8: =[2]หน้าผ้า!EB17 -> 0 | AW8: =[2]หน้าผ้า!EC17 -> 0 | AX8: =[2]หน้าผ้า!ED17 -> 0 | AY8: =[2]หน้าผ้า!AG17 -> 0 | AZ8: =[2]หน้าผ้า!EG17 -> 0 | BA8: =[2]หน้าผ้า!EH17 -> 0 | BB8: =[2]หน้าผ้า!EI17 -> 0 | BC8: =[2]หน้าผ้า!BZ17 -> WRWT140800/WRWT25800 | BD8: =[2]หน้าผ้า!CA17 -> 0
A9: =[2]หน้าผ้า!C18 -> ประมาณการ | B9: =[2]หน้าผ้า!B18 -> ประมาณการ | C9: =[2]หน้าผ้า!E18 -> บจก.ซัน ซีเมนต์ โพรเซส | D9: =[2]หน้าผ้า!F18 -> พระอาทิตย์(ปูนนอน-ชริงค์) | E9: =[2]หน้าผ้า!G18 -> 16 | F9: =[2]หน้าผ้า!H18 -> 25 | G9: =[2]หน้าผ้า!I18 -> ขาว | H9: =[2]หน้าผ้า!J18 -> ใส | I9: =[2]หน้าผ้า!L18 -> 50 | J9: =[2]หน้าผ้า!M18 -> ± | K9: =[2]หน้าผ้า!N18 -> 5 | L9: =[2]หน้าผ้า!R18 -> บิด | M9: =[2]หน้าผ้า!T18 -> 19 | N9: =[2]หน้าผ้า!U18 -> 28 | O9: =[2]หน้าผ้า!V18 -> 40 | P9: =[2]หน้าผ้า!AB18 -> 65.624643 | Q9: =[2]หน้าผ้า!AC18 -> 0 | R9: =[2]หน้าผ้า!AD18 -> 65.624643 | S9: =[2]หน้าผ้า!Z18 -> 500กระสอบ | T9: =[2]หน้าผ้า!X18 -> รอแจ้ง | U9: =[2]หน้าผ้า!AA18 -> 5000 | V9: =[2]หน้าผ้า!AJ18 -> 0 | W9: =[2]หน้าผ้า!AL18 -> 5000 | X9: =[2]หน้าผ้า!AM18 -> 0 | Y9: =[2]หน้าผ้า!AN18 -> 5250 | Z9: =[2]หน้าผ้า!AO18 -> WSWT1625800SM | AA9: =[2]หน้าผ้า!AQ18 -> 3702.05 | AB9: =[2]หน้าผ้า!AR18 -> 3372 | AC9: =[2]หน้าผ้า!AS18 -> 330.05 | AD9: =[2]หน้าผ้า!AT18 -> 0 | AE9: =[2]หน้าผ้า!AU18 -> 3702.05 | AF9: =[2]หน้าผ้า!AI18 -> 0 | AG9: =[3]หน้าผ้า!DC21 -> ยังไม่ได้พิมพ์ | AH9: =[2]หน้าผ้า!DL18 -> P8 | AI9: =[2]หน้าผ้า!DM18 -> 4 | AJ9: =[2]หน้าผ้า!DN18 -> รอแจ้ง | AK9: =[2]หน้าผ้า!DQ18 -> #VALUE! | AL9: =[2]หน้าผ้า!DR18 -> #VALUE! | AM9: =[2]หน้าผ้า!DS18 -> #VALUE! | AN9: =[2]หน้าผ้า!DT18 -> #VALUE! | AO9: =[2]หน้าผ้า!DU18 -> #VALUE! | AP9: =[2]หน้าผ้า!DP18 -> #VALUE! | AQ9: =[2]หน้าผ้า!DW18 -> #VALUE! | AR9: =[2]หน้าผ้า!DX18 -> 0 | AS9: =[2]หน้าผ้า!DY18 -> 0 | AT9: =[2]หน้าผ้า!DZ18 -> 0 | AU9: =[2]หน้าผ้า!EA18 -> 0 | AV9: =[2]หน้าผ้า!EB18 -> 0 | AW9: =[2]หน้าผ้า!EC18 -> งานเคลือบ+พิมพ์ | AX9: =[2]หน้าผ้า!ED18 -> รอART | AY9: =[2]หน้าผ้า!AG18 -> 0 | AZ9: =[2]หน้าผ้า!EG18 -> 0 | BA9: =[2]หน้าผ้า!EH18 -> 0 | BB9: =[2]หน้าผ้า!EI18 -> 0 | BC9: =[2]หน้าผ้า!BZ18 -> WRWT25800/WRWT25800 | BD9: =[2]หน้าผ้า!CA18 -> 18.776178
A10: =[2]หน้าผ้า!C19 -> 0 | B10: =[2]หน้าผ้า!B19 -> 0 | C10: =[2]หน้าผ้า!E19 -> 0 | D10: =[2]หน้าผ้า!F19 | E10: =[2]หน้าผ้า!G19 -> 16 | F10: =[2]หน้าผ้า!H19 -> 25 | G10: =[2]หน้าผ้า!I19 -> ขาว | H10: =[2]หน้าผ้า!J19 -> 0 | I10: =[2]หน้าผ้า!L19 -> 45 | J10: =[2]หน้าผ้า!M19 -> ± | K10: =[2]หน้าผ้า!N19 -> 5 | L10: =[2]หน้าผ้า!R19 -> 0 | M10: =[2]หน้าผ้า!T19 -> 0 | N10: =[2]หน้าผ้า!U19 -> 0 | O10: =[2]หน้าผ้า!V19 -> 0 | P10: =[2]หน้าผ้า!AB19 -> 0 | Q10: =[2]หน้าผ้า!AC19 -> 0 | R10: =[2]หน้าผ้า!AD19 -> 0 | S10: =[2]หน้าผ้า!Z19 -> 0 | T10: =[2]หน้าผ้า!X19 -> 0 | U10: =[2]หน้าผ้า!AA19 -> 0 | V10: =[2]หน้าผ้า!AJ19 -> 0 | W10: =[2]หน้าผ้า!AL19 -> 0 | X10: =[2]หน้าผ้า!AM19 -> 0 | Y10: =[2]หน้าผ้า!AN19 -> 0 | Z10: =[2]หน้าผ้า!AO19 -> WSWT1625800SM | AA10: =[2]หน้าผ้า!AQ19 -> 3702.05 | AB10: =[2]หน้าผ้า!AR19 -> 3372 | AC10: =[2]หน้าผ้า!AS19 -> 330.05 | AD10: =[2]หน้าผ้า!AT19 -> 0 | AE10: =[2]หน้าผ้า!AU19 -> 3702.05 | AF10: =[2]หน้าผ้า!AI19 -> ระบุในSD | AG10: =[3]หน้าผ้า!DC22 -> พร้อมส่ง | AH10: =[2]หน้าผ้า!DL19 -> 0 | AI10: =[2]หน้าผ้า!DM19 -> Lead time | AJ10: =[2]หน้าผ้า!DN19 -> 0 | AK10: =[2]หน้าผ้า!DQ19 -> 0 | AL10: =[2]หน้าผ้า!DR19 -> 0 | AM10: =[2]หน้าผ้า!DS19 -> 0 | AN10: =[2]หน้าผ้า!DT19 -> 0 | AO10: =[2]หน้าผ้า!DU19 -> 0 | AP10: =[2]หน้าผ้า!DP19 -> 0 | AQ10: =[2]หน้าผ้า!DW19 -> 0 | AR10: =[2]หน้าผ้า!DX19 -> 0 | AS10: =[2]หน้าผ้า!DY19 -> 0 | AT10: =[2]หน้าผ้า!DZ19 -> 0 | AU10: =[2]หน้าผ้า!EA19 -> 0 | AV10: =[2]หน้าผ้า!EB19 -> 0 | AW10: =[2]หน้าผ้า!EC19 -> 0 | AX10: =[2]หน้าผ้า!ED19 -> 0 | AY10: =[2]หน้าผ้า!AG19 -> 0 | AZ10: =[2]หน้าผ้า!EG19 -> 0 | BA10: =[2]หน้าผ้า!EH19 -> 0 | BB10: =[2]หน้าผ้า!EI19 -> 0 | BC10: =[2]หน้าผ้า!BZ19 -> WRWT160800/WRWT25800 | BD10: =[2]หน้าผ้า!CA19 -> 0
A11: =[2]หน้าผ้า!C20 -> 0 | B11: =[2]หน้าผ้า!B20 -> 0 | C11: =[2]หน้าผ้า!E20 -> 0 | D11: =[2]หน้าผ้า!F20 -> 0 | E11: =[2]หน้าผ้า!G20 -> 16 | F11: =[2]หน้าผ้า!H20 -> 25 | G11: =[2]หน้าผ้า!I20 -> ขาว | H11: =[2]หน้าผ้า!J20 -> 0 | I11: =[2]หน้าผ้า!L20 -> 45 | J11: =[2]หน้าผ้า!M20 -> ± | K11: =[2]หน้าผ้า!N20 -> 5 | L11: =[2]หน้าผ้า!R20 -> 0 | M11: =[2]หน้าผ้า!T20 -> 0 | N11: =[2]หน้าผ้า!U20 -> 0 | O11: =[2]หน้าผ้า!V20 -> 0 | P11: =[2]หน้าผ้า!AB20 -> 0 | Q11: =[2]หน้าผ้า!AC20 -> 0 | R11: =[2]หน้าผ้า!AD20 -> 0 | S11: =[2]หน้าผ้า!Z20 -> 0 | T11: =[2]หน้าผ้า!X20 -> 0 | U11: =[2]หน้าผ้า!AA20 -> 0 | V11: =[2]หน้าผ้า!AJ20 -> 0 | W11: =[2]หน้าผ้า!AL20 -> 0 | X11: =[2]หน้าผ้า!AM20 -> 0 | Y11: =[2]หน้าผ้า!AN20 -> 0 | Z11: =[2]หน้าผ้า!AO20 -> WSWT1625800 | AA11: =[2]หน้าผ้า!AQ20 -> #REF! | AB11: =[2]หน้าผ้า!AR20 -> #REF! | AC11: =[2]หน้าผ้า!AS20 -> #REF! | AD11: =[2]หน้าผ้า!AT20 -> #REF! | AE11: =[2]หน้าผ้า!AU20 -> #REF! | AF11: =[2]หน้าผ้า!AI20 -> ระบุในSD | AG11: =[3]หน้าผ้า!DC23 -> พร้อมส่ง | AH11: =[2]หน้าผ้า!DL20 -> 0 | AI11: =[2]หน้าผ้า!DM20 -> Lead time | AJ11: =[2]หน้าผ้า!DN20 -> 0 | AK11: =[2]หน้าผ้า!DQ20 -> 0 | AL11: =[2]หน้าผ้า!DR20 -> 0 | AM11: =[2]หน้าผ้า!DS20 -> 0 | AN11: =[2]หน้าผ้า!DT20 -> 0 | AO11: =[2]หน้าผ้า!DU20 -> 0 | AP11: =[2]หน้าผ้า!DP20 -> 0 | AQ11: =[2]หน้าผ้า!DW20 -> 0 | AR11: =[2]หน้าผ้า!DX20 -> 0 | AS11: =[2]หน้าผ้า!DY20 -> 0 | AT11: =[2]หน้าผ้า!DZ20 -> 0 | AU11: =[2]หน้าผ้า!EA20 -> 0 | AV11: =[2]หน้าผ้า!EB20 -> 0 | AW11: =[2]หน้าผ้า!EC20 -> 0 | AX11: =[2]หน้าผ้า!ED20 -> 0 | AY11: =[2]หน้าผ้า!AG20 -> 0 | AZ11: =[2]หน้าผ้า!EG20 -> 0 | BA11: =[2]หน้าผ้า!EH20 -> 0 | BB11: =[2]หน้าผ้า!EI20 -> 0 | BC11: =[2]หน้าผ้า!BZ20 -> WRWT160800/WRWT25800 | BD11: =[2]หน้าผ้า!CA20 -> 0
A12: =[2]หน้าผ้า!C21 -> 45814 | B12: =[2]หน้าผ้า!B21 -> MK68-000754 | C12: =[2]หน้าผ้า!E21 -> โรงสีลิ้มย่งฮวด | D12: =[2]หน้าผ้า!F21 -> ข้าวหอมมะลิสร้อยฟ้า | E12: =[2]หน้าผ้า!G21 -> 16 | F12: =[2]หน้าผ้า!H21 -> 25 | G12: =[2]หน้าผ้า!I21 -> ขาว | H12: =[2]หน้าผ้า!J21 -> 0 | I12: =[2]หน้าผ้า!L21 -> 45 | J12: =[2]หน้าผ้า!M21 -> ± | K12: =[2]หน้าผ้า!N21 -> 5 | L12: =[2]หน้าผ้า!R21 -> ไม่ | M12: =[2]หน้าผ้า!T21 -> ไม่สวมถุงใน | N12: =[2]หน้าผ้า!U21 -> 0 | O12: =[2]หน้าผ้า!V21 -> 0 | P12: =[2]หน้าผ้า!AB21 -> 0 | Q12: =[2]หน้าผ้า!AC21 -> 0 | R12: =[2]หน้าผ้า!AD21 -> 0 | S12: =[2]หน้าผ้า!Z21 -> 500กระสอบ | T12: =[2]หน้าผ้า!X21 -> 45829 | U12: =[2]หน้าผ้า!AA21 -> 5000 | V12: =[2]หน้าผ้า!AJ21 -> 0 | W12: =[2]หน้าผ้า!AL21 -> 5000 | X12: =[2]หน้าผ้า!AM21 -> 0 | Y12: =[2]หน้าผ้า!AN21 -> 5250 | Z12: =[2]หน้าผ้า!AO21 -> WSWT1621720SMFX | AA12: =[2]หน้าผ้า!AQ21 -> 3702.05 | AB12: =[2]หน้าผ้า!AR21 -> 3702.05 | AC12: =[2]หน้าผ้า!AS21 -> 0 | AD12: =[2]หน้าผ้า!AT21 -> 0 | AE12: =[2]หน้าผ้า!AU21 -> 0 | AF12: =[2]หน้าผ้า!AI21 -> ขาด-เกินได้5% | AG12: =[3]หน้าผ้า!DC24 -> ยังไม่ได้พิมพ์ | AH12: =[2]หน้าผ้า!DL21 -> P7 | AI12: =[2]หน้าผ้า!DM21 -> 2 | AJ12: =[2]หน้าผ้า!DN21 -> 45829 | AK12: =[2]หน้าผ้า!DQ21 -> 0 | AL12: =[2]หน้าผ้า!DR21 -> 45820 | AM12: =[2]หน้าผ้า!DS21 -> 45827 | AN12: =[2]หน้าผ้า!DT21 -> 45828 | AO12: =[2]หน้าผ้า!DU21 -> 45828 | AP12: =[2]หน้าผ้า!DP21 -> 45824 | AQ12: =[2]หน้าผ้า!DW21 -> 0 | AR12: =[2]หน้าผ้า!DX21 -> 0 | AS12: =[2]หน้าผ้า!DY21 -> 0 | AT12: =[2]หน้าผ้า!DZ21 -> 0 | AU12: =[2]หน้าผ้า!EA21 -> 0 | AV12: =[2]หน้าผ้า!EB21 -> 0 | AW12: =[2]หน้าผ้า!EC21 -> งานพิมพ์ | AX12: =[2]หน้าผ้า!ED21 -> / | AY12: =[2]หน้าผ้า!AG21 -> 0 | AZ12: =[2]หน้าผ้า!EG21 -> 0 | BA12: =[2]หน้าผ้า!EH21 -> 0 | BB12: =[2]หน้าผ้า!EI21 -> 0 | BC12: =[2]หน้าผ้า!BZ21 -> WRWT21720/WRWT21720 | BD12: =[2]หน้าผ้า!CA21 -> 0
A13: =[2]หน้าผ้า!C22 -> 0 | B13: =[2]หน้าผ้า!B22 -> 0 | C13: =[2]หน้าผ้า!E22 -> 0 | D13: =[2]หน้าผ้า!F22 -> 0 | E13: =[2]หน้าผ้า!G22 -> 16 | F13: =[2]หน้าผ้า!H22 -> 25 | G13: =[2]หน้าผ้า!I22 -> 0 | H13: =[2]หน้าผ้า!J22 -> 0 | I13: =[2]หน้าผ้า!L22 -> 47 | J13: =[2]หน้าผ้า!M22 -> ± | K13: =[2]หน้าผ้า!N22 -> 5 | L13: =[2]หน้าผ้า!R22 -> 0 | M13: =[2]หน้าผ้า!T22 -> 0 | N13: =[2]หน้าผ้า!U22 -> 0 | O13: =[2]หน้าผ้า!V22 -> 0 | P13: =[2]หน้าผ้า!AB22 -> 0 | Q13: =[2]หน้าผ้า!AC22 -> 0 | R13: =[2]หน้าผ้า!AD22 -> 0 | S13: =[2]หน้าผ้า!Z22 -> 0 | T13: =[2]หน้าผ้า!X22 -> 0 | U13: =[2]หน้าผ้า!AA22 -> 0 | V13: =[2]หน้าผ้า!AJ22 -> 0 | W13: =[2]หน้าผ้า!AL22 -> 0 | X13: =[2]หน้าผ้า!AM22 -> 0 | Y13: =[2]หน้าผ้า!AN22 -> 0 | Z13: =[2]หน้าผ้า!AO22 -> WSWT1621720SMFX | AA13: =[2]หน้าผ้า!AQ22 -> 3702.05 | AB13: =[2]หน้าผ้า!AR22 -> 3702.05 | AC13: =[2]หน้าผ้า!AS22 -> 0 | AD13: =[2]หน้าผ้า!AT22 -> 0 | AE13: =[2]หน้าผ้า!AU22 -> 0 | AF13: =[2]หน้าผ้า!AI22 -> ระบุในSD | AG13: =[3]หน้าผ้า!DC25 -> พร้อมส่ง | AH13: =[2]หน้าผ้า!DL22 -> 0 | AI13: =[2]หน้าผ้า!DM22 -> 0 | AJ13: =[2]หน้าผ้า!DN22 -> 0 | AK13: =[2]หน้าผ้า!DQ22 -> 0 | AL13: =[2]หน้าผ้า!DR22 -> 0 | AM13: =[2]หน้าผ้า!DS22 -> 0 | AN13: =[2]หน้าผ้า!DT22 -> 0 | AO13: =[2]หน้าผ้า!DU22 -> 0 | AP13: =[2]หน้าผ้า!DP22 -> 0 | AQ13: =[2]หน้าผ้า!DW22 -> 0 | AR13: =[2]หน้าผ้า!DX22 -> 0 | AS13: =[2]หน้าผ้า!DY22 -> 0 | AT13: =[2]หน้าผ้า!DZ22 -> 0 | AU13: =[2]หน้าผ้า!EA22 -> 0 | AV13: =[2]หน้าผ้า!EB22 -> 0 | AW13: =[2]หน้าผ้า!EC22 -> 0 | AX13: =[2]หน้าผ้า!ED22 -> 0 | AY13: =[2]หน้าผ้า!AG22 -> 0 | AZ13: =[2]หน้าผ้า!EG22 -> 0 | BA13: =[2]หน้าผ้า!EH22 -> 0 | BB13: =[2]หน้าผ้า!EI22 -> 0 | BC13: =[2]หน้าผ้า!BZ22 -> WRWT160720/WRWT21720 | BD13: =[2]หน้าผ้า!CA22 -> 0
A14: =[2]หน้าผ้า!C23 -> 0 | B14: =[2]หน้าผ้า!B23 -> 0 | C14: =[2]หน้าผ้า!E23 -> 0 | D14: =[2]หน้าผ้า!F23 -> 0 | E14: =[2]หน้าผ้า!G23 -> 17 | F14: =[2]หน้าผ้า!H23 -> 26 | G14: =[2]หน้าผ้า!I23 -> 0 | H14: =[2]หน้าผ้า!J23 -> 0 | I14: =[2]หน้าผ้า!L23 -> 48 | J14: =[2]หน้าผ้า!M23 -> ± | K14: =[2]หน้าผ้า!N23 -> 5 | L14: =[2]หน้าผ้า!R23 -> 0 | M14: =[2]หน้าผ้า!T23 -> 0 | N14: =[2]หน้าผ้า!U23 -> 0 | O14: =[2]หน้าผ้า!V23 -> 0 | P14: =[2]หน้าผ้า!AB23 -> 0 | Q14: =[2]หน้าผ้า!AC23 -> 0 | R14: =[2]หน้าผ้า!AD23 -> 0 | S14: =[2]หน้าผ้า!Z23 -> 0 | T14: =[2]หน้าผ้า!X23 -> 0 | U14: =[2]หน้าผ้า!AA23 -> 0 | V14: =[2]หน้าผ้า!AJ23 -> 0 | W14: =[2]หน้าผ้า!AL23 -> 0 | X14: =[2]หน้าผ้า!AM23 -> 0 | Y14: =[2]หน้าผ้า!AN23 -> 0 | Z14: =[2]หน้าผ้า!AO23 -> WSWT1725800 | AA14: =[2]หน้าผ้า!AQ23 -> #REF! | AB14: =[2]หน้าผ้า!AR23 -> #REF! | AC14: =[2]หน้าผ้า!AS23 -> #REF! | AD14: =[2]หน้าผ้า!AT23 -> #REF! | AE14: =[2]หน้าผ้า!AU23 -> #REF! | AF14: =[2]หน้าผ้า!AI23 -> ระบุในSD | AG14: =[3]หน้าผ้า!DC26 -> ยังไม่ได้พิมพ์ | AH14: =[2]หน้าผ้า!DL23 -> 0 | AI14: =[2]หน้าผ้า!DM23 -> 0 | AJ14: =[2]หน้าผ้า!DN23 -> 0 | AK14: =[2]หน้าผ้า!DQ23 -> 0 | AL14: =[2]หน้าผ้า!DR23 -> 0 | AM14: =[2]หน้าผ้า!DS23 -> 0 | AN14: =[2]หน้าผ้า!DT23 -> 0 | AO14: =[2]หน้าผ้า!DU23 -> 0 | AP14: =[2]หน้าผ้า!DP23 -> 0 | AQ14: =[2]หน้าผ้า!DW23 -> 0 | AR14: =[2]หน้าผ้า!DX23 -> 0 | AS14: =[2]หน้าผ้า!DY23 -> 0 | AT14: =[2]หน้าผ้า!DZ23 -> 0 | AU14: =[2]หน้าผ้า!EA23 -> 0 | AV14: =[2]หน้าผ้า!EB23 -> 0 | AW14: =[2]หน้าผ้า!EC23 -> 0 | AX14: =[2]หน้าผ้า!ED23 -> 0 | AY14: =[2]หน้าผ้า!AG23 -> 0 | AZ14: =[2]หน้าผ้า!EG23 -> 0 | BA14: =[2]หน้าผ้า!EH23 -> 0 | BB14: =[2]หน้าผ้า!EI23 -> 0 | BC14: =[2]หน้าผ้า!BZ23 -> WRWT170800/WRWT25800 | BD14: =[2]หน้าผ้า!CA23 -> 0
A15: =[2]หน้าผ้า!C24 -> ประมาณการ | B15: =[2]หน้าผ้า!B24 -> ประมาณการ | C15: =[2]หน้าผ้า!E24 -> บจก.ฟาร์เธอร์ส วิง ซัพพลาย | D15: =[2]หน้าผ้า!F24 -> รถไฟ | E15: =[2]หน้าผ้า!G24 -> 18 | F15: =[2]หน้าผ้า!H24 -> 30 | G15: =[2]หน้าผ้า!I24 -> ขาว | H15: =[2]หน้าผ้า!J24 -> 0 | I15: =[2]หน้าผ้า!L24 -> 54 | J15: =[2]หน้าผ้า!M24 -> ± | K15: =[2]หน้าผ้า!N24 -> 5 | L15: =[2]หน้าผ้า!R24 -> บิด | M15: =[2]หน้าผ้า!T24 -> 19 | N15: =[2]หน้าผ้า!U24 -> 33 | O15: =[2]หน้าผ้า!V24 -> 40 | P15: =[2]หน้าผ้า!AB24 -> 232.02999 | Q15: =[2]หน้าผ้า!AC24 -> 0 | R15: =[2]หน้าผ้า!AD24 -> 232.02999 | S15: =[2]หน้าผ้า!Z24 -> 500กระสอบ | T15: =[2]หน้าผ้า!X24 -> 45838 | U15: =[2]หน้าผ้า!AA24 -> 15000 | V15: =[2]หน้าผ้า!AJ24 -> 0 | W15: =[2]หน้าผ้า!AL24 -> 15000 | X15: =[2]หน้าผ้า!AM24 -> 0 | Y15: =[2]หน้าผ้า!AN24 -> 15750 | Z15: =[2]หน้าผ้า!AO24 -> WSWT1825800 | AA15: =[2]หน้าผ้า!AQ24 -> 13201.65 | AB15: =[2]หน้าผ้า!AR24 -> 6301 | AC15: =[2]หน้าผ้า!AS24 -> 6900.65 | AD15: =[2]หน้าผ้า!AT24 -> 0 | AE15: =[2]หน้าผ้า!AU24 -> 0 | AF15: =[2]หน้าผ้า!AI24 -> 0 | AG15: =[3]หน้าผ้า!DC27 -> ยังไม่ได้พิมพ์ | AH15: =[2]หน้าผ้า!DL24 -> P9 | AI15: =[2]หน้าผ้า!DM24 -> 3 | AJ15: =[2]หน้าผ้า!DN24 -> 45838 | AK15: =[2]หน้าผ้า!DQ24 -> 0 | AL15: =[2]หน้าผ้า!DR24 -> 45828 | AM15: =[2]หน้าผ้า!DS24 -> 45835 | AN15: =[2]หน้าผ้า!DT24 -> 45836 | AO15: =[2]หน้าผ้า!DU24 -> 45836 | AP15: =[2]หน้าผ้า!DP24 -> 45833 | AQ15: =[2]หน้าผ้า!DW24 -> 45837 | AR15: =[2]หน้าผ้า!DX24 -> 0 | AS15: =[2]หน้าผ้า!DY24 -> 0 | AT15: =[2]หน้าผ้า!DZ24 -> 0 | AU15: =[2]หน้าผ้า!EA24 -> 0 | AV15: =[2]หน้าผ้า!EB24 -> 0 | AW15: =[2]หน้าผ้า!EC24 -> งานพิมพ์ | AX15: =[2]หน้าผ้า!ED24 -> รอART | AY15: =[2]หน้าผ้า!AG24 -> 0 | AZ15: =[2]หน้าผ้า!EG24 -> 0 | BA15: =[2]หน้าผ้า!EH24 -> 0 | BB15: =[2]หน้าผ้า!EI24 -> 0 | BC15: =[2]หน้าผ้า!BZ24 -> WRWT25800/WRWT25800 | BD15: =[2]หน้าผ้า!CA24 -> 474.76472
A16: =[2]หน้าผ้า!C25 -> 0 | B16: =[2]หน้าผ้า!B25 -> 0 | C16: =[2]หน้าผ้า!E25 | D16: =[2]หน้าผ้า!F25 | E16: =[2]หน้าผ้า!G25 -> 18 | F16: =[2]หน้าผ้า!H25 -> 30 | G16: =[2]หน้าผ้า!I25 -> ขาว | H16: =[2]หน้าผ้า!J25 -> 0 | I16: =[2]หน้าผ้า!L25 -> 54 | J16: =[2]หน้าผ้า!M25 -> ± | K16: =[2]หน้าผ้า!N25 -> 5 | L16: =[2]หน้าผ้า!R25 -> 0 | M16: =[2]หน้าผ้า!T25 -> 0 | N16: =[2]หน้าผ้า!U25 -> 0 | O16: =[2]หน้าผ้า!V25 -> 0 | P16: =[2]หน้าผ้า!AB25 -> 0 | Q16: =[2]หน้าผ้า!AC25 -> 0 | R16: =[2]หน้าผ้า!AD25 -> 0 | S16: =[2]หน้าผ้า!Z25 -> 0 | T16: =[2]หน้าผ้า!X25 -> 0 | U16: =[2]หน้าผ้า!AA25 -> 0 | V16: =[2]หน้าผ้า!AJ25 -> 0 | W16: =[2]หน้าผ้า!AL25 -> 0 | X16: =[2]หน้าผ้า!AM25 -> 0 | Y16: =[2]หน้าผ้า!AN25 -> 0 | Z16: =[2]หน้าผ้า!AO25 -> WSWT1825800 | AA16: =[2]หน้าผ้า!AQ25 -> 13201.65 | AB16: =[2]หน้าผ้า!AR25 -> 6301 | AC16: =[2]หน้าผ้า!AS25 -> 6900.65 | AD16: =[2]หน้าผ้า!AT25 -> 0 | AE16: =[2]หน้าผ้า!AU25 -> 0 | AF16: =[2]หน้าผ้า!AI25 -> ระบุในSD | AG16: =[3]หน้าผ้า!DC28 -> พร้อมส่ง | AH16: =[2]หน้าผ้า!DL25 -> 0 | AI16: =[2]หน้าผ้า!DM25 -> Lead time | AJ16: =[2]หน้าผ้า!DN25 -> 0 | AK16: =[2]หน้าผ้า!DQ25 -> 0 | AL16: =[2]หน้าผ้า!DR25 -> 0 | AM16: =[2]หน้าผ้า!DS25 -> 0 | AN16: =[2]หน้าผ้า!DT25 -> 0 | AO16: =[2]หน้าผ้า!DU25 -> 0 | AP16: =[2]หน้าผ้า!DP25 -> 0 | AQ16: =[2]หน้าผ้า!DW25 -> 0 | AR16: =[2]หน้าผ้า!DX25 -> 0 | AS16: =[2]หน้าผ้า!DY25 -> 0 | AT16: =[2]หน้าผ้า!DZ25 -> 0 | AU16: =[2]หน้าผ้า!EA25 -> 0 | AV16: =[2]หน้าผ้า!EB25 -> 0 | AW16: =[2]หน้าผ้า!EC25 -> 0 | AX16: =[2]หน้าผ้า!ED25 -> 0 | AY16: =[2]หน้าผ้า!AG25 -> 0 | AZ16: =[2]หน้าผ้า!EG25 -> 0 | BA16: =[2]หน้าผ้า!EH25 -> 0 | BB16: =[2]หน้าผ้า!EI25 -> 0 | BC16: =[2]หน้าผ้า!BZ25 -> WRWT25800/WRWT25800 | BD16: =[2]หน้าผ้า!CA25 -> 0
A17: =[2]หน้าผ้า!C26 -> 45805 | B17: =[2]หน้าผ้า!B26 -> MK68-000716 | C17: =[2]หน้าผ้า!E26 -> บจก.ไบโอกรีนนิค | D17: =[2]หน้าผ้า!F26 -> หนุมานเทอร์โบ | E17: =[2]หน้าผ้า!G26 -> 18 | F17: =[2]หน้าผ้า!H26 -> 28 | G17: =[2]หน้าผ้า!I26 -> ขาว | H17: =[2]หน้าผ้า!J26 -> ใส | I17: =[2]หน้าผ้า!L26 -> 69 | J17: =[2]หน้าผ้า!M26 -> ± | K17: =[2]หน้าผ้า!N26 -> 5 | L17: =[2]หน้าผ้า!R26 -> จับจีบ4" | M17: =[2]หน้าผ้า!T26 -> 19 | N17: =[2]หน้าผ้า!U26 -> 31 | O17: =[2]หน้าผ้า!V26 -> 60 | P17: =[2]หน้าผ้า!AB26 -> 217.96756 | Q17: =[2]หน้าผ้า!AC26 -> 0 | R17: =[2]หน้าผ้า!AD26 -> 217.96756 | S17: =[2]หน้าผ้า!Z26 -> 500กระสอบ | T17: =[2]หน้าผ้า!X26 -> 45820 | U17: =[2]หน้าผ้า!AA26 -> 10000 | V17: =[2]หน้าผ้า!AJ26 -> 0 | W17: =[2]หน้าผ้า!AL26 -> 10000 | X17: =[2]หน้าผ้า!AM26 -> 0 | Y17: =[2]หน้าผ้า!AN26 -> 10500 | Z17: =[2]หน้าผ้า!AO26 -> WSWT1825800SM | AA17: =[2]หน้าผ้า!AQ26 -> 8242.3 | AB17: =[2]หน้าผ้า!AR26 -> 8242.3 | AC17: =[2]หน้าผ้า!AS26 -> 0 | AD17: =[2]หน้าผ้า!AT26 -> 0 | AE17: =[2]หน้าผ้า!AU26 -> 8242.3 | AF17: =[2]หน้าผ้า!AI26 -> ขาด-เกินได้5% | AG17: =[3]หน้าผ้า!DC29 -> พร้อมส่ง | AH17: =[2]หน้าผ้า!DL26 -> P6 | AI17: =[2]หน้าผ้า!DM26 -> 4 | AJ17: =[2]หน้าผ้า!DN26 -> 45820 | AK17: =[2]หน้าผ้า!DQ26 -> 45816 | AL17: =[2]หน้าผ้า!DR26 -> 45809 | AM17: =[2]หน้าผ้า!DS26 -> 45817 | AN17: =[2]หน้าผ้า!DT26 -> 45818 | AO17: =[2]หน้าผ้า!DU26 -> 45819 | AP17: =[2]หน้าผ้า!DP26 -> 45815 | AQ17: =[2]หน้าผ้า!DW26 -> 0 | AR17: =[2]หน้าผ้า!DX26 -> 0 | AS17: =[2]หน้าผ้า!DY26 -> 0 | AT17: =[2]หน้าผ้า!DZ26 -> 0 | AU17: =[2]หน้าผ้า!EA26 -> 0 | AV17: =[2]หน้าผ้า!EB26 -> 0 | AW17: =[2]หน้าผ้า!EC26 -> งานเคลือบ+พิมพ์ | AX17: =[2]หน้าผ้า!ED26 -> รอART | AY17: =[2]หน้าผ้า!AG26 -> 0 | AZ17: =[2]หน้าผ้า!EG26 -> 0 | BA17: =[2]หน้าผ้า!EH26 -> 0 | BB17: =[2]หน้าผ้า!EI26 -> 0 | BC17: =[2]หน้าผ้า!BZ26 -> WRWT25800/WRWT25800 | BD17: =[2]หน้าผ้า!CA26 -> 0
... A575: =[2]หน้าผ้า!C584 -> 0 | B575: =[2]หน้าผ้า!B584 -> 0 | C575: =[2]หน้าผ้า!E584 -> 0 | D575: =[2]หน้าผ้า!F584 -> 0 | E575: =[2]หน้าผ้า!G584 -> 0 | F575: =[2]หน้าผ้า!H584 -> 0 | G575: =[2]หน้าผ้า!I584 -> 0 | H575: =[2]หน้าผ้า!J584 -> 0 | I575: =[2]หน้าผ้า!L584 -> 0 | J575: =[2]หน้าผ้า!M584 -> 0 | K575: =[2]หน้าผ้า!N584 -> 0 | L575: =[2]หน้าผ้า!R584 -> 0 | M575: =[2]หน้าผ้า!T584 -> 0 | N575: =[2]หน้าผ้า!U584 -> 0 | O575: =[2]หน้าผ้า!V584 -> 0 | P575: =[2]หน้าผ้า!AB584 -> 0 | Q575: =[2]หน้าผ้า!AC584 -> 0 | R575: =[2]หน้าผ้า!AD584 -> 0 | S575: =[2]หน้าผ้า!Z584 -> 0 | T575: =[2]หน้าผ้า!X584 -> 0 | U575: =[2]หน้าผ้า!AA584 -> 0 | V575: =[2]หน้าผ้า!AJ584 -> 0 | W575: =[2]หน้าผ้า!AL584 -> 0 | X575: =[2]หน้าผ้า!AM584 -> 0 | Y575: =[2]หน้าผ้า!AN584 -> 0 | Z575: =[2]หน้าผ้า!AO584 -> 0 | AA575: =[2]หน้าผ้า!AQ584 -> 0 | AB575: =[2]หน้าผ้า!AR584 -> 0 | AC575: =[2]หน้าผ้า!AS584 -> 0 | AD575: =[2]หน้าผ้า!AT584 -> 0 | AE575: =[2]หน้าผ้า!AU584 -> 0 | AF575: =[2]หน้าผ้า!AI584 -> 0 | AG575: =[3]หน้าผ้า!DC587 -> 0 | AH575: =[2]หน้าผ้า!DL584 -> 0 | AI575: =[2]หน้าผ้า!DM584 -> 0 | AJ575: =[2]หน้าผ้า!DN584 -> 0 | AK575: =[2]หน้าผ้า!DQ584 -> 0 | AL575: =[2]หน้าผ้า!DR584 -> 0 | AM575: =[2]หน้าผ้า!DS584 -> 0 | AN575: =[2]หน้าผ้า!DT584 -> 0 | AO575: =[2]หน้าผ้า!DU584 -> 0 | AP575: =[2]หน้าผ้า!DP584 -> 0 | AQ575: =[2]หน้าผ้า!DW584 -> 0 | AR575: =[2]หน้าผ้า!DX584 -> 0 | AS575: =[2]หน้าผ้า!DY584 -> 0 | AT575: =[2]หน้าผ้า!DZ584 -> 0 | AU575: =[2]หน้าผ้า!EA584 -> 0 | AV575: =[2]หน้าผ้า!EB584 -> 0 | AW575: =[2]หน้าผ้า!EC584 -> 0 | AX575: =[2]หน้าผ้า!ED584 -> 0 | AY575: =[2]หน้าผ้า!AG584 -> 0 | AZ575: =[2]หน้าผ้า!EG584 -> 0 | BA575: =[2]หน้าผ้า!EH584 -> 0 | BB575: =[2]หน้าผ้า!EI584 -> 0 | BC575: =[2]หน้าผ้า!BZ584 -> 0 | BD575: =[2]หน้าผ้า!CA584 -> 0

Sheet 4(Order+FC) (-4)
A2: เลขที่ SO | B2: (หลายรายการ)
A3: วันส่ง | B3: รอแจ้ง
A4: ชื่อลูกค้า | B4: (ทั้งหมด)
A6: ประเภท | B6: ผลรวม ของ จำนวนส่ง | C6: ผลรวม ของ ค้างพิมพ์ | D6: ผลรวม ของ ค้างตัด | E6: ผลรวม ของ Stock | F6: ผลรวม ของ ใช้ | G6: ผลรวม ของ ค้างทอ
A7: WSWT1625800SM | B7: 5000 | C7: 5250 | D7: 5000 | E7: 3372 | F7: 3702.05 | G7: 330.05 | H7: =+J7-I7 -> 330.05 | J7: =G7 -> 330.05
A8: WSWT1825800SM | B8: 10000 | C8: 10500 | D8: 10000 | E8: 3198 | F8: 8801.1 | G8: 5603.1 | H8: =+J8-I8 -> 5603.1 | J8: =G8 -> 5603.1
A9: WSWT1921720 | B9: 600000 | C9: 630000 | D9: 600000 | E9: 0 | F9: 528066 | G9: 528066 | H9: =+J9-I9 -> 528066 | J9: =G9 -> 528066
A10: WSWT1925800 | B10: 10000 | C10: 10500 | D10: 10000 | E10: 0 | F10: 9359.9 | G10: 9359.9 | H10: =+J10-I10 -> 9359.9 | J10: =G10 -> 9359.9
A11: WSWT2025700 | B11: 50000 | C11: 0 | D11: 50000 | E11: 9009 | F11: 55181.5 | G11: 46172.5 | H11: =+J11-I11 -> 46172.5 | J11: =G11 -> 46172.5
A12: WSWT2025800 | B12: 110000 | C12: 115500 | D12: 110000 | E12: 0 | F12: 115252.5 | G12: 115252.5 | H12: =+J12-I12 -> 115252.5 | J12: =G12 -> 115252.5
A13: WSWT2025800SM | B13: 69250 | C13: 66150 | D13: 69183 | E13: 0 | F13: 68578.73 | G13: 68578.73 | H13: =+J13-I13 -> 68578.73 | J13: =G13 -> 68578.73
A14: WSWT2121670SM | B14: 71000 | C14: 74550 | D14: 71000 | E14: 0 | F14: 77743.05 | G14: 77743.05 | H14: =+J14-I14 -> 77743.05 | J14: =G14 -> 77743.05
A15: WSWT2321112512551 | B15: 106278 | C15: 111591.9 | D15: 106278 | E15: 0 | F15: 114322.18 | G15: 114322.18 | H15: =+J15-I15 -> 114322.18 | J15: =G15 -> 114322.18
A16: WSWT2625650 | B16: 50000 | C16: 10500 | D16: 50000 | E16: 0 | F16: 60490.1 | G16: 60490.1 | H16: =+J16-I16 -> 60490.1 | J16: =G16 -> 60490.1
A17: WSWT2625800 | B17: 30000 | C17: 0 | D17: 30000 | E17: 6278 | F17: 37299.9 | G17: 31021.9 | H17: 0 | I17: 160000 | J17: =G17 -> 31021.9
A18: WSWT2625850SM | B18: 20000 | C18: 21000 | D18: 20000 | E18: 7700 | F18: 24866.6 | G18: 17166.6 | H18: =+J18-I18 -> 17166.6 | J18: =G18 -> 17166.6
A19: ผลรวมทั้งหมด | B19: 1131528 | C19: 1055541.9 | D19: 1131461 | E19: 29557 | F19: 1103663.6 | G19: 1074106.6 | H19: =+J19-I19 -> 1074106.6 | J19: =G19 -> 1074106.6
H20: =+J20-I20 -> 0 | J20: =G20 -> 0
H21: =+J21-I21 -> 0 | J21: =G21 -> 0
H22: =+J22-I22 -> 0 | J22: =G22 -> 0
H23: =+J23-I23 -> 0 | J23: =G23 -> 0
H24: =+J24-I24 -> 0 | J24: =G24 -> 0
H25: =+J25-I25 -> 0 | J25: =G25 -> 0
H27: =SUM(H8:H25) -> 2116861.3 | J27: =SUM(J8:J25) -> 2147883.2
M28: =+GETPIVOTDATA("ผลรวม ของ ใช้",$A$6)+H29+H31 -> 1193663.6
H30: =+H27 -> 2116861.3
A31: กรม | B31: 70000 | C31: 70000 | D31: 70000 | G31: 90000 | H31: 90000 | I31: 95 | J31: =+H31*I31 -> 8550000 | K31: =+J31/1000 -> 8550
G33: 160000 | H33: =+H29+H30 -> 2116861.3 | I33: 85 | J33: =+H33*I33 -> 1.7993321e+08 | K33: =+J33/1000 -> 179933.21
H34: =+H30+H31+H29 -> 2206861.3
H35: 15 | I35: =+H34/H35 -> 147124.08 | K35: =+K33+K31 -> 188483.21
N36: 705222
A37: ยอดส่ง 1/2/68 - 10/2/68 | B37: 817879 | I37: =+H35*100000 -> 1500000
N38: =+H34+N36 -> 2912083.3
H39: 16 | I39: =+H39*90000 -> 1440000
B41: =+B26+B37+B31 -> 887879 | C41: =+C26+C37+C31 -> 70000 | D41: =+D26+D37+D31 -> 70000 | E41: =+E26+E37+E31 -> 0 | F41: =+F26+F37+F31 -> 0
B43: 2992955
B45: =+B43-B41 -> 2105076 | C45: =+C32+($B$45*1) -> 2105076 | D45: =+D32+($B$45*1) -> 2105076 | E45: =+E31+($B$45*1) -> 2105076 | F45: =+F30+($B$45*1) -> 2105076 | G45: =+G30+($B$45*1) -> 2105076
C47: =+C41/13 -> 5384.6154 | D47: =+D41/15 -> 4666.6667
B49: 16 | C49: 135000 | D49: 135000
C50: =+B49*C49 -> 2160000 | D50: =+B49*D49 -> 2160000
...

Sheet 4(Order+FC)
A2: เลขที่ SO | B2: (หลายรายการ)
A3: วันส่ง | B3: (หลายรายการ)
A4: ชื่อลูกค้า | B4: (ทั้งหมด)
K5: 9
A6: ประเภท | B6: ผลรวม ของ จำนวนส่ง | C6: ผลรวม ของ ค้างพิมพ์ | D6: ผลรวม ของ ค้างตัด | E6: ผลรวม ของ ใช้ | F6: ผลรวม ของ Stock | G6: ผลรวม ของ ค้างทอ
A7: WSWT1625800 | B7: 10000 | C7: 0 | D7: 10000 | E7: 0 | F7: 0 | G7: 0 | H7: =+J7-I7 -> 0 | J7: =G7 -> 0
A8: WSWT1921720 | B8: 90000 | C8: 41976.9 | D8: 74828 | E8: 40423.788 | F8: 8801.1 | G8: 31622.688 | H8: =+J8-I8 -> 31622.688 | J8: =G8 -> 31622.688
A9: WSWT1925800 | B9: 118000 | C9: 54869.85 | D9: 118000 | E9: 45972.484 | F9: 8242.3 | G9: 37730.184 | H9: =+J9-I9 -> 37730.184 | J9: =G9 -> 37730.184
A10: WSWT2025700 | B10: 10000 | C10: 0 | D10: 10000 | E10: 8801.1 | F10: 0 | G10: 8801.1 | H10: =+J10-I10 -> 8801.1 | J10: =G10 -> 8801.1
A11: WSWT2025800 | B11: 193960 | C11: 70687.05 | D11: 193960 | E11: 74062.357 | F11: 50571 | G11: 23491.357 | H11: =+J11-I11 -> 23491.357 | J11: =G11 -> 23491.357
A12: WSWT2025800SM | B12: 142160 | C12: 123783.45 | D12: 139160 | E12: 123659.07 | F12: 74605.09 | G12: 49053.98 | H12: =+J12-I12 -> 49053.98 | J12: =G12 -> 49053.98 | K12: 40000 | L12: =+K5*K12 -> 360000 | M12: =+L12-J12 -> 310946.02
A13: WSWT2121670SM | B13: 82000 | C13: 54153.75 | D13: 79000 | E13: 55670.991 | F13: 17415.391 | G13: 38255.6 | H13: =+J13-I13 -> 38255.6 | J13: =G13 -> 38255.6 | K13: 14000 | L13: =+K13*K5 -> 126000 | M13: =+L13-J13 -> 87744.4
A14: WSWT2321750 | B14: 8000 | C14: 0 | D14: 8000 | E14: 0 | F14: 0 | G14: 0 | H14: =+J14-I14 -> 0 | J14: =G14 -> 0
A15: WSWT2325650 | B15: 40000 | C15: 0 | D15: 40000 | E15: 0 | F15: 0 | G15: 0 | H15: =+J15-I15 -> 0 | J15: =G15 -> 0 | K15: 20000 | L15: =+K15*K5 -> 180000 | M15: =+L15-J15 -> 180000
A16: WSWT2625650 | B16: 12563 | C16: 8400 | D16: 8000 | E16: 9499.6 | F16: 6749.8 | G16: 2749.8 | H16: =+J16-I16 -> 2749.8 | J16: =G16 -> 2749.8
A17: WSWT2625850SM | B17: 10000 | C17: 0 | D17: 10000 | E17: 0 | F17: 0 | G17: 0 | H17: =+J17-I17 -> 0 | J17: =G17 -> 0
A18: WSWT2825850 | B18: 31500 | C18: 0 | D18: 10500 | E18: 0 | F18: 0 | G18: 0 | H18: =+J18-I18 -> 0 | J18: =G18 -> 0
A19: ผลรวมทั้งหมด | B19: 748183 | C19: 353871 | D19: 701448 | E19: 358089.39 | F19: 166384.68 | G19: 191704.71 | H19: 0 | I19: 54000 | J19: =G19 -> 191704.71
H20: =+J20-I20 -> 0 | J20: =G20 -> 0
H21: =+J21-I21 -> 0 | J21: =G21 -> 0
H22: =+J22-I22 -> 0 | J22: =G22 -> 0
H23: =+J23-I23 -> 0 | J23: =G23 -> 0
H24: =+J24-I24 -> 0 | J24: =G24 -> 0
H25: =+J25-I25 -> 0 | J25: =G25 -> 0
H26: =+J26-I26 -> 0 | J26: =G26 -> 0
H27: =+J27-I27 -> 0 | J27: =G27 -> 0
H28: =+J28-I28 -> 0 | J28: =G28 -> 0 | M28: =+GETPIVOTDATA("ผลรวม ของ ใช้",$A$6)+H29+H33 -> 639794.1
H29: =SUM(H7:H28) -> 191704.71 | I29: =SUM(I7:I28) -> 54000 | J29: =SUM(J7:J28) -> 383409.42
H32: =+H26 -> 0 | I32: 85 | J32: =+(H32+H29)*I32 -> 16294900 | K32: =+J32/1000 -> 16294.9
H33: 90000 | I33: 95 | J33: =+H33*I33 -> 8550000 | K33: =+J33/1000 -> 8550
H35: =+H32+H33+H29 -> 281704.71 | K35: =+K32+K33 -> 24844.9
N36: 705222
A37: ยอดส่ง 1/2/68 - 17/2/68 | B37: 1565717 | H37: 15 | I37: =+H35/H37 -> 18780.314
N38: =+H35+N36 -> 986926.71
I39: =+H37*110000 -> 1650000
B41: =+B29+B37+B31-110000 -> 1455717 | C41: =+C29+C37+C31 -> 0 | D41: =+D29+D37+D31-110000 -> -110000 | E41: =+E29+E37+E31 -> 0 | F41: =+F29+F37+F31 -> 0 | G41: =+G29+G37+G31 -> 0
B43: 3218150
B45: =+B43-B41 -> 1762433
C47: =+C41/9 -> 0 | D47: =+D41/9 -> -12222.222

Sheet 7(Order)
A2: เลขที่ SO | B2: (หลายรายการ)
A3: วันส่ง | B3: (หลายรายการ)
A4: ชื่อลูกค้า | B4: (ทั้งหมด)
A6: ประเภท | B6: ผลรวม ของ จำนวนส่ง | C6: ผลรวม ของ ค้างพิมพ์ | D6: ผลรวม ของ ค้างตัด | E6: ผลรวม ของ ใช้ | F6: ผลรวม ของ Stock | G6: ผลรวม ของ ค้างทอ
A7: WSWT1825800SM | B7: 10000 | C7: 10500 | D7: 10000 | E7: 8801.1 | F7: 4000 | G7: 4801.1 | I7: =+K7-J7 -> 4801.1 | K7: =G7 -> 4801.1
A8: WSWT2025800 | B8: 205000 | C8: 204750 | D8: 205000 | E8: 209759.55 | F8: 148777.35 | G8: 60982.2 | I8: =+K8-J8 -> 60982.2 | K8: =G8 -> 60982.2
A9: WSWT2321112512551 | B9: 50800 | C9: 45024 | D9: 42880 | E9: 46125.587 | F9: 0 | G9: 46125.587 | I9: =+K9-J9 -> 46125.587 | K9: =G9 -> 46125.587
A10: ผลรวมทั้งหมด | B10: 265800 | C10: 260274 | D10: 257880 | E10: 264686.24 | F10: 152777.35 | G10: 111908.89 | I10: =+K10-J10 -> 111908.89 | K10: =G10 -> 111908.89
I11: =+K11-J11 -> 0 | K11: =G11 -> 0
I12: =+K12-J12 -> 0 | K12: =G12 -> 0
I13: =+K13-J13 -> 0 | K13: =G13 -> 0
I14: =+K14-J14 -> 0 | K14: =G14 -> 0
I15: =+K15-J15 -> 0 | K15: =G15 -> 0
I16: =+K16-J16 -> 0 | K16: =G16 -> 0
I17: 0 | J17: 54000 | K17: =G17 -> 0
I18: =+K18-J18 -> 0 | K18: =G18 -> 0
I19: =+K19-J19 -> 0 | K19: =G19 -> 0
I20: =+K20-J20 -> 0 | K20: =G20 -> 0
I21: =+K21-J21 -> 0 | K21: =G21 -> 0
I22: =+K22-J22 -> 0 | K22: =G22 -> 0
I23: =+K23-J23 -> 0 | K23: =G23 -> 0
I24: =+K24-J24 -> 0 | K24: =G24 -> 0
I25: =+K25-J25 -> 0 | K25: =G25 -> 0
I26: =SUM(I7:I25) -> 223817.77 | J26: =SUM(J7:J25) -> 54000 | K26: =SUM(K7:K25) -> 223817.77
D34: =D18 -> 0
D36: =D20 -> 0
A37: ยอดส่ง 1/4/68 - 12/4/68 | B37: 887615
A38: Order+ส่ง | B38: =++B25+B37 -> 887615
A39: ประมาณการ | B39: 262000 | C39: 238350 | D39: 262000 | E39: 279847.04 | F39: 60825.09 | G39: 219021.95
A41: Order+ส่ง+ประมาณการ | B41: =+B25+B37+B39+B33 -> 1149615 | C41: =+C25+C37+C39+C33 -> 238350 | D41: =+D25+D37+D39+D33 -> 262000 | E41: =+E25+E37+E39+E33 -> 279847.04 | F41: =+F25+F37+F39+F33 -> 60825.09 | G41: =+G25+G37+G39+G33 -> 219021.95
B43: 3171376
B45: =+B41-B43 -> -2021761 | C45: =+$B$45 -> -2021761 | D45: =+$B$45 -> -2021761 | F45: =+$B$45 -> -2021761
D47: =+D41/6 -> 43666.667

Sheet 4(Order) แยกลูกค้า
A1: เลขที่ SO | B1: (หลายรายการ)
A2: วันส่ง | B2: (หลายรายการ)
A4: ประเภท | B4: ชื่อลูกค้า | C4: ผลรวม ของ จำนวนส่ง | D4: ผลรวม ของ ค้างพิมพ์ | E4: ผลรวม ของ ค้างตัด | F4: ผลรวม ของ Stock | G4: ผลรวม ของ ค้างทอ | I4: vn
A5: WSWT1625800 | B5: บจก.เคอรี่ฟลาวมิลล์ | C5: 10000 | D5: 0 | E5: 10000 | F5: 0 | G5: 0 | H5: =G5 -> 0
A6: WSWT1625800 ผลรวม | C6: 10000 | D6: 0 | E6: 10000 | F6: 0 | G6: 0 | H6: =G6 -> 0
A7: WSWT1725800 | B7: โรงสีข้าวธัญญาวัฒน์ | C7: 24200 | D7: 25410 | E7: 24200 | F7: 15615 | G7: 2979.07 | H7: =G7 -> 2979.07
A8: WSWT1725800 ผลรวม | C8: 24200 | D8: 25410 | E8: 24200 | F8: 15615 | G8: 2979.07 | H8: =G8 -> 2979.07
A9: WSWT1921720 | B9: บจก.เคอรี่ฟลาวมิลล์ | C9: 90000 | D9: 41976.9 | E9: 74828 | F9: 8801.1 | G9: 31622.688 | H9: =G9 -> 31622.688
A10: WSWT1921720 ผลรวม | C10: 90000 | D10: 41976.9 | E10: 74828 | F10: 8801.1 | G10: 31622.688 | H10: =G10 -> 31622.688
A11: WSWT1925800 | B11: บจก.เพรซิเดนท์ฟลาวมิลล์ | C11: 60000 | D11: 12869.85 | E11: 60000 | F11: 0 | G11: 11326.884 | H11: =G11 -> 11326.884
B12: บจก.ซีแมน | C12: 28000 | D12: 10500 | E12: 28000 | F12: 8242.3 | G12: 0 | H12: =G12 -> 0
B13: บจก.เอ็กเซลเล้นท์ | C13: 30000 | D13: 31500 | E13: 30000 | F13: 0 | G13: 26403.3 | H13: =G13 -> 26403.3
A14: WSWT1925800 ผลรวม | C14: 118000 | D14: 54869.85 | E14: 118000 | F14: 8242.3 | G14: 37730.184 | H14: =G14 -> 37730.184
A15: WSWT2025700 | B15: บจก.หนองบัวฟีดมิลล์ | C15: 10000 | D15: 0 | E15: 10000 | F15: 0 | G15: 8801.1 | H15: =G15 -> 8801.1
A16: WSWT2025700 ผลรวม | C16: 10000 | D16: 0 | E16: 10000 | F16: 0 | G16: 8801.1 | H16: =G16 -> 8801.1
A17: WSWT2025800 | B17: บจก.เบทาโกร | C17: 65000 | D17: 0 | E17: 65000 | F17: 0 | G17: 0 | H17: =G17 -> 0
B18: บจก.อินเทคค์ โกลบอล | C18: 128960 | D18: 70687.05 | E18: 128960 | F18: 50571 | G18: 23491.357 | H18: =G18 -> 23491.357
A19: WSWT2025800 ผลรวม | C19: 193960 | D19: 70687.05 | E19: 193960 | F19: 50571 | G19: 23491.357 | H19: =G19 -> 23491.357
A20: WSWT2025800SM | B20: บจก.เบทาโกร | C20: 12000 | D20: 0 | E20: 9000 | F20: 0 | G20: 0 | H20: =G20 -> 0
B21: บจก.อินเทคค์ โกลบอล | C21: 130160 | D21: 123783.45 | E21: 130160 | F21: 74605.09 | G21: 49053.98 | H21: =G21 -> 49053.98
A22: WSWT2025800SM ผลรวม | C22: 142160 | D22: 123783.45 | E22: 139160 | F22: 74605.09 | G22: 49053.98 | H22: =G22 -> 49053.98
A23: WSWT2121670SM | B23: บจก.เอพีเอ็ม อะโกร | C23: 3000 | D23: 0 | E23: 0 | F23: 0 | G23: 0 | H23: =G23 -> 0
B24: บจก.แอมโก้เวท | C24: 60000 | D24: 40503.75 | E24: 60000 | F24: 14188.321 | G24: 27498.7 | H24: =G24 -> 27498.7
B25: บจก.หนองบัวฟีดมิลล์ | C25: 10000 | D25: 10500 | E25: 10000 | F25: 0 | G25: 10756.9 | H25: =G25 -> 10756.9
B26: ร้านกัลยาพาณิชย์ | C26: 6000 | D26: 0 | E26: 6000 | F26: 0 | G26: 0 | H26: =G26 -> 0
B27: บจก.เอเซียอควาเซอร์วิสเซส | C27: 3000 | D27: 3150 | E27: 3000 | F27: 3227.07 | G27: 0 | H27: =G27 -> 0
A28: WSWT2121670SM ผลรวม | C28: 82000 | D28: 54153.75 | E28: 79000 | F28: 17415.391 | G28: 38255.6 | H28: =G28 -> 38255.6
A29: WSWT2125800 | B29: โรงสีข้าวธัญญาวัฒน์ | C29: 6600 | D29: 0 | E29: 6600 | F29: 0 | G29: 0 | H29: =G29 -> 0
A30: WSWT2125800 ผลรวม | C30: 6600 | D30: 0 | E30: 6600 | F30: 0 | G30: 0 | H30: =G30 -> 0
A31: WSWT2321750 | B31: บจก.ปริ้นซ์ อโกร ไซแอนส์ | C31: 8000 | D31: 0 | E31: 8000 | F31: 0 | G31: 0 | H31: =G31 -> 0
A32: WSWT2321750 ผลรวม | C32: 8000 | D32: 0 | E32: 8000 | F32: 0 | G32: 0 | H32: =G32 -> 0
A33: WSWT2325650 | B33: คุณปราสาท เจริญธรรมรักษา | C33: 40000 | D33: 0 | E33: 40000 | F33: 0 | G33: 0 | H33: =G33 -> 0
A34: WSWT2325650 ผลรวม | C34: 40000 | D34: 0 | E34: 40000 | F34: 0 | G34: 0 | H34: =G34 -> 0
A35: WSWT2625650 | B35: บจก.กบินทร์อินทรีย์ | C35: 8000 | D35: 8400 | E35: 8000 | F35: 6749.8 | G35: 2749.8 | H35: =G35 -> 2749.8
B36: คุณธนนท์ อุทัยไพศาลวงศ์ | C36: 4563 | D36: 0 | E36: 0 | F36: 0 | G36: 0 | H36: =G36 -> 0
A37: WSWT2625650 ผลรวม | C37: 12563 | D37: 8400 | E37: 8000 | F37: 6749.8 | G37: 2749.8 | H37: =G37 -> 2749.8
A38: WSWT2625850SM | B38: บจก.ที.ซี.ยูเนี่ยน อโกรเทค | C38: 10000 | D38: 0 | E38: 10000 | F38: 0 | G38: 0 | H38: =G38 -> 0
A39: WSWT2625850SM ผลรวม | C39: 10000 | D39: 0 | E39: 10000 | F39: 0 | G39: 0 | H39: =G39 -> 0
A40: WSWT2825850 | B40: บจก.ไทยร่วมใจน้ำมันพืช | C40: 31500 | D40: 0 | E40: 10500 | F40: 0 | G40: 0 | H40: =G40 -> 0
A41: WSWT2825850 ผลรวม | C41: 31500 | D41: 0 | E41: 10500 | F41: 0 | G41: 0 | H41: =G41 -> 0
...

Sheet 4(Fc) แยกลูกค้า
A1: เลขที่ SO | B1: ประมาณการ
A2: วันส่ง | B2: (หลายรายการ) | D2: 12
A4: ประเภท | B4: ชื่อลูกค้า | C4: ผลรวม ของ จำนวนส่ง | D4: ผลรวม ของ ค้างพิมพ์ | E4: ผลรวม ของ ค้างตัด | F4: ผลรวม ของ ใช้ | G4: ผลรวม ของ Stock | H4: ผลรวม ของ ค้างทอ
A5: ผลรวมทั้งหมด
D119: Cap พิมพ์ | E119: Cap ตัด | F119: Stock 16/7 บ่าย | G119: Cap ทอ | I119: วันทงาน
B120: lส่ง | C120: 1-16/7 | D120: 160000 | E120: 160000 | G120: 120000 | I120: 12
C121: 1975256 | D121: =+D120*I120 -> 1920000 | E121: =+E120*I120 -> 1920000 | F121: 825147 | G121: =+G120*I120 -> 1440000
A122: เบทาโกรส่งแล้ว | B122: 20700 | C122: 424374
A123: เบทาโกรส่งแล้ว | B123: 20800 | C123: 155973
C126: รวมส่ง+ค้างส่ง | D126: ส่วนต่างCapคงเหลือ | E126: ส่วนต่างCapคงเหลือ | F126: คงเหลือ
C127: =+C50+C121 -> 1975256 | D127: =+D121-D50 -> 1920000 | E127: =+E121-E50 -> 1920000 | F127: =+F121-F50 -> 825147 | G127: =+G121-G50 -> 1440000
B129: 20700VN 20/7 | G129: 350000

Sheet 6(Order+Fc) แยกลูกค้า
A1: เลขที่ SO | B1: (หลายรายการ)
A2: วันส่ง | B2: (หลายรายการ) | D2: 12 | I2: เมตร | J2: vn | K2: ใบ | P2: วัน
A4: ประเภท | B4: ชื่อลูกค้า | C4: ผลรวม ของ จำนวนส่ง | D4: ผลรวม ของ ค้างพิมพ์ | E4: ผลรวม ของ ค้างตัด | F4: ผลรวม ของ Stock | G4: ผลรวม ของ ใช้ | H4: ผลรวม ของ ค้างทอ
A5: WSWT1425800 | B5: หจก.ปึงเป้งน้ำ | C5: 10000 | D5: 10500 | E5: 10000 | F5: 5557 | G5: 6565.9 | H5: 1008.9 | I5: =H5 -> 1008.9
A6: WSWT1425800 ผลรวม | C6: 10000 | D6: 10500 | E6: 10000 | F6: 5557 | G6: 6565.9 | H6: 1008.9
A7: WSWT1621720SMFX | B7: โรงสีลิ้มย่งฮวด | C7: 5000 | D7: 5250 | E7: 5000 | F7: 3702.05 | G7: 3702.05 | H7: 0 | I7: =H7 -> 0
A8: WSWT1621720SMFX ผลรวม | C8: 5000 | D8: 5250 | E8: 5000 | F8: 3702.05 | G8: 3702.05 | H8: 0 | I8: =H8 -> 0
A9: WSWT1825800 | B9: บจก.ฟาร์เธอร์ส วิง ซัพพลาย | C9: 15000 | D9: 15750 | E9: 15000 | F9: 6301 | G9: 13201.65 | H9: 6900.65 | I9: =H9 -> 6900.65
A10: WSWT1825800 ผลรวม | C10: 15000 | D10: 15750 | E10: 15000 | F10: 6301 | G10: 13201.65 | H10: 6900.65 | I10: =H10 -> 6900.65
A11: WSWT1825800SM | B11: บจก.ไบโอกรีนนิค | C11: 10000 | D11: 10500 | E11: 10000 | F11: 8242.3 | G11: 8242.3 | H11: 0
A12: WSWT1825800SM ผลรวม | C12: 10000 | D12: 10500 | E12: 10000 | F12: 8242.3 | G12: 8242.3 | H12: 0 | I12: =H12 -> 0
A13: WSWT1921720 | B13: บจก.เคอรี่ฟลาวมิลล์ | C13: 473000 | D13: 391650 | E13: 473000 | F13: 2854 | G13: 350633.03 | H13: 347779.03
A14: WSWT1921720 ผลรวม | C14: 473000 | D14: 391650 | E14: 473000 | F14: 2854 | G14: 350633.03 | H14: 347779.03 | I14: =H14 -> 347779.03 | P14: 15000 | Q14: =+K14/P14 -> 0
A15: WSWT1925800 | B15: บจก.เพรซิเดนท์ฟลาวมิลล์ | C15: 70000 | D15: 0 | E15: 14790 | F15: 0 | G15: 0 | H15: 0
B16: บจก.ไลม์มาสเตอร์ | C16: 10000 | D16: 10500 | E16: 10000 | F16: 0 | G16: 9359.9 | H16: 9359.9 | I16: =H16 -> 9359.9
B17: บจก.เอ็กเซลเล้นท์ | C17: 30000 | D17: 31500 | E17: 30000 | F17: 0 | G17: 26403.3 | H17: 26403.3 | I17: =H17 -> 26403.3
A18: WSWT1925800 ผลรวม | C18: 110000 | D18: 42000 | E18: 54790 | F18: 0 | G18: 35763.2 | H18: 35763.2 | I18: =H18 -> 35763.2
A19: WSWT2025650 | B19: บจก.เอเชียเหมืองแร่ | C19: 20000 | D19: 21000 | E19: 20000 | F19: 7658 | G19: 18719.8 | H19: 11061.8 | I19: =H19 -> 11061.8
A20: WSWT2025650 ผลรวม | C20: 20000 | D20: 21000 | E20: 20000 | F20: 7658 | G20: 18719.8 | H20: 11061.8 | I20: =H20 -> 11061.8 | P20: 16000 | Q20: =+K20/P20 -> 0
A21: WSWT2025800 | B21: บจก.เคอรี่ฟลาวมิลล์ | C21: 5000 | D21: 5250 | E21: 5000 | F21: 4679.95 | G21: 4679.95 | H21: 0
B22: บจก.เบทาโกร | C22: 60000 | D22: 52500 | E22: 50000 | F22: 53784.5 | G22: 53784.5 | H22: 0 | I22: =H22 -> 0
B23: บจก.อินเทคค์ โกลบอล | C23: 150000 | D23: 157500 | E23: 150000 | F23: 0 | G23: 157162.5 | H23: 157162.5
A24: WSWT2025800 ผลรวม | C24: 215000 | D24: 215250 | E24: 205000 | F24: 58464.45 | G24: 215626.95 | H24: 157162.5 | I24: =H24 -> 157162.5
A25: WSWT2025800SM | B25: บจก.ไทยธรรมดี | C25: 40000 | D25: 42000 | E25: 40000 | F25: 0 | G25: 43027.6 | H25: 43027.6
B26: บจก.อินเทคค์ โกลบอล | C26: 144842 | D26: 114858.45 | E26: 136515 | F26: 9837.3247 | G26: 114612.32 | H26: 104775 | I26: =H26 -> 104775
B27: บจก.เอพีเอ็ม อะโกร | C27: 6000 | D27: 6300 | E27: 6000 | F27: 6621.78 | G27: 6621.78 | H27: 0
B28: บจก.เอสพีเอ็ม อาหารสัตว์ | C28: 35500 | D28: 26250 | E28: 25000 | F28: 5518.15 | G28: 27590.75 | H28: 22072.6 | I28: =H28 -> 22072.6
B29: บจก.เอ.เจ.ฟาร์ม่าแล็บ | C29: 20000 | D29: 4152.75 | E29: 20000 | F29: 4118.9881 | G29: 4118.9881 | H29: 0 | I29: =H29 -> 0
B30: คุณชายชล จันทร์สว่างกูล | C30: 2500 | D30: 1575 | E30: 2500 | F30: 1487.805 | G30: 1487.805 | H30: 0 | I30: =H30 -> 0
B31: บจก.มารีน หรีดเดอร์ | C31: 10000 | D31: 10500 | E31: 10000 | F31: 8801.1 | G31: 8801.1 | H31: 0 | P31: 15000 | Q31: =+K31/P31 -> 0
B32: บจก.วีซีเอฟ | C32: 55000 | D32: 57750 | E32: 55000 | F32: 32270.7 | G32: 59162.95 | H32: 26892.25 | I32: =H32 -> 26892.25
A33: WSWT2025800SM ผลรวม | C33: 313842 | D33: 263386.2 | E33: 295015 | F33: 68655.848 | G33: 265423.3 | H33: 196767.45 | I33: =H33 -> 196767.45
A34: WSWT2121670SM | B34: บจก.ที.ซี.ยูเนี่ยน อโกรเทค | C34: 8000 | D34: 8400 | E34: 8000 | F34: 0 | G34: 8605.52 | H34: 8605.52 | I34: =H34 -> 8605.52
B35: บจก.เอพีเอ็ม อะโกร | C35: 16000 | D35: 16800 | E35: 16000 | F35: 10891.04 | G35: 18105.12 | H35: 7214.08 | I35: =H35 -> 7214.08
B36: บจก.เอสพีเอ็ม อาหารสัตว์ | C36: 5000 | D36: 0 | E36: 232 | F36: 0 | G36: 0 | H36: 0 | I36: =H36 -> 0
B37: บจก.แอมโก้เวท | C37: 285000 | D37: 220575.6 | E37: 212078 | F37: 42036.557 | G37: 227589.76 | H37: 185553.2 | I37: =H37 -> 185553.2
B38: บจก.หนองบัวฟีดมิลล์ | C38: 10000 | D38: 10500 | E38: 10000 | F38: 0 | G38: 10756.9 | H38: 10756.9 | I38: =H38 -> 10756.9
B39: คุณนพวินทร์ รัตนเศรษฐ์เมธา | C39: 5000 | D39: 5250 | E39: 5000 | F39: 5378.45 | G39: 5378.45 | H39: 0 | I39: =H39 -> 0
B40: บจก.เอ็นบี ดิสทริบิวชั่น | C40: 10000 | D40: 10500 | E40: 10000 | F40: 0 | G40: 10756.9 | H40: 10756.9 | I40: =H40 -> 10756.9
B41: บจก.บลูฟาโล่ | C41: 10000 | D41: 10500 | E41: 10000 | F41: 0 | G41: 10756.9 | H41: 10756.9
...

Sheet 6(Order)
A2: เลขที่ SO | B2: (หลายรายการ)
A3: วันส่ง | B3: (หลายรายการ)
A4: ชื่อลูกค้า | B4: (ทั้งหมด)
A6: ประเภท | B6: ผลรวม ของ จำนวนส่ง | C6: ผลรวม ของ ค้างพิมพ์ | D6: ผลรวม ของ ค้างตัด | E6: ผลรวม ของ ใช้ | F6: ผลรวม ของ Stock | G6: ผลรวม ของ ค้างทอ
A7: WSWT1425800 | B7: 10000 | C7: 10500 | D7: 10000 | E7: 6565.9 | F7: 5557 | G7: 1008.9
A8: WSWT1621720SMFX | B8: 5000 | C8: 5250 | D8: 5000 | E8: 3702.05 | F8: 3702.05 | G8: 0
A9: WSWT1825800SM | B9: 10000 | C9: 10500 | D9: 10000 | E9: 8242.3 | F9: 8242.3 | G9: 0
A10: WSWT1921720 | B10: 198000 | C10: 102900 | D10: 198000 | E10: 108602.78 | F10: 2854 | G10: 105748.78
A11: WSWT1925800 | B11: 70000 | C11: 0 | D11: 14790 | E11: 0 | F11: 0 | G11: 0 | L11: =76*2500 -> 190000
A12: WSWT2021850UV | B12: 1345000 | C12: 618123.45 | D12: 1345000 | E12: 562935.53 | F12: 73641.007 | G12: 489294.53
A13: WSWT2025650 | B13: 20000 | C13: 21000 | D13: 20000 | E13: 18719.8 | F13: 7658 | G13: 11061.8
A14: WSWT2025800 | B14: 65000 | C14: 57750 | D14: 55000 | E14: 58464.45 | F14: 58464.45 | G14: 0
A15: WSWT2025800SM | B15: 153842 | C15: 95386.2 | D15: 135015 | E15: 95548.098 | F15: 68655.848 | G15: 26892.25
A16: WSWT2121670SM | B16: 219000 | C16: 146025.6 | D16: 141310 | E16: 152109.85 | F16: 58306.047 | G16: 93803.8
A17: WSWT2125650 | B17: 29000 | C17: 10500 | D17: 29000 | E17: 30887.67 | F17: 7700 | G17: 23187.67
A18: WSWT2125800 | B18: 10000 | C18: 8400 | D18: 10000 | E18: 10253.98 | F18: 10253.98 | G18: 0
A19: WSWT2221940 | B19: 239700 | C19: 128625 | D19: 239700 | E19: 127579.28 | F19: 37618 | G19: 89961.279
A20: WSWT2321112512551 | B20: 108000 | C20: 113400 | D20: 108000 | E20: 116174.52 | F20: 62765.26 | G20: 53409.26
A21: WSWT2625650 | B21: 8800 | C21: 0 | D21: 5300 | E21: 5997.321 | F21: 0 | G21: 5997.321
A22: WSWT262575051 | B22: 16000 | C22: 8400 | D22: 16000 | E22: 9499.6 | F22: 9499.6 | G22: 0
A23: WSWT2625800 | B23: 10000 | C23: 10500 | D23: 10000 | E23: 11595.1 | F23: 11595.1 | G23: 0
... A26: ผลรวมทั้งหมด | B26: 2597342 | C26: 1371063.8 | D26: 2423776 | E26: 1392443.6 | F26: 469692.54 | G26: 922751.05
A37: ยอดส่ง 1/1/68 - 17/1/68 | B37: 1287052
A38: Order+ส่ง | B38: =++B22+B37 -> 1303052
A39: ประมาณการ | I39: 0
A41: Order+ส่ง+ประมาณการ | B41: =+B22+B37+B39+B29 -> 1303052 | C41: =+C22+C37+C39+C29 -> 8400 | D41: =+D22+D37+D39+D29 -> 16000 | E41: =+E22+E37+E39+E29 -> 9499.6 | F41: =+F22+F37+F39+F29 -> 9499.6 | G41: =+G22+G37+G39+G29 -> 0
B43: 3000000 | I43: 9
B45: =+B41-B43 -> -1696948
D46: =+D22/I43 -> 1777.7778
C47: =+C41/I43 -> 933.33333 | D47: =+D41/I43 -> 1777.7778 | G47: =+G41/I43 -> 0

Sheet 6(Order) แยกลูกค้า
A1: เลขที่ SO | B1: (หลายรายการ)
A2: วันส่ง | B2: (หลายรายการ)
A4: ประเภท | B4: ชื่อลูกค้า | C4: ผลรวม ของ จำนวนส่ง | D4: ผลรวม ของ ค้างพิมพ์ | E4: ผลรวม ของ ค้างตัด | F4: ผลรวม ของ Stock | G4: ผลรวม ของ ค้างทอ | I4: vn
A5: WSWT1425800 | B5: หจก.ปึงเป้งน้ำ | C5: 10000 | D5: 10500 | E5: 10000 | F5: 5557 | G5: 1008.9 | H5: =G5 -> 1008.9
A6: WSWT1425800 ผลรวม | C6: 10000 | D6: 10500 | E6: 10000 | F6: 5557 | G6: 1008.9 | H6: =G6 -> 1008.9
A7: WSWT1825800SM | B7: บจก.ไบโอกรีนนิค | C7: 10000 | D7: 10500 | E7: 10000 | F7: 8242.3 | G7: 0 | H7: =G7 -> 0
A8: WSWT1825800SM ผลรวม | C8: 10000 | D8: 10500 | E8: 10000 | F8: 8242.3 | G8: 0
A9: WSWT1921720 | B9: บจก.เคอรี่ฟลาวมิลล์ | C9: 30000 | D9: 0 | E9: 30000 | F9: 0 | G9: 0 | H9: =G9 -> 0
A10: WSWT1921720 ผลรวม | C10: 30000 | D10: 0 | E10: 30000 | F10: 0 | G10: 0 | H10: =G10 -> 0
A11: WSWT1925800 | B11: บจก.เพรซิเดนท์ฟลาวมิลล์ | C11: 70000 | D11: 0 | E11: 14790 | F11: 0 | G11: 0
A12: WSWT1925800 ผลรวม | C12: 70000 | D12: 0 | E12: 14790 | F12: 0 | G12: 0 | H12: =G12 -> 0
A13: WSWT2025800 | B13: บจก.เบทาโกร | C13: 40000 | D13: 31500 | E13: 30000 | F13: 32270.7 | G13: 0 | H13: =G13 -> 0
A14: WSWT2025800 ผลรวม | C14: 40000 | D14: 31500 | E14: 30000 | F14: 32270.7 | G14: 0 | H14: =G14 -> 0
A15: WSWT2025800SM | B15: บจก.อินเทคค์ โกลบอล | C15: 44842 | D15: 9858.45 | E15: 36515 | F15: 9837.3247 | G15: 0
B16: บจก.เอพีเอ็ม อะโกร | C16: 6000 | D16: 6300 | E16: 6000 | F16: 6621.78 | G16: 0 | H16: =G16 -> 0
B17: บจก.เอสพีเอ็ม อาหารสัตว์ | C17: 15500 | D17: 5250 | E17: 5000 | F17: 5518.15 | G17: 0
B18: บจก.เอ.เจ.ฟาร์ม่าแล็บ | C18: 20000 | D18: 4152.75 | E18: 20000 | F18: 4118.9881 | G18: 0 | H18: =G18 -> 0
B19: คุณชายชล จันทร์สว่างกูล | C19: 2500 | D19: 1575 | E19: 2500 | F19: 1487.805 | G19: 0 | H19: =G19 -> 0
B20: บจก.มารีน หรีดเดอร์ | C20: 10000 | D20: 10500 | E20: 10000 | F20: 8801.1 | G20: 0 | H20: =G20 -> 0
A21: WSWT2025800SM ผลรวม | C21: 98842 | D21: 37636.2 | E21: 80015 | F21: 36385.148 | G21: 0 | H21: =G21 -> 0
A22: WSWT2121670SM | B22: บจก.ที.ซี.ยูเนี่ยน อโกรเทค | C22: 8000 | D22: 8400 | E22: 8000 | F22: 0 | G22: 8605.52
B23: บจก.เอพีเอ็ม อะโกร | C23: 10000 | D23: 10500 | E23: 10000 | F23: 5518.15 | G23: 5797.55 | H23: =G23 -> 5797.55
B24: บจก.เอสพีเอ็ม อาหารสัตว์ | C24: 5000 | D24: 0 | E24: 232 | F24: 0 | G24: 0
B25: บจก.แอมโก้เวท | C25: 155000 | D25: 84075.6 | E25: 82078 | F25: 42036.557 | G25: 45713.5 | H25: =G25 -> 45713.5
B26: บจก.บลูฟาโล่ | C26: 10000 | D26: 10500 | E26: 10000 | F26: 0 | G26: 10756.9
A27: WSWT2121670SM ผลรวม | C27: 188000 | D27: 113475.6 | E27: 110310 | F27: 47554.707 | G27: 70873.47 | H27: =G27 -> 70873.47
A28: WSWT2125650 | B28: บจก.หนองบัวฟีดมิลล์ | C28: 15000 | D28: 0 | E28: 15000 | F28: 0 | G28: 16554.45 | H28: =G28 -> 16554.45
B29: บจก.ไลม์มาสเตอร์ | C29: 10000 | D29: 10500 | E29: 10000 | F29: 7700 | G29: 2218.7 | H29: =G29 -> 2218.7
A30: WSWT2125650 ผลรวม | C30: 25000 | D30: 10500 | E30: 25000 | F30: 7700 | G30: 18773.15
A31: WSWT2125800 | B31: บจก.ทีเจทีเทรดเดอร์ | C31: 2000 | D31: 0 | E31: 2000 | F31: 2319.02 | G31: 0 | H31: =G31 -> 0
A32: WSWT2125800 ผลรวม | C32: 2000 | D32: 0 | E32: 2000 | F32: 2319.02 | G32: 0 | H32: =G32 -> 0
A33: WSWT2221940 | B33: กรมการข้าว | C33: 239700 | D33: 128625 | E33: 239700 | F33: 37618 | G33: 89961.279 | H33: =G33 -> 89961.279
A34: WSWT2221940 ผลรวม | C34: 239700 | D34: 128625 | E34: 239700 | F34: 37618 | G34: 89961.279 | H34: =G34 -> 89961.279
A35: WSWT2321112512551 | B35: บจก.น้ำตาลทิพย์สุโขทัย | C35: 108000 | D35: 113400 | E35: 108000 | F35: 62765.26 | G35: 53409.26 | H35: =G35 -> 53409.26
A36: WSWT2321112512551 ผลรวม | C36: 108000 | D36: 113400 | E36: 108000 | F36: 62765.26 | G36: 53409.26 | H36: =G36 -> 53409.26
A37: WSWT262575051 | B37: บจก.กบินทร์อินทรีย์ | C37: 8000 | D37: 0 | E37: 8000 | F37: 0 | G37: 0 | H37: =G37 -> 0
A38: WSWT262575051 ผลรวม | C38: 8000 | D38: 0 | E38: 8000 | F38: 0 | G38: 0 | H38: =G38 -> 0
A39: WSWT2625850SM | B39: บจก.ที.ซี.ยูเนี่ยน อโกรเทค | C39: 15000 | D39: 0 | E39: 15000 | F39: 18649.95 | G39: 0 | H39: =G39 -> 0
A40: WSWT2625850SM ผลรวม | C40: 15000 | D40: 0 | E40: 15000 | F40: 18649.95 | G40: 0
A41: WSWT2825850 | B41: บจก.ไทยร่วมใจน้ำมันพืช | C41: 50000 | D41: 23803.5 | E41: 41661 | F41: 5880 | G41: 22385.466 | H41: =G41 -> 22385.466
...

Sheet 6(Fc) แยกลูกค้
A1: เลขที่ SO | B1: ประมาณการ
A2: วันส่ง | B2: (หลายรายการ) | D2: 12
A4: ประเภท | B4: ชื่อลูกค้า | C4: ผลรวม ของ จำนวนส่ง | D4: ผลรวม ของ ค้างพิมพ์ | E4: ผลรวม ของ ค้างตัด | F4: ผลรวม ของ Stock | G4: ผลรวม ของ ใช้ | H4: ผลรวม ของ ค้างทอ
A5: WSWT1825800 | B5: บจก.ฟาร์เธอร์ส วิง ซัพพลาย | C5: 15000 | D5: 15750 | E5: 15000 | F5: 6301 | G5: 13201.65 | H5: 6900.65
A6: WSWT1825800 ผลรวม | C6: 15000 | D6: 15750 | E6: 15000 | F6: 6301 | G6: 13201.65 | H6: 6900.65
A7: WSWT1921720 | B7: บจก.เคอรี่ฟลาวมิลล์ | C7: 275000 | D7: 288750 | E7: 275000 | F7: 0 | G7: 242030.25 | H7: 242030.25
A8: WSWT1921720 ผลรวม | C8: 275000 | D8: 288750 | E8: 275000 | F8: 0 | G8: 242030.25 | H8: 242030.25
A9: WSWT1925800 | B9: บจก.ไลม์มาสเตอร์ | C9: 10000 | D9: 10500 | E9: 10000 | F9: 0 | G9: 9359.9 | H9: 9359.9
B10: บจก.เอ็กเซลเล้นท์ | C10: 30000 | D10: 31500 | E10: 30000 | F10: 0 | G10: 26403.3 | H10: 26403.3
A11: WSWT1925800 ผลรวม | C11: 40000 | D11: 42000 | E11: 40000 | F11: 0 | G11: 35763.2 | H11: 35763.2
A12: WSWT2025800 | B12: บจก.อินเทคค์ โกลบอล | C12: 150000 | D12: 157500 | E12: 150000 | F12: 0 | G12: 157162.5 | H12: 157162.5
A13: WSWT2025800 ผลรวม | C13: 150000 | D13: 157500 | E13: 150000 | F13: 0 | G13: 157162.5 | H13: 157162.5
A14: WSWT2025800SM | B14: บจก.ไทยธรรมดี | C14: 40000 | D14: 42000 | E14: 40000 | F14: 0 | G14: 43027.6 | H14: 43027.6
B15: บจก.อินเทคค์ โกลบอล | C15: 100000 | D15: 105000 | E15: 100000 | F15: 0 | G15: 104775 | H15: 104775
B16: บจก.เอสพีเอ็ม อาหารสัตว์ | C16: 20000 | D16: 21000 | E16: 20000 | F16: 0 | G16: 22072.6 | H16: 22072.6
A17: WSWT2025800SM ผลรวม | C17: 160000 | D17: 168000 | E17: 160000 | F17: 0 | G17: 169875.2 | H17: 169875.2
A18: WSWT2121670SM | B18: บจก.แอมโก้เวท | C18: 130000 | D18: 136500 | E18: 130000 | F18: 0 | G18: 139839.7 | H18: 139839.7
A19: WSWT2121670SM ผลรวม | C19: 130000 | D19: 136500 | E19: 130000 | F19: 0 | G19: 139839.7 | H19: 139839.7
A20: WSWT2325650 | B20: บจก.ซิเบลโก้(สบปราบ) | C20: 20000 | D20: 21000 | E20: 20000 | F20: 19837.4 | G20: 19837.4 | H20: 0
A21: WSWT2325650 ผลรวม | C21: 20000 | D21: 21000 | E21: 20000 | F21: 19837.4 | G21: 19837.4 | H21: 0
A22: WSWT2625650 | B22: บจก.โอเชี่ยนฟีด | C22: 40000 | D22: 0 | E22: 40000 | F22: 0 | G22: 48615.6 | H22: 48615.6
B23: บจก.กบินทร์อินทรีย์ | C23: 10000 | D23: 10500 | E23: 10000 | F23: 0 | G23: 11874.5 | H23: 11874.5
A24: WSWT2625650 ผลรวม | C24: 50000 | D24: 10500 | E24: 50000 | F24: 0 | G24: 60490.1 | H24: 60490.1
A25: WSWT2625800 | B25: บจก.ที.ซี.ยูเนี่ยน อโกรเทค | C25: 20000 | D25: 0 | E25: 20000 | F25: 3896 | G25: 24866.6 | H25: 20970.6
A26: WSWT2625800 ผลรวม | C26: 20000 | D26: 0 | E26: 20000 | F26: 3896 | G26: 24866.6 | H26: 20970.6
A27: WSWT2825850 | B27: บจก.ที.ซี.ยูเนี่ยน อโกรเทค | C27: 10000 | D27: 0 | E27: 10000 | F27: 0 | G27: 13550.9 | H27: 13550.9
A28: WSWT2825850 ผลรวม | C28: 10000 | D28: 0 | E28: 10000 | F28: 0 | G28: 13550.9 | H28: 13550.9
A29: WSWTSCL052325650 | B29: พันธุ์ข้าว | C29: 10000 | D29: 10500 | E29: 10000 | F29: 0 | G29: 9918.7 | H29: 9918.7
A30: WSWTSCL052325650 ผลรวม | C30: 10000 | D30: 10500 | E30: 10000 | F30: 0 | G30: 9918.7 | H30: 9918.7
A31: ผลรวมทั้งหมด | C31: 880000 | D31: 850500 | E31: 880000 | F31: 30034.4 | G31: 886536.2 | H31: 856501.8
H41: 296578.28
H43: =+GETPIVOTDATA("ผลรวม ของ ค้างทอ",$A$4)+H41 -> 1153080.1
I119: วันทงาน
I120: 12
C121: 1975256 | D121: =+D120*I120 -> 0 | E121: =+E120*I120 -> 0 | F121: 825147 | G121: =+G120*I120 -> 0
A122: เบทาโกรส่งแล้ว | B122: 20700 | C122: 424374
A123: เบทาโกรส่งแล้ว | B123: 20800 | C123: 155973
C126: รวมส่ง+ค้างส่ง | D126: ส่วนต่างCapคงเหลือ | E126: ส่วนต่างCapคงเหลือ | F126: คงเหลือ
C127: =+C50+C121 -> 1975256 | D127: =+D121-D50 -> 0 | E127: =+E121-E50 -> 0 | F127: =+F121-F50 -> 825147 | G127: =+G121-G50 -> 0
B129: 20700VN 20/7 | G129: 350000

Sheet ค้างทอ10-6-68
A3: ผลรวม ของ ค้างทอ | B3: ป้ายชื่อคอลัมน์
A4: ป้ายชื่อแถว | B4: 45814 | C4: 45815 | D4: 45816 | E4: 45817 | F4: 45819 | G4: 45820 | H4: 45821 | I4: 45822 | J4: 45823 | K4: 45824 | L4: 45826 | M4: 45828 | N4: 45830 | O4: 45833 | P4: ผลรวมทั้งหมด
A5: WSWT1425800 | D5: 1008.9 | P5: 1008.9
A6: WSWT1621720SMFX | K6: 0 | P6: 0
A7: WSWT1825800SM | C7: 0 | P7: 0
A8: WSWT1921720 | C8: 1546.55 | E8: 23679.15 | G8: 13117.83 | I8: 40443.15 | J8: 13760.45 | K8: 13201.65 | P8: 105748.78
A9: WSWT1925800 | B9: 0 | P9: 0
A10: WSWT2021850UV | O10: 489294.53 | P10: 489294.53
A11: WSWT2025650 | K11: 11061.8 | P11: 11061.8
A12: WSWT2025800 | H12: 0 | I12: 0 | L12: 0 | O12: 0 | P12: 0
A13: WSWT2025800SM | B13: 0 | C13: 0 | D13: 0 | E13: 0 | L13: 0 | N13: 26892.25 | P13: 26892.25
A14: WSWT2121670SM | B14: 0 | D14: 47130.03 | E14: 0 | G14: 10756.9 | K14: 10756.9 | L14: 16554.45 | O14: 8605.52 | P14: 93803.8
A15: WSWT2125650 | B15: 0 | C15: 6633.22 | F15: 16554.45 | P15: 25506.69
A16: WSWT2125800 | B16: 0 | E16: 0 | P16: 0
A17: WSWT2221940 | M17: 89961.279 | P17: 89961.279
A18: WSWT2321112512551 | L18: 0 | N18: 53409.26 | P18: 53409.26
A19: WSWT2625650 | D19: 5997.321 | P19: 5997.321
A20: WSWT262575051 | B20: 0 | J20: 0 | P20: 0
A21: WSWT2625800 | G21: 0 | P21: 0
A22: WSWT2625850SM | G22: 0 | N22: 0 | P22: 0
A23: WSWT2825850 | F23: 22385.466 | P23: 22385.466
A24: ผลรวมทั้งหมด | B24: =SUM(B5:B23) -> 0 | C24: =SUM(C5:C23) -> 8179.77 | D24: =SUM(D5:D23) -> 54136.251 | E24: =SUM(E5:E23) -> 23679.15 | F24: =SUM(F5:F23) -> 38939.916 | G24: =SUM(G5:G23) -> 23874.73 | H24: =SUM(H5:H23) -> 0 | I24: =SUM(I5:I23) -> 40443.15 | ... P24: =SUM(P5:P23) -> 925070.07

Sheet 10-6-68
B2: เรียงกำหนดส่ง | D2: ลบ 0 | T2: เรียง 1
B3: ข้อมูลUpdate ณ. วันที่ | D3: 45818 | E3: เวลา | G3: 11.04
A4: วันรับออร์เดอร์/แบบ | B4: เลขที่ SO | C4: ชื่อลูกค้า | E4: 10.3 | I4: น้ำหนัก | L4: บิด/จับจีบ | M4: ถุงใน | Q4: 44873 | S4: วิธีบรรจุ | T4: วันส่ง | U4: จำนวนส่ง | V4: ตัดเย็บ (ใบ) | W4: 44873 | X4: พิมพ์ (ใบ) | Y4: 44876 | Z4: ผ้าทอ (เมตร) Updateณ | AB4: 44876 | AD4: ผ้าเคลือบ(เมตร) | AF4: หมายเหตุ | AG4: เครื่อง
A5: วันรับออร์เดอร์/แบบ | B5: เลขที่ SO | C5: ชื่อลูกค้า | D5: ตรา | E5: กว้าง | F5: ยาว | G5: สี | H5: เคลือบ | I5: กรัม/ใบ | J5: * | K5: aw | L5: บิด/จับจีบ | M5: กว้าง | N5: ยาว | O5: หนา | P5: ใช้(กก.) | Q5: Stock(กก.) | R5: ผลิต(กก.) | S5: วิธีบรรจุ | T5: วันส่ง | U5: จำนวนส่ง | V5: StockFG | W5: ค้างตัด | X5: พิมพ์แล้ว | Y5: ค้างพิมพ์ | Z5: ประเภท | AA5: ใช้ | AB5: Stock | AC5: ค้างทอ | AD5: Stock | AE5: ค้างเคลือบ | AF5: หมายเหตุ | AG5: ที่พิมพ์ได้ | AH5: process | AI5: Lead time | AJ5: วันที่ส่งPL | AK5: เคลือบ | AL5: ได้ ART | AM5: พิมพ์ | AN5: จีบ-บิด | AO5: ตัด-เย็บ | AP5: ทอ | AQ5: สวมถุง | AR5: เย็บปาก | AS5: PT | AT5: ม้วน | AU5: ตัด | AV5: ตอกตาไก่ | AW5: GROUP | AX5: ART | AY5: หมายเหตุปัญหา | AZ5: ราคา/ใบ | BA5: ราคารวม | BB5: workweek | BC5: เส้นเทป | BD5: จำนวน
A6: 45800 | B6: MK68-000701 | C6: หจก.ปึงเป้งน้ำ | D6: เกลือตรามือ 10กก | E6: 14 | F6: 22 | G6: ขาว | H6: ใส | I6: 42 | J6: ± | K6: 5 | L6: ไม่ | M6: ไม่สวมถุงใน | N6: 0 | O6: 0 | P6: 0 | Q6: 0 | R6: 0 | S6: 500กระสอบแบนเต็มใบ | T6: 45821 | U6: 10000 | V6: 0 | W6: 10000 | X6: 0 | Y6: 10500 | Z6: WSWT1425800 | AA6: 6565.9 | AB6: 5557 | AC6: 1008.9 | AD6: 1220 | AE6: 5345.9 | AF6: 0 | AG6: พร้อมส่ง | AH6: P6 | AI6: 4 | AJ6: 45821 | AK6: 45817 | AL6: 45810 | AM6: 45818 | AN6: 45819 | AO6: 45820 | AP6: 45816 | AQ6: 0 | AR6: 0 | AS6: 0 | AT6: 0 | AU6: 0 | AV6: 0 | AW6: งานเคลือบ+พิมพ์ | AX6: / | AY6: 0 | AZ6: 0 | BA6: 0 | BB6: 0 | BC6: WRWT25800/WRWT25800 | BD6: 56.4984
A7: 0 | B7: 0 | C7: 0 | D7: 0 | E7: 14 | F7: 22 | G7: ขาว | H7: 0 | I7: 36 | J7: ± | K7: 5 | L7: 0 | M7: 0 | N7: 0 | O7: 0 | P7: 0 | Q7: 0 | R7: 0 | S7: 0 | U7: 0 | V7: 0 | W7: 0 | X7: 0 | Y7: 0 | Z7: WSWT1425800 | AA7: 6565.9 | AB7: 5557 | AC7: 1008.9 | AD7: 1220 | AE7: 5345.9 | AF7: ระบุในSD | AG7: พร้อมส่ง | AH7: 0 | AI7: Lead time | AJ7: 0 | AK7: 0 | AL7: 0 | AM7: 0 | AN7: 0 | AO7: 0 | AP7: 0 | AQ7: 0 | AR7: 0 | AS7: 0 | AT7: 0 | AU7: 0 | AV7: 0 | AW7: 0 | AX7: 0 | AY7: 0 | AZ7: 0 | BA7: 0 | BB7: 0 | BC7: WRWT140800/WRWT25800 | BD7: 0
A8: ประมาณการ | B8: ประมาณการ | C8: บจก.ซัน ซีเมนต์ โพรเซส | D8: พระอาทิตย์(ปูนนอน-ชริงค์) | E8: 16 | F8: 25 | G8: ขาว | H8: ใส | I8: 50 | J8: ± | K8: 5 | L8: บิด | M8: 19 | N8: 28 | O8: 40 | P8: 65.624643 | Q8: 0 | R8: 65.624643 | S8: 500กระสอบ | T8: รอแจ้ง | U8: 5000 | V8: 0 | W8: 5000 | X8: 0 | Y8: 5250 | Z8: WSWT1625800SM | AA8: 3702.05 | AB8: 3372 | AC8: 330.05 | AD8: 0 | AE8: 3702.05 | AF8: 0 | AG8: ยังไม่ได้พิมพ์ | AH8: P8 | AI8: 4 | AJ8: รอแจ้ง | AK8: #VALUE! | AL8: #VALUE! | AM8: #VALUE! | AN8: #VALUE! | AO8: #VALUE! | AP8: #VALUE! | AQ8: #VALUE! | AR8: 0 | AS8: 0 | AT8: 0 | AU8: 0 | AV8: 0 | AW8: งานเคลือบ+พิมพ์ | AX8: รอART | AY8: 0 | AZ8: 0 | BA8: 0 | BB8: 0 | BC8: WRWT25800/WRWT25800 | BD8: 18.776178
A9: 0 | B9: 0 | C9: 0 | E9: 16 | F9: 25 | G9: ขาว | H9: 0 | I9: 45 | J9: ± | K9: 5 | L9: 0 | M9: 0 | N9: 0 | O9: 0 | P9: 0 | Q9: 0 | R9: 0 | S9: 0 | U9: 0 | V9: 0 | W9: 0 | X9: 0 | Y9: 0 | Z9: WSWT1625800SM | AA9: 3702.05 | AB9: 3372 | AC9: 330.05 | AD9: 0 | AE9: 3702.05 | AF9: ระบุในSD | AG9: พร้อมส่ง | AH9: 0 | AI9: Lead time | AJ9: 0 | AK9: 0 | AL9: 0 | AM9: 0 | AN9: 0 | AO9: 0 | AP9: 0 | AQ9: 0 | AR9: 0 | AS9: 0 | AT9: 0 | AU9: 0 | AV9: 0 | AW9: 0 | AX9: 0 | AY9: 0 | AZ9: 0 | BA9: 0 | BB9: 0 | BC9: WRWT160800/WRWT25800 | BD9: 0
