Workbook

Sheet Linkสูตรออร์เดอร์  (2)
B2: เรียงกำหนดส่ง | D2: ลบ 0 | T2: เรียง 1
B3: ข้อมูลUpdate ณ. วันที่ | D3: 45665 | E3: เวลา | G3: 11.1
A4: วันรับออร์เดอร์/แบบ | B4: เลขที่ SO | C4: ชื่อลูกค้า | D4: ตรา | E4: 10.3 | I4: น้ำหนัก | L4: บิด/จับจีบ | M4: ถุงใน | Q4: =[1]หน้าผ้า!$AC$13 -> 44873 | S4: วิธีบรรจุ | T4: วันส่ง | U4: จำนวนส่ง | V4: ตัดเย็บ (ใบ) | W4: =[1]หน้าผ้า!$AJ$13 -> 44873 | X4: พิมพ์ (ใบ) | Y4: =[1]หน้าผ้า!$AM$13 -> 44876 | Z4: ผ้าทอ (เมตร) Updateณ | AB4: =[1]หน้าผ้า!$AR$12 -> 44876 | AD4: ผ้าเคลือบ(เมตร) | AF4: หมายเหตุ | AG4: เครื่อง
B5: เลขที่ SO | C5: ชื่อลูกค้า | D5: ตรา | E5: กว้าง | F5: ยาว | G5: สี | H5: เคลือบ | I5: กรัม/ใบ | J5: * | K5: aw | L5: บิด/จับจีบ | M5: กว้าง | N5: ยาว | O5: หนา | P5: ใช้(กก.) | Q5: Stock(กก.) | R5: ผลิต(กก.) | S5: วิธีบรรจุ | T5: วันส่ง | U5: จำนวนส่ง | V5: StockFG | W5: ค้างตัด | X5: พิมพ์แล้ว | Y5: ค้างพิมพ์ | Z5: ประเภท | AA5: ใช้ | AB5: Stock | AC5: ค้างทอ | AD5: Stock | AE5: ค้างเคลือบ | AF5: หมายเหตุ | AG5: ที่พิมพ์ได้ | AH5: process | AI5: Lead time | AJ5: วันที่ส่งPL | AK5: เคลือบ | AL5: ได้ ART | AM5: พิมพ์ | AN5: จีบ-บิด | AO5: ตัด-เย็บ | AP5: ทอ | AQ5: สวมถุง | AR5: เย็บปาก | AS5: PT | AT5: ม้วน | AU5: ตัด | AV5: ตอกตาไก่ | AW5: GROUP | AX5: ART | AY5: หมายเหตุปัญหา | AZ5: ราคา/ใบ | BA5: ราคารวม | BB5: workweek | BC5: เส้นเทป | BD5: จำนวน
A6: =[2]หน้าผ้า!C15 -> 0 | B6: =[2]หน้าผ้า!B15 -> 0 | C6: =[2]หน้าผ้า!E15 -> 0 | D6: =[2]หน้าผ้า!F15 -> 0 | E6: =[2]หน้าผ้า!G15 -> 12 | F6: =[2]หน้าผ้า!H15 -> 16 | G6: =[2]หน้าผ้า!I15 -> ขาว | H6: =[2]หน้าผ้า!J15 -> 0 | I6: =[2]หน้าผ้า!L15 -> 25 | J6: =[2]หน้าผ้า!M15 -> ± | K6: =[2]หน้าผ้า!N15 -> 5 | L6: =[2]หน้าผ้า!R15 -> 0 | M6: =[2]หน้าผ้า!T15 -> 0 | N6: =[2]หน้าผ้า!U15 -> 0 | O6: =[2]หน้าผ้า!V15 -> 0 | P6: =[2]หน้าผ้า!AB15 -> 0 | Q6: =[2]หน้าผ้า!AC15 -> 0 | R6: =[2]หน้าผ้า!AD15 -> 0 | S6: =[2]หน้าผ้า!Z15 -> 0 | T6: =[2]หน้าผ้า!X15 -> 0 | U6: =[2]หน้าผ้า!AA15 -> 0 | V6: =[2]หน้าผ้า!AJ15 -> 0 | W6: =[2]หน้าผ้า!AL15 -> 0 | X6: =[2]หน้าผ้า!AM15 -> 0 | Y6: =[2]หน้าผ้า!AN15 -> 0 | Z6: =[2]หน้าผ้า!AO15 -> WSWT1221750 | AA6: =[2]หน้าผ้า!AQ15 -> #REF! | AB6: =[2]หน้าผ้า!AR15 -> #REF! | AC6: =[2]หน้าผ้า!AS15 -> #REF! | AD6: =[2]หน้าผ้า!AT15 -> #REF! | AE6: =[2]หน้าผ้า!AU15 -> #REF! | AF6: =[2]หน้าผ้า!AI15 -> ระบุในSD | AG6: =[3]หน้าผ้า!DC18 -> < Ord 20,000 | AH6: =[2]หน้าผ้า!DL15 -> 0 | AI6: =[2]หน้าผ้า!DM15 -> 0 | AJ6: =[2]หน้าผ้า!DN15 -> 0 | AK6: =[2]หน้าผ้า!DQ15 -> 0 | AL6: =[2]หน้าผ้า!DR15 -> 0 | AM6: =[2]หน้าผ้า!DS15 -> 0 | AN6: =[2]หน้าผ้า!DT15 -> 0 | AO6: =[2]หน้าผ้า!DU15 -> 0 | AP6: =[2]หน้าผ้า!DP15 -> 0 | AQ6: =[2]หน้าผ้า!DW15 -> 0 | AR6: =[2]หน้าผ้า!DX15 -> 0 | AS6: =[2]หน้าผ้า!DY15 -> 0 | AT6: =[2]หน้าผ้า!DZ15 -> 0 | AU6: =[2]หน้าผ้า!EA15 -> 0 | AV6: =[2]หน้าผ้า!EB15 -> 0 | AW6: =[2]หน้าผ้า!EC15 -> 0 | AX6: =[2]หน้าผ้า!ED15 -> 0 | AY6: =[2]หน้าผ้า!AG15 -> 0 | AZ6: =[2]หน้าผ้า!EG15 -> 0 | BA6: =[2]หน้าผ้า!EH15 -> 0 | BB6: =[2]หน้าผ้า!EI15 -> 0 | BC6: =[2]หน้าผ้า!BZ15 -> WRWT120750/WRWT21750 | BD6: =[2]หน้าผ้า!CA15 -> 0
A7: =[2]หน้าผ้า!C16 -> 0 | B7: =[2]หน้าผ้า!B16 -> 0 | C7: =[2]หน้าผ้า!E16 -> 0 | D7: =[2]หน้าผ้า!F16 -> 0 | E7: =[2]หน้าผ้า!G16 -> 14 | F7: =[2]หน้าผ้า!H16 -> 22 | G7: =[2]หน้าผ้า!I16 -> ขาว | H7: =[2]หน้าผ้า!J16 -> 0 | I7: =[2]หน้าผ้า!L16 -> 36 | J7: =[2]หน้าผ้า!M16 -> ± | K7: =[2]หน้าผ้า!N16 -> 5 | L7: =[2]หน้าผ้า!R16 -> 0 | M7: =[2]หน้าผ้า!T16 -> 0 | N7: =[2]หน้าผ้า!U16 -> 0 | O7: =[2]หน้าผ้า!V16 -> 0 | P7: =[2]หน้าผ้า!AB16 -> 0 | Q7: =[2]หน้าผ้า!AC16 -> 0 | R7: =[2]หน้าผ้า!AD16 -> 0 | S7: =[2]หน้าผ้า!Z16 -> 0 | T7: =[2]หน้าผ้า!X16 -> 0 | U7: =[2]หน้าผ้า!AA16 -> 0 | V7: =[2]หน้าผ้า!AJ16 -> 0 | W7: =[2]หน้าผ้า!AL16 -> 0 | X7: =[2]หน้าผ้า!AM16 -> 0 | Y7: =[2]หน้าผ้า!AN16 -> 0 | Z7: =[2]หน้าผ้า!AO16 -> WSWT1425800 | AA7: =[2]หน้าผ้า!AQ16 -> #REF! | AB7: =[2]หน้าผ้า!AR16 -> #REF! | AC7: =[2]หน้าผ้า!AS16 -> #REF! | AD7: =[2]หน้าผ้า!AT16 -> #REF! | AE7: =[2]หน้าผ้า!AU16 -> #REF! | AF7: =[2]หน้าผ้า!AI16 -> ระบุในSD | AG7: =[3]หน้าผ้า!DC19 -> ยังไม่ได้พิมพ์ | AH7: =[2]หน้าผ้า!DL16 -> 0 | AI7: =[2]หน้าผ้า!DM16 -> Lead time | AJ7: =[2]หน้าผ้า!DN16 -> 0 | AK7: =[2]หน้าผ้า!DQ16 -> 0 | AL7: =[2]หน้าผ้า!DR16 -> 0 | AM7: =[2]หน้าผ้า!DS16 -> 0 | AN7: =[2]หน้าผ้า!DT16 -> 0 | AO7: =[2]หน้าผ้า!DU16 -> 0 | AP7: =[2]หน้าผ้า!DP16 -> 0 | AQ7: =[2]หน้าผ้า!DW16 -> 0 | AR7: =[2]หน้าผ้า!DX16 -> 0 | AS7: =[2]หน้าผ้า!DY16 -> 0 | AT7: =[2]หน้าผ้า!DZ16 -> 0 | AU7: =[2]หน้าผ้า!EA16 -> 0 | AV7: =[2]หน้าผ้า!EB16 -> 0 | AW7: =[2]หน้าผ้า!EC16 -> 0 | AX7: =[2]หน้าผ้า!ED16 -> 0 | AY7: =[2]หน้าผ้า!AG16 -> 0 | AZ7: =[2]หน้าผ้า!EG16 -> 0 | BA7: =[2]หน้าผ้า!EH16 -> 0 | BB7: =[2]หน้าผ้า!EI16 -> 0 | BC7: =[2]หน้าผ้า!BZ16 -> WRWT140800/WRWT25800 | BD7: =[2]หน้าผ้า!CA16 -> 0
A8: =[2]หน้าผ้า!C17 -> 0 | B8: =[2]หน้าผ้า!B17 -> 0 | C8: =[2]หน้าผ้า!E17 -> 0 | D8: =[2]หน้าผ้า!F17 | E8: =[2]หน้าผ้า!G17 -> 16 | F8: =[2]หน้าผ้า!H17 -> 25 | G8: =[2]หน้าผ้า!I17 -> ขาว | H8: =[2]หน้าผ้า!J17 -> 0 | I8: =[2]หน้าผ้า!L17 -> 45 | J8: =[2]หน้าผ้า!M17 -> ± | K8: =[2]หน้าผ้า!N17 -> 5 | L8: =[2]หน้าผ้า!R17 -> 0 | M8: =[2]หน้าผ้า!T17 -> 0 | N8: =[2]หน้าผ้า!U17 -> 0 | O8: =[2]หน้าผ้า!V17 -> 0 | P8: =[2]หน้าผ้า!AB17 -> 0 | Q8: =[2]หน้าผ้า!AC17 -> 0 | R8: =[2]หน้าผ้า!AD17 -> 0 | S8: =[2]หน้าผ้า!Z17 -> 0 | T8: =[2]หน้าผ้า!X17 -> 0 | U8: =[2]หน้าผ้า!AA17 -> 0 | V8: =[2]หน้าผ้า!AJ17 -> 0 | W8: =[2]หน้าผ้า!AL17 -> 0 | X8: =[2]หน้าผ้า!AM17 -> 0 | Y8: =[2]หน้าผ้า!AN17 -> 0 | Z8: =[2]หน้าผ้า!AO17 -> WSWT1625800SM | AA8: =[2]หน้าผ้า!AQ17 -> #REF! | AB8: =[2]หน้าผ้า!AR17 -> #REF! | AC8: =[2]หน้าผ้า!AS17 -> #REF! | AD8: =[2]หน้าผ้า!AT17 -> #REF! | AE8: =[2]หน้าผ้า!AU17 -> #REF! | AF8: =[2]หน้าผ้า!AI17 -> ระบุในSD | AG8: =[3]หน้าผ้า!DC20 -> พร้อมส่ง | AH8: =[2]หน้าผ้า!DL17 -> 0 | AI8: =[2]หน้าผ้า!DM17 -> Lead time | AJ8: =[2]หน้าผ้า!DN17 -> 0 | AK8: =[2]หน้าผ้า!DQ17 -> 0 | AL8: =[2]หน้าผ้า!DR17 -> 0 | AM8: =[2]หน้าผ้า!DS17 -> 0 | AN8: =[2]หน้าผ้า!DT17 -> 0 | AO8: =[2]หน้าผ้า!DU17 -> 0 | AP8: =[2]หน้าผ้า!DP17 -> 0 | AQ8: =[2]หน้าผ้า!DW17 -> 0 | AR8: =[2]หน้าผ้า!DX17 -> 0 | AS8: =[2]หน้าผ้า!DY17 -> 0 | AT8: =[2]หน้าผ้า!DZ17 -> 0 | AU8: =[2]หน้าผ้า!EA17 -> 0 | AV8: =[2]หน้าผ้า!EB17 -> 0 | AW8: =[2]หน้าผ้า!EC17 -> 0 | AX8: =[2]หน้าผ้า!ED17 -> 0 | AY8: =[2]หน้าผ้า!AG17 -> 0 | AZ8: =[2]หน้าผ้า!EG17 -> 0 | BA8: =[2]หน้าผ้า!EH17 -> 0 | BB8: =[2]หน้าผ้า!EI17 -> 0 | BC8: =[2]หน้าผ้า!BZ17 -> WRWT160800/WRWT25800 | BD8: =[2]หน้าผ้า!CA17 -> 0
A9: =[2]หน้าผ้า!C18 -> 0 | B9: =[2]หน้าผ้า!B18 -> 0 | C9: =[2]หน้าผ้า!E18 -> 0 | D9: =[2]หน้าผ้า!F18 -> 0 | E9: =[2]หน้าผ้า!G18 -> 16 | F9: =[2]หน้าผ้า!H18 -> 25 | G9: =[2]หน้าผ้า!I18 -> ขาว | H9: =[2]หน้าผ้า!J18 -> 0 | I9: =[2]หน้าผ้า!L18 -> 45 | J9: =[2]หน้าผ้า!M18 -> ± | K9: =[2]หน้าผ้า!N18 -> 5 | L9: =[2]หน้าผ้า!R18 -> 0 | M9: =[2]หน้าผ้า!T18 -> 0 | N9: =[2]หน้าผ้า!U18 -> 0 | O9: =[2]หน้าผ้า!V18 -> 0 | P9: =[2]หน้าผ้า!AB18 -> 0 | Q9: =[2]หน้าผ้า!AC18 -> 0 | R9: =[2]หน้าผ้า!AD18 -> 0 | S9: =[2]หน้าผ้า!Z18 -> 0 | T9: =[2]หน้าผ้า!X18 -> 0 | U9: =[2]หน้าผ้า!AA18 -> 0 | V9: =[2]หน้าผ้า!AJ18 -> 0 | W9: =[2]หน้าผ้า!AL18 -> 0 | X9: =[2]หน้าผ้า!AM18 -> 0 | Y9: =[2]หน้าผ้า!AN18 -> 0 | Z9: =[2]หน้าผ้า!AO18 -> WSWT1625800 | AA9: =[2]หน้าผ้า!AQ18 -> #REF! | AB9: =[2]หน้าผ้า!AR18 -> #REF! | AC9: =[2]หน้าผ้า!AS18 -> #REF! | AD9: =[2]หน้าผ้า!AT18 -> #REF! | AE9: =[2]หน้าผ้า!AU18 -> #REF! | AF9: =[2]หน้าผ้า!AI18 -> ระบุในSD | AG9: =[3]หน้าผ้า!DC21 -> พิมพ์ไม่ครบ | AH9: =[2]หน้าผ้า!DL18 -> 0 | AI9: =[2]หน้าผ้า!DM18 -> Lead time | AJ9: =[2]หน้าผ้า!DN18 -> 0 | AK9: =[2]หน้าผ้า!DQ18 -> 0 | AL9: =[2]หน้าผ้า!DR18 -> 0 | AM9: =[2]หน้าผ้า!DS18 -> 0 | AN9: =[2]หน้าผ้า!DT18 -> 0 | AO9: =[2]หน้าผ้า!DU18 -> 0 | AP9: =[2]หน้าผ้า!DP18 -> 0 | AQ9: =[2]หน้าผ้า!DW18 -> 0 | AR9: =[2]หน้าผ้า!DX18 -> 0 | AS9: =[2]หน้าผ้า!DY18 -> 0 | AT9: =[2]หน้าผ้า!DZ18 -> 0 | AU9: =[2]หน้าผ้า!EA18 -> 0 | AV9: =[2]หน้าผ้า!EB18 -> 0 | AW9: =[2]หน้าผ้า!EC18 -> 0 | AX9: =[2]หน้าผ้า!ED18 -> 0 | AY9: =[2]หน้าผ้า!AG18 -> 0 | AZ9: =[2]หน้าผ้า!EG18 -> 0 | BA9: =[2]หน้าผ้า!EH18 -> 0 | BB9: =[2]หน้าผ้า!EI18 -> 0 | BC9: =[2]หน้าผ้า!BZ18 -> WRWT160800/WRWT25800 | BD9: =[2]หน้าผ้า!CA18 -> 0
A10: =[2]หน้าผ้า!C19 -> 45651 | B10: =[2]หน้าผ้า!B19 -> MK67-001730 | C10: =[2]หน้าผ้า!E19 -> โรงสีข้าวธัญญาวัฒน์ | D10: =[2]หน้าผ้า!F19 -> LUNG SHIN 12 kg | E10: =[2]หน้าผ้า!G19 -> 17 | F10: =[2]หน้าผ้า!H19 -> 26 | G10: =[2]หน้าผ้า!I19 -> ขาว | H10: =[2]หน้าผ้า!J19 -> 0 | I10: =[2]หน้าผ้า!L19 -> 48 | J10: =[2]หน้าผ้า!M19 -> ± | K10: =[2]หน้าผ้า!N19 -> 5 | L10: =[2]หน้าผ้า!R19 -> ไม่ | M10: =[2]หน้าผ้า!T19 -> ไม่สวมถุงใน | N10: =[2]หน้าผ้า!U19 -> 0 | O10: =[2]หน้าผ้า!V19 -> 0 | P10: =[2]หน้าผ้า!AB19 -> 0 | Q10: =[2]หน้าผ้า!AC19 -> 0 | R10: =[2]หน้าผ้า!AD19 -> 0 | S10: =[2]หน้าผ้า!Z19 -> 500กระสอบแบน | T10: =[2]หน้าผ้า!X19 -> 45668 | U10: =[2]หน้าผ้า!AA19 -> 8850 | V10: =[2]หน้าผ้า!AJ19 -> 0 | W10: =[2]หน้าผ้า!AL19 -> 8850 | X10: =[2]หน้าผ้า!AM19 -> 0 | Y10: =[2]หน้าผ้า!AN19 -> 9292.5 | Z10: =[2]หน้าผ้า!AO19 -> WSWT1725800 | AA10: =[2]หน้าผ้า!AQ19 -> 6799.8975 | AB10: =[2]หน้าผ้า!AR19 -> 6799.8975 | AC10: =[2]หน้าผ้า!AS19 -> 0 | AD10: =[2]หน้าผ้า!AT19 -> 0 | AE10: =[2]หน้าผ้า!AU19 -> 0 | AF10: =[2]หน้าผ้า!AI19 -> 0 | AG10: =[3]หน้าผ้า!DC22 -> ยังไม่ได้พิมพ์ | AH10: =[2]หน้าผ้า!DL19 -> P7 | AI10: =[2]หน้าผ้า!DM19 -> 2 | AJ10: =[2]หน้าผ้า!DN19 -> 45668 | AK10: =[2]หน้าผ้า!DQ19 -> 0 | AL10: =[2]หน้าผ้า!DR19 -> 45659 | AM10: =[2]หน้าผ้า!DS19 -> 45666 | AN10: =[2]หน้าผ้า!DT19 -> 45667 | AO10: =[2]หน้าผ้า!DU19 -> 45667 | AP10: =[2]หน้าผ้า!DP19 -> 45663 | AQ10: =[2]หน้าผ้า!DW19 -> 0 | AR10: =[2]หน้าผ้า!DX19 -> 0 | AS10: =[2]หน้าผ้า!DY19 -> 0 | AT10: =[2]หน้าผ้า!DZ19 -> 0 | AU10: =[2]หน้าผ้า!EA19 -> 0 | AV10: =[2]หน้าผ้า!EB19 -> 0 | AW10: =[2]หน้าผ้า!EC19 -> งานพิมพ์ | AX10: =[2]หน้าผ้า!ED19 -> รอART | AY10: =[2]หน้าผ้า!AG19 -> 10/1 เย็น | AZ10: =[2]หน้าผ้า!EG19 -> 0 | BA10: =[2]หน้าผ้า!EH19 -> 0 | BB10: =[2]หน้าผ้า!EI19 -> 0 | BC10: =[2]หน้าผ้า!BZ19 -> WRWT25800/WRWT25800 | BD10: =[2]หน้าผ้า!CA19 -> 0
A11: =[2]หน้าผ้า!C20 -> 0 | B11: =[2]หน้าผ้า!B20 -> 0 | C11: =[2]หน้าผ้า!E20 -> 0 | D11: =[2]หน้าผ้า!F20 -> 0 | E11: =[2]หน้าผ้า!G20 -> 17 | F11: =[2]หน้าผ้า!H20 -> 26 | G11: =[2]หน้าผ้า!I20 -> 0 | H11: =[2]หน้าผ้า!J20 -> 0 | I11: =[2]หน้าผ้า!L20 -> 48 | J11: =[2]หน้าผ้า!M20 -> ± | K11: =[2]หน้าผ้า!N20 -> 5 | L11: =[2]หน้าผ้า!R20 -> 0 | M11: =[2]หน้าผ้า!T20 -> 0 | N11: =[2]หน้าผ้า!U20 -> 0 | O11: =[2]หน้าผ้า!V20 -> 0 | P11: =[2]หน้าผ้า!AB20 -> 0 | Q11: =[2]หน้าผ้า!AC20 -> 0 | R11: =[2]หน้าผ้า!AD20 -> 0 | S11: =[2]หน้าผ้า!Z20 -> 0 | T11: =[2]หน้าผ้า!X20 -> 0 | U11: =[2]หน้าผ้า!AA20 -> 0 | V11: =[2]หน้าผ้า!AJ20 -> 0 | W11: =[2]หน้าผ้า!AL20 -> 0 | X11: =[2]หน้าผ้า!AM20 -> 0 | Y11: =[2]หน้าผ้า!AN20 -> 0 | Z11: =[2]หน้าผ้า!AO20 -> WSWT1725800 | AA11: =[2]หน้าผ้า!AQ20 -> 6799.8975 | AB11: =[2]หน้าผ้า!AR20 -> 6799.8975 | AC11: =[2]หน้าผ้า!AS20 -> 0 | AD11: =[2]หน้าผ้า!AT20 -> 0 | AE11: =[2]หน้าผ้า!AU20 -> 0 | AF11: =[2]หน้าผ้า!AI20 -> ระบุในSD | AG11: =[3]หน้าผ้า!DC23 -> ผ้าขาว | AH11: =[2]หน้าผ้า!DL20 -> 0 | AI11: =[2]หน้าผ้า!DM20 -> 0 | AJ11: =[2]หน้าผ้า!DN20 -> 0 | AK11: =[2]หน้าผ้า!DQ20 -> 0 | AL11: =[2]หน้าผ้า!DR20 -> 0 | AM11: =[2]หน้าผ้า!DS20 -> 0 | AN11: =[2]หน้าผ้า!DT20 -> 0 | AO11: =[2]หน้าผ้า!DU20 -> 0 | AP11: =[2]หน้าผ้า!DP20 -> 0 | AQ11: =[2]หน้าผ้า!DW20 -> 0 | AR11: =[2]หน้าผ้า!DX20 -> 0 | AS11: =[2]หน้าผ้า!DY20 -> 0 | AT11: =[2]หน้าผ้า!DZ20 -> 0 | AU11: =[2]หน้าผ้า!EA20 -> 0 | AV11: =[2]หน้าผ้า!EB20 -> 0 | AW11: =[2]หน้าผ้า!EC20 -> 0 | AX11: =[2]หน้าผ้า!ED20 -> 0 | AY11: =[2]หน้าผ้า!AG20 -> 0 | AZ11: =[2]หน้าผ้า!EG20 -> 0 | BA11: =[2]หน้าผ้า!EH20 -> 0 | BB11: =[2]หน้าผ้า!EI20 -> 0 | BC11: =[2]หน้าผ้า!BZ20 -> WRWT170800/WRWT25800 | BD11: =[2]หน้าผ้า!CA20 -> 0
A12: =[2]หน้าผ้า!C21 -> 45659 | B12: =[2]หน้าผ้า!B21 -> MK68-000006 | C12: =[2]หน้าผ้า!E21 -> หจก.อนนท์อุตสาหกรรม | D12: =[2]หน้าผ้า!F21 -> อนนท์ 20 กก. | E12: =[2]หน้าผ้า!G21 -> 18 | F12: =[2]หน้าผ้า!H21 -> 28 | G12: =[2]หน้าผ้า!I21 -> ขาว | H12: =[2]หน้าผ้า!J21 -> 0 | I12: =[2]หน้าผ้า!L21 -> 50 | J12: =[2]หน้าผ้า!M21 -> ± | K12: =[2]หน้าผ้า!N21 -> 5 | L12: =[2]หน้าผ้า!R21 -> ไม่ | M12: =[2]หน้าผ้า!T21 -> 19 | N12: =[2]หน้าผ้า!U21 -> 31 | O12: =[2]หน้าผ้า!V21 -> 40 | P12: =[2]หน้าผ้า!AB21 -> 363.27927 | Q12: =[2]หน้าผ้า!AC21 -> 0 | R12: =[2]หน้าผ้า!AD21 -> 363.27927 | S12: =[2]หน้าผ้า!Z21 -> 500กระสอบ | T12: =[2]หน้าผ้า!X21 -> 45668 | U12: =[2]หน้าผ้า!AA21 -> 25000 | V12: =[2]หน้าผ้า!AJ21 -> 0 | W12: =[2]หน้าผ้า!AL21 -> 25000 | X12: =[2]หน้าผ้า!AM21 -> 19025 | Y12: =[2]หน้าผ้า!AN21 -> 6273.75 | Z12: =[2]หน้าผ้า!AO21 -> WSWT1825800 | AA12: =[2]หน้าผ้า!AQ21 -> 5171.013 | AB12: =[2]หน้าผ้า!AR21 -> 0 | AC12: =[2]หน้าผ้า!AS21 -> 5171.013 | AD12: =[2]หน้าผ้า!AT21 -> 0 | AE12: =[2]หน้าผ้า!AU21 -> 0 | AF12: =[2]หน้าผ้า!AI21 -> 0 | AG12: =[3]หน้าผ้า!DC24 -> พร้อมส่ง | AH12: =[2]หน้าผ้า!DL21 -> P9 | AI12: =[2]หน้าผ้า!DM21 -> 3 | AJ12: =[2]หน้าผ้า!DN21 -> 45668 | AK12: =[2]หน้าผ้า!DQ21 -> 0 | AL12: =[2]หน้าผ้า!DR21 -> 45658 | AM12: =[2]หน้าผ้า!DS21 -> 45665 | AN12: =[2]หน้าผ้า!DT21 -> 45666 | AO12: =[2]หน้าผ้า!DU21 -> 45666 | AP12: =[2]หน้าผ้า!DP21 -> 45663 | AQ12: =[2]หน้าผ้า!DW21 -> 45667 | AR12: =[2]หน้าผ้า!DX21 -> 0 | AS12: =[2]หน้าผ้า!DY21 -> 0 | AT12: =[2]หน้าผ้า!DZ21 -> 0 | AU12: =[2]หน้าผ้า!EA21 -> 0 | AV12: =[2]หน้าผ้า!EB21 -> 0 | AW12: =[2]หน้าผ้า!EC21 -> งานพิมพ์ | AX12: =[2]หน้าผ้า!ED21 -> รอART | AY12: =[2]หน้าผ้า!AG21 -> 0 | AZ12: =[2]หน้าผ้า!EG21 -> 0 | BA12: =[2]หน้าผ้า!EH21 -> 0 | BB12: =[2]หน้าผ้า!EI21 -> 0 | BC12: =[2]หน้าผ้า!BZ21 -> WRWT25800/WRWT25800 | BD12: =[2]หน้าผ้า!CA21 -> 355.76569
A13: =[2]หน้าผ้า!C22 -> 45659 | B13: =[2]หน้าผ้า!B22 -> MK68-000009 | C13: =[2]หน้าผ้า!E22 -> บจก.ฟาร์เธอร์ส วิง ซัพพลาย | D13: =[2]หน้าผ้า!F22 -> รถไฟฟ้า | E13: =[2]หน้าผ้า!G22 -> 18 | F13: =[2]หน้าผ้า!H22 -> 30 | G13: =[2]หน้าผ้า!I22 -> ขาว | H13: =[2]หน้าผ้า!J22 -> 0 | I13: =[2]หน้าผ้า!L22 -> 54 | J13: =[2]หน้าผ้า!M22 -> ± | K13: =[2]หน้าผ้า!N22 -> 5 | L13: =[2]หน้าผ้า!R22 -> บิด | M13: =[2]หน้าผ้า!T22 -> 19 | N13: =[2]หน้าผ้า!U22 -> 33 | O13: =[2]หน้าผ้า!V22 -> 40 | P13: =[2]หน้าผ้า!AB22 -> 232.02999 | Q13: =[2]หน้าผ้า!AC22 -> 0 | R13: =[2]หน้าผ้า!AD22 -> 232.02999 | S13: =[2]หน้าผ้า!Z22 -> 500กระสอบ | T13: =[2]หน้าผ้า!X22 -> 45672 | U13: =[2]หน้าผ้า!AA22 -> 15000 | V13: =[2]หน้าผ้า!AJ22 -> 0 | W13: =[2]หน้าผ้า!AL22 -> 15000 | X13: =[2]หน้าผ้า!AM22 -> 0 | Y13: =[2]หน้าผ้า!AN22 -> 15750 | Z13: =[2]หน้าผ้า!AO22 -> WSWT1825800 | AA13: =[2]หน้าผ้า!AQ22 -> 13201.65 | AB13: =[2]หน้าผ้า!AR22 -> 0 | AC13: =[2]หน้าผ้า!AS22 -> 13201.65 | AD13: =[2]หน้าผ้า!AT22 -> 0 | AE13: =[2]หน้าผ้า!AU22 -> 0 | AF13: =[2]หน้าผ้า!AI22 -> 0 | AG13: =[3]หน้าผ้า!DC25 -> ยังไม่ได้พิมพ์ | AH13: =[2]หน้าผ้า!DL22 -> P9 | AI13: =[2]หน้าผ้า!DM22 -> 3 | AJ13: =[2]หน้าผ้า!DN22 -> 45672 | AK13: =[2]หน้าผ้า!DQ22 -> 0 | AL13: =[2]หน้าผ้า!DR22 -> 45662 | AM13: =[2]หน้าผ้า!DS22 -> 45669 | AN13: =[2]หน้าผ้า!DT22 -> 45670 | AO13: =[2]หน้าผ้า!DU22 -> 45670 | AP13: =[2]หน้าผ้า!DP22 -> 45667 | AQ13: =[2]หน้าผ้า!DW22 -> 45671 | AR13: =[2]หน้าผ้า!DX22 -> 0 | AS13: =[2]หน้าผ้า!DY22 -> 0 | AT13: =[2]หน้าผ้า!DZ22 -> 0 | AU13: =[2]หน้าผ้า!EA22 -> 0 | AV13: =[2]หน้าผ้า!EB22 -> 0 | AW13: =[2]หน้าผ้า!EC22 -> งานพิมพ์ | AX13: =[2]หน้าผ้า!ED22 -> รอART | AY13: =[2]หน้าผ้า!AG22 -> 0 | AZ13: =[2]หน้าผ้า!EG22 -> 0 | BA13: =[2]หน้าผ้า!EH22 -> 0 | BB13: =[2]หน้าผ้า!EI22 -> 0 | BC13: =[2]หน้าผ้า!BZ22 -> WRWT25800/WRWT25800 | BD13: =[2]หน้าผ้า!CA22 -> 908.27352
A14: =[2]หน้าผ้า!C23 -> 45659 | B14: =[2]หน้าผ้า!B23 -> MK68-000009 | C14: =[2]หน้าผ้า!E23 -> บจก.ฟาร์เธอร์ส วิง ซัพพลาย | D14: =[2]หน้าผ้า!F23 -> ไม่พิมพ์ | E14: =[2]หน้าผ้า!G23 -> 18 | F14: =[2]หน้าผ้า!H23 -> 30 | G14: =[2]หน้าผ้า!I23 -> ขาว | H14: =[2]หน้าผ้า!J23 -> 0 | I14: =[2]หน้าผ้า!L23 -> 54 | J14: =[2]หน้าผ้า!M23 -> ± | K14: =[2]หน้าผ้า!N23 -> 5 | L14: =[2]หน้าผ้า!R23 -> ไม่ | M14: =[2]หน้าผ้า!T23 -> 19 | N14: =[2]หน้าผ้า!U23 -> 33 | O14: =[2]หน้าผ้า!V23 -> 40 | P14: =[2]หน้าผ้า!AB23 -> 46.405998 | Q14: =[2]หน้าผ้า!AC23 -> 0 | R14: =[2]หน้าผ้า!AD23 -> 46.405998 | S14: =[2]หน้าผ้า!Z23 -> 500กระสอบ | T14: =[2]หน้าผ้า!X23 -> 45672 | U14: =[2]หน้าผ้า!AA23 -> 3000 | V14: =[2]หน้าผ้า!AJ23 -> 0 | W14: =[2]หน้าผ้า!AL23 -> 3000 | X14: =[2]หน้าผ้า!AM23 -> 0 | Y14: =[2]หน้าผ้า!AN23 -> 0 | Z14: =[2]หน้าผ้า!AO23 -> WSWT1825800 | AA14: =[2]หน้าผ้า!AQ23 -> 2640.33 | AB14: =[2]หน้าผ้า!AR23 -> 0 | AC14: =[2]หน้าผ้า!AS23 -> 2640.33 | AD14: =[2]หน้าผ้า!AT23 -> 0 | AE14: =[2]หน้าผ้า!AU23 -> 0 | AF14: =[2]หน้าผ้า!AI23 -> 0 | AG14: =[3]หน้าผ้า!DC26 -> พร้อมส่ง | AH14: =[2]หน้าผ้า!DL23 -> P13 | AI14: =[2]หน้าผ้า!DM23 -> 2 | AJ14: =[2]หน้าผ้า!DN23 -> 45672 | AK14: =[2]หน้าผ้า!DQ23 -> 0 | AL14: =[2]หน้าผ้า!DR23 -> 0 | AM14: =[2]หน้าผ้า!DS23 -> 0 | AN14: =[2]หน้าผ้า!DT23 -> 0 | AO14: =[2]หน้าผ้า!DU23 -> 45670 | AP14: =[2]หน้าผ้า!DP23 -> 45667 | AQ14: =[2]หน้าผ้า!DW23 -> 45671 | AR14: =[2]หน้าผ้า!DX23 -> 0 | AS14: =[2]หน้าผ้า!DY23 -> 0 | AT14: =[2]หน้าผ้า!DZ23 -> 0 | AU14: =[2]หน้าผ้า!EA23 -> 0 | AV14: =[2]หน้าผ้า!EB23 -> 0 | AW14: =[2]หน้าผ้า!EC23 -> ตัด | AX14: =[2]หน้าผ้า!ED23 -> 0 | AY14: =[2]หน้าผ้า!AG23 -> 0 | AZ14: =[2]หน้าผ้า!EG23 -> 0 | BA14: =[2]หน้าผ้า!EH23 -> 0 | BB14: =[2]หน้าผ้า!EI23 -> 0 | BC14: =[2]หน้าผ้า!BZ23 -> WRWT25800/WRWT25800 | BD14: =[2]หน้าผ้า!CA23 -> 181.6547
A15: =[2]หน้าผ้า!C24 -> 0 | B15: =[2]หน้าผ้า!B24 -> 0 | C15: =[2]หน้าผ้า!E24 | D15: =[2]หน้าผ้า!F24 | E15: =[2]หน้าผ้า!G24 -> 18 | F15: =[2]หน้าผ้า!H24 -> 30 | G15: =[2]หน้าผ้า!I24 -> ขาว | H15: =[2]หน้าผ้า!J24 -> 0 | I15: =[2]หน้าผ้า!L24 -> 54 | J15: =[2]หน้าผ้า!M24 -> ± | K15: =[2]หน้าผ้า!N24 -> 5 | L15: =[2]หน้าผ้า!R24 -> 0 | M15: =[2]หน้าผ้า!T24 -> 0 | N15: =[2]หน้าผ้า!U24 -> 0 | O15: =[2]หน้าผ้า!V24 -> 0 | P15: =[2]หน้าผ้า!AB24 -> 0 | Q15: =[2]หน้าผ้า!AC24 -> 0 | R15: =[2]หน้าผ้า!AD24 -> 0 | S15: =[2]หน้าผ้า!Z24 -> 0 | T15: =[2]หน้าผ้า!X24 -> 0 | U15: =[2]หน้าผ้า!AA24 -> 0 | V15: =[2]หน้าผ้า!AJ24 -> 0 | W15: =[2]หน้าผ้า!AL24 -> 0 | X15: =[2]หน้าผ้า!AM24 -> 0 | Y15: =[2]หน้าผ้า!AN24 -> 0 | Z15: =[2]หน้าผ้า!AO24 -> WSWT1825800 | AA15: =[2]หน้าผ้า!AQ24 -> 21012.993 | AB15: =[2]หน้าผ้า!AR24 -> 0 | AC15: =[2]หน้าผ้า!AS24 -> 21012.993 | AD15: =[2]หน้าผ้า!AT24 -> 0 | AE15: =[2]หน้าผ้า!AU24 -> 0 | AF15: =[2]หน้าผ้า!AI24 -> ระบุในSD | AG15: =[3]หน้าผ้า!DC27 -> พิมพ์ไม่ครบ | AH15: =[2]หน้าผ้า!DL24 -> 0 | AI15: =[2]หน้าผ้า!DM24 -> Lead time | AJ15: =[2]หน้าผ้า!DN24 -> 0 | AK15: =[2]หน้าผ้า!DQ24 -> 0 | AL15: =[2]หน้าผ้า!DR24 -> 0 | AM15: =[2]หน้าผ้า!DS24 -> 0 | AN15: =[2]หน้าผ้า!DT24 -> 0 | AO15: =[2]หน้าผ้า!DU24 -> 0 | AP15: =[2]หน้าผ้า!DP24 -> 0 | AQ15: =[2]หน้าผ้า!DW24 -> 0 | AR15: =[2]หน้าผ้า!DX24 -> 0 | AS15: =[2]หน้าผ้า!DY24 -> 0 | AT15: =[2]หน้าผ้า!DZ24 -> 0 | AU15: =[2]หน้าผ้า!EA24 -> 0 | AV15: =[2]หน้าผ้า!EB24 -> 0 | AW15: =[2]หน้าผ้า!EC24 -> 0 | AX15: =[2]หน้าผ้า!ED24 -> 0 | AY15: =[2]หน้าผ้า!AG24 -> 0 | AZ15: =[2]หน้าผ้า!EG24 -> 0 | BA15: =[2]หน้าผ้า!EH24 -> 0 | BB15: =[2]หน้าผ้า!EI24 -> 0 | BC15: =[2]หน้าผ้า!BZ24 -> WRWT25800/WRWT25800 | BD15: =[2]หน้าผ้า!CA24 -> 0
A16: =[2]หน้าผ้า!C25 -> 45659 | B16: =[2]หน้าผ้า!B25 -> MK68-000008 | C16: =[2]หน้าผ้า!E25 -> บจก.2 เอ็ม อโกร เท็ค | D16: =[2]หน้าผ้า!F25 -> เลิฟชอยล์ 14-3-3 | E16: =[2]หน้าผ้า!G25 -> 18 | F16: =[2]หน้าผ้า!H25 -> 30 | G16: =[2]หน้าผ้า!I25 -> ขาว | H16: =[2]หน้าผ้า!J25 -> ใส | I16: =[2]หน้าผ้า!L25 -> 74 | J16: =[2]หน้าผ้า!M25 -> ± | K16: =[2]หน้าผ้า!N25 -> 5 | L16: =[2]หน้าผ้า!R25 -> บิด | M16: =[2]หน้าผ้า!T25 -> 19 | N16: =[2]หน้าผ้า!U25 -> 33 | O16: =[2]หน้าผ้า!V25 -> 70 | P16: =[2]หน้าผ้า!AB25 -> 135.35083 | Q16: =[2]หน้าผ้า!AC25 -> 0 | R16: =[2]หน้าผ้า!AD25 -> 135.35083 | S16: =[2]หน้าผ้า!Z25 -> 500กระสอบ | T16: =[2]หน้าผ้า!X25 -> 45672 | U16: =[2]หน้าผ้า!AA25 -> 5000 | V16: =[2]หน้าผ้า!AJ25 -> 0 | W16: =[2]หน้าผ้า!AL25 -> 5000 | X16: =[2]หน้าผ้า!AM25 -> 0 | Y16: =[2]หน้าผ้า!AN25 -> 5250 | Z16: =[2]หน้าผ้า!AO25 -> WSWT1825800SM | AA16: =[2]หน้าผ้า!AQ25 -> 4400.55 | AB16: =[2]หน้าผ้า!AR25 -> 0 | AC16: =[2]หน้าผ้า!AS25 -> 4400.55 | AD16: =[2]หน้าผ้า!AT25 -> 0 | AE16: =[2]หน้าผ้า!AU25 -> 4400.55 | AF16: =[2]หน้าผ้า!AI25 -> 0 | AG16: =[3]หน้าผ้า!DC28 -> ยังไม่ได้พิมพ์ | AH16: =[2]หน้าผ้า!DL25 -> P8 | AI16: =[2]หน้าผ้า!DM25 -> 4 | AJ16: =[2]หน้าผ้า!DN25 -> 45672 | AK16: =[2]หน้าผ้า!DQ25 -> 45668 | AL16: =[2]หน้าผ้า!DR25 -> 45662 | AM16: =[2]หน้าผ้า!DS25 -> 45669 | AN16: =[2]หน้าผ้า!DT25 -> 45670 | AO16: =[2]หน้าผ้า!DU25 -> 45670 | AP16: =[2]หน้าผ้า!DP25 -> 45667 | AQ16: =[2]หน้าผ้า!DW25 -> 45671 | AR16: =[2]หน้าผ้า!DX25 -> 0 | AS16: =[2]หน้าผ้า!DY25 -> 0 | AT16: =[2]หน้าผ้า!DZ25 -> 0 | AU16: =[2]หน้าผ้า!EA25 -> 0 | AV16: =[2]หน้าผ้า!EB25 -> 0 | AW16: =[2]หน้าผ้า!EC25 -> งานเคลือบ+พิมพ์ | AX16: =[2]หน้าผ้า!ED25 -> / | AY16: =[2]หน้าผ้า!AG25 -> 0 | AZ16: =[2]หน้าผ้า!EG25 -> 0 | BA16: =[2]หน้าผ้า!EH25 -> 0 | BB16: =[2]หน้าผ้า!EI25 -> 0 | BC16: =[2]หน้าผ้า!BZ25 -> WRWT25800/WRWT25800 | BD16: =[2]หน้าผ้า!CA25 -> 281.6352
A17: =[2]หน้าผ้า!C26 -> 0 | B17: =[2]หน้าผ้า!B26 -> 0 | C17: =[2]หน้าผ้า!E26 -> 0 | D17: =[2]หน้าผ้า!F26 | E17: =[2]หน้าผ้า!G26 -> 18 | F17: =[2]หน้าผ้า!H26 -> 25 | G17: =[2]หน้าผ้า!I26 -> ขาว | H17: =[2]หน้าผ้า!J26 -> 0 | I17: =[2]หน้าผ้า!L26 -> 50 | J17: =[2]หน้าผ้า!M26 -> ± | K17: =[2]หน้าผ้า!N26 -> 5 | L17: =[2]หน้าผ้า!R26 -> 0 | M17: =[2]หน้าผ้า!T26 -> 0 | N17: =[2]หน้าผ้า!U26 -> 0 | O17: =[2]หน้าผ้า!V26 -> 0 | P17: =[2]หน้าผ้า!AB26 -> 0 | Q17: =[2]หน้าผ้า!AC26 -> 0 | R17: =[2]หน้าผ้า!AD26 -> 0 | S17: =[2]หน้าผ้า!Z26 -> 0 | T17: =[2]หน้าผ้า!X26 -> 0 | U17: =[2]หน้าผ้า!AA26 -> 0 | V17: =[2]หน้าผ้า!AJ26 -> 0 | W17: =[2]หน้าผ้า!AL26 -> 0 | X17: =[2]หน้าผ้า!AM26 -> 0 | Y17: =[2]หน้าผ้า!AN26 -> 0 | Z17: =[2]หน้าผ้า!AO26 -> WSWT1825800SM | AA17: =[2]หน้าผ้า!AQ26 -> 4400.55 | AB17: =[2]หน้าผ้า!AR26 -> 0 | AC17: =[2]หน้าผ้า!AS26 -> 4400.55 | AD17: =[2]หน้าผ้า!AT26 -> 0 | AE17: =[2]หน้าผ้า!AU26 -> 4400.55 | AF17: =[2]หน้าผ้า!AI26 -> ระบุในSD | AG17: =[3]หน้าผ้า!DC29 -> ยังไม่ได้พิมพ์ | AH17: =[2]หน้าผ้า!DL26 -> 0 | AI17: =[2]หน้าผ้า!DM26 -> Lead time | AJ17: =[2]หน้าผ้า!DN26 -> 0 | AK17: =[2]หน้าผ้า!DQ26 -> 0 | AL17: =[2]หน้าผ้า!DR26 -> 0 | AM17: =[2]หน้าผ้า!DS26 -> 0 | AN17: =[2]หน้าผ้า!DT26 -> 0 | AO17: =[2]หน้าผ้า!DU26 -> 0 | AP17: =[2]หน้าผ้า!DP26 -> 0 | AQ17: =[2]หน้าผ้า!DW26 -> 0 | AR17: =[2]หน้าผ้า!DX26 -> 0 | AS17: =[2]หน้าผ้า!DY26 -> 0 | AT17: =[2]หน้าผ้า!DZ26 -> 0 | AU17: =[2]หน้าผ้า!EA26 -> 0 | AV17: =[2]หน้าผ้า!EB26 -> 0 | AW17: =[2]หน้าผ้า!EC26 -> 0 | AX17: =[2]หน้าผ้า!ED26 -> 0 | AY17: =[2]หน้าผ้า!AG26 -> 0 | AZ17: =[2]หน้าผ้า!EG26 -> 0 | BA17: =[2]หน้าผ้า!EH26 -> 0 | BB17: =[2]หน้าผ้า!EI26 -> 0 | BC17: =[2]หน้าผ้า!BZ26 -> WRWT180800/WRWT25800 | BD17: =[2]หน้าผ้า!CA26 -> 0
... A1200: =[2]หน้าผ้า!C1209 -> 0 | B1200: =[2]หน้าผ้า!B1209 -> 0 | C1200: =[2]หน้าผ้า!E1209 -> 0 | D1200: =[2]หน้าผ้า!F1209 -> 0 | E1200: =[2]หน้าผ้า!G1209 -> 0 | F1200: =[2]หน้าผ้า!H1209 -> 0 | G1200: =[2]หน้าผ้า!I1209 -> 0 | H1200: =[2]หน้าผ้า!J1209 -> 0 | I1200: =[2]หน้าผ้า!L1209 -> 0 | J1200: =[2]หน้าผ้า!M1209 -> 0 | K1200: =[2]หน้าผ้า!N1209 -> 0 | L1200: =[2]หน้าผ้า!R1209 -> 0 | M1200: =[2]หน้าผ้า!T1209 -> 0 | N1200: =[2]หน้าผ้า!U1209 -> 0 | O1200: =[2]หน้าผ้า!V1209 -> 0 | P1200: =[2]หน้าผ้า!AB1209 -> 0 | Q1200: =[2]หน้าผ้า!AC1209 -> 0 | R1200: =[2]หน้าผ้า!AD1209 -> 0 | S1200: =[2]หน้าผ้า!Z1209 -> 0 | T1200: =[2]หน้าผ้า!X1209 -> 0 | U1200: =[2]หน้าผ้า!AA1209 -> 0 | V1200: =[2]หน้าผ้า!AJ1209 -> 0 | W1200: =[2]หน้าผ้า!AL1209 -> 0 | X1200: =[2]หน้าผ้า!AM1209 -> 0 | Y1200: =[2]หน้าผ้า!AN1209 -> 0 | Z1200: =[2]หน้าผ้า!AO1209 -> 0 | AA1200: =[2]หน้าผ้า!AQ1209 -> 0 | AB1200: =[2]หน้าผ้า!AR1209 -> 0 | AC1200: =[2]หน้าผ้า!AS1209 -> 0 | AD1200: =[2]หน้าผ้า!AT1209 -> 0 | AE1200: =[2]หน้าผ้า!AU1209 -> 0 | AF1200: =[2]หน้าผ้า!AI1209 -> 0 | AG1200: =[3]หน้าผ้า!DC1212 -> 0 | AH1200: =[2]หน้าผ้า!DL1209 -> 0 | AI1200: =[2]หน้าผ้า!DM1209 -> 0 | AJ1200: =[2]หน้าผ้า!DN1209 -> 0 | AK1200: =[2]หน้าผ้า!DQ1209 -> 0 | AL1200: =[2]หน้าผ้า!DR1209 -> 0 | AM1200: =[2]หน้าผ้า!DS1209 -> 0 | AN1200: =[2]หน้าผ้า!DT1209 -> 0 | AO1200: =[2]หน้าผ้า!DU1209 -> 0 | AP1200: =[2]หน้าผ้า!DP1209 -> 0 | AQ1200: =[2]หน้าผ้า!DW1209 -> 0 | AR1200: =[2]หน้าผ้า!DX1209 -> 0 | AS1200: =[2]หน้าผ้า!DY1209 -> 0 | AT1200: =[2]หน้าผ้า!DZ1209 -> 0 | AU1200: =[2]หน้าผ้า!EA1209 -> 0 | AV1200: =[2]หน้าผ้า!EB1209 -> 0 | AW1200: =[2]หน้าผ้า!EC1209 -> 0 | AX1200: =[2]หน้าผ้า!ED1209 -> 0 | AY1200: =[2]หน้าผ้า!AG1209 -> 0 | AZ1200: =[2]หน้าผ้า!EG1209 -> 0 | BA1200: =[2]หน้าผ้า!EH1209 -> 0 | BB1200: =[2]หน้าผ้า!EI1209 -> 0 | BC1200: =[2]หน้าผ้า!BZ1209 -> 0 | BD1200: =[2]หน้าผ้า!CA1209 -> 0

Sheet 2(Order+FC)
A2: เลขที่ SO | B2: (ทั้งหมด)
A3: วันส่ง | B3: (ทั้งหมด)
A4: ชื่อลูกค้า | B4: (ทั้งหมด)
A6: ประเภท | B6: ผลรวม ของ จำนวนส่ง | C6: ผลรวม ของ ค้างพิมพ์ | D6: ผลรวม ของ ค้างตัด | E6: ผลรวม ของ Stock | F6: ผลรวม ของ ค้างทอ | G6: ผลรวม ของ ใช้
A7: WSWT1425800 | B7: 10000 | C7: 10500 | D7: 10000 | E7: 13131.8 | F7: 0 | G7: 13131.8
A8: WSWT1725800 | B8: 8850 | C8: 9292.5 | D8: 8850 | E8: 974 | F8: 12625.795 | G8: 13599.795 | H8: =F8 -> 12625.795
A9: WSWT1825800 | B9: 43000 | C9: 42000 | D9: 43000 | E9: 0 | F9: 72895.46 | G9: 72895.46
A10: WSWT1825800SM | B10: 25000 | C10: 10500 | D10: 25000 | E10: 8801.1 | F10: 8801.1 | G10: 17602.2
A11: WSWT1921720 | B11: 453000 | C11: 407400 | D11: 453000 | E11: 54830 | F11: 748137.66 | G11: 802967.66 | H11: =F11 -> 748137.66
A12: WSWT19251000SM | B12: 248 | C12: 0 | D12: 248 | E12: 0 | F12: 0 | G12: 0 | H12: =F12 -> 0
A13: WSWT1925800 | B13: 180000 | C13: 172914 | D13: 164680 | E13: 62193.549 | F13: 224885.48 | G13: 287079.03 | H13: =F13 -> 224885.48
A14: WSWT2021750 | B14: 5000 | C14: 5250 | D14: 5000 | E14: 1178 | F14: 9578.9 | G14: 10756.9 | H14: =F14 -> 9578.9
A15: WSWT2025650 | B15: 33300 | C15: 15750 | D15: 31100 | E15: 0 | F15: 62716.918 | G15: 62716.918 | H15: =F15 -> 62716.918
A16: WSWT2025700 | B16: 70000 | C16: 52500 | D16: 60000 | E16: 0 | F16: 135788.4 | G16: 135788.4 | H16: =F16 -> 135788.4
A17: WSWT2025800 | B17: 265760 | C17: 225750 | D17: 236776 | E17: 5540 | F17: 441919.1 | G17: 447459.1 | H17: 128461
A18: WSWT2025800SM | B18: 556402 | C18: 531801.9 | D18: 528431 | E18: 619346.82 | F18: 482567.75 | G18: 1101914.6
A19: WSWT2025850 | B19: 255000 | C19: 246750 | D19: 245000 | E19: 0 | F19: 537984.7 | G19: 537984.7
A20: WSWT2121670SM | B20: 264000 | C20: 197489.25 | D20: 259122 | E20: 97091.5 | F20: 396947 | G20: 494038.5
A21: WSWT2125650 | B21: 52000 | C21: 17850 | D21: 42000 | E21: 5380 | F21: 85425 | G21: 90805
A22: WSWT2125800 | B22: 7200 | C22: 7560 | D22: 7200 | E22: 0 | F22: 13478.256 | G22: 13478.256
A23: WSWT2321112512551 | B23: 1877500 | C23: 1884781.5 | D23: 1821500 | E23: 138194.87 | F23: 3726558.2 | G23: 3864753 | H23: =F23 -> 3726558.2
A24: WSWT2325650 | B24: 40000 | C24: 31500 | D24: 40000 | E24: 0 | F24: 63982.6 | G24: 63982.6 | H24: =F24 -> 63982.6
A25: WSWT2421112512551 | B25: 40400 | C25: 42420 | D25: 40400 | E25: 21820 | F25: 65095.752 | G25: 86915.752
A26: WSWT2625650 | B26: 67000 | C26: 10500 | D26: 67000 | E26: 0 | F26: 160850.58 | G26: 160850.58 | H26: =F26 -> 160850.58
A27: WSWT262575051 | B27: 20000 | C27: 21000 | D27: 20000 | E27: 7340 | F27: 42393.2 | G27: 49733.2 | H27: =F27 -> 42393.2
A28: WSWT2625800 | B28: 40000 | C28: 0 | D28: 33080 | E28: 3020 | F28: 79238.713 | G28: 82258.713 | H28: =SUM(H7:H27) -> 5315978.7 | K28: 33.981 | L28: =+K28*M28 -> 16990.5 | M28: 500
A29: WSWT2625850SM | B29: 50000 | C29: 52500 | D29: 50000 | E29: 12764 | F29: 111569 | G29: 124333
A30: WSWT2825850 | B30: 25000 | C30: 19700.1 | D30: 18762 | E30: 30020 | F30: 14537.874 | G30: 44557.874
A31: ผลรวมทั้งหมด | B31: 4388660 | C31: 4015709.2 | D31: 4210149 | E31: 1081625.6 | F31: 7497977.4 | G31: 8579603
A37: ยอดส่ง 1/12/67 - 10/12/67 | B37: 627338 | F37: 508000 | H37: ผ้า vn
B41: =+B28+B37 -> 667338 | C41: =+C28+C37 -> 0 | D41: =+D28+D37 -> 33080 | E41: =+E28+E37 -> 3020 | F41: =+F28-F37 -> -428761.29 | G41: =+G30+G37 -> 44557.874
B43: 2303789
B45: =+B43-B41 -> 1636451 | C45: =+C32+($B$45*1) -> 1636451 | D45: =+D32+($B$45*1) -> 1636451 | E45: =+E31+($B$45*1) -> 2718076.6 | F45: =+F30+($B$45*1) -> 1650988.9 | G45: =+G31+($B$45*1) -> 10216054
C47: =+C41+C45 -> 1636451 | D47: =+D41+D45 -> 1669531 | E47: ค้างทอรวม | F47: =+F45-F37 -> 1142988.9 | I47: =+F47*85 -> 97154054 | J47: =+I47/1000 -> 97154.054 | K47: =+J47/1000 -> 97.154054
D50: =+D47/16 -> 104345.69 | F50: =+F47/70000 -> 16.328412

Sheet 2(Order)
A2: เลขที่ SO | B2: (ทั้งหมด)
A3: วันส่ง | B3: (ทั้งหมด)
A4: ชื่อลูกค้า | B4: (ทั้งหมด)
A6: ประเภท | B6: ผลรวม ของ จำนวนส่ง | C6: ผลรวม ของ ค้างพิมพ์ | D6: ผลรวม ของ ค้างตัด | E6: ผลรวม ของ Stock | F6: ผลรวม ของ ค้างทอ | G6: ผลรวม ของ ใช้
A7: WSWT1425800 | B7: 10000 | C7: 10500 | D7: 10000 | E7: 13131.8 | F7: 0 | G7: 13131.8
A8: WSWT1725800 | B8: 8850 | C8: 9292.5 | D8: 8850 | E8: 974 | F8: 12625.795 | G8: 13599.795
A9: WSWT1825800 | B9: 43000 | C9: 42000 | D9: 43000 | E9: 0 | F9: 72895.46 | G9: 72895.46
A10: WSWT1825800SM | B10: 25000 | C10: 10500 | D10: 25000 | E10: 8801.1 | F10: 8801.1 | G10: 17602.2
A11: WSWT1921720 | B11: 453000 | C11: 407400 | D11: 453000 | E11: 54830 | F11: 748137.66 | G11: 802967.66
A12: WSWT19251000SM | B12: 248 | C12: 0 | D12: 248 | E12: 0 | F12: 0 | G12: 0
A13: WSWT1925800 | B13: 180000 | C13: 172914 | D13: 164680 | E13: 62193.549 | F13: 224885.48 | G13: 287079.03
A14: WSWT2021750 | B14: 5000 | C14: 5250 | D14: 5000 | E14: 1178 | F14: 9578.9 | G14: 10756.9
A15: WSWT2025650 | B15: 33300 | C15: 15750 | D15: 31100 | E15: 0 | F15: 62716.918 | G15: 62716.918
A16: WSWT2025700 | B16: 70000 | C16: 52500 | D16: 60000 | E16: 0 | F16: 135788.4 | G16: 135788.4
A17: WSWT2025800 | B17: 265760 | C17: 225750 | D17: 236776 | E17: 5540 | F17: 441919.1 | G17: 447459.1
A18: WSWT2025800SM | B18: 556402 | C18: 531801.9 | D18: 528431 | E18: 619346.82 | F18: 482567.75 | G18: 1101914.6
... A31: ผลรวมทั้งหมด | B31: 4388660 | C31: 4015709.2 | D31: 4210149 | E31: 1081625.6 | F31: 7497977.4 | G31: 8579603
H33: ผ้า vn
A37: ยอดส่ง 1/12/67 - 19/12/67 | B37: 1366383
A38: Order+ส่ง | B38: =++B21+B37 -> 1418383
A39: ประมาณการ
A41: Order+ส่ง+ประมาณการ | B41: =+B21+B37+B39+30000 -> 1448383 | C41: =+C21+C37+C39 -> 17850 | D41: =+D21+D37+D39 -> 42000 | E41: =+E21+E37+E39 -> 5380 | F41: =+F21+F37+F39 -> 85425
B43: 1996883
B45: =+B41-B43 -> -548500 | C45: =+$B$45 -> -548500 | D45: =+$B$45 -> -548500 | F45: =+$B$45 -> -548500

Sheet 2(Fc) แยกลูกค้า
A1: เลขที่ SO | B1: ประมาณการ
A2: วันส่ง | B2: รอแจ้ง | D2: 12
A4: ประเภท | B4: ชื่อลูกค้า | C4: ผลรวม ของ จำนวนส่ง | D4: ผลรวม ของ ค้างพิมพ์ | E4: ผลรวม ของ ค้างตัด | F4: ผลรวม ของ Stock | G4: ผลรวม ของ ใช้ | H4: ผลรวม ของ ค้างทอ
A5: WSWT2121670SM | B5: บจก.แอมโก้เวท | C5: 40000 | D5: 0 | E5: 40000 | F5: 43027.6 | G5: 43027.6 | H5: 0
A6: WSWT2121670SM ผลรวม | C6: 40000 | D6: 0 | E6: 40000 | F6: 43027.6 | G6: 43027.6 | H6: 0
A7: ผลรวมทั้งหมด | C7: 40000 | D7: 0 | E7: 40000 | F7: 43027.6 | G7: 43027.6 | H7: 0
I17: =C17 -> 0
I22: =C22 -> 0
I23: =C23 -> 0
I24: =C24 -> 0
I33: =SUM(I5:I32) -> 0
D119: Cap พิมพ์ | E119: Cap ตัด | F119: Stock 16/7 บ่าย | G119: Cap ทอ | I119: วันทงาน
B120: lส่ง | C120: 1-16/7 | D120: 160000 | E120: 160000 | G120: 120000 | I120: 12
C121: 1975256 | D121: =+D120*I120 -> 1920000 | E121: =+E120*I120 -> 1920000 | F121: 825147 | G121: =+G120*I120 -> 1440000
A122: เบทาโกรส่งแล้ว | B122: 20700 | C122: 424374
A123: เบทาโกรส่งแล้ว | B123: 20800 | C123: 155973
C126: รวมส่ง+ค้างส่ง | D126: ส่วนต่างCapคงเหลือ | E126: ส่วนต่างCapคงเหลือ | F126: คงเหลือ
C127: =+C50+C121 -> 1975256 | D127: =+D121-D50 -> 1920000 | E127: =+E121-E50 -> 1920000 | F127: =+F121-F50 -> 825147 | G127: =+G121-G50 -> 1440000
B129: 20700VN 20/7 | G129: 350000

Sheet 12(Order+Fc) แยกลูกค้า
A1: เลขที่ SO | B1: (หลายรายการ)
A2: วันส่ง | B2: (หลายรายการ) | D2: 12 | I2: เมตร | J2: vn | K2: ใบ | P2: วัน
A4: ประเภท | B4: ชื่อลูกค้า | C4: ผลรวม ของ จำนวนส่ง | D4: ผลรวม ของ ค้างพิมพ์ | E4: ผลรวม ของ ค้างตัด | F4: ผลรวม ของ Stock | G4: ผลรวม ของ ใช้ | H4: ผลรวม ของ ค้างทอ
A5: WSWT1725800 | B5: โรงสีข้าวธัญญาวัฒน์ | C5: 8850 | D5: 9292.5 | E5: 8850 | F5: 5496 | G5: 6799.8975 | H5: 1303.8975 | I5: =H5 -> 1303.8975
A6: WSWT1725800 ผลรวม | C6: 8850 | D6: 9292.5 | E6: 8850 | F6: 5496 | G6: 6799.8975 | H6: 1303.8975
A7: WSWT1825800 | B7: หจก.อนนท์อุตสาหกรรม | C7: 25000 | D7: 26250 | E7: 25000 | F7: 12923 | G7: 20605.75 | H7: 7682.75 | I7: =H7 -> 7682.75
B8: บจก.ฟาร์เธอร์ส วิง ซัพพลาย | C8: 18000 | D8: 15750 | E8: 18000 | F8: 0 | G8: 15841.98 | H8: 15841.98 | I8: =H8 -> 15841.98
A9: WSWT1825800 ผลรวม | C9: 43000 | D9: 42000 | E9: 43000 | F9: 12923 | G9: 36447.73 | H9: 23524.73
A10: WSWT1825800SM | B10: บจก.2 เอ็ม อโกร เท็ค | C10: 5000 | D10: 5250 | E10: 5000 | F10: 0 | G10: 4400.55 | H10: 4400.55 | I10: =H10 -> 4400.55
A11: WSWT1825800SM ผลรวม | C11: 5000 | D11: 5250 | E11: 5000 | F11: 0 | G11: 4400.55 | H11: 4400.55
A12: WSWT1921720 | B12: บจก.เคอรี่ฟลาวมิลล์ | C12: 433000 | D12: 381150 | E12: 433000 | F12: 42531.7 | G12: 384999.23 | H12: 342467.53 | I12: =H12 -> 342467.53
A13: WSWT1921720 ผลรวม | C13: 433000 | D13: 381150 | E13: 433000 | F13: 42531.7 | G13: 384999.23 | H13: 342467.53
A14: WSWT1925800 | B14: บจก.เพรซิเดนท์ฟลาวมิลล์ | C14: 100000 | D14: 69573 | E14: 95365 | F14: 15026.118 | G14: 59031.618 | H14: 44005.5 | I14: =H14 -> 44005.5 | P14: 15000 | Q14: =+K14/P14 -> 0
B15: บจก.ซีแมนอินดัสตรี | C15: 30000 | D15: 31500 | E15: 30000 | F15: 6094 | G15: 24726.9 | H15: 18632.9 | I15: =H15 -> 18632.9
B16: หจก.ชนุตร์ แคเซี่ยม 888 | C16: 5000 | D16: 5250 | E16: 5000 | F16: 0 | G16: 4679.95 | H16: 4679.95 | I16: =H16 -> 4679.95
B17: หจก.ไอทีอี เกษตรพัฒนา | C17: 5000 | D17: 5250 | E17: 5000 | F17: 0 | G17: 4959.35 | H17: 4959.35 | I17: =H17 -> 4959.35
A18: WSWT1925800 ผลรวม | C18: 140000 | D18: 111573 | E18: 135365 | F18: 21120.118 | G18: 93397.818 | H18: 72277.7
A19: WSWT2021750 | B19: คุณสมบัติ นิมวชิรวัฒนา | C19: 5000 | D19: 5250 | E19: 5000 | F19: 589 | G19: 5378.45 | H19: 4789.45 | I19: =H19 -> 4789.45
A20: WSWT2021750 ผลรวม | C20: 5000 | D20: 5250 | E20: 5000 | F20: 589 | G20: 5378.45 | H20: 4789.45 | P20: 16000 | Q20: =+K20/P20 -> 0
A21: WSWT2025650 | B21: บจก.อินเทคค์ โกลบอล | C21: 10140 | D21: 0 | E21: 10140 | F21: 5300 | G21: 10907.497 | H21: 5607.4966 | I21: =H21 -> 5607.4966
B22: บจก.เอเชียเหมืองแร่ | C22: 15000 | D22: 15750 | E22: 15000 | F22: 0 | G22: 14039.85 | H22: 14039.85 | I22: =H22 -> 14039.85
A23: WSWT2025650 ผลรวม | C23: 25140 | D23: 15750 | E23: 25140 | F23: 5300 | G23: 24947.347 | H23: 19647.347
A24: WSWT2025700 | B24: บจก.เบทาโกร | C24: 70000 | D24: 21878.85 | E24: 59494 | F24: 11961 | G24: 35500.576 | H24: 23539.576 | I24: =H24 -> 23539.576
A25: WSWT2025700 ผลรวม | C25: 70000 | D25: 21878.85 | E25: 59494 | F25: 11961 | G25: 35500.576 | H25: 23539.576
A26: WSWT2025800 | B26: บจก.เคอรี่ฟลาวมิลล์ | C26: 20000 | D26: 21000 | E26: 20000 | F26: 0 | G26: 18719.8 | H26: 18719.8 | I26: =H26 -> 18719.8
B27: บจก.เบทาโกร | C27: 180000 | D27: 173799.15 | E27: 170042 | F27: 0 | G27: 178348.49 | H27: 178348.49 | I27: =H27 -> 178348.49
B28: บจก.อินเทคค์ โกลบอล | C28: 172728 | D28: 170270.1 | E28: 172728 | F28: 0 | G28: 169905.24 | H28: 169905.24 | I28: =H28 -> 169905.24
A29: WSWT2025800 ผลรวม | C29: 372728 | D29: 365069.25 | E29: 362770 | F29: 0 | G29: 366973.52 | H29: 366973.52
A30: WSWT2025800SM | B30: บจก.ซันฟีด | C30: 50000 | D30: 52500 | E30: 50000 | F30: 55041.8 | G30: 55041.8 | H30: 0 | I30: =H30 -> 0
B31: บจก.ไทยธรรมดี | C31: 20000 | D31: 21000 | E31: 20000 | F31: 21513.8 | G31: 21513.8 | H31: 0 | I31: =H31 -> 0 | P31: 15000 | Q31: =+K31/P31 -> 0
B32: บจก.เบทาโกร | C32: 25000 | D32: 26250 | E32: 25000 | F32: 25495.25 | G32: 25495.25 | H32: 0 | I32: =H32 -> 0
B33: บจก.อินเทคค์ โกลบอล | C33: 50000 | D33: 52500 | E33: 50000 | F33: 52387.5 | G33: 52387.5 | H33: 0 | I33: =H33 -> 0
B34: บจก.เอ.เจ.ฟาร์ม่าแล็บ | C34: 8000 | D34: 0 | E34: 866 | F34: 0 | G34: 0 | H34: 0 | I34: =H34 -> 0
B35: บจก.เอพีเอ็ม อะโกร | C35: 34000 | D35: 13650 | E35: 22527 | F35: 14347.19 | G35: 14347.19 | H35: 0 | I35: =H35 -> 0
B36: บจก.เอสพีเอ็ม อาหารสัตว์ | C36: 58000 | D36: 56700 | E36: 58000 | F36: 59596.02 | G36: 59596.02 | H36: 0 | I36: =H36 -> 0
B37: คุณชายชล จันทร์สว่างกูล | C37: 1000 | D37: 0 | E37: 0 | F37: 0 | G37: 0 | H37: 0 | I37: =H37 -> 0
B38: บจก.มารีน ลีดเดอร์ | C38: 10000 | D38: 10500 | E38: 10000 | F38: 8801.1 | G38: 8801.1 | H38: 0 | I38: =H38 -> 0
B39: บจก.วีซีเอฟ | C39: 100000 | D39: 105000 | E39: 100000 | F39: 0 | G39: 107569 | H39: 107569 | I39: =H39 -> 107569
A40: WSWT2025800SM ผลรวม | C40: 356000 | D40: 338100 | E40: 336393 | F40: 237182.66 | G40: 344751.66 | H40: 107569
A41: WSWT2025850 | B41: บจก.ซันฟีด | C41: 435000 | D41: 456750 | E41: 435000 | F41: 2400 | G41: 484549.45 | H41: 482149.45 | I41: =H41 -> 482149.45
...

Sheet 1(Order)
A2: เลขที่ SO | B2: (หลายรายการ)
A3: วันส่ง | B3: (หลายรายการ)
A4: ชื่อลูกค้า | B4: (ทั้งหมด)
A6: ประเภท | B6: ผลรวม ของ จำนวนส่ง | C6: ผลรวม ของ ค้างพิมพ์ | D6: ผลรวม ของ ค้างตัด | E6: ผลรวม ของ Stock | F6: ผลรวม ของ ค้างทอ | G6: ผลรวม ของ ใช้
A7: WSWT1425800 | B7: 10000 | C7: 10500 | D7: 10000 | E7: 6565.9 | F7: 0 | G7: 6565.9
A8: WSWT1725800 | B8: 8850 | C8: 9292.5 | D8: 8850 | E8: 487 | F8: 6312.8975 | G8: 6799.8975
A9: WSWT1825800 | B9: 43000 | C9: 42000 | D9: 43000 | E9: 0 | F9: 36447.73 | G9: 36447.73
A10: WSWT1825800SM | B10: 25000 | C10: 10500 | D10: 25000 | E10: 4400.55 | F10: 4400.55 | G10: 8801.1
A11: WSWT1921720 | B11: 333000 | C11: 281400 | D11: 333000 | E11: 27415 | F11: 268455.63 | G11: 295870.63
A12: WSWT1925800 | B12: 180000 | C12: 172914 | D12: 164680 | E12: 31096.775 | F12: 112442.74 | G12: 143539.51
A13: WSWT2025650 | B13: 18300 | C13: 0 | D13: 16100 | E13: 0 | F13: 17318.609 | G13: 17318.609
A14: WSWT2025700 | B14: 70000 | C14: 52500 | D14: 60000 | E14: 0 | F14: 67894.2 | G14: 67894.2
A15: WSWT2025800 | B15: 259880 | C15: 225750 | D15: 235768 | E15: 2770 | F15: 220959.55 | G15: 223729.55
A16: WSWT2025800SM | B16: 173080 | C16: 161733.6 | D16: 164946 | E16: 128794.59 | F16: 35847.02 | G16: 164641.61
A17: WSWT2025850 | B17: 245000 | C17: 246750 | D17: 235000 | E17: 0 | F17: 258235.45 | G17: 258235.45
A18: WSWT2121670SM | B18: 127000 | C18: 100889.25 | D18: 127000 | E18: 0 | F18: 104189.97 | G18: 104189.97
... A27: ผลรวมทั้งหมด | B27: 2067310 | C27: 1722146 | D27: 1918386 | E27: 296219.25 | F27: 1549048.3 | G27: 1845267.6
A37: ยอดส่ง 1/12/67 - 19/12/67 | B37: 1366383
A38: Order+ส่ง | B38: =++B21+B37 -> 1744383
A39: ประมาณการ
A41: Order+ส่ง+ประมาณการ | B41: =+B21+B37+B39+30000 -> 1774383 | C41: =+C21+C37+C39 -> 310306.5 | D41: =+D21+D37+D39 -> 322000 | E41: =+E21+E37+E39 -> 69097.433 | F41: =+F21+F37+F39 -> 250281.92
B43: 1996883
B45: =+B41-B43 -> -222500 | C45: =+$B$45 -> -222500 | D45: =+$B$45 -> -222500 | F45: =+$B$45 -> -222500
F75: 508000 | H75: ผ้า vn
A79: ยอดส่ง 1/12/67 - 14/12/67 | B79: 927060
A80: Order+ส่ง | B80: =++B68+B79 -> 927060
A81: ประมาณการ | B81: 325000 | C81: 330750 | D81: 325000 | E81: 104775 | F81: 321798.95 | G81: 217023.95
A83: Order+ส่ง+ประมาณการ | B83: =+B25+B79+B81 -> 1302060 | C83: =+C25+C79+C81 -> 383250 | D83: =+D25+D79+D81 -> 375000 | E83: =+E25+E79+E81 -> 111157 | F83: =+F25+F87+F81-F75 -> -1045916.5
B85: 2217560
B87: =+B83-B85 -> -915500 | C87: =+$B$87 -> -915500 | D87: =+$B$87 -> -915500 | F87: =+$B$87 -> -915500
D89: =+D83/13.5 -> 27777.778

Sheet 1(Order) แยกลูกค้า
A1: เลขที่ SO | B1: (หลายรายการ)
A2: วันส่ง | B2: (หลายรายการ)
A4: ประเภท | B4: ชื่อลูกค้า | C4: ผลรวม ของ จำนวนส่ง | D4: ผลรวม ของ ค้างพิมพ์ | E4: ผลรวม ของ ค้างตัด | F4: ผลรวม ของ Stock | G4: ผลรวม ของ ค้างทอ | I4: vn
A5: WSWT1425800 | B5: หจก.ปึงเป้งน้ำ | C5: 10000 | D5: 10500 | E5: 10000 | F5: 6565.9 | G5: 0 | H5: =G5 -> 0
A6: WSWT1425800 ผลรวม | C6: 10000 | D6: 10500 | E6: 10000 | F6: 6565.9 | G6: 0 | H6: =G6 -> 0
A7: WSWT1725800 | B7: โรงสีข้าวธัญญาวัฒน์ | C7: 8850 | D7: 9292.5 | E7: 8850 | F7: 487 | G7: 6312.8975 | H7: =G7 -> 6312.8975
A8: WSWT1725800 ผลรวม | C8: 8850 | D8: 9292.5 | E8: 8850 | F8: 487 | G8: 6312.8975
A9: WSWT1825800 | B9: หจก.อนนท์อุตสาหกรรม | C9: 25000 | D9: 26250 | E9: 25000 | F9: 0 | G9: 20605.75 | H9: =G9 -> 20605.75
B10: บจก.ฟาร์เธอร์ส วิง ซัพพลาย | C10: 18000 | D10: 15750 | E10: 18000 | F10: 0 | G10: 15841.98 | H10: =G10 -> 15841.98
A11: WSWT1825800 ผลรวม | C11: 43000 | D11: 42000 | E11: 43000 | F11: 0 | G11: 36447.73
A12: WSWT1825800SM | B12: บจก.ซิเบลโก้ | C12: 15000 | D12: 0 | E12: 15000 | F12: 0 | G12: 0 | H12: =G12 -> 0
B13: บจก.ซิเบลโก้(บางเลน) | C13: 5000 | D13: 5250 | E13: 5000 | F13: 4400.55 | G13: 0 | H13: =G13 -> 0
B14: บจก.2 เอ็ม อโกร เท็ค | C14: 5000 | D14: 5250 | E14: 5000 | F14: 0 | G14: 4400.55 | H14: =G14 -> 4400.55
A15: WSWT1825800SM ผลรวม | C15: 25000 | D15: 10500 | E15: 25000 | F15: 4400.55 | G15: 4400.55
A16: WSWT1921720 | B16: บจก.เคอรี่ฟลาวมิลล์ | C16: 333000 | D16: 281400 | E16: 333000 | F16: 27415 | G16: 268455.63 | H16: =G16 -> 268455.63
A17: WSWT1921720 ผลรวม | C17: 333000 | D17: 281400 | E17: 333000 | F17: 27415 | G17: 268455.63
A18: WSWT1925800 | B18: บจก.เพรซิเดนท์ฟลาวมิลล์ | C18: 135000 | D18: 136164 | E18: 129680 | F18: 31096.775 | G18: 83035.89 | H18: =G18 -> 83035.89
B19: บจก.ซีแมนอินดัสตรี | C19: 30000 | D19: 31500 | E19: 30000 | F19: 0 | G19: 24726.9 | H19: =G19 -> 24726.9
B20: บจก.ไลม์มาสเตอร์ | C20: 10000 | D20: 0 | E20: 0 | F20: 0 | G20: 0 | H20: =G20 -> 0
B21: หจก.ชนุตร์ แคเซี่ยม 888 | C21: 5000 | D21: 5250 | E21: 5000 | F21: 0 | G21: 4679.95 | H21: =G21 -> 4679.95
A22: WSWT1925800 ผลรวม | C22: 180000 | D22: 172914 | E22: 164680 | F22: 31096.775 | G22: 112442.74
A23: WSWT2025650 | B23: บจก.อินเทคค์ โกลบอล | C23: 18300 | D23: 0 | E23: 16100 | F23: 0 | G23: 17318.609 | H23: =G23 -> 17318.609
A24: WSWT2025650 ผลรวม | C24: 18300 | D24: 0 | E24: 16100 | F24: 0 | G24: 17318.609
A25: WSWT2025700 | B25: บจก.เบทาโกร | C25: 70000 | D25: 52500 | E25: 60000 | F25: 0 | G25: 67894.2 | H25: =G25 -> 67894.2
A26: WSWT2025700 ผลรวม | C26: 70000 | D26: 52500 | E26: 60000 | F26: 0 | G26: 67894.2
A27: WSWT2025800 | B27: บจก.เคอรี่ฟลาวมิลล์ | C27: 20000 | D27: 21000 | E27: 20000 | F27: 0 | G27: 18719.8 | H27: =G27 -> 18719.8
B28: บจก.เบทาโกร | C28: 35000 | D28: 26250 | E28: 25042 | F28: 0 | G28: 26892.25 | H28: =G28 -> 26892.25
B29: บจก.อินเทคค์ โกลบอล | C29: 204880 | D29: 178500 | E29: 190726 | F29: 2770 | G29: 175347.5 | H29: =G29 -> 175347.5
A30: WSWT2025800 ผลรวม | C30: 259880 | D30: 225750 | E30: 235768 | F30: 2770 | G30: 220959.55
A31: WSWT2025800SM | B31: บจก.ซันฟีด | C31: 50000 | D31: 52500 | E31: 50000 | F31: 55041.8 | G31: 0 | H31: =G31 -> 0
B32: บจก.ไทยธรรมดี | C32: 15000 | D32: 5199.6 | E32: 15000 | F32: 5593.1577 | G32: 0 | H32: =G32 -> 0
B33: บจก.เบทาโกร | C33: 25000 | D33: 26250 | E33: 25000 | F33: 5099.05 | G33: 20396.2 | H33: =G33 -> 20396.2
B34: บจก.อินเทคค์ โกลบอล | C34: 20080 | D34: 21084 | E34: 20080 | F34: 21038.82 | G34: 0 | H34: =G34 -> 0
B35: บจก.เอ.เจ.ฟาร์ม่าแล็บ | C35: 8000 | D35: 0 | E35: 866 | F35: 0 | G35: 0 | H35: =G35 -> 0
B36: บจก.เอพีเอ็ม อะโกร | C36: 31000 | D36: 32550 | E36: 31000 | F36: 28582.62 | G36: 5518.15 | H36: =G36 -> 5518.15
B37: บจก.เอสพีเอ็ม อาหารสัตว์ | C37: 13000 | D37: 13650 | E37: 13000 | F37: 4638.04 | G37: 9932.67 | H37: =G37 -> 9932.67
B38: คุณชายชล จันทร์สว่างกูล | C38: 1000 | D38: 0 | E38: 0 | F38: 0 | G38: 0 | H38: =G38 -> 0
B39: บจก.มารีน ลีดเดอร์ | C39: 10000 | D39: 10500 | E39: 10000 | F39: 8801.1 | G39: 0 | H39: =G39 -> 0
A40: WSWT2025800SM ผลรวม | C40: 173080 | D40: 161733.6 | E40: 164946 | F40: 128794.59 | G40: 35847.02
A41: WSWT2025850 | B41: บจก.ซันฟีด | C41: 235000 | D41: 246750 | E41: 235000 | F41: 0 | G41: 258235.45 | H41: =G41 -> 258235.45
...

Sheet 1(Fc) แยกลูกค้
A1: เลขที่ SO | B1: ประมาณการ
A2: วันส่ง | B2: (หลายรายการ) | D2: 12
A4: ประเภท | B4: ชื่อลูกค้า | C4: ผลรวม ของ จำนวนส่ง | D4: ผลรวม ของ ค้างพิมพ์ | E4: ผลรวม ของ ค้างตัด | F4: ผลรวม ของ Stock | G4: ผลรวม ของ ใช้ | H4: ผลรวม ของ ค้างทอ
A5: WSWT1921720 | B5: บจก.เคอรี่ฟลาวมิลล์ | C5: 30000 | D5: 31500 | E5: 30000 | F5: 0 | G5: 26403.3 | H5: 26403.3
A6: WSWT1921720 ผลรวม | C6: 30000 | D6: 31500 | E6: 30000 | F6: 0 | G6: 26403.3 | H6: 26403.3
A7: WSWT2021750 | B7: คุณสมบัติ นิมวชิรวัฒนา | C7: 5000 | D7: 5250 | E7: 5000 | F7: 589 | G7: 5378.45 | H7: 4789.45
A8: WSWT2021750 ผลรวม | C8: 5000 | D8: 5250 | E8: 5000 | F8: 589 | G8: 5378.45 | H8: 4789.45
A9: WSWT2025650 | B9: บจก.เอเชียเหมืองแร่ | C9: 15000 | D9: 15750 | E9: 15000 | F9: 0 | G9: 14039.85 | H9: 14039.85
A10: WSWT2025650 ผลรวม | C10: 15000 | D10: 15750 | E10: 15000 | F10: 0 | G10: 14039.85 | H10: 14039.85
A11: WSWT2025800SM | B11: บจก.ไทยธรรมดี | C11: 20000 | D11: 21000 | E11: 20000 | F11: 21513.8 | G11: 21513.8 | H11: 0
B12: บจก.อินเทคค์ โกลบอล | C12: 50000 | D12: 52500 | E12: 50000 | F12: 52387.5 | G12: 52387.5 | H12: 0
B13: บจก.เอสพีเอ็ม อาหารสัตว์ | C13: 50000 | D13: 52500 | E13: 50000 | F13: 55181.5 | G13: 55181.5 | H13: 0
B14: บจก.วีซีเอฟ | C14: 100000 | D14: 105000 | E14: 100000 | F14: 0 | G14: 107569 | H14: 107569
A15: WSWT2025800SM ผลรวม | C15: 220000 | D15: 231000 | E15: 220000 | F15: 129082.8 | G15: 236651.8 | H15: 107569
A16: WSWT2025850 | B16: บจก.ซันฟีด | C16: 200000 | D16: 210000 | E16: 200000 | F16: 0 | G16: 226314 | H16: 226314
B17: บจก.ไทยธรรมดี | C17: 10000 | D17: 0 | E17: 10000 | F17: 0 | G17: 10756.9 | H17: 10756.9
A18: WSWT2025850 ผลรวม | C18: 210000 | D18: 210000 | E18: 210000 | F18: 0 | G18: 237070.9 | H18: 237070.9
A19: WSWT2121670SM | B19: บจก.เอ็นบี ดิสทริบิวชั่น | C19: 40000 | D19: 42000 | E19: 40000 | F19: 0 | G19: 43027.6 | H19: 43027.6
A20: WSWT2121670SM ผลรวม | C20: 40000 | D20: 42000 | E20: 40000 | F20: 0 | G20: 43027.6 | H20: 43027.6
A21: WSWT2325650 | B21: บจก.ซิเบลโก้ | C21: 30000 | D21: 31500 | E21: 30000 | F21: 0 | G21: 31991.3 | H21: 31991.3
A22: WSWT2325650 ผลรวม | C22: 30000 | D22: 31500 | E22: 30000 | F22: 0 | G22: 31991.3 | H22: 31991.3
A23: WSWT2625650 | B23: บจก.โอเชี่ยนฟีด | C23: 40000 | D23: 0 | E23: 40000 | F23: 0 | G23: 48615.6 | H23: 48615.6
B24: บจก.เบสท์ อินเตอร์เทรด | C24: 5000 | D24: 0 | E24: 5000 | F24: 0 | G24: 5797.55 | H24: 5797.55
B25: บจก.กบินทร์อินทรีย์ | C25: 10000 | D25: 10500 | E25: 10000 | F25: 0 | G25: 11874.5 | H25: 11874.5
A26: WSWT2625650 ผลรวม | C26: 55000 | D26: 10500 | E26: 55000 | F26: 0 | G26: 66287.65 | H26: 66287.65
A27: WSWT262575051 | B27: บจก.ทีพีเค แอ็ดวานซ์ สตาร์ซ | C27: 20000 | D27: 21000 | E27: 20000 | F27: 3670 | G27: 24866.6 | H27: 21196.6
A28: WSWT262575051 ผลรวม | C28: 20000 | D28: 21000 | E28: 20000 | F28: 3670 | G28: 24866.6 | H28: 21196.6
A29: ผลรวมทั้งหมด | C29: 625000 | D29: 598500 | E29: 625000 | F29: 133341.8 | G29: 685717.45 | H29: 552375.65
D119: Cap พิมพ์ | E119: Cap ตัด | F119: Stock 16/7 บ่าย | G119: Cap ทอ | I119: วันทงาน
B120: lส่ง | C120: 1-16/7 | D120: 160000 | E120: 160000 | G120: 120000 | I120: 12
C121: 1975256 | D121: =+D120*I120 -> 1920000 | E121: =+E120*I120 -> 1920000 | F121: 825147 | G121: =+G120*I120 -> 1440000
A122: เบทาโกรส่งแล้ว | B122: 20700 | C122: 424374
A123: เบทาโกรส่งแล้ว | B123: 20800 | C123: 155973
C126: รวมส่ง+ค้างส่ง | D126: ส่วนต่างCapคงเหลือ | E126: ส่วนต่างCapคงเหลือ | F126: คงเหลือ
C127: =+C50+C121 -> 1975256 | D127: =+D121-D50 -> 1920000 | E127: =+E121-E50 -> 1920000 | F127: =+F121-F50 -> 825147 | G127: =+G121-G50 -> 1440000
B129: 20700VN 20/7 | G129: 350000

Sheet ค้างทอ4-1-68
A3: ผลรวม ของ ค้างทอ
A4: ป้ายชื่อแถว | B4: 45658 | C4: 45659 | D4: 45660 | E4: 45661 | F4: 45662 | G4: 45663 | H4: 45665 | I4: 45666 | J4: 45667 | K4: 45668 | L4: 45669 | M4: 45670 | N4: 45672 | O4: 45673 | P4: 45674 | Q4: 45675 | R4: 45676 | S4: 45677 | T4: 45679 | U4: 45680 | V4: 45681 | W4: 45682 | X4: 45683 | Y4: 45686 | Z4: 45698 | AA4: 45700 | AB4: ผลรวมทั้งหมด
A5: WSWT1425800 | B5: 0 | AB5: =SUM(B5:AA5) -> 0
A6: WSWT1725800 | G6: 6312.8975 | AB6: =SUM(B6:AA6) -> 6312.8975
A7: WSWT1825800 | G7: 19988.75 | J7: 15841.98 | AB7: =SUM(B7:AA7) -> 35830.73
A8: WSWT1825800SM | B8: 0 | J8: 4400.55 | AB8: =SUM(B8:AA8) -> 4400.55
A9: WSWT1921720 | B9: 7558.1 | E9: 35483.8 | F9: 17602.2 | G9: 35763.2 | H9: 25204.4 | I9: 44564.3 | J9: 9359.9 | K9: 16680.18 | L9: 22002.75 | M9: 35483.8 | O9: 22002.75 | P9: 17602.2 | S9: 8801.1 | AB9: =SUM(B9:AA9) -> 298108.68
A10: WSWT19251000SM | AB10: =SUM(B10:AA10) -> 0
A11: WSWT1925800 | C11: 0 | D11: 10758.19 | H11: 24726.9 | J11: 66287.65 | AB11: =SUM(B11:AA11) -> 101772.74
A12: WSWT2021750 | AB12: =SUM(B12:AA12) -> 0
A13: WSWT2025650 | B13: 10968.609 | AB13: =SUM(B13:AA13) -> 10968.609
A14: WSWT2025700 | D14: 56578.5 | G14: 11315.7 | AB14: =SUM(B14:AA14) -> 67894.2
A15: WSWT2025800 | C15: 18743.8 | D15: 31432.5 | E15: 31432.5 | F15: 31432.5 | G15: 9359.9 | J15: 31432.5 | L15: 0 | M15: 9359.9 | N15: 26333.45 | S15: 20955 | T15: 0 | V15: 10477.5 | AB15: =SUM(B15:AA15) -> 220959.55
A16: WSWT2025800SM | B16: 0 | C16: 0 | F16: 0 | H16: 0 | I16: 0 | J16: 3058.05 | L16: 0 | O16: 10198.1 | P16: 0 | Q16: 0 | R16: 0 | U16: 0 | W16: 5518.15 | X16: 4414.52 | AB16: =SUM(B16:AA16) -> 23188.82
A17: WSWT2025850 | C17: 0 | F17: 21513.8 | I17: 29860.875 | L17: 18964.275 | O17: 19103.975 | P17: 28009.85 | Q17: 22072.6 | R17: 10896.6 | U17: 41595.675 | V17: 27451.05 | W17: 28009.85 | X17: 10756.9 | AB17: =SUM(B17:AA17) -> 258235.45
A18: WSWT2121670SM | B18: 0 | E18: 32635.628 | F18: 10756.9 | H18: 37788.85 | N18: 17211.04 | Y18: 17211.04 | AA18: 17211.04 | AB18: =SUM(B18:AA18) -> 132814.5
A19: WSWT2125650 | B19: 2828.15 | D19: 22072.6 | Q19: 17811.75 | AB19: =SUM(B19:AA19) -> 42712.5
A20: WSWT2125800 | G20: 6739.128 | AB20: =SUM(B20:AA20) -> 6739.128
A21: WSWT2321112512551 | E21: 0 | H21: 20084.26 | K21: 0 | N21: 55935.88 | Q21: 58087.26 | T21: 58087.26 | W21: 58087.26 | AB21: =SUM(B21:AA21) -> 250281.92
A22: WSWT2321750 | AB22: =SUM(B22:AA22) -> 0
A23: WSWT2325650 | B23: 0 | N23: 57732.2 | AB23: =SUM(B23:AA23) -> 57732.2
A24: WSWT2421112512551 | Z24: 29447.876 | AB24: =SUM(B24:AA24) -> 29447.876
A25: WSWT2625650 | B25: 7920.99 | E25: 6216.65 | AB25: =SUM(B25:AA25) -> 14137.64
A26: WSWT262575051 | AB26: =SUM(B26:AA26) -> 0
A27: WSWT2625800 | D27: 14752.756 | L27: 24866.6 | AB27: =SUM(B27:AA27) -> 39619.356
A28: WSWT2625850SM | J28: 48284.5 | AB28: =SUM(B28:AA28) -> 48284.5
A29: WSWT2825850 | B29: 0 | K29: 7268.9369 | AB29: =SUM(B29:AA29) -> 7268.9369
A30: ผลรวมทั้งหมด | B30: =SUM(B5:B29) -> 29275.849 | C30: =SUM(C5:C29) -> 18743.8 | D30: =SUM(D5:D29) -> 135594.55 | E30: =SUM(E5:E29) -> 105768.58 | F30: =SUM(F5:F29) -> 81305.4 | G30: =SUM(G5:G29) -> 89479.576 | H30: =SUM(H5:H29) -> 107804.41 | I30: =SUM(I5:I29) -> 74425.175 | ... AB30: =SUM(AB5:AB29) -> 1656710.8

Sheet ค้างทอ7-1-68
A3: ผลรวม ของ ค้างทอ | Z3: ผลรวม ของ ค้างทอ
A4: ป้ายชื่อแถว | B4: 45660 | C4: 45661 | D4: 45662 | E4: 45663 | F4: 45665 | G4: 45666 | H4: 45667 | I4: 45668 | J4: 45669 | K4: 45670 | L4: 45672 | M4: 45673 | N4: 45674 | O4: 45675 | P4: 45676 | Q4: 45677 | R4: 45679 | S4: 45680 | T4: 45681 | U4: 45682 | V4: 45683 | W4: 45686 | X4: ค้างทอ | Z4: ป้ายชื่อแถว | AA4: 45690 | AB4: 45693 | AC4: 45698 | AD4: 45700 | AE4: 45703 | AF4: ผลรวมทั้งหมด
A5: WSWT1725800 | E5: 1303.8975 | X5: =SUM(B5:W5) -> 1303.8975 | Z5: WSWT1725800 | AF5: =SUM(AA5:AE5) -> 0
A6: WSWT1825800 | E6: 7682.75 | H6: 15841.98 | X6: =SUM(B6:W6) -> 23524.73 | Z6: WSWT1825800 | AF6: =SUM(AA6:AE6) -> 0
A7: WSWT1825800SM | H7: 4400.55 | X7: =SUM(B7:W7) -> 4400.55 | Z7: WSWT1825800SM | AF7: =SUM(AA7:AE7) -> 0
A8: WSWT1921720 | C8: 2952.1 | D8: 17602.2 | E8: 35763.2 | F8: 25204.4 | G8: 44564.3 | H8: 9359.9 | I8: 16680.18 | J8: 22002.75 | K8: 35483.8 | M8: 22002.75 | N8: 17602.2 | O8: 22002.75 | Q8: 22002.75 | S8: 22840.95 | X8: =SUM(B8:W8) -> 316064.23 | Z8: WSWT1921720 | AF8: =SUM(AA8:AE8) -> 0
A9: WSWT19251000SM | X9: =SUM(B9:W9) -> 0 | Z9: WSWT19251000SM | AF9: =SUM(AA9:AE9) -> 0
A10: WSWT1925800 | C10: 0 | F10: 18632.9 | H10: 4679.95 | J10: 4959.35 | L10: 44005.5 | X10: =SUM(B10:W10) -> 72277.7 | Z10: WSWT1925800 | AF10: =SUM(AA10:AE10) -> 0
A11: WSWT2021750 | X11: =SUM(B11:W11) -> 0 | Z11: WSWT2021750 | AF11: =SUM(AA11:AE11) -> 0
A12: WSWT2025650 | C12: 5607.4966 | X12: =SUM(B12:W12) -> 5607.4966 | Z12: WSWT2025650 | AF12: =SUM(AA12:AE12) -> 0
A13: WSWT2025700 | B13: 12796.45 | E13: 10743.126 | X13: =SUM(B13:W13) -> 23539.576 | Z13: WSWT2025700 | AF13: =SUM(AA13:AE13) -> 0
A14: WSWT2025800 | B14: 37670.588 | C14: 23220.236 | D14: 31432.5 | E14: 9359.9 | H14: 31432.5 | J14: 0 | K14: 9359.9 | L14: 63982.6 | P14: 69919.85 | Q14: 20955 | R14: 0 | T14: 69640.45 | X14: =SUM(B14:W14) -> 366973.52 | Z14: WSWT2025800 | AA14: 43027.6 | AB14: 43027.6 | AE14: 10756.9 | AF14: =SUM(AA14:AE14) -> 96812.1
A15: WSWT2025800SM | D15: 0 | F15: 0 | G15: 0 | H15: 0 | J15: 0 | M15: 0 | N15: 0 | O15: 0 | P15: 0 | S15: 0 | U15: 0 | V15: 0 | X15: =SUM(B15:W15) -> 0 | Z15: WSWT2025800SM | AF15: =SUM(AA15:AE15) -> 0
A16: WSWT2025850 | D16: 19113.8 | G16: 29860.875 | J16: 18964.275 | M16: 19103.975 | N16: 28009.85 | O16: 22072.6 | P16: 10896.6 | S16: 41595.675 | T16: 27451.05 | U16: 28009.85 | V16: 10756.9 | X16: =SUM(B16:W16) -> 255835.45 | Z16: WSWT2025850 | AF16: =SUM(AA16:AE16) -> 0
A17: WSWT2121670SM | C17: 5378.45 | D17: 10756.9 | F17: 37788.85 | L17: 17211.04 | W17: 17211.04 | X17: =SUM(B17:W17) -> 88346.28 | Z17: WSWT2121670SM | AD17: 17211.04 | AF17: =SUM(AA17:AE17) -> 17211.04
A18: WSWT2125650 | B18: 19469.785 | O18: 17811.75 | X18: =SUM(B18:W18) -> 37281.535 | Z18: WSWT2125650 | AF18: =SUM(AA18:AE18) -> 0
A19: WSWT2125800 | E19: 0 | X19: =SUM(B19:W19) -> 0 | Z19: WSWT2125800 | AF19: =SUM(AA19:AE19) -> 0
A20: WSWT2321112512551 | C20: 0 | F20: 20084.26 | I20: 58087.26 | L20: 55935.88 | O20: 6454.14 | R20: 58087.26 | U20: 58087.26 | X20: =SUM(B20:W20) -> 256736.06 | Z20: WSWT2321112512551 | AF20: =SUM(AA20:AE20) -> 0
A21: WSWT2321750 | G21: 10756.9 | X21: =SUM(B21:W21) -> 10756.9 | Z21: WSWT2321750 | AF21: =SUM(AA21:AE21) -> 0
A22: WSWT2325650 | L22: 55232.2 | X22: =SUM(B22:W22) -> 55232.2 | Z22: WSWT2325650 | AF22: =SUM(AA22:AE22) -> 0
A23: WSWT2421112512551 | X23: =SUM(B23:W23) -> 0 | Z23: WSWT2421112512551 | AC23: 19737.876 | AF23: =SUM(AA23:AE23) -> 19737.876
A24: WSWT2625650 | C24: 0 | F24: 3665.99 | X24: =SUM(B24:W24) -> 3665.99 | Z24: WSWT2625650 | AF24: =SUM(AA24:AE24) -> 0
A25: WSWT262575051 | X25: =SUM(B25:W25) -> 0 | Z25: WSWT262575051 | AF25: =SUM(AA25:AE25) -> 0
A26: WSWT2625800 | B26: 6752.7564 | J26: 24866.6 | X26: =SUM(B26:W26) -> 31619.356 | Z26: WSWT2625800 | AF26: =SUM(AA26:AE26) -> 0
A27: WSWT2625850SM | H27: 26357.5 | X27: =SUM(B27:W27) -> 26357.5 | Z27: WSWT2625850SM | AF27: =SUM(AA27:AE27) -> 0
A28: WSWT2825850 | E28: 0 | I28: 4268.9369 | L28: 0 | X28: =SUM(B28:W28) -> 4268.9369 | Z28: WSWT2825850 | AF28: =SUM(AA28:AE28) -> 0
A29: ผลรวมทั้งหมด | B29: =SUM(B5:B28) -> 76689.579 | C29: =SUM(C5:C28) -> 37158.282 | D29: =SUM(D5:D28) -> 78905.4 | E29: =SUM(E5:E28) -> 64852.873 | F29: =SUM(F5:F28) -> 105376.4 | G29: =SUM(G5:G28) -> 85182.075 | H29: =SUM(H5:H28) -> 92072.38 | I29: =SUM(I5:I28) -> 79036.377 | ... W29: =SUM(W5:W28) -> 17211.04 | X29: =SUM(B29:W29) -> 1583791.9 | Z29: ผลรวมทั้งหมด | AA29: =SUM(AA5:AA28) -> 43027.6 | AB29: =SUM(AB5:AB28) -> 43027.6 | AC29: =SUM(AC5:AC28) -> 19737.876 | AD29: =SUM(AD5:AD28) -> 17211.04 | AE29: =SUM(AE5:AE28) -> 10756.9 | AF29: =SUM(AF5:AF28) -> 133761.02
A32: WSWT2025800SMMLVN | H32: 21000 | I32: เมตร
A33: WSWT2121670SMLVN | H33: 75000 | I33: เมตร
A34: WSWT2121670SMLMVN | H34: 75000 | I34: เมตร
A35: WSWT2321112512551 FG | H35: 48000 | I35: ใบ

Sheet 8-1-68
B2: เรียงกำหนดส่ง | D2: ลบ 0 | T2: เรียง 1
B3: ข้อมูลUpdate ณ. วันที่ | D3: 45665 | E3: เวลา | G3: 11.1
A4: วันรับออร์เดอร์/แบบ | B4: เลขที่ SO | C4: ชื่อลูกค้า | D4: ตรา | E4: 10.3 | I4: น้ำหนัก | L4: บิด/จับจีบ | M4: ถุงใน | Q4: 44873 | S4: วิธีบรรจุ | T4: วันส่ง | U4: จำนวนส่ง | V4: ตัดเย็บ (ใบ) | W4: 44873 | X4: พิมพ์ (ใบ) | Y4: 44876 | Z4: ผ้าทอ (เมตร) Updateณ | AB4: 44876 | AD4: ผ้าเคลือบ(เมตร) | AF4: หมายเหตุ | AG4: เครื่อง
B5: เลขที่ SO | C5: ชื่อลูกค้า | D5: ตรา | E5: กว้าง | F5: ยาว | G5: สี | H5: เคลือบ | I5: กรัม/ใบ | J5: * | K5: aw | L5: บิด/จับจีบ | M5: กว้าง | N5: ยาว | O5: หนา | P5: ใช้(กก.) | Q5: Stock(กก.) | R5: ผลิต(กก.) | S5: วิธีบรรจุ | T5: วันส่ง | U5: จำนวนส่ง | V5: StockFG | W5: ค้างตัด | X5: พิมพ์แล้ว | Y5: ค้างพิมพ์ | Z5: ประเภท | AA5: ใช้ | AB5: Stock | AC5: ค้างทอ | AD5: Stock | AE5: ค้างเคลือบ | AF5: หมายเหตุ | AG5: ที่พิมพ์ได้ | AH5: process | AI5: Lead time | AJ5: วันที่ส่งPL | AK5: เคลือบ | AL5: ได้ ART | AM5: พิมพ์ | AN5: จีบ-บิด | AO5: ตัด-เย็บ | AP5: ทอ | AQ5: สวมถุง | AR5: เย็บปาก | AS5: PT | AT5: ม้วน | AU5: ตัด | AV5: ตอกตาไก่ | AW5: GROUP | AX5: ART | AY5: หมายเหตุปัญหา | AZ5: ราคา/ใบ | BA5: ราคารวม | BB5: workweek | BC5: เส้นเทป | BD5: จำนวน
A6: 45651 | B6: MK67-001730 | C6: โรงสีข้าวธัญญาวัฒน์ | D6: LUNG SHIN 12 kg | E6: 17 | F6: 26 | G6: ขาว | H6: 0 | I6: 48 | J6: ± | K6: 5 | L6: ไม่ | M6: ไม่สวมถุงใน | N6: 0 | O6: 0 | P6: 0 | Q6: 0 | R6: 0 | S6: 500กระสอบแบน | T6: 45668 | U6: 8850 | V6: 0 | W6: 8850 | X6: 0 | Y6: 9292.5 | Z6: WSWT1725800 | AA6: 6799.8975 | AB6: 6799.8975 | AC6: 0 | AD6: 0 | AE6: 0 | AF6: 0 | AG6: ยังไม่ได้พิมพ์ | AH6: P7 | AI6: 2 | AJ6: 45668 | AK6: 0 | AL6: 45659 | AM6: 45666 | AN6: 45667 | AO6: 45667 | AP6: 45663 | AQ6: 0 | AR6: 0 | AS6: 0 | AT6: 0 | AU6: 0 | AV6: 0 | AW6: งานพิมพ์ | AX6: รอART | AY6: 10/1 เย็น | AZ6: 0 | BA6: 0 | BB6: 0 | BC6: WRWT25800/WRWT25800 | BD6: 0
A7: 0 | B7: 0 | C7: 0 | D7: 0 | E7: 17 | F7: 26 | G7: 0 | H7: 0 | I7: 48 | J7: ± | K7: 5 | L7: 0 | M7: 0 | N7: 0 | O7: 0 | P7: 0 | Q7: 0 | R7: 0 | S7: 0 | U7: 0 | V7: 0 | W7: 0 | X7: 0 | Y7: 0 | Z7: WSWT1725800 | AA7: 6799.8975 | AB7: 6799.8975 | AC7: 0 | AD7: 0 | AE7: 0 | AF7: ระบุในSD | AG7: ผ้าขาว | AH7: 0 | AI7: 0 | AJ7: 0 | AK7: 0 | AL7: 0 | AM7: 0 | AN7: 0 | AO7: 0 | AP7: 0 | AQ7: 0 | AR7: 0 | AS7: 0 | AT7: 0 | AU7: 0 | AV7: 0 | AW7: 0 | AX7: 0 | AY7: 0 | AZ7: 0 | BA7: 0 | BB7: 0 | BC7: WRWT170800/WRWT25800 | BD7: 0
A8: 45659 | B8: MK68-000006 | C8: หจก.อนนท์อุตสาหกรรม | D8: อนนท์ 20 กก. | E8: 18 | F8: 28 | G8: ขาว | H8: 0 | I8: 50 | J8: ± | K8: 5 | L8: ไม่ | M8: 19 | N8: 31 | O8: 40 | P8: 363.27927 | Q8: 0 | R8: 363.27927 | S8: 500กระสอบ | T8: 45668 | U8: 25000 | V8: 0 | W8: 25000 | X8: 19025 | Y8: 6273.75 | Z8: WSWT1825800 | AA8: 5171.013 | AB8: 0 | AC8: 5171.013 | AD8: 0 | AE8: 0 | AF8: 0 | AG8: พร้อมส่ง | AH8: P9 | AI8: 3 | AJ8: 45668 | AK8: 0 | AL8: 45658 | AM8: 45665 | AN8: 45666 | AO8: 45666 | AP8: 45663 | AQ8: 45667 | AR8: 0 | AS8: 0 | AT8: 0 | AU8: 0 | AV8: 0 | AW8: งานพิมพ์ | AX8: รอART | AY8: 0 | AZ8: 0 | BA8: 0 | BB8: 0 | BC8: WRWT25800/WRWT25800 | BD8: 355.76569
A9: 45659 | B9: MK68-000009 | C9: บจก.ฟาร์เธอร์ส วิง ซัพพลาย | D9: รถไฟฟ้า | E9: 18 | F9: 30 | G9: ขาว | H9: 0 | I9: 54 | J9: ± | K9: 5 | L9: บิด | M9: 19 | N9: 33 | O9: 40 | P9: 232.02999 | Q9: 0 | R9: 232.02999 | S9: 500กระสอบ | T9: 45672 | U9: 15000 | V9: 0 | W9: 15000 | X9: 0 | Y9: 15750 | Z9: WSWT1825800 | AA9: 13201.65 | AB9: 0 | AC9: 13201.65 | AD9: 0 | AE9: 0 | AF9: 0 | AG9: ยังไม่ได้พิมพ์ | AH9: P9 | AI9: 3 | AJ9: 45672 | AK9: 0 | AL9: 45662 | AM9: 45669 | AN9: 45670 | AO9: 45670 | AP9: 45667 | AQ9: 45671 | AR9: 0 | AS9: 0 | AT9: 0 | AU9: 0 | AV9: 0 | AW9: งานพิมพ์ | AX9: รอART | AY9: 0 | AZ9: 0 | BA9: 0 | BB9: 0 | BC9: WRWT25800/WRWT25800 | BD9: 908.27352
A10: 45659 | B10: MK68-000009 | C10: บจก.ฟาร์เธอร์ส วิง ซัพพลาย | D10: ไม่พิมพ์ | E10: 18 | F10: 30 | G10: ขาว | H10: 0 | I10: 54 | J10: ± | K10: 5 | L10: ไม่ | M10: 19 | N10: 33 | O10: 40 | P10: 46.405998 | Q10: 0 | R10: 46.405998 | S10: 500กระสอบ | T10: 45672 | U10: 3000 | V10: 0 | W10: 3000 | X10: 0 | Y10: 0 | Z10: WSWT1825800 | AA10: 2640.33 | AB10: 0 | AC10: 2640.33 | AD10: 0 | AE10: 0 | AF10: 0 | AG10: พร้อมส่ง | AH10: P13 | AI10: 2 | AJ10: 45672 | AK10: 0 | AL10: 0 | AM10: 0 | AN10: 0 | AO10: 45670 | AP10: 45667 | AQ10: 45671 | AR10: 0 | AS10: 0 | AT10: 0 | AU10: 0 | AV10: 0 | AW10: ตัด | AX10: 0 | AY10: 0 | AZ10: 0 | BA10: 0 | BB10: 0 | BC10: WRWT25800/WRWT25800 | BD10: 181.6547
A11: 0 | B11: 0 | E11: 18 | F11: 30 | G11: ขาว | H11: 0 | I11: 54 | J11: ± | K11: 5 | L11: 0 | M11: 0 | N11: 0 | O11: 0 | P11: 0 | Q11: 0 | R11: 0 | S11: 0 | U11: 0 | V11: 0 | W11: 0 | X11: 0 | Y11: 0 | Z11: WSWT1825800 | AA11: 21012.993 | AB11: 0 | AC11: 21012.993 | AD11: 0 | AE11: 0 | AF11: ระบุในSD | AG11: พิมพ์ไม่ครบ | AH11: 0 | AI11: Lead time | AJ11: 0 | AK11: 0 | AL11: 0 | AM11: 0 | AN11: 0 | AO11: 0 | AP11: 0 | AQ11: 0 | AR11: 0 | AS11: 0 | AT11: 0 | AU11: 0 | AV11: 0 | AW11: 0 | AX11: 0 | AY11: 0 | AZ11: 0 | BA11: 0 | BB11: 0 | BC11: WRWT25800/WRWT25800 | BD11: 0
