Workbook

Sheet Linkสูตรออร์เดอร์  (2)
B2: เรียงกำหนดส่ง | D2: ลบ 0 | T2: เรียง 1
B3: ข้อมูลUpdate ณ. วันที่ | D3: 45754 | E3: เวลา | G3: 10.22
A4: วันรับออร์เดอร์/แบบ | B4: เลขที่ SO | C4: ชื่อลูกค้า | E4: 10.3 | I4: น้ำหนัก | L4: บิด/จับจีบ | M4: ถุงใน | Q4: =[1]หน้าผ้า!$AC$13 -> 44873 | S4: วิธีบรรจุ | T4: วันส่ง | U4: จำนวนส่ง | V4: ตัดเย็บ (ใบ) | W4: =[1]หน้าผ้า!$AJ$13 -> 44873 | X4: พิมพ์ (ใบ) | Y4: =[1]หน้าผ้า!$AM$13 -> 44876 | Z4: ผ้าทอ (เมตร) Updateณ | AB4: =[1]หน้าผ้า!$AR$12 -> 44876 | AD4: ผ้าเคลือบ(เมตร) | AF4: หมายเหตุ | AG4: เครื่อง
B5: เลขที่ SO | C5: ชื่อลูกค้า | D5: ตรา | E5: กว้าง | F5: ยาว | G5: สี | H5: เคลือบ | I5: กรัม/ใบ | J5: * | K5: aw | L5: บิด/จับจีบ | M5: กว้าง | N5: ยาว | O5: หนา | P5: ใช้(กก.) | Q5: Stock(กก.) | R5: ผลิต(กก.) | S5: วิธีบรรจุ | T5: วันส่ง | U5: จำนวนส่ง | V5: StockFG | W5: ค้างตัด | X5: พิมพ์แล้ว | Y5: ค้างพิมพ์ | Z5: ประเภท | AA5: ใช้ | AB5: Stock | AC5: ค้างทอ | AD5: Stock | AE5: ค้างเคลือบ | AF5: หมายเหตุ | AG5: ที่พิมพ์ได้ | AH5: process | AI5: Lead time | AJ5: วันที่ส่งPL | AK5: เคลือบ | AL5: ได้ ART | AM5: พิมพ์ | AN5: จีบ-บิด | AO5: ตัด-เย็บ | AP5: ทอ | AQ5: สวมถุง | AR5: เย็บปาก | AS5: PT | AT5: ม้วน | AU5: ตัด | AV5: ตอกตาไก่ | AW5: GROUP | AX5: ART | AY5: หมายเหตุปัญหา | AZ5: ราคา/ใบ | BA5: ราคารวม | BB5: workweek | BC5: เส้นเทป | BD5: จำนวน
A6: =[2]หน้าผ้า!C15 -> 0 | B6: =[2]หน้าผ้า!B15 -> 0 | C6: =[2]หน้าผ้า!E15 -> 0 | D6: =[2]หน้าผ้า!F15 -> 0 | E6: =[2]หน้าผ้า!G15 -> 12 | F6: =[2]หน้าผ้า!H15 -> 16 | G6: =[2]หน้าผ้า!I15 -> ขาว | H6: =[2]หน้าผ้า!J15 -> 0 | I6: =[2]หน้าผ้า!L15 -> 25 | J6: =[2]หน้าผ้า!M15 -> ± | K6: =[2]หน้าผ้า!N15 -> 5 | L6: =[2]หน้าผ้า!R15 -> 0 | M6: =[2]หน้าผ้า!T15 -> 0 | N6: =[2]หน้าผ้า!U15 -> 0 | O6: =[2]หน้าผ้า!V15 -> 0 | P6: =[2]หน้าผ้า!AB15 -> 0 | Q6: =[2]หน้าผ้า!AC15 -> 0 | R6: =[2]หน้าผ้า!AD15 -> 0 | S6: =[2]หน้าผ้า!Z15 -> 0 | T6: =[2]หน้าผ้า!X15 -> 0 | U6: =[2]หน้าผ้า!AA15 -> 0 | V6: =[2]หน้าผ้า!AJ15 -> 0 | W6: =[2]หน้าผ้า!AL15 -> 0 | X6: =[2]หน้าผ้า!AM15 -> 0 | Y6: =[2]หน้าผ้า!AN15 -> 0 | Z6: =[2]หน้าผ้า!AO15 -> WSWT1221750 | AA6: =[2]หน้าผ้า!AQ15 -> #REF! | AB6: =[2]หน้าผ้า!AR15 -> #REF! | AC6: =[2]หน้าผ้า!AS15 -> #REF! | AD6: =[2]หน้าผ้า!AT15 -> #REF! | AE6: =[2]หน้าผ้า!AU15 -> #REF! | AF6: =[2]หน้าผ้า!AI15 -> ระบุในSD | AG6: =[3]หน้าผ้า!DC18 -> < Ord 20,000 | AH6: =[2]หน้าผ้า!DL15 -> 0 | AI6: =[2]หน้าผ้า!DM15 -> 0 | AJ6: =[2]หน้าผ้า!DN15 -> 0 | AK6: =[2]หน้าผ้า!DQ15 -> 0 | AL6: =[2]หน้าผ้า!DR15 -> 0 | AM6: =[2]หน้าผ้า!DS15 -> 0 | AN6: =[2]หน้าผ้า!DT15 -> 0 | AO6: =[2]หน้าผ้า!DU15 -> 0 | AP6: =[2]หน้าผ้า!DP15 -> 0 | AQ6: =[2]หน้าผ้า!DW15 -> 0 | AR6: =[2]หน้าผ้า!DX15 -> 0 | AS6: =[2]หน้าผ้า!DY15 -> 0 | AT6: =[2]หน้าผ้า!DZ15 -> 0 | AU6: =[2]หน้าผ้า!EA15 -> 0 | AV6: =[2]หน้าผ้า!EB15 -> 0 | AW6: =[2]หน้าผ้า!EC15 -> 0 | AX6: =[2]หน้าผ้า!ED15 -> 0 | AY6: =[2]หน้าผ้า!AG15 -> 0 | AZ6: =[2]หน้าผ้า!EG15 -> 0 | BA6: =[2]หน้าผ้า!EH15 -> 0 | BB6: =[2]หน้าผ้า!EI15 -> 0 | BC6: =[2]หน้าผ้า!BZ15 -> WRWT120750/WRWT21750 | BD6: =[2]หน้าผ้า!CA15 -> 0
A7: =[2]หน้าผ้า!C16 -> 45743 | B7: =[2]หน้าผ้า!B16 -> MK68-000464 | C7: =[2]หน้าผ้า!E16 -> บจก.ปึงเป้งน้ำ | D7: =[2]หน้าผ้า!F16 -> เกลือตรามือ 10กก. | E7: =[2]หน้าผ้า!G16 -> 14 | F7: =[2]หน้าผ้า!H16 -> 22 | G7: =[2]หน้าผ้า!I16 -> ขาว | H7: =[2]หน้าผ้า!J16 -> ใส | I7: =[2]หน้าผ้า!L16 -> 42 | J7: =[2]หน้าผ้า!M16 -> ± | K7: =[2]หน้าผ้า!N16 -> 5 | L7: =[2]หน้าผ้า!R16 -> ไม่ | M7: =[2]หน้าผ้า!T16 -> ไม่สวมถุงใน | N7: =[2]หน้าผ้า!U16 -> 0 | O7: =[2]หน้าผ้า!V16 -> 0 | P7: =[2]หน้าผ้า!AB16 -> 0 | Q7: =[2]หน้าผ้า!AC16 -> 0 | R7: =[2]หน้าผ้า!AD16 -> 0 | S7: =[2]หน้าผ้า!Z16 -> 500กระสอบแบน | T7: =[2]หน้าผ้า!X16 -> 45757 | U7: =[2]หน้าผ้า!AA16 -> 10000 | V7: =[2]หน้าผ้า!AJ16 -> 0 | W7: =[2]หน้าผ้า!AL16 -> 10000 | X7: =[2]หน้าผ้า!AM16 -> 0 | Y7: =[2]หน้าผ้า!AN16 -> 10500 | Z7: =[2]หน้าผ้า!AO16 -> WSWT1425800 | AA7: =[2]หน้าผ้า!AQ16 -> 6565.9 | AB7: =[2]หน้าผ้า!AR16 -> 6565.9 | AC7: =[2]หน้าผ้า!AS16 -> 0 | AD7: =[2]หน้าผ้า!AT16 -> 2186 | AE7: =[2]หน้าผ้า!AU16 -> 4379.9 | AF7: =[2]หน้าผ้า!AI16 -> 0 | AG7: =[3]หน้าผ้า!DC19 -> พร้อมส่ง | AH7: =[2]หน้าผ้า!DL16 -> P6 | AI7: =[2]หน้าผ้า!DM16 -> 4 | AJ7: =[2]หน้าผ้า!DN16 -> 45757 | AK7: =[2]หน้าผ้า!DQ16 -> 45753 | AL7: =[2]หน้าผ้า!DR16 -> 45746 | AM7: =[2]หน้าผ้า!DS16 -> 45754 | AN7: =[2]หน้าผ้า!DT16 -> 45755 | AO7: =[2]หน้าผ้า!DU16 -> 45756 | AP7: =[2]หน้าผ้า!DP16 -> 45752 | AQ7: =[2]หน้าผ้า!DW16 -> 0 | AR7: =[2]หน้าผ้า!DX16 -> 0 | AS7: =[2]หน้าผ้า!DY16 -> 0 | AT7: =[2]หน้าผ้า!DZ16 -> 0 | AU7: =[2]หน้าผ้า!EA16 -> 0 | AV7: =[2]หน้าผ้า!EB16 -> 0 | AW7: =[2]หน้าผ้า!EC16 -> งานเคลือบ+พิมพ์ | AX7: =[2]หน้าผ้า!ED16 -> / | AY7: =[2]หน้าผ้า!AG16 -> 0 | AZ7: =[2]หน้าผ้า!EG16 -> 0 | BA7: =[2]หน้าผ้า!EH16 -> 0 | BB7: =[2]หน้าผ้า!EI16 -> 0 | BC7: =[2]หน้าผ้า!BZ16 -> WRWT25800/WRWT25800 | BD7: =[2]หน้าผ้า!CA16 -> 0
A8: =[2]หน้าผ้า!C17 -> 0 | B8: =[2]หน้าผ้า!B17 -> 0 | C8: =[2]หน้าผ้า!E17 -> 0 | D8: =[2]หน้าผ้า!F17 -> 0 | E8: =[2]หน้าผ้า!G17 -> 14 | F8: =[2]หน้าผ้า!H17 -> 22 | G8: =[2]หน้าผ้า!I17 -> ขาว | H8: =[2]หน้าผ้า!J17 -> 0 | I8: =[2]หน้าผ้า!L17 -> 36 | J8: =[2]หน้าผ้า!M17 -> ± | K8: =[2]หน้าผ้า!N17 -> 5 | L8: =[2]หน้าผ้า!R17 -> 0 | M8: =[2]หน้าผ้า!T17 -> 0 | N8: =[2]หน้าผ้า!U17 -> 0 | O8: =[2]หน้าผ้า!V17 -> 0 | P8: =[2]หน้าผ้า!AB17 -> 0 | Q8: =[2]หน้าผ้า!AC17 -> 0 | R8: =[2]หน้าผ้า!AD17 -> 0 | S8: =[2]หน้าผ้า!Z17 -> 0 | T8: =[2]หน้าผ้า!X17 -> 0 | U8: =[2]หน้าผ้า!AA17 -> 0 | V8: =[2]หน้าผ้า!AJ17 -> 0 | W8: =[2]หน้าผ้า!AL17 -> 0 | X8: =[2]หน้าผ้า!AM17 -> 0 | Y8: =[2]หน้าผ้า!AN17 -> 0 | Z8: =[2]หน้าผ้า!AO17 -> WSWT1425800 | AA8: =[2]หน้าผ้า!AQ17 -> 6565.9 | AB8: =[2]หน้าผ้า!AR17 -> 6565.9 | AC8: =[2]หน้าผ้า!AS17 -> 0 | AD8: =[2]หน้าผ้า!AT17 -> 2186 | AE8: =[2]หน้าผ้า!AU17 -> 4379.9 | AF8: =[2]หน้าผ้า!AI17 -> ระบุในSD | AG8: =[3]หน้าผ้า!DC20 -> ยังไม่ได้พิมพ์ | AH8: =[2]หน้าผ้า!DL17 -> 0 | AI8: =[2]หน้าผ้า!DM17 -> Lead time | AJ8: =[2]หน้าผ้า!DN17 -> 0 | AK8: =[2]หน้าผ้า!DQ17 -> 0 | AL8: =[2]หน้าผ้า!DR17 -> 0 | AM8: =[2]หน้าผ้า!DS17 -> 0 | AN8: =[2]หน้าผ้า!DT17 -> 0 | AO8: =[2]หน้าผ้า!DU17 -> 0 | AP8: =[2]หน้าผ้า!DP17 -> 0 | AQ8: =[2]หน้าผ้า!DW17 -> 0 | AR8: =[2]หน้าผ้า!DX17 -> 0 | AS8: =[2]หน้าผ้า!DY17 -> 0 | AT8: =[2]หน้าผ้า!DZ17 -> 0 | AU8: =[2]หน้าผ้า!EA17 -> 0 | AV8: =[2]หน้าผ้า!EB17 -> 0 | AW8: =[2]หน้าผ้า!EC17 -> 0 | AX8: =[2]หน้าผ้า!ED17 -> 0 | AY8: =[2]หน้าผ้า!AG17 -> 0 | AZ8: =[2]หน้าผ้า!EG17 -> 0 | BA8: =[2]หน้าผ้า!EH17 -> 0 | BB8: =[2]หน้าผ้า!EI17 -> 0 | BC8: =[2]หน้าผ้า!BZ17 -> WRWT140800/WRWT25800 | BD8: =[2]หน้าผ้า!CA17 -> 0
A9: =[2]หน้าผ้า!C18 -> ประมาณการ | B9: =[2]หน้าผ้า!B18 -> ประมาณการ | C9: =[2]หน้าผ้า!E18 -> บจก.ซัน ซีเมนต์ โพรเซส | D9: =[2]หน้าผ้า!F18 -> พระอาทิตย์(ปูนนอน-ชริงค์) | E9: =[2]หน้าผ้า!G18 -> 16 | F9: =[2]หน้าผ้า!H18 -> 25 | G9: =[2]หน้าผ้า!I18 -> ขาว | H9: =[2]หน้าผ้า!J18 -> ใส | I9: =[2]หน้าผ้า!L18 -> 50 | J9: =[2]หน้าผ้า!M18 -> ± | K9: =[2]หน้าผ้า!N18 -> 5 | L9: =[2]หน้าผ้า!R18 -> บิด | M9: =[2]หน้าผ้า!T18 -> 19 | N9: =[2]หน้าผ้า!U18 -> 28 | O9: =[2]หน้าผ้า!V18 -> 40 | P9: =[2]หน้าผ้า!AB18 -> 65.624643 | Q9: =[2]หน้าผ้า!AC18 -> 0 | R9: =[2]หน้าผ้า!AD18 -> 65.624643 | S9: =[2]หน้าผ้า!Z18 -> 500กระสอบ | T9: =[2]หน้าผ้า!X18 -> รอแจ้ง | U9: =[2]หน้าผ้า!AA18 -> 5000 | V9: =[2]หน้าผ้า!AJ18 -> 0 | W9: =[2]หน้าผ้า!AL18 -> 5000 | X9: =[2]หน้าผ้า!AM18 -> 0 | Y9: =[2]หน้าผ้า!AN18 -> 5250 | Z9: =[2]หน้าผ้า!AO18 -> WSWT1625800SM | AA9: =[2]หน้าผ้า!AQ18 -> 3702.05 | AB9: =[2]หน้าผ้า!AR18 -> 3372 | AC9: =[2]หน้าผ้า!AS18 -> 330.05 | AD9: =[2]หน้าผ้า!AT18 -> 0 | AE9: =[2]หน้าผ้า!AU18 -> 3702.05 | AF9: =[2]หน้าผ้า!AI18 -> 0 | AG9: =[3]หน้าผ้า!DC21 -> ยังไม่ได้พิมพ์ | AH9: =[2]หน้าผ้า!DL18 -> P8 | AI9: =[2]หน้าผ้า!DM18 -> 4 | AJ9: =[2]หน้าผ้า!DN18 -> รอแจ้ง | AK9: =[2]หน้าผ้า!DQ18 -> #VALUE! | AL9: =[2]หน้าผ้า!DR18 -> #VALUE! | AM9: =[2]หน้าผ้า!DS18 -> #VALUE! | AN9: =[2]หน้าผ้า!DT18 -> #VALUE! | AO9: =[2]หน้าผ้า!DU18 -> #VALUE! | AP9: =[2]หน้าผ้า!DP18 -> #VALUE! | AQ9: =[2]หน้าผ้า!DW18 -> #VALUE! | AR9: =[2]หน้าผ้า!DX18 -> 0 | AS9: =[2]หน้าผ้า!DY18 -> 0 | AT9: =[2]หน้าผ้า!DZ18 -> 0 | AU9: =[2]หน้าผ้า!EA18 -> 0 | AV9: =[2]หน้าผ้า!EB18 -> 0 | AW9: =[2]หน้าผ้า!EC18 -> งานเคลือบ+พิมพ์ | AX9: =[2]หน้าผ้า!ED18 -> รอART | AY9: =[2]หน้าผ้า!AG18 -> 0 | AZ9: =[2]หน้าผ้า!EG18 -> 0 | BA9: =[2]หน้าผ้า!EH18 -> 0 | BB9: =[2]หน้าผ้า!EI18 -> 0 | BC9: =[2]หน้าผ้า!BZ18 -> WRWT25800/WRWT25800 | BD9: =[2]หน้าผ้า!CA18 -> 18.776178
A10: =[2]หน้าผ้า!C19 -> 0 | B10: =[2]หน้าผ้า!B19 -> 0 | C10: =[2]หน้าผ้า!E19 -> 0 | D10: =[2]หน้าผ้า!F19 | E10: =[2]หน้าผ้า!G19 -> 16 | F10: =[2]หน้าผ้า!H19 -> 25 | G10: =[2]หน้าผ้า!I19 -> ขาว | H10: =[2]หน้าผ้า!J19 -> 0 | I10: =[2]หน้าผ้า!L19 -> 45 | J10: =[2]หน้าผ้า!M19 -> ± | K10: =[2]หน้าผ้า!N19 -> 5 | L10: =[2]หน้าผ้า!R19 -> 0 | M10: =[2]หน้าผ้า!T19 -> 0 | N10: =[2]หน้าผ้า!U19 -> 0 | O10: =[2]หน้าผ้า!V19 -> 0 | P10: =[2]หน้าผ้า!AB19 -> 0 | Q10: =[2]หน้าผ้า!AC19 -> 0 | R10: =[2]หน้าผ้า!AD19 -> 0 | S10: =[2]หน้าผ้า!Z19 -> 0 | T10: =[2]หน้าผ้า!X19 -> 0 | U10: =[2]หน้าผ้า!AA19 -> 0 | V10: =[2]หน้าผ้า!AJ19 -> 0 | W10: =[2]หน้าผ้า!AL19 -> 0 | X10: =[2]หน้าผ้า!AM19 -> 0 | Y10: =[2]หน้าผ้า!AN19 -> 0 | Z10: =[2]หน้าผ้า!AO19 -> WSWT1625800SM | AA10: =[2]หน้าผ้า!AQ19 -> 3702.05 | AB10: =[2]หน้าผ้า!AR19 -> 3372 | AC10: =[2]หน้าผ้า!AS19 -> 330.05 | AD10: =[2]หน้าผ้า!AT19 -> 0 | AE10: =[2]หน้าผ้า!AU19 -> 3702.05 | AF10: =[2]หน้าผ้า!AI19 -> ระบุในSD | AG10: =[3]หน้าผ้า!DC22 -> พร้อมส่ง | AH10: =[2]หน้าผ้า!DL19 -> 0 | AI10: =[2]หน้าผ้า!DM19 -> Lead time | AJ10: =[2]หน้าผ้า!DN19 -> 0 | AK10: =[2]หน้าผ้า!DQ19 -> 0 | AL10: =[2]หน้าผ้า!DR19 -> 0 | AM10: =[2]หน้าผ้า!DS19 -> 0 | AN10: =[2]หน้าผ้า!DT19 -> 0 | AO10: =[2]หน้าผ้า!DU19 -> 0 | AP10: =[2]หน้าผ้า!DP19 -> 0 | AQ10: =[2]หน้าผ้า!DW19 -> 0 | AR10: =[2]หน้าผ้า!DX19 -> 0 | AS10: =[2]หน้าผ้า!DY19 -> 0 | AT10: =[2]หน้าผ้า!DZ19 -> 0 | AU10: =[2]หน้าผ้า!EA19 -> 0 | AV10: =[2]หน้าผ้า!EB19 -> 0 | AW10: =[2]หน้าผ้า!EC19 -> 0 | AX10: =[2]หน้าผ้า!ED19 -> 0 | AY10: =[2]หน้าผ้า!AG19 -> 0 | AZ10: =[2]หน้าผ้า!EG19 -> 0 | BA10: =[2]หน้าผ้า!EH19 -> 0 | BB10: =[2]หน้าผ้า!EI19 -> 0 | BC10: =[2]หน้าผ้า!BZ19 -> WRWT160800/WRWT25800 | BD10: =[2]หน้าผ้า!CA19 -> 0
A11: =[2]หน้าผ้า!C20 -> 45751 | B11: =[2]หน้าผ้า!B20 -> MK68-000511 | C11: =[2]หน้าผ้า!E20 -> บจก.เคอรี่ฟลาวมิลล์ | D11: =[2]หน้าผ้า!F20 -> โบว์น้ำเงิน 10กก. | E11: =[2]หน้าผ้า!G20 -> 16 | F11: =[2]หน้าผ้า!H20 -> 25 | G11: =[2]หน้าผ้า!I20 -> ขาว | H11: =[2]หน้าผ้า!J20 -> 0 | I11: =[2]หน้าผ้า!L20 -> 45 | J11: =[2]หน้าผ้า!M20 -> ± | K11: =[2]หน้าผ้า!N20 -> 5 | L11: =[2]หน้าผ้า!R20 -> ไม่ | M11: =[2]หน้าผ้า!T20 -> ไม่สวมถุงใน | N11: =[2]หน้าผ้า!U20 -> 0 | O11: =[2]หน้าผ้า!V20 -> 0 | P11: =[2]หน้าผ้า!AB20 -> 0 | Q11: =[2]หน้าผ้า!AC20 -> 0 | R11: =[2]หน้าผ้า!AD20 -> 0 | S11: =[2]หน้าผ้า!Z20 -> ห่ออัดเบลแบน500 | T11: =[2]หน้าผ้า!X20 -> 45773 | U11: =[2]หน้าผ้า!AA20 -> 5000 | V11: =[2]หน้าผ้า!AJ20 -> 0 | W11: =[2]หน้าผ้า!AL20 -> 5000 | X11: =[2]หน้าผ้า!AM20 -> 0 | Y11: =[2]หน้าผ้า!AN20 -> 5250 | Z11: =[2]หน้าผ้า!AO20 -> WSWT1625800 | AA11: =[2]หน้าผ้า!AQ20 -> 3702.05 | AB11: =[2]หน้าผ้า!AR20 -> 3702.05 | AC11: =[2]หน้าผ้า!AS20 -> 0 | AD11: =[2]หน้าผ้า!AT20 -> 0 | AE11: =[2]หน้าผ้า!AU20 -> 0 | AF11: =[2]หน้าผ้า!AI20 -> PDR250117 | AG11: =[3]หน้าผ้า!DC23 -> ยังไม่ได้พิมพ์ | AH11: =[2]หน้าผ้า!DL20 -> P7 | AI11: =[2]หน้าผ้า!DM20 -> 2 | AJ11: =[2]หน้าผ้า!DN20 -> 45773 | AK11: =[2]หน้าผ้า!DQ20 -> 0 | AL11: =[2]หน้าผ้า!DR20 -> 45764 | AM11: =[2]หน้าผ้า!DS20 -> 45771 | AN11: =[2]หน้าผ้า!DT20 -> 45772 | AO11: =[2]หน้าผ้า!DU20 -> 45772 | AP11: =[2]หน้าผ้า!DP20 -> 45768 | AQ11: =[2]หน้าผ้า!DW20 -> 0 | AR11: =[2]หน้าผ้า!DX20 -> 0 | AS11: =[2]หน้าผ้า!DY20 -> 0 | AT11: =[2]หน้าผ้า!DZ20 -> 0 | AU11: =[2]หน้าผ้า!EA20 -> 0 | AV11: =[2]หน้าผ้า!EB20 -> 0 | AW11: =[2]หน้าผ้า!EC20 -> งานพิมพ์ | AX11: =[2]หน้าผ้า!ED20 -> / | AY11: =[2]หน้าผ้า!AG20 -> 0 | AZ11: =[2]หน้าผ้า!EG20 -> 0 | BA11: =[2]หน้าผ้า!EH20 -> 0 | BB11: =[2]หน้าผ้า!EI20 -> 0 | BC11: =[2]หน้าผ้า!BZ20 -> WRWT25800/WRWT25800 | BD11: =[2]หน้าผ้า!CA20 -> 0
A12: =[2]หน้าผ้า!C21 -> 45751 | B12: =[2]หน้าผ้า!B21 -> MK68-000511 | C12: =[2]หน้าผ้า!E21 -> บจก.เคอรี่ฟลาวมิลล์ | D12: =[2]หน้าผ้า!F21 -> โบว์แดง 10กก. | E12: =[2]หน้าผ้า!G21 -> 16 | F12: =[2]หน้าผ้า!H21 -> 25 | G12: =[2]หน้าผ้า!I21 -> ขาว | H12: =[2]หน้าผ้า!J21 -> 0 | I12: =[2]หน้าผ้า!L21 -> 45 | J12: =[2]หน้าผ้า!M21 -> ± | K12: =[2]หน้าผ้า!N21 -> 5 | L12: =[2]หน้าผ้า!R21 -> ไม่ | M12: =[2]หน้าผ้า!T21 -> ไม่สวมถุงใน | N12: =[2]หน้าผ้า!U21 -> 0 | O12: =[2]หน้าผ้า!V21 -> 0 | P12: =[2]หน้าผ้า!AB21 -> 0 | Q12: =[2]หน้าผ้า!AC21 -> 0 | R12: =[2]หน้าผ้า!AD21 -> 0 | S12: =[2]หน้าผ้า!Z21 -> ห่ออัดเบลแบน500 | T12: =[2]หน้าผ้า!X21 -> 45773 | U12: =[2]หน้าผ้า!AA21 -> 5000 | V12: =[2]หน้าผ้า!AJ21 -> 0 | W12: =[2]หน้าผ้า!AL21 -> 5000 | X12: =[2]หน้าผ้า!AM21 -> 0 | Y12: =[2]หน้าผ้า!AN21 -> 5250 | Z12: =[2]หน้าผ้า!AO21 -> WSWT1625800 | AA12: =[2]หน้าผ้า!AQ21 -> 3702.05 | AB12: =[2]หน้าผ้า!AR21 -> 3702.05 | AC12: =[2]หน้าผ้า!AS21 -> 0 | AD12: =[2]หน้าผ้า!AT21 -> 0 | AE12: =[2]หน้าผ้า!AU21 -> 0 | AF12: =[2]หน้าผ้า!AI21 -> PDR250117 | AG12: =[3]หน้าผ้า!DC24 -> พร้อมส่ง | AH12: =[2]หน้าผ้า!DL21 -> P7 | AI12: =[2]หน้าผ้า!DM21 -> 2 | AJ12: =[2]หน้าผ้า!DN21 -> 45773 | AK12: =[2]หน้าผ้า!DQ21 -> 0 | AL12: =[2]หน้าผ้า!DR21 -> 45764 | AM12: =[2]หน้าผ้า!DS21 -> 45771 | AN12: =[2]หน้าผ้า!DT21 -> 45772 | AO12: =[2]หน้าผ้า!DU21 -> 45772 | AP12: =[2]หน้าผ้า!DP21 -> 45768 | AQ12: =[2]หน้าผ้า!DW21 -> 0 | AR12: =[2]หน้าผ้า!DX21 -> 0 | AS12: =[2]หน้าผ้า!DY21 -> 0 | AT12: =[2]หน้าผ้า!DZ21 -> 0 | AU12: =[2]หน้าผ้า!EA21 -> 0 | AV12: =[2]หน้าผ้า!EB21 -> 0 | AW12: =[2]หน้าผ้า!EC21 -> งานพิมพ์ | AX12: =[2]หน้าผ้า!ED21 -> / | AY12: =[2]หน้าผ้า!AG21 -> 0 | AZ12: =[2]หน้าผ้า!EG21 -> 0 | BA12: =[2]หน้าผ้า!EH21 -> 0 | BB12: =[2]หน้าผ้า!EI21 -> 0 | BC12: =[2]หน้าผ้า!BZ21 -> WRWT25800/WRWT25800 | BD12: =[2]หน้าผ้า!CA21 -> 0
A13: =[2]หน้าผ้า!C22 -> 0 | B13: =[2]หน้าผ้า!B22 -> 0 | C13: =[2]หน้าผ้า!E22 -> 0 | D13: =[2]หน้าผ้า!F22 -> 0 | E13: =[2]หน้าผ้า!G22 -> 16 | F13: =[2]หน้าผ้า!H22 -> 25 | G13: =[2]หน้าผ้า!I22 -> ขาว | H13: =[2]หน้าผ้า!J22 -> 0 | I13: =[2]หน้าผ้า!L22 -> 45 | J13: =[2]หน้าผ้า!M22 -> ± | K13: =[2]หน้าผ้า!N22 -> 5 | L13: =[2]หน้าผ้า!R22 -> 0 | M13: =[2]หน้าผ้า!T22 -> 0 | N13: =[2]หน้าผ้า!U22 -> 0 | O13: =[2]หน้าผ้า!V22 -> 0 | P13: =[2]หน้าผ้า!AB22 -> 0 | Q13: =[2]หน้าผ้า!AC22 -> 0 | R13: =[2]หน้าผ้า!AD22 -> 0 | S13: =[2]หน้าผ้า!Z22 -> 0 | T13: =[2]หน้าผ้า!X22 -> 0 | U13: =[2]หน้าผ้า!AA22 -> 0 | V13: =[2]หน้าผ้า!AJ22 -> 0 | W13: =[2]หน้าผ้า!AL22 -> 0 | X13: =[2]หน้าผ้า!AM22 -> 0 | Y13: =[2]หน้าผ้า!AN22 -> 0 | Z13: =[2]หน้าผ้า!AO22 -> WSWT1625800 | AA13: =[2]หน้าผ้า!AQ22 -> 7404.1 | AB13: =[2]หน้าผ้า!AR22 -> 7404.1 | AC13: =[2]หน้าผ้า!AS22 -> 0 | AD13: =[2]หน้าผ้า!AT22 -> 0 | AE13: =[2]หน้าผ้า!AU22 -> 0 | AF13: =[2]หน้าผ้า!AI22 -> ระบุในSD | AG13: =[3]หน้าผ้า!DC25 -> ยังไม่ได้พิมพ์ | AH13: =[2]หน้าผ้า!DL22 -> 0 | AI13: =[2]หน้าผ้า!DM22 -> Lead time | AJ13: =[2]หน้าผ้า!DN22 -> 0 | AK13: =[2]หน้าผ้า!DQ22 -> 0 | AL13: =[2]หน้าผ้า!DR22 -> 0 | AM13: =[2]หน้าผ้า!DS22 -> 0 | AN13: =[2]หน้าผ้า!DT22 -> 0 | AO13: =[2]หน้าผ้า!DU22 -> 0 | AP13: =[2]หน้าผ้า!DP22 -> 0 | AQ13: =[2]หน้าผ้า!DW22 -> 0 | AR13: =[2]หน้าผ้า!DX22 -> 0 | AS13: =[2]หน้าผ้า!DY22 -> 0 | AT13: =[2]หน้าผ้า!DZ22 -> 0 | AU13: =[2]หน้าผ้า!EA22 -> 0 | AV13: =[2]หน้าผ้า!EB22 -> 0 | AW13: =[2]หน้าผ้า!EC22 -> 0 | AX13: =[2]หน้าผ้า!ED22 -> 0 | AY13: =[2]หน้าผ้า!AG22 -> 0 | AZ13: =[2]หน้าผ้า!EG22 -> 0 | BA13: =[2]หน้าผ้า!EH22 -> 0 | BB13: =[2]หน้าผ้า!EI22 -> 0 | BC13: =[2]หน้าผ้า!BZ22 -> WRWT160800/WRWT25800 | BD13: =[2]หน้าผ้า!CA22 -> 0
A14: =[2]หน้าผ้า!C23 -> 45744 | B14: =[2]หน้าผ้า!B23 -> MK68-000468 | C14: =[2]หน้าผ้า!E23 -> โรงสีธัญญกิจ(ราชบุรี) | D14: =[2]หน้าผ้า!F23 -> ราชสีห์(ข้าวหอมมะลิ) | E14: =[2]หน้าผ้า!G23 -> 16 | F14: =[2]หน้าผ้า!H23 -> 25 | G14: =[2]หน้าผ้า!I23 -> ขาว | H14: =[2]หน้าผ้า!J23 -> 0 | I14: =[2]หน้าผ้า!L23 -> 47 | J14: =[2]หน้าผ้า!M23 -> ± | K14: =[2]หน้าผ้า!N23 -> 5 | L14: =[2]หน้าผ้า!R23 -> ไม่ | M14: =[2]หน้าผ้า!T23 -> ไม่สวมถุงใน | N14: =[2]หน้าผ้า!U23 -> 0 | O14: =[2]หน้าผ้า!V23 -> 0 | P14: =[2]หน้าผ้า!AB23 -> 0 | Q14: =[2]หน้าผ้า!AC23 -> 0 | R14: =[2]หน้าผ้า!AD23 -> 0 | S14: =[2]หน้าผ้า!Z23 -> 500กระสอบ | T14: =[2]หน้าผ้า!X23 -> 45756 | U14: =[2]หน้าผ้า!AA23 -> 10000 | V14: =[2]หน้าผ้า!AJ23 -> 0 | W14: =[2]หน้าผ้า!AL23 -> 10000 | X14: =[2]หน้าผ้า!AM23 -> 0 | Y14: =[2]หน้าผ้า!AN23 -> 10500 | Z14: =[2]หน้าผ้า!AO23 -> WSWT1621720SMFX | AA14: =[2]หน้าผ้า!AQ23 -> 7404.1 | AB14: =[2]หน้าผ้า!AR23 -> 7300 | AC14: =[2]หน้าผ้า!AS23 -> 104.1 | AD14: =[2]หน้าผ้า!AT23 -> 0 | AE14: =[2]หน้าผ้า!AU23 -> 0 | AF14: =[2]หน้าผ้า!AI23 -> 0 | AG14: =[3]หน้าผ้า!DC26 -> ยังไม่ได้พิมพ์ | AH14: =[2]หน้าผ้า!DL23 -> P7 | AI14: =[2]หน้าผ้า!DM23 -> 2 | AJ14: =[2]หน้าผ้า!DN23 -> 45756 | AK14: =[2]หน้าผ้า!DQ23 -> 0 | AL14: =[2]หน้าผ้า!DR23 -> 45747 | AM14: =[2]หน้าผ้า!DS23 -> 45754 | AN14: =[2]หน้าผ้า!DT23 -> 45755 | AO14: =[2]หน้าผ้า!DU23 -> 45755 | AP14: =[2]หน้าผ้า!DP23 -> 45751 | AQ14: =[2]หน้าผ้า!DW23 -> 0 | AR14: =[2]หน้าผ้า!DX23 -> 0 | AS14: =[2]หน้าผ้า!DY23 -> 0 | AT14: =[2]หน้าผ้า!DZ23 -> 0 | AU14: =[2]หน้าผ้า!EA23 -> 0 | AV14: =[2]หน้าผ้า!EB23 -> 0 | AW14: =[2]หน้าผ้า!EC23 -> งานพิมพ์ | AX14: =[2]หน้าผ้า!ED23 -> / | AY14: =[2]หน้าผ้า!AG23 -> 0 | AZ14: =[2]หน้าผ้า!EG23 -> 0 | BA14: =[2]หน้าผ้า!EH23 -> 0 | BB14: =[2]หน้าผ้า!EI23 -> 0 | BC14: =[2]หน้าผ้า!BZ23 -> WRWT21720/WRWT21720 | BD14: =[2]หน้าผ้า!CA23 -> 6.196032
A15: =[2]หน้าผ้า!C24 -> 0 | B15: =[2]หน้าผ้า!B24 -> 0 | C15: =[2]หน้าผ้า!E24 -> 0 | D15: =[2]หน้าผ้า!F24 -> 0 | E15: =[2]หน้าผ้า!G24 -> 16 | F15: =[2]หน้าผ้า!H24 -> 25 | G15: =[2]หน้าผ้า!I24 -> 0 | H15: =[2]หน้าผ้า!J24 -> 0 | I15: =[2]หน้าผ้า!L24 -> 47 | J15: =[2]หน้าผ้า!M24 -> ± | K15: =[2]หน้าผ้า!N24 -> 5 | L15: =[2]หน้าผ้า!R24 -> 0 | M15: =[2]หน้าผ้า!T24 -> 0 | N15: =[2]หน้าผ้า!U24 -> 0 | O15: =[2]หน้าผ้า!V24 -> 0 | P15: =[2]หน้าผ้า!AB24 -> 0 | Q15: =[2]หน้าผ้า!AC24 -> 0 | R15: =[2]หน้าผ้า!AD24 -> 0 | S15: =[2]หน้าผ้า!Z24 -> 0 | T15: =[2]หน้าผ้า!X24 -> 0 | U15: =[2]หน้าผ้า!AA24 -> 0 | V15: =[2]หน้าผ้า!AJ24 -> 0 | W15: =[2]หน้าผ้า!AL24 -> 0 | X15: =[2]หน้าผ้า!AM24 -> 0 | Y15: =[2]หน้าผ้า!AN24 -> 0 | Z15: =[2]หน้าผ้า!AO24 -> WSWT1621720SMFX | AA15: =[2]หน้าผ้า!AQ24 -> 7404.1 | AB15: =[2]หน้าผ้า!AR24 -> 7300 | AC15: =[2]หน้าผ้า!AS24 -> 104.1 | AD15: =[2]หน้าผ้า!AT24 -> 0 | AE15: =[2]หน้าผ้า!AU24 -> 0 | AF15: =[2]หน้าผ้า!AI24 -> ระบุในSD | AG15: =[3]หน้าผ้า!DC27 -> พร้อมส่ง | AH15: =[2]หน้าผ้า!DL24 -> 0 | AI15: =[2]หน้าผ้า!DM24 -> 0 | AJ15: =[2]หน้าผ้า!DN24 -> 0 | AK15: =[2]หน้าผ้า!DQ24 -> 0 | AL15: =[2]หน้าผ้า!DR24 -> 0 | AM15: =[2]หน้าผ้า!DS24 -> 0 | AN15: =[2]หน้าผ้า!DT24 -> 0 | AO15: =[2]หน้าผ้า!DU24 -> 0 | AP15: =[2]หน้าผ้า!DP24 -> 0 | AQ15: =[2]หน้าผ้า!DW24 -> 0 | AR15: =[2]หน้าผ้า!DX24 -> 0 | AS15: =[2]หน้าผ้า!DY24 -> 0 | AT15: =[2]หน้าผ้า!DZ24 -> 0 | AU15: =[2]หน้าผ้า!EA24 -> 0 | AV15: =[2]หน้าผ้า!EB24 -> 0 | AW15: =[2]หน้าผ้า!EC24 -> 0 | AX15: =[2]หน้าผ้า!ED24 -> 0 | AY15: =[2]หน้าผ้า!AG24 -> 0 | AZ15: =[2]หน้าผ้า!EG24 -> 0 | BA15: =[2]หน้าผ้า!EH24 -> 0 | BB15: =[2]หน้าผ้า!EI24 -> 0 | BC15: =[2]หน้าผ้า!BZ24 -> WRWT160720/WRWT21720 | BD15: =[2]หน้าผ้า!CA24 -> 0
A16: =[2]หน้าผ้า!C25 -> 45752 | B16: =[2]หน้าผ้า!B25 -> MK68-000515 | C16: =[2]หน้าผ้า!E25 -> ร้านเห็ดไพลิน | D16: =[2]หน้าผ้า!F25 -> เพชร | E16: =[2]หน้าผ้า!G25 -> 18 | F16: =[2]หน้าผ้า!H25 -> 28 | G16: =[2]หน้าผ้า!I25 -> ขาว | H16: =[2]หน้าผ้า!J25 -> 0 | I16: =[2]หน้าผ้า!L25 -> 50 | J16: =[2]หน้าผ้า!M25 -> ± | K16: =[2]หน้าผ้า!N25 -> 5 | L16: =[2]หน้าผ้า!R25 -> ไม่ | M16: =[2]หน้าผ้า!T25 -> 19 | N16: =[2]หน้าผ้า!U25 -> 29 | O16: =[2]หน้าผ้า!V25 -> 40 | P16: =[2]หน้าผ้า!AB25 -> 67.96838 | Q16: =[2]หน้าผ้า!AC25 -> 0 | R16: =[2]หน้าผ้า!AD25 -> 67.96838 | S16: =[2]หน้าผ้า!Z25 -> 500กระสอบ | T16: =[2]หน้าผ้า!X25 -> 45770 | U16: =[2]หน้าผ้า!AA25 -> 5000 | V16: =[2]หน้าผ้า!AJ25 -> 0 | W16: =[2]หน้าผ้า!AL25 -> 5000 | X16: =[2]หน้าผ้า!AM25 -> 0 | Y16: =[2]หน้าผ้า!AN25 -> 5250 | Z16: =[2]หน้าผ้า!AO25 -> WSWT1825800 | AA16: =[2]หน้าผ้า!AQ25 -> 4121.15 | AB16: =[2]หน้าผ้า!AR25 -> 4121.15 | AC16: =[2]หน้าผ้า!AS25 -> 0 | AD16: =[2]หน้าผ้า!AT25 -> 0 | AE16: =[2]หน้าผ้า!AU25 -> 0 | AF16: =[2]หน้าผ้า!AI25 -> 0 | AG16: =[3]หน้าผ้า!DC28 -> ยังไม่ได้พิมพ์ | AH16: =[2]หน้าผ้า!DL25 -> P9 | AI16: =[2]หน้าผ้า!DM25 -> 3 | AJ16: =[2]หน้าผ้า!DN25 -> 45770 | AK16: =[2]หน้าผ้า!DQ25 -> 0 | AL16: =[2]หน้าผ้า!DR25 -> 45760 | AM16: =[2]หน้าผ้า!DS25 -> 45767 | AN16: =[2]หน้าผ้า!DT25 -> 45768 | AO16: =[2]หน้าผ้า!DU25 -> 45768 | AP16: =[2]หน้าผ้า!DP25 -> 45765 | AQ16: =[2]หน้าผ้า!DW25 -> 45769 | AR16: =[2]หน้าผ้า!DX25 -> 0 | AS16: =[2]หน้าผ้า!DY25 -> 0 | AT16: =[2]หน้าผ้า!DZ25 -> 0 | AU16: =[2]หน้าผ้า!EA25 -> 0 | AV16: =[2]หน้าผ้า!EB25 -> 0 | AW16: =[2]หน้าผ้า!EC25 -> งานพิมพ์ | AX16: =[2]หน้าผ้า!ED25 -> / | AY16: =[2]หน้าผ้า!AG25 -> 0 | AZ16: =[2]หน้าผ้า!EG25 -> 0 | BA16: =[2]หน้าผ้า!EH25 -> 0 | BB16: =[2]หน้าผ้า!EI25 -> 0 | BC16: =[2]หน้าผ้า!BZ25 -> WRWT25800/WRWT25800 | BD16: =[2]หน้าผ้า!CA25 -> 0
A17: =[2]หน้าผ้า!C26 -> ประมาณการ | B17: =[2]หน้าผ้า!B26 -> ประมาณการ | C17: =[2]หน้าผ้า!E26 -> บจก.ฟาร์เธอร์ส วิง ซัพพลาย | D17: =[2]หน้าผ้า!F26 -> รถไฟ | E17: =[2]หน้าผ้า!G26 -> 18 | F17: =[2]หน้าผ้า!H26 -> 30 | G17: =[2]หน้าผ้า!I26 -> ขาว | H17: =[2]หน้าผ้า!J26 -> 0 | I17: =[2]หน้าผ้า!L26 -> 54 | J17: =[2]หน้าผ้า!M26 -> ± | K17: =[2]หน้าผ้า!N26 -> 5 | L17: =[2]หน้าผ้า!R26 -> บิด | M17: =[2]หน้าผ้า!T26 -> 19 | N17: =[2]หน้าผ้า!U26 -> 33 | O17: =[2]หน้าผ้า!V26 -> 40 | P17: =[2]หน้าผ้า!AB26 -> 232.02999 | Q17: =[2]หน้าผ้า!AC26 -> 0 | R17: =[2]หน้าผ้า!AD26 -> 232.02999 | S17: =[2]หน้าผ้า!Z26 -> 500กระสอบ | T17: =[2]หน้าผ้า!X26 -> 45777 | U17: =[2]หน้าผ้า!AA26 -> 15000 | V17: =[2]หน้าผ้า!AJ26 -> 0 | W17: =[2]หน้าผ้า!AL26 -> 15000 | X17: =[2]หน้าผ้า!AM26 -> 0 | Y17: =[2]หน้าผ้า!AN26 -> 15750 | Z17: =[2]หน้าผ้า!AO26 -> WSWT1825800 | AA17: =[2]หน้าผ้า!AQ26 -> 13201.65 | AB17: =[2]หน้าผ้า!AR26 -> 7949 | AC17: =[2]หน้าผ้า!AS26 -> 5252.65 | AD17: =[2]หน้าผ้า!AT26 -> 0 | AE17: =[2]หน้าผ้า!AU26 -> 0 | AF17: =[2]หน้าผ้า!AI26 -> 0 | AG17: =[3]หน้าผ้า!DC29 -> ยังไม่ได้พิมพ์ | AH17: =[2]หน้าผ้า!DL26 -> P9 | AI17: =[2]หน้าผ้า!DM26 -> 3 | AJ17: =[2]หน้าผ้า!DN26 -> 45777 | AK17: =[2]หน้าผ้า!DQ26 -> 0 | AL17: =[2]หน้าผ้า!DR26 -> 45767 | AM17: =[2]หน้าผ้า!DS26 -> 45774 | AN17: =[2]หน้าผ้า!DT26 -> 45775 | AO17: =[2]หน้าผ้า!DU26 -> 45775 | AP17: =[2]หน้าผ้า!DP26 -> 45772 | AQ17: =[2]หน้าผ้า!DW26 -> 45776 | AR17: =[2]หน้าผ้า!DX26 -> 0 | AS17: =[2]หน้าผ้า!DY26 -> 0 | AT17: =[2]หน้าผ้า!DZ26 -> 0 | AU17: =[2]หน้าผ้า!EA26 -> 0 | AV17: =[2]หน้าผ้า!EB26 -> 0 | AW17: =[2]หน้าผ้า!EC26 -> งานพิมพ์ | AX17: =[2]หน้าผ้า!ED26 -> รอART | AY17: =[2]หน้าผ้า!AG26 -> 0 | AZ17: =[2]หน้าผ้า!EG26 -> 0 | BA17: =[2]หน้าผ้า!EH26 -> 0 | BB17: =[2]หน้าผ้า!EI26 -> 0 | BC17: =[2]หน้าผ้า!BZ26 -> WRWT25800/WRWT25800 | BD17: =[2]หน้าผ้า!CA26 -> 361.38232
... A574: =[2]หน้าผ้า!C583 -> 0 | B574: =[2]หน้าผ้า!B583 -> 0 | C574: =[2]หน้าผ้า!E583 -> 0 | D574: =[2]หน้าผ้า!F583 -> 0 | E574: =[2]หน้าผ้า!G583 -> 0 | F574: =[2]หน้าผ้า!H583 -> 0 | G574: =[2]หน้าผ้า!I583 -> 0 | H574: =[2]หน้าผ้า!J583 -> 0 | I574: =[2]หน้าผ้า!L583 -> 0 | J574: =[2]หน้าผ้า!M583 -> 0 | K574: =[2]หน้าผ้า!N583 -> 0 | L574: =[2]หน้าผ้า!R583 -> 0 | M574: =[2]หน้าผ้า!T583 -> 0 | N574: =[2]หน้าผ้า!U583 -> 0 | O574: =[2]หน้าผ้า!V583 -> 0 | P574: =[2]หน้าผ้า!AB583 -> 0 | Q574: =[2]หน้าผ้า!AC583 -> 0 | R574: =[2]หน้าผ้า!AD583 -> 0 | S574: =[2]หน้าผ้า!Z583 -> 0 | T574: =[2]หน้าผ้า!X583 -> 0 | U574: =[2]หน้าผ้า!AA583 -> 0 | V574: =[2]หน้าผ้า!AJ583 -> 0 | W574: =[2]หน้าผ้า!AL583 -> 0 | X574: =[2]หน้าผ้า!AM583 -> 0 | Y574: =[2]หน้าผ้า!AN583 -> 0 | Z574: =[2]หน้าผ้า!AO583 -> 0 | AA574: =[2]หน้าผ้า!AQ583 -> 0 | AB574: =[2]หน้าผ้า!AR583 -> 0 | AC574: =[2]หน้าผ้า!AS583 -> 0 | AD574: =[2]หน้าผ้า!AT583 -> 0 | AE574: =[2]หน้าผ้า!AU583 -> 0 | AF574: =[2]หน้าผ้า!AI583 -> 0 | AG574: =[3]หน้าผ้า!DC586 -> 0 | AH574: =[2]หน้าผ้า!DL583 -> 0 | AI574: =[2]หน้าผ้า!DM583 -> 0 | AJ574: =[2]หน้าผ้า!DN583 -> 0 | AK574: =[2]หน้าผ้า!DQ583 -> 0 | AL574: =[2]หน้าผ้า!DR583 -> 0 | AM574: =[2]หน้าผ้า!DS583 -> 0 | AN574: =[2]หน้าผ้า!DT583 -> 0 | AO574: =[2]หน้าผ้า!DU583 -> 0 | AP574: =[2]หน้าผ้า!DP583 -> 0 | AQ574: =[2]หน้าผ้า!DW583 -> 0 | AR574: =[2]หน้าผ้า!DX583 -> 0 | AS574: =[2]หน้าผ้า!DY583 -> 0 | AT574: =[2]หน้าผ้า!DZ583 -> 0 | AU574: =[2]หน้าผ้า!EA583 -> 0 | AV574: =[2]หน้าผ้า!EB583 -> 0 | AW574: =[2]หน้าผ้า!EC583 -> 0 | AX574: =[2]หน้าผ้า!ED583 -> 0 | AY574: =[2]หน้าผ้า!AG583 -> 0 | AZ574: =[2]หน้าผ้า!EG583 -> 0 | BA574: =[2]หน้าผ้า!EH583 -> 0 | BB574: =[2]หน้าผ้า!EI583 -> 0 | BC574: =[2]หน้าผ้า!BZ583 -> 0 | BD574: =[2]หน้าผ้า!CA583 -> 0

Sheet 3(Order+Fc) แยกลูกค้า
A1: เลขที่ SO | B1: (หลายรายการ)
A2: วันส่ง | B2: รอแจ้ง | D2: 12 | I2: เมตร | J2: vn | K2: ใบ | P2: วัน
A4: ประเภท | B4: ชื่อลูกค้า | C4: ผลรวม ของ จำนวนส่ง | D4: ผลรวม ของ ค้างพิมพ์ | E4: ผลรวม ของ ค้างตัด | F4: ผลรวม ของ Stock | G4: ผลรวม ของ ใช้ | H4: ผลรวม ของ ค้างทอ
A5: WSWT1625800SM | B5: บจก.ซัน ซีเมนต์ โพรเซส | C5: 5000 | D5: 5250 | E5: 5000 | F5: 3372 | G5: 3702.05 | H5: 330.05 | I5: =H5 -> 330.05
A6: WSWT1625800SM ผลรวม | C6: 5000 | D6: 5250 | E6: 5000 | F6: 3372 | G6: 3702.05 | H6: 330.05
A7: WSWT1825800SM | B7: บจก.ซิเบลโก้ | C7: 10000 | D7: 10500 | E7: 10000 | F7: 0 | G7: 8801.1 | H7: 8801.1 | I7: =H7 -> 8801.1
A8: WSWT1825800SM ผลรวม | C8: 10000 | D8: 10500 | E8: 10000 | F8: 0 | G8: 8801.1 | H8: 8801.1 | I8: =H8 -> 8801.1
A9: WSWT1925800 | B9: บจก.ไลม์มาสเตอร์ | C9: 10000 | D9: 10500 | E9: 10000 | F9: 0 | G9: 9359.9 | H9: 9359.9 | I9: =H9 -> 9359.9
A10: WSWT1925800 ผลรวม | C10: 10000 | D10: 10500 | E10: 10000 | F10: 0 | G10: 9359.9 | H10: 9359.9 | I10: =H10 -> 9359.9
A11: WSWT2025700 | B11: บจก.เบทาโกร | C11: 50000 | D11: 0 | E11: 50000 | F11: 14387 | G11: 55181.5 | H11: 40794.5
A12: WSWT2025700 ผลรวม | C12: 50000 | D12: 0 | E12: 50000 | F12: 14387 | G12: 55181.5 | H12: 40794.5 | I12: =H12 -> 40794.5
A13: WSWT2025800 | B13: บจก.อินเทคค์ โกลบอล | C13: 110000 | D13: 115500 | E13: 110000 | F13: 0 | G13: 115252.5 | H13: 115252.5
A14: WSWT2025800 ผลรวม | C14: 110000 | D14: 115500 | E14: 110000 | F14: 0 | G14: 115252.5 | H14: 115252.5 | I14: =H14 -> 115252.5 | P14: 15000 | Q14: =+K14/P14 -> 0
A15: WSWT2025800SM | B15: บจก.ไทยธรรมดี | C15: 40000 | D15: 42000 | E15: 40000 | F15: 0 | G15: 43027.6 | H15: 43027.6
B16: บจก.อินเทคค์ โกลบอล | C16: 7227 | D16: 0 | E16: 7160 | F16: 0 | G16: 0 | H16: 0 | I16: =H16 -> 0
B17: บจก.เอพีเอ็ม อะโกร | C17: 5000 | D17: 5250 | E17: 5000 | F17: 0 | G17: 5518.15 | H17: 5518.15 | I17: =H17 -> 5518.15
B18: บจก.เอสพีเอ็ม อาหารสัตว์ | C18: 23000 | D18: 24150 | E18: 23000 | F18: 0 | G18: 25551.13 | H18: 25551.13 | I18: =H18 -> 25551.13
A19: WSWT2025800SM ผลรวม | C19: 75227 | D19: 71400 | E19: 75160 | F19: 0 | G19: 74096.88 | H19: 74096.88 | I19: =H19 -> 74096.88
A20: WSWT2121670SM | B20: บจก.ที.ซี.ยูเนี่ยน อโกรเทค | C20: 42000 | D20: 44100 | E20: 42000 | F20: 34422.08 | G20: 45178.98 | H20: 10756.9 | I20: =H20 -> 10756.9 | P20: 16000 | Q20: =+K20/P20 -> 0
B21: บจก.เอพีเอ็ม อะโกร | C21: 32000 | D21: 33600 | E21: 32000 | F21: 20703.54 | G21: 36154.36 | H21: 15450.82
B22: บจก.เอสพีเอ็ม อาหารสัตว์ | C22: 5000 | D22: 5250 | E22: 5000 | F22: 0 | G22: 5518.15 | H22: 5518.15 | I22: =H22 -> 5518.15
A23: WSWT2121670SM ผลรวม | C23: 79000 | D23: 82950 | E23: 79000 | F23: 55125.62 | G23: 86851.49 | H23: 31725.87
A24: WSWT2321112512551 | B24: บจก.น้ำตาลทิพย์สุโขทัย | C24: 106278 | D24: 111591.9 | E24: 106278 | F24: 0 | G24: 114322.18 | H24: 114322.18 | I24: =H24 -> 114322.18
A25: WSWT2321112512551 ผลรวม | C25: 106278 | D25: 111591.9 | E25: 106278 | F25: 0 | G25: 114322.18 | H25: 114322.18
A26: WSWT2625650 | B26: บจก.โอเชี่ยนฟีด | C26: 40000 | D26: 0 | E26: 40000 | F26: 0 | G26: 48615.6 | H26: 48615.6 | I26: =H26 -> 48615.6
B27: บจก.กบินทร์อินทรีย์ | C27: 10000 | D27: 10500 | E27: 10000 | F27: 0 | G27: 11874.5 | H27: 11874.5
A28: WSWT2625650 ผลรวม | C28: 50000 | D28: 10500 | E28: 50000 | F28: 0 | G28: 60490.1 | H28: 60490.1 | I28: =H28 -> 60490.1
A29: WSWT2625800 | B29: บจก.ที.ซี.ยูเนี่ยน อโกรเทค | C29: 30000 | D29: 0 | E29: 30000 | F29: 6278 | G29: 37299.9 | H29: 31021.9 | I29: =H29 -> 31021.9
A30: WSWT2625800 ผลรวม | C30: 30000 | D30: 0 | E30: 30000 | F30: 6278 | G30: 37299.9 | H30: 31021.9 | I30: =H30 -> 31021.9
A31: WSWT2625850SM | B31: บจก.ที.ซี.ยูเนี่ยน อโกรเทค | C31: 20000 | D31: 21000 | E31: 20000 | F31: 0 | G31: 24866.6 | H31: 24866.6 | P31: 15000 | Q31: =+K31/P31 -> 0
A32: WSWT2625850SM ผลรวม | C32: 20000 | D32: 21000 | E32: 20000 | F32: 0 | G32: 24866.6 | H32: 24866.6 | I32: =H32 -> 24866.6
A33: ผลรวมทั้งหมด | C33: 545505 | D33: 439191.9 | E33: 545438 | F33: 79162.62 | G33: 590224.2 | H33: 511061.58 | I33: =H33 -> 511061.58
I34: =H34 -> 0
I35: =H35 -> 0
I36: =H36 -> 0
I37: =H37 -> 0
I38: =H38 -> 0
I39: =H39 -> 0
I40: =H40 -> 0
I42: =H42 -> 0
...

Sheet 5(Order)
A2: เลขที่ SO | B2: (หลายรายการ)
A3: วันส่ง | B3: รอแจ้ง
A4: ชื่อลูกค้า | B4: (ทั้งหมด)
A6: ประเภท | B6: ผลรวม ของ จำนวนส่ง | C6: ผลรวม ของ ค้างพิมพ์ | D6: ผลรวม ของ ค้างตัด | E6: ผลรวม ของ Stock | F6: ผลรวม ของ ใช้ | G6: ผลรวม ของ ค้างทอ
A7: WSWT19251000SM | B7: 400 | C7: 0 | D7: 400 | E7: 0 | F7: 0 | G7: 0
A8: WSWT2025800SM | B8: 35935 | C8: 25200 | D8: 35868 | E8: 0 | F8: 26654.76 | G8: 26654.76
A9: WSWT2121670SM | B9: 59000 | C9: 61950 | D9: 59000 | E9: 43530.52 | F9: 64499.49 | G9: 20968.97
A10: WSWT2321112512551 | B10: 106278 | C10: 111591.9 | D10: 106278 | E10: 0 | F10: 114322.18 | G10: 114322.18
A11: WSWT2321750 | B11: 1000 | C11: 0 | D11: 1000 | E11: 0 | F11: 1159.51 | G11: 1159.51
A12: WSWT2625650 | B12: 4000 | C12: 4200 | D12: 4000 | E12: 0 | F12: 4749.8 | G12: 4749.8
A13: WSWT2625800 | B13: 10000 | C13: 0 | D13: 10000 | E13: 6278 | F13: 12433.3 | G13: 6155.3
A14: ผลรวมทั้งหมด | B14: 216613 | C14: 202941.9 | D14: 216546 | E14: 49808.52 | F14: 223819.04 | G14: 174010.52
A37: ยอดส่ง 1/1/68 - 17/1/68 | B37: 1287052
A38: Order+ส่ง | B38: =++B22+B37 -> 1287052
A39: ประมาณการ | I39: 0
A41: Order+ส่ง+ประมาณการ | B41: =+B22+B37+B39+B29 -> 1287052 | C41: =+C22+C37+C39+C29 -> 0 | D41: =+D22+D37+D39+D29 -> 0 | E41: =+E22+E37+E39+E29 -> 0 | F41: =+F22+F37+F39+F29 -> 0 | G41: =+G22+G37+G39+G29 -> 0
B43: 3000000 | I43: 9
B45: =+B41-B43 -> -1712948
D46: =+D22/I43 -> 0
C47: =+C41/I43 -> 0 | D47: =+D41/I43 -> 0 | G47: =+G41/I43 -> 0

Sheet 3(Order) แยกลูกค้า
A1: เลขที่ SO | B1: (หลายรายการ)
A2: วันส่ง | B2: รอแจ้ง
A4: ประเภท | B4: ชื่อลูกค้า | C4: ผลรวม ของ จำนวนส่ง | D4: ผลรวม ของ ค้างพิมพ์ | E4: ผลรวม ของ ค้างตัด | F4: ผลรวม ของ Stock | G4: ผลรวม ของ ค้างทอ | I4: vn
A5: WSWT2025800SM | B5: บจก.อินเทคค์ โกลบอล | C5: 6250 | D5: 0 | E5: 6183 | F5: 0 | G5: 0 | H5: =G5 -> 0
A6: WSWT2025800SM ผลรวม | C6: 6250 | D6: 0 | E6: 6183 | F6: 0 | G6: 0 | H6: =G6 -> 0
A7: WSWT2121670SM | B7: บจก.ที.ซี.ยูเนี่ยน อโกรเทค | C7: 32000 | D7: 33600 | E7: 32000 | F7: 34422.08 | G7: 0 | H7: =G7 -> 0
B8: บจก.เอพีเอ็ม อะโกร | C8: 14000 | D8: 14700 | E8: 14000 | F8: 0 | G8: 15450.82
B9: บจก.เอสพีเอ็ม อาหารสัตว์ | C9: 5000 | D9: 5250 | E9: 5000 | F9: 0 | G9: 5518.15 | H9: =G9 -> 5518.15
A10: WSWT2121670SM ผลรวม | C10: 51000 | D10: 53550 | E10: 51000 | F10: 34422.08 | G10: 20968.97 | H10: =G10 -> 20968.97
A11: WSWT2321112512551 | B11: บจก.น้ำตาลทิพย์สุโขทัย | C11: 106278 | D11: 111591.9 | E11: 106278 | F11: 0 | G11: 114322.18
A12: WSWT2321112512551 ผลรวม | C12: 106278 | D12: 111591.9 | E12: 106278 | F12: 0 | G12: 114322.18 | H12: =G12 -> 114322.18
A13: WSWT2625800 | B13: บจก.ที.ซี.ยูเนี่ยน อโกรเทค | C13: 10000 | D13: 0 | E13: 10000 | F13: 6278 | G13: 6155.3 | H13: =G13 -> 6155.3
A14: WSWT2625800 ผลรวม | C14: 10000 | D14: 0 | E14: 10000 | F14: 6278 | G14: 6155.3 | H14: =G14 -> 6155.3
A15: ผลรวมทั้งหมด | C15: 173528 | D15: 165141.9 | E15: 173461 | F15: 40700.08 | G15: 141446.45
H16: =G16 -> 0
H18: =G18 -> 0
H19: =G19 -> 0
H20: =G20 -> 0
H21: =G21 -> 0
H23: =G23 -> 0
H25: =G25 -> 0
H27: =G27 -> 0
H28: =G28 -> 0
H29: =G29 -> 0
H31: =G31 -> 0
H32: =G32 -> 0
... H68: =G68 -> 0
H70: =SUM(H5:H69) -> 153119.9
D119: Cap พิมพ์ | E119: Cap ตัด | F119: Stock 16/7 บ่าย | G119: Cap ทอ | I119: วันทงาน
B120: lส่ง | C120: 1-16/7 | D120: 160000 | E120: 160000 | G120: 120000 | I120: 12
C121: 1975256 | D121: =+D120*I120 -> 1920000 | E121: =+E120*I120 -> 1920000 | F121: 825147 | G121: =+G120*I120 -> 1440000
A122: เบทาโกรส่งแล้ว | B122: 20700 | C122: 424374
A123: เบทาโกรส่งแล้ว | B123: 20800 | C123: 155973
C126: รวมส่ง+ค้างส่ง | D126: ส่วนต่างCapคงเหลือ | E126: ส่วนต่างCapคงเหลือ | F126: คงเหลือ
C127: =+C50+C121 -> 1975256 | D127: =+D121-D50 -> 1920000 | E127: =+E121-E50 -> 1920000 | F127: =+F121-F50 -> 825147 | G127: =+G121-G50 -> 1440000
B129: 20700VN 20/7 | G129: 350000

Sheet 3(Fc) แยกลูกค้
A1: เลขที่ SO | B1: ประมาณการ
A2: วันส่ง | B2: รอแจ้ง | D2: 12
A4: ประเภท | B4: ชื่อลูกค้า | C4: ผลรวม ของ จำนวนส่ง | D4: ผลรวม ของ ค้างพิมพ์ | E4: ผลรวม ของ ค้างตัด | F4: ผลรวม ของ Stock | G4: ผลรวม ของ ใช้ | H4: ผลรวม ของ ค้างทอ
A5: WSWT1625800SM | B5: บจก.ซัน ซีเมนต์ โพรเซส | C5: 5000 | D5: 5250 | E5: 5000 | F5: 3372 | G5: 3702.05 | H5: 330.05
A6: WSWT1625800SM ผลรวม | C6: 5000 | D6: 5250 | E6: 5000 | F6: 3372 | G6: 3702.05 | H6: 330.05
A7: WSWT1825800SM | B7: บจก.ซิเบลโก้ | C7: 10000 | D7: 10500 | E7: 10000 | F7: 0 | G7: 8801.1 | H7: 8801.1
A8: WSWT1825800SM ผลรวม | C8: 10000 | D8: 10500 | E8: 10000 | F8: 0 | G8: 8801.1 | H8: 8801.1
A9: WSWT1925800 | B9: บจก.ไลม์มาสเตอร์ | C9: 10000 | D9: 10500 | E9: 10000 | F9: 0 | G9: 9359.9 | H9: 9359.9
A10: WSWT1925800 ผลรวม | C10: 10000 | D10: 10500 | E10: 10000 | F10: 0 | G10: 9359.9 | H10: 9359.9
A11: WSWT2025700 | B11: บจก.เบทาโกร | C11: 50000 | D11: 0 | E11: 50000 | F11: 14387 | G11: 55181.5 | H11: 40794.5
A12: WSWT2025700 ผลรวม | C12: 50000 | D12: 0 | E12: 50000 | F12: 14387 | G12: 55181.5 | H12: 40794.5
A13: WSWT2025800 | B13: บจก.อินเทคค์ โกลบอล | C13: 110000 | D13: 115500 | E13: 110000 | F13: 0 | G13: 115252.5 | H13: 115252.5
A14: WSWT2025800 ผลรวม | C14: 110000 | D14: 115500 | E14: 110000 | F14: 0 | G14: 115252.5 | H14: 115252.5
A15: WSWT2025800SM | B15: บจก.ไทยธรรมดี | C15: 40000 | D15: 42000 | E15: 40000 | F15: 0 | G15: 43027.6 | H15: 43027.6
B16: บจก.เอสพีเอ็ม อาหารสัตว์ | C16: 20000 | D16: 21000 | E16: 20000 | F16: 0 | G16: 22072.6 | H16: 22072.6
A17: WSWT2025800SM ผลรวม | C17: 60000 | D17: 63000 | E17: 60000 | F17: 0 | G17: 65100.2 | H17: 65100.2
A18: WSWT2121670SM | B18: บจก.ที.ซี.ยูเนี่ยน อโกรเทค | C18: 10000 | D18: 10500 | E18: 10000 | F18: 0 | G18: 10756.9 | H18: 10756.9
B19: บจก.เอพีเอ็ม อะโกร | C19: 10000 | D19: 10500 | E19: 10000 | F19: 11595.1 | G19: 11595.1 | H19: 0
A20: WSWT2121670SM ผลรวม | C20: 20000 | D20: 21000 | E20: 20000 | F20: 11595.1 | G20: 22352 | H20: 10756.9
A21: WSWT2625650 | B21: บจก.โอเชี่ยนฟีด | C21: 40000 | D21: 0 | E21: 40000 | F21: 0 | G21: 48615.6 | H21: 48615.6
B22: บจก.กบินทร์อินทรีย์ | C22: 10000 | D22: 10500 | E22: 10000 | F22: 0 | G22: 11874.5 | H22: 11874.5
A23: WSWT2625650 ผลรวม | C23: 50000 | D23: 10500 | E23: 50000 | F23: 0 | G23: 60490.1 | H23: 60490.1
A24: WSWT2625800 | B24: บจก.ที.ซี.ยูเนี่ยน อโกรเทค | C24: 20000 | D24: 0 | E24: 20000 | F24: 0 | G24: 24866.6 | H24: 24866.6
A25: WSWT2625800 ผลรวม | C25: 20000 | D25: 0 | E25: 20000 | F25: 0 | G25: 24866.6 | H25: 24866.6
A26: WSWT2625850SM | B26: บจก.ที.ซี.ยูเนี่ยน อโกรเทค | C26: 20000 | D26: 21000 | E26: 20000 | F26: 0 | G26: 24866.6 | H26: 24866.6
A27: WSWT2625850SM ผลรวม | C27: 20000 | D27: 21000 | E27: 20000 | F27: 0 | G27: 24866.6 | H27: 24866.6
A28: ผลรวมทั้งหมด | C28: 355000 | D28: 257250 | E28: 355000 | F28: 29354.1 | G28: 389972.55 | H28: 360618.45
D119: Cap พิมพ์ | E119: Cap ตัด | F119: Stock 16/7 บ่าย | G119: Cap ทอ | I119: วันทงาน
B120: lส่ง | C120: 1-16/7 | D120: 160000 | E120: 160000 | G120: 120000 | I120: 12
C121: 1975256 | D121: =+D120*I120 -> 1920000 | E121: =+E120*I120 -> 1920000 | F121: 825147 | G121: =+G120*I120 -> 1440000
A122: เบทาโกรส่งแล้ว | B122: 20700 | C122: 424374
A123: เบทาโกรส่งแล้ว | B123: 20800 | C123: 155973
C126: รวมส่ง+ค้างส่ง | D126: ส่วนต่างCapคงเหลือ | E126: ส่วนต่างCapคงเหลือ | F126: คงเหลือ
C127: =+C50+C121 -> 1975256 | D127: =+D121-D50 -> 1920000 | E127: =+E121-E50 -> 1920000 | F127: =+F121-F50 -> 825147 | G127: =+G121-G50 -> 1440000
B129: 20700VN 20/7 | G129: 350000

Sheet 4(Order+FC) (-4)
A2: เลขที่ SO | B2: (หลายรายการ)
A3: วันส่ง | B3: รอแจ้ง
A4: ชื่อลูกค้า | B4: (ทั้งหมด)
A6: ประเภท | B6: ผลรวม ของ จำนวนส่ง | C6: ผลรวม ของ ค้างพิมพ์ | D6: ผลรวม ของ ค้างตัด | E6: ผลรวม ของ Stock | F6: ผลรวม ของ ใช้ | G6: ผลรวม ของ ค้างทอ
A7: WSWT1625800SM | B7: 5000 | C7: 5250 | D7: 5000 | E7: 3372 | F7: 3702.05 | G7: 330.05 | H7: =+J7-I7 -> 330.05 | J7: =G7 -> 330.05
A8: WSWT1825800SM | B8: 10000 | C8: 10500 | D8: 10000 | E8: 0 | F8: 8801.1 | G8: 8801.1 | H8: =+J8-I8 -> 8801.1 | J8: =G8 -> 8801.1
A9: WSWT1925800 | B9: 10000 | C9: 10500 | D9: 10000 | E9: 0 | F9: 9359.9 | G9: 9359.9 | H9: =+J9-I9 -> 9359.9 | J9: =G9 -> 9359.9
A10: WSWT2025700 | B10: 50000 | C10: 0 | D10: 50000 | E10: 14387 | F10: 55181.5 | G10: 40794.5 | H10: =+J10-I10 -> 40794.5 | J10: =G10 -> 40794.5
A11: WSWT2025800 | B11: 110000 | C11: 115500 | D11: 110000 | E11: 0 | F11: 115252.5 | G11: 115252.5 | H11: =+J11-I11 -> 115252.5 | J11: =G11 -> 115252.5
A12: WSWT2025800SM | B12: 69250 | C12: 66150 | D12: 69183 | E12: 0 | F12: 68578.73 | G12: 68578.73 | H12: =+J12-I12 -> 68578.73 | J12: =G12 -> 68578.73
A13: WSWT2121670SM | B13: 71000 | C13: 74550 | D13: 71000 | E13: 46017.18 | F13: 77743.05 | G13: 31725.87 | H13: =+J13-I13 -> 31725.87 | J13: =G13 -> 31725.87
A14: WSWT2321112512551 | B14: 106278 | C14: 111591.9 | D14: 106278 | E14: 0 | F14: 114322.18 | G14: 114322.18 | H14: =+J14-I14 -> 114322.18 | J14: =G14 -> 114322.18
A15: WSWT2625650 | B15: 50000 | C15: 10500 | D15: 50000 | E15: 0 | F15: 60490.1 | G15: 60490.1 | H15: =+J15-I15 -> 60490.1 | J15: =G15 -> 60490.1
A16: WSWT2625800 | B16: 30000 | C16: 0 | D16: 30000 | E16: 6278 | F16: 37299.9 | G16: 31021.9 | H16: =+J16-I16 -> 31021.9 | J16: =G16 -> 31021.9
A17: WSWT2625850SM | B17: 20000 | C17: 21000 | D17: 20000 | E17: 0 | F17: 24866.6 | G17: 24866.6 | H17: 0 | I17: 160000 | J17: =G17 -> 24866.6
A18: ผลรวมทั้งหมด | B18: 531528 | C18: 425541.9 | D18: 531461 | E18: 70054.18 | F18: 575597.61 | G18: 505543.43 | H18: =+J18-I18 -> 505543.43 | J18: =G18 -> 505543.43
H19: =+J19-I19 -> 0 | J19: =G19 -> 0
H20: =+J20-I20 -> 0 | J20: =G20 -> 0
H21: =+J21-I21 -> 0 | J21: =G21 -> 0
H22: =+J22-I22 -> 0 | J22: =G22 -> 0
H23: =+J23-I23 -> 0 | J23: =G23 -> 0
H24: =+J24-I24 -> 0 | J24: =G24 -> 0
H25: =+J25-I25 -> 0 | J25: =G25 -> 0
H27: =SUM(H8:H25) -> 985890.21 | J27: =SUM(J8:J25) -> 1010756.8
M28: =+GETPIVOTDATA("ผลรวม ของ ใช้",$A$6)+H29+H31 -> 665597.61
H30: =+H27 -> 985890.21
A31: กรม | B31: 70000 | C31: 70000 | D31: 70000 | G31: 90000 | H31: 90000 | I31: 95 | J31: =+H31*I31 -> 8550000 | K31: =+J31/1000 -> 8550
G33: 160000 | H33: =+H29+H30 -> 985890.21 | I33: 85 | J33: =+H33*I33 -> 83800668 | K33: =+J33/1000 -> 83800.668
H34: =+H30+H31+H29 -> 1075890.2
H35: 15 | I35: =+H34/H35 -> 71726.014 | K35: =+K33+K31 -> 92350.668
N36: 705222
A37: ยอดส่ง 1/2/68 - 10/2/68 | B37: 817879 | I37: =+H35*100000 -> 1500000
N38: =+H34+N36 -> 1781112.2
H39: 16 | I39: =+H39*90000 -> 1440000
B41: =+B26+B37+B31 -> 887879 | C41: =+C26+C37+C31 -> 70000 | D41: =+D26+D37+D31 -> 70000 | E41: =+E26+E37+E31 -> 0 | F41: =+F26+F37+F31 -> 0
B43: 2992955
B45: =+B43-B41 -> 2105076 | C45: =+C32+($B$45*1) -> 2105076 | D45: =+D32+($B$45*1) -> 2105076 | E45: =+E31+($B$45*1) -> 2105076 | F45: =+F30+($B$45*1) -> 2105076 | G45: =+G30+($B$45*1) -> 2105076
C47: =+C41/13 -> 5384.6154 | D47: =+D41/15 -> 4666.6667
B49: 16 | C49: 135000 | D49: 135000
C50: =+B49*C49 -> 2160000 | D50: =+B49*D49 -> 2160000
...

Sheet 4(Order+FC)
A2: เลขที่ SO | B2: (หลายรายการ)
A3: วันส่ง | B3: (หลายรายการ)
A4: ชื่อลูกค้า | B4: (ทั้งหมด)
K5: 9
A6: ประเภท | B6: ผลรวม ของ จำนวนส่ง | C6: ผลรวม ของ ค้างพิมพ์ | D6: ผลรวม ของ ค้างตัด | E6: ผลรวม ของ ใช้ | F6: ผลรวม ของ Stock | G6: ผลรวม ของ ค้างทอ
A7: WSWT1425800 | B7: 10000 | C7: 10500 | D7: 10000 | E7: 6565.9 | F7: 6565.9 | G7: 0 | H7: =+J7-I7 -> 0 | J7: =G7 -> 0
A8: WSWT1825800 | B8: 20000 | C8: 21000 | D8: 20000 | E8: 17322.8 | F8: 12070.15 | G8: 5252.65 | H8: =+J8-I8 -> 5252.65 | J8: =G8 -> 5252.65
A9: WSWT1825800SM | B9: 10000 | C9: 10500 | D9: 10000 | E9: 8801.1 | F9: 0 | G9: 8801.1 | H9: =+J9-I9 -> 8801.1 | J9: =G9 -> 8801.1
A10: WSWT1921720 | B10: 370000 | C10: 341250 | D10: 365000 | E10: 321240.15 | F10: 0 | G10: 321240.15 | H10: =+J10-I10 -> 321240.15 | J10: =G10 -> 321240.15
A11: WSWT19251000SM | B11: 10080 | C11: 10584 | D11: 10080 | E11: 9998.0496 | F11: 8000.0248 | G11: 1998.0248 | H11: =+J11-I11 -> 1998.0248 | J11: =G11 -> 1998.0248
A12: WSWT1925800 | B12: 210000 | C12: 178500 | D12: 210000 | E12: 148501.1 | F12: 5000 | G12: 143501.1 | H12: =+J12-I12 -> 143501.1 | J12: =G12 -> 143501.1 | K12: 40000 | L12: =+K5*K12 -> 360000 | M12: =+L12-J12 -> 216498.9
A13: WSWT1925800SM | B13: 10000 | C13: 10500 | D13: 10000 | E13: 7683.5 | F13: 7683.5 | G13: 0 | H13: =+J13-I13 -> 0 | J13: =G13 -> 0 | K13: 14000 | L13: =+K13*K5 -> 126000 | M13: =+L13-J13 -> 126000
A14: WSWT2025650 | B14: 5000 | C14: 0 | D14: 5000 | E14: 4400.55 | F14: 0 | G14: 4400.55 | H14: =+J14-I14 -> 4400.55 | J14: =G14 -> 4400.55
A15: WSWT2025800 | B15: 481998 | C15: 436483.95 | D15: 472141 | E15: 448313.84 | F15: 0 | G15: 448313.84 | H15: =+J15-I15 -> 448313.84 | J15: =G15 -> 448313.84 | K15: 20000 | L15: =+K15*K5 -> 180000 | M15: =+L15-J15 -> -268313.84
A16: WSWT2025800SM | B16: 226000 | C16: 226800 | D16: 226000 | E16: 229080.06 | F16: 18538.19 | G16: 210541.87 | H16: =+J16-I16 -> 210541.87 | J16: =G16 -> 210541.87
A17: WSWT2121670SM | B17: 103000 | C17: 85050 | D17: 103000 | E17: 87130.89 | F17: 17211.04 | G17: 69919.85 | H17: =+J17-I17 -> 69919.85 | J17: =G17 -> 69919.85
A18: WSWT2125650 | B18: 35000 | C18: 10500 | D18: 35000 | E18: 37509.45 | F18: 0 | G18: 37509.45 | H18: =+J18-I18 -> 37509.45 | J18: =G18 -> 37509.45
A19: WSWT2321750 | B19: 12000 | C19: 12600 | D19: 12000 | E19: 12684.76 | F19: 5116.24 | G19: 7568.52 | H19: 0 | I19: 54000 | J19: =G19 -> 7568.52
A20: WSWT2325650 | B20: 52000 | C20: 49350 | D20: 52000 | E20: 46338.49 | F20: 10232.95 | G20: 36105.54 | H20: =+J20-I20 -> 36105.54 | J20: =G20 -> 36105.54
A21: WSWT2625650 | B21: 8563 | C21: 4200 | D21: 8563 | E21: 9913.1539 | F21: 2306 | G21: 7607.1539 | H21: =+J21-I21 -> 7607.1539 | J21: =G21 -> 7607.1539
A22: WSWT262575051 | B22: 10000 | C22: 7350 | D22: 7000 | E22: 8703.31 | F22: 0 | G22: 8703.31 | H22: =+J22-I22 -> 8703.31 | J22: =G22 -> 8703.31
A23: WSWT2625850SM | B23: 101000 | C23: 90459.6 | D23: 97152 | E23: 120792 | F23: 51818.196 | G23: 68973.8 | H23: =+J23-I23 -> 68973.8 | J23: =G23 -> 68973.8
A24: WSWT2825850 | B24: 70000 | C24: 52500 | D24: 70000 | E24: 86474.3 | F24: 7016 | G24: 79458.3 | H24: =+J24-I24 -> 79458.3 | J24: =G24 -> 79458.3
A25: WSWTFCL022325650 | B25: 10000 | C25: 10500 | D25: 10000 | E25: 9918.7 | F25: 6043 | G25: 3875.7 | H25: =+J25-I25 -> 3875.7 | J25: =G25 -> 3875.7
A26: WSWTSCL052325650 | B26: 5000 | C26: 5250 | D26: 5000 | E26: 5099.05 | F26: 5099.05 | G26: 0 | H26: =+J26-I26 -> 0 | J26: =G26 -> 0
A27: ผลรวมทั้งหมด | B27: 1759641 | C27: 1573877.6 | D27: 1737936 | E27: 1626471.1 | F27: 162700.24 | G27: 1463770.9 | H27: =+J27-I27 -> 1463770.9 | J27: =G27 -> 1463770.9
H28: =+J28-I28 -> 0 | J28: =G28 -> 0 | M28: =+GETPIVOTDATA("ผลรวม ของ ใช้",$A$6)+H29+H33 -> 4636444.4
H29: =SUM(H7:H28) -> 2919973.3 | I29: =SUM(I7:I28) -> 54000 | J29: =SUM(J7:J28) -> 2927541.8
H32: =+H26 -> 0 | I32: 85 | J32: =+(H32+H29)*I32 -> 2.4819773e+08 | K32: =+J32/1000 -> 248197.73
H33: 90000 | I33: 95 | J33: =+H33*I33 -> 8550000 | K33: =+J33/1000 -> 8550
H35: =+H32+H33+H29 -> 3009973.3 | K35: =+K32+K33 -> 256747.73
N36: 705222
A37: ยอดส่ง 1/2/68 - 17/2/68 | B37: 1565717 | H37: 15 | I37: =+H35/H37 -> 200664.89
N38: =+H35+N36 -> 3715195.3
I39: =+H37*110000 -> 1650000
B41: =+B29+B37+B31-110000 -> 1455717 | C41: =+C29+C37+C31 -> 0 | D41: =+D29+D37+D31-110000 -> -110000 | E41: =+E29+E37+E31 -> 0 | F41: =+F29+F37+F31 -> 0 | G41: =+G29+G37+G31 -> 0
B43: 3218150
B45: =+B43-B41 -> 1762433
C47: =+C41/9 -> 0 | D47: =+D41/9 -> -12222.222

Sheet 4(Order)
A2: เลขที่ SO | B2: (หลายรายการ)
A3: วันส่ง | B3: (หลายรายการ)
A4: ชื่อลูกค้า | B4: (ทั้งหมด)
A6: ประเภท | B6: ผลรวม ของ จำนวนส่ง | C6: ผลรวม ของ ค้างพิมพ์ | D6: ผลรวม ของ ค้างตัด | E6: ผลรวม ของ ใช้ | F6: ผลรวม ของ Stock | G6: ผลรวม ของ ค้างทอ
A7: WSWT1425800 | B7: 10000 | C7: 10500 | D7: 10000 | E7: 6565.9 | F7: 6565.9 | G7: 0 | I7: =+K7-J7 -> 0 | K7: =G7 -> 0
A8: WSWT1621720SMFX | B8: 10000 | C8: 10500 | D8: 10000 | E8: 7404.1 | F8: 3572 | G8: 3832.1 | I8: =+K8-J8 -> 3832.1 | K8: =G8 -> 3832.1
A9: WSWT1625800 | B9: 10000 | C9: 10500 | D9: 10000 | E9: 7404.1 | F9: 7404.1 | G9: 0 | I9: =+K9-J9 -> 0 | K9: =G9 -> 0
A10: WSWT1825800 | B10: 5000 | C10: 5250 | D10: 5000 | E10: 4121.15 | F10: 4121.15 | G10: 0 | I10: =+K10-J10 -> 0 | K10: =G10 -> 0
A11: WSWT1825800SM | B11: 10000 | C11: 10500 | D11: 10000 | E11: 8801.1 | F11: 0 | G11: 8801.1 | I11: =+K11-J11 -> 8801.1 | K11: =G11 -> 8801.1
A12: WSWT1921720 | B12: 190000 | C12: 141750 | D12: 185000 | E12: 165055.55 | F12: 7603.95 | G12: 157451.6 | I12: =+K12-J12 -> 157451.6 | K12: =G12 -> 157451.6
A13: WSWT19251000SM | B13: 10080 | C13: 10584 | D13: 10080 | E13: 9998.0496 | F13: 8000.0248 | G13: 1998.0248 | I13: =+K13-J13 -> 1998.0248 | K13: =G13 -> 1998.0248
A14: WSWT1925800 | B14: 60000 | C14: 21000 | D14: 60000 | E14: 16484.6 | F14: 5000 | G14: 11484.6 | I14: =+K14-J14 -> 11484.6 | K14: =G14 -> 11484.6
A15: WSWT1925800SM | B15: 10000 | C15: 10500 | D15: 10000 | E15: 7683.5 | F15: 7683.5 | G15: 0 | I15: =+K15-J15 -> 0 | K15: =G15 -> 0
A16: WSWT2025800 | B16: 546998 | C16: 504733.95 | D16: 537141 | E16: 517535.19 | F16: 0 | G16: 517535.19 | I16: =+K16-J16 -> 517535.19 | K16: =G16 -> 517535.19
A17: WSWT2025800SM | B17: 106000 | C17: 100800 | D17: 106000 | E17: 103350.06 | F17: 18538.19 | G17: 84811.87 | I17: 0 | J17: 54000 | K17: =G17 -> 84811.87
A18: WSWT2121670SM | B18: 38000 | C18: 16800 | D18: 38000 | E18: 17211.04 | F18: 17211.04 | G18: 0 | I18: =+K18-J18 -> 0 | K18: =G18 -> 0
A19: WSWT2125650 | B19: 47000 | C19: 10500 | D19: 47000 | E19: 50361.85 | F19: 5900 | G19: 44461.85 | I19: =+K19-J19 -> 44461.85 | K19: =G19 -> 44461.85
A20: WSWT2321750 | B20: 12000 | C20: 12600 | D20: 12000 | E20: 12684.76 | F20: 5116.24 | G20: 7568.52 | I20: =+K20-J20 -> 7568.52 | K20: =G20 -> 7568.52
A21: WSWT2325650 | B21: 20000 | C21: 15750 | D21: 20000 | E21: 14598.65 | F21: 10232.95 | G21: 4365.7 | I21: =+K21-J21 -> 4365.7 | K21: =G21 -> 4365.7
A22: WSWT2625650 | B22: 8563 | C22: 4200 | D22: 8563 | E22: 9913.1539 | F22: 2306 | G22: 7607.1539 | I22: =+K22-J22 -> 7607.1539 | K22: =G22 -> 7607.1539
A23: WSWT262575051 | B23: 10000 | C23: 7350 | D23: 7000 | E23: 8703.31 | F23: 0 | G23: 8703.31 | I23: =+K23-J23 -> 8703.31 | K23: =G23 -> 8703.31
A24: WSWT2625850SM | B24: 101000 | C24: 90459.6 | D24: 97152 | E24: 120792 | F24: 51818.196 | G24: 68973.8 | I24: =+K24-J24 -> 68973.8 | K24: =G24 -> 68973.8
A25: WSWT2825850 | B25: 50000 | C25: 52500 | D25: 50000 | E25: 59372.5 | F25: 7016 | G25: 52356.5 | I25: =+K25-J25 -> 52356.5 | K25: =G25 -> 52356.5
A26: WSWTFCL022325650 | B26: 10000 | C26: 10500 | D26: 10000 | E26: 9918.7 | F26: 6043 | G26: 3875.7 | I26: =SUM(I7:I25) -> 895139.45 | J26: =SUM(J7:J25) -> 54000 | K26: =SUM(K7:K25) -> 979951.32
A27: WSWTSCL052325650 | B27: 5000 | C27: 5250 | D27: 5000 | E27: 5099.05 | F27: 5099.05 | G27: 0
A28: ผลรวมทั้งหมด | B28: 1269641 | C28: 1062527.5 | D28: 1247936 | E28: 1163058.3 | F28: 179231.29 | G28: 983827.02
A37: ยอดส่ง 1/4/68 - 5/4/68 | B37: 434796
A38: Order+ส่ง | B38: =++B28+B37 -> 1704437
A39: ประมาณการ | B39: 742000 | C39: 742350 | D39: 742000 | E39: 701182.24 | F39: 7949 | G39: 693233.24
A41: Order+ส่ง+ประมาณการ | B41: =+B28+B37+B39+B31 -> 2446437 | C41: =+C24+C37+C39+C31 -> 832809.6 | D41: =+D24+D37+D39+D31 -> 839152 | E41: =+E24+E37+E39+E31 -> 821974.24 | F41: =+F24+F37+F39+F31 -> 59767.196 | G41: =+G24+G37+G39+G31 -> 762207.04
B43: 3171376
B45: =+B41-B43 -> -724939 | C45: =+$B$45 -> -724939 | D45: =+$B$45 -> -724939 | F45: =+$B$45 -> -724939
D47: =+D41/6 -> 139858.67

Sheet 4(Order) แยกลูกค้า
A1: เลขที่ SO | B1: (หลายรายการ)
A2: วันส่ง | B2: (หลายรายการ)
A4: ประเภท | B4: ชื่อลูกค้า | C4: ผลรวม ของ จำนวนส่ง | D4: ผลรวม ของ ค้างพิมพ์ | E4: ผลรวม ของ ค้างตัด | F4: ผลรวม ของ Stock | G4: ผลรวม ของ ค้างทอ | I4: vn
A5: WSWT1425800 | B5: บจก.ปึงเป้งน้ำ | C5: 10000 | D5: 10500 | E5: 10000 | F5: 6565.9 | G5: 0 | H5: =G5 -> 0
A6: WSWT1425800 ผลรวม | C6: 10000 | D6: 10500 | E6: 10000 | F6: 6565.9 | G6: 0 | H6: =G6 -> 0
A7: WSWT1825800 | B7: ร้านเห็ดไพลิน | C7: 5000 | D7: 5250 | E7: 5000 | F7: 4121.15 | G7: 0 | H7: =G7 -> 0
A8: WSWT1825800 ผลรวม | C8: 5000 | D8: 5250 | E8: 5000 | F8: 4121.15 | G8: 0 | H8: =G8 -> 0
A9: WSWT1825800SM | B9: บจก.2เอ็ม อโกรเท็ค | C9: 10000 | D9: 10500 | E9: 10000 | F9: 0 | G9: 8801.1 | H9: =G9 -> 8801.1
A10: WSWT1825800SM ผลรวม | C10: 10000 | D10: 10500 | E10: 10000 | F10: 0 | G10: 8801.1 | H10: =G10 -> 8801.1
A11: WSWT1921720 | B11: บจก.เคอรี่ฟลาวมิลล์ | C11: 45000 | D11: 0 | E11: 40000 | F11: 0 | G11: 35204.4 | H11: =G11 -> 35204.4
A12: WSWT1921720 ผลรวม | C12: 45000 | D12: 0 | E12: 40000 | F12: 0 | G12: 35204.4 | H12: =G12 -> 35204.4
A13: WSWT19251000SM | B13: บจก.อินเทคค์ โกลบอล | C13: 10080 | D13: 10584 | E13: 10080 | F13: 8000.0248 | G13: 1998.0248 | H13: =G13 -> 1998.0248
A14: WSWT19251000SM ผลรวม | C14: 10080 | D14: 10584 | E14: 10080 | F14: 8000.0248 | G14: 1998.0248 | H14: =G14 -> 1998.0248
A15: WSWT1925800 | B15: บจก.ซีแมน | C15: 60000 | D15: 21000 | E15: 60000 | F15: 5000 | G15: 11484.6 | H15: =G15 -> 11484.6
A16: WSWT1925800 ผลรวม | C16: 60000 | D16: 21000 | E16: 60000 | F16: 5000 | G16: 11484.6 | H16: =G16 -> 11484.6
A17: WSWT1925800SM | B17: บจก.เอเชี่ยนเคมิคัล | C17: 10000 | D17: 10500 | E17: 10000 | F17: 7683.5 | G17: 0 | H17: =G17 -> 0
A18: WSWT1925800SM ผลรวม | C18: 10000 | D18: 10500 | E18: 10000 | F18: 7683.5 | G18: 0 | H18: =G18 -> 0
A19: WSWT2025800 | B19: บจก.เบทาโกร | C19: 449000 | D19: 407018.85 | E19: 439143 | F19: 0 | G19: 417441.78 | H19: =G19 -> 417441.78
B20: บจก.อินเทคค์ โกลบอล | C20: 32998 | D20: 29465.1 | E20: 32998 | F20: 0 | G20: 30872.059 | H20: =G20 -> 30872.059
A21: WSWT2025800 ผลรวม | C21: 481998 | D21: 436483.95 | E21: 472141 | F21: 0 | G21: 448313.84 | H21: =G21 -> 448313.84
A22: WSWT2025800SM | B22: บจก.อินเทคค์ โกลบอล | C22: 10000 | D22: 10500 | E22: 10000 | F22: 0 | G22: 10477.5 | H22: =G22 -> 10477.5
B23: บจก.เอพีเอ็ม อะโกร | C23: 18000 | D23: 8400 | E23: 18000 | F23: 4414.52 | G23: 4414.52 | H23: =G23 -> 4414.52
B24: บจก.เอสพีเอ็ม อาหารสัตว์ | C24: 8000 | D24: 8400 | E24: 8000 | F24: 8745.22 | G24: 0 | H24: =G24 -> 0
B25: บจก.วีซีเอฟ | C25: 70000 | D25: 73500 | E25: 70000 | F25: 5378.45 | G25: 69919.85 | H25: =G25 -> 69919.85
A26: WSWT2025800SM ผลรวม | C26: 106000 | D26: 100800 | E26: 106000 | F26: 18538.19 | G26: 84811.87 | H26: =G26 -> 84811.87
A27: WSWT2121670SM | B27: บจก.ที.ซี.ยูเนี่ยน อโกรเทค | C27: 16000 | D27: 16800 | E27: 16000 | F27: 17211.04 | G27: 0 | H27: =G27 -> 0
B28: บจก.เอ็นบี ดิสทริบิวชั่น | C28: 17000 | D28: 0 | E28: 17000 | F28: 0 | G28: 0 | H28: =G28 -> 0
B29: คุณนพวินทร์ รัตนเศรษฐ์เมธา | C29: 5000 | D29: 0 | E29: 5000 | F29: 0 | G29: 0 | H29: =G29 -> 0
A30: WSWT2121670SM ผลรวม | C30: 38000 | D30: 16800 | E30: 38000 | F30: 17211.04 | G30: 0 | H30: =G30 -> 0
A31: WSWT2125650 | B31: บจก.หนองบัวฟีดมิลล์ | C31: 15000 | D31: 0 | E31: 15000 | F31: 0 | G31: 16554.45 | H31: =G31 -> 16554.45
B32: บจก.ไลม์มาสเตอร์ | C32: 10000 | D32: 10500 | E32: 10000 | F32: 0 | G32: 9918.7 | H32: =G32 -> 9918.7
A33: WSWT2125650 ผลรวม | C33: 25000 | D33: 10500 | E33: 25000 | F33: 0 | G33: 26473.15 | H33: =G33 -> 26473.15
A34: WSWT2221940 | B34: กองเมล็ดพันธุ์ข้าว กรมการข้าว | C34: 268368 | D34: 259284.9 | E34: 252429 | F34: 135598 | G34: 121578.91 | H34: =G34 -> 121578.91
A35: WSWT2221940 ผลรวม | C35: 268368 | D35: 259284.9 | E35: 252429 | F35: 135598 | G35: 121578.91 | H35: =G35 -> 121578.91
A36: WSWT2321750 | B36: บจก.ปริ้นซ์ อโกร ไซแอนส์ | C36: 8000 | D36: 8400 | E36: 8000 | F36: 1037 | G36: 7568.52 | H36: =G36 -> 7568.52
B37: บจก.รุ่งเรืองค้าเจริญ | C37: 4000 | D37: 4200 | E37: 4000 | F37: 4079.24 | G37: 0 | H37: =G37 -> 0
A38: WSWT2321750 ผลรวม | C38: 12000 | D38: 12600 | E38: 12000 | F38: 5116.24 | G38: 7568.52 | H38: =G38 -> 7568.52
A39: WSWT2325650 | B39: บจก.กบินทร์อินทรีย์ | C39: 5000 | D39: 5250 | E39: 5000 | F39: 4679.95 | G39: 0 | H39: =G39 -> 0
B40: บจก.ซิเบลโก้(บางเลน) | C40: 5000 | D40: 0 | E40: 5000 | F40: 0 | G40: 0 | H40: =G40 -> 0
B41: คุณปราสาท เจริญธรรมรักษา | C41: 10000 | D41: 10500 | E41: 10000 | F41: 5553 | G41: 4365.7 | H41: =G41 -> 4365.7
...

Sheet 4(Fc) แยกลูกค้า
A1: เลขที่ SO | B1: ประมาณการ
A2: วันส่ง | B2: (หลายรายการ) | D2: 12
A4: ประเภท | B4: ชื่อลูกค้า | C4: ผลรวม ของ จำนวนส่ง | D4: ผลรวม ของ ค้างพิมพ์ | E4: ผลรวม ของ ค้างตัด | F4: ผลรวม ของ ใช้ | G4: ผลรวม ของ Stock | H4: ผลรวม ของ ค้างทอ
A5: WSWT1825800 | B5: บจก.ฟาร์เธอร์ส วิง ซัพพลาย | C5: 15000 | D5: 15750 | E5: 15000 | F5: 13201.65 | G5: 7949 | H5: 5252.65
A6: WSWT1825800 ผลรวม | C6: 15000 | D6: 15750 | E6: 15000 | F6: 13201.65 | G6: 7949 | H6: 5252.65
A7: WSWT1921720 | B7: บจก.เคอรี่ฟลาวมิลล์ | C7: 325000 | D7: 341250 | E7: 325000 | F7: 286035.75 | G7: 0 | H7: 286035.75
A8: WSWT1921720 ผลรวม | C8: 325000 | D8: 341250 | E8: 325000 | F8: 286035.75 | G8: 0 | H8: 286035.75
A9: WSWT1925800 | B9: บจก.เพรซิเดนท์ฟลาวมิลล์ | C9: 120000 | D9: 126000 | E9: 120000 | F9: 105613.2 | G9: 0 | H9: 105613.2
B10: บจก.เอ็กเซลเล้นท์ | C10: 30000 | D10: 31500 | E10: 30000 | F10: 26403.3 | G10: 0 | H10: 26403.3
A11: WSWT1925800 ผลรวม | C11: 150000 | D11: 157500 | E11: 150000 | F11: 132016.5 | G11: 0 | H11: 132016.5
A12: WSWT2025650 | B12: บจก.หนองบัวฟีดมิลล์ | C12: 5000 | D12: 0 | E12: 5000 | F12: 4400.55 | G12: 0 | H12: 4400.55
A13: WSWT2025650 ผลรวม | C13: 5000 | D13: 0 | E13: 5000 | F13: 4400.55 | G13: 0 | H13: 4400.55
A14: WSWT2025800SM | B14: บจก.อินเทคค์ โกลบอล | C14: 120000 | D14: 126000 | E14: 120000 | F14: 125730 | G14: 0 | H14: 125730
A15: WSWT2025800SM ผลรวม | C15: 120000 | D15: 126000 | E15: 120000 | F15: 125730 | G15: 0 | H15: 125730
A16: WSWT2121670SM | B16: บจก.ที.ซี.ยูเนี่ยน อโกรเทค | C16: 20000 | D16: 21000 | E16: 20000 | F16: 21513.8 | G16: 0 | H16: 21513.8
B17: บจก.แอมโก้เวท | C17: 40000 | D17: 42000 | E17: 40000 | F17: 43027.6 | G17: 0 | H17: 43027.6
B18: บจก.เอ็นบี ดิสทริบิวชั่น | C18: 5000 | D18: 5250 | E18: 5000 | F18: 5378.45 | G18: 0 | H18: 5378.45
A19: WSWT2121670SM ผลรวม | C19: 65000 | D19: 68250 | E19: 65000 | F19: 69919.85 | G19: 0 | H19: 69919.85
A20: WSWT2125650 | B20: บจก.หนองบัวฟีดมิลล์ | C20: 10000 | D20: 0 | E20: 10000 | F20: 11036.3 | G20: 0 | H20: 11036.3
A21: WSWT2125650 ผลรวม | C21: 10000 | D21: 0 | E21: 10000 | F21: 11036.3 | G21: 0 | H21: 11036.3
A22: WSWT2325650 | B22: บจก.ซิเบลโก้ | C22: 20000 | D22: 21000 | E22: 20000 | F22: 19837.4 | G22: 0 | H22: 19837.4
B23: พันธุ์ข้าว | C23: 7000 | D23: 7350 | E23: 7000 | F23: 6943.09 | G23: 0 | H23: 6943.09
B24: บจก.ซิเบลโก้(สบปราบ) | C24: 5000 | D24: 5250 | E24: 5000 | F24: 4959.35 | G24: 0 | H24: 4959.35
A25: WSWT2325650 ผลรวม | C25: 32000 | D25: 33600 | E25: 32000 | F25: 31739.84 | G25: 0 | H25: 31739.84
A26: WSWT2825850 | B26: บจก.ที.ซี.ยูเนี่ยน อโกรเทค | C26: 20000 | D26: 0 | E26: 20000 | F26: 27101.8 | G26: 0 | H26: 27101.8
A27: WSWT2825850 ผลรวม | C27: 20000 | D27: 0 | E27: 20000 | F27: 27101.8 | G27: 0 | H27: 27101.8
A28: ผลรวมทั้งหมด | C28: 742000 | D28: 742350 | E28: 742000 | F28: 701182.24 | G28: 7949 | H28: 693233.24
D119: Cap พิมพ์ | E119: Cap ตัด | F119: Stock 16/7 บ่าย | G119: Cap ทอ | I119: วันทงาน
B120: lส่ง | C120: 1-16/7 | D120: 160000 | E120: 160000 | G120: 120000 | I120: 12
C121: 1975256 | D121: =+D120*I120 -> 1920000 | E121: =+E120*I120 -> 1920000 | F121: 825147 | G121: =+G120*I120 -> 1440000
A122: เบทาโกรส่งแล้ว | B122: 20700 | C122: 424374
A123: เบทาโกรส่งแล้ว | B123: 20800 | C123: 155973
C126: รวมส่ง+ค้างส่ง | D126: ส่วนต่างCapคงเหลือ | E126: ส่วนต่างCapคงเหลือ | F126: คงเหลือ
C127: =+C50+C121 -> 1975256 | D127: =+D121-D50 -> 1920000 | E127: =+E121-E50 -> 1920000 | F127: =+F121-F50 -> 825147 | G127: =+G121-G50 -> 1440000
B129: 20700VN 20/7 | G129: 350000

Sheet ค้างทอ14-3-68
A3: ผลรวม ของ ค้างทอ | W3: ผลรวม ของ ค้างทอ
A4: ป้ายชื่อแถว | B4: 45726 | C4: 45728 | D4: 45729 | E4: 45730 | F4: 45731 | G4: 45732 | H4: 45733 | I4: 45735 | J4: 45736 | K4: 45737 | L4: 45738 | M4: 45739 | N4: 45740 | O4: 45741 | P4: 45742 | Q4: 45743 | R4: 45745 | S4: 45746 | T4: 45747 | U4: ค้างทอ | W4: ป้ายชื่อแถว | X4: 45749 | Y4: 45750 | Z4: 45751 | AA4: 45752 | AB4: 45760 | AC4: 45765 | AD4: 45766 | AE4: 45767 | AF4: 45775 | AG4: ผลรวมทั้งหมด
A5: WSWT1625800SM | U5: =SUM(B5:T5) -> 0 | W5: WSWT1625800SM | AG5: =SUM(X5:AF5) -> 0
A6: WSWT1825800 | U6: =SUM(B6:T6) -> 0 | W6: WSWT1825800 | AG6: =SUM(X6:AF6) -> 0
A7: WSWT1825800SM | U7: =SUM(B7:T7) -> 0 | W7: WSWT1825800SM | AG7: =SUM(X7:AF7) -> 0
A8: WSWT1921720 | B8: 30196.794 | D8: 22002.75 | E8: 18440.4 | F8: 22840.95 | H8: 45123.1 | J8: 22002.75 | K8: 22561.55 | L8: 14039.85 | M8: 22282.15 | N8: 35204.4 | U8: =SUM(B8:T8) -> 254694.69 | W8: WSWT1921720 | AG8: =SUM(X8:AF8) -> 0
A9: WSWT19251000SM | M9: 0 | U9: =SUM(B9:T9) -> 0 | W9: WSWT19251000SM | AG9: =SUM(X9:AF9) -> 0
A10: WSWT1925800 | F10: 0 | J10: 30464.7 | U10: =SUM(B10:T10) -> 30464.7 | W10: WSWT1925800 | AG10: =SUM(X10:AF10) -> 0
A11: WSWT1925800SM | C11: 0 | U11: =SUM(B11:T11) -> 0 | W11: WSWT1925800SM | AG11: =SUM(X11:AF11) -> 0
A12: WSWT2025650 | U12: =SUM(B12:T12) -> 0 | W12: WSWT2025650 | AG12: =SUM(X12:AF12) -> 0
A13: WSWT2025700 | U13: =SUM(B13:T13) -> 0 | W13: WSWT2025700 | AG13: =SUM(X13:AF13) -> 0
A14: WSWT2025800 | B14: 0 | C14: 33187.481 | D14: 12908.28 | I14: 86055.2 | J14: 21513.8 | L14: 64262 | M14: 140873.48 | P14: 102190.55 | Q14: 73901.3 | R14: 96812.1 | S14: 16135.35 | T14: 31432.5 | U14: =SUM(B14:T14) -> 679272.04 | W14: WSWT2025800 | X14: 21513.8 | Y14: 21513.8 | Z14: 10756.9 | AA14: 107569 | AB14: 21513.8 | AC14: 10756.9 | AD14: 21513.8 | AG14: =SUM(X14:AF14) -> 215138
A15: WSWT2025800SM | C15: 0 | D15: 0 | E15: 0 | F15: 0 | G15: 3310.89 | H15: 4959.35 | I15: 37649.15 | J15: 0 | K15: 0 | L15: 5280.66 | M15: 18342.959 | P15: 16554.45 | Q15: 47427.661 | U15: =SUM(B15:T15) -> 133525.12 | W15: WSWT2025800SM | AG15: =SUM(X15:AF15) -> 0
A16: WSWT2025850 | C16: 0 | D16: 712.8891 | E16: 0 | F16: 0 | G16: 0 | I16: 0 | K16: 0 | L16: 0 | U16: =SUM(B16:T16) -> 712.8891 | W16: WSWT2025850 | AG16: =SUM(X16:AF16) -> 0
A17: WSWT2121670SM | D17: 0 | I17: 0 | J17: 0 | P17: 0 | U17: =SUM(B17:T17) -> 0 | W17: WSWT2121670SM | AG17: =SUM(X17:AF17) -> 0
A18: WSWT2125650 | U18: =SUM(B18:T18) -> 0 | W18: WSWT2125650 | AG18: =SUM(X18:AF18) -> 0
A19: WSWT2221940 | O19: 177732.47 | U19: =SUM(B19:T19) -> 177732.47 | W19: WSWT2221940 | AG19: =SUM(X19:AF19) -> 0
A20: WSWT2321112512551 | U20: =SUM(B20:T20) -> 0 | W20: WSWT2321112512551 | AG20: =SUM(X20:AF20) -> 0
A21: WSWT2321112512551VN | U21: =SUM(B21:T21) -> 0 | W21: WSWT2321112512551VN | AF21: 49481.74 | AG21: =SUM(X21:AF21) -> 49481.74
A22: WSWT2321750 | D22: 2957.55 | J22: 11595.1 | L22: 4959.35 | U22: =SUM(B22:T22) -> 19512 | W22: WSWT2321750 | AG22: =SUM(X22:AF22) -> 0
A23: WSWT2325650 | E23: 2797.7 | F23: 4959.35 | P23: 0 | U23: =SUM(B23:T23) -> 7757.05 | W23: WSWT2325650 | AG23: =SUM(X23:AF23) -> 0
A24: WSWT2625650 | B24: 0 | G24: 0 | J24: 0 | U24: =SUM(B24:T24) -> 0 | W24: WSWT2625650 | AG24: =SUM(X24:AF24) -> 0
A25: WSWT262575051 | T25: 29183.25 | U25: =SUM(B25:T25) -> 29183.25 | W25: WSWT262575051 | AG25: =SUM(X25:AF25) -> 0
A26: WSWT2625800 | U26: =SUM(B26:T26) -> 0 | W26: WSWT2625800 | AG26: =SUM(X26:AF26) -> 0
A27: WSWT2625850SM | C27: 21299.9 | J27: 37299.9 | M27: 37299.9 | O27: 12433 | P27: 37300 | U27: =SUM(B27:T27) -> 145632.7 | W27: WSWT2625850SM | Y27: 37299.9 | AE27: 37299.9 | AG27: =SUM(X27:AF27) -> 74599.8
A28: WSWT2825850 | P28: 0 | U28: =SUM(B28:T28) -> 0 | W28: WSWT2825850 | AG28: =SUM(X28:AF28) -> 0
A29: WSWTFCL022325650 | P29: 12396.05 | U29: =SUM(B29:T29) -> 12396.05 | W29: WSWTFCL022325650 | AG29: =SUM(X29:AF29) -> 0
A30: WSWTSCL052325650 | F30: 0 | U30: =SUM(B30:T30) -> 0 | W30: WSWTSCL052325650 | AG30: =SUM(X30:AF30) -> 0
