Workbook

Sheet Linkสูตรออร์เดอร์  (2)
B2: เรียงกำหนดส่ง | D2: ลบ 0 | T2: เรียง 1
B3: ข้อมูลUpdate ณ. วันที่ | D3: 45751 | E3: เวลา | G3: 10.53
A4: วันรับออร์เดอร์/แบบ | B4: เลขที่ SO | C4: ชื่อลูกค้า | E4: 10.3 | I4: น้ำหนัก | L4: บิด/จับจีบ | M4: ถุงใน | Q4: =[1]หน้าผ้า!$AC$13 -> 44873 | S4: วิธีบรรจุ | T4: วันส่ง | U4: จำนวนส่ง | V4: ตัดเย็บ (ใบ) | W4: =[1]หน้าผ้า!$AJ$13 -> 44873 | X4: พิมพ์ (ใบ) | Y4: =[1]หน้าผ้า!$AM$13 -> 44876 | Z4: ผ้าทอ (เมตร) Updateณ | AB4: =[1]หน้าผ้า!$AR$12 -> 44876 | AD4: ผ้าเคลือบ(เมตร) | AF4: หมายเหตุ | AG4: เครื่อง
B5: เลขที่ SO | C5: ชื่อลูกค้า | D5: ตรา | E5: กว้าง | F5: ยาว | G5: สี | H5: เคลือบ | I5: กรัม/ใบ | J5: * | K5: aw | L5: บิด/จับจีบ | M5: กว้าง | N5: ยาว | O5: หนา | P5: ใช้(กก.) | Q5: Stock(กก.) | R5: ผลิต(กก.) | S5: วิธีบรรจุ | T5: วันส่ง | U5: จำนวนส่ง | V5: StockFG | W5: ค้างตัด | X5: พิมพ์แล้ว | Y5: ค้างพิมพ์ | Z5: ประเภท | AA5: ใช้ | AB5: Stock | AC5: ค้างทอ | AD5: Stock | AE5: ค้างเคลือบ | AF5: หมายเหตุ | AG5: ที่พิมพ์ได้ | AH5: process | AI5: Lead time | AJ5: วันที่ส่งPL | AK5: เคลือบ | AL5: ได้ ART | AM5: พิมพ์ | AN5: จีบ-บิด | AO5: ตัด-เย็บ | AP5: ทอ | AQ5: สวมถุง | AR5: เย็บปาก | AS5: PT | AT5: ม้วน | AU5: ตัด | AV5: ตอกตาไก่ | AW5: GROUP | AX5: ART | AY5: หมายเหตุปัญหา | AZ5: ราคา/ใบ | BA5: ราคารวม | BB5: workweek | BC5: เส้นเทป | BD5: จำนวน
A6: =[2]หน้าผ้า!C15 -> 0 | B6: =[2]หน้าผ้า!B15 -> 0 | C6: =[2]หน้าผ้า!E15 -> 0 | D6: =[2]หน้าผ้า!F15 -> 0 | E6: =[2]หน้าผ้า!G15 -> 12 | F6: =[2]หน้าผ้า!H15 -> 16 | G6: =[2]หน้าผ้า!I15 -> ขาว | H6: =[2]หน้าผ้า!J15 -> 0 | I6: =[2]หน้าผ้า!L15 -> 25 | J6: =[2]หน้าผ้า!M15 -> ± | K6: =[2]หน้าผ้า!N15 -> 5 | L6: =[2]หน้าผ้า!R15 -> 0 | M6: =[2]หน้าผ้า!T15 -> 0 | N6: =[2]หน้าผ้า!U15 -> 0 | O6: =[2]หน้าผ้า!V15 -> 0 | P6: =[2]หน้าผ้า!AB15 -> 0 | Q6: =[2]หน้าผ้า!AC15 -> 0 | R6: =[2]หน้าผ้า!AD15 -> 0 | S6: =[2]หน้าผ้า!Z15 -> 0 | T6: =[2]หน้าผ้า!X15 -> 0 | U6: =[2]หน้าผ้า!AA15 -> 0 | V6: =[2]หน้าผ้า!AJ15 -> 0 | W6: =[2]หน้าผ้า!AL15 -> 0 | X6: =[2]หน้าผ้า!AM15 -> 0 | Y6: =[2]หน้าผ้า!AN15 -> 0 | Z6: =[2]หน้าผ้า!AO15 -> WSWT1221750 | AA6: =[2]หน้าผ้า!AQ15 -> #REF! | AB6: =[2]หน้าผ้า!AR15 -> #REF! | AC6: =[2]หน้าผ้า!AS15 -> #REF! | AD6: =[2]หน้าผ้า!AT15 -> #REF! | AE6: =[2]หน้าผ้า!AU15 -> #REF! | AF6: =[2]หน้าผ้า!AI15 -> ระบุในSD | AG6: =[3]หน้าผ้า!DC18 -> < Ord 20,000 | AH6: =[2]หน้าผ้า!DL15 -> 0 | AI6: =[2]หน้าผ้า!DM15 -> 0 | AJ6: =[2]หน้าผ้า!DN15 -> 0 | AK6: =[2]หน้าผ้า!DQ15 -> 0 | AL6: =[2]หน้าผ้า!DR15 -> 0 | AM6: =[2]หน้าผ้า!DS15 -> 0 | AN6: =[2]หน้าผ้า!DT15 -> 0 | AO6: =[2]หน้าผ้า!DU15 -> 0 | AP6: =[2]หน้าผ้า!DP15 -> 0 | AQ6: =[2]หน้าผ้า!DW15 -> 0 | AR6: =[2]หน้าผ้า!DX15 -> 0 | AS6: =[2]หน้าผ้า!DY15 -> 0 | AT6: =[2]หน้าผ้า!DZ15 -> 0 | AU6: =[2]หน้าผ้า!EA15 -> 0 | AV6: =[2]หน้าผ้า!EB15 -> 0 | AW6: =[2]หน้าผ้า!EC15 -> 0 | AX6: =[2]หน้าผ้า!ED15 -> 0 | AY6: =[2]หน้าผ้า!AG15 -> 0 | AZ6: =[2]หน้าผ้า!EG15 -> 0 | BA6: =[2]หน้าผ้า!EH15 -> 0 | BB6: =[2]หน้าผ้า!EI15 -> 0 | BC6: =[2]หน้าผ้า!BZ15 -> WRWT120750/WRWT21750 | BD6: =[2]หน้าผ้า!CA15 -> 0
A7: =[2]หน้าผ้า!C16 -> 45743 | B7: =[2]หน้าผ้า!B16 -> MK68-000464 | C7: =[2]หน้าผ้า!E16 -> บจก.ปึงเป้งน้ำ | D7: =[2]หน้าผ้า!F16 -> เกลือตรามือ 10กก. | E7: =[2]หน้าผ้า!G16 -> 14 | F7: =[2]หน้าผ้า!H16 -> 22 | G7: =[2]หน้าผ้า!I16 -> ขาว | H7: =[2]หน้าผ้า!J16 -> ใส | I7: =[2]หน้าผ้า!L16 -> 42 | J7: =[2]หน้าผ้า!M16 -> ± | K7: =[2]หน้าผ้า!N16 -> 5 | L7: =[2]หน้าผ้า!R16 -> ไม่ | M7: =[2]หน้าผ้า!T16 -> ไม่สวมถุงใน | N7: =[2]หน้าผ้า!U16 -> 0 | O7: =[2]หน้าผ้า!V16 -> 0 | P7: =[2]หน้าผ้า!AB16 -> 0 | Q7: =[2]หน้าผ้า!AC16 -> 0 | R7: =[2]หน้าผ้า!AD16 -> 0 | S7: =[2]หน้าผ้า!Z16 -> 500กระสอบแบน | T7: =[2]หน้าผ้า!X16 -> 45757 | U7: =[2]หน้าผ้า!AA16 -> 10000 | V7: =[2]หน้าผ้า!AJ16 -> 0 | W7: =[2]หน้าผ้า!AL16 -> 10000 | X7: =[2]หน้าผ้า!AM16 -> 0 | Y7: =[2]หน้าผ้า!AN16 -> 10500 | Z7: =[2]หน้าผ้า!AO16 -> WSWT1425800 | AA7: =[2]หน้าผ้า!AQ16 -> 6565.9 | AB7: =[2]หน้าผ้า!AR16 -> 6565.9 | AC7: =[2]หน้าผ้า!AS16 -> 0 | AD7: =[2]หน้าผ้า!AT16 -> 2186 | AE7: =[2]หน้าผ้า!AU16 -> 4379.9 | AF7: =[2]หน้าผ้า!AI16 -> 0 | AG7: =[3]หน้าผ้า!DC19 -> ยังไม่ได้พิมพ์ | AH7: =[2]หน้าผ้า!DL16 -> P6 | AI7: =[2]หน้าผ้า!DM16 -> 4 | AJ7: =[2]หน้าผ้า!DN16 -> 45757 | AK7: =[2]หน้าผ้า!DQ16 -> 45753 | AL7: =[2]หน้าผ้า!DR16 -> 45746 | AM7: =[2]หน้าผ้า!DS16 -> 45754 | AN7: =[2]หน้าผ้า!DT16 -> 45755 | AO7: =[2]หน้าผ้า!DU16 -> 45756 | AP7: =[2]หน้าผ้า!DP16 -> 45752 | AQ7: =[2]หน้าผ้า!DW16 -> 0 | AR7: =[2]หน้าผ้า!DX16 -> 0 | AS7: =[2]หน้าผ้า!DY16 -> 0 | AT7: =[2]หน้าผ้า!DZ16 -> 0 | AU7: =[2]หน้าผ้า!EA16 -> 0 | AV7: =[2]หน้าผ้า!EB16 -> 0 | AW7: =[2]หน้าผ้า!EC16 -> งานเคลือบ+พิมพ์ | AX7: =[2]หน้าผ้า!ED16 -> / | AY7: =[2]หน้าผ้า!AG16 -> 0 | AZ7: =[2]หน้าผ้า!EG16 -> 0 | BA7: =[2]หน้าผ้า!EH16 -> 0 | BB7: =[2]หน้าผ้า!EI16 -> 0 | BC7: =[2]หน้าผ้า!BZ16 -> WRWT25800/WRWT25800 | BD7: =[2]หน้าผ้า!CA16 -> 0
A8: =[2]หน้าผ้า!C17 -> 0 | B8: =[2]หน้าผ้า!B17 -> 0 | C8: =[2]หน้าผ้า!E17 -> 0 | D8: =[2]หน้าผ้า!F17 -> 0 | E8: =[2]หน้าผ้า!G17 -> 14 | F8: =[2]หน้าผ้า!H17 -> 22 | G8: =[2]หน้าผ้า!I17 -> ขาว | H8: =[2]หน้าผ้า!J17 -> 0 | I8: =[2]หน้าผ้า!L17 -> 36 | J8: =[2]หน้าผ้า!M17 -> ± | K8: =[2]หน้าผ้า!N17 -> 5 | L8: =[2]หน้าผ้า!R17 -> 0 | M8: =[2]หน้าผ้า!T17 -> 0 | N8: =[2]หน้าผ้า!U17 -> 0 | O8: =[2]หน้าผ้า!V17 -> 0 | P8: =[2]หน้าผ้า!AB17 -> 0 | Q8: =[2]หน้าผ้า!AC17 -> 0 | R8: =[2]หน้าผ้า!AD17 -> 0 | S8: =[2]หน้าผ้า!Z17 -> 0 | T8: =[2]หน้าผ้า!X17 -> 0 | U8: =[2]หน้าผ้า!AA17 -> 0 | V8: =[2]หน้าผ้า!AJ17 -> 0 | W8: =[2]หน้าผ้า!AL17 -> 0 | X8: =[2]หน้าผ้า!AM17 -> 0 | Y8: =[2]หน้าผ้า!AN17 -> 0 | Z8: =[2]หน้าผ้า!AO17 -> WSWT1425800 | AA8: =[2]หน้าผ้า!AQ17 -> 6565.9 | AB8: =[2]หน้าผ้า!AR17 -> 6565.9 | AC8: =[2]หน้าผ้า!AS17 -> 0 | AD8: =[2]หน้าผ้า!AT17 -> 2186 | AE8: =[2]หน้าผ้า!AU17 -> 4379.9 | AF8: =[2]หน้าผ้า!AI17 -> ระบุในSD | AG8: =[3]หน้าผ้า!DC20 -> พร้อมส่ง | AH8: =[2]หน้าผ้า!DL17 -> 0 | AI8: =[2]หน้าผ้า!DM17 -> Lead time | AJ8: =[2]หน้าผ้า!DN17 -> 0 | AK8: =[2]หน้าผ้า!DQ17 -> 0 | AL8: =[2]หน้าผ้า!DR17 -> 0 | AM8: =[2]หน้าผ้า!DS17 -> 0 | AN8: =[2]หน้าผ้า!DT17 -> 0 | AO8: =[2]หน้าผ้า!DU17 -> 0 | AP8: =[2]หน้าผ้า!DP17 -> 0 | AQ8: =[2]หน้าผ้า!DW17 -> 0 | AR8: =[2]หน้าผ้า!DX17 -> 0 | AS8: =[2]หน้าผ้า!DY17 -> 0 | AT8: =[2]หน้าผ้า!DZ17 -> 0 | AU8: =[2]หน้าผ้า!EA17 -> 0 | AV8: =[2]หน้าผ้า!EB17 -> 0 | AW8: =[2]หน้าผ้า!EC17 -> 0 | AX8: =[2]หน้าผ้า!ED17 -> 0 | AY8: =[2]หน้าผ้า!AG17 -> 0 | AZ8: =[2]หน้าผ้า!EG17 -> 0 | BA8: =[2]หน้าผ้า!EH17 -> 0 | BB8: =[2]หน้าผ้า!EI17 -> 0 | BC8: =[2]หน้าผ้า!BZ17 -> WRWT140800/WRWT25800 | BD8: =[2]หน้าผ้า!CA17 -> 0
A9: =[2]หน้าผ้า!C18 -> 45713 | B9: =[2]หน้าผ้า!B18 -> MK68-000278 | C9: =[2]หน้าผ้า!E18 -> บจก.พีค อินโนเวชั่นโปรดักส์ | D9: =[2]หน้าผ้า!F18 -> โลลิโก้ | E9: =[2]หน้าผ้า!G18 -> 16 | F9: =[2]หน้าผ้า!H18 -> 25 | G9: =[2]หน้าผ้า!I18 -> ขาว | H9: =[2]หน้าผ้า!J18 -> ใส | I9: =[2]หน้าผ้า!L18 -> 50 | J9: =[2]หน้าผ้า!M18 -> ± | K9: =[2]หน้าผ้า!N18 -> 5 | L9: =[2]หน้าผ้า!R18 -> บิด | M9: =[2]หน้าผ้า!T18 -> 19 | N9: =[2]หน้าผ้า!U18 -> 28 | O9: =[2]หน้าผ้า!V18 -> 40 | P9: =[2]หน้าผ้า!AB18 -> 0 | Q9: =[2]หน้าผ้า!AC18 -> 0 | R9: =[2]หน้าผ้า!AD18 -> 0 | S9: =[2]หน้าผ้า!Z18 -> 500กระสอบ | T9: =[2]หน้าผ้า!X18 -> รอส่ง | U9: =[2]หน้าผ้า!AA18 -> 5000 | V9: =[2]หน้าผ้า!AJ18 -> 5049 | W9: =[2]หน้าผ้า!AL18 -> 0 | X9: =[2]หน้าผ้า!AM18 -> 5400 | Y9: =[2]หน้าผ้า!AN18 -> 0 | Z9: =[2]หน้าผ้า!AO18 -> WSWT1625800SM | AA9: =[2]หน้าผ้า!AQ18 -> 0 | AB9: =[2]หน้าผ้า!AR18 -> 0 | AC9: =[2]หน้าผ้า!AS18 -> 0 | AD9: =[2]หน้าผ้า!AT18 -> 0 | AE9: =[2]หน้าผ้า!AU18 -> 0 | AF9: =[2]หน้าผ้า!AI18 -> 0 | AG9: =[3]หน้าผ้า!DC21 -> ยังไม่ได้พิมพ์ | AH9: =[2]หน้าผ้า!DL18 -> P8 | AI9: =[2]หน้าผ้า!DM18 -> 4 | AJ9: =[2]หน้าผ้า!DN18 -> รอส่ง | AK9: =[2]หน้าผ้า!DQ18 -> #VALUE! | AL9: =[2]หน้าผ้า!DR18 -> #VALUE! | AM9: =[2]หน้าผ้า!DS18 -> #VALUE! | AN9: =[2]หน้าผ้า!DT18 -> #VALUE! | AO9: =[2]หน้าผ้า!DU18 -> #VALUE! | AP9: =[2]หน้าผ้า!DP18 -> #VALUE! | AQ9: =[2]หน้าผ้า!DW18 -> #VALUE! | AR9: =[2]หน้าผ้า!DX18 -> 0 | AS9: =[2]หน้าผ้า!DY18 -> 0 | AT9: =[2]หน้าผ้า!DZ18 -> 0 | AU9: =[2]หน้าผ้า!EA18 -> 0 | AV9: =[2]หน้าผ้า!EB18 -> 0 | AW9: =[2]หน้าผ้า!EC18 -> งานเคลือบ+พิมพ์ | AX9: =[2]หน้าผ้า!ED18 -> / | AY9: =[2]หน้าผ้า!AG18 -> ถุงในใช้ผสม กรีด 193340 193140 193370 | AZ9: =[2]หน้าผ้า!EG18 -> 0 | BA9: =[2]หน้าผ้า!EH18 -> 0 | BB9: =[2]หน้าผ้า!EI18 -> 0 | BC9: =[2]หน้าผ้า!BZ18 -> WRWT25800/WRWT25800 | BD9: =[2]หน้าผ้า!CA18 -> 0
A10: =[2]หน้าผ้า!C19 -> ประมาณการ | B10: =[2]หน้าผ้า!B19 -> ประมาณการ | C10: =[2]หน้าผ้า!E19 -> บจก.ซัน ซีเมนต์ โพรเซส | D10: =[2]หน้าผ้า!F19 -> พระอาทิตย์(ปูนนอน-ชริงค์) | E10: =[2]หน้าผ้า!G19 -> 16 | F10: =[2]หน้าผ้า!H19 -> 25 | G10: =[2]หน้าผ้า!I19 -> ขาว | H10: =[2]หน้าผ้า!J19 -> ใส | I10: =[2]หน้าผ้า!L19 -> 50 | J10: =[2]หน้าผ้า!M19 -> ± | K10: =[2]หน้าผ้า!N19 -> 5 | L10: =[2]หน้าผ้า!R19 -> บิด | M10: =[2]หน้าผ้า!T19 -> 19 | N10: =[2]หน้าผ้า!U19 -> 28 | O10: =[2]หน้าผ้า!V19 -> 40 | P10: =[2]หน้าผ้า!AB19 -> 65.624643 | Q10: =[2]หน้าผ้า!AC19 -> 0 | R10: =[2]หน้าผ้า!AD19 -> 65.624643 | S10: =[2]หน้าผ้า!Z19 -> 500กระสอบ | T10: =[2]หน้าผ้า!X19 -> รอแจ้ง | U10: =[2]หน้าผ้า!AA19 -> 5000 | V10: =[2]หน้าผ้า!AJ19 -> 0 | W10: =[2]หน้าผ้า!AL19 -> 5000 | X10: =[2]หน้าผ้า!AM19 -> 0 | Y10: =[2]หน้าผ้า!AN19 -> 5250 | Z10: =[2]หน้าผ้า!AO19 -> WSWT1625800SM | AA10: =[2]หน้าผ้า!AQ19 -> 3702.05 | AB10: =[2]หน้าผ้า!AR19 -> 3372 | AC10: =[2]หน้าผ้า!AS19 -> 330.05 | AD10: =[2]หน้าผ้า!AT19 -> 0 | AE10: =[2]หน้าผ้า!AU19 -> 3702.05 | AF10: =[2]หน้าผ้า!AI19 -> 0 | AG10: =[3]หน้าผ้า!DC22 -> ยังไม่ได้พิมพ์ | AH10: =[2]หน้าผ้า!DL19 -> P8 | AI10: =[2]หน้าผ้า!DM19 -> 4 | AJ10: =[2]หน้าผ้า!DN19 -> รอแจ้ง | AK10: =[2]หน้าผ้า!DQ19 -> #VALUE! | AL10: =[2]หน้าผ้า!DR19 -> #VALUE! | AM10: =[2]หน้าผ้า!DS19 -> #VALUE! | AN10: =[2]หน้าผ้า!DT19 -> #VALUE! | AO10: =[2]หน้าผ้า!DU19 -> #VALUE! | AP10: =[2]หน้าผ้า!DP19 -> #VALUE! | AQ10: =[2]หน้าผ้า!DW19 -> #VALUE! | AR10: =[2]หน้าผ้า!DX19 -> 0 | AS10: =[2]หน้าผ้า!DY19 -> 0 | AT10: =[2]หน้าผ้า!DZ19 -> 0 | AU10: =[2]หน้าผ้า!EA19 -> 0 | AV10: =[2]หน้าผ้า!EB19 -> 0 | AW10: =[2]หน้าผ้า!EC19 -> งานเคลือบ+พิมพ์ | AX10: =[2]หน้าผ้า!ED19 -> รอART | AY10: =[2]หน้าผ้า!AG19 -> 0 | AZ10: =[2]หน้าผ้า!EG19 -> 0 | BA10: =[2]หน้าผ้า!EH19 -> 0 | BB10: =[2]หน้าผ้า!EI19 -> 0 | BC10: =[2]หน้าผ้า!BZ19 -> WRWT25800/WRWT25800 | BD10: =[2]หน้าผ้า!CA19 -> 18.776178
A11: =[2]หน้าผ้า!C20 -> 0 | B11: =[2]หน้าผ้า!B20 -> 0 | C11: =[2]หน้าผ้า!E20 -> 0 | D11: =[2]หน้าผ้า!F20 | E11: =[2]หน้าผ้า!G20 -> 16 | F11: =[2]หน้าผ้า!H20 -> 25 | G11: =[2]หน้าผ้า!I20 -> ขาว | H11: =[2]หน้าผ้า!J20 -> 0 | I11: =[2]หน้าผ้า!L20 -> 45 | J11: =[2]หน้าผ้า!M20 -> ± | K11: =[2]หน้าผ้า!N20 -> 5 | L11: =[2]หน้าผ้า!R20 -> 0 | M11: =[2]หน้าผ้า!T20 -> 0 | N11: =[2]หน้าผ้า!U20 -> 0 | O11: =[2]หน้าผ้า!V20 -> 0 | P11: =[2]หน้าผ้า!AB20 -> 0 | Q11: =[2]หน้าผ้า!AC20 -> 0 | R11: =[2]หน้าผ้า!AD20 -> 0 | S11: =[2]หน้าผ้า!Z20 -> 0 | T11: =[2]หน้าผ้า!X20 -> 0 | U11: =[2]หน้าผ้า!AA20 -> 0 | V11: =[2]หน้าผ้า!AJ20 -> 0 | W11: =[2]หน้าผ้า!AL20 -> 0 | X11: =[2]หน้าผ้า!AM20 -> 0 | Y11: =[2]หน้าผ้า!AN20 -> 0 | Z11: =[2]หน้าผ้า!AO20 -> WSWT1625800SM | AA11: =[2]หน้าผ้า!AQ20 -> 3702.05 | AB11: =[2]หน้าผ้า!AR20 -> 3372 | AC11: =[2]หน้าผ้า!AS20 -> 330.05 | AD11: =[2]หน้าผ้า!AT20 -> 0 | AE11: =[2]หน้าผ้า!AU20 -> 3702.05 | AF11: =[2]หน้าผ้า!AI20 -> ระบุในSD | AG11: =[3]หน้าผ้า!DC23 -> พร้อมส่ง | AH11: =[2]หน้าผ้า!DL20 -> 0 | AI11: =[2]หน้าผ้า!DM20 -> Lead time | AJ11: =[2]หน้าผ้า!DN20 -> 0 | AK11: =[2]หน้าผ้า!DQ20 -> 0 | AL11: =[2]หน้าผ้า!DR20 -> 0 | AM11: =[2]หน้าผ้า!DS20 -> 0 | AN11: =[2]หน้าผ้า!DT20 -> 0 | AO11: =[2]หน้าผ้า!DU20 -> 0 | AP11: =[2]หน้าผ้า!DP20 -> 0 | AQ11: =[2]หน้าผ้า!DW20 -> 0 | AR11: =[2]หน้าผ้า!DX20 -> 0 | AS11: =[2]หน้าผ้า!DY20 -> 0 | AT11: =[2]หน้าผ้า!DZ20 -> 0 | AU11: =[2]หน้าผ้า!EA20 -> 0 | AV11: =[2]หน้าผ้า!EB20 -> 0 | AW11: =[2]หน้าผ้า!EC20 -> 0 | AX11: =[2]หน้าผ้า!ED20 -> 0 | AY11: =[2]หน้าผ้า!AG20 -> 0 | AZ11: =[2]หน้าผ้า!EG20 -> 0 | BA11: =[2]หน้าผ้า!EH20 -> 0 | BB11: =[2]หน้าผ้า!EI20 -> 0 | BC11: =[2]หน้าผ้า!BZ20 -> WRWT160800/WRWT25800 | BD11: =[2]หน้าผ้า!CA20 -> 0
A12: =[2]หน้าผ้า!C21 -> 45751 | B12: =[2]หน้าผ้า!B21 -> ใบรับคำสั่งซื้อ | C12: =[2]หน้าผ้า!E21 -> บจก.เคอรี่ฟลาวมิลล์ | D12: =[2]หน้าผ้า!F21 -> โบว์น้ำเงิน 10กก. | E12: =[2]หน้าผ้า!G21 -> 16 | F12: =[2]หน้าผ้า!H21 -> 25 | G12: =[2]หน้าผ้า!I21 -> ขาว | H12: =[2]หน้าผ้า!J21 -> 0 | I12: =[2]หน้าผ้า!L21 -> 45 | J12: =[2]หน้าผ้า!M21 -> ± | K12: =[2]หน้าผ้า!N21 -> 5 | L12: =[2]หน้าผ้า!R21 -> ไม่ | M12: =[2]หน้าผ้า!T21 -> ไม่สวมถุงใน | N12: =[2]หน้าผ้า!U21 -> 0 | O12: =[2]หน้าผ้า!V21 -> 0 | P12: =[2]หน้าผ้า!AB21 -> 0 | Q12: =[2]หน้าผ้า!AC21 -> 0 | R12: =[2]หน้าผ้า!AD21 -> 0 | S12: =[2]หน้าผ้า!Z21 -> ห่ออัดเบลแบน500 | T12: =[2]หน้าผ้า!X21 -> 45773 | U12: =[2]หน้าผ้า!AA21 -> 5000 | V12: =[2]หน้าผ้า!AJ21 -> 0 | W12: =[2]หน้าผ้า!AL21 -> 5000 | X12: =[2]หน้าผ้า!AM21 -> 0 | Y12: =[2]หน้าผ้า!AN21 -> 5250 | Z12: =[2]หน้าผ้า!AO21 -> WSWT1625800 | AA12: =[2]หน้าผ้า!AQ21 -> 3702.05 | AB12: =[2]หน้าผ้า!AR21 -> 3702.05 | AC12: =[2]หน้าผ้า!AS21 -> 0 | AD12: =[2]หน้าผ้า!AT21 -> 0 | AE12: =[2]หน้าผ้า!AU21 -> 0 | AF12: =[2]หน้าผ้า!AI21 -> PDR250117 | AG12: =[3]หน้าผ้า!DC24 -> ยังไม่ได้พิมพ์ | AH12: =[2]หน้าผ้า!DL21 -> P7 | AI12: =[2]หน้าผ้า!DM21 -> 2 | AJ12: =[2]หน้าผ้า!DN21 -> 45773 | AK12: =[2]หน้าผ้า!DQ21 -> 0 | AL12: =[2]หน้าผ้า!DR21 -> 45764 | AM12: =[2]หน้าผ้า!DS21 -> 45771 | AN12: =[2]หน้าผ้า!DT21 -> 45772 | AO12: =[2]หน้าผ้า!DU21 -> 45772 | AP12: =[2]หน้าผ้า!DP21 -> 45768 | AQ12: =[2]หน้าผ้า!DW21 -> 0 | AR12: =[2]หน้าผ้า!DX21 -> 0 | AS12: =[2]หน้าผ้า!DY21 -> 0 | AT12: =[2]หน้าผ้า!DZ21 -> 0 | AU12: =[2]หน้าผ้า!EA21 -> 0 | AV12: =[2]หน้าผ้า!EB21 -> 0 | AW12: =[2]หน้าผ้า!EC21 -> งานพิมพ์ | AX12: =[2]หน้าผ้า!ED21 -> รอART | AY12: =[2]หน้าผ้า!AG21 -> 0 | AZ12: =[2]หน้าผ้า!EG21 -> 0 | BA12: =[2]หน้าผ้า!EH21 -> 0 | BB12: =[2]หน้าผ้า!EI21 -> 0 | BC12: =[2]หน้าผ้า!BZ21 -> WRWT25800/WRWT25800 | BD12: =[2]หน้าผ้า!CA21 -> 0
A13: =[2]หน้าผ้า!C22 -> 45751 | B13: =[2]หน้าผ้า!B22 -> ใบรับคำสั่งซื้อ | C13: =[2]หน้าผ้า!E22 -> บจก.เคอรี่ฟลาวมิลล์ | D13: =[2]หน้าผ้า!F22 -> โบว์แดง 10กก. | E13: =[2]หน้าผ้า!G22 -> 16 | F13: =[2]หน้าผ้า!H22 -> 25 | G13: =[2]หน้าผ้า!I22 -> ขาว | H13: =[2]หน้าผ้า!J22 -> 0 | I13: =[2]หน้าผ้า!L22 -> 45 | J13: =[2]หน้าผ้า!M22 -> ± | K13: =[2]หน้าผ้า!N22 -> 5 | L13: =[2]หน้าผ้า!R22 -> ไม่ | M13: =[2]หน้าผ้า!T22 -> ไม่สวมถุงใน | N13: =[2]หน้าผ้า!U22 -> 0 | O13: =[2]หน้าผ้า!V22 -> 0 | P13: =[2]หน้าผ้า!AB22 -> 0 | Q13: =[2]หน้าผ้า!AC22 -> 0 | R13: =[2]หน้าผ้า!AD22 -> 0 | S13: =[2]หน้าผ้า!Z22 -> ห่ออัดเบลแบน500 | T13: =[2]หน้าผ้า!X22 -> 45773 | U13: =[2]หน้าผ้า!AA22 -> 5000 | V13: =[2]หน้าผ้า!AJ22 -> 0 | W13: =[2]หน้าผ้า!AL22 -> 5000 | X13: =[2]หน้าผ้า!AM22 -> 0 | Y13: =[2]หน้าผ้า!AN22 -> 5250 | Z13: =[2]หน้าผ้า!AO22 -> WSWT1625800 | AA13: =[2]หน้าผ้า!AQ22 -> 3702.05 | AB13: =[2]หน้าผ้า!AR22 -> 3702.05 | AC13: =[2]หน้าผ้า!AS22 -> 0 | AD13: =[2]หน้าผ้า!AT22 -> 0 | AE13: =[2]หน้าผ้า!AU22 -> 0 | AF13: =[2]หน้าผ้า!AI22 -> PDR250117 | AG13: =[3]หน้าผ้า!DC25 -> พร้อมส่ง | AH13: =[2]หน้าผ้า!DL22 -> P7 | AI13: =[2]หน้าผ้า!DM22 -> 2 | AJ13: =[2]หน้าผ้า!DN22 -> 45773 | AK13: =[2]หน้าผ้า!DQ22 -> 0 | AL13: =[2]หน้าผ้า!DR22 -> 45764 | AM13: =[2]หน้าผ้า!DS22 -> 45771 | AN13: =[2]หน้าผ้า!DT22 -> 45772 | AO13: =[2]หน้าผ้า!DU22 -> 45772 | AP13: =[2]หน้าผ้า!DP22 -> 45768 | AQ13: =[2]หน้าผ้า!DW22 -> 0 | AR13: =[2]หน้าผ้า!DX22 -> 0 | AS13: =[2]หน้าผ้า!DY22 -> 0 | AT13: =[2]หน้าผ้า!DZ22 -> 0 | AU13: =[2]หน้าผ้า!EA22 -> 0 | AV13: =[2]หน้าผ้า!EB22 -> 0 | AW13: =[2]หน้าผ้า!EC22 -> งานพิมพ์ | AX13: =[2]หน้าผ้า!ED22 -> รอART | AY13: =[2]หน้าผ้า!AG22 -> 0 | AZ13: =[2]หน้าผ้า!EG22 -> 0 | BA13: =[2]หน้าผ้า!EH22 -> 0 | BB13: =[2]หน้าผ้า!EI22 -> 0 | BC13: =[2]หน้าผ้า!BZ22 -> WRWT25800/WRWT25800 | BD13: =[2]หน้าผ้า!CA22 -> 0
A14: =[2]หน้าผ้า!C23 -> 0 | B14: =[2]หน้าผ้า!B23 -> 0 | C14: =[2]หน้าผ้า!E23 -> 0 | D14: =[2]หน้าผ้า!F23 -> 0 | E14: =[2]หน้าผ้า!G23 -> 16 | F14: =[2]หน้าผ้า!H23 -> 25 | G14: =[2]หน้าผ้า!I23 -> ขาว | H14: =[2]หน้าผ้า!J23 -> 0 | I14: =[2]หน้าผ้า!L23 -> 45 | J14: =[2]หน้าผ้า!M23 -> ± | K14: =[2]หน้าผ้า!N23 -> 5 | L14: =[2]หน้าผ้า!R23 -> 0 | M14: =[2]หน้าผ้า!T23 -> 0 | N14: =[2]หน้าผ้า!U23 -> 0 | O14: =[2]หน้าผ้า!V23 -> 0 | P14: =[2]หน้าผ้า!AB23 -> 0 | Q14: =[2]หน้าผ้า!AC23 -> 0 | R14: =[2]หน้าผ้า!AD23 -> 0 | S14: =[2]หน้าผ้า!Z23 -> 0 | T14: =[2]หน้าผ้า!X23 -> 0 | U14: =[2]หน้าผ้า!AA23 -> 0 | V14: =[2]หน้าผ้า!AJ23 -> 0 | W14: =[2]หน้าผ้า!AL23 -> 0 | X14: =[2]หน้าผ้า!AM23 -> 0 | Y14: =[2]หน้าผ้า!AN23 -> 0 | Z14: =[2]หน้าผ้า!AO23 -> WSWT1625800 | AA14: =[2]หน้าผ้า!AQ23 -> 7404.1 | AB14: =[2]หน้าผ้า!AR23 -> 7404.1 | AC14: =[2]หน้าผ้า!AS23 -> 0 | AD14: =[2]หน้าผ้า!AT23 -> 0 | AE14: =[2]หน้าผ้า!AU23 -> 0 | AF14: =[2]หน้าผ้า!AI23 -> ระบุในSD | AG14: =[3]หน้าผ้า!DC26 -> ยังไม่ได้พิมพ์ | AH14: =[2]หน้าผ้า!DL23 -> 0 | AI14: =[2]หน้าผ้า!DM23 -> Lead time | AJ14: =[2]หน้าผ้า!DN23 -> 0 | AK14: =[2]หน้าผ้า!DQ23 -> 0 | AL14: =[2]หน้าผ้า!DR23 -> 0 | AM14: =[2]หน้าผ้า!DS23 -> 0 | AN14: =[2]หน้าผ้า!DT23 -> 0 | AO14: =[2]หน้าผ้า!DU23 -> 0 | AP14: =[2]หน้าผ้า!DP23 -> 0 | AQ14: =[2]หน้าผ้า!DW23 -> 0 | AR14: =[2]หน้าผ้า!DX23 -> 0 | AS14: =[2]หน้าผ้า!DY23 -> 0 | AT14: =[2]หน้าผ้า!DZ23 -> 0 | AU14: =[2]หน้าผ้า!EA23 -> 0 | AV14: =[2]หน้าผ้า!EB23 -> 0 | AW14: =[2]หน้าผ้า!EC23 -> 0 | AX14: =[2]หน้าผ้า!ED23 -> 0 | AY14: =[2]หน้าผ้า!AG23 -> 0 | AZ14: =[2]หน้าผ้า!EG23 -> 0 | BA14: =[2]หน้าผ้า!EH23 -> 0 | BB14: =[2]หน้าผ้า!EI23 -> 0 | BC14: =[2]หน้าผ้า!BZ23 -> WRWT160800/WRWT25800 | BD14: =[2]หน้าผ้า!CA23 -> 0
A15: =[2]หน้าผ้า!C24 -> 45744 | B15: =[2]หน้าผ้า!B24 -> ใบรับคำสั่งซื้อ | C15: =[2]หน้าผ้า!E24 -> โรงสีธัญญกิจ(ราชบุรี) | D15: =[2]หน้าผ้า!F24 -> ราชสีห์(ข้าวหอมมะลิ) | E15: =[2]หน้าผ้า!G24 -> 16 | F15: =[2]หน้าผ้า!H24 -> 25 | G15: =[2]หน้าผ้า!I24 -> ขาว | H15: =[2]หน้าผ้า!J24 -> 0 | I15: =[2]หน้าผ้า!L24 -> 47 | J15: =[2]หน้าผ้า!M24 -> ± | K15: =[2]หน้าผ้า!N24 -> 5 | L15: =[2]หน้าผ้า!R24 -> ไม่ | M15: =[2]หน้าผ้า!T24 -> ไม่สวมถุงใน | N15: =[2]หน้าผ้า!U24 -> 0 | O15: =[2]หน้าผ้า!V24 -> 0 | P15: =[2]หน้าผ้า!AB24 -> 0 | Q15: =[2]หน้าผ้า!AC24 -> 0 | R15: =[2]หน้าผ้า!AD24 -> 0 | S15: =[2]หน้าผ้า!Z24 -> 500กระสอบ | T15: =[2]หน้าผ้า!X24 -> 45756 | U15: =[2]หน้าผ้า!AA24 -> 10000 | V15: =[2]หน้าผ้า!AJ24 -> 0 | W15: =[2]หน้าผ้า!AL24 -> 10000 | X15: =[2]หน้าผ้า!AM24 -> 0 | Y15: =[2]หน้าผ้า!AN24 -> 10500 | Z15: =[2]หน้าผ้า!AO24 -> WSWT1621720SMFX | AA15: =[2]หน้าผ้า!AQ24 -> 7404.1 | AB15: =[2]หน้าผ้า!AR24 -> 4589 | AC15: =[2]หน้าผ้า!AS24 -> 2815.1 | AD15: =[2]หน้าผ้า!AT24 -> 0 | AE15: =[2]หน้าผ้า!AU24 -> 0 | AF15: =[2]หน้าผ้า!AI24 -> 0 | AG15: =[3]หน้าผ้า!DC27 -> พร้อมส่ง | AH15: =[2]หน้าผ้า!DL24 -> P7 | AI15: =[2]หน้าผ้า!DM24 -> 2 | AJ15: =[2]หน้าผ้า!DN24 -> 45756 | AK15: =[2]หน้าผ้า!DQ24 -> 0 | AL15: =[2]หน้าผ้า!DR24 -> 45747 | AM15: =[2]หน้าผ้า!DS24 -> 45754 | AN15: =[2]หน้าผ้า!DT24 -> 45755 | AO15: =[2]หน้าผ้า!DU24 -> 45755 | AP15: =[2]หน้าผ้า!DP24 -> 45751 | AQ15: =[2]หน้าผ้า!DW24 -> 0 | AR15: =[2]หน้าผ้า!DX24 -> 0 | AS15: =[2]หน้าผ้า!DY24 -> 0 | AT15: =[2]หน้าผ้า!DZ24 -> 0 | AU15: =[2]หน้าผ้า!EA24 -> 0 | AV15: =[2]หน้าผ้า!EB24 -> 0 | AW15: =[2]หน้าผ้า!EC24 -> งานพิมพ์ | AX15: =[2]หน้าผ้า!ED24 -> รอART | AY15: =[2]หน้าผ้า!AG24 -> 0 | AZ15: =[2]หน้าผ้า!EG24 -> 0 | BA15: =[2]หน้าผ้า!EH24 -> 0 | BB15: =[2]หน้าผ้า!EI24 -> 0 | BC15: =[2]หน้าผ้า!BZ24 -> WRWT21720/WRWT21720 | BD15: =[2]หน้าผ้า!CA24 -> 167.55475
A16: =[2]หน้าผ้า!C25 -> 0 | B16: =[2]หน้าผ้า!B25 -> 0 | C16: =[2]หน้าผ้า!E25 -> 0 | D16: =[2]หน้าผ้า!F25 -> 0 | E16: =[2]หน้าผ้า!G25 -> 16 | F16: =[2]หน้าผ้า!H25 -> 25 | G16: =[2]หน้าผ้า!I25 -> 0 | H16: =[2]หน้าผ้า!J25 -> 0 | I16: =[2]หน้าผ้า!L25 -> 47 | J16: =[2]หน้าผ้า!M25 -> ± | K16: =[2]หน้าผ้า!N25 -> 5 | L16: =[2]หน้าผ้า!R25 -> 0 | M16: =[2]หน้าผ้า!T25 -> 0 | N16: =[2]หน้าผ้า!U25 -> 0 | O16: =[2]หน้าผ้า!V25 -> 0 | P16: =[2]หน้าผ้า!AB25 -> 0 | Q16: =[2]หน้าผ้า!AC25 -> 0 | R16: =[2]หน้าผ้า!AD25 -> 0 | S16: =[2]หน้าผ้า!Z25 -> 0 | T16: =[2]หน้าผ้า!X25 -> 0 | U16: =[2]หน้าผ้า!AA25 -> 0 | V16: =[2]หน้าผ้า!AJ25 -> 0 | W16: =[2]หน้าผ้า!AL25 -> 0 | X16: =[2]หน้าผ้า!AM25 -> 0 | Y16: =[2]หน้าผ้า!AN25 -> 0 | Z16: =[2]หน้าผ้า!AO25 -> WSWT1621720SMFX | AA16: =[2]หน้าผ้า!AQ25 -> 7404.1 | AB16: =[2]หน้าผ้า!AR25 -> 4589 | AC16: =[2]หน้าผ้า!AS25 -> 2815.1 | AD16: =[2]หน้าผ้า!AT25 -> 0 | AE16: =[2]หน้าผ้า!AU25 -> 0 | AF16: =[2]หน้าผ้า!AI25 -> ระบุในSD | AG16: =[3]หน้าผ้า!DC28 -> ยังไม่ได้พิมพ์ | AH16: =[2]หน้าผ้า!DL25 -> 0 | AI16: =[2]หน้าผ้า!DM25 -> 0 | AJ16: =[2]หน้าผ้า!DN25 -> 0 | AK16: =[2]หน้าผ้า!DQ25 -> 0 | AL16: =[2]หน้าผ้า!DR25 -> 0 | AM16: =[2]หน้าผ้า!DS25 -> 0 | AN16: =[2]หน้าผ้า!DT25 -> 0 | AO16: =[2]หน้าผ้า!DU25 -> 0 | AP16: =[2]หน้าผ้า!DP25 -> 0 | AQ16: =[2]หน้าผ้า!DW25 -> 0 | AR16: =[2]หน้าผ้า!DX25 -> 0 | AS16: =[2]หน้าผ้า!DY25 -> 0 | AT16: =[2]หน้าผ้า!DZ25 -> 0 | AU16: =[2]หน้าผ้า!EA25 -> 0 | AV16: =[2]หน้าผ้า!EB25 -> 0 | AW16: =[2]หน้าผ้า!EC25 -> 0 | AX16: =[2]หน้าผ้า!ED25 -> 0 | AY16: =[2]หน้าผ้า!AG25 -> 0 | AZ16: =[2]หน้าผ้า!EG25 -> 0 | BA16: =[2]หน้าผ้า!EH25 -> 0 | BB16: =[2]หน้าผ้า!EI25 -> 0 | BC16: =[2]หน้าผ้า!BZ25 -> WRWT160720/WRWT21720 | BD16: =[2]หน้าผ้า!CA25 -> 0
A17: =[2]หน้าผ้า!C26 -> ประมาณการ | B17: =[2]หน้าผ้า!B26 -> ประมาณการ | C17: =[2]หน้าผ้า!E26 -> บจก.ฟาร์เธอร์ส วิง ซัพพลาย | D17: =[2]หน้าผ้า!F26 -> รถไฟ | E17: =[2]หน้าผ้า!G26 -> 18 | F17: =[2]หน้าผ้า!H26 -> 30 | G17: =[2]หน้าผ้า!I26 -> ขาว | H17: =[2]หน้าผ้า!J26 -> 0 | I17: =[2]หน้าผ้า!L26 -> 54 | J17: =[2]หน้าผ้า!M26 -> ± | K17: =[2]หน้าผ้า!N26 -> 5 | L17: =[2]หน้าผ้า!R26 -> บิด | M17: =[2]หน้าผ้า!T26 -> 19 | N17: =[2]หน้าผ้า!U26 -> 33 | O17: =[2]หน้าผ้า!V26 -> 40 | P17: =[2]หน้าผ้า!AB26 -> 232.02999 | Q17: =[2]หน้าผ้า!AC26 -> 0 | R17: =[2]หน้าผ้า!AD26 -> 232.02999 | S17: =[2]หน้าผ้า!Z26 -> 500กระสอบ | T17: =[2]หน้าผ้า!X26 -> 45777 | U17: =[2]หน้าผ้า!AA26 -> 15000 | V17: =[2]หน้าผ้า!AJ26 -> 0 | W17: =[2]หน้าผ้า!AL26 -> 15000 | X17: =[2]หน้าผ้า!AM26 -> 0 | Y17: =[2]หน้าผ้า!AN26 -> 15750 | Z17: =[2]หน้าผ้า!AO26 -> WSWT1825800 | AA17: =[2]หน้าผ้า!AQ26 -> 13201.65 | AB17: =[2]หน้าผ้า!AR26 -> 12070 | AC17: =[2]หน้าผ้า!AS26 -> 1131.65 | AD17: =[2]หน้าผ้า!AT26 -> 0 | AE17: =[2]หน้าผ้า!AU26 -> 0 | AF17: =[2]หน้าผ้า!AI26 -> 0 | AG17: =[3]หน้าผ้า!DC29 -> ยังไม่ได้พิมพ์ | AH17: =[2]หน้าผ้า!DL26 -> P9 | AI17: =[2]หน้าผ้า!DM26 -> 3 | AJ17: =[2]หน้าผ้า!DN26 -> 45777 | AK17: =[2]หน้าผ้า!DQ26 -> 0 | AL17: =[2]หน้าผ้า!DR26 -> 45767 | AM17: =[2]หน้าผ้า!DS26 -> 45774 | AN17: =[2]หน้าผ้า!DT26 -> 45775 | AO17: =[2]หน้าผ้า!DU26 -> 45775 | AP17: =[2]หน้าผ้า!DP26 -> 45772 | AQ17: =[2]หน้าผ้า!DW26 -> 45776 | AR17: =[2]หน้าผ้า!DX26 -> 0 | AS17: =[2]หน้าผ้า!DY26 -> 0 | AT17: =[2]หน้าผ้า!DZ26 -> 0 | AU17: =[2]หน้าผ้า!EA26 -> 0 | AV17: =[2]หน้าผ้า!EB26 -> 0 | AW17: =[2]หน้าผ้า!EC26 -> งานพิมพ์ | AX17: =[2]หน้าผ้า!ED26 -> รอART | AY17: =[2]หน้าผ้า!AG26 -> 0 | AZ17: =[2]หน้าผ้า!EG26 -> 0 | BA17: =[2]หน้าผ้า!EH26 -> 0 | BB17: =[2]หน้าผ้า!EI26 -> 0 | BC17: =[2]หน้าผ้า!BZ26 -> WRWT25800/WRWT25800 | BD17: =[2]หน้าผ้า!CA26 -> 77.85752
... A574: =[2]หน้าผ้า!C583 -> 0 | B574: =[2]หน้าผ้า!B583 -> 0 | C574: =[2]หน้าผ้า!E583 -> 0 | D574: =[2]หน้าผ้า!F583 -> 0 | E574: =[2]หน้าผ้า!G583 -> 0 | F574: =[2]หน้าผ้า!H583 -> 0 | G574: =[2]หน้าผ้า!I583 -> 0 | H574: =[2]หน้าผ้า!J583 -> 0 | I574: =[2]หน้าผ้า!L583 -> 0 | J574: =[2]หน้าผ้า!M583 -> 0 | K574: =[2]หน้าผ้า!N583 -> 0 | L574: =[2]หน้าผ้า!R583 -> 0 | M574: =[2]หน้าผ้า!T583 -> 0 | N574: =[2]หน้าผ้า!U583 -> 0 | O574: =[2]หน้าผ้า!V583 -> 0 | P574: =[2]หน้าผ้า!AB583 -> 0 | Q574: =[2]หน้าผ้า!AC583 -> 0 | R574: =[2]หน้าผ้า!AD583 -> 0 | S574: =[2]หน้าผ้า!Z583 -> 0 | T574: =[2]หน้าผ้า!X583 -> 0 | U574: =[2]หน้าผ้า!AA583 -> 0 | V574: =[2]หน้าผ้า!AJ583 -> 0 | W574: =[2]หน้าผ้า!AL583 -> 0 | X574: =[2]หน้าผ้า!AM583 -> 0 | Y574: =[2]หน้าผ้า!AN583 -> 0 | Z574: =[2]หน้าผ้า!AO583 -> 0 | AA574: =[2]หน้าผ้า!AQ583 -> 0 | AB574: =[2]หน้าผ้า!AR583 -> 0 | AC574: =[2]หน้าผ้า!AS583 -> 0 | AD574: =[2]หน้าผ้า!AT583 -> 0 | AE574: =[2]หน้าผ้า!AU583 -> 0 | AF574: =[2]หน้าผ้า!AI583 -> 0 | AG574: =[3]หน้าผ้า!DC586 -> 0 | AH574: =[2]หน้าผ้า!DL583 -> 0 | AI574: =[2]หน้าผ้า!DM583 -> 0 | AJ574: =[2]หน้าผ้า!DN583 -> 0 | AK574: =[2]หน้าผ้า!DQ583 -> 0 | AL574: =[2]หน้าผ้า!DR583 -> 0 | AM574: =[2]หน้าผ้า!DS583 -> 0 | AN574: =[2]หน้าผ้า!DT583 -> 0 | AO574: =[2]หน้าผ้า!DU583 -> 0 | AP574: =[2]หน้าผ้า!DP583 -> 0 | AQ574: =[2]หน้าผ้า!DW583 -> 0 | AR574: =[2]หน้าผ้า!DX583 -> 0 | AS574: =[2]หน้าผ้า!DY583 -> 0 | AT574: =[2]หน้าผ้า!DZ583 -> 0 | AU574: =[2]หน้าผ้า!EA583 -> 0 | AV574: =[2]หน้าผ้า!EB583 -> 0 | AW574: =[2]หน้าผ้า!EC583 -> 0 | AX574: =[2]หน้าผ้า!ED583 -> 0 | AY574: =[2]หน้าผ้า!AG583 -> 0 | AZ574: =[2]หน้าผ้า!EG583 -> 0 | BA574: =[2]หน้าผ้า!EH583 -> 0 | BB574: =[2]หน้าผ้า!EI583 -> 0 | BC574: =[2]หน้าผ้า!BZ583 -> 0 | BD574: =[2]หน้าผ้า!CA583 -> 0

Sheet 3(Order+Fc) แยกลูกค้า
A1: เลขที่ SO | B1: (หลายรายการ)
A2: วันส่ง | B2: (หลายรายการ) | D2: 12 | I2: เมตร | J2: vn | K2: ใบ | P2: วัน
A4: ประเภท | B4: ชื่อลูกค้า | C4: ผลรวม ของ จำนวนส่ง | D4: ผลรวม ของ ค้างพิมพ์ | E4: ผลรวม ของ ค้างตัด | F4: ผลรวม ของ Stock | G4: ผลรวม ของ ใช้ | H4: ผลรวม ของ ค้างทอ
A5: WSWT1425800 | B5: หจก.ปึงเป้งน้ำ | C5: 10000 | D5: 10500 | E5: 10000 | F5: 4949 | G5: 6565.9 | H5: 1616.9 | I5: =H5 -> 1616.9
A6: WSWT1425800 ผลรวม | C6: 10000 | D6: 10500 | E6: 10000 | F6: 4949 | G6: 6565.9 | H6: 1616.9
A7: WSWT1625800 | B7: บจก.เคอรี่ฟลาวมิลล์ | C7: 5000 | D7: 5250 | E7: 5000 | F7: 2093 | G7: 3702.05 | H7: 1609.05 | I7: =H7 -> 1609.05
A8: WSWT1625800 ผลรวม | C8: 5000 | D8: 5250 | E8: 5000 | F8: 2093 | G8: 3702.05 | H8: 1609.05 | I8: =H8 -> 1609.05
A9: WSWT1921720 | B9: บจก.เคอรี่ฟลาวมิลล์ | C9: 195000 | D9: 141750 | E9: 195000 | F9: 13201.65 | G9: 164496.75 | H9: 151295.1 | I9: =H9 -> 151295.1
A10: WSWT1921720 ผลรวม | C10: 195000 | D10: 141750 | E10: 195000 | F10: 13201.65 | G10: 164496.75 | H10: 151295.1 | I10: =H10 -> 151295.1
A11: WSWT1925800 | B11: บจก.เพรซิเดนท์ฟลาวมิลล์ | C11: 100000 | D11: 105000 | E11: 100000 | F11: 88011 | G11: 88011 | H11: 0
B12: บจก.ซีแมน | C12: 50000 | D12: 52500 | E12: 50000 | F12: 4667 | G12: 41211.5 | H12: 36544.5 | I12: =H12 -> 36544.5
A13: WSWT1925800 ผลรวม | C13: 150000 | D13: 157500 | E13: 150000 | F13: 92678 | G13: 129222.5 | H13: 36544.5
A14: WSWT2025800 | B14: บจก.เคอรี่ฟลาวมิลล์ | C14: 10000 | D14: 10500 | E14: 10000 | F14: 0 | G14: 9359.9 | H14: 9359.9 | I14: =H14 -> 9359.9 | P14: 15000 | Q14: =+K14/P14 -> 0
B15: บจก.เบทาโกร | C15: 176000 | D15: 184800 | E15: 176000 | F15: 0 | G15: 189321.44 | H15: 189321.44
B16: บจก.อินเทคค์ โกลบอล | C16: 180000 | D16: 189000 | E16: 180000 | F16: 0 | G16: 188595 | H16: 188595 | I16: =H16 -> 188595
A17: WSWT2025800 ผลรวม | C17: 366000 | D17: 384300 | E17: 366000 | F17: 0 | G17: 387276.34 | H17: 387276.34 | I17: =H17 -> 387276.34
A18: WSWT2025800SM | B18: บจก.ซันฟีด | C18: 134500 | D18: 111766.2 | E18: 109264 | F18: 0 | G18: 117572.58 | H18: 117572.58 | I18: =H18 -> 117572.58
B19: บจก.อินเทคค์ โกลบอล | C19: 185040 | D19: 189000 | E19: 183840 | F19: 13645.5 | G19: 188595 | H19: 174949.5 | I19: =H19 -> 174949.5
B20: บจก.เอพีเอ็ม อะโกร | C20: 17500 | D20: 15821.4 | E20: 15068 | F20: 75.04684 | G20: 16797.137 | H20: 16722.09 | I20: =H20 -> 16722.09 | P20: 16000 | Q20: =+K20/P20 -> 0
B21: บจก.เอสพีเอ็ม อาหารสัตว์ | C21: 5000 | D21: 5250 | E21: 5000 | F21: 0 | G21: 5518.15 | H21: 5518.15
B22: บจก.วีซีเอฟ | C22: 30000 | D22: 31500 | E22: 30000 | F22: 0 | G22: 32270.7 | H22: 32270.7 | I22: =H22 -> 32270.7
B23: บจก.เอ.เจ.ฟาร์ม่าแล็บ | C23: 16000 | D23: 16800 | E23: 16000 | F23: 0 | G23: 15869.92 | H23: 15869.92
B24: คุณชายชล จันทร์สว่างกูล | C24: 1500 | D24: 1575 | E24: 1500 | F24: 0 | G24: 1487.805 | H24: 1487.805 | I24: =H24 -> 1487.805
A25: WSWT2025800SM ผลรวม | C25: 389540 | D25: 371712.6 | E25: 360672 | F25: 13720.547 | G25: 378111.29 | H25: 364390.75
A26: WSWT2025850 | B26: บจก.ซันฟีด | C26: 361000 | D26: 340473 | E26: 334872 | F26: 0 | G26: 357954.15 | H26: 357954.15 | I26: =H26 -> 357954.15
A27: WSWT2025850 ผลรวม | C27: 361000 | D27: 340473 | E27: 334872 | F27: 0 | G27: 357954.15 | H27: 357954.15
A28: WSWT2121670SM | B28: บจก.ที.ซี.ยูเนี่ยน อโกรเทค | C28: 48000 | D28: 48553.05 | E28: 46241 | F28: 0 | G28: 49740.981 | H28: 49740.981 | I28: =H28 -> 49740.981
B29: บจก.เอพีเอ็ม อะโกร | C29: 5000 | D29: 5250 | E29: 5000 | F29: 0 | G29: 5797.55 | H29: 5797.55 | I29: =H29 -> 5797.55
B30: บจก.แอมโก้เวท | C30: 20000 | D30: 21000 | E30: 20000 | F30: 0 | G30: 21513.8 | H30: 21513.8 | I30: =H30 -> 21513.8
B31: บจก.พี.เอส.อินเตอร์เวท | C31: 6000 | D31: 5250 | E31: 6000 | F31: 6398.26 | G31: 6398.26 | H31: 0 | P31: 15000 | Q31: =+K31/P31 -> 0
A32: WSWT2121670SM ผลรวม | C32: 79000 | D32: 80053.05 | E32: 77241 | F32: 6398.26 | G32: 83450.591 | H32: 77052.331 | I32: =H32 -> 77052.331
A33: WSWT2321112512551VN | B33: บจก.น้ำตาลทิพย์สุโขทัย | C33: 100000 | D33: 88281.9 | E33: 85837 | F33: 49306.403 | G33: 92498.637 | H33: 43192.234 | I33: =H33 -> 43192.234
A34: WSWT2321112512551VN ผลรวม | C34: 100000 | D34: 88281.9 | E34: 85837 | F34: 49306.403 | G34: 92498.637 | H34: 43192.234 | I34: =H34 -> 43192.234
A35: WSWT2321750 | B35: คุณวัลภา เผ่าเต้ม | C35: 10000 | D35: 10500 | E35: 10000 | F35: 5633 | G35: 10756.9 | H35: 5123.9 | I35: =H35 -> 5123.9
A36: WSWT2321750 ผลรวม | C36: 10000 | D36: 10500 | E36: 10000 | F36: 5633 | G36: 10756.9 | H36: 5123.9 | I36: =H36 -> 5123.9
A37: WSWT2325650 | B37: บจก.ซิเบลโก้(สบปราบ) | C37: 30000 | D37: 31500 | E37: 30000 | F37: 13938.7 | G37: 29756.1 | H37: 15817.4 | I37: =H37 -> 15817.4
B38: ร้าน.ส.กิจเจริญพันธุ์ข้าว | C38: 2000 | D38: 0 | E38: 2000 | F38: 0 | G38: 1983.74 | H38: 1983.74 | I38: =H38 -> 1983.74
A39: WSWT2325650 ผลรวม | C39: 32000 | D39: 31500 | E39: 32000 | F39: 13938.7 | G39: 31739.84 | H39: 17801.14 | I39: =H39 -> 17801.14
A40: WSWT2625850SM | B40: บจก.ที.ซี.ยูเนี่ยน อโกรเทค | C40: 18000 | D40: 18900 | E40: 18000 | F40: 22379.94 | G40: 22379.94 | H40: 0 | I40: =H40 -> 0
A41: WSWT2625850SM ผลรวม | C41: 18000 | D41: 18900 | E41: 18000 | F41: 22379.94 | G41: 22379.94 | H41: 0
...

Sheet 5(Order)
A2: เลขที่ SO | B2: (หลายรายการ)
A3: วันส่ง | B3: รอแจ้ง
A4: ชื่อลูกค้า | B4: (ทั้งหมด)
A6: ประเภท | B6: ผลรวม ของ จำนวนส่ง | C6: ผลรวม ของ ค้างพิมพ์ | D6: ผลรวม ของ ค้างตัด | E6: ผลรวม ของ Stock | F6: ผลรวม ของ ใช้ | G6: ผลรวม ของ ค้างทอ
A7: WSWT19251000SM | B7: 400 | C7: 0 | D7: 400 | E7: 0 | F7: 0 | G7: 0
A8: WSWT2025800SM | B8: 32862 | C8: 25200 | D8: 32795 | E8: 0 | F8: 26654.76 | G8: 26654.76
A9: WSWT2121670SM | B9: 59000 | C9: 61950 | D9: 59000 | E9: 43530.52 | F9: 64499.49 | G9: 20968.97
A10: WSWT2321112512551 | B10: 106278 | C10: 111591.9 | D10: 106278 | E10: 0 | F10: 114322.18 | G10: 114322.18
A11: WSWT2321750 | B11: 1000 | C11: 0 | D11: 1000 | E11: 0 | F11: 1159.51 | G11: 1159.51
A12: WSWT2625650 | B12: 4000 | C12: 4200 | D12: 4000 | E12: 0 | F12: 4749.8 | G12: 4749.8
A13: ผลรวมทั้งหมด | B13: 203540 | C13: 202941.9 | D13: 203473 | E13: 43530.52 | F13: 211385.74 | G13: 167855.22
A37: ยอดส่ง 1/1/68 - 17/1/68 | B37: 1287052
A38: Order+ส่ง | B38: =++B22+B37 -> 1287052
A39: ประมาณการ | I39: 0
A41: Order+ส่ง+ประมาณการ | B41: =+B22+B37+B39+B29 -> 1287052 | C41: =+C22+C37+C39+C29 -> 0 | D41: =+D22+D37+D39+D29 -> 0 | E41: =+E22+E37+E39+E29 -> 0 | F41: =+F22+F37+F39+F29 -> 0 | G41: =+G22+G37+G39+G29 -> 0
B43: 3000000 | I43: 9
B45: =+B41-B43 -> -1712948
D46: =+D22/I43 -> 0
C47: =+C41/I43 -> 0 | D47: =+D41/I43 -> 0 | G47: =+G41/I43 -> 0

Sheet 3(Order) แยกลูกค้า
A1: เลขที่ SO | B1: (หลายรายการ)
A2: วันส่ง | B2: รอแจ้ง
A4: ประเภท | B4: ชื่อลูกค้า | C4: ผลรวม ของ จำนวนส่ง | D4: ผลรวม ของ ค้างพิมพ์ | E4: ผลรวม ของ ค้างตัด | F4: ผลรวม ของ Stock | G4: ผลรวม ของ ค้างทอ | I4: vn
A5: WSWT1625800SM | B5: บจก.ซัน ซีเมนต์ โพรเซส | C5: 5000 | D5: 5250 | E5: 5000 | F5: 3702.05 | G5: 0 | H5: =G5 -> 0
A6: WSWT1625800SM ผลรวม | C6: 5000 | D6: 5250 | E6: 5000 | F6: 3702.05 | G6: 0 | H6: =G6 -> 0
A7: WSWT19251000SM | B7: บจก.อินเทคค์ โกลบอล | C7: 248 | D7: 0 | E7: 248 | F7: 0 | G7: 0 | H7: =G7 -> 0
A8: WSWT19251000SM ผลรวม | C8: 248 | D8: 0 | E8: 248 | F8: 0 | G8: 0
A9: WSWT2025800SM | B9: บจก.อินเทคค์ โกลบอล | C9: 10187 | D9: 0 | E9: 10187 | F9: 0 | G9: 0 | H9: =G9 -> 0
B10: บจก.เอพีเอ็ม อะโกร | C10: 5000 | D10: 5250 | E10: 5000 | F10: 0 | G10: 5518.15 | H10: =G10 -> 5518.15
A11: WSWT2025800SM ผลรวม | C11: 15187 | D11: 5250 | E11: 15187 | F11: 0 | G11: 5518.15
A12: WSWT2121670SM | B12: บจก.เอพีเอ็ม อะโกร | C12: 14000 | D12: 14700 | E12: 14000 | F12: 0 | G12: 15450.82 | H12: =G12 -> 15450.82
B13: บจก.เอสพีเอ็ม อาหารสัตว์ | C13: 5000 | D13: 5250 | E13: 5000 | F13: 5518.15 | G13: 0 | H13: =G13 -> 0
A14: WSWT2121670SM ผลรวม | C14: 19000 | D14: 19950 | E14: 19000 | F14: 5518.15 | G14: 15450.82 | H14: =G14 -> 15450.82
A15: WSWT2321112512551VN | B15: บจก.น้ำตาลทิพย์สุโขทัย | C15: 126278 | D15: 132591.9 | E15: 126278 | F15: 0 | G15: 135835.98
A16: WSWT2321112512551VN ผลรวม | C16: 126278 | D16: 132591.9 | E16: 126278 | F16: 0 | G16: 135835.98 | H16: =G16 -> 135835.98
A17: WSWT2625850SM | B17: บจก.ที.ซี.ยูเนี่ยน อโกรเทค | C17: 1300 | D17: 0 | E17: 1300 | F17: 0 | G17: 0
A18: WSWT2625850SM ผลรวม | C18: 1300 | D18: 0 | E18: 1300 | F18: 0 | G18: 0 | H18: =G18 -> 0
A19: ผลรวมทั้งหมด | C19: 167013 | D19: 163041.9 | E19: 167013 | F19: 9220.2 | G19: 156804.95 | H19: =G19 -> 156804.95
H20: =G20 -> 0
H21: =G21 -> 0
H23: =G23 -> 0
H25: =G25 -> 0
H27: =G27 -> 0
H28: =G28 -> 0
H29: =G29 -> 0
H31: =G31 -> 0
H32: =G32 -> 0
H33: =G33 -> 0
H34: =G34 -> 0
H35: =G35 -> 0
... H68: =G68 -> 0
H70: =SUM(H5:H69) -> 329060.72
D119: Cap พิมพ์ | E119: Cap ตัด | F119: Stock 16/7 บ่าย | G119: Cap ทอ | I119: วันทงาน
B120: lส่ง | C120: 1-16/7 | D120: 160000 | E120: 160000 | G120: 120000 | I120: 12
C121: 1975256 | D121: =+D120*I120 -> 1920000 | E121: =+E120*I120 -> 1920000 | F121: 825147 | G121: =+G120*I120 -> 1440000
A122: เบทาโกรส่งแล้ว | B122: 20700 | C122: 424374
A123: เบทาโกรส่งแล้ว | B123: 20800 | C123: 155973
C126: รวมส่ง+ค้างส่ง | D126: ส่วนต่างCapคงเหลือ | E126: ส่วนต่างCapคงเหลือ | F126: คงเหลือ
C127: =+C50+C121 -> 1975256 | D127: =+D121-D50 -> 1920000 | E127: =+E121-E50 -> 1920000 | F127: =+F121-F50 -> 825147 | G127: =+G121-G50 -> 1440000
B129: 20700VN 20/7 | G129: 350000

Sheet 3(Fc) แยกลูกค้
A1: เลขที่ SO | B1: ประมาณการ
A2: วันส่ง | B2: รอแจ้ง | D2: 12
A4: ประเภท | B4: ชื่อลูกค้า | C4: ผลรวม ของ จำนวนส่ง | D4: ผลรวม ของ ค้างพิมพ์ | E4: ผลรวม ของ ค้างตัด | F4: ผลรวม ของ Stock | G4: ผลรวม ของ ใช้ | H4: ผลรวม ของ ค้างทอ
A5: WSWT1921720 | B5: บจก.เคอรี่ฟลาวมิลล์ | C5: 300000 | D5: 315000 | E5: 300000 | F5: 0 | G5: 264033 | H5: 264033
A6: WSWT1921720 ผลรวม | C6: 300000 | D6: 315000 | E6: 300000 | F6: 0 | G6: 264033 | H6: 264033
A7: WSWT1925800SM | B7: บจก.เอเชี่ยนเคมิคัล | C7: 30000 | D7: 31500 | E7: 30000 | F7: 13045.25 | G7: 23050.5 | H7: 10005.25
A8: WSWT1925800SM ผลรวม | C8: 30000 | D8: 31500 | E8: 30000 | F8: 13045.25 | G8: 23050.5 | H8: 10005.25
A9: WSWT2025650 | B9: บจก.หนองบัวฟีดมิลล์ | C9: 10000 | D9: 0 | E9: 10000 | F9: 8801.1 | G9: 8801.1 | H9: 0
A10: WSWT2025650 ผลรวม | C10: 10000 | D10: 0 | E10: 10000 | F10: 8801.1 | G10: 8801.1 | H10: 0
A11: WSWT2025800 | B11: บจก.อินเทคค์ โกลบอล | C11: 30000 | D11: 31500 | E11: 30000 | F11: 0 | G11: 31432.5 | H11: 31432.5
A12: WSWT2025800 ผลรวม | C12: 30000 | D12: 31500 | E12: 30000 | F12: 0 | G12: 31432.5 | H12: 31432.5
A13: WSWT2025800SM | B13: บจก.ไทยธรรมดี | C13: 20000 | D13: 21000 | E13: 20000 | F13: 0 | G13: 21513.8 | H13: 21513.8
B14: บจก.วีซีเอฟ | C14: 40000 | D14: 42000 | E14: 40000 | F14: 0 | G14: 43027.6 | H14: 43027.6
A15: WSWT2025800SM ผลรวม | C15: 60000 | D15: 63000 | E15: 60000 | F15: 0 | G15: 64541.4 | H15: 64541.4
A16: WSWT2121670SM | B16: บจก.ที.ซี.ยูเนี่ยน อโกรเทค | C16: 10000 | D16: 10500 | E16: 10000 | F16: 0 | G16: 10756.9 | H16: 10756.9
B17: บจก.แอมโก้เวท | C17: 40000 | D17: 0 | E17: 40000 | F17: 43027.6 | G17: 43027.6 | H17: 0
A18: WSWT2121670SM ผลรวม | C18: 50000 | D18: 10500 | E18: 50000 | F18: 43027.6 | G18: 53784.5 | H18: 10756.9
A19: WSWT2125650 | B19: บจก.หนองบัวฟีดมิลล์ | C19: 10000 | D19: 0 | E19: 10000 | F19: 10000.15 | G19: 11036.3 | H19: 1036.15
A20: WSWT2125650 ผลรวม | C20: 10000 | D20: 0 | E20: 10000 | F20: 10000.15 | G20: 11036.3 | H20: 1036.15
A21: WSWT2325650 | B21: บจก.ซิเบลโก้ | C21: 20000 | D21: 21000 | E21: 20000 | F21: 0 | G21: 19837.4 | H21: 19837.4
B22: พันธุ์ข้าว | C22: 10000 | D22: 10500 | E22: 10000 | F22: 0 | G22: 9918.7 | H22: 9918.7
A23: WSWT2325650 ผลรวม | C23: 30000 | D23: 31500 | E23: 30000 | F23: 0 | G23: 29756.1 | H23: 29756.1
A24: WSWT2625650 | B24: บจก.โอเชี่ยนฟีด | C24: 60000 | D24: 0 | E24: 60000 | F24: 2000 | G24: 72923.4 | H24: 70923.4
B25: บจก.กบินทร์อินทรีย์ | C25: 20000 | D25: 21000 | E25: 20000 | F25: 11874.5 | G25: 23749 | H25: 11874.5
B26: คุณธนนท์ อุทัยไพศาลวงศ์ | C26: 10000 | D26: 0 | E26: 10000 | F26: 0 | G26: 11315.7 | H26: 11315.7
A27: WSWT2625650 ผลรวม | C27: 90000 | D27: 21000 | E27: 90000 | F27: 13874.5 | G27: 107988.1 | H27: 94113.6
A28: WSWT2625800 | B28: บจก.ที.ซี.ยูเนี่ยน อโกรเทค | C28: 30000 | D28: 0 | E28: 30000 | F28: 8418 | G28: 37299.9 | H28: 28881.9
A29: WSWT2625800 ผลรวม | C29: 30000 | D29: 0 | E29: 30000 | F29: 8418 | G29: 37299.9 | H29: 28881.9
A30: WSWT2625850SM | B30: บจก.ที.ซี.ยูเนี่ยน อโกรเทค | C30: 20000 | D30: 21000 | E30: 20000 | F30: 2620 | G30: 24866.6 | H30: 22246.6
A31: WSWT2625850SM ผลรวม | C31: 20000 | D31: 21000 | E31: 20000 | F31: 2620 | G31: 24866.6 | H31: 22246.6
A32: ผลรวมทั้งหมด | C32: 660000 | D32: 525000 | E32: 660000 | F32: 99786.6 | G32: 656590 | H32: 556803.4
D119: Cap พิมพ์ | E119: Cap ตัด | F119: Stock 16/7 บ่าย | G119: Cap ทอ | I119: วันทงาน
B120: lส่ง | C120: 1-16/7 | D120: 160000 | E120: 160000 | G120: 120000 | I120: 12
C121: 1975256 | D121: =+D120*I120 -> 1920000 | E121: =+E120*I120 -> 1920000 | F121: 825147 | G121: =+G120*I120 -> 1440000
A122: เบทาโกรส่งแล้ว | B122: 20700 | C122: 424374
A123: เบทาโกรส่งแล้ว | B123: 20800 | C123: 155973
C126: รวมส่ง+ค้างส่ง | D126: ส่วนต่างCapคงเหลือ | E126: ส่วนต่างCapคงเหลือ | F126: คงเหลือ
C127: =+C50+C121 -> 1975256 | D127: =+D121-D50 -> 1920000 | E127: =+E121-E50 -> 1920000 | F127: =+F121-F50 -> 825147 | G127: =+G121-G50 -> 1440000
B129: 20700VN 20/7 | G129: 350000

Sheet 4(Order+FC) (-4)
A2: เลขที่ SO | B2: (หลายรายการ)
A3: วันส่ง | B3: รอแจ้ง
A4: ชื่อลูกค้า | B4: (ทั้งหมด)
A6: ประเภท | B6: ผลรวม ของ จำนวนส่ง | C6: ผลรวม ของ ค้างพิมพ์ | D6: ผลรวม ของ ค้างตัด | E6: ผลรวม ของ Stock | F6: ผลรวม ของ ใช้ | G6: ผลรวม ของ ค้างทอ
A7: WSWT1625800SM | B7: 5000 | C7: 5250 | D7: 5000 | E7: 3372 | F7: 3702.05 | G7: 330.05 | H7: =+J7-I7 -> 330.05 | J7: =G7 -> 330.05
A8: WSWT2025700 | B8: 50000 | C8: 0 | D8: 50000 | E8: 14387 | F8: 55181.5 | G8: 40794.5 | H8: =+J8-I8 -> 40794.5 | J8: =G8 -> 40794.5
A9: WSWT2025800SM | B9: 48439 | C9: 45150 | D9: 48372 | E9: 0 | F9: 46506.13 | G9: 46506.13 | H9: =+J9-I9 -> 46506.13 | J9: =G9 -> 46506.13
A10: WSWT2121670SM | B10: 61000 | C10: 64050 | D10: 61000 | E10: 34422.08 | F10: 66147.95 | G10: 31725.87 | H10: =+J10-I10 -> 31725.87 | J10: =G10 -> 31725.87
A11: WSWT2321112512551 | B11: 106278 | C11: 111591.9 | D11: 106278 | E11: 0 | F11: 114322.18 | G11: 114322.18 | H11: =+J11-I11 -> 114322.18 | J11: =G11 -> 114322.18
A12: WSWT2625650 | B12: 50000 | C12: 10500 | D12: 50000 | E12: 0 | F12: 60490.1 | G12: 60490.1 | H12: =+J12-I12 -> 60490.1 | J12: =G12 -> 60490.1
A13: WSWT2625800 | B13: 20000 | C13: 0 | D13: 20000 | E13: 0 | F13: 24866.6 | G13: 24866.6 | H13: =+J13-I13 -> 24866.6 | J13: =G13 -> 24866.6
A14: ผลรวมทั้งหมด | B14: 340717 | C14: 236541.9 | D14: 340650 | E14: 52181.08 | F14: 371216.51 | G14: 319035.43 | H14: =+J14-I14 -> 319035.43 | J14: =G14 -> 319035.43
H15: =+J15-I15 -> 0 | J15: =G15 -> 0
H16: =+J16-I16 -> 0 | J16: =G16 -> 0
H17: 0 | I17: 160000 | J17: =G17 -> 0
H18: =+J18-I18 -> 0 | J18: =G18 -> 0
H19: =+J19-I19 -> 0 | J19: =G19 -> 0
H20: =+J20-I20 -> 0 | J20: =G20 -> 0
H21: =+J21-I21 -> 0 | J21: =G21 -> 0
H22: =+J22-I22 -> 0 | J22: =G22 -> 0
H23: =+J23-I23 -> 0 | J23: =G23 -> 0
H24: =+J24-I24 -> 0 | J24: =G24 -> 0
H25: =+J25-I25 -> 0 | J25: =G25 -> 0
H27: =SUM(H8:H25) -> 637740.81 | J27: =SUM(J8:J25) -> 637740.81
M28: =+GETPIVOTDATA("ผลรวม ของ ใช้",$A$6)+H29+H31 -> 461216.51
H30: =+H27 -> 637740.81
A31: กรม | B31: 70000 | C31: 70000 | D31: 70000 | G31: 90000 | H31: 90000 | I31: 95 | J31: =+H31*I31 -> 8550000 | K31: =+J31/1000 -> 8550
G33: 160000 | H33: =+H29+H30 -> 637740.81 | I33: 85 | J33: =+H33*I33 -> 54207969 | K33: =+J33/1000 -> 54207.969
H34: =+H30+H31+H29 -> 727740.81
H35: 15 | I35: =+H34/H35 -> 48516.054 | K35: =+K33+K31 -> 62757.969
N36: 705222
A37: ยอดส่ง 1/2/68 - 10/2/68 | B37: 817879 | I37: =+H35*100000 -> 1500000
N38: =+H34+N36 -> 1432962.8
H39: 16 | I39: =+H39*90000 -> 1440000
B41: =+B26+B37+B31 -> 887879 | C41: =+C26+C37+C31 -> 70000 | D41: =+D26+D37+D31 -> 70000 | E41: =+E26+E37+E31 -> 0 | F41: =+F26+F37+F31 -> 0
B43: 2992955
B45: =+B43-B41 -> 2105076 | C45: =+C32+($B$45*1) -> 2105076 | D45: =+D32+($B$45*1) -> 2105076 | E45: =+E31+($B$45*1) -> 2105076 | F45: =+F30+($B$45*1) -> 2105076 | G45: =+G30+($B$45*1) -> 2105076
C47: =+C41/13 -> 5384.6154 | D47: =+D41/15 -> 4666.6667
B49: 16 | C49: 135000 | D49: 135000
C50: =+B49*C49 -> 2160000 | D50: =+B49*D49 -> 2160000
...

Sheet 4(Order+FC) (-5)
A3: เลขที่ SO | B3: (หลายรายการ)
A4: วันส่ง | B4: (หลายรายการ)
A6: ประเภท | B6: ชื่อลูกค้า | C6: ผลรวม ของ จำนวนส่ง | D6: ผลรวม ของ ค้างพิมพ์ | E6: ผลรวม ของ ค้างตัด | F6: ผลรวม ของ ใช้ | G6: ผลรวม ของ Stock | H6: ผลรวม ของ ค้างทอ
A7: WSWT1425800 | B7: บจก.ปึงเป้งน้ำ | C7: 10000 | D7: 10500 | E7: 10000 | F7: 6565.9 | G7: 6565.9 | H7: 0 | J7: =G7 -> 6565.9
A8: WSWT1425800 ผลรวม | C8: 10000 | D8: 10500 | E8: 10000 | F8: 6565.9 | G8: 6565.9 | H8: 0 | J8: =G8 -> 6565.9
A9: WSWT1621720SMFX | B9: โรงสีธัญญกิจ(ราชบุรี) | C9: 10000 | D9: 10500 | E9: 10000 | F9: 7404.1 | G9: 4589 | H9: 2815.1 | J9: =G9 -> 4589
A10: WSWT1621720SMFX ผลรวม | C10: 10000 | D10: 10500 | E10: 10000 | F10: 7404.1 | G10: 4589 | H10: 2815.1 | J10: =G10 -> 4589
A11: WSWT1625800 | B11: บจก.เคอรี่ฟลาวมิลล์ | C11: 10000 | D11: 10500 | E11: 10000 | F11: 7404.1 | G11: 7404.1 | H11: 0 | J11: =G11 -> 7404.1
A12: WSWT1625800 ผลรวม | C12: 10000 | D12: 10500 | E12: 10000 | F12: 7404.1 | G12: 7404.1 | H12: 0 | J12: =G12 -> 7404.1
A13: WSWT1825800 | B13: บจก.ฟาร์เธอร์ส วิง ซัพพลาย | C13: 15000 | D13: 15750 | E13: 15000 | F13: 13201.65 | G13: 12070 | H13: 1131.65 | J13: =G13 -> 12070
A14: WSWT1825800 ผลรวม | C14: 15000 | D14: 15750 | E14: 15000 | F14: 13201.65 | G14: 12070 | H14: 1131.65 | J14: =G14 -> 12070
A15: WSWT1825800SM | B15: บจก.2เอ็ม อโกรเท็ค | C15: 10000 | D15: 10500 | E15: 10000 | F15: 8801.1 | G15: 0 | H15: 8801.1 | J15: =G15 -> 0
A16: WSWT1825800SM ผลรวม | C16: 10000 | D16: 10500 | E16: 10000 | F16: 8801.1 | G16: 0 | H16: 8801.1 | J16: =G16 -> 0
A17: WSWT1921720 | B17: บจก.เคอรี่ฟลาวมิลล์ | C17: 550000 | D17: 498750 | E17: 545000 | F17: 464292.95 | G17: 7603.75 | H17: 456689.2 | J17: =G17 -> 7603.75
A18: WSWT1921720 ผลรวม | C18: 550000 | D18: 498750 | E18: 545000 | F18: 464292.95 | G18: 7603.75 | H18: 456689.2 | I18: =54000+106000 -> 160000 | J18: =G18 -> 7603.75
A19: WSWT19251000SM | B19: บจก.อินเทคค์ โกลบอล | C19: 10080 | D19: 10584 | E19: 10080 | F19: 9998.0496 | G19: 8000.0248 | H19: 1998.0248 | J19: =G19 -> 8000.0248
A20: WSWT19251000SM ผลรวม | C20: 10080 | D20: 10584 | E20: 10080 | F20: 9998.0496 | G20: 8000.0248 | H20: 1998.0248 | J20: =G20 -> 8000.0248
A21: WSWT1925800 | B21: บจก.เพรซิเดนท์ฟลาวมิลล์ | C21: 120000 | D21: 126000 | E21: 120000 | F21: 105613.2 | G21: 0 | H21: 105613.2 | J21: =G21 -> 0
B22: บจก.ซีแมน | C22: 60000 | D22: 29400 | E22: 60000 | F22: 23408.132 | G22: 6923.532 | H22: 16484.6 | J22: =G22 -> 6923.532
B23: บจก.เอ็กเซลเล้นท์ | C23: 30000 | D23: 31500 | E23: 30000 | F23: 26403.3 | G23: 0 | H23: 26403.3 | J23: =G23 -> 0
A24: WSWT1925800 ผลรวม | C24: 210000 | D24: 186900 | E24: 210000 | F24: 155424.63 | G24: 6923.532 | H24: 148501.1 | J24: =G24 -> 6923.532
A25: WSWT1925800SM | B25: บจก.เอเชี่ยนเคมิคัล | C25: 10000 | D25: 10500 | E25: 10000 | F25: 7683.5 | G25: 7683.5 | H25: 0 | J25: =G25 -> 7683.5
A26: WSWT1925800SM ผลรวม | C26: 10000 | D26: 10500 | E26: 10000 | F26: 7683.5 | G26: 7683.5 | H26: 0 | J26: =G26 -> 7683.5
A27: WSWT2025650 | B27: บจก.หนองบัวฟีดมิลล์ | C27: 5000 | D27: 0 | E27: 5000 | F27: 4400.55 | G27: 0 | H27: 4400.55 | J27: =G27 -> 0
A28: WSWT2025650 ผลรวม | C28: 5000 | D28: 0 | E28: 5000 | F28: 4400.55 | G28: 0 | H28: 4400.55 | I28: =SUM(I9:I27) -> 160000 | J28: =SUM(J9:J27) -> 108547.81 | M28: =+GETPIVOTDATA("ผลรวม ของ ใช้",$A$6)+H29+H31 -> 2252602.2
A29: WSWT2025800 | B29: บจก.เคอรี่ฟลาวมิลล์ | C29: 10000 | D29: 5250 | E29: 5000 | F29: 4679.95 | G29: 0 | H29: 4679.95
B30: บจก.เบทาโกร | C30: 509000 | D30: 501488.4 | E30: 499143 | F30: 514758.97 | G30: 9000 | H30: 505758.97
B31: บจก.อินเทคค์ โกลบอล | C31: 50000 | D31: 29465.1 | E31: 50000 | F31: 30872.059 | G31: 0 | H31: 30872.059 | I31: 95 | J31: =+H31*I31 -> 2932845.6 | K31: =+J31/1000 -> 2932.8456
A32: WSWT2025800 ผลรวม | C32: 569000 | D32: 536203.5 | E32: 554143 | F32: 550310.98 | G32: 9000 | H32: 541310.98
A33: WSWT2025800SM | B33: บจก.อินเทคค์ โกลบอล | C33: 148841 | D33: 148187.55 | E33: 143801 | F33: 147870.01 | G33: 8000 | H33: 139870.01 | I33: 85 | J33: =+H33*I33 -> 11888950 | K33: =+J33/1000 -> 11888.95
B34: บจก.เอพีเอ็ม อะโกร | C34: 25000 | D34: 14700 | E34: 25000 | F34: 15450.82 | G34: 2000 | H34: 13450.82
B35: บจก.เอสพีเอ็ม อาหารสัตว์ | C35: 8000 | D35: 8400 | E35: 8000 | F35: 8745.22 | G35: 0 | H35: 8745.22 | I35: =+H34/H35 -> 1.5380768 | K35: =+K33+K31 -> 14821.796
B36: บจก.วีซีเอฟ | C36: 80000 | D36: 73500 | E36: 80000 | F36: 75298.3 | G36: 5378.45 | H36: 69919.85 | N36: 705222
A37: WSWT2025800SM ผลรวม | C37: 261841 | D37: 244787.55 | E37: 256801 | F37: 247364.35 | G37: 15378.45 | H37: 231985.9 | I37: =+H35*100000 -> 8.74522e+08
A38: WSWT2121670SM | B38: บจก.ที.ซี.ยูเนี่ยน อโกรเทค | C38: 36000 | D38: 37800 | E38: 36000 | F38: 38724.84 | G38: 17211.04 | H38: 21513.8 | N38: =+H34+N36 -> 718672.82
B39: บจก.เอพีเอ็ม อะโกร | C39: 5000 | D39: 0 | E39: 19 | F39: 0 | G39: 0 | H39: 0 | I39: =+H39*90000 -> 0
B40: บจก.เอสพีเอ็ม อาหารสัตว์ | C40: 3000 | D40: 0 | E40: 3000 | F40: 0 | G40: 0 | H40: 0
B41: บจก.แอมโก้เวท | C41: 40000 | D41: 42000 | E41: 40000 | F41: 43027.6 | G41: 0 | H41: 43027.6
B42: บจก.เอ็นบี ดิสทริบิวชั่น | C42: 35000 | D42: 15750 | E42: 30000 | F42: 16135.35 | G42: 10756.9 | H42: 5378.45
B43: บจก.หนองบัว อโกรฟอร์ไลด์ | C43: 5000 | D43: 0 | E43: 5000 | F43: 0 | G43: 0 | H43: 0
...

Sheet 4(Order+FC)
A2: เลขที่ SO | B2: (หลายรายการ)
A3: วันส่ง | B3: (หลายรายการ)
A4: ชื่อลูกค้า | B4: (ทั้งหมด)
K5: 9
A6: ประเภท | B6: ผลรวม ของ จำนวนส่ง | C6: ผลรวม ของ ค้างพิมพ์ | D6: ผลรวม ของ ค้างตัด | E6: ผลรวม ของ ใช้ | F6: ผลรวม ของ Stock | G6: ผลรวม ของ ค้างทอ
A7: WSWT1425800 | B7: 10000 | C7: 10500 | D7: 10000 | E7: 6565.9 | F7: 6565.9 | G7: 0 | H7: =+J7-I7 -> 0 | J7: =G7 -> 0
A8: WSWT1621720SMFX | B8: 10000 | C8: 10500 | D8: 10000 | E8: 7404.1 | F8: 4589 | G8: 2815.1 | H8: =+J8-I8 -> 2815.1 | J8: =G8 -> 2815.1
A9: WSWT1625800 | B9: 10000 | C9: 10500 | D9: 10000 | E9: 7404.1 | F9: 7404.1 | G9: 0 | H9: =+J9-I9 -> 0 | J9: =G9 -> 0
A10: WSWT1825800 | B10: 15000 | C10: 15750 | D10: 15000 | E10: 13201.65 | F10: 12070 | G10: 1131.65 | H10: =+J10-I10 -> 1131.65 | J10: =G10 -> 1131.65
A11: WSWT1825800SM | B11: 10000 | C11: 10500 | D11: 10000 | E11: 8801.1 | F11: 0 | G11: 8801.1 | H11: =+J11-I11 -> 8801.1 | J11: =G11 -> 8801.1
A12: WSWT1921720 | B12: 550000 | C12: 498750 | D12: 545000 | E12: 464292.95 | F12: 7603.75 | G12: 456689.2 | H12: =+J12-I12 -> 456689.2 | J12: =G12 -> 456689.2 | K12: 40000 | L12: =+K5*K12 -> 360000 | M12: =+L12-J12 -> -96689.2
A13: WSWT19251000SM | B13: 10080 | C13: 10584 | D13: 10080 | E13: 9998.0496 | F13: 8000.0248 | G13: 1998.0248 | H13: =+J13-I13 -> 1998.0248 | J13: =G13 -> 1998.0248 | K13: 14000 | L13: =+K13*K5 -> 126000 | M13: =+L13-J13 -> 124001.98
A14: WSWT1925800 | B14: 210000 | C14: 186900 | D14: 210000 | E14: 155424.63 | F14: 6923.532 | G14: 148501.1 | H14: =+J14-I14 -> 148501.1 | J14: =G14 -> 148501.1
A15: WSWT1925800SM | B15: 10000 | C15: 10500 | D15: 10000 | E15: 7683.5 | F15: 7683.5 | G15: 0 | H15: =+J15-I15 -> 0 | J15: =G15 -> 0 | K15: 20000 | L15: =+K15*K5 -> 180000 | M15: =+L15-J15 -> 180000
A16: WSWT2025650 | B16: 5000 | C16: 0 | D16: 5000 | E16: 4400.55 | F16: 0 | G16: 4400.55 | H16: =+J16-I16 -> 4400.55 | J16: =G16 -> 4400.55
A17: WSWT2025800 | B17: 569000 | C17: 536203.5 | D17: 554143 | E17: 550310.98 | F17: 9000 | G17: 541310.98 | H17: =+J17-I17 -> 541310.98 | J17: =G17 -> 541310.98
A18: WSWT2025800SM | B18: 261841 | C18: 244787.55 | D18: 256801 | E18: 247364.35 | F18: 15378.45 | G18: 231985.9 | H18: =+J18-I18 -> 231985.9 | J18: =G18 -> 231985.9
A19: WSWT2121670SM | B19: 129000 | C19: 100800 | D19: 119019 | E19: 103266.24 | F19: 33346.39 | G19: 69919.85 | H19: 0 | I19: 54000 | J19: =G19 -> 69919.85
A20: WSWT2125650 | B20: 52000 | C20: 10500 | D20: 52000 | E20: 55880 | F20: 0 | G20: 55880 | H20: =+J20-I20 -> 55880 | J20: =G20 -> 55880
A21: WSWT2221940 | B21: 268368 | C21: 259284.9 | D21: 252429 | E21: 257176.91 | F21: 84469 | G21: 172707.91 | H21: =+J21-I21 -> 172707.91 | J21: =G21 -> 172707.91
A22: WSWT2321750 | B22: 12000 | C22: 12600 | D22: 12000 | E22: 12684.76 | F22: 5116.24 | G22: 7568.52 | H22: =+J22-I22 -> 7568.52 | J22: =G22 -> 7568.52
A23: WSWT2325650 | B23: 52000 | C23: 54600 | D23: 52000 | E23: 51856.64 | F23: 15751.1 | G23: 36105.54 | H23: =+J23-I23 -> 36105.54 | J23: =G23 -> 36105.54
A24: WSWT2625650 | B24: 8563 | C24: 4200 | D24: 8563 | E24: 9913.1539 | F24: 2306 | G24: 7607.1539 | H24: =+J24-I24 -> 7607.1539 | J24: =G24 -> 7607.1539
A25: WSWT262575051 | B25: 10000 | C25: 7350 | D25: 7000 | E25: 8703.31 | F25: 0 | G25: 8703.31 | H25: =+J25-I25 -> 8703.31 | J25: =G25 -> 8703.31
A26: WSWT2625800 | B26: 10000 | C26: 0 | D26: 10000 | E26: 12433.3 | F26: 6278 | G26: 6155.3 | H26: =+J26-I26 -> 6155.3 | J26: =G26 -> 6155.3
A27: WSWT2625850SM | B27: 101000 | C27: 90459.6 | D27: 97152 | E27: 120792 | F27: 45818.63 | G27: 74973.366 | H27: =+J27-I27 -> 74973.366 | J27: =G27 -> 74973.366
A28: WSWT2825850 | B28: 70000 | C28: 52500 | D28: 70000 | E28: 86474.3 | F28: 4036 | G28: 82438.3 | H28: =+J28-I28 -> 82438.3 | J28: =G28 -> 82438.3 | M28: =+GETPIVOTDATA("ผลรวม ของ ใช้",$A$6)+H29+H33 -> 4156823.2
A29: WSWTFCL022325650 | B29: 10000 | C29: 10500 | D29: 10000 | E29: 9918.7 | F29: 6043 | G29: 3875.7 | H29: =SUM(H7:H28) -> 1849773 | I29: =SUM(I7:I28) -> 54000 | J29: =SUM(J7:J28) -> 1919692.9
A30: WSWTSCL052325650 | B30: 5000 | C30: 5250 | D30: 5000 | E30: 5099.05 | F30: 5099.05 | G30: 0
A31: ผลรวมทั้งหมด | B31: 2398852 | C31: 2153519.6 | D31: 2341187 | E31: 2217050.2 | F31: 293481.67 | G31: 1923568.6
H32: =+H26 -> 6155.3 | I32: 85 | J32: =+(H32+H29)*I32 -> 1.5775391e+08 | K32: =+J32/1000 -> 157753.91
H33: 90000 | I33: 95 | J33: =+H33*I33 -> 8550000 | K33: =+J33/1000 -> 8550
H35: =+H32+H33+H29 -> 1945928.3 | K35: =+K32+K33 -> 166303.91
N36: 705222
A37: ยอดส่ง 1/2/68 - 17/2/68 | B37: 1565717 | H37: 15 | I37: =+H35/H37 -> 129728.55
N38: =+H35+N36 -> 2651150.3
I39: =+H37*110000 -> 1650000
B41: =+B29+B37+B31-110000 -> 3864569 | C41: =+C29+C37+C31 -> 2164019.6 | D41: =+D29+D37+D31-110000 -> 2241187 | E41: =+E29+E37+E31 -> 2226968.9 | F41: =+F29+F37+F31 -> 299524.67 | G41: =+G29+G37+G31 -> 1927444.3
B43: 3218150
B45: =+B43-B41 -> -646419
...

Sheet 4(Order)
A2: เลขที่ SO | B2: (หลายรายการ)
A3: วันส่ง | B3: (หลายรายการ)
A4: ชื่อลูกค้า | B4: (ทั้งหมด)
A6: ประเภท | B6: ผลรวม ของ จำนวนส่ง | C6: ผลรวม ของ ค้างพิมพ์ | D6: ผลรวม ของ ค้างตัด | E6: ผลรวม ของ ใช้ | F6: ผลรวม ของ Stock | G6: ผลรวม ของ ค้างทอ
A7: WSWT1425800 | B7: 10000 | C7: 10500 | D7: 10000 | E7: 6565.9 | F7: 6565.9 | G7: 0 | I7: =+K7-J7 -> 0 | K7: =G7 -> 0
A8: WSWT1621720SMFX | B8: 10000 | C8: 10500 | D8: 10000 | E8: 7404.1 | F8: 4589 | G8: 2815.1 | I8: =+K8-J8 -> 2815.1 | K8: =G8 -> 2815.1
A9: WSWT1625800 | B9: 10000 | C9: 10500 | D9: 10000 | E9: 7404.1 | F9: 7404.1 | G9: 0 | I9: =+K9-J9 -> 0 | K9: =G9 -> 0
A10: WSWT1825800SM | B10: 10000 | C10: 10500 | D10: 10000 | E10: 8801.1 | F10: 0 | G10: 8801.1 | I10: =+K10-J10 -> 8801.1 | K10: =G10 -> 8801.1
A11: WSWT1921720 | B11: 225000 | C11: 157500 | D11: 220000 | E11: 178257.2 | F11: 7603.75 | G11: 170653.45 | I11: =+K11-J11 -> 170653.45 | K11: =G11 -> 170653.45
A12: WSWT19251000SM | B12: 10080 | C12: 10584 | D12: 10080 | E12: 9998.0496 | F12: 8000.0248 | G12: 1998.0248 | I12: =+K12-J12 -> 1998.0248 | K12: =G12 -> 1998.0248
A13: WSWT1925800 | B13: 60000 | C13: 29400 | D13: 60000 | E13: 23408.132 | F13: 6923.532 | G13: 16484.6 | I13: =+K13-J13 -> 16484.6 | K13: =G13 -> 16484.6
A14: WSWT1925800SM | B14: 10000 | C14: 10500 | D14: 10000 | E14: 7683.5 | F14: 7683.5 | G14: 0 | I14: =+K14-J14 -> 0 | K14: =G14 -> 0
A15: WSWT2025800 | B15: 569000 | C15: 536203.5 | D15: 554143 | E15: 550310.98 | F15: 9000 | G15: 541310.98 | I15: =+K15-J15 -> 541310.98 | K15: =G15 -> 541310.98
A16: WSWT2025800SM | B16: 141841 | C16: 118787.55 | D16: 136801 | E16: 121634.35 | F16: 15378.45 | G16: 106255.9 | I16: =+K16-J16 -> 106255.9 | K16: =G16 -> 106255.9
A17: WSWT2121670SM | B17: 64000 | C17: 32550 | D17: 54019 | E17: 33346.39 | F17: 33346.39 | G17: 0 | I17: 0 | J17: 54000 | K17: =G17 -> 0
A18: WSWT2125650 | B18: 32000 | C18: 10500 | D18: 32000 | E18: 33807.4 | F18: 0 | G18: 33807.4 | I18: =+K18-J18 -> 33807.4 | K18: =G18 -> 33807.4
A19: WSWT2321750 | B19: 12000 | C19: 12600 | D19: 12000 | E19: 12684.76 | F19: 5116.24 | G19: 7568.52 | I19: =+K19-J19 -> 7568.52 | K19: =G19 -> 7568.52
A20: WSWT2325650 | B20: 20000 | C20: 21000 | D20: 20000 | E20: 20116.8 | F20: 15751.1 | G20: 4365.7 | I20: =+K20-J20 -> 4365.7 | K20: =G20 -> 4365.7
A21: WSWT2625650 | B21: 8563 | C21: 4200 | D21: 8563 | E21: 9913.1539 | F21: 2306 | G21: 7607.1539 | I21: =+K21-J21 -> 7607.1539 | K21: =G21 -> 7607.1539
A22: WSWT262575051 | B22: 10000 | C22: 7350 | D22: 7000 | E22: 8703.31 | F22: 0 | G22: 8703.31 | I22: =+K22-J22 -> 8703.31 | K22: =G22 -> 8703.31
A23: WSWT2625800 | B23: 10000 | C23: 0 | D23: 10000 | E23: 12433.3 | F23: 6278 | G23: 6155.3 | I23: =+K23-J23 -> 6155.3 | K23: =G23 -> 6155.3
A24: WSWT2625850SM | B24: 101000 | C24: 90459.6 | D24: 97152 | E24: 120792 | F24: 45818.63 | G24: 74973.366 | I24: =+K24-J24 -> 74973.366 | K24: =G24 -> 74973.366
A25: WSWT2825850 | B25: 50000 | C25: 52500 | D25: 50000 | E25: 59372.5 | F25: 4036 | G25: 55336.5 | I25: =+K25-J25 -> 55336.5 | K25: =G25 -> 55336.5
A26: WSWTFCL022325650 | B26: 10000 | C26: 10500 | D26: 10000 | E26: 9918.7 | F26: 6043 | G26: 3875.7 | I26: =SUM(I7:I25) -> 1046836.4 | J26: =SUM(J7:J25) -> 54000 | K26: =SUM(K7:K25) -> 1046836.4
A27: WSWTSCL052325650 | B27: 5000 | C27: 5250 | D27: 5000 | E27: 5099.05 | F27: 5099.05 | G27: 0
A28: ผลรวมทั้งหมด | B28: 1378484 | C28: 1151884.7 | D28: 1336758 | E28: 1247654.8 | F28: 196942.67 | G28: 1050712.1
A37: ยอดส่ง 1/4/68 - 4/4/68 | B37: 333878
A38: Order+ส่ง | B38: =++B28+B37 -> 1712362
A39: ประมาณการ | B39: 752000 | C39: 742350 | D39: 752000 | E39: 712218.54 | F39: 12070 | G39: 700148.54
A41: Order+ส่ง+ประมาณการ | B41: =+B28+B37+B39+B31 -> 2464362 | C41: =+C24+C37+C39+C31 -> 832809.6 | D41: =+D24+D37+D39+D31 -> 849152 | E41: =+E24+E37+E39+E31 -> 833010.54 | F41: =+F24+F37+F39+F31 -> 57888.63 | G41: =+G24+G37+G39+G31 -> 775121.91
B43: 3171376
B45: =+B41-B43 -> -707014 | C45: =+$B$45 -> -707014 | D45: =+$B$45 -> -707014 | F45: =+$B$45 -> -707014
D47: =+D41/6 -> 141525.33

Sheet 4(Order) แยกลูกค้า
A1: เลขที่ SO | B1: (หลายรายการ)
A2: วันส่ง | B2: (หลายรายการ)
A4: ประเภท | B4: ชื่อลูกค้า | C4: ผลรวม ของ จำนวนส่ง | D4: ผลรวม ของ ค้างพิมพ์ | E4: ผลรวม ของ ค้างตัด | F4: ผลรวม ของ Stock | G4: ผลรวม ของ ค้างทอ | I4: vn
A5: WSWT1425800 | B5: บจก.ปึงเป้งน้ำ | C5: 10000 | D5: 10500 | E5: 10000 | F5: 6565.9 | G5: 0 | H5: =G5 -> 0
A6: WSWT1425800 ผลรวม | C6: 10000 | D6: 10500 | E6: 10000 | F6: 6565.9 | G6: 0 | H6: =G6 -> 0
A7: WSWT1621720SMFX | B7: โรงสีธัญญกิจ(ราชบุรี) | C7: 10000 | D7: 10500 | E7: 10000 | F7: 4589 | G7: 2815.1 | H7: =G7 -> 2815.1
A8: WSWT1621720SMFX ผลรวม | C8: 10000 | D8: 10500 | E8: 10000 | F8: 4589 | G8: 2815.1 | H8: =G8 -> 2815.1
A9: WSWT1625800 | B9: บจก.เคอรี่ฟลาวมิลล์ | C9: 10000 | D9: 10500 | E9: 10000 | F9: 7404.1 | G9: 0 | H9: =G9 -> 0
A10: WSWT1625800 ผลรวม | C10: 10000 | D10: 10500 | E10: 10000 | F10: 7404.1 | G10: 0 | H10: =G10 -> 0
A11: WSWT1825800SM | B11: บจก.2เอ็ม อโกรเท็ค | C11: 10000 | D11: 10500 | E11: 10000 | F11: 0 | G11: 8801.1 | H11: =G11 -> 8801.1
A12: WSWT1825800SM ผลรวม | C12: 10000 | D12: 10500 | E12: 10000 | F12: 0 | G12: 8801.1 | H12: =G12 -> 8801.1
A13: WSWT1921720 | B13: บจก.เคอรี่ฟลาวมิลล์ | C13: 225000 | D13: 157500 | E13: 220000 | F13: 7603.75 | G13: 170653.45 | H13: =G13 -> 170653.45
A14: WSWT1921720 ผลรวม | C14: 225000 | D14: 157500 | E14: 220000 | F14: 7603.75 | G14: 170653.45 | H14: =G14 -> 170653.45
A15: WSWT19251000SM | B15: บจก.อินเทคค์ โกลบอล | C15: 10080 | D15: 10584 | E15: 10080 | F15: 8000.0248 | G15: 1998.0248 | H15: =G15 -> 1998.0248
A16: WSWT19251000SM ผลรวม | C16: 10080 | D16: 10584 | E16: 10080 | F16: 8000.0248 | G16: 1998.0248 | H16: =G16 -> 1998.0248
A17: WSWT1925800 | B17: บจก.ซีแมน | C17: 60000 | D17: 29400 | E17: 60000 | F17: 6923.532 | G17: 16484.6 | H17: =G17 -> 16484.6
A18: WSWT1925800 ผลรวม | C18: 60000 | D18: 29400 | E18: 60000 | F18: 6923.532 | G18: 16484.6 | H18: =G18 -> 16484.6
A19: WSWT1925800SM | B19: บจก.เอเชี่ยนเคมิคัล | C19: 10000 | D19: 10500 | E19: 10000 | F19: 7683.5 | G19: 0 | H19: =G19 -> 0
A20: WSWT1925800SM ผลรวม | C20: 10000 | D20: 10500 | E20: 10000 | F20: 7683.5 | G20: 0 | H20: =G20 -> 0
A21: WSWT2025800 | B21: บจก.เคอรี่ฟลาวมิลล์ | C21: 10000 | D21: 5250 | E21: 5000 | F21: 0 | G21: 4679.95 | H21: =G21 -> 4679.95
B22: บจก.เบทาโกร | C22: 509000 | D22: 501488.4 | E22: 499143 | F22: 9000 | G22: 505758.97 | H22: =G22 -> 505758.97
B23: บจก.อินเทคค์ โกลบอล | C23: 50000 | D23: 29465.1 | E23: 50000 | F23: 0 | G23: 30872.059 | H23: =G23 -> 30872.059
A24: WSWT2025800 ผลรวม | C24: 569000 | D24: 536203.5 | E24: 554143 | F24: 9000 | G24: 541310.98 | H24: =G24 -> 541310.98
A25: WSWT2025800SM | B25: บจก.อินเทคค์ โกลบอล | C25: 28841 | D25: 22187.55 | E25: 23801 | F25: 8000 | G25: 14140.005 | H25: =G25 -> 14140.005
B26: บจก.เอพีเอ็ม อะโกร | C26: 25000 | D26: 14700 | E26: 25000 | F26: 2000 | G26: 13450.82 | H26: =G26 -> 13450.82
B27: บจก.เอสพีเอ็ม อาหารสัตว์ | C27: 8000 | D27: 8400 | E27: 8000 | F27: 0 | G27: 8745.22 | H27: =G27 -> 8745.22
B28: บจก.วีซีเอฟ | C28: 80000 | D28: 73500 | E28: 80000 | F28: 5378.45 | G28: 69919.85 | H28: =G28 -> 69919.85
A29: WSWT2025800SM ผลรวม | C29: 141841 | D29: 118787.55 | E29: 136801 | F29: 15378.45 | G29: 106255.9 | H29: =G29 -> 106255.9
A30: WSWT2121670SM | B30: บจก.ที.ซี.ยูเนี่ยน อโกรเทค | C30: 16000 | D30: 16800 | E30: 16000 | F30: 17211.04 | G30: 0 | H30: =G30 -> 0
B31: บจก.เอพีเอ็ม อะโกร | C31: 5000 | D31: 0 | E31: 19 | F31: 0 | G31: 0 | H31: =G31 -> 0
B32: บจก.เอสพีเอ็ม อาหารสัตว์ | C32: 3000 | D32: 0 | E32: 3000 | F32: 0 | G32: 0 | H32: =G32 -> 0
B33: บจก.เอ็นบี ดิสทริบิวชั่น | C33: 30000 | D33: 10500 | E33: 25000 | F33: 10756.9 | G33: 0 | H33: =G33 -> 0
B34: บจก.หนองบัว อโกรฟอร์ไลด์ | C34: 5000 | D34: 0 | E34: 5000 | F34: 0 | G34: 0 | H34: =G34 -> 0
B35: คุณนพวินทร์ รัตนเศรษฐ์เมธา | C35: 5000 | D35: 5250 | E35: 5000 | F35: 5378.45 | G35: 0 | H35: =G35 -> 0
A36: WSWT2121670SM ผลรวม | C36: 64000 | D36: 32550 | E36: 54019 | F36: 33346.39 | G36: 0 | H36: =G36 -> 0
A37: WSWT2125650 | B37: บจก.หนองบัวฟีดมิลล์ | C37: 20000 | D37: 0 | E37: 20000 | F37: 0 | G37: 22072.6 | H37: =G37 -> 22072.6
B38: บจก.เอเชี่ยนเคมิคัล | C38: 2000 | D38: 0 | E38: 2000 | F38: 0 | G38: 1816.1 | H38: =G38 -> 1816.1
B39: บจก.ไลม์มาสเตอร์ | C39: 10000 | D39: 10500 | E39: 10000 | F39: 0 | G39: 9918.7 | H39: =G39 -> 9918.7
A40: WSWT2125650 ผลรวม | C40: 32000 | D40: 10500 | E40: 32000 | F40: 0 | G40: 33807.4 | H40: =G40 -> 33807.4
A41: WSWT2221940 | B41: กองเมล็ดพันธุ์ข้าว กรมการข้าว | C41: 268368 | D41: 259284.9 | E41: 252429 | F41: 84469 | G41: 172707.91 | H41: =G41 -> 172707.91
...

Sheet 4(Fc) แยกลูกค้า
A1: เลขที่ SO | B1: ประมาณการ
A2: วันส่ง | B2: (หลายรายการ) | D2: 12
A4: ประเภท | B4: ชื่อลูกค้า | C4: ผลรวม ของ จำนวนส่ง | D4: ผลรวม ของ ค้างพิมพ์ | E4: ผลรวม ของ ค้างตัด | F4: ผลรวม ของ ใช้ | G4: ผลรวม ของ Stock | H4: ผลรวม ของ ค้างทอ
A5: WSWT1825800 | B5: บจก.ฟาร์เธอร์ส วิง ซัพพลาย | C5: 15000 | D5: 15750 | E5: 15000 | F5: 13201.65 | G5: 12070 | H5: 1131.65
A6: WSWT1825800 ผลรวม | C6: 15000 | D6: 15750 | E6: 15000 | F6: 13201.65 | G6: 12070 | H6: 1131.65
A7: WSWT1921720 | B7: บจก.เคอรี่ฟลาวมิลล์ | C7: 325000 | D7: 341250 | E7: 325000 | F7: 286035.75 | G7: 0 | H7: 286035.75
