Workbook

Sheet Linkสูตรออร์เดอร์  (2)
B2: เรียงกำหนดส่ง | D2: ลบ 0 | T2: เรียง 1
B3: ข้อมูลUpdate ณ. วันที่ | D3: 45943 | E3: เวลา | G3: 9.44
A4: วันรับออร์เดอร์/แบบ | B4: เลขที่ SO | C4: ชื่อลูกค้า | E4: 10.3 | I4: น้ำหนัก | L4: บิด/จับจีบ | M4: ถุงใน | Q4: =[1]หน้าผ้า!$AC$13 -> 44873 | S4: วิธีบรรจุ | T4: วันส่ง | U4: จำนวนส่ง | V4: ตัดเย็บ (ใบ) | W4: =[1]หน้าผ้า!$AJ$13 -> 44873 | X4: พิมพ์ (ใบ) | Y4: =[1]หน้าผ้า!$AM$13 -> 44876 | Z4: ผ้าทอ (เมตร) Updateณ | AB4: =[1]หน้าผ้า!$AR$12 -> 44876 | AD4: ผ้าเคลือบ(เมตร) | AF4: หมายเหตุ | AG4: เครื่อง
B5: เลขที่ SO | C5: ชื่อลูกค้า | D5: ตรา | E5: กว้าง | F5: ยาว | G5: สี | H5: เคลือบ | I5: กรัม/ใบ | J5: * | K5: aw | L5: บิด/จับจีบ | M5: กว้าง | N5: ยาว | O5: หนา | P5: ใช้(กก.) | Q5: Stock(กก.) | R5: ผลิต(กก.) | S5: วิธีบรรจุ | T5: วันส่ง | U5: จำนวนส่ง | V5: StockFG | W5: ค้างตัด | X5: พิมพ์แล้ว | Y5: ค้างพิมพ์ | Z5: ประเภท | AA5: ใช้ | AB5: Stock | AC5: ค้างทอ | AD5: Stock | AE5: ค้างเคลือบ | AF5: หมายเหตุ | AG5: ที่พิมพ์ได้ | AH5: process | AI5: Lead time | AJ5: วันที่ส่งPL | AK5: เคลือบ | AL5: ได้ ART | AM5: พิมพ์ | AN5: จีบ-บิด | AO5: ตัด-เย็บ | AP5: ทอ | AQ5: สวมถุง | AR5: เย็บปาก | AS5: PT | AT5: ม้วน | AU5: ตัด | AV5: ตอกตาไก่ | AW5: GROUP | AX5: ART | AY5: หมายเหตุปัญหา | AZ5: ราคา/ใบ | BA5: ราคารวม | BB5: workweek | BC5: เส้นเทป | BD5: จำนวน
A6: =[2]หน้าผ้า!C15 -> 0 | B6: =[2]หน้าผ้า!B15 -> 0 | C6: =[2]หน้าผ้า!E15 -> 0 | D6: =[2]หน้าผ้า!F15 -> 0 | E6: =[2]หน้าผ้า!G15 -> 12 | F6: =[2]หน้าผ้า!H15 -> 16 | G6: =[2]หน้าผ้า!I15 -> ขาว | H6: =[2]หน้าผ้า!J15 -> 0 | I6: =[2]หน้าผ้า!L15 -> 25 | J6: =[2]หน้าผ้า!M15 -> ± | K6: =[2]หน้าผ้า!N15 -> 5 | L6: =[2]หน้าผ้า!R15 -> 0 | M6: =[2]หน้าผ้า!T15 -> 0 | N6: =[2]หน้าผ้า!U15 -> 0 | O6: =[2]หน้าผ้า!V15 -> 0 | P6: =[2]หน้าผ้า!AB15 -> 0 | Q6: =[2]หน้าผ้า!AC15 -> 0 | R6: =[2]หน้าผ้า!AD15 -> 0 | S6: =[2]หน้าผ้า!Z15 -> 0 | T6: =[2]หน้าผ้า!X15 -> 0 | U6: =[2]หน้าผ้า!AA15 -> 0 | V6: =[2]หน้าผ้า!AJ15 -> 0 | W6: =[2]หน้าผ้า!AL15 -> 0 | X6: =[2]หน้าผ้า!AM15 -> 0 | Y6: =[2]หน้าผ้า!AN15 -> 0 | Z6: =[2]หน้าผ้า!AO15 -> WSWT1221750 | AA6: =[2]หน้าผ้า!AQ15 -> #REF! | AB6: =[2]หน้าผ้า!AR15 -> #REF! | AC6: =[2]หน้าผ้า!AS15 -> #REF! | AD6: =[2]หน้าผ้า!AT15 -> #REF! | AE6: =[2]หน้าผ้า!AU15 -> #REF! | AF6: =[2]หน้าผ้า!AI15 -> ระบุในSD | AG6: =[3]หน้าผ้า!DC18 -> < Ord 20,000 | AH6: =[2]หน้าผ้า!DL15 -> 0 | AI6: =[2]หน้าผ้า!DM15 -> 0 | AJ6: =[2]หน้าผ้า!DN15 -> 0 | AK6: =[2]หน้าผ้า!DQ15 -> 0 | AL6: =[2]หน้าผ้า!DR15 -> 0 | AM6: =[2]หน้าผ้า!DS15 -> 0 | AN6: =[2]หน้าผ้า!DT15 -> 0 | AO6: =[2]หน้าผ้า!DU15 -> 0 | AP6: =[2]หน้าผ้า!DP15 -> 0 | AQ6: =[2]หน้าผ้า!DW15 -> 0 | AR6: =[2]หน้าผ้า!DX15 -> 0 | AS6: =[2]หน้าผ้า!DY15 -> 0 | AT6: =[2]หน้าผ้า!DZ15 -> 0 | AU6: =[2]หน้าผ้า!EA15 -> 0 | AV6: =[2]หน้าผ้า!EB15 -> 0 | AW6: =[2]หน้าผ้า!EC15 -> 0 | AX6: =[2]หน้าผ้า!ED15 -> 0 | AY6: =[2]หน้าผ้า!AG15 -> 0 | AZ6: =[2]หน้าผ้า!EG15 -> 0 | BA6: =[2]หน้าผ้า!EH15 -> 0 | BB6: =[2]หน้าผ้า!EI15 -> 0 | BC6: =[2]หน้าผ้า!BZ15 -> WRWT120750/WRWT21750 | BD6: =[2]หน้าผ้า!CA15 -> 0
A7: =[2]หน้าผ้า!C16 -> 0 | B7: =[2]หน้าผ้า!B16 -> 0 | C7: =[2]หน้าผ้า!E16 -> 0 | D7: =[2]หน้าผ้า!F16 -> 0 | E7: =[2]หน้าผ้า!G16 -> 14 | F7: =[2]หน้าผ้า!H16 -> 22 | G7: =[2]หน้าผ้า!I16 -> ขาว | H7: =[2]หน้าผ้า!J16 -> 0 | I7: =[2]หน้าผ้า!L16 -> 36 | J7: =[2]หน้าผ้า!M16 -> ± | K7: =[2]หน้าผ้า!N16 -> 5 | L7: =[2]หน้าผ้า!R16 -> 0 | M7: =[2]หน้าผ้า!T16 -> 0 | N7: =[2]หน้าผ้า!U16 -> 0 | O7: =[2]หน้าผ้า!V16 -> 0 | P7: =[2]หน้าผ้า!AB16 -> 0 | Q7: =[2]หน้าผ้า!AC16 -> 0 | R7: =[2]หน้าผ้า!AD16 -> 0 | S7: =[2]หน้าผ้า!Z16 -> 0 | T7: =[2]หน้าผ้า!X16 -> 0 | U7: =[2]หน้าผ้า!AA16 -> 0 | V7: =[2]หน้าผ้า!AJ16 -> 0 | W7: =[2]หน้าผ้า!AL16 -> 0 | X7: =[2]หน้าผ้า!AM16 -> 0 | Y7: =[2]หน้าผ้า!AN16 -> 0 | Z7: =[2]หน้าผ้า!AO16 -> WSWT1425800 | AA7: =[2]หน้าผ้า!AQ16 -> #REF! | AB7: =[2]หน้าผ้า!AR16 -> #REF! | AC7: =[2]หน้าผ้า!AS16 -> #REF! | AD7: =[2]หน้าผ้า!AT16 -> #REF! | AE7: =[2]หน้าผ้า!AU16 -> #REF! | AF7: =[2]หน้าผ้า!AI16 -> ระบุในSD | AG7: =[3]หน้าผ้า!DC19 -> พร้อมส่ง | AH7: =[2]หน้าผ้า!DL16 -> 0 | AI7: =[2]หน้าผ้า!DM16 -> Lead time | AJ7: =[2]หน้าผ้า!DN16 -> 0 | AK7: =[2]หน้าผ้า!DQ16 -> 0 | AL7: =[2]หน้าผ้า!DR16 -> 0 | AM7: =[2]หน้าผ้า!DS16 -> 0 | AN7: =[2]หน้าผ้า!DT16 -> 0 | AO7: =[2]หน้าผ้า!DU16 -> 0 | AP7: =[2]หน้าผ้า!DP16 -> 0 | AQ7: =[2]หน้าผ้า!DW16 -> 0 | AR7: =[2]หน้าผ้า!DX16 -> 0 | AS7: =[2]หน้าผ้า!DY16 -> 0 | AT7: =[2]หน้าผ้า!DZ16 -> 0 | AU7: =[2]หน้าผ้า!EA16 -> 0 | AV7: =[2]หน้าผ้า!EB16 -> 0 | AW7: =[2]หน้าผ้า!EC16 -> 0 | AX7: =[2]หน้าผ้า!ED16 -> 0 | AY7: =[2]หน้าผ้า!AG16 -> 0 | AZ7: =[2]หน้าผ้า!EG16 -> 0 | BA7: =[2]หน้าผ้า!EH16 -> 0 | BB7: =[2]หน้าผ้า!EI16 -> 0 | BC7: =[2]หน้าผ้า!BZ16 -> WRWT140800/WRWT25800 | BD7: =[2]หน้าผ้า!CA16 -> 0
A8: =[2]หน้าผ้า!C17 -> 0 | B8: =[2]หน้าผ้า!B17 -> 0 | C8: =[2]หน้าผ้า!E17 -> 0 | D8: =[2]หน้าผ้า!F17 | E8: =[2]หน้าผ้า!G17 -> 16 | F8: =[2]หน้าผ้า!H17 -> 25 | G8: =[2]หน้าผ้า!I17 -> ขาว | H8: =[2]หน้าผ้า!J17 -> 0 | I8: =[2]หน้าผ้า!L17 -> 45 | J8: =[2]หน้าผ้า!M17 -> ± | K8: =[2]หน้าผ้า!N17 -> 5 | L8: =[2]หน้าผ้า!R17 -> 0 | M8: =[2]หน้าผ้า!T17 -> 0 | N8: =[2]หน้าผ้า!U17 -> 0 | O8: =[2]หน้าผ้า!V17 -> 0 | P8: =[2]หน้าผ้า!AB17 -> 0 | Q8: =[2]หน้าผ้า!AC17 -> 0 | R8: =[2]หน้าผ้า!AD17 -> 0 | S8: =[2]หน้าผ้า!Z17 -> 0 | T8: =[2]หน้าผ้า!X17 -> 0 | U8: =[2]หน้าผ้า!AA17 -> 0 | V8: =[2]หน้าผ้า!AJ17 -> 0 | W8: =[2]หน้าผ้า!AL17 -> 0 | X8: =[2]หน้าผ้า!AM17 -> 0 | Y8: =[2]หน้าผ้า!AN17 -> 0 | Z8: =[2]หน้าผ้า!AO17 -> WSWT1625800SM | AA8: =[2]หน้าผ้า!AQ17 -> #REF! | AB8: =[2]หน้าผ้า!AR17 -> #REF! | AC8: =[2]หน้าผ้า!AS17 -> #REF! | AD8: =[2]หน้าผ้า!AT17 -> #REF! | AE8: =[2]หน้าผ้า!AU17 -> #REF! | AF8: =[2]หน้าผ้า!AI17 -> ระบุในSD | AG8: =[3]หน้าผ้า!DC20 -> พร้อมส่ง | AH8: =[2]หน้าผ้า!DL17 -> 0 | AI8: =[2]หน้าผ้า!DM17 -> Lead time | AJ8: =[2]หน้าผ้า!DN17 -> 0 | AK8: =[2]หน้าผ้า!DQ17 -> 0 | AL8: =[2]หน้าผ้า!DR17 -> 0 | AM8: =[2]หน้าผ้า!DS17 -> 0 | AN8: =[2]หน้าผ้า!DT17 -> 0 | AO8: =[2]หน้าผ้า!DU17 -> 0 | AP8: =[2]หน้าผ้า!DP17 -> 0 | AQ8: =[2]หน้าผ้า!DW17 -> 0 | AR8: =[2]หน้าผ้า!DX17 -> 0 | AS8: =[2]หน้าผ้า!DY17 -> 0 | AT8: =[2]หน้าผ้า!DZ17 -> 0 | AU8: =[2]หน้าผ้า!EA17 -> 0 | AV8: =[2]หน้าผ้า!EB17 -> 0 | AW8: =[2]หน้าผ้า!EC17 -> 0 | AX8: =[2]หน้าผ้า!ED17 -> 0 | AY8: =[2]หน้าผ้า!AG17 -> 0 | AZ8: =[2]หน้าผ้า!EG17 -> 0 | BA8: =[2]หน้าผ้า!EH17 -> 0 | BB8: =[2]หน้าผ้า!EI17 -> 0 | BC8: =[2]หน้าผ้า!BZ17 -> WRWT160800/WRWT25800 | BD8: =[2]หน้าผ้า!CA17 -> 0
A9: =[2]หน้าผ้า!C18 -> 45941 | B9: =[2]หน้าผ้า!B18 -> MK68-001228 | C9: =[2]หน้าผ้า!E18 -> บจก.เคอรี่ฟลาวมิลล์ | D9: =[2]หน้าผ้า!F18 -> โบว์แดง 10กก | E9: =[2]หน้าผ้า!G18 -> 16 | F9: =[2]หน้าผ้า!H18 -> 25 | G9: =[2]หน้าผ้า!I18 -> ขาว | H9: =[2]หน้าผ้า!J18 -> 0 | I9: =[2]หน้าผ้า!L18 -> 45 | J9: =[2]หน้าผ้า!M18 -> ± | K9: =[2]หน้าผ้า!N18 -> 5 | L9: =[2]หน้าผ้า!R18 -> ไม่ | M9: =[2]หน้าผ้า!T18 -> ไม่สวมถุงใน | N9: =[2]หน้าผ้า!U18 -> 0 | O9: =[2]หน้าผ้า!V18 -> 0 | P9: =[2]หน้าผ้า!AB18 -> 0 | Q9: =[2]หน้าผ้า!AC18 -> 0 | R9: =[2]หน้าผ้า!AD18 -> 0 | S9: =[2]หน้าผ้า!Z18 -> ห่ออัดเบลแบน500 | T9: =[2]หน้าผ้า!X18 -> 45952 | U9: =[2]หน้าผ้า!AA18 -> 5000 | V9: =[2]หน้าผ้า!AJ18 -> 0 | W9: =[2]หน้าผ้า!AL18 -> 5000 | X9: =[2]หน้าผ้า!AM18 -> 0 | Y9: =[2]หน้าผ้า!AN18 -> 5250 | Z9: =[2]หน้าผ้า!AO18 -> WSWT1625800 | AA9: =[2]หน้าผ้า!AQ18 -> 3702.05 | AB9: =[2]หน้าผ้า!AR18 -> 3702.05 | AC9: =[2]หน้าผ้า!AS18 -> 0 | AD9: =[2]หน้าผ้า!AT18 -> 0 | AE9: =[2]หน้าผ้า!AU18 -> 0 | AF9: =[2]หน้าผ้า!AI18 -> 0 | AG9: =[3]หน้าผ้า!DC21 -> พร้อมส่ง | AH9: =[2]หน้าผ้า!DL18 -> P7 | AI9: =[2]หน้าผ้า!DM18 -> 2 | AJ9: =[2]หน้าผ้า!DN18 -> 45952 | AK9: =[2]หน้าผ้า!DQ18 -> 0 | AL9: =[2]หน้าผ้า!DR18 -> 45943 | AM9: =[2]หน้าผ้า!DS18 -> 45950 | AN9: =[2]หน้าผ้า!DT18 -> 45951 | AO9: =[2]หน้าผ้า!DU18 -> 45951 | AP9: =[2]หน้าผ้า!DP18 -> 45947 | AQ9: =[2]หน้าผ้า!DW18 -> 0 | AR9: =[2]หน้าผ้า!DX18 -> 0 | AS9: =[2]หน้าผ้า!DY18 -> 0 | AT9: =[2]หน้าผ้า!DZ18 -> 0 | AU9: =[2]หน้าผ้า!EA18 -> 0 | AV9: =[2]หน้าผ้า!EB18 -> 0 | AW9: =[2]หน้าผ้า!EC18 -> งานพิมพ์ | AX9: =[2]หน้าผ้า!ED18 -> รอART | AY9: =[2]หน้าผ้า!AG18 -> 0 | AZ9: =[2]หน้าผ้า!EG18 -> 0 | BA9: =[2]หน้าผ้า!EH18 -> 0 | BB9: =[2]หน้าผ้า!EI18 -> 0 | BC9: =[2]หน้าผ้า!BZ18 -> WRWT25800/WRWT25800 | BD9: =[2]หน้าผ้า!CA18 -> 0
A10: =[2]หน้าผ้า!C19 -> 0 | B10: =[2]หน้าผ้า!B19 -> 0 | C10: =[2]หน้าผ้า!E19 -> 0 | D10: =[2]หน้าผ้า!F19 -> 0 | E10: =[2]หน้าผ้า!G19 -> 16 | F10: =[2]หน้าผ้า!H19 -> 25 | G10: =[2]หน้าผ้า!I19 -> ขาว | H10: =[2]หน้าผ้า!J19 -> 0 | I10: =[2]หน้าผ้า!L19 -> 45 | J10: =[2]หน้าผ้า!M19 -> ± | K10: =[2]หน้าผ้า!N19 -> 5 | L10: =[2]หน้าผ้า!R19 -> 0 | M10: =[2]หน้าผ้า!T19 -> 0 | N10: =[2]หน้าผ้า!U19 -> 0 | O10: =[2]หน้าผ้า!V19 -> 0 | P10: =[2]หน้าผ้า!AB19 -> 0 | Q10: =[2]หน้าผ้า!AC19 -> 0 | R10: =[2]หน้าผ้า!AD19 -> 0 | S10: =[2]หน้าผ้า!Z19 -> 0 | T10: =[2]หน้าผ้า!X19 -> 0 | U10: =[2]หน้าผ้า!AA19 -> 0 | V10: =[2]หน้าผ้า!AJ19 -> 0 | W10: =[2]หน้าผ้า!AL19 -> 0 | X10: =[2]หน้าผ้า!AM19 -> 0 | Y10: =[2]หน้าผ้า!AN19 -> 0 | Z10: =[2]หน้าผ้า!AO19 -> WSWT1625800 | AA10: =[2]หน้าผ้า!AQ19 -> 3702.05 | AB10: =[2]หน้าผ้า!AR19 -> 3702.05 | AC10: =[2]หน้าผ้า!AS19 -> 0 | AD10: =[2]หน้าผ้า!AT19 -> 0 | AE10: =[2]หน้าผ้า!AU19 -> 0 | AF10: =[2]หน้าผ้า!AI19 -> ระบุในSD | AG10: =[3]หน้าผ้า!DC22 -> พร้อมส่ง | AH10: =[2]หน้าผ้า!DL19 -> 0 | AI10: =[2]หน้าผ้า!DM19 -> Lead time | AJ10: =[2]หน้าผ้า!DN19 -> 0 | AK10: =[2]หน้าผ้า!DQ19 -> 0 | AL10: =[2]หน้าผ้า!DR19 -> 0 | AM10: =[2]หน้าผ้า!DS19 -> 0 | AN10: =[2]หน้าผ้า!DT19 -> 0 | AO10: =[2]หน้าผ้า!DU19 -> 0 | AP10: =[2]หน้าผ้า!DP19 -> 0 | AQ10: =[2]หน้าผ้า!DW19 -> 0 | AR10: =[2]หน้าผ้า!DX19 -> 0 | AS10: =[2]หน้าผ้า!DY19 -> 0 | AT10: =[2]หน้าผ้า!DZ19 -> 0 | AU10: =[2]หน้าผ้า!EA19 -> 0 | AV10: =[2]หน้าผ้า!EB19 -> 0 | AW10: =[2]หน้าผ้า!EC19 -> 0 | AX10: =[2]หน้าผ้า!ED19 -> 0 | AY10: =[2]หน้าผ้า!AG19 -> 0 | AZ10: =[2]หน้าผ้า!EG19 -> 0 | BA10: =[2]หน้าผ้า!EH19 -> 0 | BB10: =[2]หน้าผ้า!EI19 -> 0 | BC10: =[2]หน้าผ้า!BZ19 -> WRWT160800/WRWT25800 | BD10: =[2]หน้าผ้า!CA19 -> 0
A11: =[2]หน้าผ้า!C20 -> 0 | B11: =[2]หน้าผ้า!B20 -> 0 | C11: =[2]หน้าผ้า!E20 -> 0 | D11: =[2]หน้าผ้า!F20 -> 0 | E11: =[2]หน้าผ้า!G20 -> 16 | F11: =[2]หน้าผ้า!H20 -> 25 | G11: =[2]หน้าผ้า!I20 -> 0 | H11: =[2]หน้าผ้า!J20 -> 0 | I11: =[2]หน้าผ้า!L20 -> 47 | J11: =[2]หน้าผ้า!M20 -> ± | K11: =[2]หน้าผ้า!N20 -> 5 | L11: =[2]หน้าผ้า!R20 -> 0 | M11: =[2]หน้าผ้า!T20 -> 0 | N11: =[2]หน้าผ้า!U20 -> 0 | O11: =[2]หน้าผ้า!V20 -> 0 | P11: =[2]หน้าผ้า!AB20 -> 0 | Q11: =[2]หน้าผ้า!AC20 -> 0 | R11: =[2]หน้าผ้า!AD20 -> 0 | S11: =[2]หน้าผ้า!Z20 -> 0 | T11: =[2]หน้าผ้า!X20 -> 0 | U11: =[2]หน้าผ้า!AA20 -> 0 | V11: =[2]หน้าผ้า!AJ20 -> 0 | W11: =[2]หน้าผ้า!AL20 -> 0 | X11: =[2]หน้าผ้า!AM20 -> 0 | Y11: =[2]หน้าผ้า!AN20 -> 0 | Z11: =[2]หน้าผ้า!AO20 -> WSWT1621720SMFX | AA11: =[2]หน้าผ้า!AQ20 -> #REF! | AB11: =[2]หน้าผ้า!AR20 -> #REF! | AC11: =[2]หน้าผ้า!AS20 -> #REF! | AD11: =[2]หน้าผ้า!AT20 -> #REF! | AE11: =[2]หน้าผ้า!AU20 -> #REF! | AF11: =[2]หน้าผ้า!AI20 -> ระบุในSD | AG11: =[3]หน้าผ้า!DC23 -> ผ้าขาว | AH11: =[2]หน้าผ้า!DL20 -> 0 | AI11: =[2]หน้าผ้า!DM20 -> 0 | AJ11: =[2]หน้าผ้า!DN20 -> 0 | AK11: =[2]หน้าผ้า!DQ20 -> 0 | AL11: =[2]หน้าผ้า!DR20 -> 0 | AM11: =[2]หน้าผ้า!DS20 -> 0 | AN11: =[2]หน้าผ้า!DT20 -> 0 | AO11: =[2]หน้าผ้า!DU20 -> 0 | AP11: =[2]หน้าผ้า!DP20 -> 0 | AQ11: =[2]หน้าผ้า!DW20 -> 0 | AR11: =[2]หน้าผ้า!DX20 -> 0 | AS11: =[2]หน้าผ้า!DY20 -> 0 | AT11: =[2]หน้าผ้า!DZ20 -> 0 | AU11: =[2]หน้าผ้า!EA20 -> 0 | AV11: =[2]หน้าผ้า!EB20 -> 0 | AW11: =[2]หน้าผ้า!EC20 -> 0 | AX11: =[2]หน้าผ้า!ED20 -> 0 | AY11: =[2]หน้าผ้า!AG20 -> 0 | AZ11: =[2]หน้าผ้า!EG20 -> 0 | BA11: =[2]หน้าผ้า!EH20 -> 0 | BB11: =[2]หน้าผ้า!EI20 -> 0 | BC11: =[2]หน้าผ้า!BZ20 -> WRWT160720/WRWT21720 | BD11: =[2]หน้าผ้า!CA20 -> 0
A12: =[2]หน้าผ้า!C21 -> 0 | B12: =[2]หน้าผ้า!B21 -> 0 | C12: =[2]หน้าผ้า!E21 -> 0 | D12: =[2]หน้าผ้า!F21 -> 0 | E12: =[2]หน้าผ้า!G21 -> 17 | F12: =[2]หน้าผ้า!H21 -> 26 | G12: =[2]หน้าผ้า!I21 -> 0 | H12: =[2]หน้าผ้า!J21 -> 0 | I12: =[2]หน้าผ้า!L21 -> 48 | J12: =[2]หน้าผ้า!M21 -> ± | K12: =[2]หน้าผ้า!N21 -> 5 | L12: =[2]หน้าผ้า!R21 -> 0 | M12: =[2]หน้าผ้า!T21 -> 0 | N12: =[2]หน้าผ้า!U21 -> 0 | O12: =[2]หน้าผ้า!V21 -> 0 | P12: =[2]หน้าผ้า!AB21 -> 0 | Q12: =[2]หน้าผ้า!AC21 -> 0 | R12: =[2]หน้าผ้า!AD21 -> 0 | S12: =[2]หน้าผ้า!Z21 -> 0 | T12: =[2]หน้าผ้า!X21 -> 0 | U12: =[2]หน้าผ้า!AA21 -> 0 | V12: =[2]หน้าผ้า!AJ21 -> 0 | W12: =[2]หน้าผ้า!AL21 -> 0 | X12: =[2]หน้าผ้า!AM21 -> 0 | Y12: =[2]หน้าผ้า!AN21 -> 0 | Z12: =[2]หน้าผ้า!AO21 -> WSWT1725800 | AA12: =[2]หน้าผ้า!AQ21 -> #REF! | AB12: =[2]หน้าผ้า!AR21 -> #REF! | AC12: =[2]หน้าผ้า!AS21 -> #REF! | AD12: =[2]หน้าผ้า!AT21 -> #REF! | AE12: =[2]หน้าผ้า!AU21 -> #REF! | AF12: =[2]หน้าผ้า!AI21 -> ระบุในSD | AG12: =[3]หน้าผ้า!DC24 -> ยังไม่ได้พิมพ์ | AH12: =[2]หน้าผ้า!DL21 -> 0 | AI12: =[2]หน้าผ้า!DM21 -> 0 | AJ12: =[2]หน้าผ้า!DN21 -> 0 | AK12: =[2]หน้าผ้า!DQ21 -> 0 | AL12: =[2]หน้าผ้า!DR21 -> 0 | AM12: =[2]หน้าผ้า!DS21 -> 0 | AN12: =[2]หน้าผ้า!DT21 -> 0 | AO12: =[2]หน้าผ้า!DU21 -> 0 | AP12: =[2]หน้าผ้า!DP21 -> 0 | AQ12: =[2]หน้าผ้า!DW21 -> 0 | AR12: =[2]หน้าผ้า!DX21 -> 0 | AS12: =[2]หน้าผ้า!DY21 -> 0 | AT12: =[2]หน้าผ้า!DZ21 -> 0 | AU12: =[2]หน้าผ้า!EA21 -> 0 | AV12: =[2]หน้าผ้า!EB21 -> 0 | AW12: =[2]หน้าผ้า!EC21 -> 0 | AX12: =[2]หน้าผ้า!ED21 -> 0 | AY12: =[2]หน้าผ้า!AG21 -> 0 | AZ12: =[2]หน้าผ้า!EG21 -> 0 | BA12: =[2]หน้าผ้า!EH21 -> 0 | BB12: =[2]หน้าผ้า!EI21 -> 0 | BC12: =[2]หน้าผ้า!BZ21 -> WRWT170800/WRWT25800 | BD12: =[2]หน้าผ้า!CA21 -> 0
A13: =[2]หน้าผ้า!C22 -> 45933 | B13: =[2]หน้าผ้า!B22 -> MK68-001198 | C13: =[2]หน้าผ้า!E22 -> บจก.ฟาร์เธอร์ส วิง ซัพพลาย | D13: =[2]หน้าผ้า!F22 -> รถไฟฟ้าปูนขาวเย็น | E13: =[2]หน้าผ้า!G22 -> 18 | F13: =[2]หน้าผ้า!H22 -> 30 | G13: =[2]หน้าผ้า!I22 -> ขาว | H13: =[2]หน้าผ้า!J22 -> 0 | I13: =[2]หน้าผ้า!L22 -> 54 | J13: =[2]หน้าผ้า!M22 -> ± | K13: =[2]หน้าผ้า!N22 -> 5 | L13: =[2]หน้าผ้า!R22 -> บิด | M13: =[2]หน้าผ้า!T22 -> 19 | N13: =[2]หน้าผ้า!U22 -> 33 | O13: =[2]หน้าผ้า!V22 -> 40 | P13: =[2]หน้าผ้า!AB22 -> 0 | Q13: =[2]หน้าผ้า!AC22 -> 0 | R13: =[2]หน้าผ้า!AD22 -> 0 | S13: =[2]หน้าผ้า!Z22 -> 500กระสอบ | T13: =[2]หน้าผ้า!X22 -> 45944 | U13: =[2]หน้าผ้า!AA22 -> 15000 | V13: =[2]หน้าผ้า!AJ22 -> 15000 | W13: =[2]หน้าผ้า!AL22 -> 0 | X13: =[2]หน้าผ้า!AM22 -> 15835 | Y13: =[2]หน้าผ้า!AN22 -> 0 | Z13: =[2]หน้าผ้า!AO22 -> WSWT1825800 | AA13: =[2]หน้าผ้า!AQ22 -> 0 | AB13: =[2]หน้าผ้า!AR22 -> 0 | AC13: =[2]หน้าผ้า!AS22 -> 0 | AD13: =[2]หน้าผ้า!AT22 -> 0 | AE13: =[2]หน้าผ้า!AU22 -> 0 | AF13: =[2]หน้าผ้า!AI22 -> 0 | AG13: =[3]หน้าผ้า!DC25 -> พร้อมส่ง | AH13: =[2]หน้าผ้า!DL22 -> P9 | AI13: =[2]หน้าผ้า!DM22 -> 3 | AJ13: =[2]หน้าผ้า!DN22 -> 45944 | AK13: =[2]หน้าผ้า!DQ22 -> 0 | AL13: =[2]หน้าผ้า!DR22 -> 45934 | AM13: =[2]หน้าผ้า!DS22 -> 45941 | AN13: =[2]หน้าผ้า!DT22 -> 45942 | AO13: =[2]หน้าผ้า!DU22 -> 45942 | AP13: =[2]หน้าผ้า!DP22 -> 45939 | AQ13: =[2]หน้าผ้า!DW22 -> 45943 | AR13: =[2]หน้าผ้า!DX22 -> 0 | AS13: =[2]หน้าผ้า!DY22 -> 0 | AT13: =[2]หน้าผ้า!DZ22 -> 0 | AU13: =[2]หน้าผ้า!EA22 -> 0 | AV13: =[2]หน้าผ้า!EB22 -> 0 | AW13: =[2]หน้าผ้า!EC22 -> งานพิมพ์ | AX13: =[2]หน้าผ้า!ED22 -> / | AY13: =[2]หน้าผ้า!AG22 -> 0 | AZ13: =[2]หน้าผ้า!EG22 -> 0 | BA13: =[2]หน้าผ้า!EH22 -> 0 | BB13: =[2]หน้าผ้า!EI22 -> 0 | BC13: =[2]หน้าผ้า!BZ22 -> WRWT25800/WRWT25800 | BD13: =[2]หน้าผ้า!CA22 -> 0
A14: =[2]หน้าผ้า!C23 -> 45933 | B14: =[2]หน้าผ้า!B23 -> MK68-001198 | C14: =[2]หน้าผ้า!E23 -> บจก.ฟาร์เธอร์ส วิง ซัพพลาย | D14: =[2]หน้าผ้า!F23 -> ไม่พิมพ์ | E14: =[2]หน้าผ้า!G23 -> 18 | F14: =[2]หน้าผ้า!H23 -> 30 | G14: =[2]หน้าผ้า!I23 -> ขาว | H14: =[2]หน้าผ้า!J23 -> 0 | I14: =[2]หน้าผ้า!L23 -> 54 | J14: =[2]หน้าผ้า!M23 -> ± | K14: =[2]หน้าผ้า!N23 -> 5 | L14: =[2]หน้าผ้า!R23 -> บิด | M14: =[2]หน้าผ้า!T23 -> 19 | N14: =[2]หน้าผ้า!U23 -> 33 | O14: =[2]หน้าผ้า!V23 -> 40 | P14: =[2]หน้าผ้า!AB23 -> 0 | Q14: =[2]หน้าผ้า!AC23 -> 0 | R14: =[2]หน้าผ้า!AD23 -> 0 | S14: =[2]หน้าผ้า!Z23 -> 500กระสอบ | T14: =[2]หน้าผ้า!X23 -> 45944 | U14: =[2]หน้าผ้า!AA23 -> 3000 | V14: =[2]หน้าผ้า!AJ23 -> 3000 | W14: =[2]หน้าผ้า!AL23 -> 0 | X14: =[2]หน้าผ้า!AM23 -> 0 | Y14: =[2]หน้าผ้า!AN23 -> 0 | Z14: =[2]หน้าผ้า!AO23 -> WSWT1825800 | AA14: =[2]หน้าผ้า!AQ23 -> 0 | AB14: =[2]หน้าผ้า!AR23 -> 0 | AC14: =[2]หน้าผ้า!AS23 -> 0 | AD14: =[2]หน้าผ้า!AT23 -> 0 | AE14: =[2]หน้าผ้า!AU23 -> 0 | AF14: =[2]หน้าผ้า!AI23 -> 0 | AG14: =[3]หน้าผ้า!DC26 -> ยังไม่ได้พิมพ์ | AH14: =[2]หน้าผ้า!DL23 -> P9 | AI14: =[2]หน้าผ้า!DM23 -> 3 | AJ14: =[2]หน้าผ้า!DN23 -> 45944 | AK14: =[2]หน้าผ้า!DQ23 -> 0 | AL14: =[2]หน้าผ้า!DR23 -> 45934 | AM14: =[2]หน้าผ้า!DS23 -> 45941 | AN14: =[2]หน้าผ้า!DT23 -> 45942 | AO14: =[2]หน้าผ้า!DU23 -> 45942 | AP14: =[2]หน้าผ้า!DP23 -> 45939 | AQ14: =[2]หน้าผ้า!DW23 -> 45943 | AR14: =[2]หน้าผ้า!DX23 -> 0 | AS14: =[2]หน้าผ้า!DY23 -> 0 | AT14: =[2]หน้าผ้า!DZ23 -> 0 | AU14: =[2]หน้าผ้า!EA23 -> 0 | AV14: =[2]หน้าผ้า!EB23 -> 0 | AW14: =[2]หน้าผ้า!EC23 -> งานพิมพ์ | AX14: =[2]หน้าผ้า!ED23 -> / | AY14: =[2]หน้าผ้า!AG23 -> 0 | AZ14: =[2]หน้าผ้า!EG23 -> 0 | BA14: =[2]หน้าผ้า!EH23 -> 0 | BB14: =[2]หน้าผ้า!EI23 -> 0 | BC14: =[2]หน้าผ้า!BZ23 -> WRWT25800/WRWT25800 | BD14: =[2]หน้าผ้า!CA23 -> 0
A15: =[2]หน้าผ้า!C24 -> 45938 | B15: =[2]หน้าผ้า!B24 -> MK68-001221 | C15: =[2]หน้าผ้า!E24 -> บจก.เอสทีเคมีธุรกืจ | D15: =[2]หน้าผ้า!F24 -> มังกรแดง STCB | E15: =[2]หน้าผ้า!G24 -> 18 | F15: =[2]หน้าผ้า!H24 -> 30 | G15: =[2]หน้าผ้า!I24 -> ขาว | H15: =[2]หน้าผ้า!J24 -> 0 | I15: =[2]หน้าผ้า!L24 -> 54 | J15: =[2]หน้าผ้า!M24 -> ± | K15: =[2]หน้าผ้า!N24 -> 5 | L15: =[2]หน้าผ้า!R24 -> ไม่ | M15: =[2]หน้าผ้า!T24 -> 19 | N15: =[2]หน้าผ้า!U24 -> 31 | O15: =[2]หน้าผ้า!V24 -> 40 | P15: =[2]หน้าผ้า!AB24 -> 145.31171 | Q15: =[2]หน้าผ้า!AC24 -> 0 | R15: =[2]หน้าผ้า!AD24 -> 145.31171 | S15: =[2]หน้าผ้า!Z24 -> 500กระสอบ | T15: =[2]หน้าผ้า!X24 -> 45946 | U15: =[2]หน้าผ้า!AA24 -> 10000 | V15: =[2]หน้าผ้า!AJ24 -> 0 | W15: =[2]หน้าผ้า!AL24 -> 10000 | X15: =[2]หน้าผ้า!AM24 -> 0 | Y15: =[2]หน้าผ้า!AN24 -> 10500 | Z15: =[2]หน้าผ้า!AO24 -> WSWT1825800 | AA15: =[2]หน้าผ้า!AQ24 -> 8801.1 | AB15: =[2]หน้าผ้า!AR24 -> 8801.1 | AC15: =[2]หน้าผ้า!AS24 -> 0 | AD15: =[2]หน้าผ้า!AT24 -> 0 | AE15: =[2]หน้าผ้า!AU24 -> 0 | AF15: =[2]หน้าผ้า!AI24 -> ห้ามเกิน | AG15: =[3]หน้าผ้า!DC27 -> ยังไม่ได้พิมพ์ | AH15: =[2]หน้าผ้า!DL24 -> P9 | AI15: =[2]หน้าผ้า!DM24 -> 3 | AJ15: =[2]หน้าผ้า!DN24 -> 45946 | AK15: =[2]หน้าผ้า!DQ24 -> 0 | AL15: =[2]หน้าผ้า!DR24 -> 45936 | AM15: =[2]หน้าผ้า!DS24 -> 45943 | AN15: =[2]หน้าผ้า!DT24 -> 45944 | AO15: =[2]หน้าผ้า!DU24 -> 45944 | AP15: =[2]หน้าผ้า!DP24 -> 45941 | AQ15: =[2]หน้าผ้า!DW24 -> 45945 | AR15: =[2]หน้าผ้า!DX24 -> 0 | AS15: =[2]หน้าผ้า!DY24 -> 0 | AT15: =[2]หน้าผ้า!DZ24 -> 0 | AU15: =[2]หน้าผ้า!EA24 -> 0 | AV15: =[2]หน้าผ้า!EB24 -> 0 | AW15: =[2]หน้าผ้า!EC24 -> งานพิมพ์ | AX15: =[2]หน้าผ้า!ED24 -> รอART | AY15: =[2]หน้าผ้า!AG24 -> 0 | AZ15: =[2]หน้าผ้า!EG24 -> 0 | BA15: =[2]หน้าผ้า!EH24 -> 0 | BB15: =[2]หน้าผ้า!EI24 -> 0 | BC15: =[2]หน้าผ้า!BZ24 -> WRWT25800/WRWT25800 | BD15: =[2]หน้าผ้า!CA24 -> 0
A16: =[2]หน้าผ้า!C25 -> 45923 | B16: =[2]หน้าผ้า!B25 -> MK68-001161 | C16: =[2]หน้าผ้า!E25 -> หจก.อนนท์อุตสาหกรรม | D16: =[2]หน้าผ้า!F25 -> อนนท์ 20 กก. | E16: =[2]หน้าผ้า!G25 -> 18 | F16: =[2]หน้าผ้า!H25 -> 28 | G16: =[2]หน้าผ้า!I25 -> ขาว | H16: =[2]หน้าผ้า!J25 -> 0 | I16: =[2]หน้าผ้า!L25 -> 50 | J16: =[2]หน้าผ้า!M25 -> ± | K16: =[2]หน้าผ้า!N25 -> 5 | L16: =[2]หน้าผ้า!R25 -> ไม่ | M16: =[2]หน้าผ้า!T25 -> 19 | N16: =[2]หน้าผ้า!U25 -> 31 | O16: =[2]หน้าผ้า!V25 -> 40 | P16: =[2]หน้าผ้า!AB25 -> 0 | Q16: =[2]หน้าผ้า!AC25 -> 0 | R16: =[2]หน้าผ้า!AD25 -> 0 | S16: =[2]หน้าผ้า!Z25 -> 500กระสอบแบน | T16: =[2]หน้าผ้า!X25 -> 45950 | U16: =[2]หน้าผ้า!AA25 -> 5000 | V16: =[2]หน้าผ้า!AJ25 -> 5000 | W16: =[2]หน้าผ้า!AL25 -> 0 | X16: =[2]หน้าผ้า!AM25 -> 5400 | Y16: =[2]หน้าผ้า!AN25 -> 0 | Z16: =[2]หน้าผ้า!AO25 -> WSWT1825800 | AA16: =[2]หน้าผ้า!AQ25 -> 0 | AB16: =[2]หน้าผ้า!AR25 -> 0 | AC16: =[2]หน้าผ้า!AS25 -> 0 | AD16: =[2]หน้าผ้า!AT25 -> 0 | AE16: =[2]หน้าผ้า!AU25 -> 0 | AF16: =[2]หน้าผ้า!AI25 -> 0 | AG16: =[3]หน้าผ้า!DC28 -> ยังไม่ได้พิมพ์ | AH16: =[2]หน้าผ้า!DL25 -> P9 | AI16: =[2]หน้าผ้า!DM25 -> 3 | AJ16: =[2]หน้าผ้า!DN25 -> 45950 | AK16: =[2]หน้าผ้า!DQ25 -> 0 | AL16: =[2]หน้าผ้า!DR25 -> 45940 | AM16: =[2]หน้าผ้า!DS25 -> 45947 | AN16: =[2]หน้าผ้า!DT25 -> 45948 | AO16: =[2]หน้าผ้า!DU25 -> 45948 | AP16: =[2]หน้าผ้า!DP25 -> 45945 | AQ16: =[2]หน้าผ้า!DW25 -> 45949 | AR16: =[2]หน้าผ้า!DX25 -> 0 | AS16: =[2]หน้าผ้า!DY25 -> 0 | AT16: =[2]หน้าผ้า!DZ25 -> 0 | AU16: =[2]หน้าผ้า!EA25 -> 0 | AV16: =[2]หน้าผ้า!EB25 -> 0 | AW16: =[2]หน้าผ้า!EC25 -> งานพิมพ์ | AX16: =[2]หน้าผ้า!ED25 -> / | AY16: =[2]หน้าผ้า!AG25 -> 0 | AZ16: =[2]หน้าผ้า!EG25 -> 0 | BA16: =[2]หน้าผ้า!EH25 -> 0 | BB16: =[2]หน้าผ้า!EI25 -> 0 | BC16: =[2]หน้าผ้า!BZ25 -> WRWT25800/WRWT25800 | BD16: =[2]หน้าผ้า!CA25 -> 0
A17: =[2]หน้าผ้า!C26 -> 45923 | B17: =[2]หน้าผ้า!B26 -> MK68-001162 | C17: =[2]หน้าผ้า!E26 -> หจก.อนนท์อุตสาหกรรม | D17: =[2]หน้าผ้า!F26 -> ดาว 20 กก. | E17: =[2]หน้าผ้า!G26 -> 18 | F17: =[2]หน้าผ้า!H26 -> 28 | G17: =[2]หน้าผ้า!I26 -> ขาว | H17: =[2]หน้าผ้า!J26 -> 0 | I17: =[2]หน้าผ้า!L26 -> 50 | J17: =[2]หน้าผ้า!M26 -> ± | K17: =[2]หน้าผ้า!N26 -> 5 | L17: =[2]หน้าผ้า!R26 -> ไม่ | M17: =[2]หน้าผ้า!T26 -> 19 | N17: =[2]หน้าผ้า!U26 -> 31 | O17: =[2]หน้าผ้า!V26 -> 40 | P17: =[2]หน้าผ้า!AB26 -> 363.27927 | Q17: =[2]หน้าผ้า!AC26 -> 0 | R17: =[2]หน้าผ้า!AD26 -> 363.27927 | S17: =[2]หน้าผ้า!Z26 -> 500กระสอบแบน | T17: =[2]หน้าผ้า!X26 -> 45950 | U17: =[2]หน้าผ้า!AA26 -> 25000 | V17: =[2]หน้าผ้า!AJ26 -> 0 | W17: =[2]หน้าผ้า!AL26 -> 25000 | X17: =[2]หน้าผ้า!AM26 -> 0 | Y17: =[2]หน้าผ้า!AN26 -> 26250 | Z17: =[2]หน้าผ้า!AO26 -> WSWT1825800 | AA17: =[2]หน้าผ้า!AQ26 -> 20605.75 | AB17: =[2]หน้าผ้า!AR26 -> 20605.75 | AC17: =[2]หน้าผ้า!AS26 -> 0 | AD17: =[2]หน้าผ้า!AT26 -> 0 | AE17: =[2]หน้าผ้า!AU26 -> 0 | AF17: =[2]หน้าผ้า!AI26 -> 0 | AG17: =[3]หน้าผ้า!DC29 -> ยังไม่ได้พิมพ์ | AH17: =[2]หน้าผ้า!DL26 -> P9 | AI17: =[2]หน้าผ้า!DM26 -> 3 | AJ17: =[2]หน้าผ้า!DN26 -> 45950 | AK17: =[2]หน้าผ้า!DQ26 -> 0 | AL17: =[2]หน้าผ้า!DR26 -> 45940 | AM17: =[2]หน้าผ้า!DS26 -> 45947 | AN17: =[2]หน้าผ้า!DT26 -> 45948 | AO17: =[2]หน้าผ้า!DU26 -> 45948 | AP17: =[2]หน้าผ้า!DP26 -> 45945 | AQ17: =[2]หน้าผ้า!DW26 -> 45949 | AR17: =[2]หน้าผ้า!DX26 -> 0 | AS17: =[2]หน้าผ้า!DY26 -> 0 | AT17: =[2]หน้าผ้า!DZ26 -> 0 | AU17: =[2]หน้าผ้า!EA26 -> 0 | AV17: =[2]หน้าผ้า!EB26 -> 0 | AW17: =[2]หน้าผ้า!EC26 -> งานพิมพ์ | AX17: =[2]หน้าผ้า!ED26 -> / | AY17: =[2]หน้าผ้า!AG26 -> 0 | AZ17: =[2]หน้าผ้า!EG26 -> 0 | BA17: =[2]หน้าผ้า!EH26 -> 0 | BB17: =[2]หน้าผ้า!EI26 -> 0 | BC17: =[2]หน้าผ้า!BZ26 -> WRWT25800/WRWT25800 | BD17: =[2]หน้าผ้า!CA26 -> 0
... A575: =[2]หน้าผ้า!C584 -> 0 | B575: =[2]หน้าผ้า!B584 -> 0 | C575: =[2]หน้าผ้า!E584 -> 0 | D575: =[2]หน้าผ้า!F584 -> 0 | E575: =[2]หน้าผ้า!G584 -> 0 | F575: =[2]หน้าผ้า!H584 -> 0 | G575: =[2]หน้าผ้า!I584 -> 0 | H575: =[2]หน้าผ้า!J584 -> 0 | I575: =[2]หน้าผ้า!L584 -> 0 | J575: =[2]หน้าผ้า!M584 -> 0 | K575: =[2]หน้าผ้า!N584 -> 0 | L575: =[2]หน้าผ้า!R584 -> 0 | M575: =[2]หน้าผ้า!T584 -> 0 | N575: =[2]หน้าผ้า!U584 -> 0 | O575: =[2]หน้าผ้า!V584 -> 0 | P575: =[2]หน้าผ้า!AB584 -> 0 | Q575: =[2]หน้าผ้า!AC584 -> 0 | R575: =[2]หน้าผ้า!AD584 -> 0 | S575: =[2]หน้าผ้า!Z584 -> 0 | T575: =[2]หน้าผ้า!X584 -> 0 | U575: =[2]หน้าผ้า!AA584 -> 0 | V575: =[2]หน้าผ้า!AJ584 -> 0 | W575: =[2]หน้าผ้า!AL584 -> 0 | X575: =[2]หน้าผ้า!AM584 -> 0 | Y575: =[2]หน้าผ้า!AN584 -> 0 | Z575: =[2]หน้าผ้า!AO584 -> 0 | AA575: =[2]หน้าผ้า!AQ584 -> 0 | AB575: =[2]หน้าผ้า!AR584 -> 0 | AC575: =[2]หน้าผ้า!AS584 -> 0 | AD575: =[2]หน้าผ้า!AT584 -> 0 | AE575: =[2]หน้าผ้า!AU584 -> 0 | AF575: =[2]หน้าผ้า!AI584 -> 0 | AG575: =[3]หน้าผ้า!DC587 -> 0 | AH575: =[2]หน้าผ้า!DL584 -> 0 | AI575: =[2]หน้าผ้า!DM584 -> 0 | AJ575: =[2]หน้าผ้า!DN584 -> 0 | AK575: =[2]หน้าผ้า!DQ584 -> 0 | AL575: =[2]หน้าผ้า!DR584 -> 0 | AM575: =[2]หน้าผ้า!DS584 -> 0 | AN575: =[2]หน้าผ้า!DT584 -> 0 | AO575: =[2]หน้าผ้า!DU584 -> 0 | AP575: =[2]หน้าผ้า!DP584 -> 0 | AQ575: =[2]หน้าผ้า!DW584 -> 0 | AR575: =[2]หน้าผ้า!DX584 -> 0 | AS575: =[2]หน้าผ้า!DY584 -> 0 | AT575: =[2]หน้าผ้า!DZ584 -> 0 | AU575: =[2]หน้าผ้า!EA584 -> 0 | AV575: =[2]หน้าผ้า!EB584 -> 0 | AW575: =[2]หน้าผ้า!EC584 -> 0 | AX575: =[2]หน้าผ้า!ED584 -> 0 | AY575: =[2]หน้าผ้า!AG584 -> 0 | AZ575: =[2]หน้าผ้า!EG584 -> 0 | BA575: =[2]หน้าผ้า!EH584 -> 0 | BB575: =[2]หน้าผ้า!EI584 -> 0 | BC575: =[2]หน้าผ้า!BZ584 -> 0 | BD575: =[2]หน้าผ้า!CA584 -> 0

Sheet 9(Order+FC)
A2: เลขที่ SO | B2: (หลายรายการ)
A3: วันส่ง | B3: (หลายรายการ)
A4: ชื่อลูกค้า | B4: (ทั้งหมด)
K5: 9
A6: ประเภท | B6: ผลรวม ของ จำนวนส่ง | C6: ผลรวม ของ ค้างพิมพ์ | D6: ผลรวม ของ ค้างตัด | E6: ผลรวม ของ ใช้ | F6: ผลรวม ของ Stock | G6: ผลรวม ของ ค้างทอ
A7: WSWT1921720 | B7: 205000 | C7: 0 | D7: 30000 | E7: 0 | F7: 0 | G7: 0 | H7: =+J7-I7 -> 0 | J7: =G7 -> 0
A8: WSWT19251000SM | B8: 5040 | C8: 5292 | D8: 5040 | E8: 4999.0248 | F8: 4999.0248 | G8: 0 | H8: =+J8-I8 -> 0 | J8: =G8 -> 0
A9: WSWT1925800 | B9: 20000 | C9: 21000 | D9: 20000 | E9: 17602.2 | F9: 17602.2 | G9: 0 | H9: =+J9-I9 -> 0 | J9: =G9 -> 0
A10: WSWT2025800 | B10: 89360 | C10: 84000 | D10: 86360 | E10: 83820 | F10: 83820 | G10: 0 | H10: =+J10-I10 -> 0 | J10: =G10 -> 0
A11: WSWT2025800SM | B11: 171120 | C11: 68376 | D11: 72271 | E11: 70323.862 | F11: 70323.862 | G11: 0 | H11: =+J11-I11 -> 0 | J11: =G11 -> 0
A12: WSWT2121670SM | B12: 85000 | C12: 38850 | D12: 64000 | E12: 56774.08 | F12: 56774.08 | G12: 0 | H12: =+J12-I12 -> 0 | J12: =G12 -> 0 | K12: 40000 | L12: =+K5*K12 -> 360000 | M12: =+L12-J12 -> 360000
A13: WSWT2325650 | B13: 60000 | C13: 63000 | D13: 60000 | E13: 59512.2 | F13: 59512.2 | G13: 0 | H13: =+J13-I13 -> 0 | J13: =G13 -> 0 | K13: 14000 | L13: =+K13*K5 -> 126000 | M13: =+L13-J13 -> 126000
A14: WSWT2625650 | B14: 5000 | C14: 0 | D14: 0 | E14: 0 | F14: 0 | G14: 0 | H14: =+J14-I14 -> 0 | J14: =G14 -> 0
A15: WSWT2625800 | B15: 10000 | C15: 0 | D15: 10000 | E15: 12433.3 | F15: 12433.3 | G15: 0 | H15: =+J15-I15 -> 0 | J15: =G15 -> 0 | K15: 20000 | L15: =+K15*K5 -> 180000 | M15: =+L15-J15 -> 180000
A16: WSWT2625850SM | B16: 40000 | C16: 31526.25 | D16: 35900 | E16: 38606.951 | F16: 17295.635 | G16: 21311.316 | H16: =+J16-I16 -> 21311.316 | J16: =G16 -> 21311.316
A17: WSWT2825850 | B17: 105000 | C17: 51765 | D17: 54300 | E17: 65316.735 | F17: 5780 | G17: 59536.735 | H17: =+J17-I17 -> 59536.735 | J17: =G17 -> 59536.735
A18: ผลรวมทั้งหมด | B18: 795520 | C18: 363809.25 | D18: 437871 | E18: 409388.35 | F18: 328540.3 | G18: 80848.051 | H18: =+J18-I18 -> 80848.051 | J18: =G18 -> 80848.051
H19: 0 | I19: 54000 | J19: =G19 -> 0
H20: =+J20-I20 -> 0 | J20: =G20 -> 0
H21: =+J21-I21 -> 0 | J21: =G21 -> 0
H22: =+J22-I22 -> 0 | J22: =G22 -> 0
H23: =+J23-I23 -> 0 | J23: =G23 -> 0
H24: =+J24-I24 -> 0 | J24: =G24 -> 0
H25: =+J25-I25 -> 0 | J25: =G25 -> 0
H26: =+J26-I26 -> 0 | J26: =G26 -> 0
H27: =+J27-I27 -> 0 | J27: =G27 -> 0
H28: =+J28-I28 -> 0 | J28: =G28 -> 0 | M28: =+GETPIVOTDATA("ผลรวม ของ ใช้",$A$6)+H29+H33 -> 661084.45
H29: =SUM(H7:H28) -> 161696.1 | I29: =SUM(I7:I28) -> 54000 | J29: =SUM(J7:J28) -> 161696.1
H32: =+H26 -> 0 | I32: 85 | J32: =+(H32+H29)*I32 -> 13744169 | K32: =+J32/1000 -> 13744.169
H33: 90000 | I33: 95 | J33: =+H33*I33 -> 8550000 | K33: =+J33/1000 -> 8550
H35: =+H32+H33+H29 -> 251696.1 | K35: =+K32+K33 -> 22294.169
N36: 705222
A37: ยอดส่ง 1/2/68 - 17/2/68 | B37: 1565717 | H37: 15 | I37: =+H35/H37 -> 16779.74
N38: =+H35+N36 -> 956918.1
I39: =+H37*110000 -> 1650000
B41: =+B29+B37+B31-110000 -> 1455717 | C41: =+C29+C37+C31 -> 0 | D41: =+D29+D37+D31-110000 -> -110000 | E41: =+E29+E37+E31 -> 0 | F41: =+F29+F37+F31 -> 0 | G41: =+G29+G37+G31 -> 0
B43: 3218150
B45: =+B43-B41 -> 1762433
C47: =+C41/9 -> 0 | D47: =+D41/9 -> -12222.222

Sheet 9(Order)
A2: เลขที่ SO | B2: (ทั้งหมด)
A3: วันส่ง | B3: 45930
A4: ชื่อลูกค้า | B4: (ทั้งหมด)
A6: ประเภท | B6: ผลรวม ของ จำนวนส่ง | C6: ผลรวม ของ ค้างพิมพ์ | D6: ผลรวม ของ ค้างตัด | E6: ผลรวม ของ ใช้ | F6: ผลรวม ของ Stock | G6: ผลรวม ของ ค้างทอ
A7: WSWT1825800 | B7: 5000 | C7: 0 | D7: 0 | E7: 0 | F7: 0 | G7: 0
A8: WSWT1921720 | B8: 25000 | C8: 0 | D8: 73 | E8: 0 | F8: 0 | G8: 0
A9: WSWT2025800SM | B9: 5000 | C9: 0 | D9: 0 | E9: 0 | F9: 0 | G9: 0
A10: WSWT2121670SM | B10: 10000 | C10: 0 | D10: 16 | E10: 0 | F10: 0 | G10: 0
A11: WSWT2625650 | B11: 5000 | C11: 0 | D11: 0 | E11: 0 | F11: 0 | G11: 0
A12: ผลรวมทั้งหมด | B12: 50000 | C12: 0 | D12: 89 | E12: 0 | F12: 0 | G12: 0
D34: =D18 -> 0
D36: =D20 -> 0
A37: ยอดส่ง 1/4/68 - 12/4/68 | B37: 887615
A38: Order+ส่ง | B38: =++B25+B37 -> 887615
A39: ประมาณการ | B39: 262000 | C39: 238350 | D39: 262000 | E39: 279847.04 | F39: 60825.09 | G39: 219021.95
A41: Order+ส่ง+ประมาณการ | B41: =+B25+B37+B39+B33 -> 1149615 | C41: =+C25+C37+C39+C33 -> 238350 | D41: =+D25+D37+D39+D33 -> 262000 | E41: =+E25+E37+E39+E33 -> 279847.04 | F41: =+F25+F37+F39+F33 -> 60825.09 | G41: =+G25+G37+G39+G33 -> 219021.95
B43: 3171376
B45: =+B41-B43 -> -2021761 | C45: =+$B$45 -> -2021761 | D45: =+$B$45 -> -2021761 | F45: =+$B$45 -> -2021761
D47: =+D41/6 -> 43666.667

Sheet 9(Order) แยกลูกค้า
A1: เลขที่ SO | B1: (หลายรายการ)
A2: วันส่ง | B2: (หลายรายการ)
A4: ประเภท | B4: ชื่อลูกค้า | C4: ผลรวม ของ จำนวนส่ง | D4: ผลรวม ของ ค้างพิมพ์ | E4: ผลรวม ของ ค้างตัด | F4: ผลรวม ของ Stock | G4: ผลรวม ของ ค้างทอ | I4: vn
A5: WSWT2025650 | B5: บจก.หนองบัวฟีด | C5: 10000 | D5: 0 | E5: 10000 | F5: 4400 | G5: 4401.1 | H5: =G5 -> 4401.1
A6: WSWT2025650 ผลรวม | C6: 10000 | D6: 0 | E6: 10000 | F6: 4400 | G6: 4401.1 | H6: =G6 -> 4401.1
A7: WSWT2025800SM | B7: บจก.เอ.เจ.ฟาร์ม่าแล็บ | C7: 8000 | D7: 0 | E7: 25 | F7: 0 | G7: 0 | H7: =G7 -> 0
A8: WSWT2025800SM ผลรวม | C8: 8000 | D8: 0 | E8: 25 | F8: 0 | G8: 0 | H8: =G8 -> 0
A9: WSWT2121670SM | B9: บจก.เอพีเอ็ม อะโกร | C9: 3000 | D9: 0 | E9: 0 | F9: 0 | G9: 0 | H9: =G9 -> 0
B10: บจก.หนองบัวฟีด | C10: 10000 | D10: 10500 | E10: 10000 | F10: 10756.9 | G10: 0 | H10: =G10 -> 0
A11: WSWT2121670SM ผลรวม | C11: 13000 | D11: 10500 | E11: 10000 | F11: 10756.9 | G11: 0 | H11: =G11 -> 0
A12: ผลรวมทั้งหมด | C12: 31000 | D12: 10500 | E12: 20025 | F12: 15156.9 | G12: 4401.1 | H12: =G12 -> 4401.1
H13: =G13 -> 0
H14: =G14 -> 0
H15: =G15 -> 0
H16: =G16 -> 0
H17: =G17 -> 0
H18: =G18 -> 0
H19: =G19 -> 0
H20: =G20 -> 0
H21: =G21 -> 0
H22: =G22 -> 0
H23: =G23 -> 0
H24: =G24 -> 0
... H65: =G65 -> 0
H70: =SUM(H5:H69) -> 13203.3
D119: Cap พิมพ์ | E119: Cap ตัด | F119: Stock 16/7 บ่าย | G119: Cap ทอ | I119: วันทงาน
B120: lส่ง | C120: 1-16/7 | D120: 160000 | E120: 160000 | G120: 120000 | I120: 12
C121: 1975256 | D121: =+D120*I120 -> 1920000 | E121: =+E120*I120 -> 1920000 | F121: 825147 | G121: =+G120*I120 -> 1440000
A122: เบทาโกรส่งแล้ว | B122: 20700 | C122: 424374
A123: เบทาโกรส่งแล้ว | B123: 20800 | C123: 155973
C126: รวมส่ง+ค้างส่ง | D126: ส่วนต่างCapคงเหลือ | E126: ส่วนต่างCapคงเหลือ | F126: คงเหลือ
C127: =+C50+C121 -> 1975256 | D127: =+D121-D50 -> 1920000 | E127: =+E121-E50 -> 1920000 | F127: =+F121-F50 -> 825147 | G127: =+G121-G50 -> 1440000
B129: 20700VN 20/7 | G129: 350000

Sheet 9(Fc) แยกลูกค้า
A1: เลขที่ SO | B1: ประมาณการ
A2: วันส่ง | B2: (หลายรายการ) | D2: 12
A4: ประเภท | B4: ชื่อลูกค้า | C4: ผลรวม ของ จำนวนส่ง | D4: ผลรวม ของ ค้างพิมพ์ | E4: ผลรวม ของ ค้างตัด | F4: ผลรวม ของ ใช้ | G4: ผลรวม ของ Stock | H4: ผลรวม ของ ค้างทอ
A5: WSWT1921720 | B5: บจก.เคอรี่ฟลาวมิลล์ | C5: 225000 | D5: 236250 | E5: 225000 | F5: 210597.75 | G5: 0 | H5: 210597.75
A6: WSWT1921720 ผลรวม | C6: 225000 | D6: 236250 | E6: 225000 | F6: 210597.75 | G6: 0 | H6: 210597.75
A7: WSWT1925800 | B7: บจก.เพรซิเดนท์ฟลาวมิลล์ | C7: 140000 | D7: 147000 | E7: 140000 | F7: 123215.4 | G7: 0 | H7: 123215.4
B8: บจก.ไลม์มาสเตอร์ | C8: 20000 | D8: 20755.35 | E8: 19767 | F8: 18501.714 | G8: 0 | H8: 18501.714
B9: บจก.เอ็กเซลเล้นท์ | C9: 40000 | D9: 42000 | E9: 40000 | F9: 35204.4 | G9: 0 | H9: 35204.4
A10: WSWT1925800 ผลรวม | C10: 200000 | D10: 209755.35 | E10: 199767 | F10: 176921.51 | G10: 0 | H10: 176921.51
A11: WSWT2025800 | B11: บจก.อินเทคค์ โกลบอล | C11: 290000 | D11: 304500 | E11: 290000 | F11: 303847.5 | G11: 0 | H11: 303847.5
A12: WSWT2025800 ผลรวม | C12: 290000 | D12: 304500 | E12: 290000 | F12: 303847.5 | G12: 0 | H12: 303847.5
A13: WSWT2025800SM | B13: บจก.ไทยธรรมดี | C13: 20000 | D13: 21000 | E13: 20000 | F13: 21513.8 | G13: 0 | H13: 21513.8
B14: บจก.อินเทคค์ โกลบอล | C14: 100000 | D14: 105000 | E14: 100000 | F14: 104775 | G14: 0 | H14: 104775
B15: บจก.เอสพีเอ็ม อาหารสัตว์ | C15: 20000 | D15: 21000 | E15: 20000 | F15: 22072.6 | G15: 0 | H15: 22072.6
B16: บจก.ซันฟีด | C16: 305000 | D16: 320250 | E16: 305000 | F16: 336607.15 | G16: 0 | H16: 336607.15
A17: WSWT2025800SM ผลรวม | C17: 445000 | D17: 467250 | E17: 445000 | F17: 484968.55 | G17: 0 | H17: 484968.55
A18: WSWT2325650 | B18: พันธุ์ข้าว | C18: 30000 | D18: 31500 | E18: 30000 | F18: 29756.1 | G18: 29756.1 | H18: 0
A19: WSWT2325650 ผลรวม | C19: 30000 | D19: 31500 | E19: 30000 | F19: 29756.1 | G19: 29756.1 | H19: 0
A20: WSWT2625800 | B20: บจก.ที.ซี.ยูเนี่ยน อโกรเทค | C20: 10000 | D20: 0 | E20: 10000 | F20: 12433.3 | G20: 12433.3 | H20: 0
A21: WSWT2625800 ผลรวม | C21: 10000 | D21: 0 | E21: 10000 | F21: 12433.3 | G21: 12433.3 | H21: 0
A22: WSWT2825850 | B22: บจก.ที.ซี.ยูเนี่ยน อโกรเทค | C22: 5000 | D22: 0 | E22: 5000 | F22: 6775.45 | G22: 0 | H22: 6775.45
A23: WSWT2825850 ผลรวม | C23: 5000 | D23: 0 | E23: 5000 | F23: 6775.45 | G23: 0 | H23: 6775.45
A24: ผลรวมทั้งหมด | C24: 1205000 | D24: 1249255.4 | E24: 1204767 | F24: 1225300.2 | G24: 42189.4 | H24: 1183110.8
D119: Cap พิมพ์ | E119: Cap ตัด | F119: Stock 16/7 บ่าย | G119: Cap ทอ | I119: วันทงาน
B120: lส่ง | C120: 1-16/7 | D120: 160000 | E120: 160000 | G120: 120000 | I120: 12
C121: 1975256 | D121: =+D120*I120 -> 1920000 | E121: =+E120*I120 -> 1920000 | F121: 825147 | G121: =+G120*I120 -> 1440000
A122: เบทาโกรส่งแล้ว | B122: 20700 | C122: 424374
A123: เบทาโกรส่งแล้ว | B123: 20800 | C123: 155973
C126: รวมส่ง+ค้างส่ง | D126: ส่วนต่างCapคงเหลือ | E126: ส่วนต่างCapคงเหลือ | F126: คงเหลือ
C127: =+C50+C121 -> 1975256 | D127: =+D121-D50 -> 1920000 | E127: =+E121-E50 -> 1920000 | F127: =+F121-F50 -> 825147 | G127: =+G121-G50 -> 1440000
B129: 20700VN 20/7 | G129: 350000

Sheet 10(Order+Fc) แยกลูกค้า
A1: เลขที่ SO | B1: (หลายรายการ)
A2: วันส่ง | B2: (หลายรายการ) | D2: 12 | I2: เมตร | J2: vn | K2: ใบ | P2: วัน
A4: ประเภท | B4: ชื่อลูกค้า | C4: ผลรวม ของ จำนวนส่ง | D4: ผลรวม ของ ค้างพิมพ์ | E4: ผลรวม ของ ค้างตัด | F4: ผลรวม ของ ใช้ | G4: ผลรวม ของ Stock | H4: ผลรวม ของ ค้างทอ
A5: WSWT1625800 | B5: บจก.เคอรี่ฟลาวมิลล์ | C5: 5000 | D5: 5250 | E5: 5000 | F5: 3702.05 | G5: 3702.05 | H5: 0 | I5: =H5 -> 0
A6: WSWT1625800 ผลรวม | C6: 5000 | D6: 5250 | E6: 5000 | F6: 3702.05 | G6: 3702.05 | H6: 0
A7: WSWT1825800 | B7: บจก.ฟาร์เธอร์ส วิง ซัพพลาย | C7: 18000 | D7: 0 | E7: 0 | F7: 0 | G7: 0 | H7: 0 | I7: =H7 -> 0
B8: หจก.อนนท์อุตสาหกรรม | C8: 105000 | D8: 105000 | E8: 100000 | F8: 82423 | G8: 82423 | H8: 0 | I8: =H8 -> 0
B9: บจก.เอสทีเคมีธุรกืจ | C9: 10000 | D9: 10500 | E9: 10000 | F9: 8801.1 | G9: 8801.1 | H9: 0 | I9: =H9 -> 0
A10: WSWT1825800 ผลรวม | C10: 133000 | D10: 115500 | E10: 110000 | F10: 91224.1 | G10: 91224.1 | H10: 0 | I10: =H10 -> 0
A11: WSWT1921720 | B11: บจก.เคอรี่ฟลาวมิลล์ | C11: 465000 | D11: 357000 | E11: 377000 | F11: 336956.4 | G11: 43182.55 | H11: 293773.85
A12: WSWT1921720 ผลรวม | C12: 465000 | D12: 357000 | E12: 377000 | F12: 336956.4 | G12: 43182.55 | H12: 293773.85 | I12: =H12 -> 293773.85
A13: WSWT1925800 | B13: บจก.เพรซิเดนท์ฟลาวมิลล์ | C13: 160000 | D13: 144308.85 | E13: 154806 | F13: 120959.68 | G13: 0 | H13: 120959.68
B14: บจก.ไลม์มาสเตอร์ | C14: 20000 | D14: 20755.35 | E14: 19767 | F14: 18501.714 | G14: 2540 | H14: 15961.714 | I14: =H14 -> 15961.714 | P14: 15000 | Q14: =+K14/P14 -> 0
B15: บจก.เอ็กเซลเล้นท์ | C15: 40000 | D15: 42000 | E15: 40000 | F15: 35204.4 | G15: 0 | H15: 35204.4
A16: WSWT1925800 ผลรวม | C16: 220000 | D16: 207064.2 | E16: 214573 | F16: 174665.79 | G16: 2540 | H16: 172125.79 | I16: =H16 -> 172125.79
A17: WSWT2025800 | B17: บจก.เคอรี่ฟลาวมิลล์ | C17: 15000 | D17: 15750 | E17: 15000 | F17: 14039.85 | G17: 14039.85 | H17: 0 | I17: =H17 -> 0
B18: บจก.อินเทคค์ โกลบอล | C18: 343880 | D18: 304500 | E18: 313440 | F18: 303847.5 | G18: 1477 | H18: 302370.5 | I18: =H18 -> 302370.5
A19: WSWT2025800 ผลรวม | C19: 358880 | D19: 320250 | E19: 328440 | F19: 317887.35 | G19: 15516.85 | H19: 302370.5 | I19: =H19 -> 302370.5
A20: WSWT2025800SM | B20: บจก.ไทยธรรมดี | C20: 20000 | D20: 21000 | E20: 20000 | F20: 21513.8 | G20: 0 | H20: 21513.8 | I20: =H20 -> 21513.8 | P20: 16000 | Q20: =+K20/P20 -> 0
B21: บจก.อินเทคค์ โกลบอล | C21: 111063 | D21: 105000 | E21: 110538 | F21: 104775 | G21: 0 | H21: 104775
B22: บจก.เอพีเอ็ม อะโกร | C22: 20000 | D22: 12600 | E22: 16000 | F22: 13411.2 | G22: 13411.2 | H22: 0 | I22: =H22 -> 0
B23: บจก.เอสพีเอ็ม อาหารสัตว์ | C23: 56500 | D23: 39900 | E23: 39022 | F23: 41937.94 | G23: 19865.34 | H23: 22072.6
B24: บจก.วีซีเอฟ | C24: 20000 | D24: 0 | E24: 2689 | F24: 0 | G24: 0 | H24: 0 | I24: =H24 -> 0
B25: บจก.ซันฟีด | C25: 394000 | D25: 346500 | E25: 335313 | F25: 364058.2 | G25: 9620.375 | H25: 354437.82
B26: คุณฐนวรวรรศณ์ ภัทรนนท์สกุล | C26: 5000 | D26: 0 | E26: 0 | F26: 0 | G26: 0 | H26: 0 | I26: =H26 -> 0
B27: บจก.มารีน ลีดเดอร์ | C27: 10000 | D27: 0 | E27: 0 | F27: 0 | G27: 0 | H27: 0
A28: WSWT2025800SM ผลรวม | C28: 636563 | D28: 525000 | E28: 523562 | F28: 545696.14 | G28: 42896.915 | H28: 502799.22 | I28: =H28 -> 502799.22
A29: WSWT2025850 | B29: บจก.ซันฟีด | C29: 262500 | D29: 165375 | E29: 227180 | F29: 175148.88 | G29: 136661.53 | H29: 38487.35 | I29: =H29 -> 38487.35
A30: WSWT2025850 ผลรวม | C30: 262500 | D30: 165375 | E30: 227180 | F30: 175148.88 | G30: 136661.53 | H30: 38487.35 | I30: =H30 -> 38487.35
A31: WSWT2121670SM | B31: บจก.เอพีเอ็ม อะโกร | C31: 3000 | D31: 0 | E31: 0 | F31: 0 | G31: 0 | H31: 0 | P31: 15000 | Q31: =+K31/P31 -> 0
B32: บจก.เอสพีเอ็ม อาหารสัตว์ | C32: 3000 | D32: 0 | E32: 0 | F32: 0 | G32: 0 | H32: 0 | I32: =H32 -> 0
B33: บจก.แอมโก้เวท | C33: 65000 | D33: 31500 | E33: 40000 | F33: 37649.15 | G33: 37649.15 | H33: 0 | I33: =H33 -> 0
B34: คุณนพวินทร์ รัตนเศรษฐ์เมธา | C34: 5000 | D34: 0 | E34: 263 | F34: 0 | G34: 0 | H34: 0 | I34: =H34 -> 0
A35: WSWT2121670SM ผลรวม | C35: 76000 | D35: 31500 | E35: 40263 | F35: 37649.15 | G35: 37649.15 | H35: 0 | I35: =H35 -> 0
A36: WSWT2321750 | B36: บจก.เอสพีเอ็ม อาหารสัตว์ | C36: 9000 | D36: 6300 | E36: 9000 | F36: 6621.78 | G36: 6621.78 | H36: 0 | I36: =H36 -> 0
B37: บจก.แอมโก้เวท | C37: 5000 | D37: 0 | E37: 5000 | F37: 5797.55 | G37: 0 | H37: 5797.55 | I37: =H37 -> 5797.55
A38: WSWT2321750 ผลรวม | C38: 14000 | D38: 6300 | E38: 14000 | F38: 12419.33 | G38: 6621.78 | H38: 5797.55 | I38: =H38 -> 5797.55
A39: WSWT2325650 | B39: พันธุ์ข้าว | C39: 30000 | D39: 31500 | E39: 30000 | F39: 29756.1 | G39: 29756.1 | H39: 0 | I39: =H39 -> 0
A40: WSWT2325650 ผลรวม | C40: 30000 | D40: 31500 | E40: 30000 | F40: 29756.1 | G40: 29756.1 | H40: 0 | I40: =H40 -> 0
A41: WSWT24211125120 | B41: หจก.อนนท์อุตสาหกรรม | C41: 10000 | D41: 0 | E41: 0 | F41: 0 | G41: 0 | H41: 0
...

Sheet 10(Order)
A2: เลขที่ SO | B2: (หลายรายการ)
A3: วันส่ง | B3: (หลายรายการ)
A4: ชื่อลูกค้า | B4: (ทั้งหมด)
A6: ประเภท | B6: ผลรวม ของ จำนวนส่ง | C6: ผลรวม ของ ค้างพิมพ์ | D6: ผลรวม ของ ค้างตัด | E6: ผลรวม ของ ใช้ | F6: ผลรวม ของ Stock | G6: ผลรวม ของ ค้างทอ
A7: WSWT1625800 | B7: 5000 | C7: 5250 | D7: 5000 | E7: 3702.05 | F7: 3702.05 | G7: 0
A8: WSWT1825800 | B8: 133000 | C8: 115500 | D8: 110000 | E8: 91224.1 | F8: 91224.1 | G8: 0
A9: WSWT1921720 | B9: 240000 | C9: 120750 | D9: 152000 | E9: 126358.65 | F9: 43182.55 | G9: 83176.1
A10: WSWT1925800 | B10: 20000 | C10: 0 | D10: 17369 | E10: 0 | F10: 0 | G10: 0 | K10: =25*32.24 -> 806
A11: WSWT2025800 | B11: 68880 | C11: 15750 | D11: 38440 | E11: 14039.85 | F11: 14039.85 | G11: 0 | L11: =76*2500 -> 190000
A12: WSWT2025800SM | B12: 191563 | C12: 57750 | D12: 78562 | E12: 60727.59 | F12: 42896.915 | G12: 17830.675
A13: WSWT2025850 | B13: 262500 | C13: 165375 | D13: 227180 | E13: 175148.88 | F13: 136661.53 | G13: 38487.35
A14: WSWT2121670SM | B14: 76000 | C14: 31500 | D14: 40263 | E14: 37649.15 | F14: 37649.15 | G14: 0
A15: WSWT2321750 | B15: 14000 | C15: 6300 | D15: 14000 | E15: 12419.33 | F15: 6621.78 | G15: 5797.55
A16: WSWT24211125120 | B16: 10000 | C16: 0 | D16: 0 | E16: 0 | F16: 0 | G16: 0
A17: WSWT262575051 | B17: 10000 | C17: 0 | D17: 0 | E17: 0 | F17: 0 | G17: 0
A18: WSWT2625800 | B18: 20122 | C18: 10500 | D18: 10000 | E18: 11595.1 | F18: 3750 | G18: 7845.1
A19: WSWT2625850SM | B19: 40000 | C19: 0 | D19: 21575 | E19: 18649.95 | F19: 18649.95 | G19: 0
A20: WSWT2825850 | B20: 5000 | C20: 0 | D20: 5000 | E20: 5657.85 | F20: 5657.85 | G20: 0
A21: ผลรวมทั้งหมด | B21: 1096065 | C21: 528675 | D21: 719389 | E21: 557172.5 | F21: 404035.72 | G21: 153136.77
A37: ยอดส่ง 1/1/68 - 17/1/68 | B37: 1287052
A38: Order+ส่ง | B38: =++B22+B37 -> 1287052
A39: ประมาณการ | I39: 0
A41: Order+ส่ง+ประมาณการ | B41: =+B22+B37+B39+B29 -> 1287052 | C41: =+C22+C37+C39+C29 -> 0 | D41: =+D22+D37+D39+D29 -> 0 | E41: =+E22+E37+E39+E29 -> 0 | F41: =+F22+F37+F39+F29 -> 0 | G41: =+G22+G37+G39+G29 -> 0
B43: 3000000 | I43: 9
B45: =+B41-B43 -> -1712948
D46: =+D22/I43 -> 0
C47: =+C41/I43 -> 0 | D47: =+D41/I43 -> 0 | G47: =+G41/I43 -> 0

Sheet 10(Order) แยกลูกค้า
A1: เลขที่ SO | B1: (หลายรายการ)
A2: วันส่ง | B2: (หลายรายการ)
A4: ประเภท | B4: ชื่อลูกค้า | C4: ผลรวม ของ จำนวนส่ง | D4: ผลรวม ของ ค้างพิมพ์ | E4: ผลรวม ของ ค้างตัด | F4: ผลรวม ของ Stock | G4: ผลรวม ของ ค้างทอ | I4: vn
A5: WSWT1825800 | B5: บจก.ฟาร์เธอร์ส วิง ซัพพลาย | C5: 18000 | D5: 0 | E5: 0 | F5: 0 | G5: 0 | H5: =G5 -> 0
B6: หจก.อนนท์อุตสาหกรรม | C6: 105000 | D6: 105000 | E6: 100000 | F6: 82423 | G6: 0 | H6: =G6 -> 0
A7: WSWT1825800 ผลรวม | C7: 123000 | D7: 105000 | E7: 100000 | F7: 82423 | G7: 0 | H7: =G7 -> 0
A8: WSWT1921720 | B8: บจก.เคอรี่ฟลาวมิลล์ | C8: 90000 | D8: 0 | E8: 2000 | F8: 0 | G8: 0
A9: WSWT1921720 ผลรวม | C9: 90000 | D9: 0 | E9: 2000 | F9: 0 | G9: 0 | H9: =G9 -> 0
A10: WSWT1925800 | B10: บจก.เพรซิเดนท์ฟลาวมิลล์ | C10: 20000 | D10: 0 | E10: 17369 | F10: 0 | G10: 0 | H10: =G10 -> 0
A11: WSWT1925800 ผลรวม | C11: 20000 | D11: 0 | E11: 17369 | F11: 0 | G11: 0
A12: WSWT2025800 | B12: บจก.อินเทคค์ โกลบอล | C12: 53880 | D12: 0 | E12: 23440 | F12: 0 | G12: 0 | H12: =G12 -> 0
A13: WSWT2025800 ผลรวม | C13: 53880 | D13: 0 | E13: 23440 | F13: 0 | G13: 0 | H13: =G13 -> 0
A14: WSWT2025800SM | B14: บจก.อินเทคค์ โกลบอล | C14: 983 | D14: 0 | E14: 458 | F14: 0 | G14: 0 | H14: =G14 -> 0
B15: บจก.เอพีเอ็ม อะโกร | C15: 20000 | D15: 12600 | E15: 16000 | F15: 13411.2 | G15: 0
B16: บจก.เอสพีเอ็ม อาหารสัตว์ | C16: 27500 | D16: 9450 | E16: 10022 | F16: 9932.67 | G16: 0 | H16: =G16 -> 0
B17: บจก.วีซีเอฟ | C17: 20000 | D17: 0 | E17: 2689 | F17: 0 | G17: 0
B18: บจก.ซันฟีด | C18: 89000 | D18: 26250 | E18: 30313 | F18: 9620.375 | G18: 17830.675 | H18: =G18 -> 17830.675
B19: คุณฐนวรวรรศณ์ ภัทรนนท์สกุล | C19: 5000 | D19: 0 | E19: 0 | F19: 0 | G19: 0 | H19: =G19 -> 0
B20: บจก.มารีน ลีดเดอร์ | C20: 10000 | D20: 0 | E20: 0 | F20: 0 | G20: 0 | H20: =G20 -> 0
A21: WSWT2025800SM ผลรวม | C21: 172483 | D21: 48300 | E21: 59482 | F21: 32964.245 | G21: 17830.675 | H21: =G21 -> 17830.675
A22: WSWT2025850 | B22: บจก.ซันฟีด | C22: 262500 | D22: 165375 | E22: 227180 | F22: 136661.53 | G22: 38487.35
A23: WSWT2025850 ผลรวม | C23: 262500 | D23: 165375 | E23: 227180 | F23: 136661.53 | G23: 38487.35 | H23: =G23 -> 38487.35
A24: WSWT2121670SM | B24: บจก.แอมโก้เวท | C24: 35000 | D24: 31500 | E24: 35000 | F24: 37649.15 | G24: 0
B25: คุณนพวินทร์ รัตนเศรษฐ์เมธา | C25: 5000 | D25: 0 | E25: 263 | F25: 0 | G25: 0 | H25: =G25 -> 0
A26: WSWT2121670SM ผลรวม | C26: 40000 | D26: 31500 | E26: 35263 | F26: 37649.15 | G26: 0
A27: WSWT2321750 | B27: บจก.แอมโก้เวท | C27: 5000 | D27: 0 | E27: 5000 | F27: 0 | G27: 5797.55 | H27: =G27 -> 5797.55
A28: WSWT2321750 ผลรวม | C28: 5000 | D28: 0 | E28: 5000 | F28: 0 | G28: 5797.55 | H28: =G28 -> 5797.55
A29: WSWT24211125120 | B29: หจก.อนนท์อุตสาหกรรม | C29: 10000 | D29: 0 | E29: 0 | F29: 0 | G29: 0 | H29: =G29 -> 0
A30: WSWT24211125120 ผลรวม | C30: 10000 | D30: 0 | E30: 0 | F30: 0 | G30: 0
A31: WSWT2625800 | B31: บจก.ที.ซี.ยูเนี่ยน อโกรเทค | C31: 10122 | D31: 0 | E31: 0 | F31: 0 | G31: 0 | H31: =G31 -> 0
A32: WSWT2625800 ผลรวม | C32: 10122 | D32: 0 | E32: 0 | F32: 0 | G32: 0 | H32: =G32 -> 0
A33: WSWT2625850SM | B33: บจก.ที.ซี.ยูเนี่ยน อโกรเทค | C33: 40000 | D33: 0 | E33: 21575 | F33: 18649.95 | G33: 0 | H33: =G33 -> 0
A34: WSWT2625850SM ผลรวม | C34: 40000 | D34: 0 | E34: 21575 | F34: 18649.95 | G34: 0 | H34: =G34 -> 0
A35: WSWT2825850 | B35: บจก.ไซแอนท์ | C35: 5000 | D35: 0 | E35: 5000 | F35: 5657.85 | G35: 0 | H35: =G35 -> 0
A36: WSWT2825850 ผลรวม | C36: 5000 | D36: 0 | E36: 5000 | F36: 5657.85 | G36: 0 | H36: =G36 -> 0
A37: ผลรวมทั้งหมด | C37: 831985 | D37: 350175 | E37: 496309 | F37: 314005.72 | G37: 62115.575 | H37: =G37 -> 62115.575
H38: =G38 -> 0
H39: =G39 -> 0
H41: =G41 -> 0
H42: =G42 -> 0
...

Sheet 10(Fc) แยกลูกค้
A1: เลขที่ SO | B1: ประมาณการ
A2: วันส่ง | B2: (หลายรายการ) | D2: 12
A4: ประเภท | B4: ชื่อลูกค้า | C4: ผลรวม ของ จำนวนส่ง | D4: ผลรวม ของ ค้างพิมพ์ | E4: ผลรวม ของ ค้างตัด | F4: ผลรวม ของ ใช้ | G4: ผลรวม ของ Stock | H4: ผลรวม ของ ค้างทอ
A5: WSWT1921720 | B5: บจก.เคอรี่ฟลาวมิลล์ | C5: 225000 | D5: 236250 | E5: 225000 | F5: 210597.75 | G5: 0 | H5: 210597.75
A6: WSWT1921720 ผลรวม | C6: 225000 | D6: 236250 | E6: 225000 | F6: 210597.75 | G6: 0 | H6: 210597.75
A7: WSWT1925800 | B7: บจก.เพรซิเดนท์ฟลาวมิลล์ | C7: 140000 | D7: 144308.85 | E7: 137437 | F7: 120959.68 | G7: 0 | H7: 120959.68
B8: บจก.ไลม์มาสเตอร์ | C8: 20000 | D8: 20755.35 | E8: 19767 | F8: 18501.714 | G8: 2540 | H8: 15961.714
B9: บจก.เอ็กเซลเล้นท์ | C9: 40000 | D9: 42000 | E9: 40000 | F9: 35204.4 | G9: 0 | H9: 35204.4
A10: WSWT1925800 ผลรวม | C10: 200000 | D10: 207064.2 | E10: 197204 | F10: 174665.79 | G10: 2540 | H10: 172125.79
A11: WSWT2025800 | B11: บจก.อินเทคค์ โกลบอล | C11: 290000 | D11: 304500 | E11: 290000 | F11: 303847.5 | G11: 1477 | H11: 302370.5
A12: WSWT2025800 ผลรวม | C12: 290000 | D12: 304500 | E12: 290000 | F12: 303847.5 | G12: 1477 | H12: 302370.5
A13: WSWT2025800SM | B13: บจก.ไทยธรรมดี | C13: 20000 | D13: 21000 | E13: 20000 | F13: 21513.8 | G13: 0 | H13: 21513.8
B14: บจก.อินเทคค์ โกลบอล | C14: 100000 | D14: 105000 | E14: 100000 | F14: 104775 | G14: 0 | H14: 104775
B15: บจก.เอสพีเอ็ม อาหารสัตว์ | C15: 20000 | D15: 21000 | E15: 20000 | F15: 22072.6 | G15: 0 | H15: 22072.6
B16: บจก.ซันฟีด | C16: 305000 | D16: 320250 | E16: 305000 | F16: 336607.15 | G16: 0 | H16: 336607.15
A17: WSWT2025800SM ผลรวม | C17: 445000 | D17: 467250 | E17: 445000 | F17: 484968.55 | G17: 0 | H17: 484968.55
A18: WSWT2325650 | B18: พันธุ์ข้าว | C18: 30000 | D18: 31500 | E18: 30000 | F18: 29756.1 | G18: 29756.1 | H18: 0
A19: WSWT2325650 ผลรวม | C19: 30000 | D19: 31500 | E19: 30000 | F19: 29756.1 | G19: 29756.1 | H19: 0
A20: WSWT2825850 | B20: บจก.ที.ซี.ยูเนี่ยน อโกรเทค | C20: 5000 | D20: 0 | E20: 5000 | F20: 6775.45 | G20: 6775.45 | H20: 0
B21: บจก.ไทยร่วมใจน้ำมันพืช | C21: 50000 | D21: 52500 | E21: 50000 | F21: 59372.5 | G21: 41284 | H21: 18088.5
A22: WSWT2825850 ผลรวม | C22: 55000 | D22: 52500 | E22: 55000 | F22: 66147.95 | G22: 48059.45 | H22: 18088.5
A23: ผลรวมทั้งหมด | C23: 1245000 | D23: 1299064.2 | E23: 1242204 | F23: 1269983.6 | G23: 81832.55 | H23: 1188151.1
I119: วันทงาน
I120: 12
C121: 1975256 | D121: =+D120*I120 -> 0 | E121: =+E120*I120 -> 0 | F121: 825147 | G121: =+G120*I120 -> 0
A122: เบทาโกรส่งแล้ว | B122: 20700 | C122: 424374
A123: เบทาโกรส่งแล้ว | B123: 20800 | C123: 155973
C126: รวมส่ง+ค้างส่ง | D126: ส่วนต่างCapคงเหลือ | E126: ส่วนต่างCapคงเหลือ | F126: คงเหลือ
C127: =+C50+C121 -> 1975256 | D127: =+D121-D50 -> 0 | E127: =+E121-E50 -> 0 | F127: =+F121-F50 -> 825147 | G127: =+G121-G50 -> 0
B129: 20700VN 20/7 | G129: 350000

Sheet ค้างตัด13-10-68
A2: งาน รอตัด หน้างาน | B2: 162217
A3: ผลรวม ของ ค้างตัด | B3: ป้ายชื่อคอลัมน์
A4: ป้ายชื่อแถว | B4: 45944 | C4: 45945 | D4: 45946 | E4: 45947 | F4: 45948 | G4: 45950 | H4: 45951 | I4: 45952 | J4: 45953 | K4: 45954 | L4: 45955 | M4: 45957 | N4: 45958 | O4: 45959 | P4: 45960 | Q4: 45961 | R4: ผลรวมทั้งหมด
A5: 21 | B5: 0 | D5: 0 | I5: 0 | N5: 893 | R5: =SUM(B5:Q5) -> 893
A6: 917 | I6: 2500 | Q6: 2500 | R6: =SUM(B6:Q6) -> 5000
A7: 931 | G7: 5000 | O7: 5000 | R7: =SUM(B7:Q7) -> 10000
A8: 932 | K8: 2500 | N8: 2500 | P8: 5000 | R8: =SUM(B8:Q8) -> 10000
A9: 935 | E9: 5000 | H9: 10000 | K9: 5000 | M9: 5000 | P9: 10000 | R9: =SUM(B9:Q9) -> 35000
A10: 952 | C10: 0 | E10: 2255 | K10: 5000 | Q10: 5000 | R10: =SUM(B10:Q10) -> 12255
A11: 953 | C11: 0 | H11: 175 | R11: =SUM(B11:Q11) -> 175
A12: 956 | H12: 1129 | R12: =SUM(B12:Q12) -> 1129
A13: 959 | K13: 5000 | R13: =SUM(B13:Q13) -> 5000
A14: 997 | K14: 5000 | R14: =SUM(B14:Q14) -> 5000
A15: 007 | E15: 0 | K15: 0 | Q15: 1371 | R15: =SUM(B15:Q15) -> 1371
A16: 915 พี | C16: 0 | E16: 800 | H16: 7500 | K16: 7500 | N16: 5000 | Q16: 7500 | R16: =SUM(B16:Q16) -> 28300
A17: 915 เอ็ม | E17: 0 | G17: 7100 | K17: 5000 | M17: 5000 | O17: 10000 | Q17: 5000 | R17: =SUM(B17:Q17) -> 32100
A18: 935 เอ | E18: 5000 | H18: 10000 | K18: 5000 | M18: 10000 | O18: 10000 | Q18: 5000 | R18: =SUM(B18:Q18) -> 45000
A19: 935 แอล | C19: 0 | H19: 5000 | P19: 5000 | R19: =SUM(B19:Q19) -> 10000
A20: 952 เอส | G20: 2641 | O20: 2500 | R20: =SUM(B20:Q20) -> 5141
A21: 953 เอส | E21: 2500 | Q21: 2500 | R21: =SUM(B21:Q21) -> 5000
A22: APM915 | E22: 3000 | R22: =SUM(B22:Q22) -> 3000
A23: BOBBI Cat รสMellow | D23: 3000 | R23: =SUM(B23:Q23) -> 3000
A24: BOBBI Cat รสSalman | D24: 3000 | R24: =SUM(B24:Q24) -> 3000
A25: BOBBI Dog รส Lamb&Rice | D25: 3000 | R25: =SUM(B25:Q25) -> 3000
A26: FW-Y | I26: 5000 | K26: 5000 | R26: =SUM(B26:Q26) -> 10000
A27: HERO 111 | D27: 3000 | R27: =SUM(B27:Q27) -> 3000
A28: PBKF2-01-03 | N28: 5000 | R28: =SUM(B28:Q28) -> 5000
A29: Soybean Meal | K29: 10000 | R29: =SUM(B29:Q29) -> 10000
A30: SPM 915 | J30: 3000 | R30: =SUM(B30:Q30) -> 3000
A31: SPM914 | J31: 3000 | R31: =SUM(B31:Q31) -> 3000
A32: VC 120 | B32: 2250 | R32: =SUM(B32:Q32) -> 2250
A33: Zhejiang UN | C33: 6575 | R33: =SUM(B33:Q33) -> 6575
A34: กุ้งแดง | C34: 0 | I34: 10000 | R34: =SUM(B34:Q34) -> 10000
A35: ไก่ไข่ | O35: 5000 | R35: =SUM(B35:Q35) -> 5000
A36: ไก่เนื้อ สระบุรี1 | K36: 2500 | O36: 2500 | R36: =SUM(B36:Q36) -> 5000
A37: ไก่เนื้อ สระบุรี2 | H37: 2500 | O37: 2500 | R37: =SUM(B37:Q37) -> 5000
A38: ขุนศึกเบอร์ 1 | C38: 0 | K38: 0 | P38: 10000 | R38: =SUM(B38:Q38) -> 10000
A39: ขุนศึกเบอร์ 2 | C39: 0 | H39: 383 | N39: 0 | P39: 0 | R39: =SUM(B39:Q39) -> 383
A40: ชามแดง 25กก | K40: 5000 | R40: =SUM(B40:Q40) -> 5000
A41: ดอกไม้เขียว | H41: 10000 | R41: =SUM(B41:Q41) -> 10000
...

Sheet 13-10-68
B2: เรียงกำหนดส่ง | D2: ลบ 0 | T2: เรียง 1
B3: ข้อมูลUpdate ณ. วันที่ | D3: 45943 | E3: เวลา | G3: 9.44
A4: วันรับออร์เดอร์/แบบ | B4: เลขที่ SO | C4: ชื่อลูกค้า | E4: 10.3 | I4: น้ำหนัก | L4: บิด/จับจีบ | M4: ถุงใน | Q4: 44873 | S4: วิธีบรรจุ | T4: วันส่ง | U4: จำนวนส่ง | V4: ตัดเย็บ (ใบ) | W4: 44873 | X4: พิมพ์ (ใบ) | Y4: 44876 | Z4: ผ้าทอ (เมตร) Updateณ | AB4: 44876 | AD4: ผ้าเคลือบ(เมตร) | AF4: หมายเหตุ | AG4: เครื่อง
A5: วันรับออร์เดอร์/แบบ | B5: เลขที่ SO | C5: ชื่อลูกค้า | D5: ตรา | E5: กว้าง | F5: ยาว | G5: สี | H5: เคลือบ | I5: กรัม/ใบ | J5: * | K5: aw | L5: บิด/จับจีบ | M5: กว้าง | N5: ยาว | O5: หนา | P5: ใช้(กก.) | Q5: Stock(กก.) | R5: ผลิต(กก.) | S5: วิธีบรรจุ | T5: วันส่ง | U5: จำนวนส่ง | V5: StockFG | W5: ค้างตัด | X5: พิมพ์แล้ว | Y5: ค้างพิมพ์ | Z5: ประเภท | AA5: ใช้ | AB5: Stock | AC5: ค้างทอ | AD5: Stock | AE5: ค้างเคลือบ | AF5: หมายเหตุ | AG5: ที่พิมพ์ได้ | AH5: process | AI5: Lead time | AJ5: วันที่ส่งPL | AK5: เคลือบ | AL5: ได้ ART | AM5: พิมพ์ | AN5: จีบ-บิด | AO5: ตัด-เย็บ | AP5: ทอ | AQ5: สวมถุง | AR5: เย็บปาก | AS5: PT | AT5: ม้วน | AU5: ตัด | AV5: ตอกตาไก่ | AW5: GROUP | AX5: ART | AY5: หมายเหตุปัญหา | AZ5: ราคา/ใบ | BA5: ราคารวม | BB5: workweek | BC5: เส้นเทป | BD5: จำนวน
A6: 45941 | B6: MK68-001228 | C6: บจก.เคอรี่ฟลาวมิลล์ | D6: โบว์แดง 10กก | E6: 16 | F6: 25 | G6: ขาว | H6: 0 | I6: 45 | J6: ± | K6: 5 | L6: ไม่ | M6: ไม่สวมถุงใน | N6: 0 | O6: 0 | P6: 0 | Q6: 0 | R6: 0 | S6: ห่ออัดเบลแบน500 | T6: 45952 | U6: 5000 | V6: 0 | W6: 5000 | X6: 0 | Y6: 5250 | Z6: WSWT1625800 | AA6: 3702.05 | AB6: 3702.05 | AC6: 0 | AD6: 0 | AE6: 0 | AF6: 0 | AG6: พร้อมส่ง | AH6: P7 | AI6: 2 | AJ6: 45952 | AK6: 0 | AL6: 45943 | AM6: 45950 | AN6: 45951 | AO6: 45951 | AP6: 45947 | AQ6: 0 | AR6: 0 | AS6: 0 | AT6: 0 | AU6: 0 | AV6: 0 | AW6: งานพิมพ์ | AX6: รอART | AY6: 0 | AZ6: 0 | BA6: 0 | BB6: 0 | BC6: WRWT25800/WRWT25800 | BD6: 0
A7: 0 | B7: 0 | C7: 0 | D7: 0 | E7: 16 | F7: 25 | G7: ขาว | H7: 0 | I7: 45 | J7: ± | K7: 5 | L7: 0 | M7: 0 | N7: 0 | O7: 0 | P7: 0 | Q7: 0 | R7: 0 | S7: 0 | U7: 0 | V7: 0 | W7: 0 | X7: 0 | Y7: 0 | Z7: WSWT1625800 | AA7: 3702.05 | AB7: 3702.05 | AC7: 0 | AD7: 0 | AE7: 0 | AF7: ระบุในSD | AG7: พร้อมส่ง | AH7: 0 | AI7: Lead time | AJ7: 0 | AK7: 0 | AL7: 0 | AM7: 0 | AN7: 0 | AO7: 0 | AP7: 0 | AQ7: 0 | AR7: 0 | AS7: 0 | AT7: 0 | AU7: 0 | AV7: 0 | AW7: 0 | AX7: 0 | AY7: 0 | AZ7: 0 | BA7: 0 | BB7: 0 | BC7: WRWT160800/WRWT25800 | BD7: 0
A8: 45933 | B8: MK68-001198 | C8: บจก.ฟาร์เธอร์ส วิง ซัพพลาย | D8: รถไฟฟ้าปูนขาวเย็น | E8: 18 | F8: 30 | G8: ขาว | H8: 0 | I8: 54 | J8: ± | K8: 5 | L8: บิด | M8: 19 | N8: 33 | O8: 40 | P8: 0 | Q8: 0 | R8: 0 | S8: 500กระสอบ | T8: 45944 | U8: 15000 | V8: 15000 | W8: 0 | X8: 15835 | Y8: 0 | Z8: WSWT1825800 | AA8: 0 | AB8: 0 | AC8: 0 | AD8: 0 | AE8: 0 | AF8: 0 | AG8: พร้อมส่ง | AH8: P9 | AI8: 3 | AJ8: 45944 | AK8: 0 | AL8: 45934 | AM8: 45941 | AN8: 45942 | AO8: 45942 | AP8: 45939 | AQ8: 45943 | AR8: 0 | AS8: 0 | AT8: 0 | AU8: 0 | AV8: 0 | AW8: งานพิมพ์ | AX8: / | AY8: 0 | AZ8: 0 | BA8: 0 | BB8: 0 | BC8: WRWT25800/WRWT25800 | BD8: 0
A9: 45933 | B9: MK68-001198 | C9: บจก.ฟาร์เธอร์ส วิง ซัพพลาย | D9: ไม่พิมพ์ | E9: 18 | F9: 30 | G9: ขาว | H9: 0 | I9: 54 | J9: ± | K9: 5 | L9: บิด | M9: 19 | N9: 33 | O9: 40 | P9: 0 | Q9: 0 | R9: 0 | S9: 500กระสอบ | T9: 45944 | U9: 3000 | V9: 3000 | W9: 0 | X9: 0 | Y9: 0 | Z9: WSWT1825800 | AA9: 0 | AB9: 0 | AC9: 0 | AD9: 0 | AE9: 0 | AF9: 0 | AG9: ยังไม่ได้พิมพ์ | AH9: P9 | AI9: 3 | AJ9: 45944 | AK9: 0 | AL9: 45934 | AM9: 45941 | AN9: 45942 | AO9: 45942 | AP9: 45939 | AQ9: 45943 | AR9: 0 | AS9: 0 | AT9: 0 | AU9: 0 | AV9: 0 | AW9: งานพิมพ์ | AX9: / | AY9: 0 | AZ9: 0 | BA9: 0 | BB9: 0 | BC9: WRWT25800/WRWT25800 | BD9: 0
A10: 45938 | B10: MK68-001221 | C10: บจก.เอสทีเคมีธุรกืจ | D10: มังกรแดง STCB | E10: 18 | F10: 30 | G10: ขาว | H10: 0 | I10: 54 | J10: ± | K10: 5 | L10: ไม่ | M10: 19 | N10: 31 | O10: 40 | P10: 145.31171 | Q10: 0 | R10: 145.31171 | S10: 500กระสอบ | T10: 45946 | U10: 10000 | V10: 0 | W10: 10000 | X10: 0 | Y10: 10500 | Z10: WSWT1825800 | AA10: 8801.1 | AB10: 8801.1 | AC10: 0 | AD10: 0 | AE10: 0 | AF10: ห้ามเกิน | AG10: ยังไม่ได้พิมพ์ | AH10: P9 | AI10: 3 | AJ10: 45946 | AK10: 0 | AL10: 45936 | AM10: 45943 | AN10: 45944 | AO10: 45944 | AP10: 45941 | AQ10: 45945 | AR10: 0 | AS10: 0 | AT10: 0 | AU10: 0 | AV10: 0 | AW10: งานพิมพ์ | AX10: รอART | AY10: 0 | AZ10: 0 | BA10: 0 | BB10: 0 | BC10: WRWT25800/WRWT25800 | BD10: 0
A11: 45923 | B11: MK68-001161 | C11: หจก.อนนท์อุตสาหกรรม | D11: อนนท์ 20 กก. | E11: 18 | F11: 28 | G11: ขาว | H11: 0 | I11: 50 | J11: ± | K11: 5 | L11: ไม่ | M11: 19 | N11: 31 | O11: 40 | P11: 0 | Q11: 0 | R11: 0 | S11: 500กระสอบแบน | T11: 45950 | U11: 5000 | V11: 5000 | W11: 0 | X11: 5400 | Y11: 0 | Z11: WSWT1825800 | AA11: 0 | AB11: 0 | AC11: 0 | AD11: 0 | AE11: 0 | AF11: 0 | AG11: ยังไม่ได้พิมพ์ | AH11: P9 | AI11: 3 | AJ11: 45950 | AK11: 0 | AL11: 45940 | AM11: 45947 | AN11: 45948 | AO11: 45948 | AP11: 45945 | AQ11: 45949 | AR11: 0 | AS11: 0 | AT11: 0 | AU11: 0 | AV11: 0 | AW11: งานพิมพ์ | AX11: / | AY11: 0 | AZ11: 0 | BA11: 0 | BB11: 0 | BC11: WRWT25800/WRWT25800 | BD11: 0
A12: 45923 | B12: MK68-001162 | C12: หจก.อนนท์อุตสาหกรรม | D12: ดาว 20 กก. | E12: 18 | F12: 28 | G12: ขาว | H12: 0 | I12: 50 | J12: ± | K12: 5 | L12: ไม่ | M12: 19 | N12: 31 | O12: 40 | P12: 363.27927 | Q12: 0 | R12: 363.27927 | S12: 500กระสอบแบน | T12: 45950 | U12: 25000 | V12: 0 | W12: 25000 | X12: 0 | Y12: 26250 | Z12: WSWT1825800 | AA12: 20605.75 | AB12: 20605.75 | AC12: 0 | AD12: 0 | AE12: 0 | AF12: 0 | AG12: ยังไม่ได้พิมพ์ | AH12: P9 | AI12: 3 | AJ12: 45950 | AK12: 0 | AL12: 45940 | AM12: 45947 | AN12: 45948 | AO12: 45948 | AP12: 45945 | AQ12: 45949 | AR12: 0 | AS12: 0 | AT12: 0 | AU12: 0 | AV12: 0 | AW12: งานพิมพ์ | AX12: / | AY12: 0 | AZ12: 0 | BA12: 0 | BB12: 0 | BC12: WRWT25800/WRWT25800 | BD12: 0
A13: 45923 | B13: MK68-001162 | C13: หจก.อนนท์อุตสาหกรรม | D13: ดาว 20 กก. | E13: 18 | F13: 28 | G13: ขาว | H13: 0 | I13: 50 | J13: ± | K13: 5 | L13: ไม่ | M13: 19 | N13: 31 | O13: 40 | P13: 363.27927 | Q13: 0 | R13: 363.27927 | S13: 500กระสอบแบน | T13: 45955 | U13: 25000 | V13: 0 | W13: 25000 | X13: 0 | Y13: 26250 | Z13: WSWT1825800 | AA13: 20605.75 | AB13: 20605.75 | AC13: 0 | AD13: 0 | AE13: 0 | AF13: 0 | AG13: พร้อมส่ง | AH13: P9 | AI13: 3 | AJ13: 45955 | AK13: 0 | AL13: 45945 | AM13: 45952 | AN13: 45953 | AO13: 45953 | AP13: 45950 | AQ13: 45954 | AR13: 0 | AS13: 0 | AT13: 0 | AU13: 0 | AV13: 0 | AW13: งานพิมพ์ | AX13: / | AY13: 0 | AZ13: 0 | BA13: 0 | BB13: 0 | BC13: WRWT25800/WRWT25800 | BD13: 0
A14: 45923 | B14: MK68-001162 | C14: หจก.อนนท์อุตสาหกรรม | D14: ดาว 20 กก. | E14: 18 | F14: 28 | G14: ขาว | H14: 0 | I14: 50 | J14: ± | K14: 5 | L14: ไม่ | M14: 19 | N14: 31 | O14: 40 | P14: 363.27927 | Q14: 0 | R14: 363.27927 | S14: 500กระสอบแบน | T14: 45958 | U14: 25000 | V14: 0 | W14: 25000 | X14: 0 | Y14: 26250 | Z14: WSWT1825800 | AA14: 20605.75 | AB14: 20605.75 | AC14: 0 | AD14: 0 | AE14: 0 | AF14: 0 | AG14: พร้อมส่ง | AH14: P9 | AI14: 3 | AJ14: 45958 | AK14: 0 | AL14: 45948 | AM14: 45955 | AN14: 45956 | AO14: 45956 | AP14: 45953 | AQ14: 45957 | AR14: 0 | AS14: 0 | AT14: 0 | AU14: 0 | AV14: 0 | AW14: งานพิมพ์ | AX14: / | AY14: 0 | AZ14: 0 | BA14: 0 | BB14: 0 | BC14: WRWT25800/WRWT25800 | BD14: 0
A15: 45923 | B15: MK68-001162 | C15: หจก.อนนท์อุตสาหกรรม | D15: ดาว 20 กก. | E15: 18 | F15: 28 | G15: ขาว | H15: 0 | I15: 50 | J15: ± | K15: 5 | L15: ไม่ | M15: 19 | N15: 31 | O15: 40 | P15: 363.27927 | Q15: 0 | R15: 363.27927 | S15: 500กระสอบแบน | T15: 45961 | U15: 25000 | V15: 0 | W15: 25000 | X15: 0 | Y15: 26250 | Z15: WSWT1825800 | AA15: 20605.75 | AB15: 20605.75 | AC15: 0 | AD15: 0 | AE15: 0 | AF15: 0 | AG15: รอตัด | AH15: P9 | AI15: 3 | AJ15: 45961 | AK15: 0 | AL15: 45951 | AM15: 45958 | AN15: 45959 | AO15: 45959 | AP15: 45956 | AQ15: 45960 | AR15: 0 | AS15: 0 | AT15: 0 | AU15: 0 | AV15: 0 | AW15: งานพิมพ์ | AX15: / | AY15: 0 | AZ15: 0 | BA15: 0 | BB15: 0 | BC15: WRWT25800/WRWT25800 | BD15: 0
A16: 0 | B16: 0 | E16: 18 | F16: 30 | G16: ขาว | H16: 0 | I16: 54 | J16: ± | K16: 5 | L16: 0 | M16: 0 | N16: 0 | O16: 0 | P16: 0 | Q16: 0 | R16: 0 | S16: 0 | U16: 0 | V16: 0 | W16: 0 | X16: 0 | Y16: 0 | Z16: WSWT1825800 | AA16: 91224.1 | AB16: 91224.1 | AC16: 0 | AD16: 0 | AE16: 0 | AF16: ระบุในSD | AG16: ยังไม่ได้พิมพ์ | AH16: 0 | AI16: Lead time | AJ16: 0 | AK16: 0 | AL16: 0 | AM16: 0 | AN16: 0 | AO16: 0 | AP16: 0 | AQ16: 0 | AR16: 0 | AS16: 0 | AT16: 0 | AU16: 0 | AV16: 0 | AW16: 0 | AX16: 0 | AY16: 0 | AZ16: 0 | BA16: 0 | BB16: 0 | BC16: WRWT25800/WRWT25800 | BD16: 0
A17: 45920 | B17: MK68-001140 | C17: บจก.เพรซิเดนท์ฟลาวมิลล์ | D17: ผึ้งชมพู | E17: 19 | F17: 30 | G17: ขาว | H17: 0 | I17: 60 | J17: ± | K17: 5 | L17: บิด | M17: ไม่สวมถุงใน | N17: 0 | O17: 0 | P17: 0 | Q17: 0 | R17: 0 | S17: 500กระสอบแบน | T17: 45952 | U17: 20000 | V17: 2631 | W17: 17369 | X17: 21131 | Y17: 0 | Z17: WSWT1925800 | AA17: 0 | AB17: 0 | AC17: 0 | AD17: 0 | AE17: 0 | AF17: 0 | AG17: ยังไม่ได้พิมพ์ | AH17: P7 | AI17: 2 | AJ17: 45952 | AK17: 0 | AL17: 45943 | AM17: 45950 | AN17: 45951 | AO17: 45951 | AP17: 45947 | AQ17: 0 | AR17: 0 | AS17: 0 | AT17: 0 | AU17: 0 | AV17: 0 | AW17: งานพิมพ์ | AX17: / | AY17: 0 | AZ17: 0 | BA17: 0 | BB17: 0 | BC17: WRWT25800/WRWT25800 | BD17: 0
A18: ประมาณการ | B18: ประมาณการ | C18: บจก.ไลม์มาสเตอร์ | D18: LMC 25 kg | E18: 19 | F18: 32 | G18: ขาว | H18: 0 | I18: 64 | J18: ± | K18: 5 | L18: ไม่ | M18: 20 | N18: 35 | O18: 40 | P18: 341.36903 | Q18: 0 | R18: 341.36903 | S18: 500กระสอบแบน | T18: 45961 | U18: 20000 | V18: 233 | W18: 19767 | X18: 0 | Y18: 20755.35 | Z18: WSWT1925800 | AA18: 18501.714 | AB18: 2540 | AC18: 15961.714 | AD18: 0 | AE18: 0 | AF18: 0 | AG18: พร้อมส่ง | AH18: P9 | AI18: 3 | AJ18: 45961 | AK18: 0 | AL18: 45951 | AM18: 45958 | AN18: 45959 | AO18: 45959 | AP18: 45956 | AQ18: 45960 | AR18: 0 | AS18: 0 | AT18: 0 | AU18: 0 | AV18: 0 | AW18: งานพิมพ์ | AX18: รอART | AY18: 0 | AZ18: 0 | BA18: 0 | BB18: 0 | BC18: WRWT25800/WRWT25800 | BD18: 1159.1752
