Workbook

Sheet Linkสูตรออร์เดอร์  (2)
B2: เรียงกำหนดส่ง | D2: ลบ 0 | T2: เรียง 1
B3: ข้อมูลUpdate ณ. วันที่ | D3: 45953 | E3: เวลา | G3: 11.56
A4: วันรับออร์เดอร์/แบบ | B4: เลขที่ SO | C4: ชื่อลูกค้า | E4: 10.3 | I4: น้ำหนัก | L4: บิด/จับจีบ | M4: ถุงใน | Q4: =[1]หน้าผ้า!$AC$13 -> 44873 | S4: วิธีบรรจุ | T4: วันส่ง | U4: จำนวนส่ง | V4: ตัดเย็บ (ใบ) | W4: =[1]หน้าผ้า!$AJ$13 -> 44873 | X4: พิมพ์ (ใบ) | Y4: =[1]หน้าผ้า!$AM$13 -> 44876 | Z4: ผ้าทอ (เมตร) Updateณ | AB4: =[1]หน้าผ้า!$AR$12 -> 44876 | AD4: ผ้าเคลือบ(เมตร) | AF4: หมายเหตุ | AG4: เครื่อง
B5: เลขที่ SO | C5: ชื่อลูกค้า | D5: ตรา | E5: กว้าง | F5: ยาว | G5: สี | H5: เคลือบ | I5: กรัม/ใบ | J5: * | K5: aw | L5: บิด/จับจีบ | M5: กว้าง | N5: ยาว | O5: หนา | P5: ใช้(กก.) | Q5: Stock(กก.) | R5: ผลิต(กก.) | S5: วิธีบรรจุ | T5: วันส่ง | U5: จำนวนส่ง | V5: StockFG | W5: ค้างตัด | X5: พิมพ์แล้ว | Y5: ค้างพิมพ์ | Z5: ประเภท | AA5: ใช้ | AB5: Stock | AC5: ค้างทอ | AD5: Stock | AE5: ค้างเคลือบ | AF5: หมายเหตุ | AG5: ที่พิมพ์ได้ | AH5: process | AI5: Lead time | AJ5: วันที่ส่งPL | AK5: เคลือบ | AL5: ได้ ART | AM5: พิมพ์ | AN5: จีบ-บิด | AO5: ตัด-เย็บ | AP5: ทอ | AQ5: สวมถุง | AR5: เย็บปาก | AS5: PT | AT5: ม้วน | AU5: ตัด | AV5: ตอกตาไก่ | AW5: GROUP | AX5: ART | AY5: หมายเหตุปัญหา | AZ5: ราคา/ใบ | BA5: ราคารวม | BB5: workweek | BC5: เส้นเทป | BD5: จำนวน
A6: =[2]หน้าผ้า!C15 -> 0 | B6: =[2]หน้าผ้า!B15 -> 0 | C6: =[2]หน้าผ้า!E15 -> 0 | D6: =[2]หน้าผ้า!F15 -> 0 | E6: =[2]หน้าผ้า!G15 -> 12 | F6: =[2]หน้าผ้า!H15 -> 16 | G6: =[2]หน้าผ้า!I15 -> ขาว | H6: =[2]หน้าผ้า!J15 -> 0 | I6: =[2]หน้าผ้า!L15 -> 25 | J6: =[2]หน้าผ้า!M15 -> ± | K6: =[2]หน้าผ้า!N15 -> 5 | L6: =[2]หน้าผ้า!R15 -> 0 | M6: =[2]หน้าผ้า!T15 -> 0 | N6: =[2]หน้าผ้า!U15 -> 0 | O6: =[2]หน้าผ้า!V15 -> 0 | P6: =[2]หน้าผ้า!AB15 -> 0 | Q6: =[2]หน้าผ้า!AC15 -> 0 | R6: =[2]หน้าผ้า!AD15 -> 0 | S6: =[2]หน้าผ้า!Z15 -> 0 | T6: =[2]หน้าผ้า!X15 -> 0 | U6: =[2]หน้าผ้า!AA15 -> 0 | V6: =[2]หน้าผ้า!AJ15 -> 0 | W6: =[2]หน้าผ้า!AL15 -> 0 | X6: =[2]หน้าผ้า!AM15 -> 0 | Y6: =[2]หน้าผ้า!AN15 -> 0 | Z6: =[2]หน้าผ้า!AO15 -> WSWT1221750 | AA6: =[2]หน้าผ้า!AQ15 -> #REF! | AB6: =[2]หน้าผ้า!AR15 -> #REF! | AC6: =[2]หน้าผ้า!AS15 -> #REF! | AD6: =[2]หน้าผ้า!AT15 -> #REF! | AE6: =[2]หน้าผ้า!AU15 -> #REF! | AF6: =[2]หน้าผ้า!AI15 -> ระบุในSD | AG6: =[3]หน้าผ้า!DC18 -> < Ord 20,000 | AH6: =[2]หน้าผ้า!DL15 -> 0 | AI6: =[2]หน้าผ้า!DM15 -> 0 | AJ6: =[2]หน้าผ้า!DN15 -> 0 | AK6: =[2]หน้าผ้า!DQ15 -> 0 | AL6: =[2]หน้าผ้า!DR15 -> 0 | AM6: =[2]หน้าผ้า!DS15 -> 0 | AN6: =[2]หน้าผ้า!DT15 -> 0 | AO6: =[2]หน้าผ้า!DU15 -> 0 | AP6: =[2]หน้าผ้า!DP15 -> 0 | AQ6: =[2]หน้าผ้า!DW15 -> 0 | AR6: =[2]หน้าผ้า!DX15 -> 0 | AS6: =[2]หน้าผ้า!DY15 -> 0 | AT6: =[2]หน้าผ้า!DZ15 -> 0 | AU6: =[2]หน้าผ้า!EA15 -> 0 | AV6: =[2]หน้าผ้า!EB15 -> 0 | AW6: =[2]หน้าผ้า!EC15 -> 0 | AX6: =[2]หน้าผ้า!ED15 -> 0 | AY6: =[2]หน้าผ้า!AG15 -> 0 | AZ6: =[2]หน้าผ้า!EG15 -> 0 | BA6: =[2]หน้าผ้า!EH15 -> 0 | BB6: =[2]หน้าผ้า!EI15 -> 0 | BC6: =[2]หน้าผ้า!BZ15 -> WRWT120750/WRWT21750 | BD6: =[2]หน้าผ้า!CA15 -> 0
A7: =[2]หน้าผ้า!C16 -> 45946 | B7: =[2]หน้าผ้า!B16 -> MK68-001239 | C7: =[2]หน้าผ้า!E16 -> หจก.ปึงเป้งน้ำ | D7: =[2]หน้าผ้า!F16 -> เกลือตรามือ 10กก. | E7: =[2]หน้าผ้า!G16 -> 14 | F7: =[2]หน้าผ้า!H16 -> 22 | G7: =[2]หน้าผ้า!I16 -> ขาว | H7: =[2]หน้าผ้า!J16 -> ใส | I7: =[2]หน้าผ้า!L16 -> 42 | J7: =[2]หน้าผ้า!M16 -> ± | K7: =[2]หน้าผ้า!N16 -> 5 | L7: =[2]หน้าผ้า!R16 -> ไม่ | M7: =[2]หน้าผ้า!T16 -> ไม่สวมถุงใน | N7: =[2]หน้าผ้า!U16 -> 0 | O7: =[2]หน้าผ้า!V16 -> 0 | P7: =[2]หน้าผ้า!AB16 -> 0 | Q7: =[2]หน้าผ้า!AC16 -> 0 | R7: =[2]หน้าผ้า!AD16 -> 0 | S7: =[2]หน้าผ้า!Z16 -> 500กระสอบแบน | T7: =[2]หน้าผ้า!X16 -> 45961 | U7: =[2]หน้าผ้า!AA16 -> 10000 | V7: =[2]หน้าผ้า!AJ16 -> 0 | W7: =[2]หน้าผ้า!AL16 -> 10000 | X7: =[2]หน้าผ้า!AM16 -> 0 | Y7: =[2]หน้าผ้า!AN16 -> 10500 | Z7: =[2]หน้าผ้า!AO16 -> WSWT1425800 | AA7: =[2]หน้าผ้า!AQ16 -> 6565.9 | AB7: =[2]หน้าผ้า!AR16 -> 5528 | AC7: =[2]หน้าผ้า!AS16 -> 1037.9 | AD7: =[2]หน้าผ้า!AT16 -> 636 | AE7: =[2]หน้าผ้า!AU16 -> 5929.9 | AF7: =[2]หน้าผ้า!AI16 -> 0 | AG7: =[3]หน้าผ้า!DC19 -> พร้อมส่ง | AH7: =[2]หน้าผ้า!DL16 -> P6 | AI7: =[2]หน้าผ้า!DM16 -> 4 | AJ7: =[2]หน้าผ้า!DN16 -> 45961 | AK7: =[2]หน้าผ้า!DQ16 -> 45957 | AL7: =[2]หน้าผ้า!DR16 -> 45950 | AM7: =[2]หน้าผ้า!DS16 -> 45958 | AN7: =[2]หน้าผ้า!DT16 -> 45959 | AO7: =[2]หน้าผ้า!DU16 -> 45960 | AP7: =[2]หน้าผ้า!DP16 -> 45956 | AQ7: =[2]หน้าผ้า!DW16 -> 0 | AR7: =[2]หน้าผ้า!DX16 -> 0 | AS7: =[2]หน้าผ้า!DY16 -> 0 | AT7: =[2]หน้าผ้า!DZ16 -> 0 | AU7: =[2]หน้าผ้า!EA16 -> 0 | AV7: =[2]หน้าผ้า!EB16 -> 0 | AW7: =[2]หน้าผ้า!EC16 -> งานเคลือบ+พิมพ์ | AX7: =[2]หน้าผ้า!ED16 -> / | AY7: =[2]หน้าผ้า!AG16 -> 0 | AZ7: =[2]หน้าผ้า!EG16 -> 0 | BA7: =[2]หน้าผ้า!EH16 -> 0 | BB7: =[2]หน้าผ้า!EI16 -> 0 | BC7: =[2]หน้าผ้า!BZ16 -> WRWT25800/WRWT25800 | BD7: =[2]หน้าผ้า!CA16 -> 58.1224
A8: =[2]หน้าผ้า!C17 -> 0 | B8: =[2]หน้าผ้า!B17 -> 0 | C8: =[2]หน้าผ้า!E17 -> 0 | D8: =[2]หน้าผ้า!F17 -> 0 | E8: =[2]หน้าผ้า!G17 -> 14 | F8: =[2]หน้าผ้า!H17 -> 22 | G8: =[2]หน้าผ้า!I17 -> ขาว | H8: =[2]หน้าผ้า!J17 -> 0 | I8: =[2]หน้าผ้า!L17 -> 36 | J8: =[2]หน้าผ้า!M17 -> ± | K8: =[2]หน้าผ้า!N17 -> 5 | L8: =[2]หน้าผ้า!R17 -> 0 | M8: =[2]หน้าผ้า!T17 -> 0 | N8: =[2]หน้าผ้า!U17 -> 0 | O8: =[2]หน้าผ้า!V17 -> 0 | P8: =[2]หน้าผ้า!AB17 -> 0 | Q8: =[2]หน้าผ้า!AC17 -> 0 | R8: =[2]หน้าผ้า!AD17 -> 0 | S8: =[2]หน้าผ้า!Z17 -> 0 | T8: =[2]หน้าผ้า!X17 -> 0 | U8: =[2]หน้าผ้า!AA17 -> 0 | V8: =[2]หน้าผ้า!AJ17 -> 0 | W8: =[2]หน้าผ้า!AL17 -> 0 | X8: =[2]หน้าผ้า!AM17 -> 0 | Y8: =[2]หน้าผ้า!AN17 -> 0 | Z8: =[2]หน้าผ้า!AO17 -> WSWT1425800 | AA8: =[2]หน้าผ้า!AQ17 -> 6565.9 | AB8: =[2]หน้าผ้า!AR17 -> 5528 | AC8: =[2]หน้าผ้า!AS17 -> 1037.9 | AD8: =[2]หน้าผ้า!AT17 -> 636 | AE8: =[2]หน้าผ้า!AU17 -> 5929.9 | AF8: =[2]หน้าผ้า!AI17 -> ระบุในSD | AG8: =[3]หน้าผ้า!DC20 -> พร้อมส่ง | AH8: =[2]หน้าผ้า!DL17 -> 0 | AI8: =[2]หน้าผ้า!DM17 -> Lead time | AJ8: =[2]หน้าผ้า!DN17 -> 0 | AK8: =[2]หน้าผ้า!DQ17 -> 0 | AL8: =[2]หน้าผ้า!DR17 -> 0 | AM8: =[2]หน้าผ้า!DS17 -> 0 | AN8: =[2]หน้าผ้า!DT17 -> 0 | AO8: =[2]หน้าผ้า!DU17 -> 0 | AP8: =[2]หน้าผ้า!DP17 -> 0 | AQ8: =[2]หน้าผ้า!DW17 -> 0 | AR8: =[2]หน้าผ้า!DX17 -> 0 | AS8: =[2]หน้าผ้า!DY17 -> 0 | AT8: =[2]หน้าผ้า!DZ17 -> 0 | AU8: =[2]หน้าผ้า!EA17 -> 0 | AV8: =[2]หน้าผ้า!EB17 -> 0 | AW8: =[2]หน้าผ้า!EC17 -> 0 | AX8: =[2]หน้าผ้า!ED17 -> 0 | AY8: =[2]หน้าผ้า!AG17 -> 0 | AZ8: =[2]หน้าผ้า!EG17 -> 0 | BA8: =[2]หน้าผ้า!EH17 -> 0 | BB8: =[2]หน้าผ้า!EI17 -> 0 | BC8: =[2]หน้าผ้า!BZ17 -> WRWT140800/WRWT25800 | BD8: =[2]หน้าผ้า!CA17 -> 0
A9: =[2]หน้าผ้า!C18 -> 0 | B9: =[2]หน้าผ้า!B18 -> 0 | C9: =[2]หน้าผ้า!E18 -> 0 | D9: =[2]หน้าผ้า!F18 | E9: =[2]หน้าผ้า!G18 -> 16 | F9: =[2]หน้าผ้า!H18 -> 25 | G9: =[2]หน้าผ้า!I18 -> ขาว | H9: =[2]หน้าผ้า!J18 -> 0 | I9: =[2]หน้าผ้า!L18 -> 45 | J9: =[2]หน้าผ้า!M18 -> ± | K9: =[2]หน้าผ้า!N18 -> 5 | L9: =[2]หน้าผ้า!R18 -> 0 | M9: =[2]หน้าผ้า!T18 -> 0 | N9: =[2]หน้าผ้า!U18 -> 0 | O9: =[2]หน้าผ้า!V18 -> 0 | P9: =[2]หน้าผ้า!AB18 -> 0 | Q9: =[2]หน้าผ้า!AC18 -> 0 | R9: =[2]หน้าผ้า!AD18 -> 0 | S9: =[2]หน้าผ้า!Z18 -> 0 | T9: =[2]หน้าผ้า!X18 -> 0 | U9: =[2]หน้าผ้า!AA18 -> 0 | V9: =[2]หน้าผ้า!AJ18 -> 0 | W9: =[2]หน้าผ้า!AL18 -> 0 | X9: =[2]หน้าผ้า!AM18 -> 0 | Y9: =[2]หน้าผ้า!AN18 -> 0 | Z9: =[2]หน้าผ้า!AO18 -> WSWT1625800SM | AA9: =[2]หน้าผ้า!AQ18 -> #REF! | AB9: =[2]หน้าผ้า!AR18 -> #REF! | AC9: =[2]หน้าผ้า!AS18 -> #REF! | AD9: =[2]หน้าผ้า!AT18 -> #REF! | AE9: =[2]หน้าผ้า!AU18 -> #REF! | AF9: =[2]หน้าผ้า!AI18 -> ระบุในSD | AG9: =[3]หน้าผ้า!DC21 -> พร้อมส่ง | AH9: =[2]หน้าผ้า!DL18 -> 0 | AI9: =[2]หน้าผ้า!DM18 -> Lead time | AJ9: =[2]หน้าผ้า!DN18 -> 0 | AK9: =[2]หน้าผ้า!DQ18 -> 0 | AL9: =[2]หน้าผ้า!DR18 -> 0 | AM9: =[2]หน้าผ้า!DS18 -> 0 | AN9: =[2]หน้าผ้า!DT18 -> 0 | AO9: =[2]หน้าผ้า!DU18 -> 0 | AP9: =[2]หน้าผ้า!DP18 -> 0 | AQ9: =[2]หน้าผ้า!DW18 -> 0 | AR9: =[2]หน้าผ้า!DX18 -> 0 | AS9: =[2]หน้าผ้า!DY18 -> 0 | AT9: =[2]หน้าผ้า!DZ18 -> 0 | AU9: =[2]หน้าผ้า!EA18 -> 0 | AV9: =[2]หน้าผ้า!EB18 -> 0 | AW9: =[2]หน้าผ้า!EC18 -> 0 | AX9: =[2]หน้าผ้า!ED18 -> 0 | AY9: =[2]หน้าผ้า!AG18 -> 0 | AZ9: =[2]หน้าผ้า!EG18 -> 0 | BA9: =[2]หน้าผ้า!EH18 -> 0 | BB9: =[2]หน้าผ้า!EI18 -> 0 | BC9: =[2]หน้าผ้า!BZ18 -> WRWT160800/WRWT25800 | BD9: =[2]หน้าผ้า!CA18 -> 0
A10: =[2]หน้าผ้า!C19 -> ประมาณการ | B10: =[2]หน้าผ้า!B19 -> ประมาณการ | C10: =[2]หน้าผ้า!E19 -> บจก.เคอรี่ฟลาวมิลล์ | D10: =[2]หน้าผ้า!F19 -> โบว์แดง 10กก | E10: =[2]หน้าผ้า!G19 -> 16 | F10: =[2]หน้าผ้า!H19 -> 25 | G10: =[2]หน้าผ้า!I19 -> ขาว | H10: =[2]หน้าผ้า!J19 -> 0 | I10: =[2]หน้าผ้า!L19 -> 45 | J10: =[2]หน้าผ้า!M19 -> ± | K10: =[2]หน้าผ้า!N19 -> 5 | L10: =[2]หน้าผ้า!R19 -> ไม่ | M10: =[2]หน้าผ้า!T19 -> ไม่สวมถุงใน | N10: =[2]หน้าผ้า!U19 -> 0 | O10: =[2]หน้าผ้า!V19 -> 0 | P10: =[2]หน้าผ้า!AB19 -> 0 | Q10: =[2]หน้าผ้า!AC19 -> 0 | R10: =[2]หน้าผ้า!AD19 -> 0 | S10: =[2]หน้าผ้า!Z19 -> ห่ออัดเบลแบน500 | T10: =[2]หน้าผ้า!X19 -> รอแจ้ง | U10: =[2]หน้าผ้า!AA19 -> 5000 | V10: =[2]หน้าผ้า!AJ19 -> 5000 | W10: =[2]หน้าผ้า!AL19 -> 0 | X10: =[2]หน้าผ้า!AM19 -> 5370 | Y10: =[2]หน้าผ้า!AN19 -> 0 | Z10: =[2]หน้าผ้า!AO19 -> WSWT1625800 | AA10: =[2]หน้าผ้า!AQ19 -> 0 | AB10: =[2]หน้าผ้า!AR19 -> 0 | AC10: =[2]หน้าผ้า!AS19 -> 0 | AD10: =[2]หน้าผ้า!AT19 -> 0 | AE10: =[2]หน้าผ้า!AU19 -> 0 | AF10: =[2]หน้าผ้า!AI19 -> 0 | AG10: =[3]หน้าผ้า!DC22 -> พร้อมส่ง | AH10: =[2]หน้าผ้า!DL19 -> P7 | AI10: =[2]หน้าผ้า!DM19 -> 2 | AJ10: =[2]หน้าผ้า!DN19 -> รอแจ้ง | AK10: =[2]หน้าผ้า!DQ19 -> 0 | AL10: =[2]หน้าผ้า!DR19 -> #VALUE! | AM10: =[2]หน้าผ้า!DS19 -> #VALUE! | AN10: =[2]หน้าผ้า!DT19 -> #VALUE! | AO10: =[2]หน้าผ้า!DU19 -> #VALUE! | AP10: =[2]หน้าผ้า!DP19 -> #VALUE! | AQ10: =[2]หน้าผ้า!DW19 -> 0 | AR10: =[2]หน้าผ้า!DX19 -> 0 | AS10: =[2]หน้าผ้า!DY19 -> 0 | AT10: =[2]หน้าผ้า!DZ19 -> 0 | AU10: =[2]หน้าผ้า!EA19 -> 0 | AV10: =[2]หน้าผ้า!EB19 -> 0 | AW10: =[2]หน้าผ้า!EC19 -> งานพิมพ์ | AX10: =[2]หน้าผ้า!ED19 -> / | AY10: =[2]หน้าผ้า!AG19 -> รอเก็บลบสีผสม | AZ10: =[2]หน้าผ้า!EG19 -> 0 | BA10: =[2]หน้าผ้า!EH19 -> 0 | BB10: =[2]หน้าผ้า!EI19 -> 0 | BC10: =[2]หน้าผ้า!BZ19 -> WRWT25800/WRWT25800 | BD10: =[2]หน้าผ้า!CA19 -> 0
A11: =[2]หน้าผ้า!C20 -> 0 | B11: =[2]หน้าผ้า!B20 -> 0 | C11: =[2]หน้าผ้า!E20 -> 0 | D11: =[2]หน้าผ้า!F20 -> 0 | E11: =[2]หน้าผ้า!G20 -> 16 | F11: =[2]หน้าผ้า!H20 -> 25 | G11: =[2]หน้าผ้า!I20 -> ขาว | H11: =[2]หน้าผ้า!J20 -> 0 | I11: =[2]หน้าผ้า!L20 -> 45 | J11: =[2]หน้าผ้า!M20 -> ± | K11: =[2]หน้าผ้า!N20 -> 5 | L11: =[2]หน้าผ้า!R20 -> 0 | M11: =[2]หน้าผ้า!T20 -> 0 | N11: =[2]หน้าผ้า!U20 -> 0 | O11: =[2]หน้าผ้า!V20 -> 0 | P11: =[2]หน้าผ้า!AB20 -> 0 | Q11: =[2]หน้าผ้า!AC20 -> 0 | R11: =[2]หน้าผ้า!AD20 -> 0 | S11: =[2]หน้าผ้า!Z20 -> 0 | T11: =[2]หน้าผ้า!X20 -> 0 | U11: =[2]หน้าผ้า!AA20 -> 0 | V11: =[2]หน้าผ้า!AJ20 -> 0 | W11: =[2]หน้าผ้า!AL20 -> 0 | X11: =[2]หน้าผ้า!AM20 -> 0 | Y11: =[2]หน้าผ้า!AN20 -> 0 | Z11: =[2]หน้าผ้า!AO20 -> WSWT1625800 | AA11: =[2]หน้าผ้า!AQ20 -> 0 | AB11: =[2]หน้าผ้า!AR20 -> 0 | AC11: =[2]หน้าผ้า!AS20 -> 0 | AD11: =[2]หน้าผ้า!AT20 -> 0 | AE11: =[2]หน้าผ้า!AU20 -> 0 | AF11: =[2]หน้าผ้า!AI20 -> ระบุในSD | AG11: =[3]หน้าผ้า!DC23 -> ยังไม่ได้พิมพ์ | AH11: =[2]หน้าผ้า!DL20 -> 0 | AI11: =[2]หน้าผ้า!DM20 -> Lead time | AJ11: =[2]หน้าผ้า!DN20 -> 0 | AK11: =[2]หน้าผ้า!DQ20 -> 0 | AL11: =[2]หน้าผ้า!DR20 -> 0 | AM11: =[2]หน้าผ้า!DS20 -> 0 | AN11: =[2]หน้าผ้า!DT20 -> 0 | AO11: =[2]หน้าผ้า!DU20 -> 0 | AP11: =[2]หน้าผ้า!DP20 -> 0 | AQ11: =[2]หน้าผ้า!DW20 -> 0 | AR11: =[2]หน้าผ้า!DX20 -> 0 | AS11: =[2]หน้าผ้า!DY20 -> 0 | AT11: =[2]หน้าผ้า!DZ20 -> 0 | AU11: =[2]หน้าผ้า!EA20 -> 0 | AV11: =[2]หน้าผ้า!EB20 -> 0 | AW11: =[2]หน้าผ้า!EC20 -> 0 | AX11: =[2]หน้าผ้า!ED20 -> 0 | AY11: =[2]หน้าผ้า!AG20 -> 0 | AZ11: =[2]หน้าผ้า!EG20 -> 0 | BA11: =[2]หน้าผ้า!EH20 -> 0 | BB11: =[2]หน้าผ้า!EI20 -> 0 | BC11: =[2]หน้าผ้า!BZ20 -> WRWT160800/WRWT25800 | BD11: =[2]หน้าผ้า!CA20 -> 0
A12: =[2]หน้าผ้า!C21 -> 0 | B12: =[2]หน้าผ้า!B21 -> 0 | C12: =[2]หน้าผ้า!E21 -> 0 | D12: =[2]หน้าผ้า!F21 -> 0 | E12: =[2]หน้าผ้า!G21 -> 16 | F12: =[2]หน้าผ้า!H21 -> 25 | G12: =[2]หน้าผ้า!I21 -> 0 | H12: =[2]หน้าผ้า!J21 -> 0 | I12: =[2]หน้าผ้า!L21 -> 47 | J12: =[2]หน้าผ้า!M21 -> ± | K12: =[2]หน้าผ้า!N21 -> 5 | L12: =[2]หน้าผ้า!R21 -> 0 | M12: =[2]หน้าผ้า!T21 -> 0 | N12: =[2]หน้าผ้า!U21 -> 0 | O12: =[2]หน้าผ้า!V21 -> 0 | P12: =[2]หน้าผ้า!AB21 -> 0 | Q12: =[2]หน้าผ้า!AC21 -> 0 | R12: =[2]หน้าผ้า!AD21 -> 0 | S12: =[2]หน้าผ้า!Z21 -> 0 | T12: =[2]หน้าผ้า!X21 -> 0 | U12: =[2]หน้าผ้า!AA21 -> 0 | V12: =[2]หน้าผ้า!AJ21 -> 0 | W12: =[2]หน้าผ้า!AL21 -> 0 | X12: =[2]หน้าผ้า!AM21 -> 0 | Y12: =[2]หน้าผ้า!AN21 -> 0 | Z12: =[2]หน้าผ้า!AO21 -> WSWT1621720SMFX | AA12: =[2]หน้าผ้า!AQ21 -> #REF! | AB12: =[2]หน้าผ้า!AR21 -> #REF! | AC12: =[2]หน้าผ้า!AS21 -> #REF! | AD12: =[2]หน้าผ้า!AT21 -> #REF! | AE12: =[2]หน้าผ้า!AU21 -> #REF! | AF12: =[2]หน้าผ้า!AI21 -> ระบุในSD | AG12: =[3]หน้าผ้า!DC24 -> พิมพ์ไม่ครบ | AH12: =[2]หน้าผ้า!DL21 -> 0 | AI12: =[2]หน้าผ้า!DM21 -> 0 | AJ12: =[2]หน้าผ้า!DN21 -> 0 | AK12: =[2]หน้าผ้า!DQ21 -> 0 | AL12: =[2]หน้าผ้า!DR21 -> 0 | AM12: =[2]หน้าผ้า!DS21 -> 0 | AN12: =[2]หน้าผ้า!DT21 -> 0 | AO12: =[2]หน้าผ้า!DU21 -> 0 | AP12: =[2]หน้าผ้า!DP21 -> 0 | AQ12: =[2]หน้าผ้า!DW21 -> 0 | AR12: =[2]หน้าผ้า!DX21 -> 0 | AS12: =[2]หน้าผ้า!DY21 -> 0 | AT12: =[2]หน้าผ้า!DZ21 -> 0 | AU12: =[2]หน้าผ้า!EA21 -> 0 | AV12: =[2]หน้าผ้า!EB21 -> 0 | AW12: =[2]หน้าผ้า!EC21 -> 0 | AX12: =[2]หน้าผ้า!ED21 -> 0 | AY12: =[2]หน้าผ้า!AG21 -> 0 | AZ12: =[2]หน้าผ้า!EG21 -> 0 | BA12: =[2]หน้าผ้า!EH21 -> 0 | BB12: =[2]หน้าผ้า!EI21 -> 0 | BC12: =[2]หน้าผ้า!BZ21 -> WRWT160720/WRWT21720 | BD12: =[2]หน้าผ้า!CA21 -> 0
A13: =[2]หน้าผ้า!C22 -> 0 | B13: =[2]หน้าผ้า!B22 -> 0 | C13: =[2]หน้าผ้า!E22 -> 0 | D13: =[2]หน้าผ้า!F22 -> 0 | E13: =[2]หน้าผ้า!G22 -> 17 | F13: =[2]หน้าผ้า!H22 -> 26 | G13: =[2]หน้าผ้า!I22 -> 0 | H13: =[2]หน้าผ้า!J22 -> 0 | I13: =[2]หน้าผ้า!L22 -> 48 | J13: =[2]หน้าผ้า!M22 -> ± | K13: =[2]หน้าผ้า!N22 -> 5 | L13: =[2]หน้าผ้า!R22 -> 0 | M13: =[2]หน้าผ้า!T22 -> 0 | N13: =[2]หน้าผ้า!U22 -> 0 | O13: =[2]หน้าผ้า!V22 -> 0 | P13: =[2]หน้าผ้า!AB22 -> 0 | Q13: =[2]หน้าผ้า!AC22 -> 0 | R13: =[2]หน้าผ้า!AD22 -> 0 | S13: =[2]หน้าผ้า!Z22 -> 0 | T13: =[2]หน้าผ้า!X22 -> 0 | U13: =[2]หน้าผ้า!AA22 -> 0 | V13: =[2]หน้าผ้า!AJ22 -> 0 | W13: =[2]หน้าผ้า!AL22 -> 0 | X13: =[2]หน้าผ้า!AM22 -> 0 | Y13: =[2]หน้าผ้า!AN22 -> 0 | Z13: =[2]หน้าผ้า!AO22 -> WSWT1725800 | AA13: =[2]หน้าผ้า!AQ22 -> #REF! | AB13: =[2]หน้าผ้า!AR22 -> #REF! | AC13: =[2]หน้าผ้า!AS22 -> #REF! | AD13: =[2]หน้าผ้า!AT22 -> #REF! | AE13: =[2]หน้าผ้า!AU22 -> #REF! | AF13: =[2]หน้าผ้า!AI22 -> ระบุในSD | AG13: =[3]หน้าผ้า!DC25 -> ผ้าขาว | AH13: =[2]หน้าผ้า!DL22 -> 0 | AI13: =[2]หน้าผ้า!DM22 -> 0 | AJ13: =[2]หน้าผ้า!DN22 -> 0 | AK13: =[2]หน้าผ้า!DQ22 -> 0 | AL13: =[2]หน้าผ้า!DR22 -> 0 | AM13: =[2]หน้าผ้า!DS22 -> 0 | AN13: =[2]หน้าผ้า!DT22 -> 0 | AO13: =[2]หน้าผ้า!DU22 -> 0 | AP13: =[2]หน้าผ้า!DP22 -> 0 | AQ13: =[2]หน้าผ้า!DW22 -> 0 | AR13: =[2]หน้าผ้า!DX22 -> 0 | AS13: =[2]หน้าผ้า!DY22 -> 0 | AT13: =[2]หน้าผ้า!DZ22 -> 0 | AU13: =[2]หน้าผ้า!EA22 -> 0 | AV13: =[2]หน้าผ้า!EB22 -> 0 | AW13: =[2]หน้าผ้า!EC22 -> 0 | AX13: =[2]หน้าผ้า!ED22 -> 0 | AY13: =[2]หน้าผ้า!AG22 -> 0 | AZ13: =[2]หน้าผ้า!EG22 -> 0 | BA13: =[2]หน้าผ้า!EH22 -> 0 | BB13: =[2]หน้าผ้า!EI22 -> 0 | BC13: =[2]หน้าผ้า!BZ22 -> WRWT170800/WRWT25800 | BD13: =[2]หน้าผ้า!CA22 -> 0
A14: =[2]หน้าผ้า!C23 -> 45950 | B14: =[2]หน้าผ้า!B23 -> MK68-001247 | C14: =[2]หน้าผ้า!E23 -> บจก.ฟาเธอร์ส วิง ซัพพลาย | D14: =[2]หน้าผ้า!F23 -> รถไฟฟ้า | E14: =[2]หน้าผ้า!G23 -> 18 | F14: =[2]หน้าผ้า!H23 -> 30 | G14: =[2]หน้าผ้า!I23 -> ขาว | H14: =[2]หน้าผ้า!J23 -> 0 | I14: =[2]หน้าผ้า!L23 -> 54 | J14: =[2]หน้าผ้า!M23 -> ± | K14: =[2]หน้าผ้า!N23 -> 5 | L14: =[2]หน้าผ้า!R23 -> บิด | M14: =[2]หน้าผ้า!T23 -> 19 | N14: =[2]หน้าผ้า!U23 -> 33 | O14: =[2]หน้าผ้า!V23 -> 40 | P14: =[2]หน้าผ้า!AB23 -> 77.343329 | Q14: =[2]หน้าผ้า!AC23 -> 0 | R14: =[2]หน้าผ้า!AD23 -> 77.343329 | S14: =[2]หน้าผ้า!Z23 -> 500กระสอบ | T14: =[2]หน้าผ้า!X23 -> 45961 | U14: =[2]หน้าผ้า!AA23 -> 5000 | V14: =[2]หน้าผ้า!AJ23 -> 0 | W14: =[2]หน้าผ้า!AL23 -> 5000 | X14: =[2]หน้าผ้า!AM23 -> 0 | Y14: =[2]หน้าผ้า!AN23 -> 5250 | Z14: =[2]หน้าผ้า!AO23 -> WSWT1825800 | AA14: =[2]หน้าผ้า!AQ23 -> 4400.55 | AB14: =[2]หน้าผ้า!AR23 -> 4400.55 | AC14: =[2]หน้าผ้า!AS23 -> 0 | AD14: =[2]หน้าผ้า!AT23 -> 0 | AE14: =[2]หน้าผ้า!AU23 -> 0 | AF14: =[2]หน้าผ้า!AI23 -> 0 | AG14: =[3]หน้าผ้า!DC26 -> ยังไม่ได้พิมพ์ | AH14: =[2]หน้าผ้า!DL23 -> P9 | AI14: =[2]หน้าผ้า!DM23 -> 3 | AJ14: =[2]หน้าผ้า!DN23 -> 45961 | AK14: =[2]หน้าผ้า!DQ23 -> 0 | AL14: =[2]หน้าผ้า!DR23 -> 45951 | AM14: =[2]หน้าผ้า!DS23 -> 45958 | AN14: =[2]หน้าผ้า!DT23 -> 45959 | AO14: =[2]หน้าผ้า!DU23 -> 45959 | AP14: =[2]หน้าผ้า!DP23 -> 45956 | AQ14: =[2]หน้าผ้า!DW23 -> 45960 | AR14: =[2]หน้าผ้า!DX23 -> 0 | AS14: =[2]หน้าผ้า!DY23 -> 0 | AT14: =[2]หน้าผ้า!DZ23 -> 0 | AU14: =[2]หน้าผ้า!EA23 -> 0 | AV14: =[2]หน้าผ้า!EB23 -> 0 | AW14: =[2]หน้าผ้า!EC23 -> งานพิมพ์ | AX14: =[2]หน้าผ้า!ED23 -> / | AY14: =[2]หน้าผ้า!AG23 -> 0 | AZ14: =[2]หน้าผ้า!EG23 -> 0 | BA14: =[2]หน้าผ้า!EH23 -> 0 | BB14: =[2]หน้าผ้า!EI23 -> 0 | BC14: =[2]หน้าผ้า!BZ23 -> WRWT25800/WRWT25800 | BD14: =[2]หน้าผ้า!CA23 -> 0
A15: =[2]หน้าผ้า!C24 -> 45950 | B15: =[2]หน้าผ้า!B24 -> MK68-001247 | C15: =[2]หน้าผ้า!E24 -> บจก.ฟาเธอร์ส วิง ซัพพลาย | D15: =[2]หน้าผ้า!F24 -> รถไฟฟ้าปูนขาวเย็น | E15: =[2]หน้าผ้า!G24 -> 18 | F15: =[2]หน้าผ้า!H24 -> 30 | G15: =[2]หน้าผ้า!I24 -> ขาว | H15: =[2]หน้าผ้า!J24 -> 0 | I15: =[2]หน้าผ้า!L24 -> 54 | J15: =[2]หน้าผ้า!M24 -> ± | K15: =[2]หน้าผ้า!N24 -> 5 | L15: =[2]หน้าผ้า!R24 -> บิด | M15: =[2]หน้าผ้า!T24 -> 19 | N15: =[2]หน้าผ้า!U24 -> 33 | O15: =[2]หน้าผ้า!V24 -> 40 | P15: =[2]หน้าผ้า!AB24 -> 309.37332 | Q15: =[2]หน้าผ้า!AC24 -> 0 | R15: =[2]หน้าผ้า!AD24 -> 309.37332 | S15: =[2]หน้าผ้า!Z24 -> 500กระสอบ | T15: =[2]หน้าผ้า!X24 -> 45961 | U15: =[2]หน้าผ้า!AA24 -> 20000 | V15: =[2]หน้าผ้า!AJ24 -> 0 | W15: =[2]หน้าผ้า!AL24 -> 20000 | X15: =[2]หน้าผ้า!AM24 -> 5520 | Y15: =[2]หน้าผ้า!AN24 -> 15204 | Z15: =[2]หน้าผ้า!AO24 -> WSWT1825800 | AA15: =[2]หน้าผ้า!AQ24 -> 13381.192 | AB15: =[2]หน้าผ้า!AR24 -> 13381.192 | AC15: =[2]หน้าผ้า!AS24 -> 0 | AD15: =[2]หน้าผ้า!AT24 -> 0 | AE15: =[2]หน้าผ้า!AU24 -> 0 | AF15: =[2]หน้าผ้า!AI24 -> 0 | AG15: =[3]หน้าผ้า!DC27 -> ยังไม่ได้พิมพ์ | AH15: =[2]หน้าผ้า!DL24 -> P9 | AI15: =[2]หน้าผ้า!DM24 -> 3 | AJ15: =[2]หน้าผ้า!DN24 -> 45961 | AK15: =[2]หน้าผ้า!DQ24 -> 0 | AL15: =[2]หน้าผ้า!DR24 -> 45951 | AM15: =[2]หน้าผ้า!DS24 -> 45958 | AN15: =[2]หน้าผ้า!DT24 -> 45959 | AO15: =[2]หน้าผ้า!DU24 -> 45959 | AP15: =[2]หน้าผ้า!DP24 -> 45956 | AQ15: =[2]หน้าผ้า!DW24 -> 45960 | AR15: =[2]หน้าผ้า!DX24 -> 0 | AS15: =[2]หน้าผ้า!DY24 -> 0 | AT15: =[2]หน้าผ้า!DZ24 -> 0 | AU15: =[2]หน้าผ้า!EA24 -> 0 | AV15: =[2]หน้าผ้า!EB24 -> 0 | AW15: =[2]หน้าผ้า!EC24 -> งานพิมพ์ | AX15: =[2]หน้าผ้า!ED24 -> / | AY15: =[2]หน้าผ้า!AG24 -> 0 | AZ15: =[2]หน้าผ้า!EG24 -> 0 | BA15: =[2]หน้าผ้า!EH24 -> 0 | BB15: =[2]หน้าผ้า!EI24 -> 0 | BC15: =[2]หน้าผ้า!BZ24 -> WRWT25800/WRWT25800 | BD15: =[2]หน้าผ้า!CA24 -> 0
A16: =[2]หน้าผ้า!C25 -> 45950 | B16: =[2]หน้าผ้า!B25 -> MK68-001247 | C16: =[2]หน้าผ้า!E25 -> บจก.ฟาเธอร์ส วิง ซัพพลาย | D16: =[2]หน้าผ้า!F25 -> ไม่พิมพ์ | E16: =[2]หน้าผ้า!G25 -> 18 | F16: =[2]หน้าผ้า!H25 -> 30 | G16: =[2]หน้าผ้า!I25 -> ขาว | H16: =[2]หน้าผ้า!J25 -> 0 | I16: =[2]หน้าผ้า!L25 -> 54 | J16: =[2]หน้าผ้า!M25 -> ± | K16: =[2]หน้าผ้า!N25 -> 5 | L16: =[2]หน้าผ้า!R25 -> ไม่ | M16: =[2]หน้าผ้า!T25 -> 19 | N16: =[2]หน้าผ้า!U25 -> 33 | O16: =[2]หน้าผ้า!V25 -> 40 | P16: =[2]หน้าผ้า!AB25 -> 46.405998 | Q16: =[2]หน้าผ้า!AC25 -> 0 | R16: =[2]หน้าผ้า!AD25 -> 46.405998 | S16: =[2]หน้าผ้า!Z25 -> 500กระสอบ | T16: =[2]หน้าผ้า!X25 -> 45961 | U16: =[2]หน้าผ้า!AA25 -> 3000 | V16: =[2]หน้าผ้า!AJ25 -> 0 | W16: =[2]หน้าผ้า!AL25 -> 3000 | X16: =[2]หน้าผ้า!AM25 -> 0 | Y16: =[2]หน้าผ้า!AN25 -> 0 | Z16: =[2]หน้าผ้า!AO25 -> WSWT1825800 | AA16: =[2]หน้าผ้า!AQ25 -> 2640.33 | AB16: =[2]หน้าผ้า!AR25 -> 2640.33 | AC16: =[2]หน้าผ้า!AS25 -> 0 | AD16: =[2]หน้าผ้า!AT25 -> 0 | AE16: =[2]หน้าผ้า!AU25 -> 0 | AF16: =[2]หน้าผ้า!AI25 -> 0 | AG16: =[3]หน้าผ้า!DC28 -> ยังไม่ได้พิมพ์ | AH16: =[2]หน้าผ้า!DL25 -> P9 | AI16: =[2]หน้าผ้า!DM25 -> 3 | AJ16: =[2]หน้าผ้า!DN25 -> 45961 | AK16: =[2]หน้าผ้า!DQ25 -> 0 | AL16: =[2]หน้าผ้า!DR25 -> 0 | AM16: =[2]หน้าผ้า!DS25 -> 0 | AN16: =[2]หน้าผ้า!DT25 -> 0 | AO16: =[2]หน้าผ้า!DU25 -> 45957 | AP16: =[2]หน้าผ้า!DP25 -> 45956 | AQ16: =[2]หน้าผ้า!DW25 -> 45958 | AR16: =[2]หน้าผ้า!DX25 -> 0 | AS16: =[2]หน้าผ้า!DY25 -> 0 | AT16: =[2]หน้าผ้า!DZ25 -> 0 | AU16: =[2]หน้าผ้า!EA25 -> 0 | AV16: =[2]หน้าผ้า!EB25 -> 0 | AW16: =[2]หน้าผ้า!EC25 -> ตัด | AX16: =[2]หน้าผ้า!ED25 -> 0 | AY16: =[2]หน้าผ้า!AG25 -> 0 | AZ16: =[2]หน้าผ้า!EG25 -> 0 | BA16: =[2]หน้าผ้า!EH25 -> 0 | BB16: =[2]หน้าผ้า!EI25 -> 0 | BC16: =[2]หน้าผ้า!BZ25 -> WRWT25800/WRWT25800 | BD16: =[2]หน้าผ้า!CA25 -> 0
A17: =[2]หน้าผ้า!C26 -> 0 | B17: =[2]หน้าผ้า!B26 -> ใบรับคำสั่งซื้อ | C17: =[2]หน้าผ้า!E26 -> บจก.ซีแมน | D17: =[2]หน้าผ้า!F26 -> Y30 | E17: =[2]หน้าผ้า!G26 -> 18 | F17: =[2]หน้าผ้า!H26 -> 25 | G17: =[2]หน้าผ้า!I26 -> ขาว | H17: =[2]หน้าผ้า!J26 -> 0 | I17: =[2]หน้าผ้า!L26 -> 50 | J17: =[2]หน้าผ้า!M26 -> ± | K17: =[2]หน้าผ้า!N26 -> 5 | L17: =[2]หน้าผ้า!R26 -> ไม่ | M17: =[2]หน้าผ้า!T26 -> 20 | N17: =[2]หน้าผ้า!U26 -> 27 | O17: =[2]หน้าผ้า!V26 -> 90 | P17: =[2]หน้าผ้า!AB26 -> 299.75166 | Q17: =[2]หน้าผ้า!AC26 -> 0 | R17: =[2]หน้าผ้า!AD26 -> 299.75166 | S17: =[2]หน้าผ้า!Z26 -> มัด100 | T17: =[2]หน้าผ้า!X26 -> 45961 | U17: =[2]หน้าผ้า!AA26 -> 10000 | V17: =[2]หน้าผ้า!AJ26 -> 0 | W17: =[2]หน้าผ้า!AL26 -> 10000 | X17: =[2]หน้าผ้า!AM26 -> 0 | Y17: =[2]หน้าผ้า!AN26 -> 10500 | Z17: =[2]หน้าผ้า!AO26 -> WSWT1825800 | AA17: =[2]หน้าผ้า!AQ26 -> 7404.1 | AB17: =[2]หน้าผ้า!AR26 -> 0 | AC17: =[2]หน้าผ้า!AS26 -> 7404.1 | AD17: =[2]หน้าผ้า!AT26 -> 0 | AE17: =[2]หน้าผ้า!AU26 -> 0 | AF17: =[2]หน้าผ้า!AI26 -> 0 | AG17: =[3]หน้าผ้า!DC29 -> ยังไม่ได้พิมพ์ | AH17: =[2]หน้าผ้า!DL26 -> P9 | AI17: =[2]หน้าผ้า!DM26 -> 3 | AJ17: =[2]หน้าผ้า!DN26 -> 45961 | AK17: =[2]หน้าผ้า!DQ26 -> 0 | AL17: =[2]หน้าผ้า!DR26 -> 45951 | AM17: =[2]หน้าผ้า!DS26 -> 45958 | AN17: =[2]หน้าผ้า!DT26 -> 45959 | AO17: =[2]หน้าผ้า!DU26 -> 45959 | AP17: =[2]หน้าผ้า!DP26 -> 45956 | AQ17: =[2]หน้าผ้า!DW26 -> 45960 | AR17: =[2]หน้าผ้า!DX26 -> 0 | AS17: =[2]หน้าผ้า!DY26 -> 0 | AT17: =[2]หน้าผ้า!DZ26 -> 0 | AU17: =[2]หน้าผ้า!EA26 -> 0 | AV17: =[2]หน้าผ้า!EB26 -> 0 | AW17: =[2]หน้าผ้า!EC26 -> งานพิมพ์ | AX17: =[2]หน้าผ้า!ED26 -> 0 | AY17: =[2]หน้าผ้า!AG26 -> 0 | AZ17: =[2]หน้าผ้า!EG26 -> 0 | BA17: =[2]หน้าผ้า!EH26 -> 0 | BB17: =[2]หน้าผ้า!EI26 -> 0 | BC17: =[2]หน้าผ้า!BZ26 -> WRWT25800/WRWT25800 | BD17: =[2]หน้าผ้า!CA26 -> 509.40208
... A575: =[2]หน้าผ้า!C584 -> 0 | B575: =[2]หน้าผ้า!B584 -> 0 | C575: =[2]หน้าผ้า!E584 -> 0 | D575: =[2]หน้าผ้า!F584 -> 0 | E575: =[2]หน้าผ้า!G584 -> 0 | F575: =[2]หน้าผ้า!H584 -> 0 | G575: =[2]หน้าผ้า!I584 -> 0 | H575: =[2]หน้าผ้า!J584 -> 0 | I575: =[2]หน้าผ้า!L584 -> 0 | J575: =[2]หน้าผ้า!M584 -> 0 | K575: =[2]หน้าผ้า!N584 -> 0 | L575: =[2]หน้าผ้า!R584 -> 0 | M575: =[2]หน้าผ้า!T584 -> 0 | N575: =[2]หน้าผ้า!U584 -> 0 | O575: =[2]หน้าผ้า!V584 -> 0 | P575: =[2]หน้าผ้า!AB584 -> 0 | Q575: =[2]หน้าผ้า!AC584 -> 0 | R575: =[2]หน้าผ้า!AD584 -> 0 | S575: =[2]หน้าผ้า!Z584 -> 0 | T575: =[2]หน้าผ้า!X584 -> 0 | U575: =[2]หน้าผ้า!AA584 -> 0 | V575: =[2]หน้าผ้า!AJ584 -> 0 | W575: =[2]หน้าผ้า!AL584 -> 0 | X575: =[2]หน้าผ้า!AM584 -> 0 | Y575: =[2]หน้าผ้า!AN584 -> 0 | Z575: =[2]หน้าผ้า!AO584 -> 0 | AA575: =[2]หน้าผ้า!AQ584 -> 0 | AB575: =[2]หน้าผ้า!AR584 -> 0 | AC575: =[2]หน้าผ้า!AS584 -> 0 | AD575: =[2]หน้าผ้า!AT584 -> 0 | AE575: =[2]หน้าผ้า!AU584 -> 0 | AF575: =[2]หน้าผ้า!AI584 -> 0 | AG575: =[3]หน้าผ้า!DC587 -> 0 | AH575: =[2]หน้าผ้า!DL584 -> 0 | AI575: =[2]หน้าผ้า!DM584 -> 0 | AJ575: =[2]หน้าผ้า!DN584 -> 0 | AK575: =[2]หน้าผ้า!DQ584 -> 0 | AL575: =[2]หน้าผ้า!DR584 -> 0 | AM575: =[2]หน้าผ้า!DS584 -> 0 | AN575: =[2]หน้าผ้า!DT584 -> 0 | AO575: =[2]หน้าผ้า!DU584 -> 0 | AP575: =[2]หน้าผ้า!DP584 -> 0 | AQ575: =[2]หน้าผ้า!DW584 -> 0 | AR575: =[2]หน้าผ้า!DX584 -> 0 | AS575: =[2]หน้าผ้า!DY584 -> 0 | AT575: =[2]หน้าผ้า!DZ584 -> 0 | AU575: =[2]หน้าผ้า!EA584 -> 0 | AV575: =[2]หน้าผ้า!EB584 -> 0 | AW575: =[2]หน้าผ้า!EC584 -> 0 | AX575: =[2]หน้าผ้า!ED584 -> 0 | AY575: =[2]หน้าผ้า!AG584 -> 0 | AZ575: =[2]หน้าผ้า!EG584 -> 0 | BA575: =[2]หน้าผ้า!EH584 -> 0 | BB575: =[2]หน้าผ้า!EI584 -> 0 | BC575: =[2]หน้าผ้า!BZ584 -> 0 | BD575: =[2]หน้าผ้า!CA584 -> 0

Sheet 9(Order+FC)
A2: เลขที่ SO | B2: (หลายรายการ)
A3: วันส่ง | B3: (หลายรายการ)
A4: ชื่อลูกค้า | B4: (ทั้งหมด)
K5: 9
A6: ประเภท | B6: ผลรวม ของ จำนวนส่ง | C6: ผลรวม ของ ค้างพิมพ์ | D6: ผลรวม ของ ค้างตัด | E6: ผลรวม ของ ใช้ | F6: ผลรวม ของ Stock | G6: ผลรวม ของ ค้างทอ
A7: WSWT1921720 | B7: 205000 | C7: 0 | D7: 30000 | E7: 0 | F7: 0 | G7: 0 | H7: =+J7-I7 -> 0 | J7: =G7 -> 0
A8: WSWT19251000SM | B8: 5040 | C8: 5292 | D8: 5040 | E8: 4999.0248 | F8: 4999.0248 | G8: 0 | H8: =+J8-I8 -> 0 | J8: =G8 -> 0
A9: WSWT1925800 | B9: 20000 | C9: 21000 | D9: 20000 | E9: 17602.2 | F9: 17602.2 | G9: 0 | H9: =+J9-I9 -> 0 | J9: =G9 -> 0
A10: WSWT2025800 | B10: 89360 | C10: 84000 | D10: 86360 | E10: 83820 | F10: 83820 | G10: 0 | H10: =+J10-I10 -> 0 | J10: =G10 -> 0
A11: WSWT2025800SM | B11: 171120 | C11: 68376 | D11: 72271 | E11: 70323.862 | F11: 70323.862 | G11: 0 | H11: =+J11-I11 -> 0 | J11: =G11 -> 0
A12: WSWT2121670SM | B12: 85000 | C12: 38850 | D12: 64000 | E12: 56774.08 | F12: 56774.08 | G12: 0 | H12: =+J12-I12 -> 0 | J12: =G12 -> 0 | K12: 40000 | L12: =+K5*K12 -> 360000 | M12: =+L12-J12 -> 360000
A13: WSWT2325650 | B13: 60000 | C13: 63000 | D13: 60000 | E13: 59512.2 | F13: 59512.2 | G13: 0 | H13: =+J13-I13 -> 0 | J13: =G13 -> 0 | K13: 14000 | L13: =+K13*K5 -> 126000 | M13: =+L13-J13 -> 126000
A14: WSWT2625650 | B14: 5000 | C14: 0 | D14: 0 | E14: 0 | F14: 0 | G14: 0 | H14: =+J14-I14 -> 0 | J14: =G14 -> 0
A15: WSWT2625800 | B15: 10000 | C15: 0 | D15: 10000 | E15: 12433.3 | F15: 12433.3 | G15: 0 | H15: =+J15-I15 -> 0 | J15: =G15 -> 0 | K15: 20000 | L15: =+K15*K5 -> 180000 | M15: =+L15-J15 -> 180000
A16: WSWT2625850SM | B16: 40000 | C16: 31526.25 | D16: 35900 | E16: 38606.951 | F16: 17295.635 | G16: 21311.316 | H16: =+J16-I16 -> 21311.316 | J16: =G16 -> 21311.316
A17: WSWT2825850 | B17: 105000 | C17: 51765 | D17: 54300 | E17: 65316.735 | F17: 5780 | G17: 59536.735 | H17: =+J17-I17 -> 59536.735 | J17: =G17 -> 59536.735
A18: ผลรวมทั้งหมด | B18: 795520 | C18: 363809.25 | D18: 437871 | E18: 409388.35 | F18: 328540.3 | G18: 80848.051 | H18: =+J18-I18 -> 80848.051 | J18: =G18 -> 80848.051
H19: 0 | I19: 54000 | J19: =G19 -> 0
H20: =+J20-I20 -> 0 | J20: =G20 -> 0
H21: =+J21-I21 -> 0 | J21: =G21 -> 0
H22: =+J22-I22 -> 0 | J22: =G22 -> 0
H23: =+J23-I23 -> 0 | J23: =G23 -> 0
H24: =+J24-I24 -> 0 | J24: =G24 -> 0
H25: =+J25-I25 -> 0 | J25: =G25 -> 0
H26: =+J26-I26 -> 0 | J26: =G26 -> 0
H27: =+J27-I27 -> 0 | J27: =G27 -> 0
H28: =+J28-I28 -> 0 | J28: =G28 -> 0 | M28: =+GETPIVOTDATA("ผลรวม ของ ใช้",$A$6)+H29+H33 -> 661084.45
H29: =SUM(H7:H28) -> 161696.1 | I29: =SUM(I7:I28) -> 54000 | J29: =SUM(J7:J28) -> 161696.1
H32: =+H26 -> 0 | I32: 85 | J32: =+(H32+H29)*I32 -> 13744169 | K32: =+J32/1000 -> 13744.169
H33: 90000 | I33: 95 | J33: =+H33*I33 -> 8550000 | K33: =+J33/1000 -> 8550
H35: =+H32+H33+H29 -> 251696.1 | K35: =+K32+K33 -> 22294.169
N36: 705222
A37: ยอดส่ง 1/2/68 - 17/2/68 | B37: 1565717 | H37: 15 | I37: =+H35/H37 -> 16779.74
N38: =+H35+N36 -> 956918.1
I39: =+H37*110000 -> 1650000
B41: =+B29+B37+B31-110000 -> 1455717 | C41: =+C29+C37+C31 -> 0 | D41: =+D29+D37+D31-110000 -> -110000 | E41: =+E29+E37+E31 -> 0 | F41: =+F29+F37+F31 -> 0 | G41: =+G29+G37+G31 -> 0
B43: 3218150
B45: =+B43-B41 -> 1762433
C47: =+C41/9 -> 0 | D47: =+D41/9 -> -12222.222

Sheet 11(Order)
A2: เลขที่ SO | B2: (หลายรายการ)
A3: วันส่ง | B3: (หลายรายการ)
A4: ชื่อลูกค้า | B4: (ทั้งหมด)
A6: ประเภท | B6: ผลรวม ของ จำนวนส่ง | C6: ผลรวม ของ ค้างพิมพ์ | D6: ผลรวม ของ ค้างตัด | E6: ผลรวม ของ ใช้ | F6: ผลรวม ของ Stock | G6: ผลรวม ของ ค้างทอ
A7: WSWT1825800 | B7: 50000 | C7: 52500 | D7: 50000 | E7: 41211.5 | F7: 41211.5 | G7: 0
A8: WSWT1925800 | B8: 110000 | C8: 112808.85 | D8: 107437 | E8: 94556.378 | F8: 0 | G8: 94556.378
A9: WSWT2025800SM | B9: 169500 | C9: 151965.45 | D9: 148100 | E9: 159858.17 | F9: 37115.077 | G9: 122743.09
A10: WSWT2025850 | B10: 436000 | C10: 381675 | D10: 395697 | E10: 401728.31 | F10: 39046.15 | G10: 362682.16
A11: WSWT2825850 | B11: 50000 | C11: 52500 | D11: 50000 | E11: 59372.5 | F11: 59372.5 | G11: 0
A12: WSWTFCL022325650 | B12: 13000 | C12: 13650 | D12: 13000 | E12: 12894.31 | F12: 2255 | G12: 10639.31
A13: WSWTSCL052325650 | B13: 5000 | C13: 5250 | D13: 5000 | E13: 4959.35 | F13: 3294 | G13: 1665.35
A14: ผลรวมทั้งหมด | B14: 833500 | C14: 770349.3 | D14: 769234 | E14: 774580.51 | F14: 182294.23 | G14: 592286.28
D34: =D18 -> 0
D36: =D20 -> 0
A37: ยอดส่ง 1/4/68 - 12/4/68 | B37: 887615
A38: Order+ส่ง | B38: =++B25+B37 -> 887615
A39: ประมาณการ | B39: 262000 | C39: 238350 | D39: 262000 | E39: 279847.04 | F39: 60825.09 | G39: 219021.95
A41: Order+ส่ง+ประมาณการ | B41: =+B25+B37+B39+B33 -> 1149615 | C41: =+C25+C37+C39+C33 -> 238350 | D41: =+D25+D37+D39+D33 -> 262000 | E41: =+E25+E37+E39+E33 -> 279847.04 | F41: =+F25+F37+F39+F33 -> 60825.09 | G41: =+G25+G37+G39+G33 -> 219021.95
B43: 3171376
B45: =+B41-B43 -> -2021761 | C45: =+$B$45 -> -2021761 | D45: =+$B$45 -> -2021761 | F45: =+$B$45 -> -2021761
D47: =+D41/6 -> 43666.667

Sheet 11(Order) แยกลูกค้า
A1: เลขที่ SO | B1: (หลายรายการ)
A2: วันส่ง | B2: (หลายรายการ)
A4: ประเภท | B4: ชื่อลูกค้า | C4: ผลรวม ของ จำนวนส่ง | D4: ผลรวม ของ ค้างพิมพ์ | E4: ผลรวม ของ ค้างตัด | F4: ผลรวม ของ Stock | G4: ผลรวม ของ ค้างทอ | I4: vn
A5: WSWT1825800 | B5: หจก.อนนท์อุตสาหกรรม | C5: 50000 | D5: 52500 | E5: 50000 | F5: 41211.5 | G5: 0 | H5: =G5 -> 0
A6: WSWT1825800 ผลรวม | C6: 50000 | D6: 52500 | E6: 50000 | F6: 41211.5 | G6: 0 | H6: =G6 -> 0
A7: WSWT1925800 | B7: บจก.เพรซิเดนท์ฟลาวมิลล์ | C7: 110000 | D7: 112808.85 | E7: 107437 | F7: 0 | G7: 94556.378 | H7: =G7 -> 94556.378
A8: WSWT1925800 ผลรวม | C8: 110000 | D8: 112808.85 | E8: 107437 | F8: 0 | G8: 94556.378 | H8: =G8 -> 94556.378
A9: WSWT2025800SM | B9: บจก.เอพีเอ็ม อะโกร | C9: 13000 | D9: 13650 | E9: 13000 | F9: 14347.19 | G9: 0 | H9: =G9 -> 0
B10: บจก.เอสพีเอ็ม อาหารสัตว์ | C10: 27000 | D10: 18900 | E10: 18500 | F10: 16554.45 | G10: 3310.89 | H10: =G10 -> 3310.89
B11: บจก.ซันฟีด | C11: 129500 | D11: 119415.45 | E11: 116600 | F11: 6213.4369 | G11: 119432.2 | H11: =G11 -> 119432.2
A12: WSWT2025800SM ผลรวม | C12: 169500 | D12: 151965.45 | E12: 148100 | F12: 37115.077 | G12: 122743.09 | H12: =G12 -> 122743.09
A13: WSWT2025850 | B13: บจก.ซันฟีด | C13: 436000 | D13: 381675 | E13: 395697 | F13: 39046.15 | G13: 362682.16 | H13: =G13 -> 362682.16
A14: WSWT2025850 ผลรวม | C14: 436000 | D14: 381675 | E14: 395697 | F14: 39046.15 | G14: 362682.16 | H14: =G14 -> 362682.16
A15: WSWT2825850 | B15: บจก.ไทยร่วมใจน้ำมันพืช | C15: 50000 | D15: 52500 | E15: 50000 | F15: 59372.5 | G15: 0 | H15: =G15 -> 0
A16: WSWT2825850 ผลรวม | C16: 50000 | D16: 52500 | E16: 50000 | F16: 59372.5 | G16: 0 | H16: =G16 -> 0
A17: WSWTFCL022325650 | B17: คุณปราสาท เจริญธรรมรักษา | C17: 13000 | D17: 13650 | E17: 13000 | F17: 2255 | G17: 10639.31 | H17: =G17 -> 10639.31
A18: WSWTFCL022325650 ผลรวม | C18: 13000 | D18: 13650 | E18: 13000 | F18: 2255 | G18: 10639.31 | H18: =G18 -> 10639.31
A19: WSWTSCL052325650 | B19: คุณปราสาท เจริญธรรมรักษา | C19: 5000 | D19: 5250 | E19: 5000 | F19: 3294 | G19: 1665.35 | H19: =G19 -> 1665.35
A20: WSWTSCL052325650 ผลรวม | C20: 5000 | D20: 5250 | E20: 5000 | F20: 3294 | G20: 1665.35 | H20: =G20 -> 1665.35
A21: ผลรวมทั้งหมด | C21: 833500 | D21: 770349.3 | E21: 769234 | F21: 182294.23 | G21: 592286.28 | H21: =G21 -> 592286.28
H22: =G22 -> 0
H23: =G23 -> 0
H24: =G24 -> 0
H25: =G25 -> 0
H26: =G26 -> 0
H27: =G27 -> 0
H28: =G28 -> 0
H29: =G29 -> 0
H30: =G30 -> 0
H31: =G31 -> 0
H32: =G32 -> 0
H33: =G33 -> 0
... H65: =G65 -> 0
H70: =SUM(H5:H69) -> 1776858.8
D119: Cap พิมพ์ | E119: Cap ตัด | F119: Stock 16/7 บ่าย | G119: Cap ทอ | I119: วันทงาน
B120: lส่ง | C120: 1-16/7 | D120: 160000 | E120: 160000 | G120: 120000 | I120: 12
C121: 1975256 | D121: =+D120*I120 -> 1920000 | E121: =+E120*I120 -> 1920000 | F121: 825147 | G121: =+G120*I120 -> 1440000
A122: เบทาโกรส่งแล้ว | B122: 20700 | C122: 424374
A123: เบทาโกรส่งแล้ว | B123: 20800 | C123: 155973
C126: รวมส่ง+ค้างส่ง | D126: ส่วนต่างCapคงเหลือ | E126: ส่วนต่างCapคงเหลือ | F126: คงเหลือ
...

Sheet 9(Fc) แยกลูกค้า
A1: เลขที่ SO | B1: ประมาณการ
A2: วันส่ง | B2: (หลายรายการ) | D2: 12
A4: ประเภท | B4: ชื่อลูกค้า | C4: ผลรวม ของ จำนวนส่ง | D4: ผลรวม ของ ค้างพิมพ์ | E4: ผลรวม ของ ค้างตัด | F4: ผลรวม ของ ใช้ | G4: ผลรวม ของ Stock | H4: ผลรวม ของ ค้างทอ
A5: WSWT1921720 | B5: บจก.เคอรี่ฟลาวมิลล์ | C5: 225000 | D5: 236250 | E5: 225000 | F5: 210597.75 | G5: 0 | H5: 210597.75
A6: WSWT1921720 ผลรวม | C6: 225000 | D6: 236250 | E6: 225000 | F6: 210597.75 | G6: 0 | H6: 210597.75
A7: WSWT1925800 | B7: บจก.เพรซิเดนท์ฟลาวมิลล์ | C7: 140000 | D7: 147000 | E7: 140000 | F7: 123215.4 | G7: 0 | H7: 123215.4
B8: บจก.ไลม์มาสเตอร์ | C8: 20000 | D8: 20755.35 | E8: 19767 | F8: 18501.714 | G8: 0 | H8: 18501.714
B9: บจก.เอ็กเซลเล้นท์ | C9: 40000 | D9: 42000 | E9: 40000 | F9: 35204.4 | G9: 0 | H9: 35204.4
A10: WSWT1925800 ผลรวม | C10: 200000 | D10: 209755.35 | E10: 199767 | F10: 176921.51 | G10: 0 | H10: 176921.51
A11: WSWT2025800 | B11: บจก.อินเทคค์ โกลบอล | C11: 290000 | D11: 304500 | E11: 290000 | F11: 303847.5 | G11: 0 | H11: 303847.5
A12: WSWT2025800 ผลรวม | C12: 290000 | D12: 304500 | E12: 290000 | F12: 303847.5 | G12: 0 | H12: 303847.5
A13: WSWT2025800SM | B13: บจก.ไทยธรรมดี | C13: 20000 | D13: 21000 | E13: 20000 | F13: 21513.8 | G13: 0 | H13: 21513.8
B14: บจก.อินเทคค์ โกลบอล | C14: 100000 | D14: 105000 | E14: 100000 | F14: 104775 | G14: 0 | H14: 104775
B15: บจก.เอสพีเอ็ม อาหารสัตว์ | C15: 20000 | D15: 21000 | E15: 20000 | F15: 22072.6 | G15: 0 | H15: 22072.6
B16: บจก.ซันฟีด | C16: 305000 | D16: 320250 | E16: 305000 | F16: 336607.15 | G16: 0 | H16: 336607.15
A17: WSWT2025800SM ผลรวม | C17: 445000 | D17: 467250 | E17: 445000 | F17: 484968.55 | G17: 0 | H17: 484968.55
A18: WSWT2325650 | B18: พันธุ์ข้าว | C18: 30000 | D18: 31500 | E18: 30000 | F18: 29756.1 | G18: 29756.1 | H18: 0
A19: WSWT2325650 ผลรวม | C19: 30000 | D19: 31500 | E19: 30000 | F19: 29756.1 | G19: 29756.1 | H19: 0
A20: WSWT2625800 | B20: บจก.ที.ซี.ยูเนี่ยน อโกรเทค | C20: 10000 | D20: 0 | E20: 10000 | F20: 12433.3 | G20: 12433.3 | H20: 0
A21: WSWT2625800 ผลรวม | C21: 10000 | D21: 0 | E21: 10000 | F21: 12433.3 | G21: 12433.3 | H21: 0
A22: WSWT2825850 | B22: บจก.ที.ซี.ยูเนี่ยน อโกรเทค | C22: 5000 | D22: 0 | E22: 5000 | F22: 6775.45 | G22: 0 | H22: 6775.45
A23: WSWT2825850 ผลรวม | C23: 5000 | D23: 0 | E23: 5000 | F23: 6775.45 | G23: 0 | H23: 6775.45
A24: ผลรวมทั้งหมด | C24: 1205000 | D24: 1249255.4 | E24: 1204767 | F24: 1225300.2 | G24: 42189.4 | H24: 1183110.8
D119: Cap พิมพ์ | E119: Cap ตัด | F119: Stock 16/7 บ่าย | G119: Cap ทอ | I119: วันทงาน
B120: lส่ง | C120: 1-16/7 | D120: 160000 | E120: 160000 | G120: 120000 | I120: 12
C121: 1975256 | D121: =+D120*I120 -> 1920000 | E121: =+E120*I120 -> 1920000 | F121: 825147 | G121: =+G120*I120 -> 1440000
A122: เบทาโกรส่งแล้ว | B122: 20700 | C122: 424374
A123: เบทาโกรส่งแล้ว | B123: 20800 | C123: 155973
C126: รวมส่ง+ค้างส่ง | D126: ส่วนต่างCapคงเหลือ | E126: ส่วนต่างCapคงเหลือ | F126: คงเหลือ
C127: =+C50+C121 -> 1975256 | D127: =+D121-D50 -> 1920000 | E127: =+E121-E50 -> 1920000 | F127: =+F121-F50 -> 825147 | G127: =+G121-G50 -> 1440000
B129: 20700VN 20/7 | G129: 350000

Sheet 10(Order+Fc) แยกลูกค้า
A1: เลขที่ SO | B1: (หลายรายการ)
A2: วันส่ง | B2: (หลายรายการ) | D2: 12 | I2: เมตร | J2: vn | K2: ใบ | P2: วัน
A4: ประเภท | B4: ชื่อลูกค้า | C4: ผลรวม ของ จำนวนส่ง | D4: ผลรวม ของ ค้างพิมพ์ | E4: ผลรวม ของ ค้างตัด | F4: ผลรวม ของ ใช้ | G4: ผลรวม ของ Stock | H4: ผลรวม ของ ค้างทอ
A5: WSWT1425800 | B5: หจก.ปึงเป้งน้ำ | C5: 10000 | D5: 10500 | E5: 10000 | F5: 6565.9 | G5: 3028 | H5: 3537.9 | I5: =H5 -> 3537.9
A6: WSWT1425800 ผลรวม | C6: 10000 | D6: 10500 | E6: 10000 | F6: 6565.9 | G6: 3028 | H6: 3537.9
A7: WSWT1625800 | B7: บจก.เคอรี่ฟลาวมิลล์ | C7: 5000 | D7: 0 | E7: 5000 | F7: 0 | G7: 0 | H7: 0 | I7: =H7 -> 0
A8: WSWT1625800 ผลรวม | C8: 5000 | D8: 0 | E8: 5000 | F8: 0 | G8: 0 | H8: 0 | I8: =H8 -> 0
A9: WSWT1825800 | B9: หจก.อนนท์อุตสาหกรรม | C9: 50000 | D9: 52500 | E9: 50000 | F9: 41211.5 | G9: 41211.5 | H9: 0 | I9: =H9 -> 0
A10: WSWT1825800 ผลรวม | C10: 50000 | D10: 52500 | E10: 50000 | F10: 41211.5 | G10: 41211.5 | H10: 0 | I10: =H10 -> 0
A11: WSWT1921720 | B11: บจก.เคอรี่ฟลาวมิลล์ | C11: 395000 | D11: 236250 | E11: 254200 | F11: 210597.75 | G11: 51686 | H11: 158911.75
A12: WSWT1921720 ผลรวม | C12: 395000 | D12: 236250 | E12: 254200 | F12: 210597.75 | G12: 51686 | H12: 158911.75
A13: WSWT1925800 | B13: บจก.เพรซิเดนท์ฟลาวมิลล์ | C13: 20000 | D13: 0 | E13: 0 | F13: 0 | G13: 0 | H13: 0 | I13: =H13 -> 0
B14: บจก.ไลม์มาสเตอร์ | C14: 20000 | D14: 20755.35 | E14: 19767 | F14: 18501.714 | G14: 0 | H14: 18501.714 | I14: =H14 -> 18501.714 | P14: 15000 | Q14: =+K14/P14 -> 0
B15: บจก.เอ็กเซลเล้นท์ | C15: 20000 | D15: 21000 | E15: 20000 | F15: 17602.2 | G15: 12640 | H15: 4962.2 | I15: =H15 -> 4962.2
A16: WSWT1925800 ผลรวม | C16: 60000 | D16: 41755.35 | E16: 39767 | F16: 36103.914 | G16: 12640 | H16: 23463.914
A17: WSWT2025700 | B17: บจก.หนองบัวฟีด | C17: 5000 | D17: 0 | E17: 5000 | F17: 4400.55 | G17: 0 | H17: 4400.55 | I17: =H17 -> 4400.55
A18: WSWT2025700 ผลรวม | C18: 5000 | D18: 0 | E18: 5000 | F18: 4400.55 | G18: 0 | H18: 4400.55 | K18: =7*2000 -> 14000
A19: WSWT2025800 | B19: บจก.เคอรี่ฟลาวมิลล์ | C19: 15000 | D19: 0 | E19: 12000 | F19: 0 | G19: 0 | H19: 0 | I19: =H19 -> 0 | K19: 7000
B20: บจก.อินเทคค์ โกลบอล | C20: 296826 | D20: 304500 | E20: 290000 | F20: 303847.5 | G20: 36749 | H20: 267098.5 | I20: =H20-100000 -> 167098.5 | K20: 9000 | P20: 16000 | Q20: =+K20/P20 -> 0.5625
B21: โรงสีข้าวธัญญาวัฒน์ | C21: 4000 | D21: 0 | E21: 1555 | F21: 0 | G21: 0 | H21: 0 | I21: =H21 -> 0
A22: WSWT2025800 ผลรวม | C22: 315826 | D22: 304500 | E22: 303555 | F22: 303847.5 | G22: 36749 | H22: 267098.5
A23: WSWT2025800SM | B23: บจก.อินเทคค์ โกลบอล | C23: 100000 | D23: 105000 | E23: 100000 | F23: 104775 | G23: 21900 | H23: 82875 | I23: =H23 -> 82875
B24: บจก.เอพีเอ็ม อะโกร | C24: 9000 | D24: 6300 | E24: 9000 | F24: 6789.42 | G24: 6789.42 | H24: 0 | I24: =H24 -> 0
B25: บจก.เอสพีเอ็ม อาหารสัตว์ | C25: 15179 | D25: 3150 | E25: 4020 | F25: 3310.89 | G25: 3310.89 | H25: 0 | I25: =H25 -> 0
B26: บจก.ซันฟีด | C26: 50755 | D26: 8925 | E26: 9079 | F26: 9380.855 | G26: 9380.855 | H26: 0 | I26: =H26 -> 0
A27: WSWT2025800SM ผลรวม | C27: 174934 | D27: 123375 | E27: 122099 | F27: 124256.17 | G27: 41381.165 | H27: 82875
A28: WSWT2025850 | B28: บจก.ซันฟีด | C28: 158300 | D28: 24675 | E28: 38517 | F28: 26116.915 | G28: 26116.915 | H28: 0 | I28: =H28 -> 0
A29: WSWT2025850 ผลรวม | C29: 158300 | D29: 24675 | E29: 38517 | F29: 26116.915 | G29: 26116.915 | H29: 0 | I29: =H29 -> 0
A30: WSWT2121670SM | B30: บจก.เอสพีเอ็ม อาหารสัตว์ | C30: 3000 | D30: 0 | E30: 0 | F30: 0 | G30: 0 | H30: 0 | I30: =H30 -> 0
B31: บจก.แอมโก้เวท | C31: 65000 | D31: 10500 | E31: 26000 | F31: 11832.59 | G31: 11832.59 | H31: 0 | I31: =H31 -> 0 | P31: 15000 | Q31: =+K31/P31 -> 0
B32: คุณนพวินทร์ รัตนเศรษฐ์เมธา | C32: 5000 | D32: 0 | E32: 263 | F32: 0 | G32: 0 | H32: 0 | I32: =H32 -> 0
A33: WSWT2121670SM ผลรวม | C33: 73000 | D33: 10500 | E33: 26263 | F33: 11832.59 | G33: 11832.59 | H33: 0 | I33: =H33 -> 0
A34: WSWT2125650 | B34: บจก.ไลม์มาสเตอร์ | C34: 20000 | D34: 0 | E34: 20000 | F34: 0 | G34: 0 | H34: 0 | I34: =H34 -> 0
B35: บจก.หนองบัวฟีด | C35: 15000 | D35: 0 | E35: 15000 | F35: 16554.45 | G35: 16554.45 | H35: 0 | I35: =H35 -> 0
A36: WSWT2125650 ผลรวม | C36: 35000 | D36: 0 | E36: 35000 | F36: 16554.45 | G36: 16554.45 | H36: 0 | I36: =H36 -> 0
A37: WSWT2321750 | B37: บจก.แอมโก้เวท | C37: 5000 | D37: 0 | E37: 0 | F37: 0 | G37: 0 | H37: 0 | I37: =H37 -> 0
A38: WSWT2321750 ผลรวม | C38: 5000 | D38: 0 | E38: 0 | F38: 0 | G38: 0 | H38: 0 | I38: =H38 -> 0
A39: WSWT2325650 | B39: พันธุ์ข้าว | C39: 30000 | D39: 31500 | E39: 30000 | F39: 29756.1 | G39: 29756.1 | H39: 0 | I39: =H39 -> 0
B40: บจก.ซิเบลโก้(บางเลน) | C40: 5000 | D40: 0 | E40: 0 | F40: 0 | G40: 0 | H40: 0 | I40: =H40 -> 0
A41: WSWT2325650 ผลรวม | C41: 35000 | D41: 31500 | E41: 30000 | F41: 29756.1 | G41: 29756.1 | H41: 0 | I41: =H41 -> 0
...

Sheet 10(Order)
A2: เลขที่ SO | B2: (หลายรายการ)
A3: วันส่ง | B3: (หลายรายการ)
A4: ชื่อลูกค้า | B4: (ทั้งหมด)
A6: ประเภท | B6: ผลรวม ของ จำนวนส่ง | C6: ผลรวม ของ ค้างพิมพ์ | D6: ผลรวม ของ ค้างตัด | E6: ผลรวม ของ ใช้ | F6: ผลรวม ของ Stock | G6: ผลรวม ของ ค้างทอ
A7: WSWT1425800 | B7: 10000 | C7: 10500 | D7: 10000 | E7: 6565.9 | F7: 3028 | G7: 3537.9
A8: WSWT1625800 | B8: 5000 | C8: 0 | D8: 5000 | E8: 0 | F8: 0 | G8: 0
A9: WSWT1825800 | B9: 50000 | C9: 52500 | D9: 50000 | E9: 41211.5 | F9: 41211.5 | G9: 0
A10: WSWT1921720 | B10: 170000 | C10: 0 | D10: 29200 | E10: 0 | F10: 0 | G10: 0 | K10: =25*32.24 -> 806
A11: WSWT1925800 | B11: 40000 | C11: 21000 | D11: 20000 | E11: 17602.2 | F11: 12640 | G11: 4962.2 | L11: =76*2500 -> 190000
A12: WSWT2025700 | B12: 5000 | C12: 0 | D12: 5000 | E12: 4400.55 | F12: 0 | G12: 4400.55
A13: WSWT2025800 | B13: 25826 | C13: 0 | D13: 13555 | E13: 0 | F13: 0 | G13: 0
A14: WSWT2025800SM | B14: 74934 | C14: 18375 | D14: 22099 | E14: 19481.165 | F14: 19481.165 | G14: 0
A15: WSWT2025850 | B15: 158300 | C15: 24675 | D15: 38517 | E15: 26116.915 | F15: 26116.915 | G15: 0
A16: WSWT2121670SM | B16: 73000 | C16: 10500 | D16: 26263 | E16: 11832.59 | F16: 11832.59 | G16: 0
A17: WSWT2125650 | B17: 35000 | C17: 0 | D17: 35000 | E17: 16554.45 | F17: 16554.45 | G17: 0
A18: WSWT2321750 | B18: 5000 | C18: 0 | D18: 0 | E18: 0 | F18: 0 | G18: 0
A19: WSWT2325650 | B19: 5000 | C19: 0 | D19: 0 | E19: 0 | F19: 0 | G19: 0
A20: WSWT262575051 | B20: 10000 | C20: 0 | D20: 5000 | E20: 6216.65 | F20: 4573 | G20: 1643.65
A21: WSWT2625800 | B21: 10000 | C21: 10500 | D21: 10000 | E21: 11595.1 | F21: 11595.1 | G21: 0
A22: WSWT2625850SM | B22: 30000 | C22: 0 | D22: 0 | E22: 0 | F22: 0 | G22: 0
A23: WSWTSCL052325650 | B23: 20000 | C23: 21000 | D23: 20000 | E23: 19837.4 | F23: 0 | G23: 19837.4
A24: ผลรวมทั้งหมด | B24: 727060 | C24: 169050 | D24: 289634 | E24: 181414.42 | F24: 147032.72 | G24: 34381.7
A37: ยอดส่ง 1/1/68 - 17/1/68 | B37: 1287052
A38: Order+ส่ง | B38: =++B22+B37 -> 1317052
A39: ประมาณการ | I39: 0
A41: Order+ส่ง+ประมาณการ | B41: =+B22+B37+B39+B29 -> 1317052 | C41: =+C22+C37+C39+C29 -> 0 | D41: =+D22+D37+D39+D29 -> 0 | E41: =+E22+E37+E39+E29 -> 0 | F41: =+F22+F37+F39+F29 -> 0 | G41: =+G22+G37+G39+G29 -> 0
B43: 3000000 | I43: 9
B45: =+B41-B43 -> -1682948
D46: =+D22/I43 -> 0
C47: =+C41/I43 -> 0 | D47: =+D41/I43 -> 0 | G47: =+G41/I43 -> 0

Sheet 10(Order) แยกลูกค้า
A1: เลขที่ SO | B1: (หลายรายการ)
A2: วันส่ง | B2: (หลายรายการ)
A4: ประเภท | B4: ชื่อลูกค้า | C4: ผลรวม ของ จำนวนส่ง | D4: ผลรวม ของ ค้างพิมพ์ | E4: ผลรวม ของ ค้างตัด | F4: ผลรวม ของ Stock | G4: ผลรวม ของ ค้างทอ | I4: vn
A5: WSWT1425800 | B5: หจก.ปึงเป้งน้ำ | C5: 10000 | D5: 10500 | E5: 10000 | F5: 3028 | G5: 3537.9 | H5: =G5 -> 3537.9
A6: WSWT1425800 ผลรวม | C6: 10000 | D6: 10500 | E6: 10000 | F6: 3028 | G6: 3537.9 | H6: =G6 -> 3537.9
A7: WSWT1625800 | B7: บจก.เคอรี่ฟลาวมิลล์ | C7: 5000 | D7: 0 | E7: 5000 | F7: 0 | G7: 0 | H7: =G7 -> 0
A8: WSWT1625800 ผลรวม | C8: 5000 | D8: 0 | E8: 5000 | F8: 0 | G8: 0
A9: WSWT1825800 | B9: หจก.อนนท์อุตสาหกรรม | C9: 50000 | D9: 52500 | E9: 50000 | F9: 41211.5 | G9: 0 | H9: =G9 -> 0
A10: WSWT1825800 ผลรวม | C10: 50000 | D10: 52500 | E10: 50000 | F10: 41211.5 | G10: 0 | H10: =G10 -> 0
A11: WSWT1921720 | B11: บจก.เคอรี่ฟลาวมิลล์ | C11: 395000 | D11: 236250 | E11: 254200 | F11: 51686 | G11: 158911.75
A12: WSWT1921720 ผลรวม | C12: 395000 | D12: 236250 | E12: 254200 | F12: 51686 | G12: 158911.75 | H12: =G12 -> 158911.75
A13: WSWT1925800 | B13: บจก.เพรซิเดนท์ฟลาวมิลล์ | C13: 20000 | D13: 0 | E13: 0 | F13: 0 | G13: 0 | H13: =G13 -> 0
B14: บจก.ไลม์มาสเตอร์ | C14: 20000 | D14: 20755.35 | E14: 19767 | F14: 0 | G14: 18501.714 | H14: =G14 -> 18501.714
B15: บจก.เอ็กเซลเล้นท์ | C15: 20000 | D15: 21000 | E15: 20000 | F15: 12640 | G15: 4962.2
A16: WSWT1925800 ผลรวม | C16: 60000 | D16: 41755.35 | E16: 39767 | F16: 12640 | G16: 23463.914 | H16: =G16 -> 23463.914
A17: WSWT2025700 | B17: บจก.หนองบัวฟีด | C17: 5000 | D17: 0 | E17: 5000 | F17: 0 | G17: 4400.55
A18: WSWT2025700 ผลรวม | C18: 5000 | D18: 0 | E18: 5000 | F18: 0 | G18: 4400.55 | H18: =G18 -> 4400.55
A19: WSWT2025800 | B19: บจก.เคอรี่ฟลาวมิลล์ | C19: 15000 | D19: 0 | E19: 12000 | F19: 0 | G19: 0 | H19: =G19 -> 0
B20: บจก.อินเทคค์ โกลบอล | C20: 296826 | D20: 304500 | E20: 290000 | F20: 36749 | G20: 267098.5 | H20: =G20 -> 267098.5
B21: โรงสีข้าวธัญญาวัฒน์ | C21: 4000 | D21: 0 | E21: 1555 | F21: 0 | G21: 0 | H21: =G21 -> 0
A22: WSWT2025800 ผลรวม | C22: 315826 | D22: 304500 | E22: 303555 | F22: 36749 | G22: 267098.5
A23: WSWT2025800SM | B23: บจก.อินเทคค์ โกลบอล | C23: 100000 | D23: 105000 | E23: 100000 | F23: 21900 | G23: 82875 | H23: =G23 -> 82875
B24: บจก.เอพีเอ็ม อะโกร | C24: 9000 | D24: 6300 | E24: 9000 | F24: 6789.42 | G24: 0
B25: บจก.เอสพีเอ็ม อาหารสัตว์ | C25: 15179 | D25: 3150 | E25: 4020 | F25: 3310.89 | G25: 0 | H25: =G25 -> 0
B26: บจก.ซันฟีด | C26: 50755 | D26: 8925 | E26: 9079 | F26: 9380.855 | G26: 0
A27: WSWT2025800SM ผลรวม | C27: 174934 | D27: 123375 | E27: 122099 | F27: 41381.165 | G27: 82875 | H27: =G27 -> 82875
A28: WSWT2025850 | B28: บจก.ซันฟีด | C28: 158300 | D28: 24675 | E28: 38517 | F28: 26116.915 | G28: 0 | H28: =G28 -> 0
A29: WSWT2025850 ผลรวม | C29: 158300 | D29: 24675 | E29: 38517 | F29: 26116.915 | G29: 0 | H29: =G29 -> 0
A30: WSWT2121670SM | B30: บจก.เอสพีเอ็ม อาหารสัตว์ | C30: 3000 | D30: 0 | E30: 0 | F30: 0 | G30: 0
B31: บจก.แอมโก้เวท | C31: 65000 | D31: 10500 | E31: 26000 | F31: 11832.59 | G31: 0 | H31: =G31 -> 0
B32: คุณนพวินทร์ รัตนเศรษฐ์เมธา | C32: 5000 | D32: 0 | E32: 263 | F32: 0 | G32: 0 | H32: =G32 -> 0
A33: WSWT2121670SM ผลรวม | C33: 73000 | D33: 10500 | E33: 26263 | F33: 11832.59 | G33: 0 | H33: =G33 -> 0
A34: WSWT2125650 | B34: บจก.ไลม์มาสเตอร์ | C34: 20000 | D34: 0 | E34: 20000 | F34: 0 | G34: 0 | H34: =G34 -> 0
B35: บจก.หนองบัวฟีด | C35: 15000 | D35: 0 | E35: 15000 | F35: 16554.45 | G35: 0 | H35: =G35 -> 0
A36: WSWT2125650 ผลรวม | C36: 35000 | D36: 0 | E36: 35000 | F36: 16554.45 | G36: 0 | H36: =G36 -> 0
A37: WSWT2321750 | B37: บจก.แอมโก้เวท | C37: 5000 | D37: 0 | E37: 0 | F37: 0 | G37: 0 | H37: =G37 -> 0
A38: WSWT2321750 ผลรวม | C38: 5000 | D38: 0 | E38: 0 | F38: 0 | G38: 0 | H38: =G38 -> 0
A39: WSWT2325650 | B39: พันธุ์ข้าว | C39: 30000 | D39: 31500 | E39: 30000 | F39: 29756.1 | G39: 0 | H39: =G39 -> 0
B40: บจก.ซิเบลโก้(บางเลน) | C40: 5000 | D40: 0 | E40: 0 | F40: 0 | G40: 0
A41: WSWT2325650 ผลรวม | C41: 35000 | D41: 31500 | E41: 30000 | F41: 29756.1 | G41: 0 | H41: =G41 -> 0
...

Sheet 10(Fc) แยกลูกค้
A1: เลขที่ SO | B1: ประมาณการ
A2: วันส่ง | B2: (หลายรายการ) | D2: 12
A4: ประเภท | B4: ชื่อลูกค้า | C4: ผลรวม ของ จำนวนส่ง | D4: ผลรวม ของ ค้างพิมพ์ | E4: ผลรวม ของ ค้างตัด | F4: ผลรวม ของ ใช้ | G4: ผลรวม ของ Stock | H4: ผลรวม ของ ค้างทอ
A5: WSWT1921720 | B5: บจก.เคอรี่ฟลาวมิลล์ | C5: 225000 | D5: 236250 | E5: 225000 | F5: 210597.75 | G5: 51686 | H5: 158911.75
A6: WSWT1921720 ผลรวม | C6: 225000 | D6: 236250 | E6: 225000 | F6: 210597.75 | G6: 51686 | H6: 158911.75
A7: WSWT1925800 | B7: บจก.ไลม์มาสเตอร์ | C7: 20000 | D7: 20755.35 | E7: 19767 | F7: 18501.714 | G7: 0 | H7: 18501.714
A8: WSWT1925800 ผลรวม | C8: 20000 | D8: 20755.35 | E8: 19767 | F8: 18501.714 | G8: 0 | H8: 18501.714
A9: WSWT2025800 | B9: บจก.อินเทคค์ โกลบอล | C9: 290000 | D9: 304500 | E9: 290000 | F9: 303847.5 | G9: 36749 | H9: 267098.5
A10: WSWT2025800 ผลรวม | C10: 290000 | D10: 304500 | E10: 290000 | F10: 303847.5 | G10: 36749 | H10: 267098.5
A11: WSWT2025800SM | B11: บจก.อินเทคค์ โกลบอล | C11: 100000 | D11: 105000 | E11: 100000 | F11: 104775 | G11: 21900 | H11: 82875
A12: WSWT2025800SM ผลรวม | C12: 100000 | D12: 105000 | E12: 100000 | F12: 104775 | G12: 21900 | H12: 82875
A13: WSWT2325650 | B13: พันธุ์ข้าว | C13: 30000 | D13: 31500 | E13: 30000 | F13: 29756.1 | G13: 29756.1 | H13: 0
A14: WSWT2325650 ผลรวม | C14: 30000 | D14: 31500 | E14: 30000 | F14: 29756.1 | G14: 29756.1 | H14: 0
A15: WSWT2825850 | B15: บจก.ที.ซี.ยูเนี่ยน อโกรเทค | C15: 5000 | D15: 0 | E15: 5000 | F15: 6775.45 | G15: 6775.45 | H15: 0
A16: WSWT2825850 ผลรวม | C16: 5000 | D16: 0 | E16: 5000 | F16: 6775.45 | G16: 6775.45 | H16: 0
A17: ผลรวมทั้งหมด | C17: 670000 | D17: 698005.35 | E17: 669767 | F17: 674253.51 | G17: 146866.55 | H17: 527386.96
I119: วันทงาน
I120: 12
C121: 1975256 | D121: =+D120*I120 -> 0 | E121: =+E120*I120 -> 0 | F121: 825147 | G121: =+G120*I120 -> 0
A122: เบทาโกรส่งแล้ว | B122: 20700 | C122: 424374
A123: เบทาโกรส่งแล้ว | B123: 20800 | C123: 155973
C126: รวมส่ง+ค้างส่ง | D126: ส่วนต่างCapคงเหลือ | E126: ส่วนต่างCapคงเหลือ | F126: คงเหลือ
C127: =+C50+C121 -> 1975256 | D127: =+D121-D50 -> 0 | E127: =+E121-E50 -> 0 | F127: =+F121-F50 -> 825147 | G127: =+G121-G50 -> 0
B129: 20700VN 20/7 | G129: 350000

Sheet ค้างตัด23-10-68
A2: งาน รอตัด หน้างาน 23/10 | B2: 39904
A3: ผลรวม ของ ค้างตัด | C3: ป้ายชื่อคอลัมน์
A4: ป้ายชื่อแถว | C4: 45954 | D4: 45955 | E4: 45957 | F4: 45958 | G4: 45959 | H4: 45960 | I4: 45961 | J4: ผลรวมทั้งหมด
A5: 954 แอล | B5: ขาว | E5: 2500 | J5: =SUM(C5:I5) -> 2500
A6: Soybean Meal | B6: ขาว | H6: 10000 | J6: =SUM(C6:I6) -> 10000
A7: TRJ | B7: ขาว | D7: 15000 | J7: =SUM(C7:I7) -> 15000
A8: TUNA MEAL MARIN TRUST | B8: ใส | H8: 10000 | J8: =SUM(C8:I8) -> 10000
A9: VC 100 | B9: ใส | G9: 30000 | J9: =SUM(C9:I9) -> 30000
A10: VC 120 | B10: ใส | G10: 50000 | J10: =SUM(C10:I10) -> 50000
A11: Y30 | B11: ขาว | I11: 10000 | J11: =SUM(C11:I11) -> 10000
A12: กัสโซ่ฟีด 101-102 | B12: ใส | I12: 10000 | J12: =SUM(C12:I12) -> 10000
A13: เกลือตรามือ 10กก. | B13: ใส | I13: 10000 | J13: =SUM(C13:I13) -> 10000
A14: ฉัตรทอง(แดง) | B14: ขาว | E14: 5000 | J14: =SUM(C14:I14) -> 5000
A15: ฉัตรทอง(บานเย็น) | B15: ขาว | E15: 5000 | J15: =SUM(C15:I15) -> 5000
A16: ฉัตรทอง(ฟ้า) | B16: ขาว | E16: 5000 | J16: =SUM(C16:I16) -> 5000
A17: ฉัตรทอง(เหลือง) | B17: ขาว | E17: 5000 | J17: =SUM(C17:I17) -> 5000
A18: ดวงใจ-ชมพู(ม่วง) | B18: ขาว | I18: 20000 | J18: =SUM(C18:I18) -> 20000
A19: ใบเตย | B19: ขาว | I19: 5000 | J19: =SUM(C19:I19) -> 5000
A20: เพอเฟคค์ 663 | B20: ขาว | I20: 10208 | J20: =SUM(C20:I20) -> 10208
A21: เพอเฟคค์ 664 | B21: ขาว | I21: 91786 | J21: =SUM(C21:I21) -> 91786
A22: เพอเฟคค์ 664HP | B22: ขาว | I22: 91374 | J22: =SUM(C22:I22)-K22 -> 21374 | K22: 70000
A23: เพอเฟคค์ 911 | B23: ด้าน | H23: 5040 | J23: =SUM(C23:I23) -> 5040
A24: เพอเฟคค์ 912 | B24: ด้าน | H24: 10928 | J24: =SUM(C24:I24) -> 10928
A25: เพอเฟคค์ 913 | B25: ด้าน | H25: 31933 | J25: =SUM(C25:I25) -> 31933
A26: เพอเฟคค์ 914 | B26: ด้าน | H26: 21174 | J26: =SUM(C26:I26) -> 21174
A27: เพอเฟคค์103P โกลด์ | B27: ด้าน | H27: 5040 | J27: =SUM(C27:I27) -> 5040
A28: เพอเฟคค์103S โกลด์ | B28: ด้าน | H28: 5040 | J28: =SUM(C28:I28) -> 5040
A29: เฟิร์สคลาส 912 | B29: ด้าน | H29: 5040 | J29: =SUM(C29:I29) -> 5040
A30: เฟิร์สช้อย 902 | B30: ด้าน | H30: 5283 | J30: =SUM(C30:I30) -> 5283
A31: เฟิร์สช้อย 911 | B31: ด้าน | H31: 5040 | J31: =SUM(C31:I31) -> 5040
A32: เฟิร์สช้อย 912 | B32: ด้าน | H32: 20604 | J32: =SUM(C32:I32) -> 20604
A33: เฟิร์สช้อย 913 | B33: ด้าน | H33: 10000 | J33: =SUM(C33:I33) -> 10000
A34: เฟิร์สช้อย 914 | B34: ด้าน | H34: 5040 | J34: =SUM(C34:I34) -> 5040
A35: มังกรเขียวMTS | B35: ขาว | C35: 10000 | J35: =SUM(C35:I35) -> 10000
A36: มาซู ฟีดบี042 | B36: ด้าน | F36: 3000 | J36: =SUM(C36:I36) -> 3000
A37: ไม่พิมพ์ | B37: ขาว | H37: 0 | I37: 3000 | J37: =SUM(C37:I37) -> 3000
A38: รถไฟฟ้า | B38: ขาว | I38: 5000 | J38: =SUM(C38:I38) -> 5000
A39: รถไฟฟ้าปูนขาวเย็น | B39: ขาว | I39: 20000 | J39: =SUM(C39:I39) -> 20000
A40: สุบรรณ 222 | B40: ด้าน | H40: 5040 | J40: =SUM(C40:I40) -> 5040
A41: สุบรรณ 333 | B41: ด้าน | H41: 5040 | J41: =SUM(C41:I41) -> 5040
...

Sheet ค้างทอ22-10-68
A3: ผลรวม ของ ค้างทอ
A4: ป้ายชื่อแถว | B4: 45952 | C4: 45953 | D4: 45954 | E4: 45955 | F4: 45956 | G4: ผลรวมทั้งหมด
A5: WSWT1425800 | F5: 3537.9 | G5: =SUM(B5:F5) -> 3537.9
A6: WSWT1825800 | F6: 0 | G6: =SUM(B6:F6) -> 0
A7: WSWT1921720 | C7: 0 | G7: =SUM(B7:F7) -> 0
A8: WSWT19251000SM | E8: 4999.0248 | G8: =SUM(B8:F8) -> 4999.0248
A9: WSWT1925800 | G9: =SUM(B9:F9) -> 0
A10: WSWT2025700 | B10: 1715.76 | G10: =SUM(B10:F10) -> 1715.76
A11: WSWT2025800 | F11: 86173.5 | G11: =SUM(B11:F11) -> 86173.5
A12: WSWT2025800SM | B12: 0 | C12: 0 | D12: 0 | E12: 66884.022 | F12: 0 | G12: =SUM(B12:F12) -> 66884.022
A13: WSWT2025850 | B13: 0 | C13: 0 | D13: 0 | E13: 0 | F13: 0 | G13: =SUM(B13:F13) -> 0
A14: WSWT2121670SM | C14: 0 | E14: 0 | F14: 0 | G14: =SUM(B14:F14) -> 0
A15: WSWT2125650 | G15: =SUM(B15:F15) -> 0
A16: WSWT2321750 | F16: 17893.8 | G16: =SUM(B16:F16) -> 17893.8
A17: WSWT262575051 | E17: 0 | G17: =SUM(B17:F17) -> 0
A18: WSWT2625800 | E18: 0 | G18: =SUM(B18:F18) -> 0
A19: WSWT2625850SM | E19: 0 | G19: =SUM(B19:F19) -> 0
A20: WSWT2825850 | G20: =SUM(B20:F20) -> 0
A21: WSWTSCL052325650 | B21: 7205.7 | G21: =SUM(B21:F21) -> 7205.7
A22: ผลรวมทั้งหมด | B22: =SUM(B5:B21) -> 8921.46 | C22: =SUM(C5:C21) -> 0 | D22: =SUM(D5:D21) -> 0 | E22: =SUM(E5:E21) -> 71883.046 | F22: =SUM(F5:F21) -> 107605.2 | G22: =SUM(G5:G21) -> 188409.71

Sheet 23-10-68
B2: เรียงกำหนดส่ง | D2: ลบ 0 | T2: เรียง 1
B3: ข้อมูลUpdate ณ. วันที่ | D3: 45953 | E3: เวลา | G3: 11.56
A4: วันรับออร์เดอร์/แบบ | B4: เลขที่ SO | C4: ชื่อลูกค้า | E4: 10.3 | I4: น้ำหนัก | L4: บิด/จับจีบ | M4: ถุงใน | Q4: 44873 | S4: วิธีบรรจุ | T4: วันส่ง | U4: จำนวนส่ง | V4: ตัดเย็บ (ใบ) | W4: 44873 | X4: พิมพ์ (ใบ) | Y4: 44876 | Z4: ผ้าทอ (เมตร) Updateณ | AB4: 44876 | AD4: ผ้าเคลือบ(เมตร) | AF4: หมายเหตุ | AG4: เครื่อง
B5: เลขที่ SO | C5: ชื่อลูกค้า | D5: ตรา | E5: กว้าง | F5: ยาว | G5: สี | H5: เคลือบ | I5: กรัม/ใบ | J5: * | K5: aw | L5: บิด/จับจีบ | M5: กว้าง | N5: ยาว | O5: หนา | P5: ใช้(กก.) | Q5: Stock(กก.) | R5: ผลิต(กก.) | S5: วิธีบรรจุ | T5: วันส่ง | U5: จำนวนส่ง | V5: StockFG | W5: ค้างตัด | X5: พิมพ์แล้ว | Y5: ค้างพิมพ์ | Z5: ประเภท | AA5: ใช้ | AB5: Stock | AC5: ค้างทอ | AD5: Stock | AE5: ค้างเคลือบ | AF5: หมายเหตุ | AG5: ที่พิมพ์ได้ | AH5: process | AI5: Lead time | AJ5: วันที่ส่งPL | AK5: เคลือบ | AL5: ได้ ART | AM5: พิมพ์ | AN5: จีบ-บิด | AO5: ตัด-เย็บ | AP5: ทอ | AQ5: สวมถุง | AR5: เย็บปาก | AS5: PT | AT5: ม้วน | AU5: ตัด | AV5: ตอกตาไก่ | AW5: GROUP | AX5: ART | AY5: หมายเหตุปัญหา | AZ5: ราคา/ใบ | BA5: ราคารวม | BB5: workweek | BC5: เส้นเทป | BD5: จำนวน
A6: 45946 | B6: MK68-001239 | C6: หจก.ปึงเป้งน้ำ | D6: เกลือตรามือ 10กก. | E6: 14 | F6: 22 | G6: ขาว | H6: ใส | I6: 42 | J6: ± | K6: 5 | L6: ไม่ | M6: ไม่สวมถุงใน | N6: 0 | O6: 0 | P6: 0 | Q6: 0 | R6: 0 | S6: 500กระสอบแบน | T6: 45961 | U6: 10000 | V6: 0 | W6: 10000 | X6: 0 | Y6: 10500 | Z6: WSWT1425800 | AA6: 6565.9 | AB6: 5528 | AC6: 1037.9 | AD6: 636 | AE6: 5929.9 | AF6: 0 | AG6: พร้อมส่ง | AH6: P6 | AI6: 4 | AJ6: 45961 | AK6: 45957 | AL6: 45950 | AM6: 45958 | AN6: 45959 | AO6: 45960 | AP6: 45956 | AQ6: 0 | AR6: 0 | AS6: 0 | AT6: 0 | AU6: 0 | AV6: 0 | AW6: งานเคลือบ+พิมพ์ | AX6: / | AY6: 0 | AZ6: 0 | BA6: 0 | BB6: 0 | BC6: WRWT25800/WRWT25800 | BD6: 58.1224
A7: 0 | B7: 0 | C7: 0 | D7: 0 | E7: 14 | F7: 22 | G7: ขาว | H7: 0 | I7: 36 | J7: ± | K7: 5 | L7: 0 | M7: 0 | N7: 0 | O7: 0 | P7: 0 | Q7: 0 | R7: 0 | S7: 0 | U7: 0 | V7: 0 | W7: 0 | X7: 0 | Y7: 0 | Z7: WSWT1425800 | AA7: 6565.9 | AB7: 5528 | AC7: 1037.9 | AD7: 636 | AE7: 5929.9 | AF7: ระบุในSD | AG7: พร้อมส่ง | AH7: 0 | AI7: Lead time | AJ7: 0 | AK7: 0 | AL7: 0 | AM7: 0 | AN7: 0 | AO7: 0 | AP7: 0 | AQ7: 0 | AR7: 0 | AS7: 0 | AT7: 0 | AU7: 0 | AV7: 0 | AW7: 0 | AX7: 0 | AY7: 0 | AZ7: 0 | BA7: 0 | BB7: 0 | BC7: WRWT140800/WRWT25800 | BD7: 0
A8: ประมาณการ | B8: ประมาณการ | C8: บจก.เคอรี่ฟลาวมิลล์ | D8: โบว์แดง 10กก | E8: 16 | F8: 25 | G8: ขาว | H8: 0 | I8: 45 | J8: ± | K8: 5 | L8: ไม่ | M8: ไม่สวมถุงใน | N8: 0 | O8: 0 | P8: 0 | Q8: 0 | R8: 0 | S8: ห่ออัดเบลแบน500 | T8: รอแจ้ง | U8: 5000 | V8: 5000 | W8: 0 | X8: 5370 | Y8: 0 | Z8: WSWT1625800 | AA8: 0 | AB8: 0 | AC8: 0 | AD8: 0 | AE8: 0 | AF8: 0 | AG8: พร้อมส่ง | AH8: P7 | AI8: 2 | AJ8: รอแจ้ง | AK8: 0 | AL8: #VALUE! | AM8: #VALUE! | AN8: #VALUE! | AO8: #VALUE! | AP8: #VALUE! | AQ8: 0 | AR8: 0 | AS8: 0 | AT8: 0 | AU8: 0 | AV8: 0 | AW8: งานพิมพ์ | AX8: / | AY8: รอเก็บลบสีผสม | AZ8: 0 | BA8: 0 | BB8: 0 | BC8: WRWT25800/WRWT25800 | BD8: 0
A9: 0 | B9: 0 | C9: 0 | D9: 0 | E9: 16 | F9: 25 | G9: ขาว | H9: 0 | I9: 45 | J9: ± | K9: 5 | L9: 0 | M9: 0 | N9: 0 | O9: 0 | P9: 0 | Q9: 0 | R9: 0 | S9: 0 | U9: 0 | V9: 0 | W9: 0 | X9: 0 | Y9: 0 | Z9: WSWT1625800 | AA9: 0 | AB9: 0 | AC9: 0 | AD9: 0 | AE9: 0 | AF9: ระบุในSD | AG9: ยังไม่ได้พิมพ์ | AH9: 0 | AI9: Lead time | AJ9: 0 | AK9: 0 | AL9: 0 | AM9: 0 | AN9: 0 | AO9: 0 | AP9: 0 | AQ9: 0 | AR9: 0 | AS9: 0 | AT9: 0 | AU9: 0 | AV9: 0 | AW9: 0 | AX9: 0 | AY9: 0 | AZ9: 0 | BA9: 0 | BB9: 0 | BC9: WRWT160800/WRWT25800 | BD9: 0
A10: 45950 | B10: MK68-001247 | C10: บจก.ฟาเธอร์ส วิง ซัพพลาย | D10: รถไฟฟ้า | E10: 18 | F10: 30 | G10: ขาว | H10: 0 | I10: 54 | J10: ± | K10: 5 | L10: บิด | M10: 19 | N10: 33 | O10: 40 | P10: 77.343329 | Q10: 0 | R10: 77.343329 | S10: 500กระสอบ | T10: 45961 | U10: 5000 | V10: 0 | W10: 5000 | X10: 0 | Y10: 5250 | Z10: WSWT1825800 | AA10: 4400.55 | AB10: 4400.55 | AC10: 0 | AD10: 0 | AE10: 0 | AF10: 0 | AG10: ยังไม่ได้พิมพ์ | AH10: P9 | AI10: 3 | AJ10: 45961 | AK10: 0 | AL10: 45951 | AM10: 45958 | AN10: 45959 | AO10: 45959 | AP10: 45956 | AQ10: 45960 | AR10: 0 | AS10: 0 | AT10: 0 | AU10: 0 | AV10: 0 | AW10: งานพิมพ์ | AX10: / | AY10: 0 | AZ10: 0 | BA10: 0 | BB10: 0 | BC10: WRWT25800/WRWT25800 | BD10: 0
A11: 45950 | B11: MK68-001247 | C11: บจก.ฟาเธอร์ส วิง ซัพพลาย | D11: รถไฟฟ้าปูนขาวเย็น | E11: 18 | F11: 30 | G11: ขาว | H11: 0 | I11: 54 | J11: ± | K11: 5 | L11: บิด | M11: 19 | N11: 33 | O11: 40 | P11: 309.37332 | Q11: 0 | R11: 309.37332 | S11: 500กระสอบ | T11: 45961 | U11: 20000 | V11: 0 | W11: 20000 | X11: 5520 | Y11: 15204 | Z11: WSWT1825800 | AA11: 13381.192 | AB11: 13381.192 | AC11: 0 | AD11: 0 | AE11: 0 | AF11: 0 | AG11: ยังไม่ได้พิมพ์ | AH11: P9 | AI11: 3 | AJ11: 45961 | AK11: 0 | AL11: 45951 | AM11: 45958 | AN11: 45959 | AO11: 45959 | AP11: 45956 | AQ11: 45960 | AR11: 0 | AS11: 0 | AT11: 0 | AU11: 0 | AV11: 0 | AW11: งานพิมพ์ | AX11: / | AY11: 0 | AZ11: 0 | BA11: 0 | BB11: 0 | BC11: WRWT25800/WRWT25800 | BD11: 0
A12: 45950 | B12: MK68-001247 | C12: บจก.ฟาเธอร์ส วิง ซัพพลาย | D12: ไม่พิมพ์ | E12: 18 | F12: 30 | G12: ขาว | H12: 0 | I12: 54 | J12: ± | K12: 5 | L12: ไม่ | M12: 19 | N12: 33 | O12: 40 | P12: 46.405998 | Q12: 0 | R12: 46.405998 | S12: 500กระสอบ | T12: 45961 | U12: 3000 | V12: 0 | W12: 3000 | X12: 0 | Y12: 0 | Z12: WSWT1825800 | AA12: 2640.33 | AB12: 2640.33 | AC12: 0 | AD12: 0 | AE12: 0 | AF12: 0 | AG12: ยังไม่ได้พิมพ์ | AH12: P9 | AI12: 3 | AJ12: 45961 | AK12: 0 | AL12: 0 | AM12: 0 | AN12: 0 | AO12: 45957 | AP12: 45956 | AQ12: 45958 | AR12: 0 | AS12: 0 | AT12: 0 | AU12: 0 | AV12: 0 | AW12: ตัด | AX12: 0 | AY12: 0 | AZ12: 0 | BA12: 0 | BB12: 0 | BC12: WRWT25800/WRWT25800 | BD12: 0
A13: 0 | B13: ใบรับคำสั่งซื้อ | C13: บจก.ซีแมน | D13: Y30 | E13: 18 | F13: 25 | G13: ขาว | H13: 0 | I13: 50 | J13: ± | K13: 5 | L13: ไม่ | M13: 20 | N13: 27 | O13: 90 | P13: 299.75166 | Q13: 0 | R13: 299.75166 | S13: มัด100 | T13: 45961 | U13: 10000 | V13: 0 | W13: 10000 | X13: 0 | Y13: 10500 | Z13: WSWT1825800 | AA13: 7404.1 | AB13: 0 | AC13: 7404.1 | AD13: 0 | AE13: 0 | AF13: 0 | AG13: ยังไม่ได้พิมพ์ | AH13: P9 | AI13: 3 | AJ13: 45961 | AK13: 0 | AL13: 45951 | AM13: 45958 | AN13: 45959 | AO13: 45959 | AP13: 45956 | AQ13: 45960 | AR13: 0 | AS13: 0 | AT13: 0 | AU13: 0 | AV13: 0 | AW13: งานพิมพ์ | AX13: 0 | AY13: 0 | AZ13: 0 | BA13: 0 | BB13: 0 | BC13: WRWT25800/WRWT25800 | BD13: 509.40208
A14: 45923 | B14: MK68-001162 | C14: หจก.อนนท์อุตสาหกรรม | D14: ดาว 20 กก. | E14: 18 | F14: 28 | G14: ขาว | H14: 0 | I14: 50 | J14: ± | K14: 5 | L14: ไม่ | M14: 19 | N14: 31 | O14: 40 | P14: 363.27927 | Q14: 0 | R14: 363.27927 | S14: 500กระสอบแบน | T14: 45966 | U14: 25000 | V14: 0 | W14: 25000 | X14: 0 | Y14: 26250 | Z14: WSWT1825800 | AA14: 20605.75 | AB14: 20605.75 | AC14: 0 | AD14: 0 | AE14: 0 | AF14: 0 | AG14: ยังไม่ได้พิมพ์ | AH14: P9 | AI14: 3 | AJ14: 45966 | AK14: 0 | AL14: 45956 | AM14: 45963 | AN14: 45964 | AO14: 45964 | AP14: 45961 | AQ14: 45965 | AR14: 0 | AS14: 0 | AT14: 0 | AU14: 0 | AV14: 0 | AW14: งานพิมพ์ | AX14: / | AY14: 0 | AZ14: 0 | BA14: 0 | BB14: 0 | BC14: WRWT25800/WRWT25800 | BD14: 0
